Workbook

Sheet Parametres
A1: FILE 1 — Composite: Ø1200 + fosse trapezoidale (overflow)
A2: But: WSE amont du Ø1200 si overflow actif, et pointe aval = Q_1200 + Q_overflow. Jaune = entrees. Autres fichiers (comparaison, series temporelles, sensibilite) = separes.
A5: Schema
A6: Qin → bassin (Stage_Storage) → Q_1200(WSE) + Q_fossé(WSE si WSE≥crest) → aval
A8: Ø1200 (jaune)
A9: n Manning (-) | B9: 0.013
A10: D (m) | B10: 1.2
A11: L (m) | B11: 31.3
A12: Zin (m) | B12: 33.6
A13: Zout (m) | B13: 33.1
A14: S0 = (Zin-Zout)/L | B14: =(B12-B13)/B11
A15: A plein (m2) | B15: =PI()*B10^2/4
A16: R plein = D/4 (m) | B16: =B10/4
A17: Q_plein Manning (m3/s) | B17: =(1/B9)*B15*(B16^(2/3))*SQRT(B14)
A18: Fond bassin WSE min (m) | B18: 34.88
A20: Overflow fosse trapezoidale (jaune)
A21: Crest (m) | B21: 37.28 | C21: Q_overflow = 0 si WSE < crest
A22: b fond (m) | B22: 2
A23: n fosse (-) | B23: 0.035
A24: z (H:V) | B24: 2
A25: S fosse (-) | B25: 0.0085 | C25: Pente fosse (ex. 0.0085)
A26: L fosse (m) | B26: 50.1
A28: Facteur securite (-) | B28: 1.2
A30: RESULTATS FILE 1 (Calcul_Composite)
A31: Vmax (m3) = max(V_pond + V_ditch) | B31: =Calcul_Composite!B7
A32: V_dimensionnement = Vmax × facteur | B32: =B31*B28
A33: WSEmax (m) | B33: =Calcul_Composite!B8 | C33: Niveau max amont Ø1200
A34: Overflow atteint? | B34: =IF(B33>B21,"OUI — WSE > crest","NON — pipe seul")
A35: Q_1200 a la pointe de Qout (m3/s) | B35: =Calcul_Composite!B10
A36: Q_overflow a la pointe de Qout (m3/s) | B36: =Calcul_Composite!B11
A37: Q_down max = Q_1200 + Q_overflow (m3/s) | B37: =Calcul_Composite!B9 | C37: Pointe vue a l'aval
A38: HW max = WSEmax − Zin (m) | B38: =IF(ISNUMBER(B33),B33-B12,"")
A40: Message cle
A41: Si overflow OUI: l'aval recoit la somme pipe + fosse. WSEmax est le niveau dans le bassin amont du Ø1200 (eau retenue a l'entree).

Sheet Hydrogramme
A1: Hydrogramme d'entree — FILE 1
A2: Qin = ratio × Qpointe (jaune B4).
A4: Qpointe (m3/s) | B4: 9.6
A6: t (min) | B6: ratio | C6: Qin (m3/s)
A7: 0 | B7: 0.081042 | C7: =B7*$B$4
A8: 5 | B8: 0.121875 | C8: =B8*$B$4
A9: 10 | B9: 0.193438 | C9: =B9*$B$4
A10: 15 | B10: 0.333542 | C10: =B10*$B$4
A11: 20 | B11: 0.657188 | C11: =B11*$B$4
A12: 22.5 | B12: 1 | C12: =B12*$B$4
A13: 27.5 | B13: 0.608958 | C13: =B13*$B$4
A14: 32.5 | B14: 0.401771 | C14: =B14*$B$4
A15: 37.5 | B15: 0.280104 | C15: =B15*$B$4
A16: 42.5 | B16: 0.203438 | C16: =B16*$B$4
A17: 47.5 | B17: 0.152292 | C17: =B17*$B$4
A18: 52.5 | B18: 0.116771 | C18: =B18*$B$4
A19: 57.5 | B19: 0.091146 | C19: =B19*$B$4

Sheet Stage_Storage
A1: Stage–storage amont Ø1200 — editer surfaces jaunes
A2: V_pas = 0.5*(A_bas+A_haut)*dWSE. Aires synchronisees avec votre leve local. Role a 37.28 m laisse vide.
A10: WSE (m) | B10: Surface A (m2) EDIT | C10: dWSE (m) | D10: V_pas (m3) | E10: V_cumul (m3) | F10: Role
A11: 34.88 | B11: 0 | C11: 0 | D11: 0 | E11: 0 | F11: Fond bassin
A12: 35.5 | B12: 120 | C12: =A12-A11 | D12: =0.5*(B11+B12)*C12 | E12: =E11+D12 | F12: Placeholder — remplacer
A13: 36.01 | B13: 419 | C13: =A13-A12 | D13: =0.5*(B12+B13)*C13 | E13: =E12+D13 | F13: Placeholder — remplacer
A14: 36.5 | B14: 480 | C14: =A14-A13 | D14: =0.5*(B13+B14)*C14 | E14: =E13+D14 | F14: Placeholder — remplacer
A15: 37 | B15: 720 | C15: =A15-A14 | D15: =0.5*(B14+B15)*C15 | E15: =E14+D15 | F15: Placeholder — remplacer
A16: 37.28 | B16: 2198 | C16: =A16-A15 | D16: =0.5*(B15+B16)*C16 | E16: =E15+D16
A17: 37.4 | B17: 1516 | C17: =A17-A16 | D17: =0.5*(B16+B17)*C17 | E17: =E16+D17 | F17: Placeholder — remplacer
A18: 40 | B18: 3746 | C18: =A18-A17 | D18: =0.5*(B17+B18)*C18 | E18: =E17+D18 | F18: Placeholder haut — remplacer
A21: Vmax / WSEmax (FILE 1) | B21: =Parametres!B31 | C21: =Parametres!B33
A22: V @ 37.28 m | B22: =E16

Sheet Courbe_QH_1200
A1: Courbe Q=f(H) Ø1200 — FHWA inlet + outlet (LIVE)
A2: Lie a Parametres. Q_gouvernant = MIN(Qinlet, Qoutlet). Facteur 1.811 = conversion SI FHWA.
A4: n | B4: =Parametres!B9 | E4: entree | F4: K | G4: M | H4: c | I4: Y | J4: Ke
A5: D (m) | B5: =Parametres!B10 | E5: square_edge | F5: 0.0098 | G5: 2 | H5: 0.0398 | I5: 0.67 | J5: 0.5
A6: L (m) | B6: =Parametres!B11 | E6: beveled | F6: 0.0018 | G6: 2.5 | H6: 0.03 | I6: 0.74 | J6: 0.2
A7: Zin (m) | B7: =Parametres!B12 | E7: groove_headwall | F7: 0.0078 | G7: 2 | H7: 0.0292 | I7: 0.74 | J7: 0.2
A8: Zout (m) | B8: =Parametres!B13
A9: S0 | B9: =Parametres!B14
A10: TW au-dessus Zout (m) | B10: 0
A11: Entree | B11: square_edge
A13: K | B13: =IFERROR(VLOOKUP(B11,$E$5:$J$7,2,FALSE),0.0098)
A14: M | B14: =IFERROR(VLOOKUP(B11,$E$5:$J$7,3,FALSE),2)
A15: c | B15: =IFERROR(VLOOKUP(B11,$E$5:$J$7,4,FALSE),0.0398)
A16: Y | B16: =IFERROR(VLOOKUP(B11,$E$5:$J$7,5,FALSE),0.67)
A17: Ke | B17: =IFERROR(VLOOKUP(B11,$E$5:$J$7,6,FALSE),0.5)
A19: HW (m) | B19: WSE (m) | C19: Qinlet | D19: Qoutlet | E19: Q gouvernant
A20: 0 | B20: =$B$7+A20 | C20: =IF(A20<=0,0,IF(A20<=1.2*$B$5,1.811*(PI()*($B$5/2)^2)*SQRT($B$5)*IF($B$13*$B$5<=0,0,(A20/($B$13*$B$5))^(1/$B$14)),MAX(1.811*(PI()*($B$5/2)^2)*SQRT($B$5)*IF($B$13*$B$5<=0,0,((1.2*$B$5)/($B$13*$B$5))^(1/$B$14)),1.811*(PI()*($B$5/2)^2)*SQRT($B$5)*SQRT(MAX(0,(A20/$B$5-$B$16)/$B$15))))) | D20: =IF(A20<$B$5,IF($B$4<=0,0,(1/$B$4)*((($B$5/2)^2/2)*((2*ACOS(1-2*(MIN(0.999,MAX(1E-6,A20/$B$5)))))-SIN(2*ACOS(1-2*(MIN(0.999,MAX(1E-6,A20/$B$5)))))))*IF((IF((($B$5/2)*(2*ACOS(1-2*(MIN(0.999,MAX(1E-6,A20/$B$5))))))<=0,0,((($B$5/2)^2/2)*((2*ACOS(1-2*(MIN(0.999,MAX(1E-6,A20/$B$5)))))-SIN(2*ACOS(1-2*(MIN(0.999,MAX(1E-6,A20/$B$5)))))))/(($B$5/2)*(2*ACOS(1-2*(MIN(0.999,MAX(1E-6,A20/$B$5))))))))<=0,0,(IF((($B$5/2)*(2*ACOS(1-2*(MIN(0.999,MAX(1E-6,A20/$B$5))))))<=0,0,((($B$5/2)^2/2)*((2*ACOS(1-2*(MIN(0.999,MAX(1E-6,A20/$B$5)))))-SIN(2*ACOS(1-2*(MIN(0.999,MAX(1E-6,A20/$B$5)))))))/(($B$5/2)*(2*ACOS(1-2*(MIN(0.999,MAX(1E-6,A20/$B$5))))))))^(2/3))*SQRT($B$9)),IF((A20-$B$10+$B$9*$B$6)<=0,0,(PI()*($B$5/2)^2)*SQRT((A20-$B$10+$B$9*$B$6)/((1+$B$17)/(2*9.81)+($B$4^2)*$B$6/(($B$5/4)^(4/3)))))) | E20: =MIN(C20,D20)
A21: 0.05 | B21: =$B$7+A21 | C21: =IF(A21<=0,0,IF(A21<=1.2*$B$5,1.811*(PI()*($B$5/2)^2)*SQRT($B$5)*IF($B$13*$B$5<=0,0,(A21/($B$13*$B$5))^(1/$B$14)),MAX(1.811*(PI()*($B$5/2)^2)*SQRT($B$5)*IF($B$13*$B$5<=0,0,((1.2*$B$5)/($B$13*$B$5))^(1/$B$14)),1.811*(PI()*($B$5/2)^2)*SQRT($B$5)*SQRT(MAX(0,(A21/$B$5-$B$16)/5))))) | D21: =IF(A21<$B$5,IF($B$4<=0,0,(1/$B$4)*((($B$5/2)^2/2)*((2*ACOS(1-2*(MIN(0.999,MAX(1E-6,A21/$B$5)))))-SIN(2*ACOS(1-2*(MIN(0.999,MAX(1E-6,A21/$B$5)))))))*IF((IF((($B$5/2)*(2*ACOS(1-2*(MIN(0.999,MAX(1E-6,A21/$B$5))))))<=0,0,((($B$5/2)^2/2)*((2*ACOS(1-2*(MIN(0.999,MAX(1E-6,A21/$B$5)))))-SIN(2*ACOS(1-2*(MIN(0.999,MAX(1E-6,A21/$B$5)))))))/(($B$5/2)*(2*ACOS(1-2*(MIN(0.999,MAX(1E-6,A21/$B$5))))))))<=0,0,(IF((($B$5/2)*(2*ACOS(1-2*(MIN(0.999,MAX(1E-6,A21/$B$5))))))<=0,0,((($B$5/2)^2/2)*((2*ACOS(1-2*(MIN(0.999,MAX(1E-6,A21/$B$5)))))-SIN(2*ACOS(1-2*(MIN(0.999,MAX(1E-6,A21/$B$5)))))))/(($B$5/2)*(2*ACOS(1-2*(MIN(0.999,MAX(1E-6,A21/$B$5))))))))^(2/3))*SQRT($B$9)),IF((A21-$B$10+$B$9*$B$6)<=0,0,(PI()*($B$5/2)^2)*SQRT((A21-$B$10+$B$9*$B$6)/((1+$B$17)/(2*9.81)+($B$4^2)*$B$6/(($B$5/4)^(4/3)))))) | E21: =MIN(C21,D21)
A22: 0.1 | B22: =$B$7+A22 | C22: =IF(A22<=0,0,IF(A22<=1.2*$B$5,1.811*(PI()*($B$5/2)^2)*SQRT($B$5)*IF($B$13*$B$5<=0,0,(A22/($B$13*$B$5))^(1/$B$14)),MAX(1.811*(PI()*($B$5/2)^2)*SQRT($B$5)*IF($B$13*$B$5<=0,0,((1.2*$B$5)/($B$13*$B$5))^(1/$B$14)),1.811*(PI()*($B$5/2)^2)*SQRT($B$5)*SQRT(MAX(0,(A22/$B$5-$B$16)/5))))) | D22: =IF(A22<$B$5,IF($B$4<=0,0,(1/$B$4)*((($B$5/2)^2/2)*((2*ACOS(1-2*(MIN(0.999,MAX(1E-6,A22/$B$5)))))-SIN(2*ACOS(1-2*(MIN(0.999,MAX(1E-6,A22/$B$5)))))))*IF((IF((($B$5/2)*(2*ACOS(1-2*(MIN(0.999,MAX(1E-6,A22/$B$5))))))<=0,0,((($B$5/2)^2/2)*((2*ACOS(1-2*(MIN(0.999,MAX(1E-6,A22/$B$5)))))-SIN(2*ACOS(1-2*(MIN(0.999,MAX(1E-6,A22/$B$5)))))))/(($B$5/2)*(2*ACOS(1-2*(MIN(0.999,MAX(1E-6,A22/$B$5))))))))<=0,0,(IF((($B$5/2)*(2*ACOS(1-2*(MIN(0.999,MAX(1E-6,A22/$B$5))))))<=0,0,((($B$5/2)^2/2)*((2*ACOS(1-2*(MIN(0.999,MAX(1E-6,A22/$B$5)))))-SIN(2*ACOS(1-2*(MIN(0.999,MAX(1E-6,A22/$B$5)))))))/(($B$5/2)*(2*ACOS(1-2*(MIN(0.999,MAX(1E-6,A22/$B$5))))))))^(2/3))*SQRT($B$9)),IF((A22-$B$10+$B$9*$B$6)<=0,0,(PI()*($B$5/2)^2)*SQRT((A22-$B$10+$B$9*$B$6)/((1+$B$17)/(2*9.81)+($B$4^2)*$B$6/(($B$5/4)^(4/3)))))) | E22: =MIN(C22,D22)
A23: 0.15 | B23: =$B$7+A23 | C23: =IF(A23<=0,0,IF(A23<=1.2*$B$5,1.811*(PI()*($B$5/2)^2)*SQRT($B$5)*IF($B$13*$B$5<=0,0,(A23/($B$13*$B$5))^(1/$B$14)),MAX(1.811*(PI()*($B$5/2)^2)*SQRT($B$5)*IF($B$13*$B$5<=0,0,((1.2*$B$5)/($B$13*$B$5))^(1/$B$14)),1.811*(PI()*($B$5/2)^2)*SQRT($B$5)*SQRT(MAX(0,(A23/$B$5-$B$16)/5))))) | D23: =IF(A23<$B$5,IF($B$4<=0,0,(1/$B$4)*((($B$5/2)^2/2)*((2*ACOS(1-2*(MIN(0.999,MAX(1E-6,A23/$B$5)))))-SIN(2*ACOS(1-2*(MIN(0.999,MAX(1E-6,A23/$B$5)))))))*IF((IF((($B$5/2)*(2*ACOS(1-2*(MIN(0.999,MAX(1E-6,A23/$B$5))))))<=0,0,((($B$5/2)^2/2)*((2*ACOS(1-2*(MIN(0.999,MAX(1E-6,A23/$B$5)))))-SIN(2*ACOS(1-2*(MIN(0.999,MAX(1E-6,A23/$B$5)))))))/(($B$5/2)*(2*ACOS(1-2*(MIN(0.999,MAX(1E-6,A23/$B$5))))))))<=0,0,(IF((($B$5/2)*(2*ACOS(1-2*(MIN(0.999,MAX(1E-6,A23/$B$5))))))<=0,0,((($B$5/2)^2/2)*((2*ACOS(1-2*(MIN(0.999,MAX(1E-6,A23/$B$5)))))-SIN(2*ACOS(1-2*(MIN(0.999,MAX(1E-6,A23/$B$5)))))))/(($B$5/2)*(2*ACOS(1-2*(MIN(0.999,MAX(1E-6,A23/$B$5))))))))^(2/3))*SQRT($B$9)),IF((A23-$B$10+$B$9*$B$6)<=0,0,(PI()*($B$5/2)^2)*SQRT((A23-$B$10+$B$9*$B$6)/((1+$B$17)/(2*9.81)+($B$4^2)*$B$6/(($B$5/4)^(4/3)))))) | E23: =MIN(C23,D23)
A24: 0.2 | B24: =$B$7+A24 | C24: =IF(A24<=0,0,IF(A24<=1.2*$B$5,1.811*(PI()*($B$5/2)^2)*SQRT($B$5)*IF($B$13*$B$5<=0,0,(A24/($B$13*$B$5))^(1/$B$14)),MAX(1.811*(PI()*($B$5/2)^2)*SQRT($B$5)*IF($B$13*$B$5<=0,0,((1.2*$B$5)/($B$13*$B$5))^(1/$B$14)),1.811*(PI()*($B$5/2)^2)*SQRT($B$5)*SQRT(MAX(0,(A24/$B$5-$B$16)/5))))) | D24: =IF(A24<$B$5,IF($B$4<=0,0,(1/$B$4)*((($B$5/2)^2/2)*((2*ACOS(1-2*(MIN(0.999,MAX(1E-6,A24/$B$5)))))-SIN(2*ACOS(1-2*(MIN(0.999,MAX(1E-6,A24/$B$5)))))))*IF((IF((($B$5/2)*(2*ACOS(1-2*(MIN(0.999,MAX(1E-6,A24/$B$5))))))<=0,0,((($B$5/2)^2/2)*((2*ACOS(1-2*(MIN(0.999,MAX(1E-6,A24/$B$5)))))-SIN(2*ACOS(1-2*(MIN(0.999,MAX(1E-6,A24/$B$5)))))))/(($B$5/2)*(2*ACOS(1-2*(MIN(0.999,MAX(1E-6,A24/$B$5))))))))<=0,0,(IF((($B$5/2)*(2*ACOS(1-2*(MIN(0.999,MAX(1E-6,A24/$B$5))))))<=0,0,((($B$5/2)^2/2)*((2*ACOS(1-2*(MIN(0.999,MAX(1E-6,A24/$B$5)))))-SIN(2*ACOS(1-2*(MIN(0.999,MAX(1E-6,A24/$B$5)))))))/(($B$5/2)*(2*ACOS(1-2*(MIN(0.999,MAX(1E-6,A24/$B$5))))))))^(2/3))*SQRT($B$9)),IF((A24-$B$10+$B$9*$B$6)<=0,0,(PI()*($B$5/2)^2)*SQRT((A24-$B$10+$B$9*$B$6)/((1+$B$17)/(2*9.81)+($B$4^2)*$B$6/(($B$5/4)^(4/3)))))) | E24: =MIN(C24,D24)
A25: 0.25 | B25: =$B$7+A25 | C25: =IF(A25<=0,0,IF(A25<=1.2*$B$5,1.811*(PI()*($B$5/2)^2)*SQRT($B$5)*IF($B$13*$B$5<=0,0,(A25/($B$13*$B$5))^(1/$B$14)),MAX(1.811*(PI()*($B$5/2)^2)*SQRT($B$5)*IF($B$13*$B$5<=0,0,((1.2*$B$5)/($B$13*$B$5))^(1/$B$14)),1.811*(PI()*($B$5/2)^2)*SQRT($B$5)*SQRT(MAX(0,(A25/$B$5-$B$16)/5))))) | D25: =IF(A25<$B$5,IF($B$4<=0,0,(1/$B$4)*((($B$5/2)^2/2)*((2*ACOS(1-2*(MIN(0.999,MAX(1E-6,A25/$B$5)))))-SIN(2*ACOS(1-2*(MIN(0.999,MAX(1E-6,A25/$B$5)))))))*IF((IF((($B$5/2)*(2*ACOS(1-2*(MIN(0.999,MAX(1E-6,A25/$B$5))))))<=0,0,((($B$5/2)^2/2)*((2*ACOS(1-2*(MIN(0.999,MAX(1E-6,A25/$B$5)))))-SIN(2*ACOS(1-2*(MIN(0.999,MAX(1E-6,A25/$B$5)))))))/(($B$5/2)*(2*ACOS(1-2*(MIN(0.999,MAX(1E-6,A25/$B$5))))))))<=0,0,(IF((($B$5/2)*(2*ACOS(1-2*(MIN(0.999,MAX(1E-6,A25/$B$5))))))<=0,0,((($B$5/2)^2/2)*((2*ACOS(1-2*(MIN(0.999,MAX(1E-6,A25/$B$5)))))-SIN(2*ACOS(1-2*(MIN(0.999,MAX(1E-6,A25/$B$5)))))))/(($B$5/2)*(2*ACOS(1-2*(MIN(0.999,MAX(1E-6,A25/$B$5))))))))^(2/3))*SQRT($B$9)),IF((A25-$B$10+$B$9*$B$6)<=0,0,(PI()*($B$5/2)^2)*SQRT((A25-$B$10+$B$9*$B$6)/((1+$B$17)/(2*9.81)+($B$4^2)*$B$6/(($B$5/4)^(4/3)))))) | E25: =MIN(C25,D25)
A26: 0.3 | B26: =$B$7+A26 | C26: =IF(A26<=0,0,IF(A26<=1.2*$B$5,1.811*(PI()*($B$5/2)^2)*SQRT($B$5)*IF($B$13*$B$5<=0,0,(A26/($B$13*$B$5))^(1/$B$14)),MAX(1.811*(PI()*($B$5/2)^2)*SQRT($B$5)*IF($B$13*$B$5<=0,0,((1.2*$B$5)/($B$13*$B$5))^(1/$B$14)),1.811*(PI()*($B$5/2)^2)*SQRT($B$5)*SQRT(MAX(0,(A26/$B$5-$B$16)/5))))) | D26: =IF(A26<$B$5,IF($B$4<=0,0,(1/$B$4)*((($B$5/2)^2/2)*((2*ACOS(1-2*(MIN(0.999,MAX(1E-6,A26/$B$5)))))-SIN(2*ACOS(1-2*(MIN(0.999,MAX(1E-6,A26/$B$5)))))))*IF((IF((($B$5/2)*(2*ACOS(1-2*(MIN(0.999,MAX(1E-6,A26/$B$5))))))<=0,0,((($B$5/2)^2/2)*((2*ACOS(1-2*(MIN(0.999,MAX(1E-6,A26/$B$5)))))-SIN(2*ACOS(1-2*(MIN(0.999,MAX(1E-6,A26/$B$5)))))))/(($B$5/2)*(2*ACOS(1-2*(MIN(0.999,MAX(1E-6,A26/$B$5))))))))<=0,0,(IF((($B$5/2)*(2*ACOS(1-2*(MIN(0.999,MAX(1E-6,A26/$B$5))))))<=0,0,((($B$5/2)^2/2)*((2*ACOS(1-2*(MIN(0.999,MAX(1E-6,A26/$B$5)))))-SIN(2*ACOS(1-2*(MIN(0.999,MAX(1E-6,A26/$B$5)))))))/(($B$5/2)*(2*ACOS(1-2*(MIN(0.999,MAX(1E-6,A26/$B$5))))))))^(2/3))*SQRT($B$9)),IF((A26-$B$10+$B$9*$B$6)<=0,0,(PI()*($B$5/2)^2)*SQRT((A26-$B$10+$B$9*$B$6)/((1+$B$17)/(2*9.81)+($B$4^2)*$B$6/(($B$5/4)^(4/3)))))) | E26: =MIN(C26,D26)
A27: 0.35 | B27: =$B$7+A27 | C27: =IF(A27<=0,0,IF(A27<=1.2*$B$5,1.811*(PI()*($B$5/2)^2)*SQRT($B$5)*IF($B$13*$B$5<=0,0,(A27/($B$13*$B$5))^(1/$B$14)),MAX(1.811*(PI()*($B$5/2)^2)*SQRT($B$5)*IF($B$13*$B$5<=0,0,((1.2*$B$5)/($B$13*$B$5))^(1/$B$14)),1.811*(PI()*($B$5/2)^2)*SQRT($B$5)*SQRT(MAX(0,(A27/$B$5-$B$16)/5))))) | D27: =IF(A27<$B$5,IF($B$4<=0,0,(1/$B$4)*((($B$5/2)^2/2)*((2*ACOS(1-2*(MIN(0.999,MAX(1E-6,A27/$B$5)))))-SIN(2*ACOS(1-2*(MIN(0.999,MAX(1E-6,A27/$B$5)))))))*IF((IF((($B$5/2)*(2*ACOS(1-2*(MIN(0.999,MAX(1E-6,A27/$B$5))))))<=0,0,((($B$5/2)^2/2)*((2*ACOS(1-2*(MIN(0.999,MAX(1E-6,A27/$B$5)))))-SIN(2*ACOS(1-2*(MIN(0.999,MAX(1E-6,A27/$B$5)))))))/(($B$5/2)*(2*ACOS(1-2*(MIN(0.999,MAX(1E-6,A27/$B$5))))))))<=0,0,(IF((($B$5/2)*(2*ACOS(1-2*(MIN(0.999,MAX(1E-6,A27/$B$5))))))<=0,0,((($B$5/2)^2/2)*((2*ACOS(1-2*(MIN(0.999,MAX(1E-6,A27/$B$5)))))-SIN(2*ACOS(1-2*(MIN(0.999,MAX(1E-6,A27/$B$5)))))))/(($B$5/2)*(2*ACOS(1-2*(MIN(0.999,MAX(1E-6,A27/$B$5))))))))^(2/3))*SQRT($B$9)),IF((A27-$B$10+$B$9*$B$6)<=0,0,(PI()*($B$5/2)^2)*SQRT((A27-$B$10+$B$9*$B$6)/((1+$B$17)/(2*9.81)+($B$4^2)*$B$6/(($B$5/4)^(4/3)))))) | E27: =MIN(C27,D27)
A28: 0.4 | B28: =$B$7+A28 | C28: =IF(A28<=0,0,IF(A28<=1.2*$B$5,1.811*(PI()*($B$5/2)^2)*SQRT($B$5)*IF($B$13*$B$5<=0,0,(A28/($B$13*$B$5))^(1/$B$14)),MAX(1.811*(PI()*($B$5/2)^2)*SQRT($B$5)*IF($B$13*$B$5<=0,0,((1.2*$B$5)/($B$13*$B$5))^(1/$B$14)),1.811*(PI()*($B$5/2)^2)*SQRT($B$5)*SQRT(MAX(0,(A28/$B$5-$B$16)/5))))) | D28: =IF(A28<$B$5,IF($B$4<=0,0,(1/$B$4)*((($B$5/2)^2/2)*((2*ACOS(1-2*(MIN(0.999,MAX(1E-6,A28/$B$5)))))-SIN(2*ACOS(1-2*(MIN(0.999,MAX(1E-6,A28/$B$5)))))))*IF((IF((($B$5/2)*(2*ACOS(1-2*(MIN(0.999,MAX(1E-6,A28/$B$5))))))<=0,0,((($B$5/2)^2/2)*((2*ACOS(1-2*(MIN(0.999,MAX(1E-6,A28/$B$5)))))-SIN(2*ACOS(1-2*(MIN(0.999,MAX(1E-6,A28/$B$5)))))))/(($B$5/2)*(2*ACOS(1-2*(MIN(0.999,MAX(1E-6,A28/$B$5))))))))<=0,0,(IF((($B$5/2)*(2*ACOS(1-2*(MIN(0.999,MAX(1E-6,A28/$B$5))))))<=0,0,((($B$5/2)^2/2)*((2*ACOS(1-2*(MIN(0.999,MAX(1E-6,A28/$B$5)))))-SIN(2*ACOS(1-2*(MIN(0.999,MAX(1E-6,A28/$B$5)))))))/(($B$5/2)*(2*ACOS(1-2*(MIN(0.999,MAX(1E-6,A28/$B$5))))))))^(2/3))*SQRT($B$9)),IF((A28-$B$10+$B$9*$B$6)<=0,0,(PI()*($B$5/2)^2)*SQRT((A28-$B$10+$B$9*$B$6)/((1+$B$17)/(2*9.81)+($B$4^2)*$B$6/(($B$5/4)^(4/3)))))) | E28: =MIN(C28,D28)
A29: 0.45 | B29: =$B$7+A29 | C29: =IF(A29<=0,0,IF(A29<=1.2*$B$5,1.811*(PI()*($B$5/2)^2)*SQRT($B$5)*IF($B$13*$B$5<=0,0,(A29/($B$13*$B$5))^(1/$B$14)),MAX(1.811*(PI()*($B$5/2)^2)*SQRT($B$5)*IF($B$13*$B$5<=0,0,((1.2*$B$5)/($B$13*$B$5))^(1/$B$14)),1.811*(PI()*($B$5/2)^2)*SQRT($B$5)*SQRT(MAX(0,(A29/$B$5-$B$16)/5))))) | D29: =IF(A29<$B$5,IF($B$4<=0,0,(1/$B$4)*((($B$5/2)^2/2)*((2*ACOS(1-2*(MIN(0.999,MAX(1E-6,A29/$B$5)))))-SIN(2*ACOS(1-2*(MIN(0.999,MAX(1E-6,A29/$B$5)))))))*IF((IF((($B$5/2)*(2*ACOS(1-2*(MIN(0.999,MAX(1E-6,A29/$B$5))))))<=0,0,((($B$5/2)^2/2)*((2*ACOS(1-2*(MIN(0.999,MAX(1E-6,A29/$B$5)))))-SIN(2*ACOS(1-2*(MIN(0.999,MAX(1E-6,A29/$B$5)))))))/(($B$5/2)*(2*ACOS(1-2*(MIN(0.999,MAX(1E-6,A29/$B$5))))))))<=0,0,(IF((($B$5/2)*(2*ACOS(1-2*(MIN(0.999,MAX(1E-6,A29/$B$5))))))<=0,0,((($B$5/2)^2/2)*((2*ACOS(1-2*(MIN(0.999,MAX(1E-6,A29/$B$5)))))-SIN(2*ACOS(1-2*(MIN(0.999,MAX(1E-6,A29/$B$5)))))))/(($B$5/2)*(2*ACOS(1-2*(MIN(0.999,MAX(1E-6,A29/$B$5))))))))^(2/3))*SQRT($B$9)),IF((A29-$B$10+$B$9*$B$6)<=0,0,(PI()*($B$5/2)^2)*SQRT((A29-$B$10+$B$9*$B$6)/((1+$B$17)/(2*9.81)+($B$4^2)*$B$6/(($B$5/4)^(4/3)))))) | E29: =MIN(C29,D29)
A30: 0.5 | B30: =$B$7+A30 | C30: =IF(A30<=0,0,IF(A30<=1.2*$B$5,1.811*(PI()*($B$5/2)^2)*SQRT($B$5)*IF($B$13*$B$5<=0,0,(A30/($B$13*$B$5))^(1/$B$14)),MAX(1.811*(PI()*($B$5/2)^2)*SQRT($B$5)*IF($B$13*$B$5<=0,0,((1.2*$B$5)/($B$13*$B$5))^(1/$B$14)),1.811*(PI()*($B$5/2)^2)*SQRT($B$5)*SQRT(MAX(0,(A30/$B$5-$B$16)/5))))) | D30: =IF(A30<$B$5,IF($B$4<=0,0,(1/$B$4)*((($B$5/2)^2/2)*((2*ACOS(1-2*(MIN(0.999,MAX(1E-6,A30/$B$5)))))-SIN(2*ACOS(1-2*(MIN(0.999,MAX(1E-6,A30/$B$5)))))))*IF((IF((($B$5/2)*(2*ACOS(1-2*(MIN(0.999,MAX(1E-6,A30/$B$5))))))<=0,0,((($B$5/2)^2/2)*((2*ACOS(1-2*(MIN(0.999,MAX(1E-6,A30/$B$5)))))-SIN(2*ACOS(1-2*(MIN(0.999,MAX(1E-6,A30/$B$5)))))))/(($B$5/2)*(2*ACOS(1-2*(MIN(0.999,MAX(1E-6,A30/$B$5))))))))<=0,0,(IF((($B$5/2)*(2*ACOS(1-2*(MIN(0.999,MAX(1E-6,A30/$B$5))))))<=0,0,((($B$5/2)^2/2)*((2*ACOS(1-2*(MIN(0.999,MAX(1E-6,A30/$B$5)))))-SIN(2*ACOS(1-2*(MIN(0.999,MAX(1E-6,A30/$B$5)))))))/(($B$5/2)*(2*ACOS(1-2*(MIN(0.999,MAX(1E-6,A30/$B$5))))))))^(2/3))*SQRT($B$9)),IF((A30-$B$10+$B$9*$B$6)<=0,0,(PI()*($B$5/2)^2)*SQRT((A30-$B$10+$B$9*$B$6)/((1+$B$17)/(2*9.81)+($B$4^2)*$B$6/(($B$5/4)^(4/3)))))) | E30: =MIN(C30,D30)
A31: 0.55 | B31: =$B$7+A31 | C31: =IF(A31<=0,0,IF(A31<=1.2*$B$5,1.811*(PI()*($B$5/2)^2)*SQRT($B$5)*IF($B$13*$B$5<=0,0,(A31/($B$13*$B$5))^(1/$B$14)),MAX(1.811*(PI()*($B$5/2)^2)*SQRT($B$5)*IF($B$13*$B$5<=0,0,((1.2*$B$5)/($B$13*$B$5))^(1/$B$14)),1.811*(PI()*($B$5/2)^2)*SQRT($B$5)*SQRT(MAX(0,(A31/$B$5-$B$16)/5))))) | D31: =IF(A31<$B$5,IF($B$4<=0,0,(1/$B$4)*((($B$5/2)^2/2)*((2*ACOS(1-2*(MIN(0.999,MAX(1E-6,A31/$B$5)))))-SIN(2*ACOS(1-2*(MIN(0.999,MAX(1E-6,A31/$B$5)))))))*IF((IF((($B$5/2)*(2*ACOS(1-2*(MIN(0.999,MAX(1E-6,A31/$B$5))))))<=0,0,((($B$5/2)^2/2)*((2*ACOS(1-2*(MIN(0.999,MAX(1E-6,A31/$B$5)))))-SIN(2*ACOS(1-2*(MIN(0.999,MAX(1E-6,A31/$B$5)))))))/(($B$5/2)*(2*ACOS(1-2*(MIN(0.999,MAX(1E-6,A31/$B$5))))))))<=0,0,(IF((($B$5/2)*(2*ACOS(1-2*(MIN(0.999,MAX(1E-6,A31/$B$5))))))<=0,0,((($B$5/2)^2/2)*((2*ACOS(1-2*(MIN(0.999,MAX(1E-6,A31/$B$5)))))-SIN(2*ACOS(1-2*(MIN(0.999,MAX(1E-6,A31/$B$5)))))))/(($B$5/2)*(2*ACOS(1-2*(MIN(0.999,MAX(1E-6,A31/$B$5))))))))^(2/3))*SQRT($B$9)),IF((A31-$B$10+$B$9*$B$6)<=0,0,(PI()*($B$5/2)^2)*SQRT((A31-$B$10+$B$9*$B$6)/((1+$B$17)/(2*9.81)+($B$4^2)*$B$6/(($B$5/4)^(4/3)))))) | E31: =MIN(C31,D31)
A32: 0.6 | B32: =$B$7+A32 | C32: =IF(A32<=0,0,IF(A32<=1.2*$B$5,1.811*(PI()*($B$5/2)^2)*SQRT($B$5)*IF($B$13*$B$5<=0,0,(A32/($B$13*$B$5))^(1/$B$14)),MAX(1.811*(PI()*($B$5/2)^2)*SQRT($B$5)*IF($B$13*$B$5<=0,0,((1.2*$B$5)/($B$13*$B$5))^(1/$B$14)),1.811*(PI()*($B$5/2)^2)*SQRT($B$5)*SQRT(MAX(0,(A32/$B$5-$B$16)/5))))) | D32: =IF(A32<$B$5,IF($B$4<=0,0,(1/$B$4)*((($B$5/2)^2/2)*((2*ACOS(1-2*(MIN(0.999,MAX(1E-6,A32/$B$5)))))-SIN(2*ACOS(1-2*(MIN(0.999,MAX(1E-6,A32/$B$5)))))))*IF((IF((($B$5/2)*(2*ACOS(1-2*(MIN(0.999,MAX(1E-6,A32/$B$5))))))<=0,0,((($B$5/2)^2/2)*((2*ACOS(1-2*(MIN(0.999,MAX(1E-6,A32/$B$5)))))-SIN(2*ACOS(1-2*(MIN(0.999,MAX(1E-6,A32/$B$5)))))))/(($B$5/2)*(2*ACOS(1-2*(MIN(0.999,MAX(1E-6,A32/$B$5))))))))<=0,0,(IF((($B$5/2)*(2*ACOS(1-2*(MIN(0.999,MAX(1E-6,A32/$B$5))))))<=0,0,((($B$5/2)^2/2)*((2*ACOS(1-2*(MIN(0.999,MAX(1E-6,A32/$B$5)))))-SIN(2*ACOS(1-2*(MIN(0.999,MAX(1E-6,A32/$B$5)))))))/(($B$5/2)*(2*ACOS(1-2*(MIN(0.999,MAX(1E-6,A32/$B$5))))))))^(2/3))*SQRT($B$9)),IF((A32-$B$10+$B$9*$B$6)<=0,0,(PI()*($B$5/2)^2)*SQRT((A32-$B$10+$B$9*$B$6)/((1+$B$17)/(2*9.81)+($B$4^2)*$B$6/(($B$5/4)^(4/3)))))) | E32: =MIN(C32,D32)
... A80: 3 | B80: =$B$7+A80 | C80: =IF(A80<=0,0,IF(A80<=1.2*$B$5,1.811*(PI()*($B$5/2)^2)*SQRT($B$5)*IF($B$13*$B$5<=0,0,(A80/($B$13*$B$5))^(1/$B$14)),MAX(1.811*(PI()*($B$5/2)^2)*SQRT($B$5)*IF($B$13*$B$5<=0,0,((1.2*$B$5)/($B$13*$B$5))^(1/$B$14)),1.811*(PI()*($B$5/2)^2)*SQRT($B$5)*SQRT(MAX(0,(A80/$B$5-$B$16)/5))))) | D80: =IF(A80<$B$5,IF($B$4<=0,0,(1/$B$4)*((($B$5/2)^2/2)*((2*ACOS(1-2*(MIN(0.999,MAX(1E-6,A80/$B$5)))))-SIN(2*ACOS(1-2*(MIN(0.999,MAX(1E-6,A80/$B$5)))))))*IF((IF((($B$5/2)*(2*ACOS(1-2*(MIN(0.999,MAX(1E-6,A80/$B$5))))))<=0,0,((($B$5/2)^2/2)*((2*ACOS(1-2*(MIN(0.999,MAX(1E-6,A80/$B$5)))))-SIN(2*ACOS(1-2*(MIN(0.999,MAX(1E-6,A80/$B$5)))))))/(($B$5/2)*(2*ACOS(1-2*(MIN(0.999,MAX(1E-6,A80/$B$5))))))))<=0,0,(IF((($B$5/2)*(2*ACOS(1-2*(MIN(0.999,MAX(1E-6,A80/$B$5))))))<=0,0,((($B$5/2)^2/2)*((2*ACOS(1-2*(MIN(0.999,MAX(1E-6,A80/$B$5)))))-SIN(2*ACOS(1-2*(MIN(0.999,MAX(1E-6,A80/$B$5)))))))/(($B$5/2)*(2*ACOS(1-2*(MIN(0.999,MAX(1E-6,A80/$B$5))))))))^(2/3))*SQRT($B$9)),IF((A80-$B$10+$B$9*$B$6)<=0,0,(PI()*($B$5/2)^2)*SQRT((A80-$B$10+$B$9*$B$6)/((1+$B$17)/(2*9.81)+($B$4^2)*$B$6/(($B$5/4)^(4/3)))))) | E80: =MIN(C80,D80)

Sheet Compose
A1: FILE 1 — Compose: Q_1200 + Q_overflow; V_pond + V_ditch
A2: Overflow Manning trapèze au-dessus du crest. Parametres lies (jaune).
A4: Crest | B4: =Parametres!B21
A5: b | B5: =Parametres!B22
A6: n | B6: =Parametres!B23
A7: z | B7: =Parametres!B24
A8: S | B8: =Parametres!B25
A9: L | B9: =Parametres!B26
A10: Zin | B10: =Parametres!B12
A12: WSE | B12: HW | C12: y_ov | D12: A_ditch | E12: V_ditch | F12: V_pond | G12: V_total | H12: Q_1200 | I12: Q_overflow | J12: Qout
A13: 34.88 | B13: =A13-$B$10 | C13: =MAX(0,A13-$B$4) | D13: =IF(C13<=0,0,($B$5+$B$7*C13)*C13) | E13: =D13*$B$9 | F13: =IF(A13<=INDEX(Stage_Storage!$A$11:$A$18,1),INDEX(Stage_Storage!$E$11:$E$18,1),IF(A13>=INDEX(Stage_Storage!$A$11:$A$18,ROWS(Stage_Storage!$A$11:$A$18)),INDEX(Stage_Storage!$E$11:$E$18,ROWS(Stage_Storage!$E$11:$E$18)),INDEX(Stage_Storage!$E$11:$E$18,MATCH(A13,Stage_Storage!$A$11:$A$18,1))+(A13-INDEX(Stage_Storage!$A$11:$A$18,MATCH(A13,Stage_Storage!$A$11:$A$18,1)))/(INDEX(Stage_Storage!$A$11:$A$18,MATCH(A13,Stage_Storage!$A$11:$A$18,1)+1)-INDEX(Stage_Storage!$A$11:$A$18,MATCH(A13,Stage_Storage!$A$11:$A$18,1)))*(INDEX(Stage_Storage!$E$11:$E$18,MATCH(A13,Stage_Storage!$A$11:$A$18,1)+1)-INDEX(Stage_Storage!$E$11:$E$18,MATCH(A13,Stage_Storage!$A$11:$A$18,1))))) | G13: =E13+F13 | H13: =IF(B13<=0,0,IF(B13>=INDEX(Courbe_QH_1200!$A$20:$A$80,ROWS(Courbe_QH_1200!$A$20:$A$80)),INDEX(Courbe_QH_1200!$E$20:$E$80,ROWS(Courbe_QH_1200!$E$20:$E$80)),INDEX(Courbe_QH_1200!$E$20:$E$80,MATCH(B13,Courbe_QH_1200!$A$20:$A$80,1))+(B13-INDEX(Courbe_QH_1200!$A$20:$A$80,MATCH(B13,Courbe_QH_1200!$A$20:$A$80,1)))/(INDEX(Courbe_QH_1200!$A$20:$A$80,MATCH(B13,Courbe_QH_1200!$A$20:$A$80,1)+1)-INDEX(Courbe_QH_1200!$A$20:$A$80,MATCH(B13,Courbe_QH_1200!$A$20:$A$80,1)))*(INDEX(Courbe_QH_1200!$E$20:$E$80,MATCH(B13,Courbe_QH_1200!$A$20:$A$80,1)+1)-INDEX(Courbe_QH_1200!$E$20:$E$80,MATCH(B13,Courbe_QH_1200!$A$20:$A$80,1))))) | I13: =IF(C13<=0,0,IF($B$6<=0,0,(1/$B$6)*D13*IF(($B$5+2*C13*SQRT(1+$B$7^2))<=0,0,((D13/($B$5+2*C13*SQRT(1+$B$7^2)))^(2/3)))*SQRT($B$8))) | J13: =H13+I13
A14: 34.98 | B14: =A14-$B$10 | C14: =MAX(0,A14-$B$4) | D14: =IF(C14<=0,0,($B$5+$B$7*C14)*C14) | E14: =D14*$B$9 | F14: =IF(A14<=INDEX(Stage_Storage!$A$11:$A$18,1),INDEX(Stage_Storage!$E$11:$E$18,1),IF(A14>=INDEX(Stage_Storage!$A$11:$A$18,ROWS(Stage_Storage!$A$11:$A$18)),INDEX(Stage_Storage!$E$11:$E$18,ROWS(Stage_Storage!$E$11:$E$18)),INDEX(Stage_Storage!$E$11:$E$18,MATCH(A14,Stage_Storage!$A$11:$A$18,1))+(A14-INDEX(Stage_Storage!$A$11:$A$18,MATCH(A14,Stage_Storage!$A$11:$A$18,1)))/(INDEX(Stage_Storage!$A$11:$A$18,MATCH(A14,Stage_Storage!$A$11:$A$18,1)+1)-INDEX(Stage_Storage!$A$11:$A$18,MATCH(A14,Stage_Storage!$A$11:$A$18,1)))*(INDEX(Stage_Storage!$E$11:$E$18,MATCH(A14,Stage_Storage!$A$11:$A$18,1)+1)-INDEX(Stage_Storage!$E$11:$E$18,MATCH(A14,Stage_Storage!$A$11:$A$18,1))))) | G14: =E14+F14 | H14: =IF(B14<=0,0,IF(B14>=INDEX(Courbe_QH_1200!$A$20:$A$80,ROWS(Courbe_QH_1200!$A$20:$A$80)),INDEX(Courbe_QH_1200!$E$20:$E$80,ROWS(Courbe_QH_1200!$E$20:$E$80)),INDEX(Courbe_QH_1200!$E$20:$E$80,MATCH(B14,Courbe_QH_1200!$A$20:$A$80,1))+(B14-INDEX(Courbe_QH_1200!$A$20:$A$80,MATCH(B14,Courbe_QH_1200!$A$20:$A$80,1)))/(INDEX(Courbe_QH_1200!$A$20:$A$80,MATCH(B14,Courbe_QH_1200!$A$20:$A$80,1)+1)-INDEX(Courbe_QH_1200!$A$20:$A$80,MATCH(B14,Courbe_QH_1200!$A$20:$A$80,1)))*(INDEX(Courbe_QH_1200!$E$20:$E$80,MATCH(B14,Courbe_QH_1200!$A$20:$A$80,1)+1)-INDEX(Courbe_QH_1200!$E$20:$E$80,MATCH(B14,Courbe_QH_1200!$A$20:$A$80,1))))) | I14: =IF(C14<=0,0,IF($B$6<=0,0,(1/$B$6)*D14*IF(($B$5+2*C14*SQRT(1+$B$7^2))<=0,0,((D14/($B$5+2*C14*SQRT(1+$B$7^2)))^(2/3)))*SQRT($B$8))) | J14: =H14+I14
A15: 35.08 | B15: =A15-$B$10 | C15: =MAX(0,A15-$B$4) | D15: =IF(C15<=0,0,($B$5+$B$7*C15)*C15) | E15: =D15*$B$9 | F15: =IF(A15<=INDEX(Stage_Storage!$A$11:$A$18,1),INDEX(Stage_Storage!$E$11:$E$18,1),IF(A15>=INDEX(Stage_Storage!$A$11:$A$18,ROWS(Stage_Storage!$A$11:$A$18)),INDEX(Stage_Storage!$E$11:$E$18,ROWS(Stage_Storage!$E$11:$E$18)),INDEX(Stage_Storage!$E$11:$E$18,MATCH(A15,Stage_Storage!$A$11:$A$18,1))+(A15-INDEX(Stage_Storage!$A$11:$A$18,MATCH(A15,Stage_Storage!$A$11:$A$18,1)))/(INDEX(Stage_Storage!$A$11:$A$18,MATCH(A15,Stage_Storage!$A$11:$A$18,1)+1)-INDEX(Stage_Storage!$A$11:$A$18,MATCH(A15,Stage_Storage!$A$11:$A$18,1)))*(INDEX(Stage_Storage!$E$11:$E$18,MATCH(A15,Stage_Storage!$A$11:$A$18,1)+1)-INDEX(Stage_Storage!$E$11:$E$18,MATCH(A15,Stage_Storage!$A$11:$A$18,1))))) | G15: =E15+F15 | H15: =IF(B15<=0,0,IF(B15>=INDEX(Courbe_QH_1200!$A$20:$A$80,ROWS(Courbe_QH_1200!$A$20:$A$80)),INDEX(Courbe_QH_1200!$E$20:$E$80,ROWS(Courbe_QH_1200!$E$20:$E$80)),INDEX(Courbe_QH_1200!$E$20:$E$80,MATCH(B15,Courbe_QH_1200!$A$20:$A$80,1))+(B15-INDEX(Courbe_QH_1200!$A$20:$A$80,MATCH(B15,Courbe_QH_1200!$A$20:$A$80,1)))/(INDEX(Courbe_QH_1200!$A$20:$A$80,MATCH(B15,Courbe_QH_1200!$A$20:$A$80,1)+1)-INDEX(Courbe_QH_1200!$A$20:$A$80,MATCH(B15,Courbe_QH_1200!$A$20:$A$80,1)))*(INDEX(Courbe_QH_1200!$E$20:$E$80,MATCH(B15,Courbe_QH_1200!$A$20:$A$80,1)+1)-INDEX(Courbe_QH_1200!$E$20:$E$80,MATCH(B15,Courbe_QH_1200!$A$20:$A$80,1))))) | I15: =IF(C15<=0,0,IF($B$6<=0,0,(1/$B$6)*D15*IF(($B$5+2*C15*SQRT(1+$B$7^2))<=0,0,((D15/($B$5+2*C15*SQRT(1+$B$7^2)))^(2/3)))*SQRT($B$8))) | J15: =H15+I15
A16: 35.18 | B16: =A16-$B$10 | C16: =MAX(0,A16-$B$4) | D16: =IF(C16<=0,0,($B$5+$B$7*C16)*C16) | E16: =D16*$B$9 | F16: =IF(A16<=INDEX(Stage_Storage!$A$11:$A$18,1),INDEX(Stage_Storage!$E$11:$E$18,1),IF(A16>=INDEX(Stage_Storage!$A$11:$A$18,ROWS(Stage_Storage!$A$11:$A$18)),INDEX(Stage_Storage!$E$11:$E$18,ROWS(Stage_Storage!$E$11:$E$18)),INDEX(Stage_Storage!$E$11:$E$18,MATCH(A16,Stage_Storage!$A$11:$A$18,1))+(A16-INDEX(Stage_Storage!$A$11:$A$18,MATCH(A16,Stage_Storage!$A$11:$A$18,1)))/(INDEX(Stage_Storage!$A$11:$A$18,MATCH(A16,Stage_Storage!$A$11:$A$18,1)+1)-INDEX(Stage_Storage!$A$11:$A$18,MATCH(A16,Stage_Storage!$A$11:$A$18,1)))*(INDEX(Stage_Storage!$E$11:$E$18,MATCH(A16,Stage_Storage!$A$11:$A$18,1)+1)-INDEX(Stage_Storage!$E$11:$E$18,MATCH(A16,Stage_Storage!$A$11:$A$18,1))))) | G16: =E16+F16 | H16: =IF(B16<=0,0,IF(B16>=INDEX(Courbe_QH_1200!$A$20:$A$80,ROWS(Courbe_QH_1200!$A$20:$A$80)),INDEX(Courbe_QH_1200!$E$20:$E$80,ROWS(Courbe_QH_1200!$E$20:$E$80)),INDEX(Courbe_QH_1200!$E$20:$E$80,MATCH(B16,Courbe_QH_1200!$A$20:$A$80,1))+(B16-INDEX(Courbe_QH_1200!$A$20:$A$80,MATCH(B16,Courbe_QH_1200!$A$20:$A$80,1)))/(INDEX(Courbe_QH_1200!$A$20:$A$80,MATCH(B16,Courbe_QH_1200!$A$20:$A$80,1)+1)-INDEX(Courbe_QH_1200!$A$20:$A$80,MATCH(B16,Courbe_QH_1200!$A$20:$A$80,1)))*(INDEX(Courbe_QH_1200!$E$20:$E$80,MATCH(B16,Courbe_QH_1200!$A$20:$A$80,1)+1)-INDEX(Courbe_QH_1200!$E$20:$E$80,MATCH(B16,Courbe_QH_1200!$A$20:$A$80,1))))) | I16: =IF(C16<=0,0,IF($B$6<=0,0,(1/$B$6)*D16*IF(($B$5+2*C16*SQRT(1+$B$7^2))<=0,0,((D16/($B$5+2*C16*SQRT(1+$B$7^2)))^(2/3)))*SQRT($B$8))) | J16: =H16+I16
A17: 35.28 | B17: =A17-$B$10 | C17: =MAX(0,A17-$B$4) | D17: =IF(C17<=0,0,($B$5+$B$7*C17)*C17) | E17: =D17*$B$9 | F17: =IF(A17<=INDEX(Stage_Storage!$A$11:$A$18,1),INDEX(Stage_Storage!$E$11:$E$18,1),IF(A17>=INDEX(Stage_Storage!$A$11:$A$18,ROWS(Stage_Storage!$A$11:$A$18)),INDEX(Stage_Storage!$E$11:$E$18,ROWS(Stage_Storage!$E$11:$E$18)),INDEX(Stage_Storage!$E$11:$E$18,MATCH(A17,Stage_Storage!$A$11:$A$18,1))+(A17-INDEX(Stage_Storage!$A$11:$A$18,MATCH(A17,Stage_Storage!$A$11:$A$18,1)))/(INDEX(Stage_Storage!$A$11:$A$18,MATCH(A17,Stage_Storage!$A$11:$A$18,1)+1)-INDEX(Stage_Storage!$A$11:$A$18,MATCH(A17,Stage_Storage!$A$11:$A$18,1)))*(INDEX(Stage_Storage!$E$11:$E$18,MATCH(A17,Stage_Storage!$A$11:$A$18,1)+1)-INDEX(Stage_Storage!$E$11:$E$18,MATCH(A17,Stage_Storage!$A$11:$A$18,1))))) | G17: =E17+F17 | H17: =IF(B17<=0,0,IF(B17>=INDEX(Courbe_QH_1200!$A$20:$A$80,ROWS(Courbe_QH_1200!$A$20:$A$80)),INDEX(Courbe_QH_1200!$E$20:$E$80,ROWS(Courbe_QH_1200!$E$20:$E$80)),INDEX(Courbe_QH_1200!$E$20:$E$80,MATCH(B17,Courbe_QH_1200!$A$20:$A$80,1))+(B17-INDEX(Courbe_QH_1200!$A$20:$A$80,MATCH(B17,Courbe_QH_1200!$A$20:$A$80,1)))/(INDEX(Courbe_QH_1200!$A$20:$A$80,MATCH(B17,Courbe_QH_1200!$A$20:$A$80,1)+1)-INDEX(Courbe_QH_1200!$A$20:$A$80,MATCH(B17,Courbe_QH_1200!$A$20:$A$80,1)))*(INDEX(Courbe_QH_1200!$E$20:$E$80,MATCH(B17,Courbe_QH_1200!$A$20:$A$80,1)+1)-INDEX(Courbe_QH_1200!$E$20:$E$80,MATCH(B17,Courbe_QH_1200!$A$20:$A$80,1))))) | I17: =IF(C17<=0,0,IF($B$6<=0,0,(1/$B$6)*D17*IF(($B$5+2*C17*SQRT(1+$B$7^2))<=0,0,((D17/($B$5+2*C17*SQRT(1+$B$7^2)))^(2/3)))*SQRT($B$8))) | J17: =H17+I17
A18: 35.38 | B18: =A18-$B$10 | C18: =MAX(0,A18-$B$4) | D18: =IF(C18<=0,0,($B$5+$B$7*C18)*C18) | E18: =D18*$B$9 | F18: =IF(A18<=INDEX(Stage_Storage!$A$11:$A$18,1),INDEX(Stage_Storage!$E$11:$E$18,1),IF(A18>=INDEX(Stage_Storage!$A$11:$A$18,ROWS(Stage_Storage!$A$11:$A$18)),INDEX(Stage_Storage!$E$11:$E$18,ROWS(Stage_Storage!$E$11:$E$18)),INDEX(Stage_Storage!$E$11:$E$18,MATCH(A18,Stage_Storage!$A$11:$A$18,1))+(A18-INDEX(Stage_Storage!$A$11:$A$18,MATCH(A18,Stage_Storage!$A$11:$A$18,1)))/(INDEX(Stage_Storage!$A$11:$A$18,MATCH(A18,Stage_Storage!$A$11:$A$18,1)+1)-INDEX(Stage_Storage!$A$11:$A$18,MATCH(A18,Stage_Storage!$A$11:$A$18,1)))*(INDEX(Stage_Storage!$E$11:$E$18,MATCH(A18,Stage_Storage!$A$11:$A$18,1)+1)-INDEX(Stage_Storage!$E$11:$E$18,MATCH(A18,Stage_Storage!$A$11:$A$18,1))))) | G18: =E18+F18 | H18: =IF(B18<=0,0,IF(B18>=INDEX(Courbe_QH_1200!$A$20:$A$80,ROWS(Courbe_QH_1200!$A$20:$A$80)),INDEX(Courbe_QH_1200!$E$20:$E$80,ROWS(Courbe_QH_1200!$E$20:$E$80)),INDEX(Courbe_QH_1200!$E$20:$E$80,MATCH(B18,Courbe_QH_1200!$A$20:$A$80,1))+(B18-INDEX(Courbe_QH_1200!$A$20:$A$80,MATCH(B18,Courbe_QH_1200!$A$20:$A$80,1)))/(INDEX(Courbe_QH_1200!$A$20:$A$80,MATCH(B18,Courbe_QH_1200!$A$20:$A$80,1)+1)-INDEX(Courbe_QH_1200!$A$20:$A$80,MATCH(B18,Courbe_QH_1200!$A$20:$A$80,1)))*(INDEX(Courbe_QH_1200!$E$20:$E$80,MATCH(B18,Courbe_QH_1200!$A$20:$A$80,1)+1)-INDEX(Courbe_QH_1200!$E$20:$E$80,MATCH(B18,Courbe_QH_1200!$A$20:$A$80,1))))) | I18: =IF(C18<=0,0,IF($B$6<=0,0,(1/$B$6)*D18*IF(($B$5+2*C18*SQRT(1+$B$7^2))<=0,0,((D18/($B$5+2*C18*SQRT(1+$B$7^2)))^(2/3)))*SQRT($B$8))) | J18: =H18+I18
A19: 35.48 | B19: =A19-$B$10 | C19: =MAX(0,A19-$B$4) | D19: =IF(C19<=0,0,($B$5+$B$7*C19)*C19) | E19: =D19*$B$9 | F19: =IF(A19<=INDEX(Stage_Storage!$A$11:$A$18,1),INDEX(Stage_Storage!$E$11:$E$18,1),IF(A19>=INDEX(Stage_Storage!$A$11:$A$18,ROWS(Stage_Storage!$A$11:$A$18)),INDEX(Stage_Storage!$E$11:$E$18,ROWS(Stage_Storage!$E$11:$E$18)),INDEX(Stage_Storage!$E$11:$E$18,MATCH(A19,Stage_Storage!$A$11:$A$18,1))+(A19-INDEX(Stage_Storage!$A$11:$A$18,MATCH(A19,Stage_Storage!$A$11:$A$18,1)))/(INDEX(Stage_Storage!$A$11:$A$18,MATCH(A19,Stage_Storage!$A$11:$A$18,1)+1)-INDEX(Stage_Storage!$A$11:$A$18,MATCH(A19,Stage_Storage!$A$11:$A$18,1)))*(INDEX(Stage_Storage!$E$11:$E$18,MATCH(A19,Stage_Storage!$A$11:$A$18,1)+1)-INDEX(Stage_Storage!$E$11:$E$18,MATCH(A19,Stage_Storage!$A$11:$A$18,1))))) | G19: =E19+F19 | H19: =IF(B19<=0,0,IF(B19>=INDEX(Courbe_QH_1200!$A$20:$A$80,ROWS(Courbe_QH_1200!$A$20:$A$80)),INDEX(Courbe_QH_1200!$E$20:$E$80,ROWS(Courbe_QH_1200!$E$20:$E$80)),INDEX(Courbe_QH_1200!$E$20:$E$80,MATCH(B19,Courbe_QH_1200!$A$20:$A$80,1))+(B19-INDEX(Courbe_QH_1200!$A$20:$A$80,MATCH(B19,Courbe_QH_1200!$A$20:$A$80,1)))/(INDEX(Courbe_QH_1200!$A$20:$A$80,MATCH(B19,Courbe_QH_1200!$A$20:$A$80,1)+1)-INDEX(Courbe_QH_1200!$A$20:$A$80,MATCH(B19,Courbe_QH_1200!$A$20:$A$80,1)))*(INDEX(Courbe_QH_1200!$E$20:$E$80,MATCH(B19,Courbe_QH_1200!$A$20:$A$80,1)+1)-INDEX(Courbe_QH_1200!$E$20:$E$80,MATCH(B19,Courbe_QH_1200!$A$20:$A$80,1))))) | I19: =IF(C19<=0,0,IF($B$6<=0,0,(1/$B$6)*D19*IF(($B$5+2*C19*SQRT(1+$B$7^2))<=0,0,((D19/($B$5+2*C19*SQRT(1+$B$7^2)))^(2/3)))*SQRT($B$8))) | J19: =H19+I19
A20: 35.58 | B20: =A20-$B$10 | C20: =MAX(0,A20-$B$4) | D20: =IF(C20<=0,0,($B$5+$B$7*C20)*C20) | E20: =D20*$B$9 | F20: =IF(A20<=INDEX(Stage_Storage!$A$11:$A$18,1),INDEX(Stage_Storage!$E$11:$E$18,1),IF(A20>=INDEX(Stage_Storage!$A$11:$A$18,ROWS(Stage_Storage!$A$11:$A$18)),INDEX(Stage_Storage!$E$11:$E$18,ROWS(Stage_Storage!$E$11:$E$18)),INDEX(Stage_Storage!$E$11:$E$18,MATCH(A20,Stage_Storage!$A$11:$A$18,1))+(A20-INDEX(Stage_Storage!$A$11:$A$18,MATCH(A20,Stage_Storage!$A$11:$A$18,1)))/(INDEX(Stage_Storage!$A$11:$A$18,MATCH(A20,Stage_Storage!$A$11:$A$18,1)+1)-INDEX(Stage_Storage!$A$11:$A$18,MATCH(A20,Stage_Storage!$A$11:$A$18,1)))*(INDEX(Stage_Storage!$E$11:$E$18,MATCH(A20,Stage_Storage!$A$11:$A$18,1)+1)-INDEX(Stage_Storage!$E$11:$E$18,MATCH(A20,Stage_Storage!$A$11:$A$18,1))))) | G20: =E20+F20 | H20: =IF(B20<=0,0,IF(B20>=INDEX(Courbe_QH_1200!$A$20:$A$80,ROWS(Courbe_QH_1200!$A$20:$A$80)),INDEX(Courbe_QH_1200!$E$20:$E$80,ROWS(Courbe_QH_1200!$E$20:$E$80)),INDEX(Courbe_QH_1200!$E$20:$E$80,MATCH(B20,Courbe_QH_1200!$A$20:$A$80,1))+(B20-INDEX(Courbe_QH_1200!$A$20:$A$80,MATCH(B20,Courbe_QH_1200!$A$20:$A$80,1)))/(INDEX(Courbe_QH_1200!$A$20:$A$80,MATCH(B20,Courbe_QH_1200!$A$20:$A$80,1)+1)-INDEX(Courbe_QH_1200!$A$20:$A$80,MATCH(B20,Courbe_QH_1200!$A$20:$A$80,1)))*(INDEX(Courbe_QH_1200!$E$20:$E$80,MATCH(B20,Courbe_QH_1200!$A$20:$A$80,1)+1)-INDEX(Courbe_QH_1200!$E$20:$E$80,MATCH(B20,Courbe_QH_1200!$A$20:$A$80,1))))) | I20: =IF(C20<=0,0,IF($B$6<=0,0,(1/$B$6)*D20*IF(($B$5+2*C20*SQRT(1+$B$7^2))<=0,0,((D20/($B$5+2*C20*SQRT(1+$B$7^2)))^(2/3)))*SQRT($B$8))) | J20: =H20+I20
A21: 35.68 | B21: =A21-$B$10 | C21: =MAX(0,A21-$B$4) | D21: =IF(C21<=0,0,($B$5+$B$7*C21)*C21) | E21: =D21*$B$9 | F21: =IF(A21<=INDEX(Stage_Storage!$A$11:$A$18,1),INDEX(Stage_Storage!$E$11:$E$18,1),IF(A21>=INDEX(Stage_Storage!$A$11:$A$18,ROWS(Stage_Storage!$A$11:$A$18)),INDEX(Stage_Storage!$E$11:$E$18,ROWS(Stage_Storage!$E$11:$E$18)),INDEX(Stage_Storage!$E$11:$E$18,MATCH(A21,Stage_Storage!$A$11:$A$18,1))+(A21-INDEX(Stage_Storage!$A$11:$A$18,MATCH(A21,Stage_Storage!$A$11:$A$18,1)))/(INDEX(Stage_Storage!$A$11:$A$18,MATCH(A21,Stage_Storage!$A$11:$A$18,1)+1)-INDEX(Stage_Storage!$A$11:$A$18,MATCH(A21,Stage_Storage!$A$11:$A$18,1)))*(INDEX(Stage_Storage!$E$11:$E$18,MATCH(A21,Stage_Storage!$A$11:$A$18,1)+1)-INDEX(Stage_Storage!$E$11:$E$18,MATCH(A21,Stage_Storage!$A$11:$A$18,1))))) | G21: =E21+F21 | H21: =IF(B21<=0,0,IF(B21>=INDEX(Courbe_QH_1200!$A$20:$A$80,ROWS(Courbe_QH_1200!$A$20:$A$80)),INDEX(Courbe_QH_1200!$E$20:$E$80,ROWS(Courbe_QH_1200!$E$20:$E$80)),INDEX(Courbe_QH_1200!$E$20:$E$80,MATCH(B21,Courbe_QH_1200!$A$20:$A$80,1))+(B21-INDEX(Courbe_QH_1200!$A$20:$A$80,MATCH(B21,Courbe_QH_1200!$A$20:$A$80,1)))/(INDEX(Courbe_QH_1200!$A$20:$A$80,MATCH(B21,Courbe_QH_1200!$A$20:$A$80,1)+1)-INDEX(Courbe_QH_1200!$A$20:$A$80,MATCH(B21,Courbe_QH_1200!$A$20:$A$80,1)))*(INDEX(Courbe_QH_1200!$E$20:$E$80,MATCH(B21,Courbe_QH_1200!$A$20:$A$80,1)+1)-INDEX(Courbe_QH_1200!$E$20:$E$80,MATCH(B21,Courbe_QH_1200!$A$20:$A$80,1))))) | I21: =IF(C21<=0,0,IF($B$6<=0,0,(1/$B$6)*D21*IF(($B$5+2*C21*SQRT(1+$B$7^2))<=0,0,((D21/($B$5+2*C21*SQRT(1+$B$7^2)))^(2/3)))*SQRT($B$8))) | J21: =H21+I21
A22: 35.78 | B22: =A22-$B$10 | C22: =MAX(0,A22-$B$4) | D22: =IF(C22<=0,0,($B$5+$B$7*C22)*C22) | E22: =D22*$B$9 | F22: =IF(A22<=INDEX(Stage_Storage!$A$11:$A$18,1),INDEX(Stage_Storage!$E$11:$E$18,1),IF(A22>=INDEX(Stage_Storage!$A$11:$A$18,ROWS(Stage_Storage!$A$11:$A$18)),INDEX(Stage_Storage!$E$11:$E$18,ROWS(Stage_Storage!$E$11:$E$18)),INDEX(Stage_Storage!$E$11:$E$18,MATCH(A22,Stage_Storage!$A$11:$A$18,1))+(A22-INDEX(Stage_Storage!$A$11:$A$18,MATCH(A22,Stage_Storage!$A$11:$A$18,1)))/(INDEX(Stage_Storage!$A$11:$A$18,MATCH(A22,Stage_Storage!$A$11:$A$18,1)+1)-INDEX(Stage_Storage!$A$11:$A$18,MATCH(A22,Stage_Storage!$A$11:$A$18,1)))*(INDEX(Stage_Storage!$E$11:$E$18,MATCH(A22,Stage_Storage!$A$11:$A$18,1)+1)-INDEX(Stage_Storage!$E$11:$E$18,MATCH(A22,Stage_Storage!$A$11:$A$18,1))))) | G22: =E22+F22 | H22: =IF(B22<=0,0,IF(B22>=INDEX(Courbe_QH_1200!$A$20:$A$80,ROWS(Courbe_QH_1200!$A$20:$A$80)),INDEX(Courbe_QH_1200!$E$20:$E$80,ROWS(Courbe_QH_1200!$E$20:$E$80)),INDEX(Courbe_QH_1200!$E$20:$E$80,MATCH(B22,Courbe_QH_1200!$A$20:$A$80,1))+(B22-INDEX(Courbe_QH_1200!$A$20:$A$80,MATCH(B22,Courbe_QH_1200!$A$20:$A$80,1)))/(INDEX(Courbe_QH_1200!$A$20:$A$80,MATCH(B22,Courbe_QH_1200!$A$20:$A$80,1)+1)-INDEX(Courbe_QH_1200!$A$20:$A$80,MATCH(B22,Courbe_QH_1200!$A$20:$A$80,1)))*(INDEX(Courbe_QH_1200!$E$20:$E$80,MATCH(B22,Courbe_QH_1200!$A$20:$A$80,1)+1)-INDEX(Courbe_QH_1200!$E$20:$E$80,MATCH(B22,Courbe_QH_1200!$A$20:$A$80,1))))) | I22: =IF(C22<=0,0,IF($B$6<=0,0,(1/$B$6)*D22*IF(($B$5+2*C22*SQRT(1+$B$7^2))<=0,0,((D22/($B$5+2*C22*SQRT(1+$B$7^2)))^(2/3)))*SQRT($B$8))) | J22: =H22+I22
A23: 35.88 | B23: =A23-$B$10 | C23: =MAX(0,A23-$B$4) | D23: =IF(C23<=0,0,($B$5+$B$7*C23)*C23) | E23: =D23*$B$9 | F23: =IF(A23<=INDEX(Stage_Storage!$A$11:$A$18,1),INDEX(Stage_Storage!$E$11:$E$18,1),IF(A23>=INDEX(Stage_Storage!$A$11:$A$18,ROWS(Stage_Storage!$A$11:$A$18)),INDEX(Stage_Storage!$E$11:$E$18,ROWS(Stage_Storage!$E$11:$E$18)),INDEX(Stage_Storage!$E$11:$E$18,MATCH(A23,Stage_Storage!$A$11:$A$18,1))+(A23-INDEX(Stage_Storage!$A$11:$A$18,MATCH(A23,Stage_Storage!$A$11:$A$18,1)))/(INDEX(Stage_Storage!$A$11:$A$18,MATCH(A23,Stage_Storage!$A$11:$A$18,1)+1)-INDEX(Stage_Storage!$A$11:$A$18,MATCH(A23,Stage_Storage!$A$11:$A$18,1)))*(INDEX(Stage_Storage!$E$11:$E$18,MATCH(A23,Stage_Storage!$A$11:$A$18,1)+1)-INDEX(Stage_Storage!$E$11:$E$18,MATCH(A23,Stage_Storage!$A$11:$A$18,1))))) | G23: =E23+F23 | H23: =IF(B23<=0,0,IF(B23>=INDEX(Courbe_QH_1200!$A$20:$A$80,ROWS(Courbe_QH_1200!$A$20:$A$80)),INDEX(Courbe_QH_1200!$E$20:$E$80,ROWS(Courbe_QH_1200!$E$20:$E$80)),INDEX(Courbe_QH_1200!$E$20:$E$80,MATCH(B23,Courbe_QH_1200!$A$20:$A$80,1))+(B23-INDEX(Courbe_QH_1200!$A$20:$A$80,MATCH(B23,Courbe_QH_1200!$A$20:$A$80,1)))/(INDEX(Courbe_QH_1200!$A$20:$A$80,MATCH(B23,Courbe_QH_1200!$A$20:$A$80,1)+1)-INDEX(Courbe_QH_1200!$A$20:$A$80,MATCH(B23,Courbe_QH_1200!$A$20:$A$80,1)))*(INDEX(Courbe_QH_1200!$E$20:$E$80,MATCH(B23,Courbe_QH_1200!$A$20:$A$80,1)+1)-INDEX(Courbe_QH_1200!$E$20:$E$80,MATCH(B23,Courbe_QH_1200!$A$20:$A$80,1))))) | I23: =IF(C23<=0,0,IF($B$6<=0,0,(1/$B$6)*D23*IF(($B$5+2*C23*SQRT(1+$B$7^2))<=0,0,((D23/($B$5+2*C23*SQRT(1+$B$7^2)))^(2/3)))*SQRT($B$8))) | J23: =H23+I23
A24: 35.98 | B24: =A24-$B$10 | C24: =MAX(0,A24-$B$4) | D24: =IF(C24<=0,0,($B$5+$B$7*C24)*C24) | E24: =D24*$B$9 | F24: =IF(A24<=INDEX(Stage_Storage!$A$11:$A$18,1),INDEX(Stage_Storage!$E$11:$E$18,1),IF(A24>=INDEX(Stage_Storage!$A$11:$A$18,ROWS(Stage_Storage!$A$11:$A$18)),INDEX(Stage_Storage!$E$11:$E$18,ROWS(Stage_Storage!$E$11:$E$18)),INDEX(Stage_Storage!$E$11:$E$18,MATCH(A24,Stage_Storage!$A$11:$A$18,1))+(A24-INDEX(Stage_Storage!$A$11:$A$18,MATCH(A24,Stage_Storage!$A$11:$A$18,1)))/(INDEX(Stage_Storage!$A$11:$A$18,MATCH(A24,Stage_Storage!$A$11:$A$18,1)+1)-INDEX(Stage_Storage!$A$11:$A$18,MATCH(A24,Stage_Storage!$A$11:$A$18,1)))*(INDEX(Stage_Storage!$E$11:$E$18,MATCH(A24,Stage_Storage!$A$11:$A$18,1)+1)-INDEX(Stage_Storage!$E$11:$E$18,MATCH(A24,Stage_Storage!$A$11:$A$18,1))))) | G24: =E24+F24 | H24: =IF(B24<=0,0,IF(B24>=INDEX(Courbe_QH_1200!$A$20:$A$80,ROWS(Courbe_QH_1200!$A$20:$A$80)),INDEX(Courbe_QH_1200!$E$20:$E$80,ROWS(Courbe_QH_1200!$E$20:$E$80)),INDEX(Courbe_QH_1200!$E$20:$E$80,MATCH(B24,Courbe_QH_1200!$A$20:$A$80,1))+(B24-INDEX(Courbe_QH_1200!$A$20:$A$80,MATCH(B24,Courbe_QH_1200!$A$20:$A$80,1)))/(INDEX(Courbe_QH_1200!$A$20:$A$80,MATCH(B24,Courbe_QH_1200!$A$20:$A$80,1)+1)-INDEX(Courbe_QH_1200!$A$20:$A$80,MATCH(B24,Courbe_QH_1200!$A$20:$A$80,1)))*(INDEX(Courbe_QH_1200!$E$20:$E$80,MATCH(B24,Courbe_QH_1200!$A$20:$A$80,1)+1)-INDEX(Courbe_QH_1200!$E$20:$E$80,MATCH(B24,Courbe_QH_1200!$A$20:$A$80,1))))) | I24: =IF(C24<=0,0,IF($B$6<=0,0,(1/$B$6)*D24*IF(($B$5+2*C24*SQRT(1+$B$7^2))<=0,0,((D24/($B$5+2*C24*SQRT(1+$B$7^2)))^(2/3)))*SQRT($B$8))) | J24: =H24+I24
... A64: 39.98 | B64: =A64-$B$10 | C64: =MAX(0,A64-$B$4) | D64: =IF(C64<=0,0,($B$5+$B$7*C64)*C64) | E64: =D64*$B$9 | F64: =IF(A64<=INDEX(Stage_Storage!$A$11:$A$18,1),INDEX(Stage_Storage!$E$11:$E$18,1),IF(A64>=INDEX(Stage_Storage!$A$11:$A$18,ROWS(Stage_Storage!$A$11:$A$18)),INDEX(Stage_Storage!$E$11:$E$18,ROWS(Stage_Storage!$E$11:$E$18)),INDEX(Stage_Storage!$E$11:$E$18,MATCH(A64,Stage_Storage!$A$11:$A$18,1))+(A64-INDEX(Stage_Storage!$A$11:$A$18,MATCH(A64,Stage_Storage!$A$11:$A$18,1)))/(INDEX(Stage_Storage!$A$11:$A$18,MATCH(A64,Stage_Storage!$A$11:$A$18,1)+1)-INDEX(Stage_Storage!$A$11:$A$18,MATCH(A64,Stage_Storage!$A$11:$A$18,1)))*(INDEX(Stage_Storage!$E$11:$E$18,MATCH(A64,Stage_Storage!$A$11:$A$18,1)+1)-INDEX(Stage_Storage!$E$11:$E$18,MATCH(A64,Stage_Storage!$A$11:$A$18,1))))) | G64: =E64+F64 | H64: =IF(B64<=0,0,IF(B64>=INDEX(Courbe_QH_1200!$A$20:$A$80,ROWS(Courbe_QH_1200!$A$20:$A$80)),INDEX(Courbe_QH_1200!$E$20:$E$80,ROWS(Courbe_QH_1200!$E$20:$E$80)),INDEX(Courbe_QH_1200!$E$20:$E$80,MATCH(B64,Courbe_QH_1200!$A$20:$A$80,1))+(B64-INDEX(Courbe_QH_1200!$A$20:$A$80,MATCH(B64,Courbe_QH_1200!$A$20:$A$80,1)))/(INDEX(Courbe_QH_1200!$A$20:$A$80,MATCH(B64,Courbe_QH_1200!$A$20:$A$80,1)+1)-INDEX(Courbe_QH_1200!$A$20:$A$80,MATCH(B64,Courbe_QH_1200!$A$20:$A$80,1)))*(INDEX(Courbe_QH_1200!$E$20:$E$80,MATCH(B64,Courbe_QH_1200!$A$20:$A$80,1)+1)-INDEX(Courbe_QH_1200!$E$20:$E$80,MATCH(B64,Courbe_QH_1200!$A$20:$A$80,1))))) | I64: =IF(C64<=0,0,IF($B$6<=0,0,(1/$B$6)*D64*IF(($B$5+2*C64*SQRT(1+$B$7^2))<=0,0,((D64/($B$5+2*C64*SQRT(1+$B$7^2)))^(2/3)))*SQRT($B$8))) | J64: =H64+I64

Sheet Calcul_Composite
A1: FILE 1 — Routage composite (eau retenue amont Ø1200)
A2: A chaque pas: WSE depuis V_total (Compose); Qout = Q_1200 + Q_overflow; ΔV = (Qin_moy − Qout)×Δt.
A4: Q_plein ref | B4: =Parametres!B17
A5: Crest | B5: =Parametres!B21
A7: Vmax (m3) | B7: =MAX(F14:F26)
A8: WSEmax (m) | B8: =MAX(C14:C26)
A9: Q_down max (m3/s) | B9: =MAX(D14:D26)
A10: Q_1200 at Q_down max (m3/s) | B10: =IFERROR(INDEX(G14:G26,MATCH(B9,D14:D26,0)),0)
A11: Q_overflow at Q_down max (m3/s) | B11: =IFERROR(INDEX(H14:H26,MATCH(B9,D14:D26,0)),0)
A12: Overflow? | B12: =IF(B8>$B$5,"oui","non")
A13: t | B13: Qin | C13: WSE | D13: Qout | E13: dt | F13: V | G13: Q_1200 | H13: Q_overflow | I13: Overflow?
A14: =Hydrogramme!A7 | B14: =Hydrogramme!C7 | C14: =Parametres!B18 | D14: =MIN(B14,$B$4) | E14: 0 | F14: 0 | G14: 0 | H14: 0 | I14: non
A15: =Hydrogramme!A8 | B15: =Hydrogramme!C8 | C15: =IF(F14<=INDEX(Compose!$G$13:$G$64,1),INDEX(Compose!$A$13:$A$64,1),IF(F14>=INDEX(Compose!$G$13:$G$64,ROWS(Compose!$G$13:$G$64)),INDEX(Compose!$A$13:$A$64,ROWS(Compose!$A$13:$A$64)),INDEX(Compose!$A$13:$A$64,MATCH(F14,Compose!$G$13:$G$64,1))+(F14-INDEX(Compose!$G$13:$G$64,MATCH(F14,Compose!$G$13:$G$64,1)))/(INDEX(Compose!$G$13:$G$64,MATCH(F14,Compose!$G$13:$G$64,1)+1)-INDEX(Compose!$G$13:$G$64,MATCH(F14,Compose!$G$13:$G$64,1)))*(INDEX(Compose!$A$13:$A$64,MATCH(F14,Compose!$G$13:$G$64,1)+1)-INDEX(Compose!$A$13:$A$64,MATCH(F14,Compose!$G$13:$G$64,1))))) | D15: =IF(F14<=0.01,MIN(0.5*(B14+B15),$B$4),IF(C15<=INDEX(Compose!$A$13:$A$64,1),INDEX(Compose!$J$13:$J$64,1),IF(C15>=INDEX(Compose!$A$13:$A$64,ROWS(Compose!$A$13:$A$64)),INDEX(Compose!$J$13:$J$64,ROWS(Compose!$J$13:$J$64)),INDEX(Compose!$J$13:$J$64,MATCH(C15,Compose!$A$13:$A$64,1))+(C15-INDEX(Compose!$A$13:$A$64,MATCH(C15,Compose!$A$13:$A$64,1)))/(INDEX(Compose!$A$13:$A$64,MATCH(C15,Compose!$A$13:$A$64,1)+1)-INDEX(Compose!$A$13:$A$64,MATCH(C15,Compose!$A$13:$A$64,1)))*(INDEX(Compose!$J$13:$J$64,MATCH(C15,Compose!$A$13:$A$64,1)+1)-INDEX(Compose!$J$13:$J$64,MATCH(C15,Compose!$A$13:$A$64,1)))))) | E15: =(A15-A14)*60 | F15: =MAX(0,F14+(0.5*(B14+B15)-D15)*E15) | G15: =IF(C15<=INDEX(Compose!$A$13:$A$64,1),INDEX(Compose!$H$13:$H$64,1),IF(C15>=INDEX(Compose!$A$13:$A$64,ROWS(Compose!$A$13:$A$64)),INDEX(Compose!$H$13:$H$64,ROWS(Compose!$H$13:$H$64)),INDEX(Compose!$H$13:$H$64,MATCH(C15,Compose!$A$13:$A$64,1))+(C15-INDEX(Compose!$A$13:$A$64,MATCH(C15,Compose!$A$13:$A$64,1)))/(INDEX(Compose!$A$13:$A$64,MATCH(C15,Compose!$A$13:$A$64,1)+1)-INDEX(Compose!$A$13:$A$64,MATCH(C15,Compose!$A$13:$A$64,1)))*(INDEX(Compose!$H$13:$H$64,MATCH(C15,Compose!$A$13:$A$64,1)+1)-INDEX(Compose!$H$13:$H$64,MATCH(C15,Compose!$A$13:$A$64,1))))) | H15: =IF(C15<=INDEX(Compose!$A$13:$A$64,1),INDEX(Compose!$I$13:$I$64,1),IF(C15>=INDEX(Compose!$A$13:$A$64,ROWS(Compose!$A$13:$A$64)),INDEX(Compose!$I$13:$I$64,ROWS(Compose!$I$13:$I$64)),INDEX(Compose!$I$13:$I$64,MATCH(C15,Compose!$A$13:$A$64,1))+(C15-INDEX(Compose!$A$13:$A$64,MATCH(C15,Compose!$A$13:$A$64,1)))/(INDEX(Compose!$A$13:$A$64,MATCH(C15,Compose!$A$13:$A$64,1)+1)-INDEX(Compose!$A$13:$A$64,MATCH(C15,Compose!$A$13:$A$64,1)))*(INDEX(Compose!$I$13:$I$64,MATCH(C15,Compose!$A$13:$A$64,1)+1)-INDEX(Compose!$I$13:$I$64,MATCH(C15,Compose!$A$13:$A$64,1))))) | I15: =IF(C15>$B$5,"oui","non")
A16: =Hydrogramme!A9 | B16: =Hydrogramme!C9 | C16: =IF(F15<=INDEX(Compose!$G$13:$G$64,1),INDEX(Compose!$A$13:$A$64,1),IF(F15>=INDEX(Compose!$G$13:$G$64,ROWS(Compose!$G$13:$G$64)),INDEX(Compose!$A$13:$A$64,ROWS(Compose!$A$13:$A$64)),INDEX(Compose!$A$13:$A$64,MATCH(F15,Compose!$G$13:$G$64,1))+(F15-INDEX(Compose!$G$13:$G$64,MATCH(F15,Compose!$G$13:$G$64,1)))/(INDEX(Compose!$G$13:$G$64,MATCH(F15,Compose!$G$13:$G$64,1)+1)-INDEX(Compose!$G$13:$G$64,MATCH(F15,Compose!$G$13:$G$64,1)))*(INDEX(Compose!$A$13:$A$64,MATCH(F15,Compose!$G$13:$G$64,1)+1)-INDEX(Compose!$A$13:$A$64,MATCH(F15,Compose!$G$13:$G$64,1))))) | D16: =IF(F15<=0.01,MIN(0.5*(B15+B16),$B$4),IF(C16<=INDEX(Compose!$A$13:$A$64,1),INDEX(Compose!$J$13:$J$64,1),IF(C16>=INDEX(Compose!$A$13:$A$64,ROWS(Compose!$A$13:$A$64)),INDEX(Compose!$J$13:$J$64,ROWS(Compose!$J$13:$J$64)),INDEX(Compose!$J$13:$J$64,MATCH(C16,Compose!$A$13:$A$64,1))+(C16-INDEX(Compose!$A$13:$A$64,MATCH(C16,Compose!$A$13:$A$64,1)))/(INDEX(Compose!$A$13:$A$64,MATCH(C16,Compose!$A$13:$A$64,1)+1)-INDEX(Compose!$A$13:$A$64,MATCH(C16,Compose!$A$13:$A$64,1)))*(INDEX(Compose!$J$13:$J$64,MATCH(C16,Compose!$A$13:$A$64,1)+1)-INDEX(Compose!$J$13:$J$64,MATCH(C16,Compose!$A$13:$A$64,1)))))) | E16: =(A16-A15)*60 | F16: =MAX(0,F15+(0.5*(B15+B16)-D16)*E16) | G16: =IF(C16<=INDEX(Compose!$A$13:$A$64,1),INDEX(Compose!$H$13:$H$64,1),IF(C16>=INDEX(Compose!$A$13:$A$64,ROWS(Compose!$A$13:$A$64)),INDEX(Compose!$H$13:$H$64,ROWS(Compose!$H$13:$H$64)),INDEX(Compose!$H$13:$H$64,MATCH(C16,Compose!$A$13:$A$64,1))+(C16-INDEX(Compose!$A$13:$A$64,MATCH(C16,Compose!$A$13:$A$64,1)))/(INDEX(Compose!$A$13:$A$64,MATCH(C16,Compose!$A$13:$A$64,1)+1)-INDEX(Compose!$A$13:$A$64,MATCH(C16,Compose!$A$13:$A$64,1)))*(INDEX(Compose!$H$13:$H$64,MATCH(C16,Compose!$A$13:$A$64,1)+1)-INDEX(Compose!$H$13:$H$64,MATCH(C16,Compose!$A$13:$A$64,1))))) | H16: =IF(C16<=INDEX(Compose!$A$13:$A$64,1),INDEX(Compose!$I$13:$I$64,1),IF(C16>=INDEX(Compose!$A$13:$A$64,ROWS(Compose!$A$13:$A$64)),INDEX(Compose!$I$13:$I$64,ROWS(Compose!$I$13:$I$64)),INDEX(Compose!$I$13:$I$64,MATCH(C16,Compose!$A$13:$A$64,1))+(C16-INDEX(Compose!$A$13:$A$64,MATCH(C16,Compose!$A$13:$A$64,1)))/(INDEX(Compose!$A$13:$A$64,MATCH(C16,Compose!$A$13:$A$64,1)+1)-INDEX(Compose!$A$13:$A$64,MATCH(C16,Compose!$A$13:$A$64,1)))*(INDEX(Compose!$I$13:$I$64,MATCH(C16,Compose!$A$13:$A$64,1)+1)-INDEX(Compose!$I$13:$I$64,MATCH(C16,Compose!$A$13:$A$64,1))))) | I16: =IF(C16>$B$5,"oui","non")
A17: =Hydrogramme!A10 | B17: =Hydrogramme!C10 | C17: =IF(F16<=INDEX(Compose!$G$13:$G$64,1),INDEX(Compose!$A$13:$A$64,1),IF(F16>=INDEX(Compose!$G$13:$G$64,ROWS(Compose!$G$13:$G$64)),INDEX(Compose!$A$13:$A$64,ROWS(Compose!$A$13:$A$64)),INDEX(Compose!$A$13:$A$64,MATCH(F16,Compose!$G$13:$G$64,1))+(F16-INDEX(Compose!$G$13:$G$64,MATCH(F16,Compose!$G$13:$G$64,1)))/(INDEX(Compose!$G$13:$G$64,MATCH(F16,Compose!$G$13:$G$64,1)+1)-INDEX(Compose!$G$13:$G$64,MATCH(F16,Compose!$G$13:$G$64,1)))*(INDEX(Compose!$A$13:$A$64,MATCH(F16,Compose!$G$13:$G$64,1)+1)-INDEX(Compose!$A$13:$A$64,MATCH(F16,Compose!$G$13:$G$64,1))))) | D17: =IF(F16<=0.01,MIN(0.5*(B16+B17),$B$4),IF(C17<=INDEX(Compose!$A$13:$A$64,1),INDEX(Compose!$J$13:$J$64,1),IF(C17>=INDEX(Compose!$A$13:$A$64,ROWS(Compose!$A$13:$A$64)),INDEX(Compose!$J$13:$J$64,ROWS(Compose!$J$13:$J$64)),INDEX(Compose!$J$13:$J$64,MATCH(C17,Compose!$A$13:$A$64,1))+(C17-INDEX(Compose!$A$13:$A$64,MATCH(C17,Compose!$A$13:$A$64,1)))/(INDEX(Compose!$A$13:$A$64,MATCH(C17,Compose!$A$13:$A$64,1)+1)-INDEX(Compose!$A$13:$A$64,MATCH(C17,Compose!$A$13:$A$64,1)))*(INDEX(Compose!$J$13:$J$64,MATCH(C17,Compose!$A$13:$A$64,1)+1)-INDEX(Compose!$J$13:$J$64,MATCH(C17,Compose!$A$13:$A$64,1)))))) | E17: =(A17-A16)*60 | F17: =MAX(0,F16+(0.5*(B16+B17)-D17)*E17) | G17: =IF(C17<=INDEX(Compose!$A$13:$A$64,1),INDEX(Compose!$H$13:$H$64,1),IF(C17>=INDEX(Compose!$A$13:$A$64,ROWS(Compose!$A$13:$A$64)),INDEX(Compose!$H$13:$H$64,ROWS(Compose!$H$13:$H$64)),INDEX(Compose!$H$13:$H$64,MATCH(C17,Compose!$A$13:$A$64,1))+(C17-INDEX(Compose!$A$13:$A$64,MATCH(C17,Compose!$A$13:$A$64,1)))/(INDEX(Compose!$A$13:$A$64,MATCH(C17,Compose!$A$13:$A$64,1)+1)-INDEX(Compose!$A$13:$A$64,MATCH(C17,Compose!$A$13:$A$64,1)))*(INDEX(Compose!$H$13:$H$64,MATCH(C17,Compose!$A$13:$A$64,1)+1)-INDEX(Compose!$H$13:$H$64,MATCH(C17,Compose!$A$13:$A$64,1))))) | H17: =IF(C17<=INDEX(Compose!$A$13:$A$64,1),INDEX(Compose!$I$13:$I$64,1),IF(C17>=INDEX(Compose!$A$13:$A$64,ROWS(Compose!$A$13:$A$64)),INDEX(Compose!$I$13:$I$64,ROWS(Compose!$I$13:$I$64)),INDEX(Compose!$I$13:$I$64,MATCH(C17,Compose!$A$13:$A$64,1))+(C17-INDEX(Compose!$A$13:$A$64,MATCH(C17,Compose!$A$13:$A$64,1)))/(INDEX(Compose!$A$13:$A$64,MATCH(C17,Compose!$A$13:$A$64,1)+1)-INDEX(Compose!$A$13:$A$64,MATCH(C17,Compose!$A$13:$A$64,1)))*(INDEX(Compose!$I$13:$I$64,MATCH(C17,Compose!$A$13:$A$64,1)+1)-INDEX(Compose!$I$13:$I$64,MATCH(C17,Compose!$A$13:$A$64,1))))) | I17: =IF(C17>$B$5,"oui","non")
A18: =Hydrogramme!A11 | B18: =Hydrogramme!C11 | C18: =IF(F17<=INDEX(Compose!$G$13:$G$64,1),INDEX(Compose!$A$13:$A$64,1),IF(F17>=INDEX(Compose!$G$13:$G$64,ROWS(Compose!$G$13:$G$64)),INDEX(Compose!$A$13:$A$64,ROWS(Compose!$A$13:$A$64)),INDEX(Compose!$A$13:$A$64,MATCH(F17,Compose!$G$13:$G$64,1))+(F17-INDEX(Compose!$G$13:$G$64,MATCH(F17,Compose!$G$13:$G$64,1)))/(INDEX(Compose!$G$13:$G$64,MATCH(F17,Compose!$G$13:$G$64,1)+1)-INDEX(Compose!$G$13:$G$64,MATCH(F17,Compose!$G$13:$G$64,1)))*(INDEX(Compose!$A$13:$A$64,MATCH(F17,Compose!$G$13:$G$64,1)+1)-INDEX(Compose!$A$13:$A$64,MATCH(F17,Compose!$G$13:$G$64,1))))) | D18: =IF(F17<=0.01,MIN(0.5*(B17+B18),$B$4),IF(C18<=INDEX(Compose!$A$13:$A$64,1),INDEX(Compose!$J$13:$J$64,1),IF(C18>=INDEX(Compose!$A$13:$A$64,ROWS(Compose!$A$13:$A$64)),INDEX(Compose!$J$13:$J$64,ROWS(Compose!$J$13:$J$64)),INDEX(Compose!$J$13:$J$64,MATCH(C18,Compose!$A$13:$A$64,1))+(C18-INDEX(Compose!$A$13:$A$64,MATCH(C18,Compose!$A$13:$A$64,1)))/(INDEX(Compose!$A$13:$A$64,MATCH(C18,Compose!$A$13:$A$64,1)+1)-INDEX(Compose!$A$13:$A$64,MATCH(C18,Compose!$A$13:$A$64,1)))*(INDEX(Compose!$J$13:$J$64,MATCH(C18,Compose!$A$13:$A$64,1)+1)-INDEX(Compose!$J$13:$J$64,MATCH(C18,Compose!$A$13:$A$64,1)))))) | E18: =(A18-A17)*60 | F18: =MAX(0,F17+(0.5*(B17+B18)-D18)*E18) | G18: =IF(C18<=INDEX(Compose!$A$13:$A$64,1),INDEX(Compose!$H$13:$H$64,1),IF(C18>=INDEX(Compose!$A$13:$A$64,ROWS(Compose!$A$13:$A$64)),INDEX(Compose!$H$13:$H$64,ROWS(Compose!$H$13:$H$64)),INDEX(Compose!$H$13:$H$64,MATCH(C18,Compose!$A$13:$A$64,1))+(C18-INDEX(Compose!$A$13:$A$64,MATCH(C18,Compose!$A$13:$A$64,1)))/(INDEX(Compose!$A$13:$A$64,MATCH(C18,Compose!$A$13:$A$64,1)+1)-INDEX(Compose!$A$13:$A$64,MATCH(C18,Compose!$A$13:$A$64,1)))*(INDEX(Compose!$H$13:$H$64,MATCH(C18,Compose!$A$13:$A$64,1)+1)-INDEX(Compose!$H$13:$H$64,MATCH(C18,Compose!$A$13:$A$64,1))))) | H18: =IF(C18<=INDEX(Compose!$A$13:$A$64,1),INDEX(Compose!$I$13:$I$64,1),IF(C18>=INDEX(Compose!$A$13:$A$64,ROWS(Compose!$A$13:$A$64)),INDEX(Compose!$I$13:$I$64,ROWS(Compose!$I$13:$I$64)),INDEX(Compose!$I$13:$I$64,MATCH(C18,Compose!$A$13:$A$64,1))+(C18-INDEX(Compose!$A$13:$A$64,MATCH(C18,Compose!$A$13:$A$64,1)))/(INDEX(Compose!$A$13:$A$64,MATCH(C18,Compose!$A$13:$A$64,1)+1)-INDEX(Compose!$A$13:$A$64,MATCH(C18,Compose!$A$13:$A$64,1)))*(INDEX(Compose!$I$13:$I$64,MATCH(C18,Compose!$A$13:$A$64,1)+1)-INDEX(Compose!$I$13:$I$64,MATCH(C18,Compose!$A$13:$A$64,1))))) | I18: =IF(C18>$B$5,"oui","non")
A19: =Hydrogramme!A12 | B19: =Hydrogramme!C12 | C19: =IF(F18<=INDEX(Compose!$G$13:$G$64,1),INDEX(Compose!$A$13:$A$64,1),IF(F18>=INDEX(Compose!$G$13:$G$64,ROWS(Compose!$G$13:$G$64)),INDEX(Compose!$A$13:$A$64,ROWS(Compose!$A$13:$A$64)),INDEX(Compose!$A$13:$A$64,MATCH(F18,Compose!$G$13:$G$64,1))+(F18-INDEX(Compose!$G$13:$G$64,MATCH(F18,Compose!$G$13:$G$64,1)))/(INDEX(Compose!$G$13:$G$64,MATCH(F18,Compose!$G$13:$G$64,1)+1)-INDEX(Compose!$G$13:$G$64,MATCH(F18,Compose!$G$13:$G$64,1)))*(INDEX(Compose!$A$13:$A$64,MATCH(F18,Compose!$G$13:$G$64,1)+1)-INDEX(Compose!$A$13:$A$64,MATCH(F18,Compose!$G$13:$G$64,1))))) | D19: =IF(F18<=0.01,MIN(0.5*(B18+B19),$B$4),IF(C19<=INDEX(Compose!$A$13:$A$64,1),INDEX(Compose!$J$13:$J$64,1),IF(C19>=INDEX(Compose!$A$13:$A$64,ROWS(Compose!$A$13:$A$64)),INDEX(Compose!$J$13:$J$64,ROWS(Compose!$J$13:$J$64)),INDEX(Compose!$J$13:$J$64,MATCH(C19,Compose!$A$13:$A$64,1))+(C19-INDEX(Compose!$A$13:$A$64,MATCH(C19,Compose!$A$13:$A$64,1)))/(INDEX(Compose!$A$13:$A$64,MATCH(C19,Compose!$A$13:$A$64,1)+1)-INDEX(Compose!$A$13:$A$64,MATCH(C19,Compose!$A$13:$A$64,1)))*(INDEX(Compose!$J$13:$J$64,MATCH(C19,Compose!$A$13:$A$64,1)+1)-INDEX(Compose!$J$13:$J$64,MATCH(C19,Compose!$A$13:$A$64,1)))))) | E19: =(A19-A18)*60 | F19: =MAX(0,F18+(0.5*(B18+B19)-D19)*E19) | G19: =IF(C19<=INDEX(Compose!$A$13:$A$64,1),INDEX(Compose!$H$13:$H$64,1),IF(C19>=INDEX(Compose!$A$13:$A$64,ROWS(Compose!$A$13:$A$64)),INDEX(Compose!$H$13:$H$64,ROWS(Compose!$H$13:$H$64)),INDEX(Compose!$H$13:$H$64,MATCH(C19,Compose!$A$13:$A$64,1))+(C19-INDEX(Compose!$A$13:$A$64,MATCH(C19,Compose!$A$13:$A$64,1)))/(INDEX(Compose!$A$13:$A$64,MATCH(C19,Compose!$A$13:$A$64,1)+1)-INDEX(Compose!$A$13:$A$64,MATCH(C19,Compose!$A$13:$A$64,1)))*(INDEX(Compose!$H$13:$H$64,MATCH(C19,Compose!$A$13:$A$64,1)+1)-INDEX(Compose!$H$13:$H$64,MATCH(C19,Compose!$A$13:$A$64,1))))) | H19: =IF(C19<=INDEX(Compose!$A$13:$A$64,1),INDEX(Compose!$I$13:$I$64,1),IF(C19>=INDEX(Compose!$A$13:$A$64,ROWS(Compose!$A$13:$A$64)),INDEX(Compose!$I$13:$I$64,ROWS(Compose!$I$13:$I$64)),INDEX(Compose!$I$13:$I$64,MATCH(C19,Compose!$A$13:$A$64,1))+(C19-INDEX(Compose!$A$13:$A$64,MATCH(C19,Compose!$A$13:$A$64,1)))/(INDEX(Compose!$A$13:$A$64,MATCH(C19,Compose!$A$13:$A$64,1)+1)-INDEX(Compose!$A$13:$A$64,MATCH(C19,Compose!$A$13:$A$64,1)))*(INDEX(Compose!$I$13:$I$64,MATCH(C19,Compose!$A$13:$A$64,1)+1)-INDEX(Compose!$I$13:$I$64,MATCH(C19,Compose!$A$13:$A$64,1))))) | I19: =IF(C19>$B$5,"oui","non")
A20: =Hydrogramme!A13 | B20: =Hydrogramme!C13 | C20: =IF(F19<=INDEX(Compose!$G$13:$G$64,1),INDEX(Compose!$A$13:$A$64,1),IF(F19>=INDEX(Compose!$G$13:$G$64,ROWS(Compose!$G$13:$G$64)),INDEX(Compose!$A$13:$A$64,ROWS(Compose!$A$13:$A$64)),INDEX(Compose!$A$13:$A$64,MATCH(F19,Compose!$G$13:$G$64,1))+(F19-INDEX(Compose!$G$13:$G$64,MATCH(F19,Compose!$G$13:$G$64,1)))/(INDEX(Compose!$G$13:$G$64,MATCH(F19,Compose!$G$13:$G$64,1)+1)-INDEX(Compose!$G$13:$G$64,MATCH(F19,Compose!$G$13:$G$64,1)))*(INDEX(Compose!$A$13:$A$64,MATCH(F19,Compose!$G$13:$G$64,1)+1)-INDEX(Compose!$A$13:$A$64,MATCH(F19,Compose!$G$13:$G$64,1))))) | D20: =IF(F19<=0.01,MIN(0.5*(B19+B20),$B$4),IF(C20<=INDEX(Compose!$A$13:$A$64,1),INDEX(Compose!$J$13:$J$64,1),IF(C20>=INDEX(Compose!$A$13:$A$64,ROWS(Compose!$A$13:$A$64)),INDEX(Compose!$J$13:$J$64,ROWS(Compose!$J$13:$J$64)),INDEX(Compose!$J$13:$J$64,MATCH(C20,Compose!$A$13:$A$64,1))+(C20-INDEX(Compose!$A$13:$A$64,MATCH(C20,Compose!$A$13:$A$64,1)))/(INDEX(Compose!$A$13:$A$64,MATCH(C20,Compose!$A$13:$A$64,1)+1)-INDEX(Compose!$A$13:$A$64,MATCH(C20,Compose!$A$13:$A$64,1)))*(INDEX(Compose!$J$13:$J$64,MATCH(C20,Compose!$A$13:$A$64,1)+1)-INDEX(Compose!$J$13:$J$64,MATCH(C20,Compose!$A$13:$A$64,1)))))) | E20: =(A20-A19)*60 | F20: =MAX(0,F19+(0.5*(B19+B20)-D20)*E20) | G20: =IF(C20<=INDEX(Compose!$A$13:$A$64,1),INDEX(Compose!$H$13:$H$64,1),IF(C20>=INDEX(Compose!$A$13:$A$64,ROWS(Compose!$A$13:$A$64)),INDEX(Compose!$H$13:$H$64,ROWS(Compose!$H$13:$H$64)),INDEX(Compose!$H$13:$H$64,MATCH(C20,Compose!$A$13:$A$64,1))+(C20-INDEX(Compose!$A$13:$A$64,MATCH(C20,Compose!$A$13:$A$64,1)))/(INDEX(Compose!$A$13:$A$64,MATCH(C20,Compose!$A$13:$A$64,1)+1)-INDEX(Compose!$A$13:$A$64,MATCH(C20,Compose!$A$13:$A$64,1)))*(INDEX(Compose!$H$13:$H$64,MATCH(C20,Compose!$A$13:$A$64,1)+1)-INDEX(Compose!$H$13:$H$64,MATCH(C20,Compose!$A$13:$A$64,1))))) | H20: =IF(C20<=INDEX(Compose!$A$13:$A$64,1),INDEX(Compose!$I$13:$I$64,1),IF(C20>=INDEX(Compose!$A$13:$A$64,ROWS(Compose!$A$13:$A$64)),INDEX(Compose!$I$13:$I$64,ROWS(Compose!$I$13:$I$64)),INDEX(Compose!$I$13:$I$64,MATCH(C20,Compose!$A$13:$A$64,1))+(C20-INDEX(Compose!$A$13:$A$64,MATCH(C20,Compose!$A$13:$A$64,1)))/(INDEX(Compose!$A$13:$A$64,MATCH(C20,Compose!$A$13:$A$64,1)+1)-INDEX(Compose!$A$13:$A$64,MATCH(C20,Compose!$A$13:$A$64,1)))*(INDEX(Compose!$I$13:$I$64,MATCH(C20,Compose!$A$13:$A$64,1)+1)-INDEX(Compose!$I$13:$I$64,MATCH(C20,Compose!$A$13:$A$64,1))))) | I20: =IF(C20>$B$5,"oui","non")
A21: =Hydrogramme!A14 | B21: =Hydrogramme!C14 | C21: =IF(F20<=INDEX(Compose!$G$13:$G$64,1),INDEX(Compose!$A$13:$A$64,1),IF(F20>=INDEX(Compose!$G$13:$G$64,ROWS(Compose!$G$13:$G$64)),INDEX(Compose!$A$13:$A$64,ROWS(Compose!$A$13:$A$64)),INDEX(Compose!$A$13:$A$64,MATCH(F20,Compose!$G$13:$G$64,1))+(F20-INDEX(Compose!$G$13:$G$64,MATCH(F20,Compose!$G$13:$G$64,1)))/(INDEX(Compose!$G$13:$G$64,MATCH(F20,Compose!$G$13:$G$64,1)+1)-INDEX(Compose!$G$13:$G$64,MATCH(F20,Compose!$G$13:$G$64,1)))*(INDEX(Compose!$A$13:$A$64,MATCH(F20,Compose!$G$13:$G$64,1)+1)-INDEX(Compose!$A$13:$A$64,MATCH(F20,Compose!$G$13:$G$64,1))))) | D21: =IF(F20<=0.01,MIN(0.5*(B20+B21),$B$4),IF(C21<=INDEX(Compose!$A$13:$A$64,1),INDEX(Compose!$J$13:$J$64,1),IF(C21>=INDEX(Compose!$A$13:$A$64,ROWS(Compose!$A$13:$A$64)),INDEX(Compose!$J$13:$J$64,ROWS(Compose!$J$13:$J$64)),INDEX(Compose!$J$13:$J$64,MATCH(C21,Compose!$A$13:$A$64,1))+(C21-INDEX(Compose!$A$13:$A$64,MATCH(C21,Compose!$A$13:$A$64,1)))/(INDEX(Compose!$A$13:$A$64,MATCH(C21,Compose!$A$13:$A$64,1)+1)-INDEX(Compose!$A$13:$A$64,MATCH(C21,Compose!$A$13:$A$64,1)))*(INDEX(Compose!$J$13:$J$64,MATCH(C21,Compose!$A$13:$A$64,1)+1)-INDEX(Compose!$J$13:$J$64,MATCH(C21,Compose!$A$13:$A$64,1)))))) | E21: =(A21-A20)*60 | F21: =MAX(0,F20+(0.5*(B20+B21)-D21)*E21) | G21: =IF(C21<=INDEX(Compose!$A$13:$A$64,1),INDEX(Compose!$H$13:$H$64,1),IF(C21>=INDEX(Compose!$A$13:$A$64,ROWS(Compose!$A$13:$A$64)),INDEX(Compose!$H$13:$H$64,ROWS(Compose!$H$13:$H$64)),INDEX(Compose!$H$13:$H$64,MATCH(C21,Compose!$A$13:$A$64,1))+(C21-INDEX(Compose!$A$13:$A$64,MATCH(C21,Compose!$A$13:$A$64,1)))/(INDEX(Compose!$A$13:$A$64,MATCH(C21,Compose!$A$13:$A$64,1)+1)-INDEX(Compose!$A$13:$A$64,MATCH(C21,Compose!$A$13:$A$64,1)))*(INDEX(Compose!$H$13:$H$64,MATCH(C21,Compose!$A$13:$A$64,1)+1)-INDEX(Compose!$H$13:$H$64,MATCH(C21,Compose!$A$13:$A$64,1))))) | H21: =IF(C21<=INDEX(Compose!$A$13:$A$64,1),INDEX(Compose!$I$13:$I$64,1),IF(C21>=INDEX(Compose!$A$13:$A$64,ROWS(Compose!$A$13:$A$64)),INDEX(Compose!$I$13:$I$64,ROWS(Compose!$I$13:$I$64)),INDEX(Compose!$I$13:$I$64,MATCH(C21,Compose!$A$13:$A$64,1))+(C21-INDEX(Compose!$A$13:$A$64,MATCH(C21,Compose!$A$13:$A$64,1)))/(INDEX(Compose!$A$13:$A$64,MATCH(C21,Compose!$A$13:$A$64,1)+1)-INDEX(Compose!$A$13:$A$64,MATCH(C21,Compose!$A$13:$A$64,1)))*(INDEX(Compose!$I$13:$I$64,MATCH(C21,Compose!$A$13:$A$64,1)+1)-INDEX(Compose!$I$13:$I$64,MATCH(C21,Compose!$A$13:$A$64,1))))) | I21: =IF(C21>$B$5,"oui","non")
