Workbook

Sheet Parametres
A1: Volume de rétention — ponceau Ø900 contrôlant
A3: Configuration (série)
A4: Ouvrage | B4: Rôle | C4: D (mm) | D4: Radier amont (m) | E4: Radier aval (m) | F4: Longueur (m) | G4: S0 (-) | H4: Q capacité donnée (m³/s)
A5: Ø1500 | B5: Entrée / amont | C5: 1500 | D5: 36.1 | E5: 35.05 | F5: 57 | G5: 0.018421053 | H5: 9.6
A6: Ø900 | B6: Contrôle sortie rétention | C6: 900 | D6: 34.88 | E6: 34.45 | F6: 50.65 | G6: 0.0084896347 | H6: 0.986
A7: Ø1200 | B7: Aval du Ø900 | C7: 1200 | D7: 33.6 | E7: 33.1 | F7: 31.3 | G7: 0.015974441 | H7: 4.93
A9: Chaîne: Ø1500 → zone de rétention → Ø900 (contrôle) → Ø1200 → exutoire. Le Ø1200 ne peut pas évacuer plus que ce que le Ø900 lui livre.
A12: Capacité Ø900 — Manning pleine section (TOG n = 0,022)
A13: n Manning (-) | B13: 0.022 | C13: TOG (tuyau ondulé galvanisé) n=0,022 — pas béton
A14: D (m) | B14: 0.9
A15: S0 = (Zamont-Zaval)/L | B15: =(D6-E6)/F6 | C15: Formule live depuis tableau géométrie Ø900
A16: A = πD²/4 (m²) | B16: =PI()*B14^2/4
A17: R = D/4 (m) | B17: =B14/4
A18: Q_plein = (1/n)·A·R^(2/3)·√S0 | B18: =(1/B13)*B16*(B17^(2/3))*SQRT(B15) | C18: m³/s — formule live (changez n ou géométrie → Q se met à jour)
A19: Q utilisé avant (m³/s) | B19: 1.77 | C19: Ancienne valeur bureau (~6% plus haute; même méthode)
A21: Entrées de calcul rétention (jaune)
A22: Qout_cap_900 (m³/s) | B22: =B18 | C22: Par défaut = Q_plein (B18). Écraser par 1.77 si besoin (ancien calcul).
A23: Facteur_securite (-) | B23: 1.2 | C23: Marge sur Vmax (ex. 1.20 = +20%)
A24: Aire_constante_B (m²) — PAS le levé | B24: 2500 | C24: Raccourci Méthode B seulement: H≈V/B24 pour lire Q=f(H). Ce n'est PAS un 2e bassin. Le vrai étang = feuille Stage_Storage (surfaces vs WSE).
A26: Débordement Méthode C — fossé trapèze au-dessus du crown (jaune)
A27: Crest = crown Ø900 (m) | B27: 35.78 | C27: 34.88+0.90 — overflow starts when WSE >= crest
A28: b fond fossé (m) | B28: 2
A29: n fossé Manning (-) | B29: 0.035
A30: z pente talus (H:V) | B30: 2 | C30: z=2 → 2H:1V
A31: S pente fossé (-) | B31: 0.0085 | C31: ≈0.0085 (corrigé; pente type lit Ø900 — pas 0.085)
A32: L fossé (m) | B32: 50.1 | C32: Longueur pour V_ditch = A × L et Manning
A33: Qout_C (débit sortie) | B33: Q_900(WSE) + Q_overflow(WSE) | C33: Débit = pipe + fossé (Compose_900). Ceci n'est PAS un volume.
A34: Stockage_C (volume) | B34: V_pond(levé) + V_ditch | C34: Volume = bassin (levé) + fossé — Compose_900 + Calcul_C
A35: Résultats Méthode A — Qout constant (feuille Calcul_A)
A36: Vmax_A (m³) | B36: =Calcul_A!B3 | C36: Volume max stocké avec Qout fixe (Parametres B22)
A37: V_dimensionnement_A = Vmax_A × facteur (m³) | B37: =B36*B23
A38: Hmax approx_A (m) = Vmax_A / Aire | B38: =IF(B24>0,B36/B24,0) | C38: Estimation grossière si l'aire de bassin est constante (pas le levé)
A39: WSEmax_A depuis levé (m) — feuille Stage_Storage | B39: =IF(B36<=Stage_Storage!E11,Stage_Storage!A11,IF(B36>=Stage_Storage!E18,"Hors table (>=40.0 m — étendre levé)",INDEX(Stage_Storage!$A$11:$A$18,MATCH(B36,Stage_Storage!$E$11:$E$18,1))+(B36-INDEX(Stage_Storage!$E$11:$E$18,MATCH(B36,Stage_Storage!$E$11:$E$18,1)))/(INDEX(Stage_Storage!$E$11:$E$18,MATCH(B36,Stage_Storage!$E$11:$E$18,1)+1)-INDEX(Stage_Storage!$E$11:$E$18,MATCH(B36,Stage_Storage!$E$11:$E$18,1)))*(INDEX(Stage_Storage!$A$11:$A$18,MATCH(B36,Stage_Storage!$E$11:$E$18,1)+1)-INDEX(Stage_Storage!$A$11:$A$18,MATCH(B36,Stage_Storage!$E$11:$E$18,1))))) | C39: Cote d'eau max pour le Vmax_A: on lit sur Stage_Storage quelle WSE donne ce volume (courbe volume–cote du levé)
A40: HW max_A = WSEmax_A − radier Ø900 (m) | B40: =IF(ISNUMBER(B39),B39-34.88,"") | C40: Comparer à 2.40 m (limite patron = +1.5 m au-dessus du crown)
A42: Résultats Méthode B — Qout = f(H) FHWA pipe seul (feuille Calcul_B)
A43: Vmax_B (m³) | B43: =Calcul_B!B7 | C43: Volume max stocké avec Q lu sur Courbe_QH_900 (dépend de Aire B24)
A44: V_dimensionnement_B = Vmax_B × facteur (m³) | B44: =B43*B23
A45: WSEmax_B depuis levé (m) — feuille Stage_Storage | B45: =IF(B43<=Stage_Storage!E11,Stage_Storage!A11,IF(B43>=Stage_Storage!E18,"Hors table (>=40.0 m — étendre levé)",INDEX(Stage_Storage!$A$11:$A$18,MATCH(B43,Stage_Storage!$E$11:$E$18,1))+(B43-INDEX(Stage_Storage!$E$11:$E$18,MATCH(B43,Stage_Storage!$E$11:$E$18,1)))/(INDEX(Stage_Storage!$E$11:$E$18,MATCH(B43,Stage_Storage!$E$11:$E$18,1)+1)-INDEX(Stage_Storage!$E$11:$E$18,MATCH(B43,Stage_Storage!$E$11:$E$18,1)))*(INDEX(Stage_Storage!$A$11:$A$18,MATCH(B43,Stage_Storage!$E$11:$E$18,1)+1)-INDEX(Stage_Storage!$A$11:$A$18,MATCH(B43,Stage_Storage!$E$11:$E$18,1))))) | C45: Même lecture volume→cote que B39, mais avec Vmax_B
A46: HW max_B = WSEmax_B − radier Ø900 (m) | B46: =IF(ISNUMBER(B45),B45-34.88,"") | C46: Comparer à 2.40 m (limite patron)
A48: Résultats Méthode C — Ø900 + fossé trapèze (Compose_900 + Calcul_C)
...

Sheet Hydrogramme
A1: Hydrogramme d'entrée (point Ø1500 / entrée rétention) — FORMULES LIVE
A2: Qin(t) = ratio(t) × Qpointe. Changez Qpointe (jaune B4) : toute la colonne Qin et Calcul_A/B/C se mettent à jour. Les ratios viennent de votre hydrogramme d'origine (pointe 9,6). À t=0, ratio≈0,081 → Qin=0,778 si Qpointe=9,6 (débit de départ du projet, pas zéro).
A4: Qpointe (m³/s) ← ÉDITER | B4: 9.6 | C4: Ex. 9.6 = pointe projet / capacité Ø1500
A5: t pointe (min) | B5: 22.5 | C5: Forme temporelle inchangée si vous changez seulement Qpointe
A7: t (min) | B7: ratio Q/Qp_ref | C7: Qin (m³/s) | D7: Remarque
A8: 0 | B8: 0.081042 | C8: =B8*$B$4 | D8: Départ: ≈0.081 × Qpointe (0.778 si Qp=9.6)
A9: 5 | B9: 0.121875 | C9: =B9*$B$4
A10: 10 | B10: 0.193438 | C10: =B10*$B$4
A11: 15 | B11: 0.333542 | C11: =B11*$B$4
A12: 20 | B12: 0.657188 | C12: =B12*$B$4
A13: 22.5 | B13: 1 | C13: =B13*$B$4 | D13: Pointe (ratio = 1)
A14: 27.5 | B14: 0.608958 | C14: =B14*$B$4
A15: 32.5 | B15: 0.401771 | C15: =B15*$B$4
A16: 37.5 | B16: 0.280104 | C16: =B16*$B$4
A17: 42.5 | B17: 0.203438 | C17: =B17*$B$4
A18: 47.5 | B18: 0.152292 | C18: =B18*$B$4
A19: 52.5 | B19: 0.116771 | C19: =B19*$B$4
A20: 57.5 | B20: 0.091146 | C20: =B20*$B$4
A22: Qin max (contrôle) | B22: =MAX(C8:C20) | C22: doit égaler Qpointe
A23: Qcap Ø900 (réf.) | B23: =Parametres!B22

Sheet Calcul_A
A1: Méthode A — Qout constant = capacité Ø900
A2: Qout (m³/s) | B2: =Parametres!B22
A3: Vmax (m³) | B3: =MAX(H8:H20) | C3: Maximum du volume stocké cumulé
A5: t début stockage approx (min) | B5: quand Qin dépasse Qout (dépend de Qpointe et Qcap)
A6: t fin accumulation nette (min) | B6: quand Qin redescend sous Qout
A7: t (min) | B7: Qin (m³/s) | C7: Qout (m³/s) | D7: Qin−Qout (m³/s) | E7: Δt (s) | F7: ΔVin (m³) | G7: ΔVout (m³) | H7: V stocké (m³) | I7: Stockage?
A8: =Hydrogramme!A8 | B8: =Hydrogramme!C8 | C8: =$B$2 | D8: =B8-C8 | E8: 0 | F8: 0 | G8: 0 | H8: 0 | I8: =IF(H8>0.5,"oui","non")
A9: =Hydrogramme!A9 | B9: =Hydrogramme!C9 | C9: =$B$2 | D9: =B9-C9 | E9: =(A9-A8)*60 | F9: =0.5*(B8+B9)*E9 | G9: =F9-(H9-H8) | H9: =MAX(0,H8+0.5*(D8+D9)*E9) | I9: =IF(H9>0.5,"oui","non")
A10: =Hydrogramme!A10 | B10: =Hydrogramme!C10 | C10: =$B$2 | D10: =B10-C10 | E10: =(A10-A9)*60 | F10: =0.5*(B9+B10)*E10 | G10: =F10-(H10-H9) | H10: =MAX(0,H9+0.5*(D9+D10)*E10) | I10: =IF(H10>0.5,"oui","non")
A11: =Hydrogramme!A11 | B11: =Hydrogramme!C11 | C11: =$B$2 | D11: =B11-C11 | E11: =(A11-A10)*60 | F11: =0.5*(B10+B11)*E11 | G11: =F11-(H11-H10) | H11: =MAX(0,H10+0.5*(D10+D11)*E11) | I11: =IF(H11>0.5,"oui","non")
A12: =Hydrogramme!A12 | B12: =Hydrogramme!C12 | C12: =$B$2 | D12: =B12-C12 | E12: =(A12-A11)*60 | F12: =0.5*(B11+B12)*E12 | G12: =F12-(H12-H11) | H12: =MAX(0,H11+0.5*(D11+D12)*E12) | I12: =IF(H12>0.5,"oui","non")
A13: =Hydrogramme!A13 | B13: =Hydrogramme!C13 | C13: =$B$2 | D13: =B13-C13 | E13: =(A13-A12)*60 | F13: =0.5*(B12+B13)*E13 | G13: =F13-(H13-H12) | H13: =MAX(0,H12+0.5*(D12+D13)*E13) | I13: =IF(H13>0.5,"oui","non")
A14: =Hydrogramme!A14 | B14: =Hydrogramme!C14 | C14: =$B$2 | D14: =B14-C14 | E14: =(A14-A13)*60 | F14: =0.5*(B13+B14)*E14 | G14: =F14-(H14-H13) | H14: =MAX(0,H13+0.5*(D13+D14)*E14) | I14: =IF(H14>0.5,"oui","non")
A15: =Hydrogramme!A15 | B15: =Hydrogramme!C15 | C15: =$B$2 | D15: =B15-C15 | E15: =(A15-A14)*60 | F15: =0.5*(B14+B15)*E15 | G15: =F15-(H15-H14) | H15: =MAX(0,H14+0.5*(D14+D15)*E15) | I15: =IF(H15>0.5,"oui","non")
A16: =Hydrogramme!A16 | B16: =Hydrogramme!C16 | C16: =$B$2 | D16: =B16-C16 | E16: =(A16-A15)*60 | F16: =0.5*(B15+B16)*E16 | G16: =F16-(H16-H15) | H16: =MAX(0,H15+0.5*(D15+D16)*E16) | I16: =IF(H16>0.5,"oui","non")
A17: =Hydrogramme!A17 | B17: =Hydrogramme!C17 | C17: =$B$2 | D17: =B17-C17 | E17: =(A17-A16)*60 | F17: =0.5*(B16+B17)*E17 | G17: =F17-(H17-H16) | H17: =MAX(0,H16+0.5*(D16+D17)*E17) | I17: =IF(H17>0.5,"oui","non")
A18: =Hydrogramme!A18 | B18: =Hydrogramme!C18 | C18: =$B$2 | D18: =B18-C18 | E18: =(A18-A17)*60 | F18: =0.5*(B17+B18)*E18 | G18: =F18-(H18-H17) | H18: =MAX(0,H17+0.5*(D17+D18)*E18) | I18: =IF(H18>0.5,"oui","non")
A19: =Hydrogramme!A19 | B19: =Hydrogramme!C19 | C19: =$B$2 | D19: =B19-C19 | E19: =(A19-A18)*60 | F19: =0.5*(B18+B19)*E19 | G19: =F19-(H19-H18) | H19: =MAX(0,H18+0.5*(D18+D19)*E19) | I19: =IF(H19>0.5,"oui","non")
A20: =Hydrogramme!A20 | B20: =Hydrogramme!C20 | C20: =$B$2 | D20: =B20-C20 | E20: =(A20-A19)*60 | F20: =0.5*(B19+B20)*E20 | G20: =F20-(H20-H19) | H20: =MAX(0,H19+0.5*(D19+D20)*E20) | I20: =IF(H20>0.5,"oui","non")

Sheet Courbe_QH_900
A1: Courbe de capacité Ø900 — Q = f(H) (FHWA HDS-5 inlet + outlet) — FORMULES LIVE
A2: Changez les cellules JAUNES (n, D, L, radiers, entrée, TW) : toute la table se recalcule. Q_gouvernant = MIN(Qinlet, Qoutlet) = debit retenu pour le design. Sur ce tuyau long, Q_gouvernant suit Qoutlet (courbe verte). Qinlet (rouge) est seulement la capacite d'entree — souvent plus haute.
A5: Paramètres Ø900 (jaune = éditable) | E5: Coeffs HDS-5 (table)
A6: n Manning (-) | B6: 0.022 | C6: TOG n=0,022 (ondulé galvanisé) | E6: entrée | F6: K | G6: M | H6: c | I6: Y | J6: Ke
A7: D (m) | B7: 0.9 | E7: square_edge | F7: 0.0098 | G7: 2 | H7: 0.0398 | I7: 0.67 | J7: 0.5
A8: L (m) | B8: 50.65 | E8: beveled | F8: 0.0018 | G8: 2.5 | H8: 0.03 | I8: 0.74 | J8: 0.2
A9: Radier amont Zin (m) | B9: 34.88 | E9: groove_headwall | F9: 0.0078 | G9: 2 | H9: 0.0292 | I9: 0.74 | J9: 0.2
A10: Radier aval Zout (m) | B10: 34.45
A11: S0 = (Zin-Zout)/L | B11: =(B9-B10)/B8 | C11: ASCII minus; LibreOffice FR: OK
A12: TW (m au-dessus Zout) | B12: 0 | C12: 0 = exutoire libre
A13: Entrée (texte exact) | B13: square_edge | C13: square_edge | beveled | groove_headwall
A15: Q_plein Manning (réf.) | B15: =(1/B6)*(PI()*B7^2/4)*((B7/4)^(2/3))*SQRT(B11) | C15: m³/s — se met à jour avec n, D, S0
A17: K (lu) | B17: =IFERROR(VLOOKUP(B13,$E$7:$J$9,2,FALSE),0.0098)
A18: M (lu) | B18: =IFERROR(VLOOKUP(B13,$E$7:$J$9,3,FALSE),2)
A19: c (lu) | B19: =IFERROR(VLOOKUP(B13,$E$7:$J$9,4,FALSE),0.0398)
A20: Y (lu) | B20: =IFERROR(VLOOKUP(B13,$E$7:$J$9,5,FALSE),0.67)
A21: Ke (lu) | B21: =IFERROR(VLOOKUP(B13,$E$7:$J$9,6,FALSE),0.5)
A23: HW (m) | B23: WSE (m) | C23: Qinlet | D23: Qoutlet | E23: Q gouvernant | F23: Contrôle
A24: 0 | B24: =$B$9+A24 | C24: =IF(A24<=0,0,IF(A24<=1.2*$B$7,1.811*(PI()*($B$7/2)^2)*SQRT($B$7)*IF($B$17*$B$7<=0,0,(A24/($B$17*$B$7))^(1/$B$18)),MAX(1.811*(PI()*($B$7/2)^2)*SQRT($B$7)*IF($B$17*$B$7<=0,0,((1.2*$B$7)/($B$17*$B$7))^(1/$B$18)),1.811*(PI()*($B$7/2)^2)*SQRT($B$7)*SQRT(MAX(0,(A24/$B$7-$B$20)/$B$19))))) | D24: =IF(A24<$B$7,IF($B$6<=0,0,(1/$B$6)*((($B$7/2)^2/2)*((2*ACOS(1-2*(MIN(0.999,MAX(1E-6,A24/$B$7)))))-SIN(2*ACOS(1-2*(MIN(0.999,MAX(1E-6,A24/$B$7)))))))*IF((IF((($B$7/2)*(2*ACOS(1-2*(MIN(0.999,MAX(1E-6,A24/$B$7))))))<=0,0,((($B$7/2)^2/2)*((2*ACOS(1-2*(MIN(0.999,MAX(1E-6,A24/$B$7)))))-SIN(2*ACOS(1-2*(MIN(0.999,MAX(1E-6,A24/$B$7)))))))/(($B$7/2)*(2*ACOS(1-2*(MIN(0.999,MAX(1E-6,A24/$B$7))))))))<=0,0,(IF((($B$7/2)*(2*ACOS(1-2*(MIN(0.999,MAX(1E-6,A24/$B$7))))))<=0,0,((($B$7/2)^2/2)*((2*ACOS(1-2*(MIN(0.999,MAX(1E-6,A24/$B$7)))))-SIN(2*ACOS(1-2*(MIN(0.999,MAX(1E-6,A24/$B$7)))))))/(($B$7/2)*(2*ACOS(1-2*(MIN(0.999,MAX(1E-6,A24/$B$7))))))))^(2/3))*SQRT($B$11)),IF((A24-$B$12+$B$11*$B$8)<=0,0,(PI()*($B$7/2)^2)*SQRT((A24-$B$12+$B$11*$B$8)/((1+$B$21)/(2*9.81)+($B$6^2)*$B$8/(($B$7/4)^(4/3)))))) | E24: =MIN(C24,D24) | F24: =IF(A24<=0,"—",IF(C24<=D24,"inlet","outlet"))
A25: 0.05 | B25: =$B$9+A25 | C25: =IF(A25<=0,0,IF(A25<=1.2*$B$7,1.811*(PI()*($B$7/2)^2)*SQRT($B$7)*IF($B$17*$B$7<=0,0,(A25/($B$17*$B$7))^(1/$B$18)),MAX(1.811*(PI()*($B$7/2)^2)*SQRT($B$7)*IF($B$17*$B$7<=0,0,((1.2*$B$7)/($B$17*$B$7))^(1/$B$18)),1.811*(PI()*($B$7/2)^2)*SQRT($B$7)*SQRT(MAX(0,(A25/$B$7-$B$20)/$B$19))))) | D25: =IF(A25<$B$7,IF($B$6<=0,0,(1/$B$6)*((($B$7/2)^2/2)*((2*ACOS(1-2*(MIN(0.999,MAX(1E-6,A25/$B$7)))))-SIN(2*ACOS(1-2*(MIN(0.999,MAX(1E-6,A25/$B$7)))))))*IF((IF((($B$7/2)*(2*ACOS(1-2*(MIN(0.999,MAX(1E-6,A25/$B$7))))))<=0,0,((($B$7/2)^2/2)*((2*ACOS(1-2*(MIN(0.999,MAX(1E-6,A25/$B$7)))))-SIN(2*ACOS(1-2*(MIN(0.999,MAX(1E-6,A25/$B$7)))))))/(($B$7/2)*(2*ACOS(1-2*(MIN(0.999,MAX(1E-6,A25/$B$7))))))))<=0,0,(IF((($B$7/2)*(2*ACOS(1-2*(MIN(0.999,MAX(1E-6,A25/$B$7))))))<=0,0,((($B$7/2)^2/2)*((2*ACOS(1-2*(MIN(0.999,MAX(1E-6,A25/$B$7)))))-SIN(2*ACOS(1-2*(MIN(0.999,MAX(1E-6,A25/$B$7)))))))/(($B$7/2)*(2*ACOS(1-2*(MIN(0.999,MAX(1E-6,A25/$B$7))))))))^(2/3))*SQRT($B$11)),IF((A25-$B$12+$B$11*$B$8)<=0,0,(PI()*($B$7/2)^2)*SQRT((A25-$B$12+$B$11*$B$8)/((1+$B$21)/(2*9.81)+($B$6^2)*$B$8/(($B$7/4)^(4/3)))))) | E25: =MIN(C25,D25) | F25: =IF(A25<=0,"—",IF(C25<=D25,"inlet","outlet"))
A26: 0.1 | B26: =$B$9+A26 | C26: =IF(A26<=0,0,IF(A26<=1.2*$B$7,1.811*(PI()*($B$7/2)^2)*SQRT($B$7)*IF($B$17*$B$7<=0,0,(A26/($B$17*$B$7))^(1/$B$18)),MAX(1.811*(PI()*($B$7/2)^2)*SQRT($B$7)*IF($B$17*$B$7<=0,0,((1.2*$B$7)/($B$17*$B$7))^(1/$B$18)),1.811*(PI()*($B$7/2)^2)*SQRT($B$7)*SQRT(MAX(0,(A26/$B$7-$B$20)/$B$19))))) | D26: =IF(A26<$B$7,IF($B$6<=0,0,(1/$B$6)*((($B$7/2)^2/2)*((2*ACOS(1-2*(MIN(0.999,MAX(1E-6,A26/$B$7)))))-SIN(2*ACOS(1-2*(MIN(0.999,MAX(1E-6,A26/$B$7)))))))*IF((IF((($B$7/2)*(2*ACOS(1-2*(MIN(0.999,MAX(1E-6,A26/$B$7))))))<=0,0,((($B$7/2)^2/2)*((2*ACOS(1-2*(MIN(0.999,MAX(1E-6,A26/$B$7)))))-SIN(2*ACOS(1-2*(MIN(0.999,MAX(1E-6,A26/$B$7)))))))/(($B$7/2)*(2*ACOS(1-2*(MIN(0.999,MAX(1E-6,A26/$B$7))))))))<=0,0,(IF((($B$7/2)*(2*ACOS(1-2*(MIN(0.999,MAX(1E-6,A26/$B$7))))))<=0,0,((($B$7/2)^2/2)*((2*ACOS(1-2*(MIN(0.999,MAX(1E-6,A26/$B$7)))))-SIN(2*ACOS(1-2*(MIN(0.999,MAX(1E-6,A26/$B$7)))))))/(($B$7/2)*(2*ACOS(1-2*(MIN(0.999,MAX(1E-6,A26/$B$7))))))))^(2/3))*SQRT($B$11)),IF((A26-$B$12+$B$11*$B$8)<=0,0,(PI()*($B$7/2)^2)*SQRT((A26-$B$12+$B$11*$B$8)/((1+$B$21)/(2*9.81)+($B$6^2)*$B$8/(($B$7/4)^(4/3)))))) | E26: =MIN(C26,D26) | F26: =IF(A26<=0,"—",IF(C26<=D26,"inlet","outlet"))
A27: 0.15 | B27: =$B$9+A27 | C27: =IF(A27<=0,0,IF(A27<=1.2*$B$7,1.811*(PI()*($B$7/2)^2)*SQRT($B$7)*IF($B$17*$B$7<=0,0,(A27/($B$17*$B$7))^(1/$B$18)),MAX(1.811*(PI()*($B$7/2)^2)*SQRT($B$7)*IF($B$17*$B$7<=0,0,((1.2*$B$7)/($B$17*$B$7))^(1/$B$18)),1.811*(PI()*($B$7/2)^2)*SQRT($B$7)*SQRT(MAX(0,(A27/$B$7-$B$20)/$B$19))))) | D27: =IF(A27<$B$7,IF($B$6<=0,0,(1/$B$6)*((($B$7/2)^2/2)*((2*ACOS(1-2*(MIN(0.999,MAX(1E-6,A27/$B$7)))))-SIN(2*ACOS(1-2*(MIN(0.999,MAX(1E-6,A27/$B$7)))))))*IF((IF((($B$7/2)*(2*ACOS(1-2*(MIN(0.999,MAX(1E-6,A27/$B$7))))))<=0,0,((($B$7/2)^2/2)*((2*ACOS(1-2*(MIN(0.999,MAX(1E-6,A27/$B$7)))))-SIN(2*ACOS(1-2*(MIN(0.999,MAX(1E-6,A27/$B$7)))))))/(($B$7/2)*(2*ACOS(1-2*(MIN(0.999,MAX(1E-6,A27/$B$7))))))))<=0,0,(IF((($B$7/2)*(2*ACOS(1-2*(MIN(0.999,MAX(1E-6,A27/$B$7))))))<=0,0,((($B$7/2)^2/2)*((2*ACOS(1-2*(MIN(0.999,MAX(1E-6,A27/$B$7)))))-SIN(2*ACOS(1-2*(MIN(0.999,MAX(1E-6,A27/$B$7)))))))/(($B$7/2)*(2*ACOS(1-2*(MIN(0.999,MAX(1E-6,A27/$B$7))))))))^(2/3))*SQRT($B$11)),IF((A27-$B$12+$B$11*$B$8)<=0,0,(PI()*($B$7/2)^2)*SQRT((A27-$B$12+$B$11*$B$8)/((1+$B$21)/(2*9.81)+($B$6^2)*$B$8/(($B$7/4)^(4/3)))))) | E27: =MIN(C27,D27) | F27: =IF(A27<=0,"—",IF(C27<=D27,"inlet","outlet"))
A28: 0.2 | B28: =$B$9+A28 | C28: =IF(A28<=0,0,IF(A28<=1.2*$B$7,1.811*(PI()*($B$7/2)^2)*SQRT($B$7)*IF($B$17*$B$7<=0,0,(A28/($B$17*$B$7))^(1/$B$18)),MAX(1.811*(PI()*($B$7/2)^2)*SQRT($B$7)*IF($B$17*$B$7<=0,0,((1.2*$B$7)/($B$17*$B$7))^(1/$B$18)),1.811*(PI()*($B$7/2)^2)*SQRT($B$7)*SQRT(MAX(0,(A28/$B$7-$B$20)/$B$19))))) | D28: =IF(A28<$B$7,IF($B$6<=0,0,(1/$B$6)*((($B$7/2)^2/2)*((2*ACOS(1-2*(MIN(0.999,MAX(1E-6,A28/$B$7)))))-SIN(2*ACOS(1-2*(MIN(0.999,MAX(1E-6,A28/$B$7)))))))*IF((IF((($B$7/2)*(2*ACOS(1-2*(MIN(0.999,MAX(1E-6,A28/$B$7))))))<=0,0,((($B$7/2)^2/2)*((2*ACOS(1-2*(MIN(0.999,MAX(1E-6,A28/$B$7)))))-SIN(2*ACOS(1-2*(MIN(0.999,MAX(1E-6,A28/$B$7)))))))/(($B$7/2)*(2*ACOS(1-2*(MIN(0.999,MAX(1E-6,A28/$B$7))))))))<=0,0,(IF((($B$7/2)*(2*ACOS(1-2*(MIN(0.999,MAX(1E-6,A28/$B$7))))))<=0,0,((($B$7/2)^2/2)*((2*ACOS(1-2*(MIN(0.999,MAX(1E-6,A28/$B$7)))))-SIN(2*ACOS(1-2*(MIN(0.999,MAX(1E-6,A28/$B$7)))))))/(($B$7/2)*(2*ACOS(1-2*(MIN(0.999,MAX(1E-6,A28/$B$7))))))))^(2/3))*SQRT($B$11)),IF((A28-$B$12+$B$11*$B$8)<=0,0,(PI()*($B$7/2)^2)*SQRT((A28-$B$12+$B$11*$B$8)/((1+$B$21)/(2*9.81)+($B$6^2)*$B$8/(($B$7/4)^(4/3)))))) | E28: =MIN(C28,D28) | F28: =IF(A28<=0,"—",IF(C28<=D28,"inlet","outlet"))
A29: 0.25 | B29: =$B$9+A29 | C29: =IF(A29<=0,0,IF(A29<=1.2*$B$7,1.811*(PI()*($B$7/2)^2)*SQRT($B$7)*IF($B$17*$B$7<=0,0,(A29/($B$17*$B$7))^(1/$B$18)),MAX(1.811*(PI()*($B$7/2)^2)*SQRT($B$7)*IF($B$17*$B$7<=0,0,((1.2*$B$7)/($B$17*$B$7))^(1/$B$18)),1.811*(PI()*($B$7/2)^2)*SQRT($B$7)*SQRT(MAX(0,(A29/$B$7-$B$20)/$B$19))))) | D29: =IF(A29<$B$7,IF($B$6<=0,0,(1/$B$6)*((($B$7/2)^2/2)*((2*ACOS(1-2*(MIN(0.999,MAX(1E-6,A29/$B$7)))))-SIN(2*ACOS(1-2*(MIN(0.999,MAX(1E-6,A29/$B$7)))))))*IF((IF((($B$7/2)*(2*ACOS(1-2*(MIN(0.999,MAX(1E-6,A29/$B$7))))))<=0,0,((($B$7/2)^2/2)*((2*ACOS(1-2*(MIN(0.999,MAX(1E-6,A29/$B$7)))))-SIN(2*ACOS(1-2*(MIN(0.999,MAX(1E-6,A29/$B$7)))))))/(($B$7/2)*(2*ACOS(1-2*(MIN(0.999,MAX(1E-6,A29/$B$7))))))))<=0,0,(IF((($B$7/2)*(2*ACOS(1-2*(MIN(0.999,MAX(1E-6,A29/$B$7))))))<=0,0,((($B$7/2)^2/2)*((2*ACOS(1-2*(MIN(0.999,MAX(1E-6,A29/$B$7)))))-SIN(2*ACOS(1-2*(MIN(0.999,MAX(1E-6,A29/$B$7)))))))/(($B$7/2)*(2*ACOS(1-2*(MIN(0.999,MAX(1E-6,A29/$B$7))))))))^(2/3))*SQRT($B$11)),IF((A29-$B$12+$B$11*$B$8)<=0,0,(PI()*($B$7/2)^2)*SQRT((A29-$B$12+$B$11*$B$8)/((1+$B$21)/(2*9.81)+($B$6^2)*$B$8/(($B$7/4)^(4/3)))))) | E29: =MIN(C29,D29) | F29: =IF(A29<=0,"—",IF(C29<=D29,"inlet","outlet"))
A30: 0.3 | B30: =$B$9+A30 | C30: =IF(A30<=0,0,IF(A30<=1.2*$B$7,1.811*(PI()*($B$7/2)^2)*SQRT($B$7)*IF($B$17*$B$7<=0,0,(A30/($B$17*$B$7))^(1/$B$18)),MAX(1.811*(PI()*($B$7/2)^2)*SQRT($B$7)*IF($B$17*$B$7<=0,0,((1.2*$B$7)/($B$17*$B$7))^(1/$B$18)),1.811*(PI()*($B$7/2)^2)*SQRT($B$7)*SQRT(MAX(0,(A30/$B$7-$B$20)/$B$19))))) | D30: =IF(A30<$B$7,IF($B$6<=0,0,(1/$B$6)*((($B$7/2)^2/2)*((2*ACOS(1-2*(MIN(0.999,MAX(1E-6,A30/$B$7)))))-SIN(2*ACOS(1-2*(MIN(0.999,MAX(1E-6,A30/$B$7)))))))*IF((IF((($B$7/2)*(2*ACOS(1-2*(MIN(0.999,MAX(1E-6,A30/$B$7))))))<=0,0,((($B$7/2)^2/2)*((2*ACOS(1-2*(MIN(0.999,MAX(1E-6,A30/$B$7)))))-SIN(2*ACOS(1-2*(MIN(0.999,MAX(1E-6,A30/$B$7)))))))/(($B$7/2)*(2*ACOS(1-2*(MIN(0.999,MAX(1E-6,A30/$B$7))))))))<=0,0,(IF((($B$7/2)*(2*ACOS(1-2*(MIN(0.999,MAX(1E-6,A30/$B$7))))))<=0,0,((($B$7/2)^2/2)*((2*ACOS(1-2*(MIN(0.999,MAX(1E-6,A30/$B$7)))))-SIN(2*ACOS(1-2*(MIN(0.999,MAX(1E-6,A30/$B$7)))))))/(($B$7/2)*(2*ACOS(1-2*(MIN(0.999,MAX(1E-6,A30/$B$7))))))))^(2/3))*SQRT($B$11)),IF((A30-$B$12+$B$11*$B$8)<=0,0,(PI()*($B$7/2)^2)*SQRT((A30-$B$12+$B$11*$B$8)/((1+$B$21)/(2*9.81)+($B$6^2)*$B$8/(($B$7/4)^(4/3)))))) | E30: =MIN(C30,D30) | F30: =IF(A30<=0,"—",IF(C30<=D30,"inlet","outlet"))
A31: 0.35 | B31: =$B$9+A31 | C31: =IF(A31<=0,0,IF(A31<=1.2*$B$7,1.811*(PI()*($B$7/2)^2)*SQRT($B$7)*IF($B$17*$B$7<=0,0,(A31/($B$17*$B$7))^(1/$B$18)),MAX(1.811*(PI()*($B$7/2)^2)*SQRT($B$7)*IF($B$17*$B$7<=0,0,((1.2*$B$7)/($B$17*$B$7))^(1/$B$18)),1.811*(PI()*($B$7/2)^2)*SQRT($B$7)*SQRT(MAX(0,(A31/$B$7-$B$20)/$B$19))))) | D31: =IF(A31<$B$7,IF($B$6<=0,0,(1/$B$6)*((($B$7/2)^2/2)*((2*ACOS(1-2*(MIN(0.999,MAX(1E-6,A31/$B$7)))))-SIN(2*ACOS(1-2*(MIN(0.999,MAX(1E-6,A31/$B$7)))))))*IF((IF((($B$7/2)*(2*ACOS(1-2*(MIN(0.999,MAX(1E-6,A31/$B$7))))))<=0,0,((($B$7/2)^2/2)*((2*ACOS(1-2*(MIN(0.999,MAX(1E-6,A31/$B$7)))))-SIN(2*ACOS(1-2*(MIN(0.999,MAX(1E-6,A31/$B$7)))))))/(($B$7/2)*(2*ACOS(1-2*(MIN(0.999,MAX(1E-6,A31/$B$7))))))))<=0,0,(IF((($B$7/2)*(2*ACOS(1-2*(MIN(0.999,MAX(1E-6,A31/$B$7))))))<=0,0,((($B$7/2)^2/2)*((2*ACOS(1-2*(MIN(0.999,MAX(1E-6,A31/$B$7)))))-SIN(2*ACOS(1-2*(MIN(0.999,MAX(1E-6,A31/$B$7)))))))/(($B$7/2)*(2*ACOS(1-2*(MIN(0.999,MAX(1E-6,A31/$B$7))))))))^(2/3))*SQRT($B$11)),IF((A31-$B$12+$B$11*$B$8)<=0,0,(PI()*($B$7/2)^2)*SQRT((A31-$B$12+$B$11*$B$8)/((1+$B$21)/(2*9.81)+($B$6^2)*$B$8/(($B$7/4)^(4/3)))))) | E31: =MIN(C31,D31) | F31: =IF(A31<=0,"—",IF(C31<=D31,"inlet","outlet"))
A32: 0.4 | B32: =$B$9+A32 | C32: =IF(A32<=0,0,IF(A32<=1.2*$B$7,1.811*(PI()*($B$7/2)^2)*SQRT($B$7)*IF($B$17*$B$7<=0,0,(A32/($B$17*$B$7))^(1/$B$18)),MAX(1.811*(PI()*($B$7/2)^2)*SQRT($B$7)*IF($B$17*$B$7<=0,0,((1.2*$B$7)/($B$17*$B$7))^(1/$B$18)),1.811*(PI()*($B$7/2)^2)*SQRT($B$7)*SQRT(MAX(0,(A32/$B$7-$B$20)/$B$19))))) | D32: =IF(A32<$B$7,IF($B$6<=0,0,(1/$B$6)*((($B$7/2)^2/2)*((2*ACOS(1-2*(MIN(0.999,MAX(1E-6,A32/$B$7)))))-SIN(2*ACOS(1-2*(MIN(0.999,MAX(1E-6,A32/$B$7)))))))*IF((IF((($B$7/2)*(2*ACOS(1-2*(MIN(0.999,MAX(1E-6,A32/$B$7))))))<=0,0,((($B$7/2)^2/2)*((2*ACOS(1-2*(MIN(0.999,MAX(1E-6,A32/$B$7)))))-SIN(2*ACOS(1-2*(MIN(0.999,MAX(1E-6,A32/$B$7)))))))/(($B$7/2)*(2*ACOS(1-2*(MIN(0.999,MAX(1E-6,A32/$B$7))))))))<=0,0,(IF((($B$7/2)*(2*ACOS(1-2*(MIN(0.999,MAX(1E-6,A32/$B$7))))))<=0,0,((($B$7/2)^2/2)*((2*ACOS(1-2*(MIN(0.999,MAX(1E-6,A32/$B$7)))))-SIN(2*ACOS(1-2*(MIN(0.999,MAX(1E-6,A32/$B$7)))))))/(($B$7/2)*(2*ACOS(1-2*(MIN(0.999,MAX(1E-6,A32/$B$7))))))))^(2/3))*SQRT($B$11)),IF((A32-$B$12+$B$11*$B$8)<=0,0,(PI()*($B$7/2)^2)*SQRT((A32-$B$12+$B$11*$B$8)/((1+$B$21)/(2*9.81)+($B$6^2)*$B$8/(($B$7/4)^(4/3)))))) | E32: =MIN(C32,D32) | F32: =IF(A32<=0,"—",IF(C32<=D32,"inlet","outlet"))
A33: 0.45 | B33: =$B$9+A33 | C33: =IF(A33<=0,0,IF(A33<=1.2*$B$7,1.811*(PI()*($B$7/2)^2)*SQRT($B$7)*IF($B$17*$B$7<=0,0,(A33/($B$17*$B$7))^(1/$B$18)),MAX(1.811*(PI()*($B$7/2)^2)*SQRT($B$7)*IF($B$17*$B$7<=0,0,((1.2*$B$7)/($B$17*$B$7))^(1/$B$18)),1.811*(PI()*($B$7/2)^2)*SQRT($B$7)*SQRT(MAX(0,(A33/$B$7-$B$20)/$B$19))))) | D33: =IF(A33<$B$7,IF($B$6<=0,0,(1/$B$6)*((($B$7/2)^2/2)*((2*ACOS(1-2*(MIN(0.999,MAX(1E-6,A33/$B$7)))))-SIN(2*ACOS(1-2*(MIN(0.999,MAX(1E-6,A33/$B$7)))))))*IF((IF((($B$7/2)*(2*ACOS(1-2*(MIN(0.999,MAX(1E-6,A33/$B$7))))))<=0,0,((($B$7/2)^2/2)*((2*ACOS(1-2*(MIN(0.999,MAX(1E-6,A33/$B$7)))))-SIN(2*ACOS(1-2*(MIN(0.999,MAX(1E-6,A33/$B$7)))))))/(($B$7/2)*(2*ACOS(1-2*(MIN(0.999,MAX(1E-6,A33/$B$7))))))))<=0,0,(IF((($B$7/2)*(2*ACOS(1-2*(MIN(0.999,MAX(1E-6,A33/$B$7))))))<=0,0,((($B$7/2)^2/2)*((2*ACOS(1-2*(MIN(0.999,MAX(1E-6,A33/$B$7)))))-SIN(2*ACOS(1-2*(MIN(0.999,MAX(1E-6,A33/$B$7)))))))/(($B$7/2)*(2*ACOS(1-2*(MIN(0.999,MAX(1E-6,A33/$B$7))))))))^(2/3))*SQRT($B$11)),IF((A33-$B$12+$B$11*$B$8)<=0,0,(PI()*($B$7/2)^2)*SQRT((A33-$B$12+$B$11*$B$8)/((1+$B$21)/(2*9.81)+($B$6^2)*$B$8/(($B$7/4)^(4/3)))))) | E33: =MIN(C33,D33) | F33: =IF(A33<=0,"—",IF(C33<=D33,"inlet","outlet"))
A34: 0.5 | B34: =$B$9+A34 | C34: =IF(A34<=0,0,IF(A34<=1.2*$B$7,1.811*(PI()*($B$7/2)^2)*SQRT($B$7)*IF($B$17*$B$7<=0,0,(A34/($B$17*$B$7))^(1/$B$18)),MAX(1.811*(PI()*($B$7/2)^2)*SQRT($B$7)*IF($B$17*$B$7<=0,0,((1.2*$B$7)/($B$17*$B$7))^(1/$B$18)),1.811*(PI()*($B$7/2)^2)*SQRT($B$7)*SQRT(MAX(0,(A34/$B$7-$B$20)/$B$19))))) | D34: =IF(A34<$B$7,IF($B$6<=0,0,(1/$B$6)*((($B$7/2)^2/2)*((2*ACOS(1-2*(MIN(0.999,MAX(1E-6,A34/$B$7)))))-SIN(2*ACOS(1-2*(MIN(0.999,MAX(1E-6,A34/$B$7)))))))*IF((IF((($B$7/2)*(2*ACOS(1-2*(MIN(0.999,MAX(1E-6,A34/$B$7))))))<=0,0,((($B$7/2)^2/2)*((2*ACOS(1-2*(MIN(0.999,MAX(1E-6,A34/$B$7)))))-SIN(2*ACOS(1-2*(MIN(0.999,MAX(1E-6,A34/$B$7)))))))/(($B$7/2)*(2*ACOS(1-2*(MIN(0.999,MAX(1E-6,A34/$B$7))))))))<=0,0,(IF((($B$7/2)*(2*ACOS(1-2*(MIN(0.999,MAX(1E-6,A34/$B$7))))))<=0,0,((($B$7/2)^2/2)*((2*ACOS(1-2*(MIN(0.999,MAX(1E-6,A34/$B$7)))))-SIN(2*ACOS(1-2*(MIN(0.999,MAX(1E-6,A34/$B$7)))))))/(($B$7/2)*(2*ACOS(1-2*(MIN(0.999,MAX(1E-6,A34/$B$7))))))))^(2/3))*SQRT($B$11)),IF((A34-$B$12+$B$11*$B$8)<=0,0,(PI()*($B$7/2)^2)*SQRT((A34-$B$12+$B$11*$B$8)/((1+$B$21)/(2*9.81)+($B$6^2)*$B$8/(($B$7/4)^(4/3)))))) | E34: =MIN(C34,D34) | F34: =IF(A34<=0,"—",IF(C34<=D34,"inlet","outlet"))
A35: 0.55 | B35: =$B$9+A35 | C35: =IF(A35<=0,0,IF(A35<=1.2*$B$7,1.811*(PI()*($B$7/2)^2)*SQRT($B$7)*IF($B$17*$B$7<=0,0,(A35/($B$17*$B$7))^(1/$B$18)),MAX(1.811*(PI()*($B$7/2)^2)*SQRT($B$7)*IF($B$17*$B$7<=0,0,((1.2*$B$7)/($B$17*$B$7))^(1/$B$18)),1.811*(PI()*($B$7/2)^2)*SQRT($B$7)*SQRT(MAX(0,(A35/$B$7-$B$20)/$B$19))))) | D35: =IF(A35<$B$7,IF($B$6<=0,0,(1/$B$6)*((($B$7/2)^2/2)*((2*ACOS(1-2*(MIN(0.999,MAX(1E-6,A35/$B$7)))))-SIN(2*ACOS(1-2*(MIN(0.999,MAX(1E-6,A35/$B$7)))))))*IF((IF((($B$7/2)*(2*ACOS(1-2*(MIN(0.999,MAX(1E-6,A35/$B$7))))))<=0,0,((($B$7/2)^2/2)*((2*ACOS(1-2*(MIN(0.999,MAX(1E-6,A35/$B$7)))))-SIN(2*ACOS(1-2*(MIN(0.999,MAX(1E-6,A35/$B$7)))))))/(($B$7/2)*(2*ACOS(1-2*(MIN(0.999,MAX(1E-6,A35/$B$7))))))))<=0,0,(IF((($B$7/2)*(2*ACOS(1-2*(MIN(0.999,MAX(1E-6,A35/$B$7))))))<=0,0,((($B$7/2)^2/2)*((2*ACOS(1-2*(MIN(0.999,MAX(1E-6,A35/$B$7)))))-SIN(2*ACOS(1-2*(MIN(0.999,MAX(1E-6,A35/$B$7)))))))/(($B$7/2)*(2*ACOS(1-2*(MIN(0.999,MAX(1E-6,A35/$B$7))))))))^(2/3))*SQRT($B$11)),IF((A35-$B$12+$B$11*$B$8)<=0,0,(PI()*($B$7/2)^2)*SQRT((A35-$B$12+$B$11*$B$8)/((1+$B$21)/(2*9.81)+($B$6^2)*$B$8/(($B$7/4)^(4/3)))))) | E35: =MIN(C35,D35) | F35: =IF(A35<=0,"—",IF(C35<=D35,"inlet","outlet"))
... A84: 3 | B84: =$B$9+A84 | C84: =IF(A84<=0,0,IF(A84<=1.2*$B$7,1.811*(PI()*($B$7/2)^2)*SQRT($B$7)*IF($B$17*$B$7<=0,0,(A84/($B$17*$B$7))^(1/$B$18)),MAX(1.811*(PI()*($B$7/2)^2)*SQRT($B$7)*IF($B$17*$B$7<=0,0,((1.2*$B$7)/($B$17*$B$7))^(1/$B$18)),1.811*(PI()*($B$7/2)^2)*SQRT($B$7)*SQRT(MAX(0,(A84/$B$7-$B$20)/$B$19))))) | D84: =IF(A84<$B$7,IF($B$6<=0,0,(1/$B$6)*((($B$7/2)^2/2)*((2*ACOS(1-2*(MIN(0.999,MAX(1E-6,A84/$B$7)))))-SIN(2*ACOS(1-2*(MIN(0.999,MAX(1E-6,A84/$B$7)))))))*IF((IF((($B$7/2)*(2*ACOS(1-2*(MIN(0.999,MAX(1E-6,A84/$B$7))))))<=0,0,((($B$7/2)^2/2)*((2*ACOS(1-2*(MIN(0.999,MAX(1E-6,A84/$B$7)))))-SIN(2*ACOS(1-2*(MIN(0.999,MAX(1E-6,A84/$B$7)))))))/(($B$7/2)*(2*ACOS(1-2*(MIN(0.999,MAX(1E-6,A84/$B$7))))))))<=0,0,(IF((($B$7/2)*(2*ACOS(1-2*(MIN(0.999,MAX(1E-6,A84/$B$7))))))<=0,0,((($B$7/2)^2/2)*((2*ACOS(1-2*(MIN(0.999,MAX(1E-6,A84/$B$7)))))-SIN(2*ACOS(1-2*(MIN(0.999,MAX(1E-6,A84/$B$7)))))))/(($B$7/2)*(2*ACOS(1-2*(MIN(0.999,MAX(1E-6,A84/$B$7))))))))^(2/3))*SQRT($B$11)),IF((A84-$B$12+$B$11*$B$8)<=0,0,(PI()*($B$7/2)^2)*SQRT((A84-$B$12+$B$11*$B$8)/((1+$B$21)/(2*9.81)+($B$6^2)*$B$8/(($B$7/4)^(4/3)))))) | E84: =MIN(C84,D84) | F84: =IF(A84<=0,"—",IF(C84<=D84,"inlet","outlet"))

Sheet Calcul_B
A1: Méthode B — routage avec Qout = f(H) depuis Courbe_QH_900 (FHWA)
A2: H = V / Aire_constante (Parametres!B24) — raccourci, PAS le levé Stage_Storage. Qout interpolé sur Courbe_QH_900!E (Q gouvernant). Si V≈0, Qout = MIN(Qin, Q_plein). ΔV = (Qin_moy - Qout)*Δt. Après routage, WSEmax_B réel est lu sur Stage_Storage via Vmax_B (Parametres B45).
A5: Aire (m²) | B5: =Parametres!B24
A6: Q_plein réf. (m³/s) | B6: =Parametres!B22
A7: Vmax_B (m³) | B7: =MAX(G12:G24)
A8: Hmax_B (m) | B8: =IF(B5>0,B7/B5,0)
A11: t (min) | B11: Qin | C11: H (m) | D11: Q_courbe | E11: Qout | F11: Δt (s) | G11: V (m³)
A12: =Hydrogramme!A8 | B12: =Hydrogramme!C8 | C12: 0 | D12: 0 | E12: =MIN(B12,$B$6) | F12: 0 | G12: 0
A13: =Hydrogramme!A9 | B13: =Hydrogramme!C9 | C13: =IF($B$5>0,G12/$B$5,0) | D13: =IF(C13<=0,0,IF(C13>=INDEX(Courbe_QH_900!$A$24:$A$84,ROWS(Courbe_QH_900!$A$24:$A$84)),INDEX(Courbe_QH_900!$E$24:$E$84,ROWS(Courbe_QH_900!$E$24:$E$84)),INDEX(Courbe_QH_900!$E$24:$E$84,MATCH(C13,Courbe_QH_900!$A$24:$A$84,1))+(C13-INDEX(Courbe_QH_900!$A$24:$A$84,MATCH(C13,Courbe_QH_900!$A$24:$A$84,1)))/(INDEX(Courbe_QH_900!$A$24:$A$84,MATCH(C13,Courbe_QH_900!$A$24:$A$84,1)+1)-INDEX(Courbe_QH_900!$A$24:$A$84,MATCH(C13,Courbe_QH_900!$A$24:$A$84,1)))*(INDEX(Courbe_QH_900!$E$24:$E$84,MATCH(C13,Courbe_QH_900!$A$24:$A$84,1)+1)-INDEX(Courbe_QH_900!$E$24:$E$84,MATCH(C13,Courbe_QH_900!$A$24:$A$84,1))))) | E13: =IF(G12<=0.01,MIN(0.5*(B12+B13),$B$6),D13) | F13: =(A13-A12)*60 | G13: =MAX(0,G12+(0.5*(B12+B13)-E13)*F13)
A14: =Hydrogramme!A10 | B14: =Hydrogramme!C10 | C14: =IF($B$5>0,G13/$B$5,0) | D14: =IF(C14<=0,0,IF(C14>=INDEX(Courbe_QH_900!$A$24:$A$84,ROWS(Courbe_QH_900!$A$24:$A$84)),INDEX(Courbe_QH_900!$E$24:$E$84,ROWS(Courbe_QH_900!$E$24:$E$84)),INDEX(Courbe_QH_900!$E$24:$E$84,MATCH(C14,Courbe_QH_900!$A$24:$A$84,1))+(C14-INDEX(Courbe_QH_900!$A$24:$A$84,MATCH(C14,Courbe_QH_900!$A$24:$A$84,1)))/(INDEX(Courbe_QH_900!$A$24:$A$84,MATCH(C14,Courbe_QH_900!$A$24:$A$84,1)+1)-INDEX(Courbe_QH_900!$A$24:$A$84,MATCH(C14,Courbe_QH_900!$A$24:$A$84,1)))*(INDEX(Courbe_QH_900!$E$24:$E$84,MATCH(C14,Courbe_QH_900!$A$24:$A$84,1)+1)-INDEX(Courbe_QH_900!$E$24:$E$84,MATCH(C14,Courbe_QH_900!$A$24:$A$84,1))))) | E14: =IF(G13<=0.01,MIN(0.5*(B13+B14),$B$6),D14) | F14: =(A14-A13)*60 | G14: =MAX(0,G13+(0.5*(B13+B14)-E14)*F14)
A15: =Hydrogramme!A11 | B15: =Hydrogramme!C11 | C15: =IF($B$5>0,G14/$B$5,0) | D15: =IF(C15<=0,0,IF(C15>=INDEX(Courbe_QH_900!$A$24:$A$84,ROWS(Courbe_QH_900!$A$24:$A$84)),INDEX(Courbe_QH_900!$E$24:$E$84,ROWS(Courbe_QH_900!$E$24:$E$84)),INDEX(Courbe_QH_900!$E$24:$E$84,MATCH(C15,Courbe_QH_900!$A$24:$A$84,1))+(C15-INDEX(Courbe_QH_900!$A$24:$A$84,MATCH(C15,Courbe_QH_900!$A$24:$A$84,1)))/(INDEX(Courbe_QH_900!$A$24:$A$84,MATCH(C15,Courbe_QH_900!$A$24:$A$84,1)+1)-INDEX(Courbe_QH_900!$A$24:$A$84,MATCH(C15,Courbe_QH_900!$A$24:$A$84,1)))*(INDEX(Courbe_QH_900!$E$24:$E$84,MATCH(C15,Courbe_QH_900!$A$24:$A$84,1)+1)-INDEX(Courbe_QH_900!$E$24:$E$84,MATCH(C15,Courbe_QH_900!$A$24:$A$84,1))))) | E15: =IF(G14<=0.01,MIN(0.5*(B14+B15),$B$6),D15) | F15: =(A15-A14)*60 | G15: =MAX(0,G14+(0.5*(B14+B15)-E15)*F15)
A16: =Hydrogramme!A12 | B16: =Hydrogramme!C12 | C16: =IF($B$5>0,G15/$B$5,0) | D16: =IF(C16<=0,0,IF(C16>=INDEX(Courbe_QH_900!$A$24:$A$84,ROWS(Courbe_QH_900!$A$24:$A$84)),INDEX(Courbe_QH_900!$E$24:$E$84,ROWS(Courbe_QH_900!$E$24:$E$84)),INDEX(Courbe_QH_900!$E$24:$E$84,MATCH(C16,Courbe_QH_900!$A$24:$A$84,1))+(C16-INDEX(Courbe_QH_900!$A$24:$A$84,MATCH(C16,Courbe_QH_900!$A$24:$A$84,1)))/(INDEX(Courbe_QH_900!$A$24:$A$84,MATCH(C16,Courbe_QH_900!$A$24:$A$84,1)+1)-INDEX(Courbe_QH_900!$A$24:$A$84,MATCH(C16,Courbe_QH_900!$A$24:$A$84,1)))*(INDEX(Courbe_QH_900!$E$24:$E$84,MATCH(C16,Courbe_QH_900!$A$24:$A$84,1)+1)-INDEX(Courbe_QH_900!$E$24:$E$84,MATCH(C16,Courbe_QH_900!$A$24:$A$84,1))))) | E16: =IF(G15<=0.01,MIN(0.5*(B15+B16),$B$6),D16) | F16: =(A16-A15)*60 | G16: =MAX(0,G15+(0.5*(B15+B16)-E16)*F16)
A17: =Hydrogramme!A13 | B17: =Hydrogramme!C13 | C17: =IF($B$5>0,G16/$B$5,0) | D17: =IF(C17<=0,0,IF(C17>=INDEX(Courbe_QH_900!$A$24:$A$84,ROWS(Courbe_QH_900!$A$24:$A$84)),INDEX(Courbe_QH_900!$E$24:$E$84,ROWS(Courbe_QH_900!$E$24:$E$84)),INDEX(Courbe_QH_900!$E$24:$E$84,MATCH(C17,Courbe_QH_900!$A$24:$A$84,1))+(C17-INDEX(Courbe_QH_900!$A$24:$A$84,MATCH(C17,Courbe_QH_900!$A$24:$A$84,1)))/(INDEX(Courbe_QH_900!$A$24:$A$84,MATCH(C17,Courbe_QH_900!$A$24:$A$84,1)+1)-INDEX(Courbe_QH_900!$A$24:$A$84,MATCH(C17,Courbe_QH_900!$A$24:$A$84,1)))*(INDEX(Courbe_QH_900!$E$24:$E$84,MATCH(C17,Courbe_QH_900!$A$24:$A$84,1)+1)-INDEX(Courbe_QH_900!$E$24:$E$84,MATCH(C17,Courbe_QH_900!$A$24:$A$84,1))))) | E17: =IF(G16<=0.01,MIN(0.5*(B16+B17),$B$6),D17) | F17: =(A17-A16)*60 | G17: =MAX(0,G16+(0.5*(B16+B17)-E17)*F17)
A18: =Hydrogramme!A14 | B18: =Hydrogramme!C14 | C18: =IF($B$5>0,G17/$B$5,0) | D18: =IF(C18<=0,0,IF(C18>=INDEX(Courbe_QH_900!$A$24:$A$84,ROWS(Courbe_QH_900!$A$24:$A$84)),INDEX(Courbe_QH_900!$E$24:$E$84,ROWS(Courbe_QH_900!$E$24:$E$84)),INDEX(Courbe_QH_900!$E$24:$E$84,MATCH(C18,Courbe_QH_900!$A$24:$A$84,1))+(C18-INDEX(Courbe_QH_900!$A$24:$A$84,MATCH(C18,Courbe_QH_900!$A$24:$A$84,1)))/(INDEX(Courbe_QH_900!$A$24:$A$84,MATCH(C18,Courbe_QH_900!$A$24:$A$84,1)+1)-INDEX(Courbe_QH_900!$A$24:$A$84,MATCH(C18,Courbe_QH_900!$A$24:$A$84,1)))*(INDEX(Courbe_QH_900!$E$24:$E$84,MATCH(C18,Courbe_QH_900!$A$24:$A$84,1)+1)-INDEX(Courbe_QH_900!$E$24:$E$84,MATCH(C18,Courbe_QH_900!$A$24:$A$84,1))))) | E18: =IF(G17<=0.01,MIN(0.5*(B17+B18),$B$6),D18) | F18: =(A18-A17)*60 | G18: =MAX(0,G17+(0.5*(B17+B18)-E18)*F18)
A19: =Hydrogramme!A15 | B19: =Hydrogramme!C15 | C19: =IF($B$5>0,G18/$B$5,0) | D19: =IF(C19<=0,0,IF(C19>=INDEX(Courbe_QH_900!$A$24:$A$84,ROWS(Courbe_QH_900!$A$24:$A$84)),INDEX(Courbe_QH_900!$E$24:$E$84,ROWS(Courbe_QH_900!$E$24:$E$84)),INDEX(Courbe_QH_900!$E$24:$E$84,MATCH(C19,Courbe_QH_900!$A$24:$A$84,1))+(C19-INDEX(Courbe_QH_900!$A$24:$A$84,MATCH(C19,Courbe_QH_900!$A$24:$A$84,1)))/(INDEX(Courbe_QH_900!$A$24:$A$84,MATCH(C19,Courbe_QH_900!$A$24:$A$84,1)+1)-INDEX(Courbe_QH_900!$A$24:$A$84,MATCH(C19,Courbe_QH_900!$A$24:$A$84,1)))*(INDEX(Courbe_QH_900!$E$24:$E$84,MATCH(C19,Courbe_QH_900!$A$24:$A$84,1)+1)-INDEX(Courbe_QH_900!$E$24:$E$84,MATCH(C19,Courbe_QH_900!$A$24:$A$84,1))))) | E19: =IF(G18<=0.01,MIN(0.5*(B18+B19),$B$6),D19) | F19: =(A19-A18)*60 | G19: =MAX(0,G18+(0.5*(B18+B19)-E19)*F19)
A20: =Hydrogramme!A16 | B20: =Hydrogramme!C16 | C20: =IF($B$5>0,G19/$B$5,0) | D20: =IF(C20<=0,0,IF(C20>=INDEX(Courbe_QH_900!$A$24:$A$84,ROWS(Courbe_QH_900!$A$24:$A$84)),INDEX(Courbe_QH_900!$E$24:$E$84,ROWS(Courbe_QH_900!$E$24:$E$84)),INDEX(Courbe_QH_900!$E$24:$E$84,MATCH(C20,Courbe_QH_900!$A$24:$A$84,1))+(C20-INDEX(Courbe_QH_900!$A$24:$A$84,MATCH(C20,Courbe_QH_900!$A$24:$A$84,1)))/(INDEX(Courbe_QH_900!$A$24:$A$84,MATCH(C20,Courbe_QH_900!$A$24:$A$84,1)+1)-INDEX(Courbe_QH_900!$A$24:$A$84,MATCH(C20,Courbe_QH_900!$A$24:$A$84,1)))*(INDEX(Courbe_QH_900!$E$24:$E$84,MATCH(C20,Courbe_QH_900!$A$24:$A$84,1)+1)-INDEX(Courbe_QH_900!$E$24:$E$84,MATCH(C20,Courbe_QH_900!$A$24:$A$84,1))))) | E20: =IF(G19<=0.01,MIN(0.5*(B19+B20),$B$6),D20) | F20: =(A20-A19)*60 | G20: =MAX(0,G19+(0.5*(B19+B20)-E20)*F20)
A21: =Hydrogramme!A17 | B21: =Hydrogramme!C17 | C21: =IF($B$5>0,G20/$B$5,0) | D21: =IF(C21<=0,0,IF(C21>=INDEX(Courbe_QH_900!$A$24:$A$84,ROWS(Courbe_QH_900!$A$24:$A$84)),INDEX(Courbe_QH_900!$E$24:$E$84,ROWS(Courbe_QH_900!$E$24:$E$84)),INDEX(Courbe_QH_900!$E$24:$E$84,MATCH(C21,Courbe_QH_900!$A$24:$A$84,1))+(C21-INDEX(Courbe_QH_900!$A$24:$A$84,MATCH(C21,Courbe_QH_900!$A$24:$A$84,1)))/(INDEX(Courbe_QH_900!$A$24:$A$84,MATCH(C21,Courbe_QH_900!$A$24:$A$84,1)+1)-INDEX(Courbe_QH_900!$A$24:$A$84,MATCH(C21,Courbe_QH_900!$A$24:$A$84,1)))*(INDEX(Courbe_QH_900!$E$24:$E$84,MATCH(C21,Courbe_QH_900!$A$24:$A$84,1)+1)-INDEX(Courbe_QH_900!$E$24:$E$84,MATCH(C21,Courbe_QH_900!$A$24:$A$84,1))))) | E21: =IF(G20<=0.01,MIN(0.5*(B20+B21),$B$6),D21) | F21: =(A21-A20)*60 | G21: =MAX(0,G20+(0.5*(B20+B21)-E21)*F21)
A22: =Hydrogramme!A18 | B22: =Hydrogramme!C18 | C22: =IF($B$5>0,G21/$B$5,0) | D22: =IF(C22<=0,0,IF(C22>=INDEX(Courbe_QH_900!$A$24:$A$84,ROWS(Courbe_QH_900!$A$24:$A$84)),INDEX(Courbe_QH_900!$E$24:$E$84,ROWS(Courbe_QH_900!$E$24:$E$84)),INDEX(Courbe_QH_900!$E$24:$E$84,MATCH(C22,Courbe_QH_900!$A$24:$A$84,1))+(C22-INDEX(Courbe_QH_900!$A$24:$A$84,MATCH(C22,Courbe_QH_900!$A$24:$A$84,1)))/(INDEX(Courbe_QH_900!$A$24:$A$84,MATCH(C22,Courbe_QH_900!$A$24:$A$84,1)+1)-INDEX(Courbe_QH_900!$A$24:$A$84,MATCH(C22,Courbe_QH_900!$A$24:$A$84,1)))*(INDEX(Courbe_QH_900!$E$24:$E$84,MATCH(C22,Courbe_QH_900!$A$24:$A$84,1)+1)-INDEX(Courbe_QH_900!$E$24:$E$84,MATCH(C22,Courbe_QH_900!$A$24:$A$84,1))))) | E22: =IF(G21<=0.01,MIN(0.5*(B21+B22),$B$6),D22) | F22: =(A22-A21)*60 | G22: =MAX(0,G21+(0.5*(B21+B22)-E22)*F22)
A23: =Hydrogramme!A19 | B23: =Hydrogramme!C19 | C23: =IF($B$5>0,G22/$B$5,0) | D23: =IF(C23<=0,0,IF(C23>=INDEX(Courbe_QH_900!$A$24:$A$84,ROWS(Courbe_QH_900!$A$24:$A$84)),INDEX(Courbe_QH_900!$E$24:$E$84,ROWS(Courbe_QH_900!$E$24:$E$84)),INDEX(Courbe_QH_900!$E$24:$E$84,MATCH(C23,Courbe_QH_900!$A$24:$A$84,1))+(C23-INDEX(Courbe_QH_900!$A$24:$A$84,MATCH(C23,Courbe_QH_900!$A$24:$A$84,1)))/(INDEX(Courbe_QH_900!$A$24:$A$84,MATCH(C23,Courbe_QH_900!$A$24:$A$84,1)+1)-INDEX(Courbe_QH_900!$A$24:$A$84,MATCH(C23,Courbe_QH_900!$A$24:$A$84,1)))*(INDEX(Courbe_QH_900!$E$24:$E$84,MATCH(C23,Courbe_QH_900!$A$24:$A$84,1)+1)-INDEX(Courbe_QH_900!$E$24:$E$84,MATCH(C23,Courbe_QH_900!$A$24:$A$84,1))))) | E23: =IF(G22<=0.01,MIN(0.5*(B22+B23),$B$6),D23) | F23: =(A23-A22)*60 | G23: =MAX(0,G22+(0.5*(B22+B23)-E23)*F23)
A24: =Hydrogramme!A20 | B24: =Hydrogramme!C20 | C24: =IF($B$5>0,G23/$B$5,0) | D24: =IF(C24<=0,0,IF(C24>=INDEX(Courbe_QH_900!$A$24:$A$84,ROWS(Courbe_QH_900!$A$24:$A$84)),INDEX(Courbe_QH_900!$E$24:$E$84,ROWS(Courbe_QH_900!$E$24:$E$84)),INDEX(Courbe_QH_900!$E$24:$E$84,MATCH(C24,Courbe_QH_900!$A$24:$A$84,1))+(C24-INDEX(Courbe_QH_900!$A$24:$A$84,MATCH(C24,Courbe_QH_900!$A$24:$A$84,1)))/(INDEX(Courbe_QH_900!$A$24:$A$84,MATCH(C24,Courbe_QH_900!$A$24:$A$84,1)+1)-INDEX(Courbe_QH_900!$A$24:$A$84,MATCH(C24,Courbe_QH_900!$A$24:$A$84,1)))*(INDEX(Courbe_QH_900!$E$24:$E$84,MATCH(C24,Courbe_QH_900!$A$24:$A$84,1)+1)-INDEX(Courbe_QH_900!$E$24:$E$84,MATCH(C24,Courbe_QH_900!$A$24:$A$84,1))))) | E24: =IF(G23<=0.01,MIN(0.5*(B23+B24),$B$6),D24) | F24: =(A24-A23)*60 | G24: =MAX(0,G23+(0.5*(B23+B24)-E24)*F24)

Sheet Compose_900
A1: Méthode C — courbe composée Ø900 + fossé trapèze (crest = crown)
A2: Qout = Q_900(WSE) + Q_overflow(WSE). V_total = V_pond(Stage_Storage) + V_ditch. Overflow: trapèze au-dessus du crown, Manning. Paramètres jaunes = Parametres!B27–B32.
A5: Paramètres (liés à Parametres)
A6: Crest (m) | B6: =Parametres!B27
A7: b (m) | B7: =Parametres!B28
A8: n fossé | B8: =Parametres!B29
A9: z (-) | B9: =Parametres!B30
A10: S fossé | B10: =Parametres!B31
A11: L fossé (m) | B11: =Parametres!B32
A12: Zin Ø900 (m) | B12: =34.88
A14: WSE (m) | B14: HW (m) | C14: y_ov (m) | D14: A_ditch (m²) | E14: V_ditch (m³) | F14: V_pond (m³) | G14: V_total (m³) | H14: Q_900 | I14: Q_overflow | J14: Qout | K14: Overflow?
A15: 34.88 | B15: =A15-$B$12 | C15: =MAX(0,A15-$B$6) | D15: =IF(C15<=0,0,($B$7+$B$9*C15)*C15) | E15: =D15*$B$11 | F15: =IF(A15<=INDEX(Stage_Storage!$A$11:$A$18,1),INDEX(Stage_Storage!$E$11:$E$18,1),IF(A15>=INDEX(Stage_Storage!$A$11:$A$18,ROWS(Stage_Storage!$A$11:$A$18)),INDEX(Stage_Storage!$E$11:$E$18,ROWS(Stage_Storage!$E$11:$E$18)),INDEX(Stage_Storage!$E$11:$E$18,MATCH(A15,Stage_Storage!$A$11:$A$18,1))+(A15-INDEX(Stage_Storage!$A$11:$A$18,MATCH(A15,Stage_Storage!$A$11:$A$18,1)))/(INDEX(Stage_Storage!$A$11:$A$18,MATCH(A15,Stage_Storage!$A$11:$A$18,1)+1)-INDEX(Stage_Storage!$A$11:$A$18,MATCH(A15,Stage_Storage!$A$11:$A$18,1)))*(INDEX(Stage_Storage!$E$11:$E$18,MATCH(A15,Stage_Storage!$A$11:$A$18,1)+1)-INDEX(Stage_Storage!$E$11:$E$18,MATCH(A15,Stage_Storage!$A$11:$A$18,1))))) | G15: =E15+F15 | H15: =IF(B15<=0,0,IF(B15>=INDEX(Courbe_QH_900!$A$24:$A$84,ROWS(Courbe_QH_900!$A$24:$A$84)),INDEX(Courbe_QH_900!$E$24:$E$84,ROWS(Courbe_QH_900!$E$24:$E$84)),INDEX(Courbe_QH_900!$E$24:$E$84,MATCH(B15,Courbe_QH_900!$A$24:$A$84,1))+(B15-INDEX(Courbe_QH_900!$A$24:$A$84,MATCH(B15,Courbe_QH_900!$A$24:$A$84,1)))/(INDEX(Courbe_QH_900!$A$24:$A$84,MATCH(B15,Courbe_QH_900!$A$24:$A$84,1)+1)-INDEX(Courbe_QH_900!$A$24:$A$84,MATCH(B15,Courbe_QH_900!$A$24:$A$84,1)))*(INDEX(Courbe_QH_900!$E$24:$E$84,MATCH(B15,Courbe_QH_900!$A$24:$A$84,1)+1)-INDEX(Courbe_QH_900!$E$24:$E$84,MATCH(B15,Courbe_QH_900!$A$24:$A$84,1))))) | I15: =IF(C15<=0,0,IF($B$8<=0,0,(1/$B$8)*D15*IF(($B$7+2*C15*SQRT(1+$B$9^2))<=0,0,((D15/($B$7+2*C15*SQRT(1+$B$9^2)))^(2/3)))*SQRT($B$10))) | J15: =H15+I15 | K15: =IF(C15>0,"oui","non")
A16: 34.93 | B16: =A16-$B$12 | C16: =MAX(0,A16-$B$6) | D16: =IF(C16<=0,0,($B$7+$B$9*C16)*C16) | E16: =D16*$B$11 | F16: =IF(A16<=INDEX(Stage_Storage!$A$11:$A$18,1),INDEX(Stage_Storage!$E$11:$E$18,1),IF(A16>=INDEX(Stage_Storage!$A$11:$A$18,ROWS(Stage_Storage!$A$11:$A$18)),INDEX(Stage_Storage!$E$11:$E$18,ROWS(Stage_Storage!$E$11:$E$18)),INDEX(Stage_Storage!$E$11:$E$18,MATCH(A16,Stage_Storage!$A$11:$A$18,1))+(A16-INDEX(Stage_Storage!$A$11:$A$18,MATCH(A16,Stage_Storage!$A$11:$A$18,1)))/(INDEX(Stage_Storage!$A$11:$A$18,MATCH(A16,Stage_Storage!$A$11:$A$18,1)+1)-INDEX(Stage_Storage!$A$11:$A$18,MATCH(A16,Stage_Storage!$A$11:$A$18,1)))*(INDEX(Stage_Storage!$E$11:$E$18,MATCH(A16,Stage_Storage!$A$11:$A$18,1)+1)-INDEX(Stage_Storage!$E$11:$E$18,MATCH(A16,Stage_Storage!$A$11:$A$18,1))))) | G16: =E16+F16 | H16: =IF(B16<=0,0,IF(B16>=INDEX(Courbe_QH_900!$A$24:$A$84,ROWS(Courbe_QH_900!$A$24:$A$84)),INDEX(Courbe_QH_900!$E$24:$E$84,ROWS(Courbe_QH_900!$E$24:$E$84)),INDEX(Courbe_QH_900!$E$24:$E$84,MATCH(B16,Courbe_QH_900!$A$24:$A$84,1))+(B16-INDEX(Courbe_QH_900!$A$24:$A$84,MATCH(B16,Courbe_QH_900!$A$24:$A$84,1)))/(INDEX(Courbe_QH_900!$A$24:$A$84,MATCH(B16,Courbe_QH_900!$A$24:$A$84,1)+1)-INDEX(Courbe_QH_900!$A$24:$A$84,MATCH(B16,Courbe_QH_900!$A$24:$A$84,1)))*(INDEX(Courbe_QH_900!$E$24:$E$84,MATCH(B16,Courbe_QH_900!$A$24:$A$84,1)+1)-INDEX(Courbe_QH_900!$E$24:$E$84,MATCH(B16,Courbe_QH_900!$A$24:$A$84,1))))) | I16: =IF(C16<=0,0,IF($B$8<=0,0,(1/$B$8)*D16*IF(($B$7+2*C16*SQRT(1+$B$9^2))<=0,0,((D16/($B$7+2*C16*SQRT(1+$B$9^2)))^(2/3)))*SQRT($B$10))) | J16: =H16+I16 | K16: =IF(C16>0,"oui","non")
A17: 34.98 | B17: =A17-$B$12 | C17: =MAX(0,A17-$B$6) | D17: =IF(C17<=0,0,($B$7+$B$9*C17)*C17) | E17: =D17*$B$11 | F17: =IF(A17<=INDEX(Stage_Storage!$A$11:$A$18,1),INDEX(Stage_Storage!$E$11:$E$18,1),IF(A17>=INDEX(Stage_Storage!$A$11:$A$18,ROWS(Stage_Storage!$A$11:$A$18)),INDEX(Stage_Storage!$E$11:$E$18,ROWS(Stage_Storage!$E$11:$E$18)),INDEX(Stage_Storage!$E$11:$E$18,MATCH(A17,Stage_Storage!$A$11:$A$18,1))+(A17-INDEX(Stage_Storage!$A$11:$A$18,MATCH(A17,Stage_Storage!$A$11:$A$18,1)))/(INDEX(Stage_Storage!$A$11:$A$18,MATCH(A17,Stage_Storage!$A$11:$A$18,1)+1)-INDEX(Stage_Storage!$A$11:$A$18,MATCH(A17,Stage_Storage!$A$11:$A$18,1)))*(INDEX(Stage_Storage!$E$11:$E$18,MATCH(A17,Stage_Storage!$A$11:$A$18,1)+1)-INDEX(Stage_Storage!$E$11:$E$18,MATCH(A17,Stage_Storage!$A$11:$A$18,1))))) | G17: =E17+F17 | H17: =IF(B17<=0,0,IF(B17>=INDEX(Courbe_QH_900!$A$24:$A$84,ROWS(Courbe_QH_900!$A$24:$A$84)),INDEX(Courbe_QH_900!$E$24:$E$84,ROWS(Courbe_QH_900!$E$24:$E$84)),INDEX(Courbe_QH_900!$E$24:$E$84,MATCH(B17,Courbe_QH_900!$A$24:$A$84,1))+(B17-INDEX(Courbe_QH_900!$A$24:$A$84,MATCH(B17,Courbe_QH_900!$A$24:$A$84,1)))/(INDEX(Courbe_QH_900!$A$24:$A$84,MATCH(B17,Courbe_QH_900!$A$24:$A$84,1)+1)-INDEX(Courbe_QH_900!$A$24:$A$84,MATCH(B17,Courbe_QH_900!$A$24:$A$84,1)))*(INDEX(Courbe_QH_900!$E$24:$E$84,MATCH(B17,Courbe_QH_900!$A$24:$A$84,1)+1)-INDEX(Courbe_QH_900!$E$24:$E$84,MATCH(B17,Courbe_QH_900!$A$24:$A$84,1))))) | I17: =IF(C17<=0,0,IF($B$8<=0,0,(1/$B$8)*D17*IF(($B$7+2*C17*SQRT(1+$B$9^2))<=0,0,((D17/($B$7+2*C17*SQRT(1+$B$9^2)))^(2/3)))*SQRT($B$10))) | J17: =H17+I17 | K17: =IF(C17>0,"oui","non")
A18: 35.03 | B18: =A18-$B$12 | C18: =MAX(0,A18-$B$6) | D18: =IF(C18<=0,0,($B$7+$B$9*C18)*C18) | E18: =D18*$B$11 | F18: =IF(A18<=INDEX(Stage_Storage!$A$11:$A$18,1),INDEX(Stage_Storage!$E$11:$E$18,1),IF(A18>=INDEX(Stage_Storage!$A$11:$A$18,ROWS(Stage_Storage!$A$11:$A$18)),INDEX(Stage_Storage!$E$11:$E$18,ROWS(Stage_Storage!$E$11:$E$18)),INDEX(Stage_Storage!$E$11:$E$18,MATCH(A18,Stage_Storage!$A$11:$A$18,1))+(A18-INDEX(Stage_Storage!$A$11:$A$18,MATCH(A18,Stage_Storage!$A$11:$A$18,1)))/(INDEX(Stage_Storage!$A$11:$A$18,MATCH(A18,Stage_Storage!$A$11:$A$18,1)+1)-INDEX(Stage_Storage!$A$11:$A$18,MATCH(A18,Stage_Storage!$A$11:$A$18,1)))*(INDEX(Stage_Storage!$E$11:$E$18,MATCH(A18,Stage_Storage!$A$11:$A$18,1)+1)-INDEX(Stage_Storage!$E$11:$E$18,MATCH(A18,Stage_Storage!$A$11:$A$18,1))))) | G18: =E18+F18 | H18: =IF(B18<=0,0,IF(B18>=INDEX(Courbe_QH_900!$A$24:$A$84,ROWS(Courbe_QH_900!$A$24:$A$84)),INDEX(Courbe_QH_900!$E$24:$E$84,ROWS(Courbe_QH_900!$E$24:$E$84)),INDEX(Courbe_QH_900!$E$24:$E$84,MATCH(B18,Courbe_QH_900!$A$24:$A$84,1))+(B18-INDEX(Courbe_QH_900!$A$24:$A$84,MATCH(B18,Courbe_QH_900!$A$24:$A$84,1)))/(INDEX(Courbe_QH_900!$A$24:$A$84,MATCH(B18,Courbe_QH_900!$A$24:$A$84,1)+1)-INDEX(Courbe_QH_900!$A$24:$A$84,MATCH(B18,Courbe_QH_900!$A$24:$A$84,1)))*(INDEX(Courbe_QH_900!$E$24:$E$84,MATCH(B18,Courbe_QH_900!$A$24:$A$84,1)+1)-INDEX(Courbe_QH_900!$E$24:$E$84,MATCH(B18,Courbe_QH_900!$A$24:$A$84,1))))) | I18: =IF(C18<=0,0,IF($B$8<=0,0,(1/$B$8)*D18*IF(($B$7+2*C18*SQRT(1+$B$9^2))<=0,0,((D18/($B$7+2*C18*SQRT(1+$B$9^2)))^(2/3)))*SQRT($B$10))) | J18: =H18+I18 | K18: =IF(C18>0,"oui","non")
A19: 35.08 | B19: =A19-$B$12 | C19: =MAX(0,A19-$B$6) | D19: =IF(C19<=0,0,($B$7+$B$9*C19)*C19) | E19: =D19*$B$11 | F19: =IF(A19<=INDEX(Stage_Storage!$A$11:$A$18,1),INDEX(Stage_Storage!$E$11:$E$18,1),IF(A19>=INDEX(Stage_Storage!$A$11:$A$18,ROWS(Stage_Storage!$A$11:$A$18)),INDEX(Stage_Storage!$E$11:$E$18,ROWS(Stage_Storage!$E$11:$E$18)),INDEX(Stage_Storage!$E$11:$E$18,MATCH(A19,Stage_Storage!$A$11:$A$18,1))+(A19-INDEX(Stage_Storage!$A$11:$A$18,MATCH(A19,Stage_Storage!$A$11:$A$18,1)))/(INDEX(Stage_Storage!$A$11:$A$18,MATCH(A19,Stage_Storage!$A$11:$A$18,1)+1)-INDEX(Stage_Storage!$A$11:$A$18,MATCH(A19,Stage_Storage!$A$11:$A$18,1)))*(INDEX(Stage_Storage!$E$11:$E$18,MATCH(A19,Stage_Storage!$A$11:$A$18,1)+1)-INDEX(Stage_Storage!$E$11:$E$18,MATCH(A19,Stage_Storage!$A$11:$A$18,1))))) | G19: =E19+F19 | H19: =IF(B19<=0,0,IF(B19>=INDEX(Courbe_QH_900!$A$24:$A$84,ROWS(Courbe_QH_900!$A$24:$A$84)),INDEX(Courbe_QH_900!$E$24:$E$84,ROWS(Courbe_QH_900!$E$24:$E$84)),INDEX(Courbe_QH_900!$E$24:$E$84,MATCH(B19,Courbe_QH_900!$A$24:$A$84,1))+(B19-INDEX(Courbe_QH_900!$A$24:$A$84,MATCH(B19,Courbe_QH_900!$A$24:$A$84,1)))/(INDEX(Courbe_QH_900!$A$24:$A$84,MATCH(B19,Courbe_QH_900!$A$24:$A$84,1)+1)-INDEX(Courbe_QH_900!$A$24:$A$84,MATCH(B19,Courbe_QH_900!$A$24:$A$84,1)))*(INDEX(Courbe_QH_900!$E$24:$E$84,MATCH(B19,Courbe_QH_900!$A$24:$A$84,1)+1)-INDEX(Courbe_QH_900!$E$24:$E$84,MATCH(B19,Courbe_QH_900!$A$24:$A$84,1))))) | I19: =IF(C19<=0,0,IF($B$8<=0,0,(1/$B$8)*D19*IF(($B$7+2*C19*SQRT(1+$B$9^2))<=0,0,((D19/($B$7+2*C19*SQRT(1+$B$9^2)))^(2/3)))*SQRT($B$10))) | J19: =H19+I19 | K19: =IF(C19>0,"oui","non")
A20: 35.13 | B20: =A20-$B$12 | C20: =MAX(0,A20-$B$6) | D20: =IF(C20<=0,0,($B$7+$B$9*C20)*C20) | E20: =D20*$B$11 | F20: =IF(A20<=INDEX(Stage_Storage!$A$11:$A$18,1),INDEX(Stage_Storage!$E$11:$E$18,1),IF(A20>=INDEX(Stage_Storage!$A$11:$A$18,ROWS(Stage_Storage!$A$11:$A$18)),INDEX(Stage_Storage!$E$11:$E$18,ROWS(Stage_Storage!$E$11:$E$18)),INDEX(Stage_Storage!$E$11:$E$18,MATCH(A20,Stage_Storage!$A$11:$A$18,1))+(A20-INDEX(Stage_Storage!$A$11:$A$18,MATCH(A20,Stage_Storage!$A$11:$A$18,1)))/(INDEX(Stage_Storage!$A$11:$A$18,MATCH(A20,Stage_Storage!$A$11:$A$18,1)+1)-INDEX(Stage_Storage!$A$11:$A$18,MATCH(A20,Stage_Storage!$A$11:$A$18,1)))*(INDEX(Stage_Storage!$E$11:$E$18,MATCH(A20,Stage_Storage!$A$11:$A$18,1)+1)-INDEX(Stage_Storage!$E$11:$E$18,MATCH(A20,Stage_Storage!$A$11:$A$18,1))))) | G20: =E20+F20 | H20: =IF(B20<=0,0,IF(B20>=INDEX(Courbe_QH_900!$A$24:$A$84,ROWS(Courbe_QH_900!$A$24:$A$84)),INDEX(Courbe_QH_900!$E$24:$E$84,ROWS(Courbe_QH_900!$E$24:$E$84)),INDEX(Courbe_QH_900!$E$24:$E$84,MATCH(B20,Courbe_QH_900!$A$24:$A$84,1))+(B20-INDEX(Courbe_QH_900!$A$24:$A$84,MATCH(B20,Courbe_QH_900!$A$24:$A$84,1)))/(INDEX(Courbe_QH_900!$A$24:$A$84,MATCH(B20,Courbe_QH_900!$A$24:$A$84,1)+1)-INDEX(Courbe_QH_900!$A$24:$A$84,MATCH(B20,Courbe_QH_900!$A$24:$A$84,1)))*(INDEX(Courbe_QH_900!$E$24:$E$84,MATCH(B20,Courbe_QH_900!$A$24:$A$84,1)+1)-INDEX(Courbe_QH_900!$E$24:$E$84,MATCH(B20,Courbe_QH_900!$A$24:$A$84,1))))) | I20: =IF(C20<=0,0,IF($B$8<=0,0,(1/$B$8)*D20*IF(($B$7+2*C20*SQRT(1+$B$9^2))<=0,0,((D20/($B$7+2*C20*SQRT(1+$B$9^2)))^(2/3)))*SQRT($B$10))) | J20: =H20+I20 | K20: =IF(C20>0,"oui","non")
A21: 35.18 | B21: =A21-$B$12 | C21: =MAX(0,A21-$B$6) | D21: =IF(C21<=0,0,($B$7+$B$9*C21)*C21) | E21: =D21*$B$11 | F21: =IF(A21<=INDEX(Stage_Storage!$A$11:$A$18,1),INDEX(Stage_Storage!$E$11:$E$18,1),IF(A21>=INDEX(Stage_Storage!$A$11:$A$18,ROWS(Stage_Storage!$A$11:$A$18)),INDEX(Stage_Storage!$E$11:$E$18,ROWS(Stage_Storage!$E$11:$E$18)),INDEX(Stage_Storage!$E$11:$E$18,MATCH(A21,Stage_Storage!$A$11:$A$18,1))+(A21-INDEX(Stage_Storage!$A$11:$A$18,MATCH(A21,Stage_Storage!$A$11:$A$18,1)))/(INDEX(Stage_Storage!$A$11:$A$18,MATCH(A21,Stage_Storage!$A$11:$A$18,1)+1)-INDEX(Stage_Storage!$A$11:$A$18,MATCH(A21,Stage_Storage!$A$11:$A$18,1)))*(INDEX(Stage_Storage!$E$11:$E$18,MATCH(A21,Stage_Storage!$A$11:$A$18,1)+1)-INDEX(Stage_Storage!$E$11:$E$18,MATCH(A21,Stage_Storage!$A$11:$A$18,1))))) | G21: =E21+F21 | H21: =IF(B21<=0,0,IF(B21>=INDEX(Courbe_QH_900!$A$24:$A$84,ROWS(Courbe_QH_900!$A$24:$A$84)),INDEX(Courbe_QH_900!$E$24:$E$84,ROWS(Courbe_QH_900!$E$24:$E$84)),INDEX(Courbe_QH_900!$E$24:$E$84,MATCH(B21,Courbe_QH_900!$A$24:$A$84,1))+(B21-INDEX(Courbe_QH_900!$A$24:$A$84,MATCH(B21,Courbe_QH_900!$A$24:$A$84,1)))/(INDEX(Courbe_QH_900!$A$24:$A$84,MATCH(B21,Courbe_QH_900!$A$24:$A$84,1)+1)-INDEX(Courbe_QH_900!$A$24:$A$84,MATCH(B21,Courbe_QH_900!$A$24:$A$84,1)))*(INDEX(Courbe_QH_900!$E$24:$E$84,MATCH(B21,Courbe_QH_900!$A$24:$A$84,1)+1)-INDEX(Courbe_QH_900!$E$24:$E$84,MATCH(B21,Courbe_QH_900!$A$24:$A$84,1))))) | I21: =IF(C21<=0,0,IF($B$8<=0,0,(1/$B$8)*D21*IF(($B$7+2*C21*SQRT(1+$B$9^2))<=0,0,((D21/($B$7+2*C21*SQRT(1+$B$9^2)))^(2/3)))*SQRT($B$10))) | J21: =H21+I21 | K21: =IF(C21>0,"oui","non")
A22: 35.23 | B22: =A22-$B$12 | C22: =MAX(0,A22-$B$6) | D22: =IF(C22<=0,0,($B$7+$B$9*C22)*C22) | E22: =D22*$B$11 | F22: =IF(A22<=INDEX(Stage_Storage!$A$11:$A$18,1),INDEX(Stage_Storage!$E$11:$E$18,1),IF(A22>=INDEX(Stage_Storage!$A$11:$A$18,ROWS(Stage_Storage!$A$11:$A$18)),INDEX(Stage_Storage!$E$11:$E$18,ROWS(Stage_Storage!$E$11:$E$18)),INDEX(Stage_Storage!$E$11:$E$18,MATCH(A22,Stage_Storage!$A$11:$A$18,1))+(A22-INDEX(Stage_Storage!$A$11:$A$18,MATCH(A22,Stage_Storage!$A$11:$A$18,1)))/(INDEX(Stage_Storage!$A$11:$A$18,MATCH(A22,Stage_Storage!$A$11:$A$18,1)+1)-INDEX(Stage_Storage!$A$11:$A$18,MATCH(A22,Stage_Storage!$A$11:$A$18,1)))*(INDEX(Stage_Storage!$E$11:$E$18,MATCH(A22,Stage_Storage!$A$11:$A$18,1)+1)-INDEX(Stage_Storage!$E$11:$E$18,MATCH(A22,Stage_Storage!$A$11:$A$18,1))))) | G22: =E22+F22 | H22: =IF(B22<=0,0,IF(B22>=INDEX(Courbe_QH_900!$A$24:$A$84,ROWS(Courbe_QH_900!$A$24:$A$84)),INDEX(Courbe_QH_900!$E$24:$E$84,ROWS(Courbe_QH_900!$E$24:$E$84)),INDEX(Courbe_QH_900!$E$24:$E$84,MATCH(B22,Courbe_QH_900!$A$24:$A$84,1))+(B22-INDEX(Courbe_QH_900!$A$24:$A$84,MATCH(B22,Courbe_QH_900!$A$24:$A$84,1)))/(INDEX(Courbe_QH_900!$A$24:$A$84,MATCH(B22,Courbe_QH_900!$A$24:$A$84,1)+1)-INDEX(Courbe_QH_900!$A$24:$A$84,MATCH(B22,Courbe_QH_900!$A$24:$A$84,1)))*(INDEX(Courbe_QH_900!$E$24:$E$84,MATCH(B22,Courbe_QH_900!$A$24:$A$84,1)+1)-INDEX(Courbe_QH_900!$E$24:$E$84,MATCH(B22,Courbe_QH_900!$A$24:$A$84,1))))) | I22: =IF(C22<=0,0,IF($B$8<=0,0,(1/$B$8)*D22*IF(($B$7+2*C22*SQRT(1+$B$9^2))<=0,0,((D22/($B$7+2*C22*SQRT(1+$B$9^2)))^(2/3)))*SQRT($B$10))) | J22: =H22+I22 | K22: =IF(C22>0,"oui","non")
A23: 35.28 | B23: =A23-$B$12 | C23: =MAX(0,A23-$B$6) | D23: =IF(C23<=0,0,($B$7+$B$9*C23)*C23) | E23: =D23*$B$11 | F23: =IF(A23<=INDEX(Stage_Storage!$A$11:$A$18,1),INDEX(Stage_Storage!$E$11:$E$18,1),IF(A23>=INDEX(Stage_Storage!$A$11:$A$18,ROWS(Stage_Storage!$A$11:$A$18)),INDEX(Stage_Storage!$E$11:$E$18,ROWS(Stage_Storage!$E$11:$E$18)),INDEX(Stage_Storage!$E$11:$E$18,MATCH(A23,Stage_Storage!$A$11:$A$18,1))+(A23-INDEX(Stage_Storage!$A$11:$A$18,MATCH(A23,Stage_Storage!$A$11:$A$18,1)))/(INDEX(Stage_Storage!$A$11:$A$18,MATCH(A23,Stage_Storage!$A$11:$A$18,1)+1)-INDEX(Stage_Storage!$A$11:$A$18,MATCH(A23,Stage_Storage!$A$11:$A$18,1)))*(INDEX(Stage_Storage!$E$11:$E$18,MATCH(A23,Stage_Storage!$A$11:$A$18,1)+1)-INDEX(Stage_Storage!$E$11:$E$18,MATCH(A23,Stage_Storage!$A$11:$A$18,1))))) | G23: =E23+F23 | H23: =IF(B23<=0,0,IF(B23>=INDEX(Courbe_QH_900!$A$24:$A$84,ROWS(Courbe_QH_900!$A$24:$A$84)),INDEX(Courbe_QH_900!$E$24:$E$84,ROWS(Courbe_QH_900!$E$24:$E$84)),INDEX(Courbe_QH_900!$E$24:$E$84,MATCH(B23,Courbe_QH_900!$A$24:$A$84,1))+(B23-INDEX(Courbe_QH_900!$A$24:$A$84,MATCH(B23,Courbe_QH_900!$A$24:$A$84,1)))/(INDEX(Courbe_QH_900!$A$24:$A$84,MATCH(B23,Courbe_QH_900!$A$24:$A$84,1)+1)-INDEX(Courbe_QH_900!$A$24:$A$84,MATCH(B23,Courbe_QH_900!$A$24:$A$84,1)))*(INDEX(Courbe_QH_900!$E$24:$E$84,MATCH(B23,Courbe_QH_900!$A$24:$A$84,1)+1)-INDEX(Courbe_QH_900!$E$24:$E$84,MATCH(B23,Courbe_QH_900!$A$24:$A$84,1))))) | I23: =IF(C23<=0,0,IF($B$8<=0,0,(1/$B$8)*D23*IF(($B$7+2*C23*SQRT(1+$B$9^2))<=0,0,((D23/($B$7+2*C23*SQRT(1+$B$9^2)))^(2/3)))*SQRT($B$10))) | J23: =H23+I23 | K23: =IF(C23>0,"oui","non")
A24: 35.33 | B24: =A24-$B$12 | C24: =MAX(0,A24-$B$6) | D24: =IF(C24<=0,0,($B$7+$B$9*C24)*C24) | E24: =D24*$B$11 | F24: =IF(A24<=INDEX(Stage_Storage!$A$11:$A$18,1),INDEX(Stage_Storage!$E$11:$E$18,1),IF(A24>=INDEX(Stage_Storage!$A$11:$A$18,ROWS(Stage_Storage!$A$11:$A$18)),INDEX(Stage_Storage!$E$11:$E$18,ROWS(Stage_Storage!$E$11:$E$18)),INDEX(Stage_Storage!$E$11:$E$18,MATCH(A24,Stage_Storage!$A$11:$A$18,1))+(A24-INDEX(Stage_Storage!$A$11:$A$18,MATCH(A24,Stage_Storage!$A$11:$A$18,1)))/(INDEX(Stage_Storage!$A$11:$A$18,MATCH(A24,Stage_Storage!$A$11:$A$18,1)+1)-INDEX(Stage_Storage!$A$11:$A$18,MATCH(A24,Stage_Storage!$A$11:$A$18,1)))*(INDEX(Stage_Storage!$E$11:$E$18,MATCH(A24,Stage_Storage!$A$11:$A$18,1)+1)-INDEX(Stage_Storage!$E$11:$E$18,MATCH(A24,Stage_Storage!$A$11:$A$18,1))))) | G24: =E24+F24 | H24: =IF(B24<=0,0,IF(B24>=INDEX(Courbe_QH_900!$A$24:$A$84,ROWS(Courbe_QH_900!$A$24:$A$84)),INDEX(Courbe_QH_900!$E$24:$E$84,ROWS(Courbe_QH_900!$E$24:$E$84)),INDEX(Courbe_QH_900!$E$24:$E$84,MATCH(B24,Courbe_QH_900!$A$24:$A$84,1))+(B24-INDEX(Courbe_QH_900!$A$24:$A$84,MATCH(B24,Courbe_QH_900!$A$24:$A$84,1)))/(INDEX(Courbe_QH_900!$A$24:$A$84,MATCH(B24,Courbe_QH_900!$A$24:$A$84,1)+1)-INDEX(Courbe_QH_900!$A$24:$A$84,MATCH(B24,Courbe_QH_900!$A$24:$A$84,1)))*(INDEX(Courbe_QH_900!$E$24:$E$84,MATCH(B24,Courbe_QH_900!$A$24:$A$84,1)+1)-INDEX(Courbe_QH_900!$E$24:$E$84,MATCH(B24,Courbe_QH_900!$A$24:$A$84,1))))) | I24: =IF(C24<=0,0,IF($B$8<=0,0,(1/$B$8)*D24*IF(($B$7+2*C24*SQRT(1+$B$9^2))<=0,0,((D24/($B$7+2*C24*SQRT(1+$B$9^2)))^(2/3)))*SQRT($B$10))) | J24: =H24+I24 | K24: =IF(C24>0,"oui","non")
A25: 35.38 | B25: =A25-$B$12 | C25: =MAX(0,A25-$B$6) | D25: =IF(C25<=0,0,($B$7+$B$9*C25)*C25) | E25: =D25*$B$11 | F25: =IF(A25<=INDEX(Stage_Storage!$A$11:$A$18,1),INDEX(Stage_Storage!$E$11:$E$18,1),IF(A25>=INDEX(Stage_Storage!$A$11:$A$18,ROWS(Stage_Storage!$A$11:$A$18)),INDEX(Stage_Storage!$E$11:$E$18,ROWS(Stage_Storage!$E$11:$E$18)),INDEX(Stage_Storage!$E$11:$E$18,MATCH(A25,Stage_Storage!$A$11:$A$18,1))+(A25-INDEX(Stage_Storage!$A$11:$A$18,MATCH(A25,Stage_Storage!$A$11:$A$18,1)))/(INDEX(Stage_Storage!$A$11:$A$18,MATCH(A25,Stage_Storage!$A$11:$A$18,1)+1)-INDEX(Stage_Storage!$A$11:$A$18,MATCH(A25,Stage_Storage!$A$11:$A$18,1)))*(INDEX(Stage_Storage!$E$11:$E$18,MATCH(A25,Stage_Storage!$A$11:$A$18,1)+1)-INDEX(Stage_Storage!$E$11:$E$18,MATCH(A25,Stage_Storage!$A$11:$A$18,1))))) | G25: =E25+F25 | H25: =IF(B25<=0,0,IF(B25>=INDEX(Courbe_QH_900!$A$24:$A$84,ROWS(Courbe_QH_900!$A$24:$A$84)),INDEX(Courbe_QH_900!$E$24:$E$84,ROWS(Courbe_QH_900!$E$24:$E$84)),INDEX(Courbe_QH_900!$E$24:$E$84,MATCH(B25,Courbe_QH_900!$A$24:$A$84,1))+(B25-INDEX(Courbe_QH_900!$A$24:$A$84,MATCH(B25,Courbe_QH_900!$A$24:$A$84,1)))/(INDEX(Courbe_QH_900!$A$24:$A$84,MATCH(B25,Courbe_QH_900!$A$24:$A$84,1)+1)-INDEX(Courbe_QH_900!$A$24:$A$84,MATCH(B25,Courbe_QH_900!$A$24:$A$84,1)))*(INDEX(Courbe_QH_900!$E$24:$E$84,MATCH(B25,Courbe_QH_900!$A$24:$A$84,1)+1)-INDEX(Courbe_QH_900!$E$24:$E$84,MATCH(B25,Courbe_QH_900!$A$24:$A$84,1))))) | I25: =IF(C25<=0,0,IF($B$8<=0,0,(1/$B$8)*D25*IF(($B$7+2*C25*SQRT(1+$B$9^2))<=0,0,((D25/($B$7+2*C25*SQRT(1+$B$9^2)))^(2/3)))*SQRT($B$10))) | J25: =H25+I25 | K25: =IF(C25>0,"oui","non")
A26: 35.43 | B26: =A26-$B$12 | C26: =MAX(0,A26-$B$6) | D26: =IF(C26<=0,0,($B$7+$B$9*C26)*C26) | E26: =D26*$B$11 | F26: =IF(A26<=INDEX(Stage_Storage!$A$11:$A$18,1),INDEX(Stage_Storage!$E$11:$E$18,1),IF(A26>=INDEX(Stage_Storage!$A$11:$A$18,ROWS(Stage_Storage!$A$11:$A$18)),INDEX(Stage_Storage!$E$11:$E$18,ROWS(Stage_Storage!$E$11:$E$18)),INDEX(Stage_Storage!$E$11:$E$18,MATCH(A26,Stage_Storage!$A$11:$A$18,1))+(A26-INDEX(Stage_Storage!$A$11:$A$18,MATCH(A26,Stage_Storage!$A$11:$A$18,1)))/(INDEX(Stage_Storage!$A$11:$A$18,MATCH(A26,Stage_Storage!$A$11:$A$18,1)+1)-INDEX(Stage_Storage!$A$11:$A$18,MATCH(A26,Stage_Storage!$A$11:$A$18,1)))*(INDEX(Stage_Storage!$E$11:$E$18,MATCH(A26,Stage_Storage!$A$11:$A$18,1)+1)-INDEX(Stage_Storage!$E$11:$E$18,MATCH(A26,Stage_Storage!$A$11:$A$18,1))))) | G26: =E26+F26 | H26: =IF(B26<=0,0,IF(B26>=INDEX(Courbe_QH_900!$A$24:$A$84,ROWS(Courbe_QH_900!$A$24:$A$84)),INDEX(Courbe_QH_900!$E$24:$E$84,ROWS(Courbe_QH_900!$E$24:$E$84)),INDEX(Courbe_QH_900!$E$24:$E$84,MATCH(B26,Courbe_QH_900!$A$24:$A$84,1))+(B26-INDEX(Courbe_QH_900!$A$24:$A$84,MATCH(B26,Courbe_QH_900!$A$24:$A$84,1)))/(INDEX(Courbe_QH_900!$A$24:$A$84,MATCH(B26,Courbe_QH_900!$A$24:$A$84,1)+1)-INDEX(Courbe_QH_900!$A$24:$A$84,MATCH(B26,Courbe_QH_900!$A$24:$A$84,1)))*(INDEX(Courbe_QH_900!$E$24:$E$84,MATCH(B26,Courbe_QH_900!$A$24:$A$84,1)+1)-INDEX(Courbe_QH_900!$E$24:$E$84,MATCH(B26,Courbe_QH_900!$A$24:$A$84,1))))) | I26: =IF(C26<=0,0,IF($B$8<=0,0,(1/$B$8)*D26*IF(($B$7+2*C26*SQRT(1+$B$9^2))<=0,0,((D26/($B$7+2*C26*SQRT(1+$B$9^2)))^(2/3)))*SQRT($B$10))) | J26: =H26+I26 | K26: =IF(C26>0,"oui","non")
... A107: 39.48 | B107: =A107-$B$12 | C107: =MAX(0,A107-$B$6) | D107: =IF(C107<=0,0,($B$7+$B$9*C107)*C107) | E107: =D107*$B$11 | F107: =IF(A107<=INDEX(Stage_Storage!$A$11:$A$18,1),INDEX(Stage_Storage!$E$11:$E$18,1),IF(A107>=INDEX(Stage_Storage!$A$11:$A$18,ROWS(Stage_Storage!$A$11:$A$18)),INDEX(Stage_Storage!$E$11:$E$18,ROWS(Stage_Storage!$E$11:$E$18)),INDEX(Stage_Storage!$E$11:$E$18,MATCH(A107,Stage_Storage!$A$11:$A$18,1))+(A107-INDEX(Stage_Storage!$A$11:$A$18,MATCH(A107,Stage_Storage!$A$11:$A$18,1)))/(INDEX(Stage_Storage!$A$11:$A$18,MATCH(A107,Stage_Storage!$A$11:$A$18,1)+1)-INDEX(Stage_Storage!$A$11:$A$18,MATCH(A107,Stage_Storage!$A$11:$A$18,1)))*(INDEX(Stage_Storage!$E$11:$E$18,MATCH(A107,Stage_Storage!$A$11:$A$18,1)+1)-INDEX(Stage_Storage!$E$11:$E$18,MATCH(A107,Stage_Storage!$A$11:$A$18,1))))) | G107: =E107+F107 | H107: =IF(B107<=0,0,IF(B107>=INDEX(Courbe_QH_900!$A$24:$A$84,ROWS(Courbe_QH_900!$A$24:$A$84)),INDEX(Courbe_QH_900!$E$24:$E$84,ROWS(Courbe_QH_900!$E$24:$E$84)),INDEX(Courbe_QH_900!$E$24:$E$84,MATCH(B107,Courbe_QH_900!$A$24:$A$84,1))+(B107-INDEX(Courbe_QH_900!$A$24:$A$84,MATCH(B107,Courbe_QH_900!$A$24:$A$84,1)))/(INDEX(Courbe_QH_900!$A$24:$A$84,MATCH(B107,Courbe_QH_900!$A$24:$A$84,1)+1)-INDEX(Courbe_QH_900!$A$24:$A$84,MATCH(B107,Courbe_QH_900!$A$24:$A$84,1)))*(INDEX(Courbe_QH_900!$E$24:$E$84,MATCH(B107,Courbe_QH_900!$A$24:$A$84,1)+1)-INDEX(Courbe_QH_900!$E$24:$E$84,MATCH(B107,Courbe_QH_900!$A$24:$A$84,1))))) | I107: =IF(C107<=0,0,IF($B$8<=0,0,(1/$B$8)*D107*IF(($B$7+2*C107*SQRT(1+$B$9^2))<=0,0,((D107/($B$7+2*C107*SQRT(1+$B$9^2)))^(2/3)))*SQRT($B$10))) | J107: =H107+I107 | K107: =IF(C107>0,"oui","non")

Sheet Calcul_C
A1: Méthode C — routage avec Qout composé + V = V_pond + V_ditch
A2: À chaque pas: WSE lu sur Compose_900!V_total → Qout sur Compose_900. ΔV = (Qin_moy − Qout)×Δt. Si V≈0, Qout = MIN(Qin, Q_plein).
A5: Q_plein réf. (m³/s) | B5: =Parametres!B22
A6: Crest (m) | B6: =Parametres!B27
A7: Vmax_C (m³) | B7: =MAX(F12:F24)
A8: WSEmax_C (m) | B8: =MAX(C12:C24)
A9: Overflow atteint? | B9: =IF(B8>$B$6,"oui — WSE > crest","non — pipe seul")
A11: t (min) | B11: Qin | C11: WSE (m) | D11: Qout | E11: Δt (s) | F11: V (m³) | G11: Overflow?
A12: =Hydrogramme!A8 | B12: =Hydrogramme!C8 | C12: =34.88 | D12: =MIN(B12,$B$5) | E12: 0 | F12: 0 | G12: non
