Workbook

Sheet Parametres
A1: Retention SANS Ø900 — control = Ø1200 (+ overflow optionnel)
A2: Hypotheses: le Ø900 est elimine; un seul bassin (surfaces = Zone1+Zone2 du leve). Entree = hydrogramme (Ø1500). Sortie = Ø1200. Limite ville WSE = 37.40 m (B27). B25=0 → volume = leve seul (pas de V_ditch). Cellules JAUNES = entrees. Aluminium ondule: augmenter n (ex. 0.024) sur Courbe_QH_1200.
A5: Schema
A6: Ø1500 (in) → bassin de retention (agrandi) → Ø1200 (controle) → exutoire
A7: Ø900: SUPPRIME (plus de goulot amont du Ø1200)
A9: Ø1200 — geometrie et Manning (jaune)
A10: n Manning (-) | B10: 0.013 | C10: beton ~0.013; aluminium ondule typ. 0.022–0.025 (changer aussi Courbe_QH_1200)
A11: D (m) | B11: 1.2
A12: L (m) | B12: 31.3
A13: Radier amont Zin (m) | B13: 33.6
A14: Radier aval Zout (m) | B14: 33.1
A15: S0 = (Zin-Zout)/L | B15: =(B13-B14)/B12
A16: A = PI()*D^2/4 (m2) | B16: =PI()*B11^2/4
A17: R = D/4 (m) | B17: =B11/4
A18: Q_plein = (1/n)*A*R^(2/3)*SQRT(S0) | B18: =(1/B10)*B16*(B17^(2/3))*SQRT(B15) | C18: m3/s — formule live
A19: Fond bassin / NSE min (m) | B19: 34.88 | C19: Depart Stage_Storage (ex-radier zone Ø900)
A21: Entrees routage (jaune)
A22: Qout_cap (m3/s) Methode A | B22: =B18 | C22: Par defaut = Q_plein Ø1200; ecraser si besoin
A23: Facteur_securite (-) | B23: 1.2
A24: Aire_plan_eau_m2 (approx Methode B) | B24: 2320 | C24: Raccourci Methode B seulement (H=V/A). Ex. A@37.40≈2320 — PAS un 2e bassin
A25: Inclure V_ditch trapeze? (1=oui, 0=leve seul) | B25: 0 | C25: 0 = recommande si Stage_Storage contient deja le fosse (V=leve seul; Q_overflow garde b,z,L). 1 = ajoute V_ditch = A_trapeze x L (risque double volume).
A26: Overflow optionnel — fosse/berme au-dessus d'un crest (jaune)
A27: Crest (m) | B27: 37.4 | C27: Limite ville = 37.40 m par defaut. Si WSE < crest → Q_overflow = 0
A28: b fond (m) | B28: 2
A29: n fosse (-) | B29: 0.035
A30: z (H:V) | B30: 2
A31: S fosse (-) | B31: 0.0085 | C31: Pente fosse (pas 0.085)
A32: L fosse (m) | B32: 50.1
A33: Qout compose | B33: Q_1200(WSE) + Q_overflow(WSE) | C33: =IF(B25=1,"V=V_pond+V_ditch","V=V_pond (leve seul, B25=0)") — Compose_1200 + Calcul_C
A35: Resultats Methode A — Qout constant Ø1200 (Calcul_A)
A36: Vmax_A (m3) | B36: =Calcul_A!B3
A37: V_dim_A = Vmax_A * facteur | B37: =B36*B23
A38: WSEmax_A (m) depuis leve | B38: =IF(B36<=Stage_Storage!E11,Stage_Storage!A11,IF(B36>=Stage_Storage!E18,"Hors table (>=40.0 m — etendre leve)",INDEX(Stage_Storage!$A$11:$A$18,MATCH(B36,Stage_Storage!$E$11:$E$18,1))+(B36-INDEX(Stage_Storage!$E$11:$E$18,MATCH(B36,Stage_Storage!$E$11:$E$18,1)))/(INDEX(Stage_Storage!$E$11:$E$18,MATCH(B36,Stage_Storage!$E$11:$E$18,1)+1)-INDEX(Stage_Storage!$E$11:$E$18,MATCH(B36,Stage_Storage!$E$11:$E$18,1)))*(INDEX(Stage_Storage!$A$11:$A$18,MATCH(B36,Stage_Storage!$E$11:$E$18,1)+1)-INDEX(Stage_Storage!$A$11:$A$18,MATCH(B36,Stage_Storage!$E$11:$E$18,1)))))
A39: HW_A = WSEmax_A - Zin_1200 (m) | B39: =IF(ISNUMBER(B38),B38-B13,"")
A41: Resultats Methode B — Q=f(H) pipe Ø1200 (Calcul_B)
A42: Vmax_B (m3) | B42: =Calcul_B!B7
A43: V_dim_B | B43: =B42*B23
A44: WSEmax_B (m) depuis leve | B44: =IF(B42<=Stage_Storage!E11,Stage_Storage!A11,IF(B42>=Stage_Storage!E18,"Hors table (>=40.0 m — etendre leve)",INDEX(Stage_Storage!$A$11:$A$18,MATCH(B42,Stage_Storage!$E$11:$E$18,1))+(B42-INDEX(Stage_Storage!$E$11:$E$18,MATCH(B42,Stage_Storage!$E$11:$E$18,1)))/(INDEX(Stage_Storage!$E$11:$E$18,MATCH(B42,Stage_Storage!$E$11:$E$18,1)+1)-INDEX(Stage_Storage!$E$11:$E$18,MATCH(B42,Stage_Storage!$E$11:$E$18,1)))*(INDEX(Stage_Storage!$A$11:$A$18,MATCH(B42,Stage_Storage!$E$11:$E$18,1)+1)-INDEX(Stage_Storage!$A$11:$A$18,MATCH(B42,Stage_Storage!$E$11:$E$18,1)))))
A45: Hmax_B approx = Vmax_B / Aire (m) | B45: =IF(B24>0,B42/B24,0)
A47: Resultats Methode C — Ø1200 + Q_overflow (V via B25)
...

Sheet Hydrogramme
A1: Hydrogramme d'entree (Ø1500 / entree retention) — LIVE
A2: Qin(t) = ratio(t) × Qpointe. Changez B4 (jaune) → Calcul_A/B/C se mettent a jour.
A4: Qpointe (m3/s) | B4: 9.6
A6: t (min) | B6: ratio | C6: Qin (m3/s)
A7: 0 | B7: 0.081042 | C7: =B7*$B$4
A8: 5 | B8: 0.121875 | C8: =B8*$B$4
A9: 10 | B9: 0.193438 | C9: =B9*$B$4
A10: 15 | B10: 0.333542 | C10: =B10*$B$4
A11: 20 | B11: 0.657188 | C11: =B11*$B$4
A12: 22.5 | B12: 1 | C12: =B12*$B$4
A13: 27.5 | B13: 0.608958 | C13: =B13*$B$4
A14: 32.5 | B14: 0.401771 | C14: =B14*$B$4
A15: 37.5 | B15: 0.280104 | C15: =B15*$B$4
A16: 42.5 | B16: 0.203438 | C16: =B16*$B$4
A17: 47.5 | B17: 0.152292 | C17: =B17*$B$4
A18: 52.5 | B18: 0.116771 | C18: =B18*$B$4
A19: 57.5 | B19: 0.091146 | C19: =B19*$B$4
A22: Qin max | B22: =MAX(C7:C19)

Sheet Calcul_A
A1: Methode A — Qout constant = Qout_cap (Ø1200)
A2: Qout | B2: =Parametres!B22
A3: Vmax_A (m3) | B3: =MAX(E8:E20)
A7: t (min) | B7: Qin | C7: Qout | D7: dt (s) | E7: V (m3) | F7: V_Ø1200 (m/s)
A8: =Hydrogramme!A7 | B8: =Hydrogramme!C7 | C8: =$B$2 | D8: 0 | E8: 0 | F8: =IF(Parametres!$C$96<=0,0,C8/Parametres!$C$96)
A9: =Hydrogramme!A8 | B9: =Hydrogramme!C8 | C9: =$B$2 | D9: =(A9-A8)*60 | E9: =MAX(0,E8+(0.5*(B8+B9)-C9)*D9) | F9: =IF(Parametres!$C$96<=0,0,C9/Parametres!$C$96)
A10: =Hydrogramme!A9 | B10: =Hydrogramme!C9 | C10: =$B$2 | D10: =(A10-A9)*60 | E10: =MAX(0,E9+(0.5*(B9+B10)-C10)*D10) | F10: =IF(Parametres!$C$96<=0,0,C10/Parametres!$C$96)
A11: =Hydrogramme!A10 | B11: =Hydrogramme!C10 | C11: =$B$2 | D11: =(A11-A10)*60 | E11: =MAX(0,E10+(0.5*(B10+B11)-C11)*D11) | F11: =IF(Parametres!$C$96<=0,0,C11/Parametres!$C$96)
A12: =Hydrogramme!A11 | B12: =Hydrogramme!C11 | C12: =$B$2 | D12: =(A12-A11)*60 | E12: =MAX(0,E11+(0.5*(B11+B12)-C12)*D12) | F12: =IF(Parametres!$C$96<=0,0,C12/Parametres!$C$96)
A13: =Hydrogramme!A12 | B13: =Hydrogramme!C12 | C13: =$B$2 | D13: =(A13-A12)*60 | E13: =MAX(0,E12+(0.5*(B12+B13)-C13)*D13) | F13: =IF(Parametres!$C$96<=0,0,C13/Parametres!$C$96)
A14: =Hydrogramme!A13 | B14: =Hydrogramme!C13 | C14: =$B$2 | D14: =(A14-A13)*60 | E14: =MAX(0,E13+(0.5*(B13+B14)-C14)*D14) | F14: =IF(Parametres!$C$96<=0,0,C14/Parametres!$C$96)
A15: =Hydrogramme!A14 | B15: =Hydrogramme!C14 | C15: =$B$2 | D15: =(A15-A14)*60 | E15: =MAX(0,E14+(0.5*(B14+B15)-C15)*D15) | F15: =IF(Parametres!$C$96<=0,0,C15/Parametres!$C$96)
A16: =Hydrogramme!A15 | B16: =Hydrogramme!C15 | C16: =$B$2 | D16: =(A16-A15)*60 | E16: =MAX(0,E15+(0.5*(B15+B16)-C16)*D16) | F16: =IF(Parametres!$C$96<=0,0,C16/Parametres!$C$96)
A17: =Hydrogramme!A16 | B17: =Hydrogramme!C16 | C17: =$B$2 | D17: =(A17-A16)*60 | E17: =MAX(0,E16+(0.5*(B16+B17)-C17)*D17) | F17: =IF(Parametres!$C$96<=0,0,C17/Parametres!$C$96)
A18: =Hydrogramme!A17 | B18: =Hydrogramme!C17 | C18: =$B$2 | D18: =(A18-A17)*60 | E18: =MAX(0,E17+(0.5*(B17+B18)-C18)*D18) | F18: =IF(Parametres!$C$96<=0,0,C18/Parametres!$C$96)
A19: =Hydrogramme!A18 | B19: =Hydrogramme!C18 | C19: =$B$2 | D19: =(A19-A18)*60 | E19: =MAX(0,E18+(0.5*(B18+B19)-C19)*D19) | F19: =IF(Parametres!$C$96<=0,0,C19/Parametres!$C$96)
A20: =Hydrogramme!A19 | B20: =Hydrogramme!C19 | C20: =$B$2 | D20: =(A20-A19)*60 | E20: =MAX(0,E19+(0.5*(B19+B20)-C20)*D20) | F20: =IF(Parametres!$C$96<=0,0,C20/Parametres!$C$96)

Sheet Courbe_QH_1200
A1: Courbe Q=f(H) Ø1200 — FHWA HDS-5 (inlet + outlet) LIVE
A2: Parametres lies a Parametres!B10–B14. Q_gouvernant = MIN(Qinlet, Qoutlet).
A4: n | B4: =Parametres!B10 | E4: entree | F4: K | G4: M | H4: c | I4: Y | J4: Ke
A5: D (m) | B5: =Parametres!B11 | E5: square_edge | F5: 0.0098 | G5: 2 | H5: 0.0398 | I5: 0.67 | J5: 0.5
A6: L (m) | B6: =Parametres!B12 | E6: beveled | F6: 0.0018 | G6: 2.5 | H6: 0.03 | I6: 0.74 | J6: 0.2
A7: Zin (m) | B7: =Parametres!B13 | E7: groove_headwall | F7: 0.0078 | G7: 2 | H7: 0.0292 | I7: 0.74 | J7: 0.2
A8: Zout (m) | B8: =Parametres!B14
A9: S0 | B9: =Parametres!B15
A10: TW au-dessus Zout (m) | B10: 0
A11: Entree | B11: square_edge | C11: square_edge | beveled | groove_headwall
A13: K | B13: =IFERROR(VLOOKUP(B11,$E$5:$J$7,2,FALSE),0.0098)
A14: M | B14: =IFERROR(VLOOKUP(B11,$E$5:$J$7,3,FALSE),2)
A15: c | B15: =IFERROR(VLOOKUP(B11,$E$5:$J$7,4,FALSE),0.0398)
A16: Y | B16: =IFERROR(VLOOKUP(B11,$E$5:$J$7,5,FALSE),0.67)
A17: Ke | B17: =IFERROR(VLOOKUP(B11,$E$5:$J$7,6,FALSE),0.5)
A19: HW (m) | B19: WSE (m) | C19: Qinlet | D19: Qoutlet | E19: Q gouvernant | F19: A_ecoul (m2) | G19: V_gouv (m/s)
A20: 0 | B20: =$B$7+A20 | C20: =IF(A20<=0,0,IF(A20<=1.2*$B$5,1.811*(PI()*($B$5/2)^2)*SQRT($B$5)*IF($B$13*$B$5<=0,0,(A20/($B$13*$B$5))^(1/$B$14)),MAX(1.811*(PI()*($B$5/2)^2)*SQRT($B$5)*IF($B$13*$B$5<=0,0,((1.2*$B$5)/($B$13*$B$5))^(1/$B$14)),1.811*(PI()*($B$5/2)^2)*SQRT($B$5)*SQRT(MAX(0,(A20/$B$5-$B$16)/$B$15))))) | D20: =IF(A20<$B$5,IF($B$4<=0,0,(1/$B$4)*((($B$5/2)^2/2)*((2*ACOS(1-2*(MIN(0.999,MAX(1E-6,A20/$B$5)))))-SIN(2*ACOS(1-2*(MIN(0.999,MAX(1E-6,A20/$B$5)))))))*IF((IF((($B$5/2)*(2*ACOS(1-2*(MIN(0.999,MAX(1E-6,A20/$B$5))))))<=0,0,((($B$5/2)^2/2)*((2*ACOS(1-2*(MIN(0.999,MAX(1E-6,A20/$B$5)))))-SIN(2*ACOS(1-2*(MIN(0.999,MAX(1E-6,A20/$B$5)))))))/(($B$5/2)*(2*ACOS(1-2*(MIN(0.999,MAX(1E-6,A20/$B$5))))))))<=0,0,(IF((($B$5/2)*(2*ACOS(1-2*(MIN(0.999,MAX(1E-6,A20/$B$5))))))<=0,0,((($B$5/2)^2/2)*((2*ACOS(1-2*(MIN(0.999,MAX(1E-6,A20/$B$5)))))-SIN(2*ACOS(1-2*(MIN(0.999,MAX(1E-6,A20/$B$5)))))))/(($B$5/2)*(2*ACOS(1-2*(MIN(0.999,MAX(1E-6,A20/$B$5))))))))^(2/3))*SQRT($B$9)),IF((A20-$B$10+$B$9*$B$6)<=0,0,(PI()*($B$5/2)^2)*SQRT((A20-$B$10+$B$9*$B$6)/((1+$B$17)/(2*9.81)+($B$4^2)*$B$6/(($B$5/4)^(4/3)))))) | E20: =MIN(C20,D20) | F20: =IF(A20<=0,0,IF(A20<$B$5,(($B$5/2)^2/2)*((2*ACOS(1-2*(MIN(0.999,MAX(1E-6,A20/$B$5)))))-SIN(2*ACOS(1-2*(MIN(0.999,MAX(1E-6,A20/$B$5)))))),(PI()*($B$5/2)^2))) | G20: =IF(F20<=0,0,E20/F20)
A21: 0.05 | B21: =$B$7+A21 | C21: =IF(A21<=0,0,IF(A21<=1.2*$B$5,1.811*(PI()*($B$5/2)^2)*SQRT($B$5)*IF($B$13*$B$5<=0,0,(A21/($B$13*$B$5))^(1/$B$14)),MAX(1.811*(PI()*($B$5/2)^2)*SQRT($B$5)*IF($B$13*$B$5<=0,0,((1.2*$B$5)/($B$13*$B$5))^(1/$B$14)),1.811*(PI()*($B$5/2)^2)*SQRT($B$5)*SQRT(MAX(0,(A21/$B$5-$B$16)/7))))) | D21: =IF(A21<$B$5,IF($B$4<=0,0,(1/$B$4)*((($B$5/2)^2/2)*((2*ACOS(1-2*(MIN(0.999,MAX(1E-6,A21/$B$5)))))-SIN(2*ACOS(1-2*(MIN(0.999,MAX(1E-6,A21/$B$5)))))))*IF((IF((($B$5/2)*(2*ACOS(1-2*(MIN(0.999,MAX(1E-6,A21/$B$5))))))<=0,0,((($B$5/2)^2/2)*((2*ACOS(1-2*(MIN(0.999,MAX(1E-6,A21/$B$5)))))-SIN(2*ACOS(1-2*(MIN(0.999,MAX(1E-6,A21/$B$5)))))))/(($B$5/2)*(2*ACOS(1-2*(MIN(0.999,MAX(1E-6,A21/$B$5))))))))<=0,0,(IF((($B$5/2)*(2*ACOS(1-2*(MIN(0.999,MAX(1E-6,A21/$B$5))))))<=0,0,((($B$5/2)^2/2)*((2*ACOS(1-2*(MIN(0.999,MAX(1E-6,A21/$B$5)))))-SIN(2*ACOS(1-2*(MIN(0.999,MAX(1E-6,A21/$B$5)))))))/(($B$5/2)*(2*ACOS(1-2*(MIN(0.999,MAX(1E-6,A21/$B$5))))))))^(2/3))*SQRT($B$9)),IF((A21-$B$10+$B$9*$B$6)<=0,0,(PI()*($B$5/2)^2)*SQRT((A21-$B$10+$B$9*$B$6)/((1+$B$17)/(2*9.81)+($B$4^2)*$B$6/(($B$5/4)^(4/3)))))) | E21: =MIN(C21,D21) | F21: =IF(A21<=0,0,IF(A21<$B$5,(($B$5/2)^2/2)*((2*ACOS(1-2*(MIN(0.999,MAX(1E-6,A21/$B$5)))))-SIN(2*ACOS(1-2*(MIN(0.999,MAX(1E-6,A21/$B$5)))))),(PI()*($B$5/2)^2))) | G21: =IF(F21<=0,0,E21/F21)
A22: 0.1 | B22: =$B$7+A22 | C22: =IF(A22<=0,0,IF(A22<=1.2*$B$5,1.811*(PI()*($B$5/2)^2)*SQRT($B$5)*IF($B$13*$B$5<=0,0,(A22/($B$13*$B$5))^(1/$B$14)),MAX(1.811*(PI()*($B$5/2)^2)*SQRT($B$5)*IF($B$13*$B$5<=0,0,((1.2*$B$5)/($B$13*$B$5))^(1/$B$14)),1.811*(PI()*($B$5/2)^2)*SQRT($B$5)*SQRT(MAX(0,(A22/$B$5-$B$16)/7))))) | D22: =IF(A22<$B$5,IF($B$4<=0,0,(1/$B$4)*((($B$5/2)^2/2)*((2*ACOS(1-2*(MIN(0.999,MAX(1E-6,A22/$B$5)))))-SIN(2*ACOS(1-2*(MIN(0.999,MAX(1E-6,A22/$B$5)))))))*IF((IF((($B$5/2)*(2*ACOS(1-2*(MIN(0.999,MAX(1E-6,A22/$B$5))))))<=0,0,((($B$5/2)^2/2)*((2*ACOS(1-2*(MIN(0.999,MAX(1E-6,A22/$B$5)))))-SIN(2*ACOS(1-2*(MIN(0.999,MAX(1E-6,A22/$B$5)))))))/(($B$5/2)*(2*ACOS(1-2*(MIN(0.999,MAX(1E-6,A22/$B$5))))))))<=0,0,(IF((($B$5/2)*(2*ACOS(1-2*(MIN(0.999,MAX(1E-6,A22/$B$5))))))<=0,0,((($B$5/2)^2/2)*((2*ACOS(1-2*(MIN(0.999,MAX(1E-6,A22/$B$5)))))-SIN(2*ACOS(1-2*(MIN(0.999,MAX(1E-6,A22/$B$5)))))))/(($B$5/2)*(2*ACOS(1-2*(MIN(0.999,MAX(1E-6,A22/$B$5))))))))^(2/3))*SQRT($B$9)),IF((A22-$B$10+$B$9*$B$6)<=0,0,(PI()*($B$5/2)^2)*SQRT((A22-$B$10+$B$9*$B$6)/((1+$B$17)/(2*9.81)+($B$4^2)*$B$6/(($B$5/4)^(4/3)))))) | E22: =MIN(C22,D22) | F22: =IF(A22<=0,0,IF(A22<$B$5,(($B$5/2)^2/2)*((2*ACOS(1-2*(MIN(0.999,MAX(1E-6,A22/$B$5)))))-SIN(2*ACOS(1-2*(MIN(0.999,MAX(1E-6,A22/$B$5)))))),(PI()*($B$5/2)^2))) | G22: =IF(F22<=0,0,E22/F22)
A23: 0.15 | B23: =$B$7+A23 | C23: =IF(A23<=0,0,IF(A23<=1.2*$B$5,1.811*(PI()*($B$5/2)^2)*SQRT($B$5)*IF($B$13*$B$5<=0,0,(A23/($B$13*$B$5))^(1/$B$14)),MAX(1.811*(PI()*($B$5/2)^2)*SQRT($B$5)*IF($B$13*$B$5<=0,0,((1.2*$B$5)/($B$13*$B$5))^(1/$B$14)),1.811*(PI()*($B$5/2)^2)*SQRT($B$5)*SQRT(MAX(0,(A23/$B$5-$B$16)/7))))) | D23: =IF(A23<$B$5,IF($B$4<=0,0,(1/$B$4)*((($B$5/2)^2/2)*((2*ACOS(1-2*(MIN(0.999,MAX(1E-6,A23/$B$5)))))-SIN(2*ACOS(1-2*(MIN(0.999,MAX(1E-6,A23/$B$5)))))))*IF((IF((($B$5/2)*(2*ACOS(1-2*(MIN(0.999,MAX(1E-6,A23/$B$5))))))<=0,0,((($B$5/2)^2/2)*((2*ACOS(1-2*(MIN(0.999,MAX(1E-6,A23/$B$5)))))-SIN(2*ACOS(1-2*(MIN(0.999,MAX(1E-6,A23/$B$5)))))))/(($B$5/2)*(2*ACOS(1-2*(MIN(0.999,MAX(1E-6,A23/$B$5))))))))<=0,0,(IF((($B$5/2)*(2*ACOS(1-2*(MIN(0.999,MAX(1E-6,A23/$B$5))))))<=0,0,((($B$5/2)^2/2)*((2*ACOS(1-2*(MIN(0.999,MAX(1E-6,A23/$B$5)))))-SIN(2*ACOS(1-2*(MIN(0.999,MAX(1E-6,A23/$B$5)))))))/(($B$5/2)*(2*ACOS(1-2*(MIN(0.999,MAX(1E-6,A23/$B$5))))))))^(2/3))*SQRT($B$9)),IF((A23-$B$10+$B$9*$B$6)<=0,0,(PI()*($B$5/2)^2)*SQRT((A23-$B$10+$B$9*$B$6)/((1+$B$17)/(2*9.81)+($B$4^2)*$B$6/(($B$5/4)^(4/3)))))) | E23: =MIN(C23,D23) | F23: =IF(A23<=0,0,IF(A23<$B$5,(($B$5/2)^2/2)*((2*ACOS(1-2*(MIN(0.999,MAX(1E-6,A23/$B$5)))))-SIN(2*ACOS(1-2*(MIN(0.999,MAX(1E-6,A23/$B$5)))))),(PI()*($B$5/2)^2))) | G23: =IF(F23<=0,0,E23/F23)
A24: 0.2 | B24: =$B$7+A24 | C24: =IF(A24<=0,0,IF(A24<=1.2*$B$5,1.811*(PI()*($B$5/2)^2)*SQRT($B$5)*IF($B$13*$B$5<=0,0,(A24/($B$13*$B$5))^(1/$B$14)),MAX(1.811*(PI()*($B$5/2)^2)*SQRT($B$5)*IF($B$13*$B$5<=0,0,((1.2*$B$5)/($B$13*$B$5))^(1/$B$14)),1.811*(PI()*($B$5/2)^2)*SQRT($B$5)*SQRT(MAX(0,(A24/$B$5-$B$16)/7))))) | D24: =IF(A24<$B$5,IF($B$4<=0,0,(1/$B$4)*((($B$5/2)^2/2)*((2*ACOS(1-2*(MIN(0.999,MAX(1E-6,A24/$B$5)))))-SIN(2*ACOS(1-2*(MIN(0.999,MAX(1E-6,A24/$B$5)))))))*IF((IF((($B$5/2)*(2*ACOS(1-2*(MIN(0.999,MAX(1E-6,A24/$B$5))))))<=0,0,((($B$5/2)^2/2)*((2*ACOS(1-2*(MIN(0.999,MAX(1E-6,A24/$B$5)))))-SIN(2*ACOS(1-2*(MIN(0.999,MAX(1E-6,A24/$B$5)))))))/(($B$5/2)*(2*ACOS(1-2*(MIN(0.999,MAX(1E-6,A24/$B$5))))))))<=0,0,(IF((($B$5/2)*(2*ACOS(1-2*(MIN(0.999,MAX(1E-6,A24/$B$5))))))<=0,0,((($B$5/2)^2/2)*((2*ACOS(1-2*(MIN(0.999,MAX(1E-6,A24/$B$5)))))-SIN(2*ACOS(1-2*(MIN(0.999,MAX(1E-6,A24/$B$5)))))))/(($B$5/2)*(2*ACOS(1-2*(MIN(0.999,MAX(1E-6,A24/$B$5))))))))^(2/3))*SQRT($B$9)),IF((A24-$B$10+$B$9*$B$6)<=0,0,(PI()*($B$5/2)^2)*SQRT((A24-$B$10+$B$9*$B$6)/((1+$B$17)/(2*9.81)+($B$4^2)*$B$6/(($B$5/4)^(4/3)))))) | E24: =MIN(C24,D24) | F24: =IF(A24<=0,0,IF(A24<$B$5,(($B$5/2)^2/2)*((2*ACOS(1-2*(MIN(0.999,MAX(1E-6,A24/$B$5)))))-SIN(2*ACOS(1-2*(MIN(0.999,MAX(1E-6,A24/$B$5)))))),(PI()*($B$5/2)^2))) | G24: =IF(F24<=0,0,E24/F24)
A25: 0.25 | B25: =$B$7+A25 | C25: =IF(A25<=0,0,IF(A25<=1.2*$B$5,1.811*(PI()*($B$5/2)^2)*SQRT($B$5)*IF($B$13*$B$5<=0,0,(A25/($B$13*$B$5))^(1/$B$14)),MAX(1.811*(PI()*($B$5/2)^2)*SQRT($B$5)*IF($B$13*$B$5<=0,0,((1.2*$B$5)/($B$13*$B$5))^(1/$B$14)),1.811*(PI()*($B$5/2)^2)*SQRT($B$5)*SQRT(MAX(0,(A25/$B$5-$B$16)/7))))) | D25: =IF(A25<$B$5,IF($B$4<=0,0,(1/$B$4)*((($B$5/2)^2/2)*((2*ACOS(1-2*(MIN(0.999,MAX(1E-6,A25/$B$5)))))-SIN(2*ACOS(1-2*(MIN(0.999,MAX(1E-6,A25/$B$5)))))))*IF((IF((($B$5/2)*(2*ACOS(1-2*(MIN(0.999,MAX(1E-6,A25/$B$5))))))<=0,0,((($B$5/2)^2/2)*((2*ACOS(1-2*(MIN(0.999,MAX(1E-6,A25/$B$5)))))-SIN(2*ACOS(1-2*(MIN(0.999,MAX(1E-6,A25/$B$5)))))))/(($B$5/2)*(2*ACOS(1-2*(MIN(0.999,MAX(1E-6,A25/$B$5))))))))<=0,0,(IF((($B$5/2)*(2*ACOS(1-2*(MIN(0.999,MAX(1E-6,A25/$B$5))))))<=0,0,((($B$5/2)^2/2)*((2*ACOS(1-2*(MIN(0.999,MAX(1E-6,A25/$B$5)))))-SIN(2*ACOS(1-2*(MIN(0.999,MAX(1E-6,A25/$B$5)))))))/(($B$5/2)*(2*ACOS(1-2*(MIN(0.999,MAX(1E-6,A25/$B$5))))))))^(2/3))*SQRT($B$9)),IF((A25-$B$10+$B$9*$B$6)<=0,0,(PI()*($B$5/2)^2)*SQRT((A25-$B$10+$B$9*$B$6)/((1+$B$17)/(2*9.81)+($B$4^2)*$B$6/(($B$5/4)^(4/3)))))) | E25: =MIN(C25,D25) | F25: =IF(A25<=0,0,IF(A25<$B$5,(($B$5/2)^2/2)*((2*ACOS(1-2*(MIN(0.999,MAX(1E-6,A25/$B$5)))))-SIN(2*ACOS(1-2*(MIN(0.999,MAX(1E-6,A25/$B$5)))))),(PI()*($B$5/2)^2))) | G25: =IF(F25<=0,0,E25/F25)
A26: 0.3 | B26: =$B$7+A26 | C26: =IF(A26<=0,0,IF(A26<=1.2*$B$5,1.811*(PI()*($B$5/2)^2)*SQRT($B$5)*IF($B$13*$B$5<=0,0,(A26/($B$13*$B$5))^(1/$B$14)),MAX(1.811*(PI()*($B$5/2)^2)*SQRT($B$5)*IF($B$13*$B$5<=0,0,((1.2*$B$5)/($B$13*$B$5))^(1/$B$14)),1.811*(PI()*($B$5/2)^2)*SQRT($B$5)*SQRT(MAX(0,(A26/$B$5-$B$16)/7))))) | D26: =IF(A26<$B$5,IF($B$4<=0,0,(1/$B$4)*((($B$5/2)^2/2)*((2*ACOS(1-2*(MIN(0.999,MAX(1E-6,A26/$B$5)))))-SIN(2*ACOS(1-2*(MIN(0.999,MAX(1E-6,A26/$B$5)))))))*IF((IF((($B$5/2)*(2*ACOS(1-2*(MIN(0.999,MAX(1E-6,A26/$B$5))))))<=0,0,((($B$5/2)^2/2)*((2*ACOS(1-2*(MIN(0.999,MAX(1E-6,A26/$B$5)))))-SIN(2*ACOS(1-2*(MIN(0.999,MAX(1E-6,A26/$B$5)))))))/(($B$5/2)*(2*ACOS(1-2*(MIN(0.999,MAX(1E-6,A26/$B$5))))))))<=0,0,(IF((($B$5/2)*(2*ACOS(1-2*(MIN(0.999,MAX(1E-6,A26/$B$5))))))<=0,0,((($B$5/2)^2/2)*((2*ACOS(1-2*(MIN(0.999,MAX(1E-6,A26/$B$5)))))-SIN(2*ACOS(1-2*(MIN(0.999,MAX(1E-6,A26/$B$5)))))))/(($B$5/2)*(2*ACOS(1-2*(MIN(0.999,MAX(1E-6,A26/$B$5))))))))^(2/3))*SQRT($B$9)),IF((A26-$B$10+$B$9*$B$6)<=0,0,(PI()*($B$5/2)^2)*SQRT((A26-$B$10+$B$9*$B$6)/((1+$B$17)/(2*9.81)+($B$4^2)*$B$6/(($B$5/4)^(4/3)))))) | E26: =MIN(C26,D26) | F26: =IF(A26<=0,0,IF(A26<$B$5,(($B$5/2)^2/2)*((2*ACOS(1-2*(MIN(0.999,MAX(1E-6,A26/$B$5)))))-SIN(2*ACOS(1-2*(MIN(0.999,MAX(1E-6,A26/$B$5)))))),(PI()*($B$5/2)^2))) | G26: =IF(F26<=0,0,E26/F26)
A27: 0.35 | B27: =$B$7+A27 | C27: =IF(A27<=0,0,IF(A27<=1.2*$B$5,1.811*(PI()*($B$5/2)^2)*SQRT($B$5)*IF($B$13*$B$5<=0,0,(A27/($B$13*$B$5))^(1/$B$14)),MAX(1.811*(PI()*($B$5/2)^2)*SQRT($B$5)*IF($B$13*$B$5<=0,0,((1.2*$B$5)/($B$13*$B$5))^(1/$B$14)),1.811*(PI()*($B$5/2)^2)*SQRT($B$5)*SQRT(MAX(0,(A27/$B$5-$B$16)/7))))) | D27: =IF(A27<$B$5,IF($B$4<=0,0,(1/$B$4)*((($B$5/2)^2/2)*((2*ACOS(1-2*(MIN(0.999,MAX(1E-6,A27/$B$5)))))-SIN(2*ACOS(1-2*(MIN(0.999,MAX(1E-6,A27/$B$5)))))))*IF((IF((($B$5/2)*(2*ACOS(1-2*(MIN(0.999,MAX(1E-6,A27/$B$5))))))<=0,0,((($B$5/2)^2/2)*((2*ACOS(1-2*(MIN(0.999,MAX(1E-6,A27/$B$5)))))-SIN(2*ACOS(1-2*(MIN(0.999,MAX(1E-6,A27/$B$5)))))))/(($B$5/2)*(2*ACOS(1-2*(MIN(0.999,MAX(1E-6,A27/$B$5))))))))<=0,0,(IF((($B$5/2)*(2*ACOS(1-2*(MIN(0.999,MAX(1E-6,A27/$B$5))))))<=0,0,((($B$5/2)^2/2)*((2*ACOS(1-2*(MIN(0.999,MAX(1E-6,A27/$B$5)))))-SIN(2*ACOS(1-2*(MIN(0.999,MAX(1E-6,A27/$B$5)))))))/(($B$5/2)*(2*ACOS(1-2*(MIN(0.999,MAX(1E-6,A27/$B$5))))))))^(2/3))*SQRT($B$9)),IF((A27-$B$10+$B$9*$B$6)<=0,0,(PI()*($B$5/2)^2)*SQRT((A27-$B$10+$B$9*$B$6)/((1+$B$17)/(2*9.81)+($B$4^2)*$B$6/(($B$5/4)^(4/3)))))) | E27: =MIN(C27,D27) | F27: =IF(A27<=0,0,IF(A27<$B$5,(($B$5/2)^2/2)*((2*ACOS(1-2*(MIN(0.999,MAX(1E-6,A27/$B$5)))))-SIN(2*ACOS(1-2*(MIN(0.999,MAX(1E-6,A27/$B$5)))))),(PI()*($B$5/2)^2))) | G27: =IF(F27<=0,0,E27/F27)
A28: 0.4 | B28: =$B$7+A28 | C28: =IF(A28<=0,0,IF(A28<=1.2*$B$5,1.811*(PI()*($B$5/2)^2)*SQRT($B$5)*IF($B$13*$B$5<=0,0,(A28/($B$13*$B$5))^(1/$B$14)),MAX(1.811*(PI()*($B$5/2)^2)*SQRT($B$5)*IF($B$13*$B$5<=0,0,((1.2*$B$5)/($B$13*$B$5))^(1/$B$14)),1.811*(PI()*($B$5/2)^2)*SQRT($B$5)*SQRT(MAX(0,(A28/$B$5-$B$16)/7))))) | D28: =IF(A28<$B$5,IF($B$4<=0,0,(1/$B$4)*((($B$5/2)^2/2)*((2*ACOS(1-2*(MIN(0.999,MAX(1E-6,A28/$B$5)))))-SIN(2*ACOS(1-2*(MIN(0.999,MAX(1E-6,A28/$B$5)))))))*IF((IF((($B$5/2)*(2*ACOS(1-2*(MIN(0.999,MAX(1E-6,A28/$B$5))))))<=0,0,((($B$5/2)^2/2)*((2*ACOS(1-2*(MIN(0.999,MAX(1E-6,A28/$B$5)))))-SIN(2*ACOS(1-2*(MIN(0.999,MAX(1E-6,A28/$B$5)))))))/(($B$5/2)*(2*ACOS(1-2*(MIN(0.999,MAX(1E-6,A28/$B$5))))))))<=0,0,(IF((($B$5/2)*(2*ACOS(1-2*(MIN(0.999,MAX(1E-6,A28/$B$5))))))<=0,0,((($B$5/2)^2/2)*((2*ACOS(1-2*(MIN(0.999,MAX(1E-6,A28/$B$5)))))-SIN(2*ACOS(1-2*(MIN(0.999,MAX(1E-6,A28/$B$5)))))))/(($B$5/2)*(2*ACOS(1-2*(MIN(0.999,MAX(1E-6,A28/$B$5))))))))^(2/3))*SQRT($B$9)),IF((A28-$B$10+$B$9*$B$6)<=0,0,(PI()*($B$5/2)^2)*SQRT((A28-$B$10+$B$9*$B$6)/((1+$B$17)/(2*9.81)+($B$4^2)*$B$6/(($B$5/4)^(4/3)))))) | E28: =MIN(C28,D28) | F28: =IF(A28<=0,0,IF(A28<$B$5,(($B$5/2)^2/2)*((2*ACOS(1-2*(MIN(0.999,MAX(1E-6,A28/$B$5)))))-SIN(2*ACOS(1-2*(MIN(0.999,MAX(1E-6,A28/$B$5)))))),(PI()*($B$5/2)^2))) | G28: =IF(F28<=0,0,E28/F28)
A29: 0.45 | B29: =$B$7+A29 | C29: =IF(A29<=0,0,IF(A29<=1.2*$B$5,1.811*(PI()*($B$5/2)^2)*SQRT($B$5)*IF($B$13*$B$5<=0,0,(A29/($B$13*$B$5))^(1/$B$14)),MAX(1.811*(PI()*($B$5/2)^2)*SQRT($B$5)*IF($B$13*$B$5<=0,0,((1.2*$B$5)/($B$13*$B$5))^(1/$B$14)),1.811*(PI()*($B$5/2)^2)*SQRT($B$5)*SQRT(MAX(0,(A29/$B$5-$B$16)/7))))) | D29: =IF(A29<$B$5,IF($B$4<=0,0,(1/$B$4)*((($B$5/2)^2/2)*((2*ACOS(1-2*(MIN(0.999,MAX(1E-6,A29/$B$5)))))-SIN(2*ACOS(1-2*(MIN(0.999,MAX(1E-6,A29/$B$5)))))))*IF((IF((($B$5/2)*(2*ACOS(1-2*(MIN(0.999,MAX(1E-6,A29/$B$5))))))<=0,0,((($B$5/2)^2/2)*((2*ACOS(1-2*(MIN(0.999,MAX(1E-6,A29/$B$5)))))-SIN(2*ACOS(1-2*(MIN(0.999,MAX(1E-6,A29/$B$5)))))))/(($B$5/2)*(2*ACOS(1-2*(MIN(0.999,MAX(1E-6,A29/$B$5))))))))<=0,0,(IF((($B$5/2)*(2*ACOS(1-2*(MIN(0.999,MAX(1E-6,A29/$B$5))))))<=0,0,((($B$5/2)^2/2)*((2*ACOS(1-2*(MIN(0.999,MAX(1E-6,A29/$B$5)))))-SIN(2*ACOS(1-2*(MIN(0.999,MAX(1E-6,A29/$B$5)))))))/(($B$5/2)*(2*ACOS(1-2*(MIN(0.999,MAX(1E-6,A29/$B$5))))))))^(2/3))*SQRT($B$9)),IF((A29-$B$10+$B$9*$B$6)<=0,0,(PI()*($B$5/2)^2)*SQRT((A29-$B$10+$B$9*$B$6)/((1+$B$17)/(2*9.81)+($B$4^2)*$B$6/(($B$5/4)^(4/3)))))) | E29: =MIN(C29,D29) | F29: =IF(A29<=0,0,IF(A29<$B$5,(($B$5/2)^2/2)*((2*ACOS(1-2*(MIN(0.999,MAX(1E-6,A29/$B$5)))))-SIN(2*ACOS(1-2*(MIN(0.999,MAX(1E-6,A29/$B$5)))))),(PI()*($B$5/2)^2))) | G29: =IF(F29<=0,0,E29/F29)
A30: 0.5 | B30: =$B$7+A30 | C30: =IF(A30<=0,0,IF(A30<=1.2*$B$5,1.811*(PI()*($B$5/2)^2)*SQRT($B$5)*IF($B$13*$B$5<=0,0,(A30/($B$13*$B$5))^(1/$B$14)),MAX(1.811*(PI()*($B$5/2)^2)*SQRT($B$5)*IF($B$13*$B$5<=0,0,((1.2*$B$5)/($B$13*$B$5))^(1/$B$14)),1.811*(PI()*($B$5/2)^2)*SQRT($B$5)*SQRT(MAX(0,(A30/$B$5-$B$16)/7))))) | D30: =IF(A30<$B$5,IF($B$4<=0,0,(1/$B$4)*((($B$5/2)^2/2)*((2*ACOS(1-2*(MIN(0.999,MAX(1E-6,A30/$B$5)))))-SIN(2*ACOS(1-2*(MIN(0.999,MAX(1E-6,A30/$B$5)))))))*IF((IF((($B$5/2)*(2*ACOS(1-2*(MIN(0.999,MAX(1E-6,A30/$B$5))))))<=0,0,((($B$5/2)^2/2)*((2*ACOS(1-2*(MIN(0.999,MAX(1E-6,A30/$B$5)))))-SIN(2*ACOS(1-2*(MIN(0.999,MAX(1E-6,A30/$B$5)))))))/(($B$5/2)*(2*ACOS(1-2*(MIN(0.999,MAX(1E-6,A30/$B$5))))))))<=0,0,(IF((($B$5/2)*(2*ACOS(1-2*(MIN(0.999,MAX(1E-6,A30/$B$5))))))<=0,0,((($B$5/2)^2/2)*((2*ACOS(1-2*(MIN(0.999,MAX(1E-6,A30/$B$5)))))-SIN(2*ACOS(1-2*(MIN(0.999,MAX(1E-6,A30/$B$5)))))))/(($B$5/2)*(2*ACOS(1-2*(MIN(0.999,MAX(1E-6,A30/$B$5))))))))^(2/3))*SQRT($B$9)),IF((A30-$B$10+$B$9*$B$6)<=0,0,(PI()*($B$5/2)^2)*SQRT((A30-$B$10+$B$9*$B$6)/((1+$B$17)/(2*9.81)+($B$4^2)*$B$6/(($B$5/4)^(4/3)))))) | E30: =MIN(C30,D30) | F30: =IF(A30<=0,0,IF(A30<$B$5,(($B$5/2)^2/2)*((2*ACOS(1-2*(MIN(0.999,MAX(1E-6,A30/$B$5)))))-SIN(2*ACOS(1-2*(MIN(0.999,MAX(1E-6,A30/$B$5)))))),(PI()*($B$5/2)^2))) | G30: =IF(F30<=0,0,E30/F30)
A31: 0.55 | B31: =$B$7+A31 | C31: =IF(A31<=0,0,IF(A31<=1.2*$B$5,1.811*(PI()*($B$5/2)^2)*SQRT($B$5)*IF($B$13*$B$5<=0,0,(A31/($B$13*$B$5))^(1/$B$14)),MAX(1.811*(PI()*($B$5/2)^2)*SQRT($B$5)*IF($B$13*$B$5<=0,0,((1.2*$B$5)/($B$13*$B$5))^(1/$B$14)),1.811*(PI()*($B$5/2)^2)*SQRT($B$5)*SQRT(MAX(0,(A31/$B$5-$B$16)/7))))) | D31: =IF(A31<$B$5,IF($B$4<=0,0,(1/$B$4)*((($B$5/2)^2/2)*((2*ACOS(1-2*(MIN(0.999,MAX(1E-6,A31/$B$5)))))-SIN(2*ACOS(1-2*(MIN(0.999,MAX(1E-6,A31/$B$5)))))))*IF((IF((($B$5/2)*(2*ACOS(1-2*(MIN(0.999,MAX(1E-6,A31/$B$5))))))<=0,0,((($B$5/2)^2/2)*((2*ACOS(1-2*(MIN(0.999,MAX(1E-6,A31/$B$5)))))-SIN(2*ACOS(1-2*(MIN(0.999,MAX(1E-6,A31/$B$5)))))))/(($B$5/2)*(2*ACOS(1-2*(MIN(0.999,MAX(1E-6,A31/$B$5))))))))<=0,0,(IF((($B$5/2)*(2*ACOS(1-2*(MIN(0.999,MAX(1E-6,A31/$B$5))))))<=0,0,((($B$5/2)^2/2)*((2*ACOS(1-2*(MIN(0.999,MAX(1E-6,A31/$B$5)))))-SIN(2*ACOS(1-2*(MIN(0.999,MAX(1E-6,A31/$B$5)))))))/(($B$5/2)*(2*ACOS(1-2*(MIN(0.999,MAX(1E-6,A31/$B$5))))))))^(2/3))*SQRT($B$9)),IF((A31-$B$10+$B$9*$B$6)<=0,0,(PI()*($B$5/2)^2)*SQRT((A31-$B$10+$B$9*$B$6)/((1+$B$17)/(2*9.81)+($B$4^2)*$B$6/(($B$5/4)^(4/3)))))) | E31: =MIN(C31,D31) | F31: =IF(A31<=0,0,IF(A31<$B$5,(($B$5/2)^2/2)*((2*ACOS(1-2*(MIN(0.999,MAX(1E-6,A31/$B$5)))))-SIN(2*ACOS(1-2*(MIN(0.999,MAX(1E-6,A31/$B$5)))))),(PI()*($B$5/2)^2))) | G31: =IF(F31<=0,0,E31/F31)
A32: 0.6 | B32: =$B$7+A32 | C32: =IF(A32<=0,0,IF(A32<=1.2*$B$5,1.811*(PI()*($B$5/2)^2)*SQRT($B$5)*IF($B$13*$B$5<=0,0,(A32/($B$13*$B$5))^(1/$B$14)),MAX(1.811*(PI()*($B$5/2)^2)*SQRT($B$5)*IF($B$13*$B$5<=0,0,((1.2*$B$5)/($B$13*$B$5))^(1/$B$14)),1.811*(PI()*($B$5/2)^2)*SQRT($B$5)*SQRT(MAX(0,(A32/$B$5-$B$16)/7))))) | D32: =IF(A32<$B$5,IF($B$4<=0,0,(1/$B$4)*((($B$5/2)^2/2)*((2*ACOS(1-2*(MIN(0.999,MAX(1E-6,A32/$B$5)))))-SIN(2*ACOS(1-2*(MIN(0.999,MAX(1E-6,A32/$B$5)))))))*IF((IF((($B$5/2)*(2*ACOS(1-2*(MIN(0.999,MAX(1E-6,A32/$B$5))))))<=0,0,((($B$5/2)^2/2)*((2*ACOS(1-2*(MIN(0.999,MAX(1E-6,A32/$B$5)))))-SIN(2*ACOS(1-2*(MIN(0.999,MAX(1E-6,A32/$B$5)))))))/(($B$5/2)*(2*ACOS(1-2*(MIN(0.999,MAX(1E-6,A32/$B$5))))))))<=0,0,(IF((($B$5/2)*(2*ACOS(1-2*(MIN(0.999,MAX(1E-6,A32/$B$5))))))<=0,0,((($B$5/2)^2/2)*((2*ACOS(1-2*(MIN(0.999,MAX(1E-6,A32/$B$5)))))-SIN(2*ACOS(1-2*(MIN(0.999,MAX(1E-6,A32/$B$5)))))))/(($B$5/2)*(2*ACOS(1-2*(MIN(0.999,MAX(1E-6,A32/$B$5))))))))^(2/3))*SQRT($B$9)),IF((A32-$B$10+$B$9*$B$6)<=0,0,(PI()*($B$5/2)^2)*SQRT((A32-$B$10+$B$9*$B$6)/((1+$B$17)/(2*9.81)+($B$4^2)*$B$6/(($B$5/4)^(4/3)))))) | E32: =MIN(C32,D32) | F32: =IF(A32<=0,0,IF(A32<$B$5,(($B$5/2)^2/2)*((2*ACOS(1-2*(MIN(0.999,MAX(1E-6,A32/$B$5)))))-SIN(2*ACOS(1-2*(MIN(0.999,MAX(1E-6,A32/$B$5)))))),(PI()*($B$5/2)^2))) | G32: =IF(F32<=0,0,E32/F32)
... A80: 3 | B80: =$B$7+A80 | C80: =IF(A80<=0,0,IF(A80<=1.2*$B$5,1.811*(PI()*($B$5/2)^2)*SQRT($B$5)*IF($B$13*$B$5<=0,0,(A80/($B$13*$B$5))^(1/$B$14)),MAX(1.811*(PI()*($B$5/2)^2)*SQRT($B$5)*IF($B$13*$B$5<=0,0,((1.2*$B$5)/($B$13*$B$5))^(1/$B$14)),1.811*(PI()*($B$5/2)^2)*SQRT($B$5)*SQRT(MAX(0,(A80/$B$5-$B$16)/7))))) | D80: =IF(A80<$B$5,IF($B$4<=0,0,(1/$B$4)*((($B$5/2)^2/2)*((2*ACOS(1-2*(MIN(0.999,MAX(1E-6,A80/$B$5)))))-SIN(2*ACOS(1-2*(MIN(0.999,MAX(1E-6,A80/$B$5)))))))*IF((IF((($B$5/2)*(2*ACOS(1-2*(MIN(0.999,MAX(1E-6,A80/$B$5))))))<=0,0,((($B$5/2)^2/2)*((2*ACOS(1-2*(MIN(0.999,MAX(1E-6,A80/$B$5)))))-SIN(2*ACOS(1-2*(MIN(0.999,MAX(1E-6,A80/$B$5)))))))/(($B$5/2)*(2*ACOS(1-2*(MIN(0.999,MAX(1E-6,A80/$B$5))))))))<=0,0,(IF((($B$5/2)*(2*ACOS(1-2*(MIN(0.999,MAX(1E-6,A80/$B$5))))))<=0,0,((($B$5/2)^2/2)*((2*ACOS(1-2*(MIN(0.999,MAX(1E-6,A80/$B$5)))))-SIN(2*ACOS(1-2*(MIN(0.999,MAX(1E-6,A80/$B$5)))))))/(($B$5/2)*(2*ACOS(1-2*(MIN(0.999,MAX(1E-6,A80/$B$5))))))))^(2/3))*SQRT($B$9)),IF((A80-$B$10+$B$9*$B$6)<=0,0,(PI()*($B$5/2)^2)*SQRT((A80-$B$10+$B$9*$B$6)/((1+$B$17)/(2*9.81)+($B$4^2)*$B$6/(($B$5/4)^(4/3)))))) | E80: =MIN(C80,D80) | F80: =IF(A80<=0,0,IF(A80<$B$5,(($B$5/2)^2/2)*((2*ACOS(1-2*(MIN(0.999,MAX(1E-6,A80/$B$5)))))-SIN(2*ACOS(1-2*(MIN(0.999,MAX(1E-6,A80/$B$5)))))),(PI()*($B$5/2)^2))) | G80: =IF(F80<=0,0,E80/F80)

Sheet Calcul_B
A1: Methode B — routage Qout = f(H) depuis Courbe_QH_1200
A2: H = V / Aire_plan_eau. Qout interpole sur Q gouvernant.
A4: Aire (m2) | B4: =Parametres!B24
A5: Q_plein ref | B5: =Parametres!B22
A7: Vmax_B (m3) | B7: =MAX(G10:G22)
A8: Hmax_B (m) | B8: =IF(B4>0,B7/B4,0)
A9: t (min) | B9: Qin | C9: H (m) | D9: Q_courbe | E9: Qout | F9: dt (s) | G9: V (m3) | H9: V_Ø1200 (m/s)
A10: =Hydrogramme!A7 | B10: =Hydrogramme!C7 | C10: 0 | D10: 0 | E10: =MIN(B10,$B$5) | F10: 0 | G10: 0 | H10: =IF(Parametres!$C$96<=0,0,E10/Parametres!$C$96)
A11: =Hydrogramme!A8 | B11: =Hydrogramme!C8 | C11: =IF($B$4>0,G10/$B$4,0) | D11: =IF(C11<=0,0,IF(C11>=INDEX(Courbe_QH_1200!$A$20:$A$80,ROWS(Courbe_QH_1200!$A$20:$A$80)),INDEX(Courbe_QH_1200!$E$20:$E$80,ROWS(Courbe_QH_1200!$E$20:$E$80)),INDEX(Courbe_QH_1200!$E$20:$E$80,MATCH(C11,Courbe_QH_1200!$A$20:$A$80,1))+(C11-INDEX(Courbe_QH_1200!$A$20:$A$80,MATCH(C11,Courbe_QH_1200!$A$20:$A$80,1)))/(INDEX(Courbe_QH_1200!$A$20:$A$80,MATCH(C11,Courbe_QH_1200!$A$20:$A$80,1)+1)-INDEX(Courbe_QH_1200!$A$20:$A$80,MATCH(C11,Courbe_QH_1200!$A$20:$A$80,1)))*(INDEX(Courbe_QH_1200!$E$20:$E$80,MATCH(C11,Courbe_QH_1200!$A$20:$A$80,1)+1)-INDEX(Courbe_QH_1200!$E$20:$E$80,MATCH(C11,Courbe_QH_1200!$A$20:$A$80,1))))) | E11: =IF(G10<=0.01,MIN(0.5*(B10+B11),$B$5),D11) | F11: =(A11-A10)*60 | G11: =MAX(0,G10+(0.5*(B10+B11)-E11)*F11) | H11: =IF(Parametres!$C$96<=0,0,E11/Parametres!$C$96)
A12: =Hydrogramme!A9 | B12: =Hydrogramme!C9 | C12: =IF($B$4>0,G11/$B$4,0) | D12: =IF(C12<=0,0,IF(C12>=INDEX(Courbe_QH_1200!$A$20:$A$80,ROWS(Courbe_QH_1200!$A$20:$A$80)),INDEX(Courbe_QH_1200!$E$20:$E$80,ROWS(Courbe_QH_1200!$E$20:$E$80)),INDEX(Courbe_QH_1200!$E$20:$E$80,MATCH(C12,Courbe_QH_1200!$A$20:$A$80,1))+(C12-INDEX(Courbe_QH_1200!$A$20:$A$80,MATCH(C12,Courbe_QH_1200!$A$20:$A$80,1)))/(INDEX(Courbe_QH_1200!$A$20:$A$80,MATCH(C12,Courbe_QH_1200!$A$20:$A$80,1)+1)-INDEX(Courbe_QH_1200!$A$20:$A$80,MATCH(C12,Courbe_QH_1200!$A$20:$A$80,1)))*(INDEX(Courbe_QH_1200!$E$20:$E$80,MATCH(C12,Courbe_QH_1200!$A$20:$A$80,1)+1)-INDEX(Courbe_QH_1200!$E$20:$E$80,MATCH(C12,Courbe_QH_1200!$A$20:$A$80,1))))) | E12: =IF(G11<=0.01,MIN(0.5*(B11+B12),$B$5),D12) | F12: =(A12-A11)*60 | G12: =MAX(0,G11+(0.5*(B11+B12)-E12)*F12) | H12: =IF(Parametres!$C$96<=0,0,E12/Parametres!$C$96)
A13: =Hydrogramme!A10 | B13: =Hydrogramme!C10 | C13: =IF($B$4>0,G12/$B$4,0) | D13: =IF(C13<=0,0,IF(C13>=INDEX(Courbe_QH_1200!$A$20:$A$80,ROWS(Courbe_QH_1200!$A$20:$A$80)),INDEX(Courbe_QH_1200!$E$20:$E$80,ROWS(Courbe_QH_1200!$E$20:$E$80)),INDEX(Courbe_QH_1200!$E$20:$E$80,MATCH(C13,Courbe_QH_1200!$A$20:$A$80,1))+(C13-INDEX(Courbe_QH_1200!$A$20:$A$80,MATCH(C13,Courbe_QH_1200!$A$20:$A$80,1)))/(INDEX(Courbe_QH_1200!$A$20:$A$80,MATCH(C13,Courbe_QH_1200!$A$20:$A$80,1)+1)-INDEX(Courbe_QH_1200!$A$20:$A$80,MATCH(C13,Courbe_QH_1200!$A$20:$A$80,1)))*(INDEX(Courbe_QH_1200!$E$20:$E$80,MATCH(C13,Courbe_QH_1200!$A$20:$A$80,1)+1)-INDEX(Courbe_QH_1200!$E$20:$E$80,MATCH(C13,Courbe_QH_1200!$A$20:$A$80,1))))) | E13: =IF(G12<=0.01,MIN(0.5*(B12+B13),$B$5),D13) | F13: =(A13-A12)*60 | G13: =MAX(0,G12+(0.5*(B12+B13)-E13)*F13) | H13: =IF(Parametres!$C$96<=0,0,E13/Parametres!$C$96)
A14: =Hydrogramme!A11 | B14: =Hydrogramme!C11 | C14: =IF($B$4>0,G13/$B$4,0) | D14: =IF(C14<=0,0,IF(C14>=INDEX(Courbe_QH_1200!$A$20:$A$80,ROWS(Courbe_QH_1200!$A$20:$A$80)),INDEX(Courbe_QH_1200!$E$20:$E$80,ROWS(Courbe_QH_1200!$E$20:$E$80)),INDEX(Courbe_QH_1200!$E$20:$E$80,MATCH(C14,Courbe_QH_1200!$A$20:$A$80,1))+(C14-INDEX(Courbe_QH_1200!$A$20:$A$80,MATCH(C14,Courbe_QH_1200!$A$20:$A$80,1)))/(INDEX(Courbe_QH_1200!$A$20:$A$80,MATCH(C14,Courbe_QH_1200!$A$20:$A$80,1)+1)-INDEX(Courbe_QH_1200!$A$20:$A$80,MATCH(C14,Courbe_QH_1200!$A$20:$A$80,1)))*(INDEX(Courbe_QH_1200!$E$20:$E$80,MATCH(C14,Courbe_QH_1200!$A$20:$A$80,1)+1)-INDEX(Courbe_QH_1200!$E$20:$E$80,MATCH(C14,Courbe_QH_1200!$A$20:$A$80,1))))) | E14: =IF(G13<=0.01,MIN(0.5*(B13+B14),$B$5),D14) | F14: =(A14-A13)*60 | G14: =MAX(0,G13+(0.5*(B13+B14)-E14)*F14) | H14: =IF(Parametres!$C$96<=0,0,E14/Parametres!$C$96)
A15: =Hydrogramme!A12 | B15: =Hydrogramme!C12 | C15: =IF($B$4>0,G14/$B$4,0) | D15: =IF(C15<=0,0,IF(C15>=INDEX(Courbe_QH_1200!$A$20:$A$80,ROWS(Courbe_QH_1200!$A$20:$A$80)),INDEX(Courbe_QH_1200!$E$20:$E$80,ROWS(Courbe_QH_1200!$E$20:$E$80)),INDEX(Courbe_QH_1200!$E$20:$E$80,MATCH(C15,Courbe_QH_1200!$A$20:$A$80,1))+(C15-INDEX(Courbe_QH_1200!$A$20:$A$80,MATCH(C15,Courbe_QH_1200!$A$20:$A$80,1)))/(INDEX(Courbe_QH_1200!$A$20:$A$80,MATCH(C15,Courbe_QH_1200!$A$20:$A$80,1)+1)-INDEX(Courbe_QH_1200!$A$20:$A$80,MATCH(C15,Courbe_QH_1200!$A$20:$A$80,1)))*(INDEX(Courbe_QH_1200!$E$20:$E$80,MATCH(C15,Courbe_QH_1200!$A$20:$A$80,1)+1)-INDEX(Courbe_QH_1200!$E$20:$E$80,MATCH(C15,Courbe_QH_1200!$A$20:$A$80,1))))) | E15: =IF(G14<=0.01,MIN(0.5*(B14+B15),$B$5),D15) | F15: =(A15-A14)*60 | G15: =MAX(0,G14+(0.5*(B14+B15)-E15)*F15) | H15: =IF(Parametres!$C$96<=0,0,E15/Parametres!$C$96)
A16: =Hydrogramme!A13 | B16: =Hydrogramme!C13 | C16: =IF($B$4>0,G15/$B$4,0) | D16: =IF(C16<=0,0,IF(C16>=INDEX(Courbe_QH_1200!$A$20:$A$80,ROWS(Courbe_QH_1200!$A$20:$A$80)),INDEX(Courbe_QH_1200!$E$20:$E$80,ROWS(Courbe_QH_1200!$E$20:$E$80)),INDEX(Courbe_QH_1200!$E$20:$E$80,MATCH(C16,Courbe_QH_1200!$A$20:$A$80,1))+(C16-INDEX(Courbe_QH_1200!$A$20:$A$80,MATCH(C16,Courbe_QH_1200!$A$20:$A$80,1)))/(INDEX(Courbe_QH_1200!$A$20:$A$80,MATCH(C16,Courbe_QH_1200!$A$20:$A$80,1)+1)-INDEX(Courbe_QH_1200!$A$20:$A$80,MATCH(C16,Courbe_QH_1200!$A$20:$A$80,1)))*(INDEX(Courbe_QH_1200!$E$20:$E$80,MATCH(C16,Courbe_QH_1200!$A$20:$A$80,1)+1)-INDEX(Courbe_QH_1200!$E$20:$E$80,MATCH(C16,Courbe_QH_1200!$A$20:$A$80,1))))) | E16: =IF(G15<=0.01,MIN(0.5*(B15+B16),$B$5),D16) | F16: =(A16-A15)*60 | G16: =MAX(0,G15+(0.5*(B15+B16)-E16)*F16) | H16: =IF(Parametres!$C$96<=0,0,E16/Parametres!$C$96)
A17: =Hydrogramme!A14 | B17: =Hydrogramme!C14 | C17: =IF($B$4>0,G16/$B$4,0) | D17: =IF(C17<=0,0,IF(C17>=INDEX(Courbe_QH_1200!$A$20:$A$80,ROWS(Courbe_QH_1200!$A$20:$A$80)),INDEX(Courbe_QH_1200!$E$20:$E$80,ROWS(Courbe_QH_1200!$E$20:$E$80)),INDEX(Courbe_QH_1200!$E$20:$E$80,MATCH(C17,Courbe_QH_1200!$A$20:$A$80,1))+(C17-INDEX(Courbe_QH_1200!$A$20:$A$80,MATCH(C17,Courbe_QH_1200!$A$20:$A$80,1)))/(INDEX(Courbe_QH_1200!$A$20:$A$80,MATCH(C17,Courbe_QH_1200!$A$20:$A$80,1)+1)-INDEX(Courbe_QH_1200!$A$20:$A$80,MATCH(C17,Courbe_QH_1200!$A$20:$A$80,1)))*(INDEX(Courbe_QH_1200!$E$20:$E$80,MATCH(C17,Courbe_QH_1200!$A$20:$A$80,1)+1)-INDEX(Courbe_QH_1200!$E$20:$E$80,MATCH(C17,Courbe_QH_1200!$A$20:$A$80,1))))) | E17: =IF(G16<=0.01,MIN(0.5*(B16+B17),$B$5),D17) | F17: =(A17-A16)*60 | G17: =MAX(0,G16+(0.5*(B16+B17)-E17)*F17) | H17: =IF(Parametres!$C$96<=0,0,E17/Parametres!$C$96)
A18: =Hydrogramme!A15 | B18: =Hydrogramme!C15 | C18: =IF($B$4>0,G17/$B$4,0) | D18: =IF(C18<=0,0,IF(C18>=INDEX(Courbe_QH_1200!$A$20:$A$80,ROWS(Courbe_QH_1200!$A$20:$A$80)),INDEX(Courbe_QH_1200!$E$20:$E$80,ROWS(Courbe_QH_1200!$E$20:$E$80)),INDEX(Courbe_QH_1200!$E$20:$E$80,MATCH(C18,Courbe_QH_1200!$A$20:$A$80,1))+(C18-INDEX(Courbe_QH_1200!$A$20:$A$80,MATCH(C18,Courbe_QH_1200!$A$20:$A$80,1)))/(INDEX(Courbe_QH_1200!$A$20:$A$80,MATCH(C18,Courbe_QH_1200!$A$20:$A$80,1)+1)-INDEX(Courbe_QH_1200!$A$20:$A$80,MATCH(C18,Courbe_QH_1200!$A$20:$A$80,1)))*(INDEX(Courbe_QH_1200!$E$20:$E$80,MATCH(C18,Courbe_QH_1200!$A$20:$A$80,1)+1)-INDEX(Courbe_QH_1200!$E$20:$E$80,MATCH(C18,Courbe_QH_1200!$A$20:$A$80,1))))) | E18: =IF(G17<=0.01,MIN(0.5*(B17+B18),$B$5),D18) | F18: =(A18-A17)*60 | G18: =MAX(0,G17+(0.5*(B17+B18)-E18)*F18) | H18: =IF(Parametres!$C$96<=0,0,E18/Parametres!$C$96)
A19: =Hydrogramme!A16 | B19: =Hydrogramme!C16 | C19: =IF($B$4>0,G18/$B$4,0) | D19: =IF(C19<=0,0,IF(C19>=INDEX(Courbe_QH_1200!$A$20:$A$80,ROWS(Courbe_QH_1200!$A$20:$A$80)),INDEX(Courbe_QH_1200!$E$20:$E$80,ROWS(Courbe_QH_1200!$E$20:$E$80)),INDEX(Courbe_QH_1200!$E$20:$E$80,MATCH(C19,Courbe_QH_1200!$A$20:$A$80,1))+(C19-INDEX(Courbe_QH_1200!$A$20:$A$80,MATCH(C19,Courbe_QH_1200!$A$20:$A$80,1)))/(INDEX(Courbe_QH_1200!$A$20:$A$80,MATCH(C19,Courbe_QH_1200!$A$20:$A$80,1)+1)-INDEX(Courbe_QH_1200!$A$20:$A$80,MATCH(C19,Courbe_QH_1200!$A$20:$A$80,1)))*(INDEX(Courbe_QH_1200!$E$20:$E$80,MATCH(C19,Courbe_QH_1200!$A$20:$A$80,1)+1)-INDEX(Courbe_QH_1200!$E$20:$E$80,MATCH(C19,Courbe_QH_1200!$A$20:$A$80,1))))) | E19: =IF(G18<=0.01,MIN(0.5*(B18+B19),$B$5),D19) | F19: =(A19-A18)*60 | G19: =MAX(0,G18+(0.5*(B18+B19)-E19)*F19) | H19: =IF(Parametres!$C$96<=0,0,E19/Parametres!$C$96)
A20: =Hydrogramme!A17 | B20: =Hydrogramme!C17 | C20: =IF($B$4>0,G19/$B$4,0) | D20: =IF(C20<=0,0,IF(C20>=INDEX(Courbe_QH_1200!$A$20:$A$80,ROWS(Courbe_QH_1200!$A$20:$A$80)),INDEX(Courbe_QH_1200!$E$20:$E$80,ROWS(Courbe_QH_1200!$E$20:$E$80)),INDEX(Courbe_QH_1200!$E$20:$E$80,MATCH(C20,Courbe_QH_1200!$A$20:$A$80,1))+(C20-INDEX(Courbe_QH_1200!$A$20:$A$80,MATCH(C20,Courbe_QH_1200!$A$20:$A$80,1)))/(INDEX(Courbe_QH_1200!$A$20:$A$80,MATCH(C20,Courbe_QH_1200!$A$20:$A$80,1)+1)-INDEX(Courbe_QH_1200!$A$20:$A$80,MATCH(C20,Courbe_QH_1200!$A$20:$A$80,1)))*(INDEX(Courbe_QH_1200!$E$20:$E$80,MATCH(C20,Courbe_QH_1200!$A$20:$A$80,1)+1)-INDEX(Courbe_QH_1200!$E$20:$E$80,MATCH(C20,Courbe_QH_1200!$A$20:$A$80,1))))) | E20: =IF(G19<=0.01,MIN(0.5*(B19+B20),$B$5),D20) | F20: =(A20-A19)*60 | G20: =MAX(0,G19+(0.5*(B19+B20)-E20)*F20) | H20: =IF(Parametres!$C$96<=0,0,E20/Parametres!$C$96)
A21: =Hydrogramme!A18 | B21: =Hydrogramme!C18 | C21: =IF($B$4>0,G20/$B$4,0) | D21: =IF(C21<=0,0,IF(C21>=INDEX(Courbe_QH_1200!$A$20:$A$80,ROWS(Courbe_QH_1200!$A$20:$A$80)),INDEX(Courbe_QH_1200!$E$20:$E$80,ROWS(Courbe_QH_1200!$E$20:$E$80)),INDEX(Courbe_QH_1200!$E$20:$E$80,MATCH(C21,Courbe_QH_1200!$A$20:$A$80,1))+(C21-INDEX(Courbe_QH_1200!$A$20:$A$80,MATCH(C21,Courbe_QH_1200!$A$20:$A$80,1)))/(INDEX(Courbe_QH_1200!$A$20:$A$80,MATCH(C21,Courbe_QH_1200!$A$20:$A$80,1)+1)-INDEX(Courbe_QH_1200!$A$20:$A$80,MATCH(C21,Courbe_QH_1200!$A$20:$A$80,1)))*(INDEX(Courbe_QH_1200!$E$20:$E$80,MATCH(C21,Courbe_QH_1200!$A$20:$A$80,1)+1)-INDEX(Courbe_QH_1200!$E$20:$E$80,MATCH(C21,Courbe_QH_1200!$A$20:$A$80,1))))) | E21: =IF(G20<=0.01,MIN(0.5*(B20+B21),$B$5),D21) | F21: =(A21-A20)*60 | G21: =MAX(0,G20+(0.5*(B20+B21)-E21)*F21) | H21: =IF(Parametres!$C$96<=0,0,E21/Parametres!$C$96)
A22: =Hydrogramme!A19 | B22: =Hydrogramme!C19 | C22: =IF($B$4>0,G21/$B$4,0) | D22: =IF(C22<=0,0,IF(C22>=INDEX(Courbe_QH_1200!$A$20:$A$80,ROWS(Courbe_QH_1200!$A$20:$A$80)),INDEX(Courbe_QH_1200!$E$20:$E$80,ROWS(Courbe_QH_1200!$E$20:$E$80)),INDEX(Courbe_QH_1200!$E$20:$E$80,MATCH(C22,Courbe_QH_1200!$A$20:$A$80,1))+(C22-INDEX(Courbe_QH_1200!$A$20:$A$80,MATCH(C22,Courbe_QH_1200!$A$20:$A$80,1)))/(INDEX(Courbe_QH_1200!$A$20:$A$80,MATCH(C22,Courbe_QH_1200!$A$20:$A$80,1)+1)-INDEX(Courbe_QH_1200!$A$20:$A$80,MATCH(C22,Courbe_QH_1200!$A$20:$A$80,1)))*(INDEX(Courbe_QH_1200!$E$20:$E$80,MATCH(C22,Courbe_QH_1200!$A$20:$A$80,1)+1)-INDEX(Courbe_QH_1200!$E$20:$E$80,MATCH(C22,Courbe_QH_1200!$A$20:$A$80,1))))) | E22: =IF(G21<=0.01,MIN(0.5*(B21+B22),$B$5),D22) | F22: =(A22-A21)*60 | G22: =MAX(0,G21+(0.5*(B21+B22)-E22)*F22) | H22: =IF(Parametres!$C$96<=0,0,E22/Parametres!$C$96)

Sheet Stage_Storage
A1: Stage–storage COMBINE (Zone1+Zone2) — bassin SANS Ø900 — editer jaune
A2: V_pas = 0.5*(A_bas+A_haut)*dWSE. Aires = somme Z1+Z2 du leve deux zones (scenario sans ponceau Ø900 intermediaire). Jaune = WSE et Surface editables (AutoCAD). Orange = 37.40 m limite ville. Ancien seuil etude 37.28 reste dans la table.
A10: WSE (m) | B10: Surface A (m2) EDIT | C10: dWSE (m) | D10: V_pas (m3) | E10: V_cumul (m3) | F10: Role
A11: 34.88 | B11: 0 | C11: 0 | D11: 0 | E11: 0 | F11: Fond bassin
A12: 35.5 | B12: 116 | C12: =A12-A11 | D12: =0.5*(B11+B12)*C12 | E12: =E11+D12 | F12: Levé Z1+Z2 — éditer si AutoCAD diffère
A13: 36.01 | B13: 429 | C13: =A13-A12 | D13: =0.5*(B12+B13)*C13 | E13: =E12+D13 | F13: Levé Z1+Z2
A14: 36.5 | B14: 530 | C14: =A14-A13 | D14: =0.5*(B13+B14)*C14 | E14: =E13+D14 | F14: Levé Z1+Z2
A15: 37 | B15: 740 | C15: =A15-A14 | D15: =0.5*(B14+B15)*C15 | E15: =E14+D15 | F15: Levé Z1+Z2
A16: 37.28 | B16: 2200 | C16: =A16-A15 | D16: =0.5*(B15+B16)*C16 | E16: =E15+D16 | F16: Ancien seuil étude (+1.5 m) — référence
A17: 37.4 | B17: 2320 | C17: =A17-A16 | D17: =0.5*(B16+B17)*C17 | E17: =E16+D17 | F17: LIMITE VILLE (WSE max + freeboard 0.6 m)
A18: 40 | B18: 3732 | C18: =A18-A17 | D18: =0.5*(B17+B18)*C18 | E18: =E17+D18 | F18: Sommet table
A21: Vmax_A / WSEmax_A | B21: =Parametres!B36 | C21: =Parametres!B38
A22: Vmax_B / WSEmax_B | B22: =Parametres!B42 | C22: =Parametres!B44
A23: V @ 37.28 m (ancien seuil) | B23: =E16
A24: V @ 37.40 m (limite ville) | B24: =E17 | C24: Comparer a Vmax Methode C

Sheet Compose_1200
A1: Methode C — Q_1200 + Q_overflow; V = V_pond (+ V_ditch si B25=1)
A2: Lie a Parametres B25–B32. Q_overflow si WSE>=crest. B25=0 → V_ditch=0 (leve seul).
A4: Crest | B4: =Parametres!B27
A5: b | B5: =Parametres!B28
A6: n | B6: =Parametres!B29
A7: z | B7: =Parametres!B30
A8: S | B8: =Parametres!B31
A9: L | B9: =Parametres!B32
A10: Zin | B10: =Parametres!B13
A11: Inclure V_ditch | B11: =Parametres!B25
A12: WSE | B12: HW | C12: y_ov | D12: A_ditch | E12: V_ditch | F12: V_pond | G12: V_total | H12: Q_1200 | I12: Q_overflow | J12: Qout | K12: V_Ø1200 (m/s) | L12: V_overflow (m/s)
A13: 34.88 | B13: =A13-$B$10 | C13: =MAX(0,A13-$B$4) | D13: =IF(C13<=0,0,($B$5+$B$7*C13)*C13) | E13: =IF($B$11=1,D13*$B$9,0) | F13: =IF(A13<=INDEX(Stage_Storage!$A$11:$A$18,1),INDEX(Stage_Storage!$E$11:$E$18,1),IF(A13>=INDEX(Stage_Storage!$A$11:$A$18,ROWS(Stage_Storage!$A$11:$A$18)),INDEX(Stage_Storage!$E$11:$E$18,ROWS(Stage_Storage!$E$11:$E$18)),INDEX(Stage_Storage!$E$11:$E$18,MATCH(A13,Stage_Storage!$A$11:$A$18,1))+(A13-INDEX(Stage_Storage!$A$11:$A$18,MATCH(A13,Stage_Storage!$A$11:$A$18,1)))/(INDEX(Stage_Storage!$A$11:$A$18,MATCH(A13,Stage_Storage!$A$11:$A$18,1)+1)-INDEX(Stage_Storage!$A$11:$A$18,MATCH(A13,Stage_Storage!$A$11:$A$18,1)))*(INDEX(Stage_Storage!$E$11:$E$18,MATCH(A13,Stage_Storage!$A$11:$A$18,1)+1)-INDEX(Stage_Storage!$E$11:$E$18,MATCH(A13,Stage_Storage!$A$11:$A$18,1))))) | G13: =F13+E13 | H13: =IF(B13<=0,0,IF(B13>=INDEX(Courbe_QH_1200!$A$20:$A$80,ROWS(Courbe_QH_1200!$A$20:$A$80)),INDEX(Courbe_QH_1200!$E$20:$E$80,ROWS(Courbe_QH_1200!$E$20:$E$80)),INDEX(Courbe_QH_1200!$E$20:$E$80,MATCH(B13,Courbe_QH_1200!$A$20:$A$80,1))+(B13-INDEX(Courbe_QH_1200!$A$20:$A$80,MATCH(B13,Courbe_QH_1200!$A$20:$A$80,1)))/(INDEX(Courbe_QH_1200!$A$20:$A$80,MATCH(B13,Courbe_QH_1200!$A$20:$A$80,1)+1)-INDEX(Courbe_QH_1200!$A$20:$A$80,MATCH(B13,Courbe_QH_1200!$A$20:$A$80,1)))*(INDEX(Courbe_QH_1200!$E$20:$E$80,MATCH(B13,Courbe_QH_1200!$A$20:$A$80,1)+1)-INDEX(Courbe_QH_1200!$E$20:$E$80,MATCH(B13,Courbe_QH_1200!$A$20:$A$80,1))))) | I13: =IF(C13<=0,0,IF($B$6<=0,0,(1/$B$6)*D13*IF(($B$5+2*C13*SQRT(1+$B$7^2))<=0,0,((D13/($B$5+2*C13*SQRT(1+$B$7^2)))^(2/3)))*SQRT($B$8))) | J13: =H13+I13 | K13: =IF(Parametres!$C$96<=0,0,H13/Parametres!$C$96) | L13: =IF(OR(C13<0.05,D13<0.05),"",I13/D13)
A14: 34.98 | B14: =A14-$B$10 | C14: =MAX(0,A14-$B$4) | D14: =IF(C14<=0,0,($B$5+$B$7*C14)*C14) | E14: =IF($B$11=1,D14*$B$9,0) | F14: =IF(A14<=INDEX(Stage_Storage!$A$11:$A$18,1),INDEX(Stage_Storage!$E$11:$E$18,1),IF(A14>=INDEX(Stage_Storage!$A$11:$A$18,ROWS(Stage_Storage!$A$11:$A$18)),INDEX(Stage_Storage!$E$11:$E$18,ROWS(Stage_Storage!$E$11:$E$18)),INDEX(Stage_Storage!$E$11:$E$18,MATCH(A14,Stage_Storage!$A$11:$A$18,1))+(A14-INDEX(Stage_Storage!$A$11:$A$18,MATCH(A14,Stage_Storage!$A$11:$A$18,1)))/(INDEX(Stage_Storage!$A$11:$A$18,MATCH(A14,Stage_Storage!$A$11:$A$18,1)+1)-INDEX(Stage_Storage!$A$11:$A$18,MATCH(A14,Stage_Storage!$A$11:$A$18,1)))*(INDEX(Stage_Storage!$E$11:$E$18,MATCH(A14,Stage_Storage!$A$11:$A$18,1)+1)-INDEX(Stage_Storage!$E$11:$E$18,MATCH(A14,Stage_Storage!$A$11:$A$18,1))))) | G14: =F14+E14 | H14: =IF(B14<=0,0,IF(B14>=INDEX(Courbe_QH_1200!$A$20:$A$80,ROWS(Courbe_QH_1200!$A$20:$A$80)),INDEX(Courbe_QH_1200!$E$20:$E$80,ROWS(Courbe_QH_1200!$E$20:$E$80)),INDEX(Courbe_QH_1200!$E$20:$E$80,MATCH(B14,Courbe_QH_1200!$A$20:$A$80,1))+(B14-INDEX(Courbe_QH_1200!$A$20:$A$80,MATCH(B14,Courbe_QH_1200!$A$20:$A$80,1)))/(INDEX(Courbe_QH_1200!$A$20:$A$80,MATCH(B14,Courbe_QH_1200!$A$20:$A$80,1)+1)-INDEX(Courbe_QH_1200!$A$20:$A$80,MATCH(B14,Courbe_QH_1200!$A$20:$A$80,1)))*(INDEX(Courbe_QH_1200!$E$20:$E$80,MATCH(B14,Courbe_QH_1200!$A$20:$A$80,1)+1)-INDEX(Courbe_QH_1200!$E$20:$E$80,MATCH(B14,Courbe_QH_1200!$A$20:$A$80,1))))) | I14: =IF(C14<=0,0,IF($B$6<=0,0,(1/$B$6)*D14*IF(($B$5+2*C14*SQRT(1+$B$7^2))<=0,0,((D14/($B$5+2*C14*SQRT(1+$B$7^2)))^(2/3)))*SQRT($B$8))) | J14: =H14+I14 | K14: =IF(Parametres!$C$96<=0,0,H14/Parametres!$C$96) | L14: =IF(OR(C14<0.05,D14<0.05),"",I14/D14)
A15: 35.08 | B15: =A15-$B$10 | C15: =MAX(0,A15-$B$4) | D15: =IF(C15<=0,0,($B$5+$B$7*C15)*C15) | E15: =IF($B$11=1,D15*$B$9,0) | F15: =IF(A15<=INDEX(Stage_Storage!$A$11:$A$18,1),INDEX(Stage_Storage!$E$11:$E$18,1),IF(A15>=INDEX(Stage_Storage!$A$11:$A$18,ROWS(Stage_Storage!$A$11:$A$18)),INDEX(Stage_Storage!$E$11:$E$18,ROWS(Stage_Storage!$E$11:$E$18)),INDEX(Stage_Storage!$E$11:$E$18,MATCH(A15,Stage_Storage!$A$11:$A$18,1))+(A15-INDEX(Stage_Storage!$A$11:$A$18,MATCH(A15,Stage_Storage!$A$11:$A$18,1)))/(INDEX(Stage_Storage!$A$11:$A$18,MATCH(A15,Stage_Storage!$A$11:$A$18,1)+1)-INDEX(Stage_Storage!$A$11:$A$18,MATCH(A15,Stage_Storage!$A$11:$A$18,1)))*(INDEX(Stage_Storage!$E$11:$E$18,MATCH(A15,Stage_Storage!$A$11:$A$18,1)+1)-INDEX(Stage_Storage!$E$11:$E$18,MATCH(A15,Stage_Storage!$A$11:$A$18,1))))) | G15: =F15+E15 | H15: =IF(B15<=0,0,IF(B15>=INDEX(Courbe_QH_1200!$A$20:$A$80,ROWS(Courbe_QH_1200!$A$20:$A$80)),INDEX(Courbe_QH_1200!$E$20:$E$80,ROWS(Courbe_QH_1200!$E$20:$E$80)),INDEX(Courbe_QH_1200!$E$20:$E$80,MATCH(B15,Courbe_QH_1200!$A$20:$A$80,1))+(B15-INDEX(Courbe_QH_1200!$A$20:$A$80,MATCH(B15,Courbe_QH_1200!$A$20:$A$80,1)))/(INDEX(Courbe_QH_1200!$A$20:$A$80,MATCH(B15,Courbe_QH_1200!$A$20:$A$80,1)+1)-INDEX(Courbe_QH_1200!$A$20:$A$80,MATCH(B15,Courbe_QH_1200!$A$20:$A$80,1)))*(INDEX(Courbe_QH_1200!$E$20:$E$80,MATCH(B15,Courbe_QH_1200!$A$20:$A$80,1)+1)-INDEX(Courbe_QH_1200!$E$20:$E$80,MATCH(B15,Courbe_QH_1200!$A$20:$A$80,1))))) | I15: =IF(C15<=0,0,IF($B$6<=0,0,(1/$B$6)*D15*IF(($B$5+2*C15*SQRT(1+$B$7^2))<=0,0,((D15/($B$5+2*C15*SQRT(1+$B$7^2)))^(2/3)))*SQRT($B$8))) | J15: =H15+I15 | K15: =IF(Parametres!$C$96<=0,0,H15/Parametres!$C$96) | L15: =IF(OR(C15<0.05,D15<0.05),"",I15/D15)
A16: 35.18 | B16: =A16-$B$10 | C16: =MAX(0,A16-$B$4) | D16: =IF(C16<=0,0,($B$5+$B$7*C16)*C16) | E16: =IF($B$11=1,D16*$B$9,0) | F16: =IF(A16<=INDEX(Stage_Storage!$A$11:$A$18,1),INDEX(Stage_Storage!$E$11:$E$18,1),IF(A16>=INDEX(Stage_Storage!$A$11:$A$18,ROWS(Stage_Storage!$A$11:$A$18)),INDEX(Stage_Storage!$E$11:$E$18,ROWS(Stage_Storage!$E$11:$E$18)),INDEX(Stage_Storage!$E$11:$E$18,MATCH(A16,Stage_Storage!$A$11:$A$18,1))+(A16-INDEX(Stage_Storage!$A$11:$A$18,MATCH(A16,Stage_Storage!$A$11:$A$18,1)))/(INDEX(Stage_Storage!$A$11:$A$18,MATCH(A16,Stage_Storage!$A$11:$A$18,1)+1)-INDEX(Stage_Storage!$A$11:$A$18,MATCH(A16,Stage_Storage!$A$11:$A$18,1)))*(INDEX(Stage_Storage!$E$11:$E$18,MATCH(A16,Stage_Storage!$A$11:$A$18,1)+1)-INDEX(Stage_Storage!$E$11:$E$18,MATCH(A16,Stage_Storage!$A$11:$A$18,1))))) | G16: =F16+E16 | H16: =IF(B16<=0,0,IF(B16>=INDEX(Courbe_QH_1200!$A$20:$A$80,ROWS(Courbe_QH_1200!$A$20:$A$80)),INDEX(Courbe_QH_1200!$E$20:$E$80,ROWS(Courbe_QH_1200!$E$20:$E$80)),INDEX(Courbe_QH_1200!$E$20:$E$80,MATCH(B16,Courbe_QH_1200!$A$20:$A$80,1))+(B16-INDEX(Courbe_QH_1200!$A$20:$A$80,MATCH(B16,Courbe_QH_1200!$A$20:$A$80,1)))/(INDEX(Courbe_QH_1200!$A$20:$A$80,MATCH(B16,Courbe_QH_1200!$A$20:$A$80,1)+1)-INDEX(Courbe_QH_1200!$A$20:$A$80,MATCH(B16,Courbe_QH_1200!$A$20:$A$80,1)))*(INDEX(Courbe_QH_1200!$E$20:$E$80,MATCH(B16,Courbe_QH_1200!$A$20:$A$80,1)+1)-INDEX(Courbe_QH_1200!$E$20:$E$80,MATCH(B16,Courbe_QH_1200!$A$20:$A$80,1))))) | I16: =IF(C16<=0,0,IF($B$6<=0,0,(1/$B$6)*D16*IF(($B$5+2*C16*SQRT(1+$B$7^2))<=0,0,((D16/($B$5+2*C16*SQRT(1+$B$7^2)))^(2/3)))*SQRT($B$8))) | J16: =H16+I16 | K16: =IF(Parametres!$C$96<=0,0,H16/Parametres!$C$96) | L16: =IF(OR(C16<0.05,D16<0.05),"",I16/D16)
A17: 35.28 | B17: =A17-$B$10 | C17: =MAX(0,A17-$B$4) | D17: =IF(C17<=0,0,($B$5+$B$7*C17)*C17) | E17: =IF($B$11=1,D17*$B$9,0) | F17: =IF(A17<=INDEX(Stage_Storage!$A$11:$A$18,1),INDEX(Stage_Storage!$E$11:$E$18,1),IF(A17>=INDEX(Stage_Storage!$A$11:$A$18,ROWS(Stage_Storage!$A$11:$A$18)),INDEX(Stage_Storage!$E$11:$E$18,ROWS(Stage_Storage!$E$11:$E$18)),INDEX(Stage_Storage!$E$11:$E$18,MATCH(A17,Stage_Storage!$A$11:$A$18,1))+(A17-INDEX(Stage_Storage!$A$11:$A$18,MATCH(A17,Stage_Storage!$A$11:$A$18,1)))/(INDEX(Stage_Storage!$A$11:$A$18,MATCH(A17,Stage_Storage!$A$11:$A$18,1)+1)-INDEX(Stage_Storage!$A$11:$A$18,MATCH(A17,Stage_Storage!$A$11:$A$18,1)))*(INDEX(Stage_Storage!$E$11:$E$18,MATCH(A17,Stage_Storage!$A$11:$A$18,1)+1)-INDEX(Stage_Storage!$E$11:$E$18,MATCH(A17,Stage_Storage!$A$11:$A$18,1))))) | G17: =F17+E17 | H17: =IF(B17<=0,0,IF(B17>=INDEX(Courbe_QH_1200!$A$20:$A$80,ROWS(Courbe_QH_1200!$A$20:$A$80)),INDEX(Courbe_QH_1200!$E$20:$E$80,ROWS(Courbe_QH_1200!$E$20:$E$80)),INDEX(Courbe_QH_1200!$E$20:$E$80,MATCH(B17,Courbe_QH_1200!$A$20:$A$80,1))+(B17-INDEX(Courbe_QH_1200!$A$20:$A$80,MATCH(B17,Courbe_QH_1200!$A$20:$A$80,1)))/(INDEX(Courbe_QH_1200!$A$20:$A$80,MATCH(B17,Courbe_QH_1200!$A$20:$A$80,1)+1)-INDEX(Courbe_QH_1200!$A$20:$A$80,MATCH(B17,Courbe_QH_1200!$A$20:$A$80,1)))*(INDEX(Courbe_QH_1200!$E$20:$E$80,MATCH(B17,Courbe_QH_1200!$A$20:$A$80,1)+1)-INDEX(Courbe_QH_1200!$E$20:$E$80,MATCH(B17,Courbe_QH_1200!$A$20:$A$80,1))))) | I17: =IF(C17<=0,0,IF($B$6<=0,0,(1/$B$6)*D17*IF(($B$5+2*C17*SQRT(1+$B$7^2))<=0,0,((D17/($B$5+2*C17*SQRT(1+$B$7^2)))^(2/3)))*SQRT($B$8))) | J17: =H17+I17 | K17: =IF(Parametres!$C$96<=0,0,H17/Parametres!$C$96) | L17: =IF(OR(C17<0.05,D17<0.05),"",I17/D17)
A18: 35.38 | B18: =A18-$B$10 | C18: =MAX(0,A18-$B$4) | D18: =IF(C18<=0,0,($B$5+$B$7*C18)*C18) | E18: =IF($B$11=1,D18*$B$9,0) | F18: =IF(A18<=INDEX(Stage_Storage!$A$11:$A$18,1),INDEX(Stage_Storage!$E$11:$E$18,1),IF(A18>=INDEX(Stage_Storage!$A$11:$A$18,ROWS(Stage_Storage!$A$11:$A$18)),INDEX(Stage_Storage!$E$11:$E$18,ROWS(Stage_Storage!$E$11:$E$18)),INDEX(Stage_Storage!$E$11:$E$18,MATCH(A18,Stage_Storage!$A$11:$A$18,1))+(A18-INDEX(Stage_Storage!$A$11:$A$18,MATCH(A18,Stage_Storage!$A$11:$A$18,1)))/(INDEX(Stage_Storage!$A$11:$A$18,MATCH(A18,Stage_Storage!$A$11:$A$18,1)+1)-INDEX(Stage_Storage!$A$11:$A$18,MATCH(A18,Stage_Storage!$A$11:$A$18,1)))*(INDEX(Stage_Storage!$E$11:$E$18,MATCH(A18,Stage_Storage!$A$11:$A$18,1)+1)-INDEX(Stage_Storage!$E$11:$E$18,MATCH(A18,Stage_Storage!$A$11:$A$18,1))))) | G18: =F18+E18 | H18: =IF(B18<=0,0,IF(B18>=INDEX(Courbe_QH_1200!$A$20:$A$80,ROWS(Courbe_QH_1200!$A$20:$A$80)),INDEX(Courbe_QH_1200!$E$20:$E$80,ROWS(Courbe_QH_1200!$E$20:$E$80)),INDEX(Courbe_QH_1200!$E$20:$E$80,MATCH(B18,Courbe_QH_1200!$A$20:$A$80,1))+(B18-INDEX(Courbe_QH_1200!$A$20:$A$80,MATCH(B18,Courbe_QH_1200!$A$20:$A$80,1)))/(INDEX(Courbe_QH_1200!$A$20:$A$80,MATCH(B18,Courbe_QH_1200!$A$20:$A$80,1)+1)-INDEX(Courbe_QH_1200!$A$20:$A$80,MATCH(B18,Courbe_QH_1200!$A$20:$A$80,1)))*(INDEX(Courbe_QH_1200!$E$20:$E$80,MATCH(B18,Courbe_QH_1200!$A$20:$A$80,1)+1)-INDEX(Courbe_QH_1200!$E$20:$E$80,MATCH(B18,Courbe_QH_1200!$A$20:$A$80,1))))) | I18: =IF(C18<=0,0,IF($B$6<=0,0,(1/$B$6)*D18*IF(($B$5+2*C18*SQRT(1+$B$7^2))<=0,0,((D18/($B$5+2*C18*SQRT(1+$B$7^2)))^(2/3)))*SQRT($B$8))) | J18: =H18+I18 | K18: =IF(Parametres!$C$96<=0,0,H18/Parametres!$C$96) | L18: =IF(OR(C18<0.05,D18<0.05),"",I18/D18)
A19: 35.48 | B19: =A19-$B$10 | C19: =MAX(0,A19-$B$4) | D19: =IF(C19<=0,0,($B$5+$B$7*C19)*C19) | E19: =IF($B$11=1,D19*$B$9,0) | F19: =IF(A19<=INDEX(Stage_Storage!$A$11:$A$18,1),INDEX(Stage_Storage!$E$11:$E$18,1),IF(A19>=INDEX(Stage_Storage!$A$11:$A$18,ROWS(Stage_Storage!$A$11:$A$18)),INDEX(Stage_Storage!$E$11:$E$18,ROWS(Stage_Storage!$E$11:$E$18)),INDEX(Stage_Storage!$E$11:$E$18,MATCH(A19,Stage_Storage!$A$11:$A$18,1))+(A19-INDEX(Stage_Storage!$A$11:$A$18,MATCH(A19,Stage_Storage!$A$11:$A$18,1)))/(INDEX(Stage_Storage!$A$11:$A$18,MATCH(A19,Stage_Storage!$A$11:$A$18,1)+1)-INDEX(Stage_Storage!$A$11:$A$18,MATCH(A19,Stage_Storage!$A$11:$A$18,1)))*(INDEX(Stage_Storage!$E$11:$E$18,MATCH(A19,Stage_Storage!$A$11:$A$18,1)+1)-INDEX(Stage_Storage!$E$11:$E$18,MATCH(A19,Stage_Storage!$A$11:$A$18,1))))) | G19: =F19+E19 | H19: =IF(B19<=0,0,IF(B19>=INDEX(Courbe_QH_1200!$A$20:$A$80,ROWS(Courbe_QH_1200!$A$20:$A$80)),INDEX(Courbe_QH_1200!$E$20:$E$80,ROWS(Courbe_QH_1200!$E$20:$E$80)),INDEX(Courbe_QH_1200!$E$20:$E$80,MATCH(B19,Courbe_QH_1200!$A$20:$A$80,1))+(B19-INDEX(Courbe_QH_1200!$A$20:$A$80,MATCH(B19,Courbe_QH_1200!$A$20:$A$80,1)))/(INDEX(Courbe_QH_1200!$A$20:$A$80,MATCH(B19,Courbe_QH_1200!$A$20:$A$80,1)+1)-INDEX(Courbe_QH_1200!$A$20:$A$80,MATCH(B19,Courbe_QH_1200!$A$20:$A$80,1)))*(INDEX(Courbe_QH_1200!$E$20:$E$80,MATCH(B19,Courbe_QH_1200!$A$20:$A$80,1)+1)-INDEX(Courbe_QH_1200!$E$20:$E$80,MATCH(B19,Courbe_QH_1200!$A$20:$A$80,1))))) | I19: =IF(C19<=0,0,IF($B$6<=0,0,(1/$B$6)*D19*IF(($B$5+2*C19*SQRT(1+$B$7^2))<=0,0,((D19/($B$5+2*C19*SQRT(1+$B$7^2)))^(2/3)))*SQRT($B$8))) | J19: =H19+I19 | K19: =IF(Parametres!$C$96<=0,0,H19/Parametres!$C$96) | L19: =IF(OR(C19<0.05,D19<0.05),"",I19/D19)
A20: 35.58 | B20: =A20-$B$10 | C20: =MAX(0,A20-$B$4) | D20: =IF(C20<=0,0,($B$5+$B$7*C20)*C20) | E20: =IF($B$11=1,D20*$B$9,0) | F20: =IF(A20<=INDEX(Stage_Storage!$A$11:$A$18,1),INDEX(Stage_Storage!$E$11:$E$18,1),IF(A20>=INDEX(Stage_Storage!$A$11:$A$18,ROWS(Stage_Storage!$A$11:$A$18)),INDEX(Stage_Storage!$E$11:$E$18,ROWS(Stage_Storage!$E$11:$E$18)),INDEX(Stage_Storage!$E$11:$E$18,MATCH(A20,Stage_Storage!$A$11:$A$18,1))+(A20-INDEX(Stage_Storage!$A$11:$A$18,MATCH(A20,Stage_Storage!$A$11:$A$18,1)))/(INDEX(Stage_Storage!$A$11:$A$18,MATCH(A20,Stage_Storage!$A$11:$A$18,1)+1)-INDEX(Stage_Storage!$A$11:$A$18,MATCH(A20,Stage_Storage!$A$11:$A$18,1)))*(INDEX(Stage_Storage!$E$11:$E$18,MATCH(A20,Stage_Storage!$A$11:$A$18,1)+1)-INDEX(Stage_Storage!$E$11:$E$18,MATCH(A20,Stage_Storage!$A$11:$A$18,1))))) | G20: =F20+E20 | H20: =IF(B20<=0,0,IF(B20>=INDEX(Courbe_QH_1200!$A$20:$A$80,ROWS(Courbe_QH_1200!$A$20:$A$80)),INDEX(Courbe_QH_1200!$E$20:$E$80,ROWS(Courbe_QH_1200!$E$20:$E$80)),INDEX(Courbe_QH_1200!$E$20:$E$80,MATCH(B20,Courbe_QH_1200!$A$20:$A$80,1))+(B20-INDEX(Courbe_QH_1200!$A$20:$A$80,MATCH(B20,Courbe_QH_1200!$A$20:$A$80,1)))/(INDEX(Courbe_QH_1200!$A$20:$A$80,MATCH(B20,Courbe_QH_1200!$A$20:$A$80,1)+1)-INDEX(Courbe_QH_1200!$A$20:$A$80,MATCH(B20,Courbe_QH_1200!$A$20:$A$80,1)))*(INDEX(Courbe_QH_1200!$E$20:$E$80,MATCH(B20,Courbe_QH_1200!$A$20:$A$80,1)+1)-INDEX(Courbe_QH_1200!$E$20:$E$80,MATCH(B20,Courbe_QH_1200!$A$20:$A$80,1))))) | I20: =IF(C20<=0,0,IF($B$6<=0,0,(1/$B$6)*D20*IF(($B$5+2*C20*SQRT(1+$B$7^2))<=0,0,((D20/($B$5+2*C20*SQRT(1+$B$7^2)))^(2/3)))*SQRT($B$8))) | J20: =H20+I20 | K20: =IF(Parametres!$C$96<=0,0,H20/Parametres!$C$96) | L20: =IF(OR(C20<0.05,D20<0.05),"",I20/D20)
A21: 35.68 | B21: =A21-$B$10 | C21: =MAX(0,A21-$B$4) | D21: =IF(C21<=0,0,($B$5+$B$7*C21)*C21) | E21: =IF($B$11=1,D21*$B$9,0) | F21: =IF(A21<=INDEX(Stage_Storage!$A$11:$A$18,1),INDEX(Stage_Storage!$E$11:$E$18,1),IF(A21>=INDEX(Stage_Storage!$A$11:$A$18,ROWS(Stage_Storage!$A$11:$A$18)),INDEX(Stage_Storage!$E$11:$E$18,ROWS(Stage_Storage!$E$11:$E$18)),INDEX(Stage_Storage!$E$11:$E$18,MATCH(A21,Stage_Storage!$A$11:$A$18,1))+(A21-INDEX(Stage_Storage!$A$11:$A$18,MATCH(A21,Stage_Storage!$A$11:$A$18,1)))/(INDEX(Stage_Storage!$A$11:$A$18,MATCH(A21,Stage_Storage!$A$11:$A$18,1)+1)-INDEX(Stage_Storage!$A$11:$A$18,MATCH(A21,Stage_Storage!$A$11:$A$18,1)))*(INDEX(Stage_Storage!$E$11:$E$18,MATCH(A21,Stage_Storage!$A$11:$A$18,1)+1)-INDEX(Stage_Storage!$E$11:$E$18,MATCH(A21,Stage_Storage!$A$11:$A$18,1))))) | G21: =F21+E21 | H21: =IF(B21<=0,0,IF(B21>=INDEX(Courbe_QH_1200!$A$20:$A$80,ROWS(Courbe_QH_1200!$A$20:$A$80)),INDEX(Courbe_QH_1200!$E$20:$E$80,ROWS(Courbe_QH_1200!$E$20:$E$80)),INDEX(Courbe_QH_1200!$E$20:$E$80,MATCH(B21,Courbe_QH_1200!$A$20:$A$80,1))+(B21-INDEX(Courbe_QH_1200!$A$20:$A$80,MATCH(B21,Courbe_QH_1200!$A$20:$A$80,1)))/(INDEX(Courbe_QH_1200!$A$20:$A$80,MATCH(B21,Courbe_QH_1200!$A$20:$A$80,1)+1)-INDEX(Courbe_QH_1200!$A$20:$A$80,MATCH(B21,Courbe_QH_1200!$A$20:$A$80,1)))*(INDEX(Courbe_QH_1200!$E$20:$E$80,MATCH(B21,Courbe_QH_1200!$A$20:$A$80,1)+1)-INDEX(Courbe_QH_1200!$E$20:$E$80,MATCH(B21,Courbe_QH_1200!$A$20:$A$80,1))))) | I21: =IF(C21<=0,0,IF($B$6<=0,0,(1/$B$6)*D21*IF(($B$5+2*C21*SQRT(1+$B$7^2))<=0,0,((D21/($B$5+2*C21*SQRT(1+$B$7^2)))^(2/3)))*SQRT($B$8))) | J21: =H21+I21 | K21: =IF(Parametres!$C$96<=0,0,H21/Parametres!$C$96) | L21: =IF(OR(C21<0.05,D21<0.05),"",I21/D21)
A22: 35.78 | B22: =A22-$B$10 | C22: =MAX(0,A22-$B$4) | D22: =IF(C22<=0,0,($B$5+$B$7*C22)*C22) | E22: =IF($B$11=1,D22*$B$9,0) | F22: =IF(A22<=INDEX(Stage_Storage!$A$11:$A$18,1),INDEX(Stage_Storage!$E$11:$E$18,1),IF(A22>=INDEX(Stage_Storage!$A$11:$A$18,ROWS(Stage_Storage!$A$11:$A$18)),INDEX(Stage_Storage!$E$11:$E$18,ROWS(Stage_Storage!$E$11:$E$18)),INDEX(Stage_Storage!$E$11:$E$18,MATCH(A22,Stage_Storage!$A$11:$A$18,1))+(A22-INDEX(Stage_Storage!$A$11:$A$18,MATCH(A22,Stage_Storage!$A$11:$A$18,1)))/(INDEX(Stage_Storage!$A$11:$A$18,MATCH(A22,Stage_Storage!$A$11:$A$18,1)+1)-INDEX(Stage_Storage!$A$11:$A$18,MATCH(A22,Stage_Storage!$A$11:$A$18,1)))*(INDEX(Stage_Storage!$E$11:$E$18,MATCH(A22,Stage_Storage!$A$11:$A$18,1)+1)-INDEX(Stage_Storage!$E$11:$E$18,MATCH(A22,Stage_Storage!$A$11:$A$18,1))))) | G22: =F22+E22 | H22: =IF(B22<=0,0,IF(B22>=INDEX(Courbe_QH_1200!$A$20:$A$80,ROWS(Courbe_QH_1200!$A$20:$A$80)),INDEX(Courbe_QH_1200!$E$20:$E$80,ROWS(Courbe_QH_1200!$E$20:$E$80)),INDEX(Courbe_QH_1200!$E$20:$E$80,MATCH(B22,Courbe_QH_1200!$A$20:$A$80,1))+(B22-INDEX(Courbe_QH_1200!$A$20:$A$80,MATCH(B22,Courbe_QH_1200!$A$20:$A$80,1)))/(INDEX(Courbe_QH_1200!$A$20:$A$80,MATCH(B22,Courbe_QH_1200!$A$20:$A$80,1)+1)-INDEX(Courbe_QH_1200!$A$20:$A$80,MATCH(B22,Courbe_QH_1200!$A$20:$A$80,1)))*(INDEX(Courbe_QH_1200!$E$20:$E$80,MATCH(B22,Courbe_QH_1200!$A$20:$A$80,1)+1)-INDEX(Courbe_QH_1200!$E$20:$E$80,MATCH(B22,Courbe_QH_1200!$A$20:$A$80,1))))) | I22: =IF(C22<=0,0,IF($B$6<=0,0,(1/$B$6)*D22*IF(($B$5+2*C22*SQRT(1+$B$7^2))<=0,0,((D22/($B$5+2*C22*SQRT(1+$B$7^2)))^(2/3)))*SQRT($B$8))) | J22: =H22+I22 | K22: =IF(Parametres!$C$96<=0,0,H22/Parametres!$C$96) | L22: =IF(OR(C22<0.05,D22<0.05),"",I22/D22)
A23: 35.88 | B23: =A23-$B$10 | C23: =MAX(0,A23-$B$4) | D23: =IF(C23<=0,0,($B$5+$B$7*C23)*C23) | E23: =IF($B$11=1,D23*$B$9,0) | F23: =IF(A23<=INDEX(Stage_Storage!$A$11:$A$18,1),INDEX(Stage_Storage!$E$11:$E$18,1),IF(A23>=INDEX(Stage_Storage!$A$11:$A$18,ROWS(Stage_Storage!$A$11:$A$18)),INDEX(Stage_Storage!$E$11:$E$18,ROWS(Stage_Storage!$E$11:$E$18)),INDEX(Stage_Storage!$E$11:$E$18,MATCH(A23,Stage_Storage!$A$11:$A$18,1))+(A23-INDEX(Stage_Storage!$A$11:$A$18,MATCH(A23,Stage_Storage!$A$11:$A$18,1)))/(INDEX(Stage_Storage!$A$11:$A$18,MATCH(A23,Stage_Storage!$A$11:$A$18,1)+1)-INDEX(Stage_Storage!$A$11:$A$18,MATCH(A23,Stage_Storage!$A$11:$A$18,1)))*(INDEX(Stage_Storage!$E$11:$E$18,MATCH(A23,Stage_Storage!$A$11:$A$18,1)+1)-INDEX(Stage_Storage!$E$11:$E$18,MATCH(A23,Stage_Storage!$A$11:$A$18,1))))) | G23: =F23+E23 | H23: =IF(B23<=0,0,IF(B23>=INDEX(Courbe_QH_1200!$A$20:$A$80,ROWS(Courbe_QH_1200!$A$20:$A$80)),INDEX(Courbe_QH_1200!$E$20:$E$80,ROWS(Courbe_QH_1200!$E$20:$E$80)),INDEX(Courbe_QH_1200!$E$20:$E$80,MATCH(B23,Courbe_QH_1200!$A$20:$A$80,1))+(B23-INDEX(Courbe_QH_1200!$A$20:$A$80,MATCH(B23,Courbe_QH_1200!$A$20:$A$80,1)))/(INDEX(Courbe_QH_1200!$A$20:$A$80,MATCH(B23,Courbe_QH_1200!$A$20:$A$80,1)+1)-INDEX(Courbe_QH_1200!$A$20:$A$80,MATCH(B23,Courbe_QH_1200!$A$20:$A$80,1)))*(INDEX(Courbe_QH_1200!$E$20:$E$80,MATCH(B23,Courbe_QH_1200!$A$20:$A$80,1)+1)-INDEX(Courbe_QH_1200!$E$20:$E$80,MATCH(B23,Courbe_QH_1200!$A$20:$A$80,1))))) | I23: =IF(C23<=0,0,IF($B$6<=0,0,(1/$B$6)*D23*IF(($B$5+2*C23*SQRT(1+$B$7^2))<=0,0,((D23/($B$5+2*C23*SQRT(1+$B$7^2)))^(2/3)))*SQRT($B$8))) | J23: =H23+I23 | K23: =IF(Parametres!$C$96<=0,0,H23/Parametres!$C$96) | L23: =IF(OR(C23<0.05,D23<0.05),"",I23/D23)
A24: 35.98 | B24: =A24-$B$10 | C24: =MAX(0,A24-$B$4) | D24: =IF(C24<=0,0,($B$5+$B$7*C24)*C24) | E24: =IF($B$11=1,D24*$B$9,0) | F24: =IF(A24<=INDEX(Stage_Storage!$A$11:$A$18,1),INDEX(Stage_Storage!$E$11:$E$18,1),IF(A24>=INDEX(Stage_Storage!$A$11:$A$18,ROWS(Stage_Storage!$A$11:$A$18)),INDEX(Stage_Storage!$E$11:$E$18,ROWS(Stage_Storage!$E$11:$E$18)),INDEX(Stage_Storage!$E$11:$E$18,MATCH(A24,Stage_Storage!$A$11:$A$18,1))+(A24-INDEX(Stage_Storage!$A$11:$A$18,MATCH(A24,Stage_Storage!$A$11:$A$18,1)))/(INDEX(Stage_Storage!$A$11:$A$18,MATCH(A24,Stage_Storage!$A$11:$A$18,1)+1)-INDEX(Stage_Storage!$A$11:$A$18,MATCH(A24,Stage_Storage!$A$11:$A$18,1)))*(INDEX(Stage_Storage!$E$11:$E$18,MATCH(A24,Stage_Storage!$A$11:$A$18,1)+1)-INDEX(Stage_Storage!$E$11:$E$18,MATCH(A24,Stage_Storage!$A$11:$A$18,1))))) | G24: =F24+E24 | H24: =IF(B24<=0,0,IF(B24>=INDEX(Courbe_QH_1200!$A$20:$A$80,ROWS(Courbe_QH_1200!$A$20:$A$80)),INDEX(Courbe_QH_1200!$E$20:$E$80,ROWS(Courbe_QH_1200!$E$20:$E$80)),INDEX(Courbe_QH_1200!$E$20:$E$80,MATCH(B24,Courbe_QH_1200!$A$20:$A$80,1))+(B24-INDEX(Courbe_QH_1200!$A$20:$A$80,MATCH(B24,Courbe_QH_1200!$A$20:$A$80,1)))/(INDEX(Courbe_QH_1200!$A$20:$A$80,MATCH(B24,Courbe_QH_1200!$A$20:$A$80,1)+1)-INDEX(Courbe_QH_1200!$A$20:$A$80,MATCH(B24,Courbe_QH_1200!$A$20:$A$80,1)))*(INDEX(Courbe_QH_1200!$E$20:$E$80,MATCH(B24,Courbe_QH_1200!$A$20:$A$80,1)+1)-INDEX(Courbe_QH_1200!$E$20:$E$80,MATCH(B24,Courbe_QH_1200!$A$20:$A$80,1))))) | I24: =IF(C24<=0,0,IF($B$6<=0,0,(1/$B$6)*D24*IF(($B$5+2*C24*SQRT(1+$B$7^2))<=0,0,((D24/($B$5+2*C24*SQRT(1+$B$7^2)))^(2/3)))*SQRT($B$8))) | J24: =H24+I24 | K24: =IF(Parametres!$C$96<=0,0,H24/Parametres!$C$96) | L24: =IF(OR(C24<0.05,D24<0.05),"",I24/D24)
