Workbook

Sheet Inputs
A1: STORMWATER PUMP STATION SIZING (PRELIMINARY)
A2: Surface_m2 | B2: 7800
A3: Surface_ha | B3: =B2/10000 | J3: Projet: 1792
A4: Coeff_ruissellement_C | B4: 0.4 | J4: Location: Métabetchouan
A5: IDF_a | B5: 4156.21 | J5: Date: | K5: =TODAY()
A6: IDF_b | B6: 15.1
A7: IDF_c | B7: 1.026 | E7: VÉRIFICATIONS DE CONCEPTION (MODÈLE vs LIMITES)
A8: Pas_temps_min | B8: 5 | E8: Indicateur | F8: Valeur du modèle | G8: Limite de conception | H8: Statut
A9: Pas_temps_sec | B9: =B8*60 | E9: S1_Stormbrixx max (m³) | F9: =MAX(Routing!$D$2:INDEX(Routing!$D:$D,Inputs!$B$53+2)) | G9: =B30 | H9: =IF(F9<=G9,"PASS","FAIL")
A10: Radier_bassin_m | B10: 102.7 | E10: Niveau WL1 max (WL1 = niveau d’eau) | F10: =MAX(Routing!$E$2:INDEX(Routing!$E:$E,Inputs!$B$53+2)) | G10: 104.2 | H10: =IF(F10<=G10,"PASS","FAIL")
A11: Radier_exutoire_m | B11: 103.32 | E11: Volume total de surverse Q_overflow1 | F11: =SUM(Routing!$G$2:INDEX(Routing!$G:$G,Inputs!$B$53+2))*Inputs!$B$9 | G11: 0 | H11: =IF(F11<=G11,"PASS","FAIL")
A12: Niveau_eau_ruisseau_m | B12: 103.32 | E12: S2_puisard max (m³) | F12: =MAX(Routing!$H$2:INDEX(Routing!$H:$H,Inputs!$B$53+2)) | G12: =B44 | H12: =IF(F12<=G12,"PASS","FAIL")
A13: Debit_unitaire_pompe_m3s | B13: =B49 | E13: Niveau WL2 max | F13: =MAX(Routing!$J$2:INDEX(Routing!$J:$J,Inputs!$B$53+2)) | G13: 104 | H13: =IF(F13<=G13,"PASS","FAIL")
A14: Pompes_en_service | B14: 1 | E14: Volume total de surverse Q_overflow2 | F14: =SUM(Routing!$I$2:INDEX(Routing!$I:$I,Inputs!$B$53+2))*Inputs!$B$9 | G14: 0 | H14: =IF(F14<=G14,"PASS","FAIL")
A15: Longueur_conduite_refoulement_m | B15: 31.5 | E15: Nombre total de démarrages (CumStarts final) | F15: =Routing!$O$205 | H15: =IF(G15="","INFO",IF(F15<=G15,"PASS","FAIL"))
A16: Diametre_conduite_refoulement_m | B16: 0.2 | E16: Démarrages/heure | F16: =Routing!$O$207 | G16: 10 | H16: =IF(F16<=G16,"PASS","FAIL")
A17: Coeff_HazenC | B17: 130 | E17: Débit maximal de pompage utilisé | F17: =MAX(Routing!$M$2:INDEX(Routing!$M:$M,MIN(200,Inputs!$B$53+2))) | G17: =B13*B14 | H17: =IF(F17<=G17,"PASS","FAIL")
A18: Coeff_pertes_singulieres_K_total | B18: =IFERROR(INDEX(Pertes_singulieres_detail!$K$10:$K$40,MATCH("S5",Pertes_singulieres_detail!$A$10:$A$40,0)),0)
A19: Niveau_marche_pompe_m | B19: 103.4 | C19: 102.8 | E19: Statut global | H19: =IF(COUNTIF(H9:H17,"FAIL")>0,"FAIL","PASS")
A20: Niveau_arret_pompe_m | B20: 102.8 | C20: 103.4
A21: Surface_plan_bassin_m2 | B21: 130
A22: Taux_vide_StormBrixx | B22: 0.9 | G22: V_reconstructed_from_area_depth_m3 | H22: =B30*B32
G23: DeltaV_m3 | H23: =H22-B30
H24: =IF(ABS(H23)<=0.01,"PASS","FAIL")
G26: Effective volume per block | H26: =0.8*0.8*0.66*B22
H27: =B30/H26
H28: =ROUND(H27,0)
H29: =H28*H26
A30: Stormbrixx_Vmax_m3 | B30: 139 | H30: =H29-B30
A31: Stormbrixx_invert_m | B31: 102.7
A32: Stormbrixx_effective_depth_m | B32: 1.32
A33: Stormbrixx_eq_area_m2 | B33: =B30/B32
A34: Orifice_d_m | B34: 0.11
A35: Cd_orifice | B35: 0.62
A36: Orifice_area_m2 | B36: =PI()*B34^2/4
A37: g | B37: 9.81
A39: Wetwell_top_level_m | B39: =MAX(B45,B46)+0.30 | C39: m | D39: Niveau de référence du puits (couvercle/limite utile). Ajustable. Par défaut: max niveau marche/arrêt + 0.30 m.
A40: Wetwell_invert_m | B40: 101.5 | C40: 102.5 | D40: 101
A41: Wetwell_diameter_m | B41: 2.8 | C41: 3 | D41: 2
A42: Wetwell_area_m2 | B42: =PI()*B41^2/4
...

Sheet IDF_Hyetograph
A1: Durée_min | B1: Intensité_mmh | C1: Lame_cumulée_mm | D1: Lame_incrementale_mm | E1: Rang | F1: Position | H1: Indice_chronologique | I1: Lame_bloc_mm | J1: Intensité_bloc_mmh | K1: Temps_min
A2: =Inputs!$B$8 | B2: =Inputs!$B$5/((A2+Inputs!$B$6)^Inputs!$B$7) | C2: =B2*A2/60 | D2: =IF(A2<=Inputs!$B$52,C2-IF(ROW()=2,0,C1),"") | E2: =IF(D2="","",COUNTIF($D$2:$D$37,">"&D2)+COUNTIF($D$2:D2,D2)) | F2: =IF(E2="","",IF(E2=1,ROUNDUP(Inputs!$B$53/2,0),IF(MOD(E2,2)=0,ROUNDUP(Inputs!$B$53/2,0)+E2/2,ROUNDUP(Inputs!$B$53/2,0)-(E2-1)/2))) | H2: 1 | I2: =IF(H2<=Inputs!$B$53,IFERROR(INDEX($D$2:$D$37,MATCH(H2,$F$2:$F$37,0)),0),0) | J2: =IF(H2<=Inputs!$B$53,I2*60/Inputs!$B$8,0) | K2: =H2*Inputs!$B$8
A3: =A2+Inputs!$B$8 | B3: =Inputs!$B$5/((A3+Inputs!$B$6)^Inputs!$B$7) | C3: =B3*A3/60 | D3: =IF(A3<=Inputs!$B$52,C3-IF(ROW()=2,0,C2),"") | E3: =IF(D3="","",COUNTIF($D$2:$D$37,">"&D3)+COUNTIF($D$2:D3,D3)) | F3: =IF(E3="","",IF(E3=1,ROUNDUP(Inputs!$B$53/2,0),IF(MOD(E3,2)=0,ROUNDUP(Inputs!$B$53/2,0)+E3/2,ROUNDUP(Inputs!$B$53/2,0)-(E3-1)/2))) | H3: 2 | I3: =IF(H3<=Inputs!$B$53,IFERROR(INDEX($D$2:$D$37,MATCH(H3,$F$2:$F$37,0)),0),0) | J3: =IF(H3<=Inputs!$B$53,I3*60/Inputs!$B$8,0) | K3: =H3*Inputs!$B$8
A4: =A3+Inputs!$B$8 | B4: =Inputs!$B$5/((A4+Inputs!$B$6)^Inputs!$B$7) | C4: =B4*A4/60 | D4: =IF(A4<=Inputs!$B$52,C4-IF(ROW()=2,0,C3),"") | E4: =IF(D4="","",COUNTIF($D$2:$D$37,">"&D4)+COUNTIF($D$2:D4,D4)) | F4: =IF(E4="","",IF(E4=1,ROUNDUP(Inputs!$B$53/2,0),IF(MOD(E4,2)=0,ROUNDUP(Inputs!$B$53/2,0)+E4/2,ROUNDUP(Inputs!$B$53/2,0)-(E4-1)/2))) | H4: 3 | I4: =IF(H4<=Inputs!$B$53,IFERROR(INDEX($D$2:$D$37,MATCH(H4,$F$2:$F$37,0)),0),0) | J4: =IF(H4<=Inputs!$B$53,I4*60/Inputs!$B$8,0) | K4: =H4*Inputs!$B$8
A5: =A4+Inputs!$B$8 | B5: =Inputs!$B$5/((A5+Inputs!$B$6)^Inputs!$B$7) | C5: =B5*A5/60 | D5: =IF(A5<=Inputs!$B$52,C5-IF(ROW()=2,0,C4),"") | E5: =IF(D5="","",COUNTIF($D$2:$D$37,">"&D5)+COUNTIF($D$2:D5,D5)) | F5: =IF(E5="","",IF(E5=1,ROUNDUP(Inputs!$B$53/2,0),IF(MOD(E5,2)=0,ROUNDUP(Inputs!$B$53/2,0)+E5/2,ROUNDUP(Inputs!$B$53/2,0)-(E5-1)/2))) | H5: 4 | I5: =IF(H5<=Inputs!$B$53,IFERROR(INDEX($D$2:$D$37,MATCH(H5,$F$2:$F$37,0)),0),0) | J5: =IF(H5<=Inputs!$B$53,I5*60/Inputs!$B$8,0) | K5: =H5*Inputs!$B$8
A6: =A5+Inputs!$B$8 | B6: =Inputs!$B$5/((A6+Inputs!$B$6)^Inputs!$B$7) | C6: =B6*A6/60 | D6: =IF(A6<=Inputs!$B$52,C6-IF(ROW()=2,0,C5),"") | E6: =IF(D6="","",COUNTIF($D$2:$D$37,">"&D6)+COUNTIF($D$2:D6,D6)) | F6: =IF(E6="","",IF(E6=1,ROUNDUP(Inputs!$B$53/2,0),IF(MOD(E6,2)=0,ROUNDUP(Inputs!$B$53/2,0)+E6/2,ROUNDUP(Inputs!$B$53/2,0)-(E6-1)/2))) | H6: 5 | I6: =IF(H6<=Inputs!$B$53,IFERROR(INDEX($D$2:$D$37,MATCH(H6,$F$2:$F$37,0)),0),0) | J6: =IF(H6<=Inputs!$B$53,I6*60/Inputs!$B$8,0) | K6: =H6*Inputs!$B$8
A7: =A6+Inputs!$B$8 | B7: =Inputs!$B$5/((A7+Inputs!$B$6)^Inputs!$B$7) | C7: =B7*A7/60 | D7: =IF(A7<=Inputs!$B$52,C7-IF(ROW()=2,0,C6),"") | E7: =IF(D7="","",COUNTIF($D$2:$D$37,">"&D7)+COUNTIF($D$2:D7,D7)) | F7: =IF(E7="","",IF(E7=1,ROUNDUP(Inputs!$B$53/2,0),IF(MOD(E7,2)=0,ROUNDUP(Inputs!$B$53/2,0)+E7/2,ROUNDUP(Inputs!$B$53/2,0)-(E7-1)/2))) | H7: 6 | I7: =IF(H7<=Inputs!$B$53,IFERROR(INDEX($D$2:$D$37,MATCH(H7,$F$2:$F$37,0)),0),0) | J7: =IF(H7<=Inputs!$B$53,I7*60/Inputs!$B$8,0) | K7: =H7*Inputs!$B$8
A8: =A7+Inputs!$B$8 | B8: =Inputs!$B$5/((A8+Inputs!$B$6)^Inputs!$B$7) | C8: =B8*A8/60 | D8: =IF(A8<=Inputs!$B$52,C8-IF(ROW()=2,0,C7),"") | E8: =IF(D8="","",COUNTIF($D$2:$D$37,">"&D8)+COUNTIF($D$2:D8,D8)) | F8: =IF(E8="","",IF(E8=1,ROUNDUP(Inputs!$B$53/2,0),IF(MOD(E8,2)=0,ROUNDUP(Inputs!$B$53/2,0)+E8/2,ROUNDUP(Inputs!$B$53/2,0)-(E8-1)/2))) | H8: 7 | I8: =IF(H8<=Inputs!$B$53,IFERROR(INDEX($D$2:$D$37,MATCH(H8,$F$2:$F$37,0)),0),0) | J8: =IF(H8<=Inputs!$B$53,I8*60/Inputs!$B$8,0) | K8: =H8*Inputs!$B$8
A9: =A8+Inputs!$B$8 | B9: =Inputs!$B$5/((A9+Inputs!$B$6)^Inputs!$B$7) | C9: =B9*A9/60 | D9: =IF(A9<=Inputs!$B$52,C9-IF(ROW()=2,0,C8),"") | E9: =IF(D9="","",COUNTIF($D$2:$D$37,">"&D9)+COUNTIF($D$2:D9,D9)) | F9: =IF(E9="","",IF(E9=1,ROUNDUP(Inputs!$B$53/2,0),IF(MOD(E9,2)=0,ROUNDUP(Inputs!$B$53/2,0)+E9/2,ROUNDUP(Inputs!$B$53/2,0)-(E9-1)/2))) | H9: 8 | I9: =IF(H9<=Inputs!$B$53,IFERROR(INDEX($D$2:$D$37,MATCH(H9,$F$2:$F$37,0)),0),0) | J9: =IF(H9<=Inputs!$B$53,I9*60/Inputs!$B$8,0) | K9: =H9*Inputs!$B$8
A10: =A9+Inputs!$B$8 | B10: =Inputs!$B$5/((A10+Inputs!$B$6)^Inputs!$B$7) | C10: =B10*A10/60 | D10: =IF(A10<=Inputs!$B$52,C10-IF(ROW()=2,0,C9),"") | E10: =IF(D10="","",COUNTIF($D$2:$D$37,">"&D10)+COUNTIF($D$2:D10,D10)) | F10: =IF(E10="","",IF(E10=1,ROUNDUP(Inputs!$B$53/2,0),IF(MOD(E10,2)=0,ROUNDUP(Inputs!$B$53/2,0)+E10/2,ROUNDUP(Inputs!$B$53/2,0)-(E10-1)/2))) | H10: 9 | I10: =IF(H10<=Inputs!$B$53,IFERROR(INDEX($D$2:$D$37,MATCH(H10,$F$2:$F$37,0)),0),0) | J10: =IF(H10<=Inputs!$B$53,I10*60/Inputs!$B$8,0) | K10: =H10*Inputs!$B$8
A11: =A10+Inputs!$B$8 | B11: =Inputs!$B$5/((A11+Inputs!$B$6)^Inputs!$B$7) | C11: =B11*A11/60 | D11: =IF(A11<=Inputs!$B$52,C11-IF(ROW()=2,0,C10),"") | E11: =IF(D11="","",COUNTIF($D$2:$D$37,">"&D11)+COUNTIF($D$2:D11,D11)) | F11: =IF(E11="","",IF(E11=1,ROUNDUP(Inputs!$B$53/2,0),IF(MOD(E11,2)=0,ROUNDUP(Inputs!$B$53/2,0)+E11/2,ROUNDUP(Inputs!$B$53/2,0)-(E11-1)/2))) | H11: 10 | I11: =IF(H11<=Inputs!$B$53,IFERROR(INDEX($D$2:$D$37,MATCH(H11,$F$2:$F$37,0)),0),0) | J11: =IF(H11<=Inputs!$B$53,I11*60/Inputs!$B$8,0) | K11: =H11*Inputs!$B$8
A12: =A11+Inputs!$B$8 | B12: =Inputs!$B$5/((A12+Inputs!$B$6)^Inputs!$B$7) | C12: =B12*A12/60 | D12: =IF(A12<=Inputs!$B$52,C12-IF(ROW()=2,0,C11),"") | E12: =IF(D12="","",COUNTIF($D$2:$D$37,">"&D12)+COUNTIF($D$2:D12,D12)) | F12: =IF(E12="","",IF(E12=1,ROUNDUP(Inputs!$B$53/2,0),IF(MOD(E12,2)=0,ROUNDUP(Inputs!$B$53/2,0)+E12/2,ROUNDUP(Inputs!$B$53/2,0)-(E12-1)/2))) | H12: 11 | I12: =IF(H12<=Inputs!$B$53,IFERROR(INDEX($D$2:$D$37,MATCH(H12,$F$2:$F$37,0)),0),0) | J12: =IF(H12<=Inputs!$B$53,I12*60/Inputs!$B$8,0) | K12: =H12*Inputs!$B$8
A13: =A12+Inputs!$B$8 | B13: =Inputs!$B$5/((A13+Inputs!$B$6)^Inputs!$B$7) | C13: =B13*A13/60 | D13: =IF(A13<=Inputs!$B$52,C13-IF(ROW()=2,0,C12),"") | E13: =IF(D13="","",COUNTIF($D$2:$D$37,">"&D13)+COUNTIF($D$2:D13,D13)) | F13: =IF(E13="","",IF(E13=1,ROUNDUP(Inputs!$B$53/2,0),IF(MOD(E13,2)=0,ROUNDUP(Inputs!$B$53/2,0)+E13/2,ROUNDUP(Inputs!$B$53/2,0)-(E13-1)/2))) | H13: 12 | I13: =IF(H13<=Inputs!$B$53,IFERROR(INDEX($D$2:$D$37,MATCH(H13,$F$2:$F$37,0)),0),0) | J13: =IF(H13<=Inputs!$B$53,I13*60/Inputs!$B$8,0) | K13: =H13*Inputs!$B$8
A14: =A13+Inputs!$B$8 | B14: =Inputs!$B$5/((A14+Inputs!$B$6)^Inputs!$B$7) | C14: =B14*A14/60 | D14: =IF(A14<=Inputs!$B$52,C14-IF(ROW()=2,0,C13),"") | E14: =IF(D14="","",COUNTIF($D$2:$D$37,">"&D14)+COUNTIF($D$2:D14,D14)) | F14: =IF(E14="","",IF(E14=1,ROUNDUP(Inputs!$B$53/2,0),IF(MOD(E14,2)=0,ROUNDUP(Inputs!$B$53/2,0)+E14/2,ROUNDUP(Inputs!$B$53/2,0)-(E14-1)/2))) | H14: 13 | I14: =IF(H14<=Inputs!$B$53,IFERROR(INDEX($D$2:$D$37,MATCH(H14,$F$2:$F$37,0)),0),0) | J14: =IF(H14<=Inputs!$B$53,I14*60/Inputs!$B$8,0) | K14: =H14*Inputs!$B$8
... A37: =A36+Inputs!$B$8 | B37: =Inputs!$B$5/((A37+Inputs!$B$6)^Inputs!$B$7) | C37: =B37*A37/60 | D37: =IF(A37<=Inputs!$B$52,C37-IF(ROW()=2,0,C36),"") | E37: =IF(D37="","",COUNTIF($D$2:$D$37,">"&D37)+COUNTIF($D$2:D37,D37)) | F37: =IF(E37="","",IF(E37=1,ROUNDUP(Inputs!$B$53/2,0),IF(MOD(E37,2)=0,ROUNDUP(Inputs!$B$53/2,0)+E37/2,ROUNDUP(Inputs!$B$53/2,0)-(E37-1)/2))) | H37: 36 | I37: =IF(H37<=Inputs!$B$53,IFERROR(INDEX($D$2:$D$37,MATCH(H37,$F$2:$F$37,0)),0),0) | J37: =IF(H37<=Inputs!$B$53,I37*60/Inputs!$B$8,0) | K37: =H37*Inputs!$B$8

Sheet Routing
A1: Temps_min | B1: Pluie_mmh | C1: Debit_entrant_toiture_m3s | D1: Stockage_S1_Stormbrixx_m3 | E1: Niveau_WL1_Stormbrixx_m | F1: Q_RP_total_m3s | G1: Debit_surverse1_m3s | H1: Stockage_S2_puisard_m3 | I1: Debit_surverse2_m3s | J1: Niveau_WL2_puisard_m | K1: Pompes_en_marche | L1: Debit_pompe_commande_m3s | M1: Debit_pompe_effectif_m3s | N1: Indicateur_demarrage | O1: Cumul_demarrages | P1: Q_jelly_in_m3s | Q1: Q_bypass_m3s | R1: Q_jelly_out_m3s | S1: Q_in_poste_m3s | V1: BlockDepth_mm
A2: 0 | B2: =IF(A2=0,0,IFERROR(INDEX(IDF_Hyetograph!$J$2:$J$37,MATCH(A2,IDF_Hyetograph!$K$2:$K$37,0)),0)) | C2: =0.00278*Inputs!$B$4*Inputs!$B$3*B2 | D2: 0 | E2: =Inputs!$B$31 | F2: 0 | G2: 0 | H2: 0 | I2: 0 | J2: =Inputs!$B$40 | K2: 0 | L2: 0 | M2: 0 | N2: 0 | O2: 0 | P2: 0 | Q2: 0 | R2: 0 | S2: 0 | U2: 1 | V2: =IFERROR(INDEX(IDF_Hyetograph!$D$2:$D$37, MATCH(U2, IDF_Hyetograph!$F$2:$F$37, 0)),"")
A3: =IF(ROW()<=Inputs!$B$53+2,A2+Inputs!$B$8,"") | B3: =IF(A3="","",IFERROR(INDEX(IDF_Hyetograph!$J$2:$J$37,MATCH(A3,IDF_Hyetograph!$K$2:$K$37,0)),0)) | C3: =IF(A3="","",0.00278*Inputs!$B$4*Inputs!$B$3*B3) | D3: =IF(A3="","",MIN( Inputs!$B$30, MAX(0, D2 + (C3-F3-G3)*Inputs!$B$9) )) | E3: =IF(A3="","",Inputs!$B$31 + D3/Inputs!$B$33) | F3: =IF(A3="","",MIN( D2/Inputs!$B$9, Inputs!$B$35*Inputs!$B$36*SQRT(2*Inputs!$B$37*MAX(E2-J2,0)) )) | G3: =IF(A3="","",MAX(0,(D2 + (C3-F3)*Inputs!$B$9 - Inputs!$B$30)/Inputs!$B$9)) | H3: =IF(A3="","",MAX(0,MIN(Inputs!$B$44,H2+(S3-M3-I3)*Inputs!$B$9))) | I3: =IF(A3="","",MAX(0,(H2+(S3-M3)*Inputs!$B$9-Inputs!$B$44)/Inputs!$B$9)) | J3: =IF(A3="","",Inputs!$B$40 + H3/Inputs!$B$42) | K3: =IF(A3="","",IF(J2>=Inputs!$B$47,2, IF(J2>=Inputs!$B$45,1, IF(J2<=Inputs!$B$46,0,K2)))) | L3: =IF(A3="","",K3*Inputs!$B$49) | M3: =IF(A3="","",MIN(L3,H2/Inputs!$B$9+S3)) | N3: =IF(A3="","",IF(AND(K3>0,K2=0),1,0)) | O3: =IF(A3="","",O2+N3) | P3: =IF(A3="","",MIN(F3,Inputs!$B$50)) | Q3: =IF(A3="","",MAX(0,F3-P3)) | R3: =IF(A3="","",P3*Inputs!$B$51) | S3: =IF(A3="","",Q3+R3) | U3: 2 | V3: =IFERROR(INDEX(IDF_Hyetograph!$D$2:$D$37, MATCH(U3, IDF_Hyetograph!$F$2:$F$37, 0)),"")
A4: =IF(ROW()<=Inputs!$B$53+2,A3+Inputs!$B$8,"") | B4: =IF(A4="","",IFERROR(INDEX(IDF_Hyetograph!$J$2:$J$37,MATCH(A4,IDF_Hyetograph!$K$2:$K$37,0)),0)) | C4: =IF(A4="","",0.00278*Inputs!$B$4*Inputs!$B$3*B4) | D4: =IF(A4="","",MIN( Inputs!$B$30, MAX(0, D3 + (C4-F4-G4)*Inputs!$B$9) )) | E4: =IF(A4="","",Inputs!$B$31 + D4/Inputs!$B$33) | F4: =IF(A4="","",MIN( D3/Inputs!$B$9, Inputs!$B$35*Inputs!$B$36*SQRT(2*Inputs!$B$37*MAX(E3-J3,0)) )) | G4: =IF(A4="","",MAX(0,(D3 + (C4-F4)*Inputs!$B$9 - Inputs!$B$30)/Inputs!$B$9)) | H4: =IF(A4="","",MAX(0,MIN(Inputs!$B$44,H3+(S4-M4-I4)*Inputs!$B$9))) | I4: =IF(A4="","",MAX(0,(H3+(S4-M4)*Inputs!$B$9-Inputs!$B$44)/Inputs!$B$9)) | J4: =IF(A4="","",Inputs!$B$40 + H4/Inputs!$B$42) | K4: =IF(A4="","",IF(J3>=Inputs!$B$47,2, IF(J3>=Inputs!$B$45,1, IF(J3<=Inputs!$B$46,0,K3)))) | L4: =IF(A4="","",K4*Inputs!$B$49) | M4: =IF(A4="","",MIN(L4,H3/Inputs!$B$9+S4)) | N4: =IF(A4="","",IF(AND(K4>0,K3=0),1,0)) | O4: =IF(A4="","",O3+N4) | P4: =IF(A4="","",MIN(F4,Inputs!$B$50)) | Q4: =IF(A4="","",MAX(0,F4-P4)) | R4: =IF(A4="","",P4*Inputs!$B$51) | S4: =IF(A4="","",Q4+R4) | U4: 3 | V4: =IFERROR(INDEX(IDF_Hyetograph!$D$2:$D$37, MATCH(U4, IDF_Hyetograph!$F$2:$F$37, 0)),"")
A5: =IF(ROW()<=Inputs!$B$53+2,A4+Inputs!$B$8,"") | B5: =IF(A5="","",IFERROR(INDEX(IDF_Hyetograph!$J$2:$J$37,MATCH(A5,IDF_Hyetograph!$K$2:$K$37,0)),0)) | C5: =IF(A5="","",0.00278*Inputs!$B$4*Inputs!$B$3*B5) | D5: =IF(A5="","",MIN( Inputs!$B$30, MAX(0, D4 + (C5-F5-G5)*Inputs!$B$9) )) | E5: =IF(A5="","",Inputs!$B$31 + D5/Inputs!$B$33) | F5: =IF(A5="","",MIN( D4/Inputs!$B$9, Inputs!$B$35*Inputs!$B$36*SQRT(2*Inputs!$B$37*MAX(E4-J4,0)) )) | G5: =IF(A5="","",MAX(0,(D4 + (C5-F5)*Inputs!$B$9 - Inputs!$B$30)/Inputs!$B$9)) | H5: =IF(A5="","",MAX(0,MIN(Inputs!$B$44,H4+(S5-M5-I5)*Inputs!$B$9))) | I5: =IF(A5="","",MAX(0,(H4+(S5-M5)*Inputs!$B$9-Inputs!$B$44)/Inputs!$B$9)) | J5: =IF(A5="","",Inputs!$B$40 + H5/Inputs!$B$42) | K5: =IF(A5="","",IF(J4>=Inputs!$B$47,2, IF(J4>=Inputs!$B$45,1, IF(J4<=Inputs!$B$46,0,K4)))) | L5: =IF(A5="","",K5*Inputs!$B$49) | M5: =IF(A5="","",MIN(L5,H4/Inputs!$B$9+S5)) | N5: =IF(A5="","",IF(AND(K5>0,K4=0),1,0)) | O5: =IF(A5="","",O4+N5) | P5: =IF(A5="","",MIN(F5,Inputs!$B$50)) | Q5: =IF(A5="","",MAX(0,F5-P5)) | R5: =IF(A5="","",P5*Inputs!$B$51) | S5: =IF(A5="","",Q5+R5) | U5: 4 | V5: =IFERROR(INDEX(IDF_Hyetograph!$D$2:$D$37, MATCH(U5, IDF_Hyetograph!$F$2:$F$37, 0)),"")
A6: =IF(ROW()<=Inputs!$B$53+2,A5+Inputs!$B$8,"") | B6: =IF(A6="","",IFERROR(INDEX(IDF_Hyetograph!$J$2:$J$37,MATCH(A6,IDF_Hyetograph!$K$2:$K$37,0)),0)) | C6: =IF(A6="","",0.00278*Inputs!$B$4*Inputs!$B$3*B6) | D6: =IF(A6="","",MIN( Inputs!$B$30, MAX(0, D5 + (C6-F6-G6)*Inputs!$B$9) )) | E6: =IF(A6="","",Inputs!$B$31 + D6/Inputs!$B$33) | F6: =IF(A6="","",MIN( D5/Inputs!$B$9, Inputs!$B$35*Inputs!$B$36*SQRT(2*Inputs!$B$37*MAX(E5-J5,0)) )) | G6: =IF(A6="","",MAX(0,(D5 + (C6-F6)*Inputs!$B$9 - Inputs!$B$30)/Inputs!$B$9)) | H6: =IF(A6="","",MAX(0,MIN(Inputs!$B$44,H5+(S6-M6-I6)*Inputs!$B$9))) | I6: =IF(A6="","",MAX(0,(H5+(S6-M6)*Inputs!$B$9-Inputs!$B$44)/Inputs!$B$9)) | J6: =IF(A6="","",Inputs!$B$40 + H6/Inputs!$B$42) | K6: =IF(A6="","",IF(J5>=Inputs!$B$47,2, IF(J5>=Inputs!$B$45,1, IF(J5<=Inputs!$B$46,0,K5)))) | L6: =IF(A6="","",K6*Inputs!$B$49) | M6: =IF(A6="","",MIN(L6,H5/Inputs!$B$9+S6)) | N6: =IF(A6="","",IF(AND(K6>0,K5=0),1,0)) | O6: =IF(A6="","",O5+N6) | P6: =IF(A6="","",MIN(F6,Inputs!$B$50)) | Q6: =IF(A6="","",MAX(0,F6-P6)) | R6: =IF(A6="","",P6*Inputs!$B$51) | S6: =IF(A6="","",Q6+R6) | U6: 5 | V6: =IFERROR(INDEX(IDF_Hyetograph!$D$2:$D$37, MATCH(U6, IDF_Hyetograph!$F$2:$F$37, 0)),"")
A7: =IF(ROW()<=Inputs!$B$53+2,A6+Inputs!$B$8,"") | B7: =IF(A7="","",IFERROR(INDEX(IDF_Hyetograph!$J$2:$J$37,MATCH(A7,IDF_Hyetograph!$K$2:$K$37,0)),0)) | C7: =IF(A7="","",0.00278*Inputs!$B$4*Inputs!$B$3*B7) | D7: =IF(A7="","",MIN( Inputs!$B$30, MAX(0, D6 + (C7-F7-G7)*Inputs!$B$9) )) | E7: =IF(A7="","",Inputs!$B$31 + D7/Inputs!$B$33) | F7: =IF(A7="","",MIN( D6/Inputs!$B$9, Inputs!$B$35*Inputs!$B$36*SQRT(2*Inputs!$B$37*MAX(E6-J6,0)) )) | G7: =IF(A7="","",MAX(0,(D6 + (C7-F7)*Inputs!$B$9 - Inputs!$B$30)/Inputs!$B$9)) | H7: =IF(A7="","",MAX(0,MIN(Inputs!$B$44,H6+(S7-M7-I7)*Inputs!$B$9))) | I7: =IF(A7="","",MAX(0,(H6+(S7-M7)*Inputs!$B$9-Inputs!$B$44)/Inputs!$B$9)) | J7: =IF(A7="","",Inputs!$B$40 + H7/Inputs!$B$42) | K7: =IF(A7="","",IF(J6>=Inputs!$B$47,2, IF(J6>=Inputs!$B$45,1, IF(J6<=Inputs!$B$46,0,K6)))) | L7: =IF(A7="","",K7*Inputs!$B$49) | M7: =IF(A7="","",MIN(L7,H6/Inputs!$B$9+S7)) | N7: =IF(A7="","",IF(AND(K7>0,K6=0),1,0)) | O7: =IF(A7="","",O6+N7) | P7: =IF(A7="","",MIN(F7,Inputs!$B$50)) | Q7: =IF(A7="","",MAX(0,F7-P7)) | R7: =IF(A7="","",P7*Inputs!$B$51) | S7: =IF(A7="","",Q7+R7) | U7: 6 | V7: =IFERROR(INDEX(IDF_Hyetograph!$D$2:$D$37, MATCH(U7, IDF_Hyetograph!$F$2:$F$37, 0)),"")
A8: =IF(ROW()<=Inputs!$B$53+2,A7+Inputs!$B$8,"") | B8: =IF(A8="","",IFERROR(INDEX(IDF_Hyetograph!$J$2:$J$37,MATCH(A8,IDF_Hyetograph!$K$2:$K$37,0)),0)) | C8: =IF(A8="","",0.00278*Inputs!$B$4*Inputs!$B$3*B8) | D8: =IF(A8="","",MIN( Inputs!$B$30, MAX(0, D7 + (C8-F8-G8)*Inputs!$B$9) )) | E8: =IF(A8="","",Inputs!$B$31 + D8/Inputs!$B$33) | F8: =IF(A8="","",MIN( D7/Inputs!$B$9, Inputs!$B$35*Inputs!$B$36*SQRT(2*Inputs!$B$37*MAX(E7-J7,0)) )) | G8: =IF(A8="","",MAX(0,(D7 + (C8-F8)*Inputs!$B$9 - Inputs!$B$30)/Inputs!$B$9)) | H8: =IF(A8="","",MAX(0,MIN(Inputs!$B$44,H7+(S8-M8-I8)*Inputs!$B$9))) | I8: =IF(A8="","",MAX(0,(H7+(S8-M8)*Inputs!$B$9-Inputs!$B$44)/Inputs!$B$9)) | J8: =IF(A8="","",Inputs!$B$40 + H8/Inputs!$B$42) | K8: =IF(A8="","",IF(J7>=Inputs!$B$47,2, IF(J7>=Inputs!$B$45,1, IF(J7<=Inputs!$B$46,0,K7)))) | L8: =IF(A8="","",K8*Inputs!$B$49) | M8: =IF(A8="","",MIN(L8,H7/Inputs!$B$9+S8)) | N8: =IF(A8="","",IF(AND(K8>0,K7=0),1,0)) | O8: =IF(A8="","",O7+N8) | P8: =IF(A8="","",MIN(F8,Inputs!$B$50)) | Q8: =IF(A8="","",MAX(0,F8-P8)) | R8: =IF(A8="","",P8*Inputs!$B$51) | S8: =IF(A8="","",Q8+R8) | U8: 7 | V8: =IFERROR(INDEX(IDF_Hyetograph!$D$2:$D$37, MATCH(U8, IDF_Hyetograph!$F$2:$F$37, 0)),"")
A9: =IF(ROW()<=Inputs!$B$53+2,A8+Inputs!$B$8,"") | B9: =IF(A9="","",IFERROR(INDEX(IDF_Hyetograph!$J$2:$J$37,MATCH(A9,IDF_Hyetograph!$K$2:$K$37,0)),0)) | C9: =IF(A9="","",0.00278*Inputs!$B$4*Inputs!$B$3*B9) | D9: =IF(A9="","",MIN( Inputs!$B$30, MAX(0, D8 + (C9-F9-G9)*Inputs!$B$9) )) | E9: =IF(A9="","",Inputs!$B$31 + D9/Inputs!$B$33) | F9: =IF(A9="","",MIN( D8/Inputs!$B$9, Inputs!$B$35*Inputs!$B$36*SQRT(2*Inputs!$B$37*MAX(E8-J8,0)) )) | G9: =IF(A9="","",MAX(0,(D8 + (C9-F9)*Inputs!$B$9 - Inputs!$B$30)/Inputs!$B$9)) | H9: =IF(A9="","",MAX(0,MIN(Inputs!$B$44,H8+(S9-M9-I9)*Inputs!$B$9))) | I9: =IF(A9="","",MAX(0,(H8+(S9-M9)*Inputs!$B$9-Inputs!$B$44)/Inputs!$B$9)) | J9: =IF(A9="","",Inputs!$B$40 + H9/Inputs!$B$42) | K9: =IF(A9="","",IF(J8>=Inputs!$B$47,2, IF(J8>=Inputs!$B$45,1, IF(J8<=Inputs!$B$46,0,K8)))) | L9: =IF(A9="","",K9*Inputs!$B$49) | M9: =IF(A9="","",MIN(L9,H8/Inputs!$B$9+S9)) | N9: =IF(A9="","",IF(AND(K9>0,K8=0),1,0)) | O9: =IF(A9="","",O8+N9) | P9: =IF(A9="","",MIN(F9,Inputs!$B$50)) | Q9: =IF(A9="","",MAX(0,F9-P9)) | R9: =IF(A9="","",P9*Inputs!$B$51) | S9: =IF(A9="","",Q9+R9) | U9: 8 | V9: =IFERROR(INDEX(IDF_Hyetograph!$D$2:$D$37, MATCH(U9, IDF_Hyetograph!$F$2:$F$37, 0)),"")
A10: =IF(ROW()<=Inputs!$B$53+2,A9+Inputs!$B$8,"") | B10: =IF(A10="","",IFERROR(INDEX(IDF_Hyetograph!$J$2:$J$37,MATCH(A10,IDF_Hyetograph!$K$2:$K$37,0)),0)) | C10: =IF(A10="","",0.00278*Inputs!$B$4*Inputs!$B$3*B10) | D10: =IF(A10="","",MIN( Inputs!$B$30, MAX(0, D9 + (C10-F10-G10)*Inputs!$B$9) )) | E10: =IF(A10="","",Inputs!$B$31 + D10/Inputs!$B$33) | F10: =IF(A10="","",MIN( D9/Inputs!$B$9, Inputs!$B$35*Inputs!$B$36*SQRT(2*Inputs!$B$37*MAX(E9-J9,0)) )) | G10: =IF(A10="","",MAX(0,(D9 + (C10-F10)*Inputs!$B$9 - Inputs!$B$30)/Inputs!$B$9)) | H10: =IF(A10="","",MAX(0,MIN(Inputs!$B$44,H9+(S10-M10-I10)*Inputs!$B$9))) | I10: =IF(A10="","",MAX(0,(H9+(S10-M10)*Inputs!$B$9-Inputs!$B$44)/Inputs!$B$9)) | J10: =IF(A10="","",Inputs!$B$40 + H10/Inputs!$B$42) | K10: =IF(A10="","",IF(J9>=Inputs!$B$47,2, IF(J9>=Inputs!$B$45,1, IF(J9<=Inputs!$B$46,0,K9)))) | L10: =IF(A10="","",K10*Inputs!$B$49) | M10: =IF(A10="","",MIN(L10,H9/Inputs!$B$9+S10)) | N10: =IF(A10="","",IF(AND(K10>0,K9=0),1,0)) | O10: =IF(A10="","",O9+N10) | P10: =IF(A10="","",MIN(F10,Inputs!$B$50)) | Q10: =IF(A10="","",MAX(0,F10-P10)) | R10: =IF(A10="","",P10*Inputs!$B$51) | S10: =IF(A10="","",Q10+R10) | U10: 9 | V10: =IFERROR(INDEX(IDF_Hyetograph!$D$2:$D$37, MATCH(U10, IDF_Hyetograph!$F$2:$F$37, 0)),"")
A11: =IF(ROW()<=Inputs!$B$53+2,A10+Inputs!$B$8,"") | B11: =IF(A11="","",IFERROR(INDEX(IDF_Hyetograph!$J$2:$J$37,MATCH(A11,IDF_Hyetograph!$K$2:$K$37,0)),0)) | C11: =IF(A11="","",0.00278*Inputs!$B$4*Inputs!$B$3*B11) | D11: =IF(A11="","",MIN( Inputs!$B$30, MAX(0, D10 + (C11-F11-G11)*Inputs!$B$9) )) | E11: =IF(A11="","",Inputs!$B$31 + D11/Inputs!$B$33) | F11: =IF(A11="","",MIN( D10/Inputs!$B$9, Inputs!$B$35*Inputs!$B$36*SQRT(2*Inputs!$B$37*MAX(E10-J10,0)) )) | G11: =IF(A11="","",MAX(0,(D10 + (C11-F11)*Inputs!$B$9 - Inputs!$B$30)/Inputs!$B$9)) | H11: =IF(A11="","",MAX(0,MIN(Inputs!$B$44,H10+(S11-M11-I11)*Inputs!$B$9))) | I11: =IF(A11="","",MAX(0,(H10+(S11-M11)*Inputs!$B$9-Inputs!$B$44)/Inputs!$B$9)) | J11: =IF(A11="","",Inputs!$B$40 + H11/Inputs!$B$42) | K11: =IF(A11="","",IF(J10>=Inputs!$B$47,2, IF(J10>=Inputs!$B$45,1, IF(J10<=Inputs!$B$46,0,K10)))) | L11: =IF(A11="","",K11*Inputs!$B$49) | M11: =IF(A11="","",MIN(L11,H10/Inputs!$B$9+S11)) | N11: =IF(A11="","",IF(AND(K11>0,K10=0),1,0)) | O11: =IF(A11="","",O10+N11) | P11: =IF(A11="","",MIN(F11,Inputs!$B$50)) | Q11: =IF(A11="","",MAX(0,F11-P11)) | R11: =IF(A11="","",P11*Inputs!$B$51) | S11: =IF(A11="","",Q11+R11) | U11: 10 | V11: =IFERROR(INDEX(IDF_Hyetograph!$D$2:$D$37, MATCH(U11, IDF_Hyetograph!$F$2:$F$37, 0)),"")
A12: =IF(ROW()<=Inputs!$B$53+2,A11+Inputs!$B$8,"") | B12: =IF(A12="","",IFERROR(INDEX(IDF_Hyetograph!$J$2:$J$37,MATCH(A12,IDF_Hyetograph!$K$2:$K$37,0)),0)) | C12: =IF(A12="","",0.00278*Inputs!$B$4*Inputs!$B$3*B12) | D12: =IF(A12="","",MIN( Inputs!$B$30, MAX(0, D11 + (C12-F12-G12)*Inputs!$B$9) )) | E12: =IF(A12="","",Inputs!$B$31 + D12/Inputs!$B$33) | F12: =IF(A12="","",MIN( D11/Inputs!$B$9, Inputs!$B$35*Inputs!$B$36*SQRT(2*Inputs!$B$37*MAX(E11-J11,0)) )) | G12: =IF(A12="","",MAX(0,(D11 + (C12-F12)*Inputs!$B$9 - Inputs!$B$30)/Inputs!$B$9)) | H12: =IF(A12="","",MAX(0,MIN(Inputs!$B$44,H11+(S12-M12-I12)*Inputs!$B$9))) | I12: =IF(A12="","",MAX(0,(H11+(S12-M12)*Inputs!$B$9-Inputs!$B$44)/Inputs!$B$9)) | J12: =IF(A12="","",Inputs!$B$40 + H12/Inputs!$B$42) | K12: =IF(A12="","",IF(J11>=Inputs!$B$47,2, IF(J11>=Inputs!$B$45,1, IF(J11<=Inputs!$B$46,0,K11)))) | L12: =IF(A12="","",K12*Inputs!$B$49) | M12: =IF(A12="","",MIN(L12,H11/Inputs!$B$9+S12)) | N12: =IF(A12="","",IF(AND(K12>0,K11=0),1,0)) | O12: =IF(A12="","",O11+N12) | P12: =IF(A12="","",MIN(F12,Inputs!$B$50)) | Q12: =IF(A12="","",MAX(0,F12-P12)) | R12: =IF(A12="","",P12*Inputs!$B$51) | S12: =IF(A12="","",Q12+R12) | U12: 11 | V12: =IFERROR(INDEX(IDF_Hyetograph!$D$2:$D$37, MATCH(U12, IDF_Hyetograph!$F$2:$F$37, 0)),"")
A13: =IF(ROW()<=Inputs!$B$53+2,A12+Inputs!$B$8,"") | B13: =IF(A13="","",IFERROR(INDEX(IDF_Hyetograph!$J$2:$J$37,MATCH(A13,IDF_Hyetograph!$K$2:$K$37,0)),0)) | C13: =IF(A13="","",0.00278*Inputs!$B$4*Inputs!$B$3*B13) | D13: =IF(A13="","",MIN( Inputs!$B$30, MAX(0, D12 + (C13-F13-G13)*Inputs!$B$9) )) | E13: =IF(A13="","",Inputs!$B$31 + D13/Inputs!$B$33) | F13: =IF(A13="","",MIN( D12/Inputs!$B$9, Inputs!$B$35*Inputs!$B$36*SQRT(2*Inputs!$B$37*MAX(E12-J12,0)) )) | G13: =IF(A13="","",MAX(0,(D12 + (C13-F13)*Inputs!$B$9 - Inputs!$B$30)/Inputs!$B$9)) | H13: =IF(A13="","",MAX(0,MIN(Inputs!$B$44,H12+(S13-M13-I13)*Inputs!$B$9))) | I13: =IF(A13="","",MAX(0,(H12+(S13-M13)*Inputs!$B$9-Inputs!$B$44)/Inputs!$B$9)) | J13: =IF(A13="","",Inputs!$B$40 + H13/Inputs!$B$42) | K13: =IF(A13="","",IF(J12>=Inputs!$B$47,2, IF(J12>=Inputs!$B$45,1, IF(J12<=Inputs!$B$46,0,K12)))) | L13: =IF(A13="","",K13*Inputs!$B$49) | M13: =IF(A13="","",MIN(L13,H12/Inputs!$B$9+S13)) | N13: =IF(A13="","",IF(AND(K13>0,K12=0),1,0)) | O13: =IF(A13="","",O12+N13) | P13: =IF(A13="","",MIN(F13,Inputs!$B$50)) | Q13: =IF(A13="","",MAX(0,F13-P13)) | R13: =IF(A13="","",P13*Inputs!$B$51) | S13: =IF(A13="","",Q13+R13) | U13: 12 | V13: =IFERROR(INDEX(IDF_Hyetograph!$D$2:$D$37, MATCH(U13, IDF_Hyetograph!$F$2:$F$37, 0)),"")
A14: =IF(ROW()<=Inputs!$B$53+2,A13+Inputs!$B$8,"") | B14: =IF(A14="","",IFERROR(INDEX(IDF_Hyetograph!$J$2:$J$37,MATCH(A14,IDF_Hyetograph!$K$2:$K$37,0)),0)) | C14: =IF(A14="","",0.00278*Inputs!$B$4*Inputs!$B$3*B14) | D14: =IF(A14="","",MIN( Inputs!$B$30, MAX(0, D13 + (C14-F14-G14)*Inputs!$B$9) )) | E14: =IF(A14="","",Inputs!$B$31 + D14/Inputs!$B$33) | F14: =IF(A14="","",MIN( D13/Inputs!$B$9, Inputs!$B$35*Inputs!$B$36*SQRT(2*Inputs!$B$37*MAX(E13-J13,0)) )) | G14: =IF(A14="","",MAX(0,(D13 + (C14-F14)*Inputs!$B$9 - Inputs!$B$30)/Inputs!$B$9)) | H14: =IF(A14="","",MAX(0,MIN(Inputs!$B$44,H13+(S14-M14-I14)*Inputs!$B$9))) | I14: =IF(A14="","",MAX(0,(H13+(S14-M14)*Inputs!$B$9-Inputs!$B$44)/Inputs!$B$9)) | J14: =IF(A14="","",Inputs!$B$40 + H14/Inputs!$B$42) | K14: =IF(A14="","",IF(J13>=Inputs!$B$47,2, IF(J13>=Inputs!$B$45,1, IF(J13<=Inputs!$B$46,0,K13)))) | L14: =IF(A14="","",K14*Inputs!$B$49) | M14: =IF(A14="","",MIN(L14,H13/Inputs!$B$9+S14)) | N14: =IF(A14="","",IF(AND(K14>0,K13=0),1,0)) | O14: =IF(A14="","",O13+N14) | P14: =IF(A14="","",MIN(F14,Inputs!$B$50)) | Q14: =IF(A14="","",MAX(0,F14-P14)) | R14: =IF(A14="","",P14*Inputs!$B$51) | S14: =IF(A14="","",Q14+R14)
A15: =IF(ROW()<=Inputs!$B$53+2,A14+Inputs!$B$8,"") | B15: =IF(A15="","",IFERROR(INDEX(IDF_Hyetograph!$J$2:$J$37,MATCH(A15,IDF_Hyetograph!$K$2:$K$37,0)),0)) | C15: =IF(A15="","",0.00278*Inputs!$B$4*Inputs!$B$3*B15) | D15: =IF(A15="","",MIN( Inputs!$B$30, MAX(0, D14 + (C15-F15-G15)*Inputs!$B$9) )) | E15: =IF(A15="","",Inputs!$B$31 + D15/Inputs!$B$33) | F15: =IF(A15="","",MIN( D14/Inputs!$B$9, Inputs!$B$35*Inputs!$B$36*SQRT(2*Inputs!$B$37*MAX(E14-J14,0)) )) | G15: =IF(A15="","",MAX(0,(D14 + (C15-F15)*Inputs!$B$9 - Inputs!$B$30)/Inputs!$B$9)) | H15: =IF(A15="","",MAX(0,MIN(Inputs!$B$44,H14+(S15-M15-I15)*Inputs!$B$9))) | I15: =IF(A15="","",MAX(0,(H14+(S15-M15)*Inputs!$B$9-Inputs!$B$44)/Inputs!$B$9)) | J15: =IF(A15="","",Inputs!$B$40 + H15/Inputs!$B$42) | K15: =IF(A15="","",IF(J14>=Inputs!$B$47,2, IF(J14>=Inputs!$B$45,1, IF(J14<=Inputs!$B$46,0,K14)))) | L15: =IF(A15="","",K15*Inputs!$B$49) | M15: =IF(A15="","",MIN(L15,H14/Inputs!$B$9+S15)) | N15: =IF(A15="","",IF(AND(K15>0,K14=0),1,0)) | O15: =IF(A15="","",O14+N15) | P15: =IF(A15="","",MIN(F15,Inputs!$B$50)) | Q15: =IF(A15="","",MAX(0,F15-P15)) | R15: =IF(A15="","",P15*Inputs!$B$51) | S15: =IF(A15="","",Q15+R15)
A16: =IF(ROW()<=Inputs!$B$53+2,A15+Inputs!$B$8,"") | B16: =IF(A16="","",IFERROR(INDEX(IDF_Hyetograph!$J$2:$J$37,MATCH(A16,IDF_Hyetograph!$K$2:$K$37,0)),0)) | C16: =IF(A16="","",0.00278*Inputs!$B$4*Inputs!$B$3*B16) | D16: =IF(A16="","",MIN( Inputs!$B$30, MAX(0, D15 + (C16-F16-G16)*Inputs!$B$9) )) | E16: =IF(A16="","",Inputs!$B$31 + D16/Inputs!$B$33) | F16: =IF(A16="","",MIN( D15/Inputs!$B$9, Inputs!$B$35*Inputs!$B$36*SQRT(2*Inputs!$B$37*MAX(E15-J15,0)) )) | G16: =IF(A16="","",MAX(0,(D15 + (C16-F16)*Inputs!$B$9 - Inputs!$B$30)/Inputs!$B$9)) | H16: =IF(A16="","",MAX(0,MIN(Inputs!$B$44,H15+(S16-M16-I16)*Inputs!$B$9))) | I16: =IF(A16="","",MAX(0,(H15+(S16-M16)*Inputs!$B$9-Inputs!$B$44)/Inputs!$B$9)) | J16: =IF(A16="","",Inputs!$B$40 + H16/Inputs!$B$42) | K16: =IF(A16="","",IF(J15>=Inputs!$B$47,2, IF(J15>=Inputs!$B$45,1, IF(J15<=Inputs!$B$46,0,K15)))) | L16: =IF(A16="","",K16*Inputs!$B$49) | M16: =IF(A16="","",MIN(L16,H15/Inputs!$B$9+S16)) | N16: =IF(A16="","",IF(AND(K16>0,K15=0),1,0)) | O16: =IF(A16="","",O15+N16) | P16: =IF(A16="","",MIN(F16,Inputs!$B$50)) | Q16: =IF(A16="","",MAX(0,F16-P16)) | R16: =IF(A16="","",P16*Inputs!$B$51) | S16: =IF(A16="","",Q16+R16)
A17: =IF(ROW()<=Inputs!$B$53+2,A16+Inputs!$B$8,"") | B17: =IF(A17="","",IFERROR(INDEX(IDF_Hyetograph!$J$2:$J$37,MATCH(A17,IDF_Hyetograph!$K$2:$K$37,0)),0)) | C17: =IF(A17="","",0.00278*Inputs!$B$4*Inputs!$B$3*B17) | D17: =IF(A17="","",MIN( Inputs!$B$30, MAX(0, D16 + (C17-F17-G17)*Inputs!$B$9) )) | E17: =IF(A17="","",Inputs!$B$31 + D17/Inputs!$B$33) | F17: =IF(A17="","",MIN( D16/Inputs!$B$9, Inputs!$B$35*Inputs!$B$36*SQRT(2*Inputs!$B$37*MAX(E16-J16,0)) )) | G17: =IF(A17="","",MAX(0,(D16 + (C17-F17)*Inputs!$B$9 - Inputs!$B$30)/Inputs!$B$9)) | H17: =IF(A17="","",MAX(0,MIN(Inputs!$B$44,H16+(S17-M17-I17)*Inputs!$B$9))) | I17: =IF(A17="","",MAX(0,(H16+(S17-M17)*Inputs!$B$9-Inputs!$B$44)/Inputs!$B$9)) | J17: =IF(A17="","",Inputs!$B$40 + H17/Inputs!$B$42) | K17: =IF(A17="","",IF(J16>=Inputs!$B$47,2, IF(J16>=Inputs!$B$45,1, IF(J16<=Inputs!$B$46,0,K16)))) | L17: =IF(A17="","",K17*Inputs!$B$49) | M17: =IF(A17="","",MIN(L17,H16/Inputs!$B$9+S17)) | N17: =IF(A17="","",IF(AND(K17>0,K16=0),1,0)) | O17: =IF(A17="","",O16+N17) | P17: =IF(A17="","",MIN(F17,Inputs!$B$50)) | Q17: =IF(A17="","",MAX(0,F17-P17)) | R17: =IF(A17="","",P17*Inputs!$B$51) | S17: =IF(A17="","",Q17+R17)
A18: =IF(ROW()<=Inputs!$B$53+2,A17+Inputs!$B$8,"") | B18: =IF(A18="","",IFERROR(INDEX(IDF_Hyetograph!$J$2:$J$37,MATCH(A18,IDF_Hyetograph!$K$2:$K$37,0)),0)) | C18: =IF(A18="","",0.00278*Inputs!$B$4*Inputs!$B$3*B18) | D18: =IF(A18="","",MIN( Inputs!$B$30, MAX(0, D17 + (C18-F18-G18)*Inputs!$B$9) )) | E18: =IF(A18="","",Inputs!$B$31 + D18/Inputs!$B$33) | F18: =IF(A18="","",MIN( D17/Inputs!$B$9, Inputs!$B$35*Inputs!$B$36*SQRT(2*Inputs!$B$37*MAX(E17-J17,0)) )) | G18: =IF(A18="","",MAX(0,(D17 + (C18-F18)*Inputs!$B$9 - Inputs!$B$30)/Inputs!$B$9)) | H18: =IF(A18="","",MAX(0,MIN(Inputs!$B$44,H17+(S18-M18-I18)*Inputs!$B$9))) | I18: =IF(A18="","",MAX(0,(H17+(S18-M18)*Inputs!$B$9-Inputs!$B$44)/Inputs!$B$9)) | J18: =IF(A18="","",Inputs!$B$40 + H18/Inputs!$B$42) | K18: =IF(A18="","",IF(J17>=Inputs!$B$47,2, IF(J17>=Inputs!$B$45,1, IF(J17<=Inputs!$B$46,0,K17)))) | L18: =IF(A18="","",K18*Inputs!$B$49) | M18: =IF(A18="","",MIN(L18,H17/Inputs!$B$9+S18)) | N18: =IF(A18="","",IF(AND(K18>0,K17=0),1,0)) | O18: =IF(A18="","",O17+N18) | P18: =IF(A18="","",MIN(F18,Inputs!$B$50)) | Q18: =IF(A18="","",MAX(0,F18-P18)) | R18: =IF(A18="","",P18*Inputs!$B$51) | S18: =IF(A18="","",Q18+R18)
A19: =IF(ROW()<=Inputs!$B$53+2,A18+Inputs!$B$8,"") | B19: =IF(A19="","",IFERROR(INDEX(IDF_Hyetograph!$J$2:$J$37,MATCH(A19,IDF_Hyetograph!$K$2:$K$37,0)),0)) | C19: =IF(A19="","",0.00278*Inputs!$B$4*Inputs!$B$3*B19) | D19: =IF(A19="","",MIN( Inputs!$B$30, MAX(0, D18 + (C19-F19-G19)*Inputs!$B$9) )) | E19: =IF(A19="","",Inputs!$B$31 + D19/Inputs!$B$33) | F19: =IF(A19="","",MIN( D18/Inputs!$B$9, Inputs!$B$35*Inputs!$B$36*SQRT(2*Inputs!$B$37*MAX(E18-J18,0)) )) | G19: =IF(A19="","",MAX(0,(D18 + (C19-F19)*Inputs!$B$9 - Inputs!$B$30)/Inputs!$B$9)) | H19: =IF(A19="","",MAX(0,MIN(Inputs!$B$44,H18+(S19-M19-I19)*Inputs!$B$9))) | I19: =IF(A19="","",MAX(0,(H18+(S19-M19)*Inputs!$B$9-Inputs!$B$44)/Inputs!$B$9)) | J19: =IF(A19="","",Inputs!$B$40 + H19/Inputs!$B$42) | K19: =IF(A19="","",IF(J18>=Inputs!$B$47,2, IF(J18>=Inputs!$B$45,1, IF(J18<=Inputs!$B$46,0,K18)))) | L19: =IF(A19="","",K19*Inputs!$B$49) | M19: =IF(A19="","",MIN(L19,H18/Inputs!$B$9+S19)) | N19: =IF(A19="","",IF(AND(K19>0,K18=0),1,0)) | O19: =IF(A19="","",O18+N19) | P19: =IF(A19="","",MIN(F19,Inputs!$B$50)) | Q19: =IF(A19="","",MAX(0,F19-P19)) | R19: =IF(A19="","",P19*Inputs!$B$51) | S19: =IF(A19="","",Q19+R19)
A20: =IF(ROW()<=Inputs!$B$53+2,A19+Inputs!$B$8,"") | B20: =IF(A20="","",IFERROR(INDEX(IDF_Hyetograph!$J$2:$J$37,MATCH(A20,IDF_Hyetograph!$K$2:$K$37,0)),0)) | C20: =IF(A20="","",0.00278*Inputs!$B$4*Inputs!$B$3*B20) | D20: =IF(A20="","",MIN( Inputs!$B$30, MAX(0, D19 + (C20-F20-G20)*Inputs!$B$9) )) | E20: =IF(A20="","",Inputs!$B$31 + D20/Inputs!$B$33) | F20: =IF(A20="","",MIN( D19/Inputs!$B$9, Inputs!$B$35*Inputs!$B$36*SQRT(2*Inputs!$B$37*MAX(E19-J19,0)) )) | G20: =IF(A20="","",MAX(0,(D19 + (C20-F20)*Inputs!$B$9 - Inputs!$B$30)/Inputs!$B$9)) | H20: =IF(A20="","",MAX(0,MIN(Inputs!$B$44,H19+(S20-M20-I20)*Inputs!$B$9))) | I20: =IF(A20="","",MAX(0,(H19+(S20-M20)*Inputs!$B$9-Inputs!$B$44)/Inputs!$B$9)) | J20: =IF(A20="","",Inputs!$B$40 + H20/Inputs!$B$42) | K20: =IF(A20="","",IF(J19>=Inputs!$B$47,2, IF(J19>=Inputs!$B$45,1, IF(J19<=Inputs!$B$46,0,K19)))) | L20: =IF(A20="","",K20*Inputs!$B$49) | M20: =IF(A20="","",MIN(L20,H19/Inputs!$B$9+S20)) | N20: =IF(A20="","",IF(AND(K20>0,K19=0),1,0)) | O20: =IF(A20="","",O19+N20) | P20: =IF(A20="","",MIN(F20,Inputs!$B$50)) | Q20: =IF(A20="","",MAX(0,F20-P20)) | R20: =IF(A20="","",P20*Inputs!$B$51) | S20: =IF(A20="","",Q20+R20)
A21: =IF(ROW()<=Inputs!$B$53+2,A20+Inputs!$B$8,"") | B21: =IF(A21="","",IFERROR(INDEX(IDF_Hyetograph!$J$2:$J$37,MATCH(A21,IDF_Hyetograph!$K$2:$K$37,0)),0)) | C21: =IF(A21="","",0.00278*Inputs!$B$4*Inputs!$B$3*B21) | D21: =IF(A21="","",MIN( Inputs!$B$30, MAX(0, D20 + (C21-F21-G21)*Inputs!$B$9) )) | E21: =IF(A21="","",Inputs!$B$31 + D21/Inputs!$B$33) | F21: =IF(A21="","",MIN( D20/Inputs!$B$9, Inputs!$B$35*Inputs!$B$36*SQRT(2*Inputs!$B$37*MAX(E20-J20,0)) )) | G21: =IF(A21="","",MAX(0,(D20 + (C21-F21)*Inputs!$B$9 - Inputs!$B$30)/Inputs!$B$9)) | H21: =IF(A21="","",MAX(0,MIN(Inputs!$B$44,H20+(S21-M21-I21)*Inputs!$B$9))) | I21: =IF(A21="","",MAX(0,(H20+(S21-M21)*Inputs!$B$9-Inputs!$B$44)/Inputs!$B$9)) | J21: =IF(A21="","",Inputs!$B$40 + H21/Inputs!$B$42) | K21: =IF(A21="","",IF(J20>=Inputs!$B$47,2, IF(J20>=Inputs!$B$45,1, IF(J20<=Inputs!$B$46,0,K20)))) | L21: =IF(A21="","",K21*Inputs!$B$49) | M21: =IF(A21="","",MIN(L21,H20/Inputs!$B$9+S21)) | N21: =IF(A21="","",IF(AND(K21>0,K20=0),1,0)) | O21: =IF(A21="","",O20+N21) | P21: =IF(A21="","",MIN(F21,Inputs!$B$50)) | Q21: =IF(A21="","",MAX(0,F21-P21)) | R21: =IF(A21="","",P21*Inputs!$B$51) | S21: =IF(A21="","",Q21+R21)
A22: =IF(ROW()<=Inputs!$B$53+2,A21+Inputs!$B$8,"") | B22: =IF(A22="","",IFERROR(INDEX(IDF_Hyetograph!$J$2:$J$37,MATCH(A22,IDF_Hyetograph!$K$2:$K$37,0)),0)) | C22: =IF(A22="","",0.00278*Inputs!$B$4*Inputs!$B$3*B22) | D22: =IF(A22="","",MIN( Inputs!$B$30, MAX(0, D21 + (C22-F22-G22)*Inputs!$B$9) )) | E22: =IF(A22="","",Inputs!$B$31 + D22/Inputs!$B$33) | F22: =IF(A22="","",MIN( D21/Inputs!$B$9, Inputs!$B$35*Inputs!$B$36*SQRT(2*Inputs!$B$37*MAX(E21-J21,0)) )) | G22: =IF(A22="","",MAX(0,(D21 + (C22-F22)*Inputs!$B$9 - Inputs!$B$30)/Inputs!$B$9)) | H22: =IF(A22="","",MAX(0,MIN(Inputs!$B$44,H21+(S22-M22-I22)*Inputs!$B$9))) | I22: =IF(A22="","",MAX(0,(H21+(S22-M22)*Inputs!$B$9-Inputs!$B$44)/Inputs!$B$9)) | J22: =IF(A22="","",Inputs!$B$40 + H22/Inputs!$B$42) | K22: =IF(A22="","",IF(J21>=Inputs!$B$47,2, IF(J21>=Inputs!$B$45,1, IF(J21<=Inputs!$B$46,0,K21)))) | L22: =IF(A22="","",K22*Inputs!$B$49) | M22: =IF(A22="","",MIN(L22,H21/Inputs!$B$9+S22)) | N22: =IF(A22="","",IF(AND(K22>0,K21=0),1,0)) | O22: =IF(A22="","",O21+N22) | P22: =IF(A22="","",MIN(F22,Inputs!$B$50)) | Q22: =IF(A22="","",MAX(0,F22-P22)) | R22: =IF(A22="","",P22*Inputs!$B$51) | S22: =IF(A22="","",Q22+R22)
A23: =IF(ROW()<=Inputs!$B$53+2,A22+Inputs!$B$8,"") | B23: =IF(A23="","",IFERROR(INDEX(IDF_Hyetograph!$J$2:$J$37,MATCH(A23,IDF_Hyetograph!$K$2:$K$37,0)),0)) | C23: =IF(A23="","",0.00278*Inputs!$B$4*Inputs!$B$3*B23) | D23: =IF(A23="","",MIN( Inputs!$B$30, MAX(0, D22 + (C23-F23-G23)*Inputs!$B$9) )) | E23: =IF(A23="","",Inputs!$B$31 + D23/Inputs!$B$33) | F23: =IF(A23="","",MIN( D22/Inputs!$B$9, Inputs!$B$35*Inputs!$B$36*SQRT(2*Inputs!$B$37*MAX(E22-J22,0)) )) | G23: =IF(A23="","",MAX(0,(D22 + (C23-F23)*Inputs!$B$9 - Inputs!$B$30)/Inputs!$B$9)) | H23: =IF(A23="","",MAX(0,MIN(Inputs!$B$44,H22+(S23-M23-I23)*Inputs!$B$9))) | I23: =IF(A23="","",MAX(0,(H22+(S23-M23)*Inputs!$B$9-Inputs!$B$44)/Inputs!$B$9)) | J23: =IF(A23="","",Inputs!$B$40 + H23/Inputs!$B$42) | K23: =IF(A23="","",IF(J22>=Inputs!$B$47,2, IF(J22>=Inputs!$B$45,1, IF(J22<=Inputs!$B$46,0,K22)))) | L23: =IF(A23="","",K23*Inputs!$B$49) | M23: =IF(A23="","",MIN(L23,H22/Inputs!$B$9+S23)) | N23: =IF(A23="","",IF(AND(K23>0,K22=0),1,0)) | O23: =IF(A23="","",O22+N23) | P23: =IF(A23="","",MIN(F23,Inputs!$B$50)) | Q23: =IF(A23="","",MAX(0,F23-P23)) | R23: =IF(A23="","",P23*Inputs!$B$51) | S23: =IF(A23="","",Q23+R23)
A24: =IF(ROW()<=Inputs!$B$53+2,A23+Inputs!$B$8,"") | B24: =IF(A24="","",IFERROR(INDEX(IDF_Hyetograph!$J$2:$J$37,MATCH(A24,IDF_Hyetograph!$K$2:$K$37,0)),0)) | C24: =IF(A24="","",0.00278*Inputs!$B$4*Inputs!$B$3*B24) | D24: =IF(A24="","",MIN( Inputs!$B$30, MAX(0, D23 + (C24-F24-G24)*Inputs!$B$9) )) | E24: =IF(A24="","",Inputs!$B$31 + D24/Inputs!$B$33) | F24: =IF(A24="","",MIN( D23/Inputs!$B$9, Inputs!$B$35*Inputs!$B$36*SQRT(2*Inputs!$B$37*MAX(E23-J23,0)) )) | G24: =IF(A24="","",MAX(0,(D23 + (C24-F24)*Inputs!$B$9 - Inputs!$B$30)/Inputs!$B$9)) | H24: =IF(A24="","",MAX(0,MIN(Inputs!$B$44,H23+(S24-M24-I24)*Inputs!$B$9))) | I24: =IF(A24="","",MAX(0,(H23+(S24-M24)*Inputs!$B$9-Inputs!$B$44)/Inputs!$B$9)) | J24: =IF(A24="","",Inputs!$B$40 + H24/Inputs!$B$42) | K24: =IF(A24="","",IF(J23>=Inputs!$B$47,2, IF(J23>=Inputs!$B$45,1, IF(J23<=Inputs!$B$46,0,K23)))) | L24: =IF(A24="","",K24*Inputs!$B$49) | M24: =IF(A24="","",MIN(L24,H23/Inputs!$B$9+S24)) | N24: =IF(A24="","",IF(AND(K24>0,K23=0),1,0)) | O24: =IF(A24="","",O23+N24) | P24: =IF(A24="","",MIN(F24,Inputs!$B$50)) | Q24: =IF(A24="","",MAX(0,F24-P24)) | R24: =IF(A24="","",P24*Inputs!$B$51) | S24: =IF(A24="","",Q24+R24)
A25: =IF(ROW()<=Inputs!$B$53+2,A24+Inputs!$B$8,"") | B25: =IF(A25="","",IFERROR(INDEX(IDF_Hyetograph!$J$2:$J$37,MATCH(A25,IDF_Hyetograph!$K$2:$K$37,0)),0)) | C25: =IF(A25="","",0.00278*Inputs!$B$4*Inputs!$B$3*B25) | D25: =IF(A25="","",MIN( Inputs!$B$30, MAX(0, D24 + (C25-F25-G25)*Inputs!$B$9) )) | E25: =IF(A25="","",Inputs!$B$31 + D25/Inputs!$B$33) | F25: =IF(A25="","",MIN( D24/Inputs!$B$9, Inputs!$B$35*Inputs!$B$36*SQRT(2*Inputs!$B$37*MAX(E24-J24,0)) )) | G25: =IF(A25="","",MAX(0,(D24 + (C25-F25)*Inputs!$B$9 - Inputs!$B$30)/Inputs!$B$9)) | H25: =IF(A25="","",MAX(0,MIN(Inputs!$B$44,H24+(S25-M25-I25)*Inputs!$B$9))) | I25: =IF(A25="","",MAX(0,(H24+(S25-M25)*Inputs!$B$9-Inputs!$B$44)/Inputs!$B$9)) | J25: =IF(A25="","",Inputs!$B$40 + H25/Inputs!$B$42) | K25: =IF(A25="","",IF(J24>=Inputs!$B$47,2, IF(J24>=Inputs!$B$45,1, IF(J24<=Inputs!$B$46,0,K24)))) | L25: =IF(A25="","",K25*Inputs!$B$49) | M25: =IF(A25="","",MIN(L25,H24/Inputs!$B$9+S25)) | N25: =IF(A25="","",IF(AND(K25>0,K24=0),1,0)) | O25: =IF(A25="","",O24+N25) | P25: =IF(A25="","",MIN(F25,Inputs!$B$50)) | Q25: =IF(A25="","",MAX(0,F25-P25)) | R25: =IF(A25="","",P25*Inputs!$B$51) | S25: =IF(A25="","",Q25+R25)
... A200: =IF(ROW()<=Inputs!$B$53+2,A199+Inputs!$B$8,"") | B200: =IF(A200="","",IFERROR(INDEX(IDF_Hyetograph!$J$2:$J$37,MATCH(A200,IDF_Hyetograph!$K$2:$K$37,0)),0)) | C200: =IF(A200="","",0.00278*Inputs!$B$4*Inputs!$B$3*B200) | D200: =IF(A200="","",MIN( Inputs!$B$30, MAX(0, D199 + (C200-F200-G200)*Inputs!$B$9) )) | E200: =IF(A200="","",Inputs!$B$31 + D200/Inputs!$B$33) | F200: =IF(A200="","",MIN( D199/Inputs!$B$9, Inputs!$B$35*Inputs!$B$36*SQRT(2*Inputs!$B$37*MAX(E199-J199,0)) )) | G200: =IF(A200="","",MAX(0,(D199 + (C200-F200)*Inputs!$B$9 - Inputs!$B$30)/Inputs!$B$9)) | H200: =IF(A200="","",MAX(0,MIN(Inputs!$B$44,H199+(S200-M200-I200)*Inputs!$B$9))) | I200: =IF(A200="","",MAX(0,(H199+(S200-M200)*Inputs!$B$9-Inputs!$B$44)/Inputs!$B$9)) | J200: =IF(A200="","",Inputs!$B$40 + H200/Inputs!$B$42) | K200: =IF(A200="","",IF(J199>=Inputs!$B$47,2, IF(J199>=Inputs!$B$45,1, IF(J199<=Inputs!$B$46,0,K199)))) | L200: =IF(A200="","",K200*Inputs!$B$49) | M200: =IF(A200="","",MIN(L200,H199/Inputs!$B$9+S200)) | N200: =IF(A200="","",IF(AND(K200>0,K199=0),1,0)) | O200: =IF(A200="","",O199+N200) | P200: =IF(A200="","",MIN(F200,Inputs!$B$50)) | Q200: =IF(A200="","",MAX(0,F200-P200)) | R200: =IF(A200="","",P200*Inputs!$B$51) | S200: =IF(A200="","",Q200+R200)
B205: MassError_m3 | C205: =C206-G206-I206-M206-E206 | N205: Total_starts | O205: =INDEX(O:O,MIN(200,Inputs!$B$53+2))
C206: =SUM(C2:INDEX(C:C,MIN(200,Inputs!$B$53+2)))*Inputs!$B$9 | D206: =INDEX(D:D,MIN(200,Inputs!$B$53+2)) | E206: =D206+H206-D2-H2 | G206: =SUM(G2:INDEX(G:G,MIN(200,Inputs!$B$53+2)))*Inputs!$B$9 | H206: =INDEX(H:H,MIN(200,Inputs!$B$53+2)) | I206: =SUM(I2:INDEX(I:I,MIN(200,Inputs!$B$53+2)))*Inputs!$B$9 | M206: =SUM(M2:INDEX(M:M,MIN(200,Inputs!$B$53+2)))*Inputs!$B$9 | N206: Event_hours | O206: =Inputs!$B$52/60
N207: Starts_per_hr | O207: =IF(O206=0,"",O205/O206)

Sheet Pump_Sizing
A1: POSTE DE POMPAGE – POINT DE FONCTIONNEMENT ET PUISSANCE (PRÉLIMINAIRE – PLUIE DE RÉCURRENCE 100 ANS)
A2: Base : Ruissellement toiture -> StormBrixx -> Puisard -> Rejet pompé au ruisseau
A3: Débit de conception vers le puisard, Q_design (m³/s) | B3: =MAX(Routing!F2:F200)
A4: Débit de pointe toiture, Q_peak (m³/s) | B4: =MAX(Routing!C2:C200)
A5: Niveau d’eau de conception du ruisseau (m) | B5: =Inputs!$B$12
A6: Niveau d’exploitation du puisard (m) | B6: =AVERAGE(Inputs!B19,Inputs!B20) | E6: Point de fonctionnement de conception
A7: Longueur de la conduite de refoulement (m) | B7: =Inputs!$B$15 | E7: Débit total requis | F7: =B16 | G7: (m³/s)
A8: Diamètre intérieur de la conduite de refoulement (m) | B8: 0.15 | E8: Débit par pompe en service | F8: =B17 | G8: (m³/s)
A9: Coefficient C de Hazen-Williams (-) | B9: 120 | E9: HMT (hauteur manométrique totale) | F9: =B23 | G9: m
A10: Coefficient de pertes singulières, K_total (-) | B10: =Inputs!B18
A11: Rendement pompe, η_pompe (-) | B11: 0.72 | E11: Critères de sélection des pompes
A12: Rendement moteur, η_moteur (-) | B12: 0.92 | E12: 1 en service + 1 en secours | F12: Oui
A13: Nombre de pompes en service (-) | B13: 1 | E13: Point nominal minimal | F13: ="≥ "&TEXT(B17,"0.000")&" m³/s @ "&TEXT(B23,"0.00")&" m TDH"
A14: Facteur de sécurité (-) | B14: 1.1 | E14: Puissance moteur retenue | F14: 2.1 kW per pump)
A16: Débit total requis de pompage (m³/s) | B16: =B3*B14 | E16: Vérification
A17: Débit requis par pompe en service (m³/s) | B17: =IF(B13=0,"",B16/B13) | E17: Démarrages/heure | F17: =B31
A18: COMPOSANTES DE CHARGE | E18: Temps de vidange | F18: =B30
A19: Charge statique (m) | B19: =MAX(0,B5-B6) | E19: Vérification niveaux MARCHE/ARRÊT | F19: =B37 | G19: =Inputs!B19
A20: Vitesse dans la conduite de refoulement (m/s) | B20: =IF(B16<=0,0,4*B16/(PI()*B8^2)) | E20: Note : le modèle final de pompe doit être confirmé par la courbe du fabricant
A21: Perte de charge linéaire (m) | B21: =IF(B16<=0,0,10.67*B7*B16^1.852/(B9^1.852*B8^4.87))
A22: Pertes singulières (m) | B22: =B10*B20^2/(2*9.81)
A23: Hauteur Manométrique Totale, HMT (m) | B23: =B19+B21+B22
A24: BESOINS EN PUISSANCE
A25: Puissance hydraulique (kW) | B25: =1000*9.81*B16*B23/1000
A26: Puissance absorbée aux bornes moteur (kW) | B26: =IF(B11*B12=0,"",B25/(B11*B12))
A27: Puissance absorbée par pompe en service (kW) | B27: =IF(B13=0,"",B26/B13)
A29: Volume utile du puisard entre MARCHE/ARRÊT (m³) | B29: =IF(Inputs!$B$19<=Inputs!$B$20,"",Inputs!$B$42*(Inputs!$B$19-Inputs!$B$20))
A30: Temps estimé de vidange (min) | B30: =IF(OR(B17<=0,B29<=0),"",B29/B17/60)
A31: Nombre total de démarrages pendant l’événement (-) | B31: =Routing!$O$205
A32: Durée de l’événement (h) | B32: =Routing!$O$206
A33: Démarrages moyens par heure (1/h) | B33: =IF(B32=0,"",B31/B32)
A34: Vérification des démarrages/heure | B34: =IF(B33="","INFO",IF(B33>10,"Too many starts","OK"))
A37: Warning on pump levels | B37: =IF(Inputs!$B$19<=Inputs!$B$20,"ERROR: ON level must be > OFF level","OK")

Sheet Quick checks
B2: V_block_eff = 0.8 * 0.8 * 0.66 * 0.9 = 0.38016 m3/block
B3: Blocks needed for 130 m3
B4: N_blocks_130 = 130 / 0.38016 = 341.96 -> 342 blocks
B5: 2) Why 95 mm is causing too much upstream storage
B6: Your peak roof inflow (from your routing) is around 0.389 m3/s (389 L/s).
B7: A 95 mm orifice typically passes only a small fraction of that (depending on head).
B8: So StormBrixx accumulates too much water, hence ~301 m3 required.
B9: 3) Pump duty point target (preliminary)
B10: H_static = 1.282 m
B11: at Q = 0.04 m3/s, you had hf + hm = 0.310 + 0.715 = 1.025 m
B12: So system curve coefficient:
B13: k_sys = (hf+hm)/Q^2 = 1.025 / (0.04^2) = 640.6
... B18: So your pump station should target roughly:
B19: Q_total | C19: ≈ | D19: 0.07 | E19: to | F19: 0.08 | G19: m3/s
B20: TDH | C20: ≈ | D20: 4.5 | E20: to | F20: 5.5 | G20: m
B21: 4) Temporary pump curve to use now (since no vendor curve yet)
B22: Use one-pump placeholder curve:
B23: H_pump_single(Q) = 7.5 - 2040*Q^2
B24: (Q in m3/s, H in m)
B25: This gives approx:
B26: shutoff head ~7.5 m
B27: ~5 m at Q ~0.035 m3/s (35 L/s)
B28: Intersection with your system curve gives about:
B29: Q_total ≈ 0.0735 m3/sH ≈ 4.74 m
B30: 5) Important design conclusion
B31: If transfer from StormBrixx to wetwell is still through 95 mm Q-brake, the pumps may be starved and upstream storage will remain too high.
B32: You likely need to increase transfer/orifice size (first-pass likely around 150–180 mm depending head), then rerun routing.
... B39: Any max discharge constraint to creek

Sheet Pertes_singulieres_detail
A1: DETAIL DES PERTES SINGULIERES ET LINEAIRES - JUSTIFICATION HYDRAULIQUE
A3: Configuration consideree: StormBrixx -> regard RP-01 (regulateur) -> split vers poste direct et vers DP-01, puis retour DP-01 au poste.
A4: IMPORTANT: Les K du regulateur et du separateur dynamique sont provisoires. Remplacer par les pertes constructeur pour le dimensionnement final.
A6: nu_eau_m2_s | B6: 1e-06
A7: g_m_s2 | B7: 9.81
A9: ID_segment | B9: Troncon | C9: L_m | D9: D_m | E9: Q_m3_s | F9: Aire_m2 | G9: v_m_s | H9: epsilon_m | I9: f_Darcy | J9: hf_m | K9: K_total | L9: hm_m | M9: h_total_m | N9: Commentaire | P9: SYNTHESE PAR BRANCHE
A10: S1 | B10: StormBrixx vers regard RP-01 regulateur | C10: 2 | D10: 0.3 | E10: =MAX(Routing!$F$2:$F$2000) | F10: =IF(D10>0,PI()*(D10^2)/4,0) | G10: =IF(F10>0,E10/F10,0) | H10: 1.5e-06 | I10: =IF(AND(G10>0,D10>0),0.25/(LOG10((H10/(3.7*D10))+5.74/((G10*D10/$B$6)^0.9))^2),0) | J10: =IF(D10>0,I10*(C10/D10)*(G10^2/(2*$B$7)),0) | K10: =SUMIFS($E$21:$E$40,$A$21:$A$40,A10) | L10: =K10*(G10^2/(2*$B$7)) | M10: =J10+L10 | N10: Troncon commun amont | P10: Branche / scenario | Q10: Perte totale (m)
A11: S2 | B11: RP-01 vers poste de pompage (branche directe) | C11: 7 | D11: 0.3 | E11: =MAX(Routing!$Q$2:$Q$2000) | F11: =IF(D11>0,PI()*(D11^2)/4,0) | G11: =IF(F11>0,E11/F11,0) | H11: 1.5e-06 | I11: =IF(AND(G11>0,D11>0),0.25/(LOG10((H11/(3.7*D11))+5.74/((G11*D11/$B$6)^0.9))^2),0) | J11: =IF(D11>0,I11*(C11/D11)*(G11^2/(2*$B$7)),0) | K11: =SUMIFS($E$21:$E$40,$A$21:$A$40,A11) | L11: =K11*(G11^2/(2*$B$7)) | M11: =J11+L11 | N11: Branche directe vers poste | P11: Chemin direct vers poste (S1+S2) | Q11: =M10+M11
A12: S3 | B12: RP-01 vers DP-01 separateur dynamique | C12: 4.5 | D12: 0.3 | E12: =MAX(Routing!$P$2:$P$2000) | F12: =IF(D12>0,PI()*(D12^2)/4,0) | G12: =IF(F12>0,E12/F12,0) | H12: 1.5e-06 | I12: =IF(AND(G12>0,D12>0),0.25/(LOG10((H12/(3.7*D12))+5.74/((G12*D12/$B$6)^0.9))^2),0) | J12: =IF(D12>0,I12*(C12/D12)*(G12^2/(2*$B$7)),0) | K12: =SUMIFS($E$21:$E$40,$A$21:$A$40,A12) | L12: =K12*(G12^2/(2*$B$7)) | M12: =J12+L12 | N12: Branche derivee vers separateur | P12: Chemin via separateur (S1+S3+S4) | Q12: =M10+M12+M13
A13: S4 | B13: DP-01 vers poste de pompage (retour) | C13: 4.5 | D13: 0.3 | E13: =MAX(Routing!$R$2:$R$2000) | F13: =IF(D13>0,PI()*(D13^2)/4,0) | G13: =IF(F13>0,E13/F13,0) | H13: 1.5e-06 | I13: =IF(AND(G13>0,D13>0),0.25/(LOG10((H13/(3.7*D13))+5.74/((G13*D13/$B$6)^0.9))^2),0) | J13: =IF(D13>0,I13*(C13/D13)*(G13^2/(2*$B$7)),0) | K13: =SUMIFS($E$21:$E$40,$A$21:$A$40,A13) | L13: =K13*(G13^2/(2*$B$7)) | M13: =J13+L13 | N13: Retour du separateur vers poste | P13: Troncon poste vers RP-02 (S5) | Q13: =M14
A14: S5 | B14: Poste de pompage vers RP-02 avec clapet | C14: 4 | D14: 0.3 | E14: =MAX(Routing!$M$2:$M$2000) | F14: =IF(D14>0,PI()*(D14^2)/4,0) | G14: =IF(F14>0,E14/F14,0) | H14: 1.5e-06 | I14: =IF(AND(G14>0,D14>0),0.25/(LOG10((H14/(3.7*D14))+5.74/((G14*D14/$B$6)^0.9))^2),0) | J14: =IF(D14>0,I14*(C14/D14)*(G14^2/(2*$B$7)),0) | K14: =SUMIFS($E$21:$E$40,$A$21:$A$40,A14) | L14: =K14*(G14^2/(2*$B$7)) | M14: =J14+L14 | N14: Aval poste vers RP-02 | P14: Troncon aval gravitaire (S6) | Q14: =M15
A15: S6 | B15: RP-02 vers exutoire gravitaire | C15: 14.5 | D15: 0.3 | E15: =E14 | F15: =IF(D15>0,PI()*(D15^2)/4,0) | G15: =IF(F15>0,E15/F15,0) | H15: 1.5e-06 | I15: =IF(AND(G15>0,D15>0),0.25/(LOG10((H15/(3.7*D15))+5.74/((G15*D15/$B$6)^0.9))^2),0) | J15: =IF(D15>0,I15*(C15/D15)*(G15^2/(2*$B$7)),0) | K15: =SUMIFS($E$21:$E$40,$A$21:$A$40,A15) | L15: =K15*(G15^2/(2*$B$7)) | M15: =J15+L15 | N15: Troncon final a gravite
P17: NOTE | Q17: Valider K regulateur, K separateur et K clapet RP-02 sur fiches fabricants.
A18: DETAIL DES ACCESSOIRES ET K SUGGERES (A AJUSTER SELON FICHE FABRICANT)
A20: ID_segment | B20: Appareil / singularite | C20: Quantite | D20: K_unitaire | E20: K_ligne
A21: S1 | B21: Entree depuis StormBrixx | C21: 1 | D21: 0.5 | E21: =C21*D21
A22: S1 | B22: Regard RP-01 (passage) | C22: 1 | D22: 0.5 | E22: =C22*D22
A23: S1 | B23: Regulateur RP-01 (provisoire) | C23: 1 | D23: 2.5 | E23: =C23*D23
A24: S2 | B24: Te passage droit (vers branche directe) | C24: 1 | D24: 0.6 | E24: =C24*D24
A25: S2 | B25: Coude de raccordement vers poste | C25: 1 | D25: 0.4 | E25: =C25*D25
A26: S3 | B26: Te derivation vers DP-01 | C26: 1 | D26: 1.8 | E26: =C26*D26
A27: S3 | B27: Entree separateur dynamique | C27: 1 | D27: 0.5 | E27: =C27*D27
A28: S4 | B28: Sortie separateur dynamique (provisoire) | C28: 1 | D28: 1.5 | E28: =C28*D28
A29: S4 | B29: Raccord retour vers poste | C29: 1 | D29: 0.4 | E29: =C29*D29
A30: S5 | B30: Clapet anti-retour RP-02 | C30: 1 | D30: 2.5 | E30: =C30*D30
A31: S5 | B31: Coude 90 | C31: 1 | D31: 0.9 | E31: =C31*D31
A32: S6 | B32: Sortie libre a l'exutoire | C32: 1 | D32: 1 | E32: =C32*D32

Sheet Analyse_duree
A1: ANALYSE AUTOMATIQUE DES DURÉES D'HYÉTOGRAPHE
A2: Durée gouvernante (min) | B2: =INDEX(A5:A8,MATCH(MAX(D5:D8),D5:D8,0)) | C2: (basée sur volume de ruissellement total)
A4: Durée_test_min | B4: Intensité_moy_mmh | C4: Lame_totale_mm | D4: Volume_ruissellement_m3 | E4: Débit_pic_proxy_m3s | F4: Rang_volume | G4: Cas_gouvernant | H4: Commentaire
A5: 30 | B5: =Inputs!$B$5/((A5+Inputs!$B$6)^Inputs!$B$7) | C5: =B5*A5/60 | D5: =C5/1000*Inputs!$B$2*Inputs!$B$4 | E5: =0.00278*Inputs!$B$3*Inputs!$B$4*B5 | F5: =RANK(D5,$D$5:$D$8,0) | G5: =IF(D5=MAX($D$5:$D$8),"GOVERNING","") | H5: =IF(G5="GOVERNING","Utiliser cette durée pour Routing","")
A6: 60 | B6: =Inputs!$B$5/((A6+Inputs!$B$6)^Inputs!$B$7) | C6: =B6*A6/60 | D6: =C6/1000*Inputs!$B$2*Inputs!$B$4 | E6: =0.00278*Inputs!$B$3*Inputs!$B$4*B6 | F6: =RANK(D6,$D$5:$D$8,0) | G6: =IF(D6=MAX($D$5:$D$8),"GOVERNING","") | H6: =IF(G6="GOVERNING","Utiliser cette durée pour Routing","")
A7: 120 | B7: =Inputs!$B$5/((A7+Inputs!$B$6)^Inputs!$B$7) | C7: =B7*A7/60 | D7: =C7/1000*Inputs!$B$2*Inputs!$B$4 | E7: =0.00278*Inputs!$B$3*Inputs!$B$4*B7 | F7: =RANK(D7,$D$5:$D$8,0) | G7: =IF(D7=MAX($D$5:$D$8),"GOVERNING","") | H7: =IF(G7="GOVERNING","Utiliser cette durée pour Routing","")
A8: 180 | B8: =Inputs!$B$5/((A8+Inputs!$B$6)^Inputs!$B$7) | C8: =B8*A8/60 | D8: =C8/1000*Inputs!$B$2*Inputs!$B$4 | E8: =0.00278*Inputs!$B$3*Inputs!$B$4*B8 | F8: =RANK(D8,$D$5:$D$8,0) | G8: =IF(D8=MAX($D$5:$D$8),"GOVERNING","") | H8: =IF(G8="GOVERNING","Utiliser cette durée pour Routing","")
A10: Durée utilisée par le modèle (Inputs!B52) | B10: =Inputs!$B$52
A11: Écart (durée modèle - durée gouvernante) | B11: =B10-B2
A13: Critère retenu: max volume de ruissellement (pré-sélection). Vérifier ensuite WL max, surverses et starts/h dans Routing/Pump_Sizing.

Sheet Aval_manhole_sync
A1: ROUTAGE DU REGARD AVAL (APRES POSTE DE POMPAGE)
A2: Calcul explicite: V_fin = MAX(0, V_debut + (Q_in - Q_out)*dt). Q_in provient de Routing!M. Q_out est lu/interpole depuis la courbe niveau-debit.
A4: PARAMETRES | F4: RESULTATS | J4: COURBE Qout UTILISATEUR
A5: Invert_regard_aval_m | B5: 103.03 | C5: m | D5: Fond du regard aval | F5: Vmax_calcule_m3 | G5: =IF(B11<=0,"",MAX(H16:INDEX(H:H,15+B11))) | J5: Niveau_eau_m | K5: Qout_gravite_m3s
A6: Diametre_regard_aval_m | B6: 1.5 | C6: m | D6: Diametre interieur utile | F6: Vreq_avec_FS_m3 | G6: =IF(G5="","",G5*B9) | J6: =B5 | K6: 0
A7: Aire_regard_aval_m2 | B7: =PI()*B6^2/4 | C7: m2 | D7: Aire de stockage verticale | F7: Hauteur_req_m | G7: =IF(OR(G6="",B7=0),"",G6/B7) | J7: =B5+0.10 | K7: 0.005
A8: Volume_initial_m3 | B8: 0 | C8: m3 | D8: Condition initiale au debut de l evenement | F8: Niveau_eau_max_requis_m | G8: =IF(G7="","",B5+G7) | J8: =B5+0.20 | K8: 0.012
A9: Facteur_securite_stockage | B9: 1.15 | C9: - | D9: Applique sur Vmax | F9: Verification_niveau | G9: =IF(OR(G8="",B12=""),"INFO",IF(G8<=B12,"PASS","FAIL")) | J9: =B5+0.30 | K9: 0.022
A10: Pas_temps_sec | B10: =Inputs!$B$9 | C10: s | D10: Pas du routage (doit suivre Inputs) | F10: Marge_niveau_m | G10: =IF(OR(G8="",B12=""),"",B12-G8) | J10: =B5+0.40 | K10: 0.035
A11: Nb_pas_evenement | B11: =Inputs!$B$53 | C11: - | D11: Nombre de pas actifs depuis Inputs | J11: =B5+0.50 | K11: 0.05
A12: Niveau_max_admissible_m | B12: =B5+1.00 | C12: m | D12: Ajuster selon geometre/rim/freeboard | J12: Note: Niveaux J6:J11 doivent etre croissants.
A15: Pas | B15: Temps_min | C15: Qin_pompe_m3s | D15: V_debut_m3 | E15: Niveau_debut_m | F15: Qout_m3s_interp | G15: DeltaV_m3 | H15: V_fin_m3 | I15: Niveau_fin_m
A16: =IF(B11<=0,"",1) | B16: =IF(ROW()-15<=$B$11,INDEX(Routing!$A:$A,ROW()-14),"") | C16: =IF(B16="","",INDEX(Routing!$M:$M,ROW()-14)) | D16: =IF(B16="","",$B$8) | E16: =IF(B16="","",$B$5+IF($B$7=0,0,D16/$B$7)) | F16: =IF(B16="","",IF(E16<=J6,K6,IF(E16>=J11,K11,INDEX(K6:K11,MATCH(E16,J6:J11,1))+(E16-INDEX(J6:J11,MATCH(E16,J6:J11,1)))*(INDEX(K6:K11,MATCH(E16,J6:J11,1)+1)-INDEX(K6:K11,MATCH(E16,J6:J11,1)))/(INDEX(J6:J11,MATCH(E16,J6:J11,1)+1)-INDEX(J6:J11,MATCH(E16,J6:J11,1)))))) | G16: =IF(B16="","",(C16-F16)*$B$10) | H16: =IF(B16="","",MAX(0,D16+G16)) | I16: =IF(B16="","",$B$5+IF($B$7=0,0,H16/$B$7))
A17: =IF(B17="","",A16+1) | B17: =IF(ROW()-15<=$B$11,INDEX(Routing!$A:$A,ROW()-14),"") | C17: =IF(B17="","",INDEX(Routing!$M:$M,ROW()-14)) | D17: =IF(B17="","",H16) | E17: =IF(B17="","",$B$5+IF($B$7=0,0,D17/$B$7)) | F17: =IF(B17="","",IF(E17<=J6,K6,IF(E17>=J11,K11,INDEX(K6:K11,MATCH(E17,J6:J11,1))+(E17-INDEX(J6:J11,MATCH(E17,J6:J11,1)))*(INDEX(K6:K11,MATCH(E17,J6:J11,1)+1)-INDEX(K6:K11,MATCH(E17,J6:J11,1)))/(INDEX(J6:J11,MATCH(E17,J6:J11,1)+1)-INDEX(J6:J11,MATCH(E17,J6:J11,1)))))) | G17: =IF(B17="","",(C17-F17)*$B$10) | H17: =IF(B17="","",MAX(0,D17+G17)) | I17: =IF(B17="","",$B$5+IF($B$7=0,0,H17/$B$7))
A18: =IF(B18="","",A17+1) | B18: =IF(ROW()-15<=$B$11,INDEX(Routing!$A:$A,ROW()-14),"") | C18: =IF(B18="","",INDEX(Routing!$M:$M,ROW()-14)) | D18: =IF(B18="","",H17) | E18: =IF(B18="","",$B$5+IF($B$7=0,0,D18/$B$7)) | F18: =IF(B18="","",IF(E18<=J6,K6,IF(E18>=J11,K11,INDEX(K6:K11,MATCH(E18,J6:J11,1))+(E18-INDEX(J6:J11,MATCH(E18,J6:J11,1)))*(INDEX(K6:K11,MATCH(E18,J6:J11,1)+1)-INDEX(K6:K11,MATCH(E18,J6:J11,1)))/(INDEX(J6:J11,MATCH(E18,J6:J11,1)+1)-INDEX(J6:J11,MATCH(E18,J6:J11,1)))))) | G18: =IF(B18="","",(C18-F18)*$B$10) | H18: =IF(B18="","",MAX(0,D18+G18)) | I18: =IF(B18="","",$B$5+IF($B$7=0,0,H18/$B$7))
A19: =IF(B19="","",A18+1) | B19: =IF(ROW()-15<=$B$11,INDEX(Routing!$A:$A,ROW()-14),"") | C19: =IF(B19="","",INDEX(Routing!$M:$M,ROW()-14)) | D19: =IF(B19="","",H18) | E19: =IF(B19="","",$B$5+IF($B$7=0,0,D19/$B$7)) | F19: =IF(B19="","",IF(E19<=J6,K6,IF(E19>=J11,K11,INDEX(K6:K11,MATCH(E19,J6:J11,1))+(E19-INDEX(J6:J11,MATCH(E19,J6:J11,1)))*(INDEX(K6:K11,MATCH(E19,J6:J11,1)+1)-INDEX(K6:K11,MATCH(E19,J6:J11,1)))/(INDEX(J6:J11,MATCH(E19,J6:J11,1)+1)-INDEX(J6:J11,MATCH(E19,J6:J11,1)))))) | G19: =IF(B19="","",(C19-F19)*$B$10) | H19: =IF(B19="","",MAX(0,D19+G19)) | I19: =IF(B19="","",$B$5+IF($B$7=0,0,H19/$B$7))
A20: =IF(B20="","",A19+1) | B20: =IF(ROW()-15<=$B$11,INDEX(Routing!$A:$A,ROW()-14),"") | C20: =IF(B20="","",INDEX(Routing!$M:$M,ROW()-14)) | D20: =IF(B20="","",H19) | E20: =IF(B20="","",$B$5+IF($B$7=0,0,D20/$B$7)) | F20: =IF(B20="","",IF(E20<=J6,K6,IF(E20>=J11,K11,INDEX(K6:K11,MATCH(E20,J6:J11,1))+(E20-INDEX(J6:J11,MATCH(E20,J6:J11,1)))*(INDEX(K6:K11,MATCH(E20,J6:J11,1)+1)-INDEX(K6:K11,MATCH(E20,J6:J11,1)))/(INDEX(J6:J11,MATCH(E20,J6:J11,1)+1)-INDEX(J6:J11,MATCH(E20,J6:J11,1)))))) | G20: =IF(B20="","",(C20-F20)*$B$10) | H20: =IF(B20="","",MAX(0,D20+G20)) | I20: =IF(B20="","",$B$5+IF($B$7=0,0,H20/$B$7))
A21: =IF(B21="","",A20+1) | B21: =IF(ROW()-15<=$B$11,INDEX(Routing!$A:$A,ROW()-14),"") | C21: =IF(B21="","",INDEX(Routing!$M:$M,ROW()-14)) | D21: =IF(B21="","",H20) | E21: =IF(B21="","",$B$5+IF($B$7=0,0,D21/$B$7)) | F21: =IF(B21="","",IF(E21<=J6,K6,IF(E21>=J11,K11,INDEX(K6:K11,MATCH(E21,J6:J11,1))+(E21-INDEX(J6:J11,MATCH(E21,J6:J11,1)))*(INDEX(K6:K11,MATCH(E21,J6:J11,1)+1)-INDEX(K6:K11,MATCH(E21,J6:J11,1)))/(INDEX(J6:J11,MATCH(E21,J6:J11,1)+1)-INDEX(J6:J11,MATCH(E21,J6:J11,1)))))) | G21: =IF(B21="","",(C21-F21)*$B$10) | H21: =IF(B21="","",MAX(0,D21+G21)) | I21: =IF(B21="","",$B$5+IF($B$7=0,0,H21/$B$7))
A22: =IF(B22="","",A21+1) | B22: =IF(ROW()-15<=$B$11,INDEX(Routing!$A:$A,ROW()-14),"") | C22: =IF(B22="","",INDEX(Routing!$M:$M,ROW()-14)) | D22: =IF(B22="","",H21) | E22: =IF(B22="","",$B$5+IF($B$7=0,0,D22/$B$7)) | F22: =IF(B22="","",IF(E22<=J6,K6,IF(E22>=J11,K11,INDEX(K6:K11,MATCH(E22,J6:J11,1))+(E22-INDEX(J6:J11,MATCH(E22,J6:J11,1)))*(INDEX(K6:K11,MATCH(E22,J6:J11,1)+1)-INDEX(K6:K11,MATCH(E22,J6:J11,1)))/(INDEX(J6:J11,MATCH(E22,J6:J11,1)+1)-INDEX(J6:J11,MATCH(E22,J6:J11,1)))))) | G22: =IF(B22="","",(C22-F22)*$B$10) | H22: =IF(B22="","",MAX(0,D22+G22)) | I22: =IF(B22="","",$B$5+IF($B$7=0,0,H22/$B$7))
A23: =IF(B23="","",A22+1) | B23: =IF(ROW()-15<=$B$11,INDEX(Routing!$A:$A,ROW()-14),"") | C23: =IF(B23="","",INDEX(Routing!$M:$M,ROW()-14)) | D23: =IF(B23="","",H22) | E23: =IF(B23="","",$B$5+IF($B$7=0,0,D23/$B$7)) | F23: =IF(B23="","",IF(E23<=J6,K6,IF(E23>=J11,K11,INDEX(K6:K11,MATCH(E23,J6:J11,1))+(E23-INDEX(J6:J11,MATCH(E23,J6:J11,1)))*(INDEX(K6:K11,MATCH(E23,J6:J11,1)+1)-INDEX(K6:K11,MATCH(E23,J6:J11,1)))/(INDEX(J6:J11,MATCH(E23,J6:J11,1)+1)-INDEX(J6:J11,MATCH(E23,J6:J11,1)))))) | G23: =IF(B23="","",(C23-F23)*$B$10) | H23: =IF(B23="","",MAX(0,D23+G23)) | I23: =IF(B23="","",$B$5+IF($B$7=0,0,H23/$B$7))
A24: =IF(B24="","",A23+1) | B24: =IF(ROW()-15<=$B$11,INDEX(Routing!$A:$A,ROW()-14),"") | C24: =IF(B24="","",INDEX(Routing!$M:$M,ROW()-14)) | D24: =IF(B24="","",H23) | E24: =IF(B24="","",$B$5+IF($B$7=0,0,D24/$B$7)) | F24: =IF(B24="","",IF(E24<=J6,K6,IF(E24>=J11,K11,INDEX(K6:K11,MATCH(E24,J6:J11,1))+(E24-INDEX(J6:J11,MATCH(E24,J6:J11,1)))*(INDEX(K6:K11,MATCH(E24,J6:J11,1)+1)-INDEX(K6:K11,MATCH(E24,J6:J11,1)))/(INDEX(J6:J11,MATCH(E24,J6:J11,1)+1)-INDEX(J6:J11,MATCH(E24,J6:J11,1)))))) | G24: =IF(B24="","",(C24-F24)*$B$10) | H24: =IF(B24="","",MAX(0,D24+G24)) | I24: =IF(B24="","",$B$5+IF($B$7=0,0,H24/$B$7))
