Workbook

Sheet Guide
A1: BASEBALL FIELD - HYDROLOGY BEFORE/AFTER (RATIONAL METHOD)
A3: Purpose: compare runoff at east discharge (culvert/ponceau) before vs after renovation.
A4: Interpretation rule used: yellow textbox elevations = proposed; plain text elevations = existing.
A5: Known from user: total paved area shown in gray is 1869.7 m2; use inclusion factor in Inputs!B20 if only part contributes to baseball drainage.
A6: For this baseball-field model, drainage paths are represented as field sheet/trench/collector to east culvert; no building-internal mechanical path assumed.
A7: Subcatchments sheet: enter/adjust tributary areas and surfaces for each contributing zone.
A8: FlowPaths: AFTER uses trench/perforated underdrain representation for field strip (TRENCH) + pipe collector to outlet.
A9: Tc for each subcatchment = Tc base + travel time on assigned path (sum of segment times).
A10: Outputs are summarized in Summary_Before_After sheet with impervious/grass totals and Q before/after.
A11: Important: because the PDF text extraction is limited, verify/complete all tributary limits and areas from plan manually.
A13: Data quality note
A14: Only one area is prefilled from your note (1869.7 m2 paved). Fill remaining tributary areas from plan labels in m2.
... A68: EAST-IN and EAST-OUT node naming aligned in FlowPaths/Segment_Legend for dimensioned east collector segments.

Sheet Inputs
A1: INPUTS
A2: Parameter | B2: Value | C2: Unit | D2: Note
A3: IDF_a | B3: 7423.67 | C3: - | D3: i = a/(tc+b)^c (only if Intensity_source=IDF_EQUATION)
A4: IDF_b | B4: 33.5 | C4: min | D4: IDF parameter b (only if Intensity_source=IDF_EQUATION)
A5: IDF_c | B5: 1.148 | C5: - | D5: IDF parameter c (only if Intensity_source=IDF_EQUATION)
A6: Flow_safety_factor | B6: 1.1 | C6: - | D6: Multiply local+upstream flow
A7: V_sheet_default_mps | B7: 0.3 | C7: m/s | D7: Sheet/overland flow adopted velocity
A8: V_swale_default_mps | B8: 1 | C8: m/s | D8: Swale/channel adopted velocity
A9: V_pipe_default_mps | B9: 1.5 | C9: m/s | D9: Pipe adopted velocity
A10: V_internal_default_mps | B10: 1.5 | C10: m/s | D10: INTERNAL velocity reserved; unused unless a dedicated internal path is intentionally reintroduced.
A11: Default_Tc_base_before_min | B11: 7 | C11: min | D11: Base Tc if not overridden (before)
A12: Default_Tc_base_after_min | B12: 7 | C12: min | D12: Base Tc if not overridden (after)
A13: C_roof | B13: 0.95 | C13: - | D13: Runoff coefficient roof
A14: C_pavage | B14: 0.85 | C14: - | D14: Runoff coefficient pavement/pave-uni
... A19: Paved_area_inclusion_factor_for_baseball | B19: 1 | C19: 0-1 | D19: Use <1 if only part of 1869.7 m2 drains to baseball design outlet
A20: Discharge_node_name | B20: East culvert / ponceau | C20: - | D20: Main discharge reference
A22: IDF_station_name | B22: SAINT-CONSTANT - McTavish station table | C22: - | D22: Project context: Saint-Constant. Station table currently from McTavish values provided by user.
A23: Intensity_source | B23: STATION_TABLE | C23: (STATION_TABLE/IDF_EQUATION) | D23: Default STATION_TABLE. Use IDF_EQUATION only if a,b,c are valid for same station.
A24: Return_period_column | B24: 100-Year | C24: text | D24: Must match one header in IDF_Station row 2.
A25: Q_allowable_user_m3s | C25: m3/s | D25: Enter allowable release at watercourse/culvert per authority or project criterion.
A26: Q_allowable_basis | B26: User/City criterion | C26: - | D26: Example: Q_after <= Q_before or municipal limit.
A27: V_trench_perforated_default_mps | B27: 0.9 | C27: m/s | D27: Adopted velocity for perforated underdrain in trench envelope (geotextile + stone).
A31: Mixed_block_target_subcatchments | B31: SC-07 + SC-08 | C31: - | D31: Outlet uncertain block for mixed-surface sensitivity.
A32: Mixed_block_total_area_m2 | B32: =SUM(Subcatchments!$C$9:$C$10) | C32: m2 | D32: Should match SC-04 area.
A33: Mixed_block_sensitivity_mode (LOW/BASE/HIGH) | B33: BASE | C33: text | D33: Controls impervious fraction used for SC-04.
A34: Mixed_block_impervious_fraction_LOW | B34: 0.35 | C34: 0-1 | D34: Low impervious assumption.
A35: Mixed_block_impervious_fraction_BASE | B35: 0.5 | C35: 0-1 | D35: Base impervious assumption.
A36: Mixed_block_impervious_fraction_HIGH | B36: 0.7 | C36: 0-1 | D36: High impervious assumption.
A37: Mixed_block_impervious_fraction_used | B37: =IF(UPPER(TRIM(B33))="LOW",B34,IF(UPPER(TRIM(B33))="HIGH",B36,B35)) | C37: 0-1 | D37: Selected by mode.
A38: Mixed_block_grass_fraction_used | B38: =1-B37 | C38: 0-1 | D38: Complementary fraction.
A39: Mixed_block_C_before_weighted | B39: =B37*B14+B38*B15 | C39: - | D39: Weighted C for BEFORE (pavage + grass existing).
A40: Mixed_block_C_after_weighted | B40: =B37*B14+B38*B16 | C40: - | D40: Weighted C for AFTER (pavage + grass proposed).
A41: Mixed_block_enable_override (YES/NO) | B41: YES | C41: text | D41: If YES, SC-04 uses weighted C overrides.
A43: Collector_trunk_slope_m_per_m | B43: 0.005 | C43: m/m | D43: From plan note: COLLECTEUR A VENIR (P=0.5%).
A44: Collector_trunk_delta_invert_to_lowpoint_m | B44: 0.983 | C44: m | D44: From plan note: radier = 0.983 m above collector low point.
A45: Collector_trunk_chainage_implied_by_note_m | B45: =IF(B43=0,"",B44/B43) | C45: m | D45: Implied chainage from note (delta/slope).
A46: Collector_trunk_east_length_m | B46: 66.398 | C46: m | D46: From latest image dimension (66.398 m) along east-side collector trajectory.
A47: Collector_trunk_bottom_length_m | B47: 34.509 | C47: m | D47: From latest image dimension (34.509 m) along center-to-south trajectory.
A48: Collector_trunk_west_length_m | B48: 67.025 | C48: m | D48: From latest image dimension (67.025 m) for west-side reach shown by dimension tool.
A49: Collector_trunk_total_explicit_length_m | B49: =SUM(B46:B48) | C49: m | D49: Total explicit chainage used in path travel times.
...

Sheet FlowPaths
A1: FLOW PATHS (BEFORE / AFTER)
A3: Scenario | B3: Path_ID | C3: Seq | D3: Segment_ID | E3: Segment_description | F3: Conveyance_type | G3: Length_m | H3: Slope_m/m | I3: Velocity_override_mps | J3: Velocity_used_mps | K3: Travel_time_min | L3: To_node | M3: Notes
A4: BEFORE | B4: P-EAST | C4: 1 | D4: B01 | E4: Field runoff to east edge | F4: SHEET | G4: 35 | H4: 0.01 | J4: =IF(I4<>"",I4,IF(UPPER(TRIM(F4))="SHEET",Inputs!$B$7,IF(UPPER(TRIM(F4))="SWALE",Inputs!$B$8,IF(UPPER(TRIM(F4))="TRENCH",Inputs!$B$27,IF(UPPER(TRIM(F4))="PIPE",Inputs!$B$9,Inputs!$B$10))))) | K4: =IF(OR(G4="",J4=""),"",G4/(J4*60)) | L4: EAST-OUT | M4: If old subdrain exists but deteriorated, keep SHEET velocity conservative or split into extra segment.
A5: BEFORE | B5: P-EAST | C5: 2 | D5: B02 | E5: Conveyance to east culvert | F5: SWALE | G5: 25 | H5: 0.005 | J5: =IF(I5<>"",I5,IF(UPPER(TRIM(F5))="SHEET",Inputs!$B$7,IF(UPPER(TRIM(F5))="SWALE",Inputs!$B$8,IF(UPPER(TRIM(F5))="TRENCH",Inputs!$B$27,IF(UPPER(TRIM(F5))="PIPE",Inputs!$B$9,Inputs!$B$10))))) | K5: =IF(OR(G5="",J5=""),"",G5/(J5*60)) | L5: EAST-OUT
A6: BEFORE | B6: P-WEST-PAVE | C6: 1 | D6: B03 | E6: West paved contribution toward east outlet | F6: SHEET | G6: 60 | H6: 0.008 | J6: =IF(I6<>"",I6,IF(UPPER(TRIM(F6))="SHEET",Inputs!$B$7,IF(UPPER(TRIM(F6))="SWALE",Inputs!$B$8,IF(UPPER(TRIM(F6))="TRENCH",Inputs!$B$27,IF(UPPER(TRIM(F6))="PIPE",Inputs!$B$9,Inputs!$B$10))))) | K6: =IF(OR(G6="",J6=""),"",G6/(J6*60)) | L6: EAST-OUT | M6: Use only if hydraulically connected
A7: AFTER | B7: P-EAST-STRIP | C7: 1 | D7: A01-EAST-STRIP | E7: East strip trench segment (SE edge toward J-EAST-IN) | F7: TRENCH | G7: 18.3 | H7: 0.008 | J7: =IF(I7<>"",I7,IF(UPPER(TRIM(F7))="SHEET",Inputs!$B$7,IF(UPPER(TRIM(F7))="SWALE",Inputs!$B$8,IF(UPPER(TRIM(F7))="TRENCH",Inputs!$B$27,IF(UPPER(TRIM(F7))="PIPE",Inputs!$B$9,Inputs!$B$10))))) | K7: =IF(OR(G7="",J7=""),"",G7/(J7*60)) | L7: J-EAST-IN | M7: Represents field underdrain laterals/collector in trench, not a plain solid pipe. | Mapped on right-field/east strip green edge.
A8: AFTER | B8: P-EAST-OUT | C8: 1 | D8: A02-EAST-OUT | E8: East outlet collector pipe (J-EAST-IN to EAST-OUT) | F8: PIPE | G8: 16.1 | H8: 0.005 | J8: =IF(I8<>"",I8,IF(UPPER(TRIM(F8))="SHEET",Inputs!$B$7,IF(UPPER(TRIM(F8))="SWALE",Inputs!$B$8,IF(UPPER(TRIM(F8))="TRENCH",Inputs!$B$27,IF(UPPER(TRIM(F8))="PIPE",Inputs!$B$9,Inputs!$B$10))))) | K8: =IF(OR(G8="",J8=""),"",G8/(J8*60)) | L8: EAST-OUT | M8: Collector/outlet branch (non-perforated). | Short outlet collector at east side to culvert zone.
A9: AFTER | B9: P-FIELD-3LINE | C9: 1 | D9: A03-FIELD-3LINE | E9: Field 3-line trench centerline (dimensioned middle segment) | F9: TRENCH | G9: =Inputs!$B$47 | H9: 0.005 | J9: =IF(I9<>"",I9,IF(UPPER(TRIM(F9))="SHEET",Inputs!$B$7,IF(UPPER(TRIM(F9))="SWALE",Inputs!$B$8,IF(UPPER(TRIM(F9))="TRENCH",Inputs!$B$27,IF(UPPER(TRIM(F9))="PIPE",Inputs!$B$9,Inputs!$B$10))))) | K9: =IF(OR(G9="",J9=""),"",G9/(J9*60)) | L9: EAST-IN | M9: Dimensioned segment from user markup: 34.509 m toward EAST-IN (not placeholder 12 m).
A10: AFTER | B10: P-WEST-PAVE | C10: 1 | D10: A04-WEST-BRANCH | E10: West branch toward collector trunk | F10: PIPE | G10: 23.6 | H10: 0.008 | J10: =IF(I10<>"",I10,IF(UPPER(TRIM(F10))="SHEET",Inputs!$B$7,IF(UPPER(TRIM(F10))="SWALE",Inputs!$B$8,IF(UPPER(TRIM(F10))="TRENCH",Inputs!$B$27,IF(UPPER(TRIM(F10))="PIPE",Inputs!$B$9,Inputs!$B$10))))) | K10: =IF(OR(G10="",J10=""),"",G10/(J10*60)) | L10: EAST-OUT | M10: Set per final profile | West paved/field branch toward trunk and outlet.
A11: AFTER | B11: P-EAST-STRIP | C11: 2 | D11: A01T-EAST-TRUNK | E11: Collector trunk east segment (dimensioned) | F11: =Inputs!$B$51 | G11: =IF(UPPER(TRIM(Inputs!$B$53))="YES",Inputs!$B$46,0) | H11: =Inputs!$B$43 | I11: =Inputs!$B$52 | J11: =IF(I11<>"",I11,IF(UPPER(TRIM(F11))="SHEET",Inputs!$B$7,IF(UPPER(TRIM(F11))="SWALE",Inputs!$B$8,IF(UPPER(TRIM(F11))="TRENCH",Inputs!$B$27,IF(UPPER(TRIM(F11))="PIPE",Inputs!$B$9,Inputs!$B$10))))) | K11: =IF(OR(G11="",J11=""),"",G11/(J11*60)) | L11: EAST-OUT | M11: East collector segment tied to EAST-IN/EAST-OUT naming for clarity. Length from Inputs!B46 (66.398 m).
A12: AFTER | B12: P-FIELD-3LINE | C12: 2 | D12: A03T-EAST-TRUNK | E12: Field-3line to outlet via east collector segment (dimensioned) | F12: =Inputs!$B$51 | G12: =IF(UPPER(TRIM(Inputs!$B$53))="YES",Inputs!$B$46,0) | H12: =Inputs!$B$43 | I12: =Inputs!$B$52 | J12: =IF(I12<>"",I12,IF(UPPER(TRIM(F12))="SHEET",Inputs!$B$7,IF(UPPER(TRIM(F12))="SWALE",Inputs!$B$8,IF(UPPER(TRIM(F12))="TRENCH",Inputs!$B$27,IF(UPPER(TRIM(F12))="PIPE",Inputs!$B$9,Inputs!$B$10))))) | K12: =IF(OR(G12="",J12=""),"",G12/(J12*60)) | L12: EAST-OUT | M12: Dimensioned segment from user markup: 66.398 m from EAST-IN to EAST-OUT along east collector trajectory.
A13: AFTER | B13: P-WEST-PAVE | C13: 2 | D13: A04T-WEST-TRUNK | E13: Collector trunk west segment (dimensioned) | F13: =Inputs!$B$51 | G13: =IF(UPPER(TRIM(Inputs!$B$53))="YES",Inputs!$B$48,0) | H13: =Inputs!$B$43 | I13: =Inputs!$B$52 | J13: =IF(I13<>"",I13,IF(UPPER(TRIM(F13))="SHEET",Inputs!$B$7,IF(UPPER(TRIM(F13))="SWALE",Inputs!$B$8,IF(UPPER(TRIM(F13))="TRENCH",Inputs!$B$27,IF(UPPER(TRIM(F13))="PIPE",Inputs!$B$9,Inputs!$B$10))))) | K13: =IF(OR(G13="",J13=""),"",G13/(J13*60)) | L13: J-TRUNK-WEST | M13: Explicit west-side trunk reach. | West trunk reach from dimension tool.
A14: AFTER | B14: P-WEST-PAVE | C14: 3 | D14: A04T-CENTER-SW | E14: Collector trunk center-to-south reach (dimensioned) | F14: =Inputs!$B$51 | G14: =IF(UPPER(TRIM(Inputs!$B$53))="YES",Inputs!$B$47,0) | H14: =Inputs!$B$43 | I14: =Inputs!$B$52 | J14: =IF(I14<>"",I14,IF(UPPER(TRIM(F14))="SHEET",Inputs!$B$7,IF(UPPER(TRIM(F14))="SWALE",Inputs!$B$8,IF(UPPER(TRIM(F14))="TRENCH",Inputs!$B$27,IF(UPPER(TRIM(F14))="PIPE",Inputs!$B$9,Inputs!$B$10))))) | K14: =IF(OR(G14="",J14=""),"",G14/(J14*60)) | L14: J-TRUNK-BOTTOM | M14: Explicit bottom trunk reach. | Middle-to-south segment from dimension tool.
A15: AFTER | B15: P-WEST-PAVE | C15: 4 | D15: A04T-EAST-TRUNK2 | E15: Collector trunk east approach to outlet | F15: =Inputs!$B$51 | G15: =IF(UPPER(TRIM(Inputs!$B$53))="YES",Inputs!$B$46,0) | H15: =Inputs!$B$43 | I15: =Inputs!$B$52 | J15: =IF(I15<>"",I15,IF(UPPER(TRIM(F15))="SHEET",Inputs!$B$7,IF(UPPER(TRIM(F15))="SWALE",Inputs!$B$8,IF(UPPER(TRIM(F15))="TRENCH",Inputs!$B$27,IF(UPPER(TRIM(F15))="PIPE",Inputs!$B$9,Inputs!$B$10))))) | K15: =IF(OR(G15="",J15=""),"",G15/(J15*60)) | L15: EAST-OUT | M15: Explicit east trunk reach to outlet. | Final east approach segment for west branch path.
A16: AFTER | B16: P-EAST-OUT | C16: 2 | D16: A02T-EAST-TRUNK | E16: Optional east trunk add-on for P-EAST-OUT | F16: =Inputs!$B$51 | G16: =IF(UPPER(TRIM(Inputs!$B$53))="YES",Inputs!$B$46,0) | H16: =Inputs!$B$43 | I16: =Inputs!$B$52 | J16: =IF(I16<>"",I16,IF(UPPER(TRIM(F16))="SHEET",Inputs!$B$7,IF(UPPER(TRIM(F16))="SWALE",Inputs!$B$8,IF(UPPER(TRIM(F16))="TRENCH",Inputs!$B$27,IF(UPPER(TRIM(F16))="PIPE",Inputs!$B$9,Inputs!$B$10))))) | K16: =IF(OR(G16="",J16=""),"",G16/(J16*60)) | L16: EAST-OUT | M16: Adds trunk run if this path is used. | Applied only when P-EAST-OUT path is active.
J17: =IF(I17<>"",I17,IF(UPPER(TRIM(F17))="SHEET",Inputs!$B$7,IF(UPPER(TRIM(F17))="SWALE",Inputs!$B$8,IF(UPPER(TRIM(F17))="TRENCH",Inputs!$B$27,IF(UPPER(TRIM(F17))="PIPE",Inputs!$B$9,Inputs!$B$10))))) | K17: =IF(OR(G17="",J17=""),"",G17/(J17*60))
J18: =IF(I18<>"",I18,IF(UPPER(TRIM(F18))="SHEET",Inputs!$B$7,IF(UPPER(TRIM(F18))="SWALE",Inputs!$B$8,IF(UPPER(TRIM(F18))="TRENCH",Inputs!$B$27,IF(UPPER(TRIM(F18))="PIPE",Inputs!$B$9,Inputs!$B$10))))) | K18: =IF(OR(G18="",J18=""),"",G18/(J18*60))
J19: =IF(I19<>"",I19,IF(UPPER(TRIM(F19))="SHEET",Inputs!$B$7,IF(UPPER(TRIM(F19))="SWALE",Inputs!$B$8,IF(UPPER(TRIM(F19))="TRENCH",Inputs!$B$27,IF(UPPER(TRIM(F19))="PIPE",Inputs!$B$9,Inputs!$B$10))))) | K19: =IF(OR(G19="",J19=""),"",G19/(J19*60))
J20: =IF(I20<>"",I20,IF(UPPER(TRIM(F20))="SHEET",Inputs!$B$7,IF(UPPER(TRIM(F20))="SWALE",Inputs!$B$8,IF(UPPER(TRIM(F20))="TRENCH",Inputs!$B$27,IF(UPPER(TRIM(F20))="PIPE",Inputs!$B$9,Inputs!$B$10))))) | K20: =IF(OR(G20="",J20=""),"",G20/(J20*60))
J21: =IF(I21<>"",I21,IF(UPPER(TRIM(F21))="SHEET",Inputs!$B$7,IF(UPPER(TRIM(F21))="SWALE",Inputs!$B$8,IF(UPPER(TRIM(F21))="TRENCH",Inputs!$B$27,IF(UPPER(TRIM(F21))="PIPE",Inputs!$B$9,Inputs!$B$10))))) | K21: =IF(OR(G21="",J21=""),"",G21/(J21*60))
J22: =IF(I22<>"",I22,IF(UPPER(TRIM(F22))="SHEET",Inputs!$B$7,IF(UPPER(TRIM(F22))="SWALE",Inputs!$B$8,IF(UPPER(TRIM(F22))="TRENCH",Inputs!$B$27,IF(UPPER(TRIM(F22))="PIPE",Inputs!$B$9,Inputs!$B$10))))) | K22: =IF(OR(G22="",J22=""),"",G22/(J22*60))
J23: =IF(I23<>"",I23,IF(UPPER(TRIM(F23))="SHEET",Inputs!$B$7,IF(UPPER(TRIM(F23))="SWALE",Inputs!$B$8,IF(UPPER(TRIM(F23))="TRENCH",Inputs!$B$27,IF(UPPER(TRIM(F23))="PIPE",Inputs!$B$9,Inputs!$B$10))))) | K23: =IF(OR(G23="",J23=""),"",G23/(J23*60))
J24: =IF(I24<>"",I24,IF(UPPER(TRIM(F24))="SHEET",Inputs!$B$7,IF(UPPER(TRIM(F24))="SWALE",Inputs!$B$8,IF(UPPER(TRIM(F24))="TRENCH",Inputs!$B$27,IF(UPPER(TRIM(F24))="PIPE",Inputs!$B$9,Inputs!$B$10))))) | K24: =IF(OR(G24="",J24=""),"",G24/(J24*60))
J25: =IF(I25<>"",I25,IF(UPPER(TRIM(F25))="SHEET",Inputs!$B$7,IF(UPPER(TRIM(F25))="SWALE",Inputs!$B$8,IF(UPPER(TRIM(F25))="TRENCH",Inputs!$B$27,IF(UPPER(TRIM(F25))="PIPE",Inputs!$B$9,Inputs!$B$10))))) | K25: =IF(OR(G25="",J25=""),"",G25/(J25*60))
J26: =IF(I26<>"",I26,IF(UPPER(TRIM(F26))="SHEET",Inputs!$B$7,IF(UPPER(TRIM(F26))="SWALE",Inputs!$B$8,IF(UPPER(TRIM(F26))="TRENCH",Inputs!$B$27,IF(UPPER(TRIM(F26))="PIPE",Inputs!$B$9,Inputs!$B$10))))) | K26: =IF(OR(G26="",J26=""),"",G26/(J26*60))
J27: =IF(I27<>"",I27,IF(UPPER(TRIM(F27))="SHEET",Inputs!$B$7,IF(UPPER(TRIM(F27))="SWALE",Inputs!$B$8,IF(UPPER(TRIM(F27))="TRENCH",Inputs!$B$27,IF(UPPER(TRIM(F27))="PIPE",Inputs!$B$9,Inputs!$B$10))))) | K27: =IF(OR(G27="",J27=""),"",G27/(J27*60))
J28: =IF(I28<>"",I28,IF(UPPER(TRIM(F28))="SHEET",Inputs!$B$7,IF(UPPER(TRIM(F28))="SWALE",Inputs!$B$8,IF(UPPER(TRIM(F28))="TRENCH",Inputs!$B$27,IF(UPPER(TRIM(F28))="PIPE",Inputs!$B$9,Inputs!$B$10))))) | K28: =IF(OR(G28="",J28=""),"",G28/(J28*60))
... J204: =IF(I204<>"",I204,IF(UPPER(TRIM(F204))="SHEET",Inputs!$B$7,IF(UPPER(TRIM(F204))="SWALE",Inputs!$B$8,IF(UPPER(TRIM(F204))="TRENCH",Inputs!$B$27,IF(UPPER(TRIM(F204))="PIPE",Inputs!$B$9,Inputs!$B$10))))) | K204: =IF(OR(G204="",J204=""),"",G204/(J204*60))

Sheet Subcatchments
A1: SUBCATCHMENTS - BEFORE vs AFTER
A3: ID | B3: Description | C3: Gross_area_m2 | D3: Include_factor_before | E3: Effective_area_before_m2 | F3: Surface_before | G3: C_before_override | H3: C_before_used | I3: Tc_base_before_min | J3: Path_ID_before | K3: Travel_time_before_min | L3: Tc_used_before_min | M3: Intensity_before_mmh | N3: Q_before_m3s | O3: Include_factor_after | P3: Effective_area_after_m2 | Q3: Surface_after | R3: C_after_override | S3: C_after_used | T3: Tc_base_after_min | U3: Path_ID_after | V3: Travel_time_after_min | W3: Tc_used_after_min | X3: Intensity_after_mmh | Y3: Q_after_m3s | Z3: Delta_Q_after_minus_before | AA3: Notes
A4: SC-01 | B4: Main field area (light green) | C4: 11873.82 | D4: 1 | E4: =IF(C4="","",C4*D4) | F4: GRASS | H4: =IF(G4<>"",G4,IF(UPPER(TRIM(F4))="ROOF",Inputs!$B$13,IF(UPPER(TRIM(F4))="PAVAGE",Inputs!$B$14,IF(UPPER(TRIM(F4))="GRASS",Inputs!$B$15,IF(UPPER(TRIM(F4))="GRAVEL",Inputs!$B$17,Inputs!$B$18))))) | I4: 7 | J4: P-EAST | K4: =IF(J4="",0,SUMIFS(FlowPaths!$K:$K,FlowPaths!$A:$A,"BEFORE",FlowPaths!$B:$B,J4)) | L4: =IF(I4="",Inputs!$B$11,I4)+K4 | M4: =IF(L4="","",IF(UPPER(TRIM(Inputs!$B$23))="IDF_EQUATION",Inputs!$B$3/((L4+Inputs!$B$4)^Inputs!$B$5),INDEX(IDF_Station!$B$3:$G$11,IFERROR(MATCH(L4,IDF_Station!$A$3:$A$11,1),1),MATCH(Inputs!$B$24,IDF_Station!$B$2:$G$2,0)))) | N4: =IF(OR(E4="",H4="",M4=""),"",2.78E-7*H4*E4*M4) | O4: 1 | P4: =IF(C4="","",C4*O4) | Q4: GRASS | S4: =IF(R4<>"",R4,IF(UPPER(TRIM(Q4))="ROOF",Inputs!$B$13,IF(UPPER(TRIM(Q4))="PAVAGE",Inputs!$B$14,IF(UPPER(TRIM(Q4))="GRASS",Inputs!$B$16,IF(UPPER(TRIM(Q4))="GRAVEL",Inputs!$B$17,Inputs!$B$18))))) | T4: 7 | U4: P-EAST-STRIP | V4: =IF(U4="",0,SUMIFS(FlowPaths!$K:$K,FlowPaths!$A:$A,"AFTER",FlowPaths!$B:$B,U4)) | W4: =IF(T4="",Inputs!$B$12,T4)+V4 | X4: =IF(W4="","",IF(UPPER(TRIM(Inputs!$B$23))="IDF_EQUATION",Inputs!$B$3/((W4+Inputs!$B$4)^Inputs!$B$5),INDEX(IDF_Station!$B$3:$G$11,IFERROR(MATCH(W4,IDF_Station!$A$3:$A$11,1),1),MATCH(Inputs!$B$24,IDF_Station!$B$2:$G$2,0)))) | Y4: =IF(OR(P4="",S4="",X4=""),"",2.78E-7*S4*P4*X4) | Z4: =IF(OR(Y4="",N4=""),"",Y4-N4) | AA4: Main grass area adjusted: 12712 - 422.73 - 415.45 = 11873.82 m2.
A5: SC-02 | B5: Peripheral field/landscape area (darker green) | C5: 2961 | D5: 1 | E5: =IF(C5="","",C5*D5) | F5: GRASS | H5: =IF(G5<>"",G5,IF(UPPER(TRIM(F5))="ROOF",Inputs!$B$13,IF(UPPER(TRIM(F5))="PAVAGE",Inputs!$B$14,IF(UPPER(TRIM(F5))="GRASS",Inputs!$B$15,IF(UPPER(TRIM(F5))="GRAVEL",Inputs!$B$17,Inputs!$B$18))))) | I5: 7 | J5: P-EAST | K5: =IF(J5="",0,SUMIFS(FlowPaths!$K:$K,FlowPaths!$A:$A,"BEFORE",FlowPaths!$B:$B,J5)) | L5: =IF(I5="",Inputs!$B$11,I5)+K5 | M5: =IF(L5="","",IF(UPPER(TRIM(Inputs!$B$23))="IDF_EQUATION",Inputs!$B$3/((L5+Inputs!$B$4)^Inputs!$B$5),INDEX(IDF_Station!$B$3:$G$11,IFERROR(MATCH(L5,IDF_Station!$A$3:$A$11,1),1),MATCH(Inputs!$B$24,IDF_Station!$B$2:$G$2,0)))) | N5: =IF(OR(E5="",H5="",M5=""),"",2.78E-7*H5*E5*M5) | O5: 1 | P5: =IF(C5="","",C5*O5) | Q5: GRASS | S5: =IF(R5<>"",R5,IF(UPPER(TRIM(Q5))="ROOF",Inputs!$B$13,IF(UPPER(TRIM(Q5))="PAVAGE",Inputs!$B$14,IF(UPPER(TRIM(Q5))="GRASS",Inputs!$B$16,IF(UPPER(TRIM(Q5))="GRAVEL",Inputs!$B$17,Inputs!$B$18))))) | T5: 7 | U5: P-EAST-STRIP | V5: =IF(U5="",0,SUMIFS(FlowPaths!$K:$K,FlowPaths!$A:$A,"AFTER",FlowPaths!$B:$B,U5)) | W5: =IF(T5="",Inputs!$B$12,T5)+V5 | X5: =IF(W5="","",IF(UPPER(TRIM(Inputs!$B$23))="IDF_EQUATION",Inputs!$B$3/((W5+Inputs!$B$4)^Inputs!$B$5),INDEX(IDF_Station!$B$3:$G$11,IFERROR(MATCH(W5,IDF_Station!$A$3:$A$11,1),1),MATCH(Inputs!$B$24,IDF_Station!$B$2:$G$2,0)))) | Y5: =IF(OR(P5="",S5="",X5=""),"",2.78E-7*S5*P5*X5) | Z5: =IF(OR(Y5="",N5=""),"",Y5-N5) | AA5: From marked plan: A=2961 m2
A6: SC-03 | B6: Paved area potentially connected (gray) | C6: 1869.7 | D6: =Inputs!$B$19 | E6: =IF(C6="","",C6*D6) | F6: PAVAGE | H6: =IF(G6<>"",G6,IF(UPPER(TRIM(F6))="ROOF",Inputs!$B$13,IF(UPPER(TRIM(F6))="PAVAGE",Inputs!$B$14,IF(UPPER(TRIM(F6))="GRASS",Inputs!$B$15,IF(UPPER(TRIM(F6))="GRAVEL",Inputs!$B$17,Inputs!$B$18))))) | I6: 7 | J6: P-WEST-PAVE | K6: =IF(J6="",0,SUMIFS(FlowPaths!$K:$K,FlowPaths!$A:$A,"BEFORE",FlowPaths!$B:$B,J6)) | L6: =IF(I6="",Inputs!$B$11,I6)+K6 | M6: =IF(L6="","",IF(UPPER(TRIM(Inputs!$B$23))="IDF_EQUATION",Inputs!$B$3/((L6+Inputs!$B$4)^Inputs!$B$5),INDEX(IDF_Station!$B$3:$G$11,IFERROR(MATCH(L6,IDF_Station!$A$3:$A$11,1),1),MATCH(Inputs!$B$24,IDF_Station!$B$2:$G$2,0)))) | N6: =IF(OR(E6="",H6="",M6=""),"",2.78E-7*H6*E6*M6) | O6: =Inputs!$B$19 | P6: =IF(C6="","",C6*O6) | Q6: PAVAGE | S6: =IF(R6<>"",R6,IF(UPPER(TRIM(Q6))="ROOF",Inputs!$B$13,IF(UPPER(TRIM(Q6))="PAVAGE",Inputs!$B$14,IF(UPPER(TRIM(Q6))="GRASS",Inputs!$B$16,IF(UPPER(TRIM(Q6))="GRAVEL",Inputs!$B$17,Inputs!$B$18))))) | T6: 7 | U6: P-WEST-PAVE | V6: =IF(U6="",0,SUMIFS(FlowPaths!$K:$K,FlowPaths!$A:$A,"AFTER",FlowPaths!$B:$B,U6)) | W6: =IF(T6="",Inputs!$B$12,T6)+V6 | X6: =IF(W6="","",IF(UPPER(TRIM(Inputs!$B$23))="IDF_EQUATION",Inputs!$B$3/((W6+Inputs!$B$4)^Inputs!$B$5),INDEX(IDF_Station!$B$3:$G$11,IFERROR(MATCH(W6,IDF_Station!$A$3:$A$11,1),1),MATCH(Inputs!$B$24,IDF_Station!$B$2:$G$2,0)))) | Y6: =IF(OR(P6="",S6="",X6=""),"",2.78E-7*S6*P6*X6) | Z6: =IF(OR(Y6="",N6=""),"",Y6-N6) | AA6: From marked plan: A=1869.7 m2 (use inclusion factor D/O).
A7: SC-04 | B7: Concrete apron / hardscape area (fully impervious) | C7: 398 | D7: 1 | E7: =IF(C7="","",C7*D7) | F7: PAVAGE | H7: =IF(G7<>"",G7,IF(UPPER(TRIM(F7))="ROOF",Inputs!$B$13,IF(UPPER(TRIM(F7))="PAVAGE",Inputs!$B$14,IF(UPPER(TRIM(F7))="GRASS",Inputs!$B$15,IF(UPPER(TRIM(F7))="GRAVEL",Inputs!$B$17,Inputs!$B$18))))) | I7: 7 | J7: P-EAST | K7: =IF(J7="",0,SUMIFS(FlowPaths!$K:$K,FlowPaths!$A:$A,"BEFORE",FlowPaths!$B:$B,J7)) | L7: =IF(I7="",Inputs!$B$11,I7)+K7 | M7: =IF(L7="","",IF(UPPER(TRIM(Inputs!$B$23))="IDF_EQUATION",Inputs!$B$3/((L7+Inputs!$B$4)^Inputs!$B$5),INDEX(IDF_Station!$B$3:$G$11,IFERROR(MATCH(L7,IDF_Station!$A$3:$A$11,1),1),MATCH(Inputs!$B$24,IDF_Station!$B$2:$G$2,0)))) | N7: =IF(OR(E7="",H7="",M7=""),"",2.78E-7*H7*E7*M7) | O7: 1 | P7: =IF(C7="","",C7*O7) | Q7: PAVAGE | S7: =IF(R7<>"",R7,IF(UPPER(TRIM(Q7))="ROOF",Inputs!$B$13,IF(UPPER(TRIM(Q7))="PAVAGE",Inputs!$B$14,IF(UPPER(TRIM(Q7))="GRASS",Inputs!$B$16,IF(UPPER(TRIM(Q7))="GRAVEL",Inputs!$B$17,Inputs!$B$18))))) | T7: 7 | U7: P-FIELD-3LINE | V7: =IF(U7="",0,SUMIFS(FlowPaths!$K:$K,FlowPaths!$A:$A,"AFTER",FlowPaths!$B:$B,U7)) | W7: =IF(T7="",Inputs!$B$12,T7)+V7 | X7: =IF(W7="","",IF(UPPER(TRIM(Inputs!$B$23))="IDF_EQUATION",Inputs!$B$3/((W7+Inputs!$B$4)^Inputs!$B$5),INDEX(IDF_Station!$B$3:$G$11,IFERROR(MATCH(W7,IDF_Station!$A$3:$A$11,1),1),MATCH(Inputs!$B$24,IDF_Station!$B$2:$G$2,0)))) | Y7: =IF(OR(P7="",S7="",X7=""),"",2.78E-7*S7*P7*X7) | Z7: =IF(OR(Y7="",N7=""),"",Y7-N7) | AA7: From marked plan: A=398 m2, fully impervious (no mixed split).
A8: SC-05 | B8: Field area near outlet (missing label recovered) | C8: 2882 | D8: 1 | E8: =IF(C8="","",C8*D8) | F8: GRASS | H8: =IF(G8<>"",G8,IF(UPPER(TRIM(F8))="ROOF",Inputs!$B$13,IF(UPPER(TRIM(F8))="PAVAGE",Inputs!$B$14,IF(UPPER(TRIM(F8))="GRASS",Inputs!$B$15,IF(UPPER(TRIM(F8))="GRAVEL",Inputs!$B$17,Inputs!$B$18))))) | I8: 7 | J8: P-EAST | K8: =IF(J8="",0,SUMIFS(FlowPaths!$K:$K,FlowPaths!$A:$A,"BEFORE",FlowPaths!$B:$B,J8)) | L8: =IF(I8="",Inputs!$B$11,I8)+K8 | M8: =IF(L8="","",IF(UPPER(TRIM(Inputs!$B$23))="IDF_EQUATION",Inputs!$B$3/((L8+Inputs!$B$4)^Inputs!$B$5),INDEX(IDF_Station!$B$3:$G$11,IFERROR(MATCH(L8,IDF_Station!$A$3:$A$11,1),1),MATCH(Inputs!$B$24,IDF_Station!$B$2:$G$2,0)))) | N8: =IF(OR(E8="",H8="",M8=""),"",2.78E-7*H8*E8*M8) | O8: 1 | P8: =IF(C8="","",C8*O8) | Q8: GRASS | S8: =IF(R8<>"",R8,IF(UPPER(TRIM(Q8))="ROOF",Inputs!$B$13,IF(UPPER(TRIM(Q8))="PAVAGE",Inputs!$B$14,IF(UPPER(TRIM(Q8))="GRASS",Inputs!$B$16,IF(UPPER(TRIM(Q8))="GRAVEL",Inputs!$B$17,Inputs!$B$18))))) | T8: 7 | U8: P-FIELD-3LINE | V8: =IF(U8="",0,SUMIFS(FlowPaths!$K:$K,FlowPaths!$A:$A,"AFTER",FlowPaths!$B:$B,U8)) | W8: =IF(T8="",Inputs!$B$12,T8)+V8 | X8: =IF(W8="","",IF(UPPER(TRIM(Inputs!$B$23))="IDF_EQUATION",Inputs!$B$3/((W8+Inputs!$B$4)^Inputs!$B$5),INDEX(IDF_Station!$B$3:$G$11,IFERROR(MATCH(W8,IDF_Station!$A$3:$A$11,1),1),MATCH(Inputs!$B$24,IDF_Station!$B$2:$G$2,0)))) | Y8: =IF(OR(P8="",S8="",X8=""),"",2.78E-7*S8*P8*X8) | Z8: =IF(OR(Y8="",N8=""),"",Y8-N8) | AA8: From marked plan: A=2882 m2 (field area close to outlet).
A9: SC-07 | B9: Mixed block - right field trajectory (SE mid) | C9: 422.73 | D9: 1 | E9: =IF(C9="","",C9*D9) | F9: MIXED | G9: =IF(UPPER(TRIM(Inputs!$B$41))="YES",Inputs!$B$39,"") | H9: =IF(G9<>"",G9,IF(UPPER(TRIM(F9))="ROOF",Inputs!$B$13,IF(UPPER(TRIM(F9))="PAVAGE",Inputs!$B$14,IF(UPPER(TRIM(F9))="GRASS",Inputs!$B$15,IF(UPPER(TRIM(F9))="GRAVEL",Inputs!$B$17,Inputs!$B$18))))) | I9: 7 | J9: P-EAST | K9: =IF(J9="",0,SUMIFS(FlowPaths!$K:$K,FlowPaths!$A:$A,"BEFORE",FlowPaths!$B:$B,J9)) | L9: =IF(J9="",0,SUMIFS(FlowPaths!$K:$K,FlowPaths!$A:$A,"BEFORE",FlowPaths!$B:$B,J9)) | M9: =IF(L9="","",IF(UPPER(TRIM(Inputs!$B$23))="IDF_EQUATION",Inputs!$B$3/((L9+Inputs!$B$4)^Inputs!$B$5),INDEX(IDF_Station!$B$3:$G$11,IFERROR(MATCH(L9,IDF_Station!$A$3:$A$11,1),1),MATCH(Inputs!$B$24,IDF_Station!$B$2:$G$2,0)))) | N9: =IF(OR(E9="",H9="",M9=""),"",2.78E-7*H9*E9*M9) | O9: 1 | P9: =IF(C9="","",C9*O9) | Q9: MIXED | R9: =IF(UPPER(TRIM(Inputs!$B$41))="YES",Inputs!$B$40,"") | S9: =IF(R9<>"",R9,IF(UPPER(TRIM(Q9))="ROOF",Inputs!$B$13,IF(UPPER(TRIM(Q9))="PAVAGE",Inputs!$B$14,IF(UPPER(TRIM(Q9))="GRASS",Inputs!$B$16,IF(UPPER(TRIM(Q9))="GRAVEL",Inputs!$B$17,Inputs!$B$18))))) | T9: 7 | U9: P-EAST-STRIP | V9: =IF(U9="",0,SUMIFS(FlowPaths!$K:$K,FlowPaths!$A:$A,"AFTER",FlowPaths!$B:$B,U9)) | W9: =IF(T9="",Inputs!$B$12,T9)+V9 | X9: =IF(W9="","",IF(UPPER(TRIM(Inputs!$B$23))="IDF_EQUATION",Inputs!$B$3/((W9+Inputs!$B$4)^Inputs!$B$5),INDEX(IDF_Station!$B$3:$G$11,IFERROR(MATCH(W9,IDF_Station!$A$3:$A$11,1),1),MATCH(Inputs!$B$24,IDF_Station!$B$2:$G$2,0)))) | Y9: =IF(OR(P9="",S9="",X9=""),"",2.78E-7*S9*P9*X9) | Z9: =IF(OR(Y9="",N9=""),"",Y9-N9) | AA9: Mixed block provided by user: A=422.73 m2 (SE/right-field trajectory).
A10: SC-08 | B10: Mixed block - left field trajectory (NW mid) | C10: 415.45 | D10: 1 | E10: =IF(C10="","",C10*D10) | F10: MIXED | G10: =IF(UPPER(TRIM(Inputs!$B$41))="YES",Inputs!$B$39,"") | H10: =IF(G10<>"",G10,IF(UPPER(TRIM(F10))="ROOF",Inputs!$B$13,IF(UPPER(TRIM(F10))="PAVAGE",Inputs!$B$14,IF(UPPER(TRIM(F10))="GRASS",Inputs!$B$15,IF(UPPER(TRIM(F10))="GRAVEL",Inputs!$B$17,Inputs!$B$18))))) | I10: 7 | J10: P-EAST | L10: =IF(J10="",0,SUMIFS(FlowPaths!$K:$K,FlowPaths!$A:$A,"BEFORE",FlowPaths!$B:$B,J10)) | M10: =IF(L10="","",IF(UPPER(TRIM(Inputs!$B$23))="IDF_EQUATION",Inputs!$B$3/((L10+Inputs!$B$4)^Inputs!$B$5),INDEX(IDF_Station!$B$3:$G$11,IFERROR(MATCH(L10,IDF_Station!$A$3:$A$11,1),1),MATCH(Inputs!$B$24,IDF_Station!$B$2:$G$2,0)))) | N10: =IF(OR(E10="",H10="",M10=""),"",2.78E-7*H10*E10*M10) | O10: 1 | P10: =IF(C10="","",C10*O10) | Q10: MIXED | R10: =IF(UPPER(TRIM(Inputs!$B$41))="YES",Inputs!$B$40,"") | S10: =IF(R10<>"",R10,IF(UPPER(TRIM(Q10))="ROOF",Inputs!$B$13,IF(UPPER(TRIM(Q10))="PAVAGE",Inputs!$B$14,IF(UPPER(TRIM(Q10))="GRASS",Inputs!$B$16,IF(UPPER(TRIM(Q10))="GRAVEL",Inputs!$B$17,Inputs!$B$18))))) | T10: 7 | U10: P-EAST-STRIP | V10: =IF(U10="",0,SUMIFS(FlowPaths!$K:$K,FlowPaths!$A:$A,"AFTER",FlowPaths!$B:$B,U10)) | W10: =IF(T10="",Inputs!$B$12,T10)+V10 | X10: =IF(W10="","",IF(UPPER(TRIM(Inputs!$B$23))="IDF_EQUATION",Inputs!$B$3/((W10+Inputs!$B$4)^Inputs!$B$5),INDEX(IDF_Station!$B$3:$G$11,IFERROR(MATCH(W10,IDF_Station!$A$3:$A$11,1),1),MATCH(Inputs!$B$24,IDF_Station!$B$2:$G$2,0)))) | Y10: =IF(OR(P10="",S10="",X10=""),"",2.78E-7*S10*P10*X10) | Z10: =IF(OR(Y10="",N10=""),"",Y10-N10) | AA10: Mixed block provided by user: A=415.45 m2 (NW/left-field trajectory).
M11: =IF(L11="","",IF(UPPER(TRIM(Inputs!$B$23))="IDF_EQUATION",Inputs!$B$3/((L11+Inputs!$B$4)^Inputs!$B$5),INDEX(IDF_Station!$B$3:$G$11,IFERROR(MATCH(L11,IDF_Station!$A$3:$A$11,1),1),MATCH(Inputs!$B$24,IDF_Station!$B$2:$G$2,0)))) | X11: =IF(W11="","",IF(UPPER(TRIM(Inputs!$B$23))="IDF_EQUATION",Inputs!$B$3/((W11+Inputs!$B$4)^Inputs!$B$5),INDEX(IDF_Station!$B$3:$G$11,IFERROR(MATCH(W11,IDF_Station!$A$3:$A$11,1),1),MATCH(Inputs!$B$24,IDF_Station!$B$2:$G$2,0))))
M12: =IF(L12="","",IF(UPPER(TRIM(Inputs!$B$23))="IDF_EQUATION",Inputs!$B$3/((L12+Inputs!$B$4)^Inputs!$B$5),INDEX(IDF_Station!$B$3:$G$11,IFERROR(MATCH(L12,IDF_Station!$A$3:$A$11,1),1),MATCH(Inputs!$B$24,IDF_Station!$B$2:$G$2,0)))) | X12: =IF(W12="","",IF(UPPER(TRIM(Inputs!$B$23))="IDF_EQUATION",Inputs!$B$3/((W12+Inputs!$B$4)^Inputs!$B$5),INDEX(IDF_Station!$B$3:$G$11,IFERROR(MATCH(W12,IDF_Station!$A$3:$A$11,1),1),MATCH(Inputs!$B$24,IDF_Station!$B$2:$G$2,0))))
M13: =IF(L13="","",IF(UPPER(TRIM(Inputs!$B$23))="IDF_EQUATION",Inputs!$B$3/((L13+Inputs!$B$4)^Inputs!$B$5),INDEX(IDF_Station!$B$3:$G$11,IFERROR(MATCH(L13,IDF_Station!$A$3:$A$11,1),1),MATCH(Inputs!$B$24,IDF_Station!$B$2:$G$2,0)))) | X13: =IF(W13="","",IF(UPPER(TRIM(Inputs!$B$23))="IDF_EQUATION",Inputs!$B$3/((W13+Inputs!$B$4)^Inputs!$B$5),INDEX(IDF_Station!$B$3:$G$11,IFERROR(MATCH(W13,IDF_Station!$A$3:$A$11,1),1),MATCH(Inputs!$B$24,IDF_Station!$B$2:$G$2,0))))
M14: =IF(L14="","",IF(UPPER(TRIM(Inputs!$B$23))="IDF_EQUATION",Inputs!$B$3/((L14+Inputs!$B$4)^Inputs!$B$5),INDEX(IDF_Station!$B$3:$G$11,IFERROR(MATCH(L14,IDF_Station!$A$3:$A$11,1),1),MATCH(Inputs!$B$24,IDF_Station!$B$2:$G$2,0)))) | X14: =IF(W14="","",IF(UPPER(TRIM(Inputs!$B$23))="IDF_EQUATION",Inputs!$B$3/((W14+Inputs!$B$4)^Inputs!$B$5),INDEX(IDF_Station!$B$3:$G$11,IFERROR(MATCH(W14,IDF_Station!$A$3:$A$11,1),1),MATCH(Inputs!$B$24,IDF_Station!$B$2:$G$2,0))))
M15: =IF(L15="","",IF(UPPER(TRIM(Inputs!$B$23))="IDF_EQUATION",Inputs!$B$3/((L15+Inputs!$B$4)^Inputs!$B$5),INDEX(IDF_Station!$B$3:$G$11,IFERROR(MATCH(L15,IDF_Station!$A$3:$A$11,1),1),MATCH(Inputs!$B$24,IDF_Station!$B$2:$G$2,0)))) | X15: =IF(W15="","",IF(UPPER(TRIM(Inputs!$B$23))="IDF_EQUATION",Inputs!$B$3/((W15+Inputs!$B$4)^Inputs!$B$5),INDEX(IDF_Station!$B$3:$G$11,IFERROR(MATCH(W15,IDF_Station!$A$3:$A$11,1),1),MATCH(Inputs!$B$24,IDF_Station!$B$2:$G$2,0))))
M16: =IF(L16="","",IF(UPPER(TRIM(Inputs!$B$23))="IDF_EQUATION",Inputs!$B$3/((L16+Inputs!$B$4)^Inputs!$B$5),INDEX(IDF_Station!$B$3:$G$11,IFERROR(MATCH(L16,IDF_Station!$A$3:$A$11,1),1),MATCH(Inputs!$B$24,IDF_Station!$B$2:$G$2,0)))) | X16: =IF(W16="","",IF(UPPER(TRIM(Inputs!$B$23))="IDF_EQUATION",Inputs!$B$3/((W16+Inputs!$B$4)^Inputs!$B$5),INDEX(IDF_Station!$B$3:$G$11,IFERROR(MATCH(W16,IDF_Station!$A$3:$A$11,1),1),MATCH(Inputs!$B$24,IDF_Station!$B$2:$G$2,0))))
M17: =IF(L17="","",IF(UPPER(TRIM(Inputs!$B$23))="IDF_EQUATION",Inputs!$B$3/((L17+Inputs!$B$4)^Inputs!$B$5),INDEX(IDF_Station!$B$3:$G$11,IFERROR(MATCH(L17,IDF_Station!$A$3:$A$11,1),1),MATCH(Inputs!$B$24,IDF_Station!$B$2:$G$2,0)))) | X17: =IF(W17="","",IF(UPPER(TRIM(Inputs!$B$23))="IDF_EQUATION",Inputs!$B$3/((W17+Inputs!$B$4)^Inputs!$B$5),INDEX(IDF_Station!$B$3:$G$11,IFERROR(MATCH(W17,IDF_Station!$A$3:$A$11,1),1),MATCH(Inputs!$B$24,IDF_Station!$B$2:$G$2,0))))
M18: =IF(L18="","",IF(UPPER(TRIM(Inputs!$B$23))="IDF_EQUATION",Inputs!$B$3/((L18+Inputs!$B$4)^Inputs!$B$5),INDEX(IDF_Station!$B$3:$G$11,IFERROR(MATCH(L18,IDF_Station!$A$3:$A$11,1),1),MATCH(Inputs!$B$24,IDF_Station!$B$2:$G$2,0)))) | X18: =IF(W18="","",IF(UPPER(TRIM(Inputs!$B$23))="IDF_EQUATION",Inputs!$B$3/((W18+Inputs!$B$4)^Inputs!$B$5),INDEX(IDF_Station!$B$3:$G$11,IFERROR(MATCH(W18,IDF_Station!$A$3:$A$11,1),1),MATCH(Inputs!$B$24,IDF_Station!$B$2:$G$2,0))))
M19: =IF(L19="","",IF(UPPER(TRIM(Inputs!$B$23))="IDF_EQUATION",Inputs!$B$3/((L19+Inputs!$B$4)^Inputs!$B$5),INDEX(IDF_Station!$B$3:$G$11,IFERROR(MATCH(L19,IDF_Station!$A$3:$A$11,1),1),MATCH(Inputs!$B$24,IDF_Station!$B$2:$G$2,0)))) | X19: =IF(W19="","",IF(UPPER(TRIM(Inputs!$B$23))="IDF_EQUATION",Inputs!$B$3/((W19+Inputs!$B$4)^Inputs!$B$5),INDEX(IDF_Station!$B$3:$G$11,IFERROR(MATCH(W19,IDF_Station!$A$3:$A$11,1),1),MATCH(Inputs!$B$24,IDF_Station!$B$2:$G$2,0))))
M20: =IF(L20="","",IF(UPPER(TRIM(Inputs!$B$23))="IDF_EQUATION",Inputs!$B$3/((L20+Inputs!$B$4)^Inputs!$B$5),INDEX(IDF_Station!$B$3:$G$11,IFERROR(MATCH(L20,IDF_Station!$A$3:$A$11,1),1),MATCH(Inputs!$B$24,IDF_Station!$B$2:$G$2,0)))) | X20: =IF(W20="","",IF(UPPER(TRIM(Inputs!$B$23))="IDF_EQUATION",Inputs!$B$3/((W20+Inputs!$B$4)^Inputs!$B$5),INDEX(IDF_Station!$B$3:$G$11,IFERROR(MATCH(W20,IDF_Station!$A$3:$A$11,1),1),MATCH(Inputs!$B$24,IDF_Station!$B$2:$G$2,0))))
M21: =IF(L21="","",IF(UPPER(TRIM(Inputs!$B$23))="IDF_EQUATION",Inputs!$B$3/((L21+Inputs!$B$4)^Inputs!$B$5),INDEX(IDF_Station!$B$3:$G$11,IFERROR(MATCH(L21,IDF_Station!$A$3:$A$11,1),1),MATCH(Inputs!$B$24,IDF_Station!$B$2:$G$2,0)))) | X21: =IF(W21="","",IF(UPPER(TRIM(Inputs!$B$23))="IDF_EQUATION",Inputs!$B$3/((W21+Inputs!$B$4)^Inputs!$B$5),INDEX(IDF_Station!$B$3:$G$11,IFERROR(MATCH(W21,IDF_Station!$A$3:$A$11,1),1),MATCH(Inputs!$B$24,IDF_Station!$B$2:$G$2,0))))
M22: =IF(L22="","",IF(UPPER(TRIM(Inputs!$B$23))="IDF_EQUATION",Inputs!$B$3/((L22+Inputs!$B$4)^Inputs!$B$5),INDEX(IDF_Station!$B$3:$G$11,IFERROR(MATCH(L22,IDF_Station!$A$3:$A$11,1),1),MATCH(Inputs!$B$24,IDF_Station!$B$2:$G$2,0)))) | X22: =IF(W22="","",IF(UPPER(TRIM(Inputs!$B$23))="IDF_EQUATION",Inputs!$B$3/((W22+Inputs!$B$4)^Inputs!$B$5),INDEX(IDF_Station!$B$3:$G$11,IFERROR(MATCH(W22,IDF_Station!$A$3:$A$11,1),1),MATCH(Inputs!$B$24,IDF_Station!$B$2:$G$2,0))))
... M204: =IF(L204="","",IF(UPPER(TRIM(Inputs!$B$23))="IDF_EQUATION",Inputs!$B$3/((L204+Inputs!$B$4)^Inputs!$B$5),INDEX(IDF_Station!$B$3:$G$11,IFERROR(MATCH(L204,IDF_Station!$A$3:$A$11,1),1),MATCH(Inputs!$B$24,IDF_Station!$B$2:$G$2,0)))) | X204: =IF(W204="","",IF(UPPER(TRIM(Inputs!$B$23))="IDF_EQUATION",Inputs!$B$3/((W204+Inputs!$B$4)^Inputs!$B$5),INDEX(IDF_Station!$B$3:$G$11,IFERROR(MATCH(W204,IDF_Station!$A$3:$A$11,1),1),MATCH(Inputs!$B$24,IDF_Station!$B$2:$G$2,0))))

Sheet Summary_Before_After
A1: RUNOFF SUMMARY AT EAST DISCHARGE
A3: Metric | B3: Value | C3: Unit | D3: Comment
A4: Total effective contributing area BEFORE (m2) | B4: =SUM(Subcatchments!$E$4:$E$200) | C4: m2
A5: Total effective contributing area AFTER (m2) | B5: =SUM(Subcatchments!$P$4:$P$200) | C5: m2
A6: Total impervious area BEFORE (m2) | B6: =SUMIFS(Subcatchments!$E$4:$E$200,Subcatchments!$F$4:$F$200,"ROOF")+SUMIFS(Subcatchments!$E$4:$E$200,Subcatchments!$F$4:$F$200,"PAVAGE")+SUMIFS(Subcatchments!$E$4:$E$200,Subcatchments!$F$4:$F$200,"TRESFOND")+Inputs!$B$54*SUMIFS(Subcatchments!$E$4:$E$200,Subcatchments!$F$4:$F$200,"GRAVEL") | C6: m2 | D6: Impervious total includes GRAVEL weighted by Inputs!B54 policy factor.
A7: Total impervious area AFTER (m2) | B7: =SUMIFS(Subcatchments!$P$4:$P$200,Subcatchments!$Q$4:$Q$200,"ROOF")+SUMIFS(Subcatchments!$P$4:$P$200,Subcatchments!$Q$4:$Q$200,"PAVAGE")+SUMIFS(Subcatchments!$P$4:$P$200,Subcatchments!$Q$4:$Q$200,"TRESFOND")+Inputs!$B$54*SUMIFS(Subcatchments!$P$4:$P$200,Subcatchments!$Q$4:$Q$200,"GRAVEL") | C7: m2 | D7: Impervious total includes GRAVEL weighted by Inputs!B54 policy factor.
A8: Total grass area BEFORE (m2) | B8: =SUMIFS(Subcatchments!$E$4:$E$200,Subcatchments!$F$4:$F$200,"GRASS") | C8: m2
A9: Total grass area AFTER (m2) | B9: =SUMIFS(Subcatchments!$P$4:$P$200,Subcatchments!$Q$4:$Q$200,"GRASS") | C9: m2
A10: Total Q BEFORE (m3/s) | B10: =SUM(Subcatchments!$N$4:$N$200)*Inputs!$B$6 | C10: m3/s | D10: At east discharge reference
A11: Total Q AFTER (m3/s) | B11: =SUM(Subcatchments!$Y$4:$Y$200)*Inputs!$B$6 | C11: m3/s | D11: At east discharge reference
A12: Delta Q (AFTER-BEFORE) (m3/s) | B12: =B11-B10 | C12: m3/s
A13: Delta Q (%) | B13: =IF(B10=0,"",B12/B10) | C13: -
A16: Discharge point considered: | B16: =Inputs!$B$20
A18: Intensity method / station | B18: =Inputs!$B$23&" | "&Inputs!$B$22&" | "&Inputs!$B$24 | C18: - | D18: STATION_TABLE uses IDF_Station lookup by Tc and return period (Saint-Constant project).
A20: Allowable runoff check
A21: Q_allowable_user (m3/s) | B21: =Inputs!$B$25 | C21: m3/s | D21: Input by user/City requirement.
A22: Q_after <= Q_allowable ? | B22: =IF(B21="","INPUT REQUIRED",IF(B11<=B21,"PASS","FAIL")) | C22: - | D22: Compares total post-development flow to user allowable limit.
A23: Margin (Q_allowable - Q_after) | B23: =IF(B21="","",B21-B11) | C23: m3/s | D23: Positive = capacity remaining; negative = exceedance.
A25: Area takeoff check (labels from marked plan)
A26: A=12712 m2 included? | B26: =IF(COUNTIF(Subcatchments!$C$4:$C$200,12712)>0,"YES","NO")
A27: A=2961 m2 included? | B27: =IF(COUNTIF(Subcatchments!$C$4:$C$200,2961)>0,"YES","NO")
A28: A=2882 m2 included? | B28: =IF(COUNTIF(Subcatchments!$C$4:$C$200,2882)>0,"YES","NO")
A29: A=1869.7 m2 included? | B29: =IF(COUNTIF(Subcatchments!$C$4:$C$200,1869.7)>0,"YES","NO")
A30: A=398 m2 included? | B30: =IF(COUNTIF(Subcatchments!$C$4:$C$200,398)>0,"YES","NO")
A32: SC-07 + SC-08 mixed-surface sensitivity (Q_after)
A33: LOW (imp frac = Inputs!B34) | B33: =Inputs!$B$6*(IF(OR(Subcatchments!$P$9="",Subcatchments!$X$9=""),0,2.78E-7*(Inputs!$B$34*Inputs!$B$14+(1-Inputs!$B$34)*Inputs!$B$16)*Subcatchments!$P$9*Subcatchments!$X$9)+IF(OR(Subcatchments!$P$10="",Subcatchments!$X$10=""),0,2.78E-7*(Inputs!$B$34*Inputs!$B$14+(1-Inputs!$B$34)*Inputs!$B$16)*Subcatchments!$P$10*Subcatchments!$X$10)) | C33: m3/s | D33: After-flow contribution of SC-07+SC-08 under LOW impervious assumption.
A34: BASE (imp frac = Inputs!B35) | B34: =Inputs!$B$6*(IF(OR(Subcatchments!$P$9="",Subcatchments!$X$9=""),0,2.78E-7*(Inputs!$B$35*Inputs!$B$14+(1-Inputs!$B$35)*Inputs!$B$16)*Subcatchments!$P$9*Subcatchments!$X$9)+IF(OR(Subcatchments!$P$10="",Subcatchments!$X$10=""),0,2.78E-7*(Inputs!$B$35*Inputs!$B$14+(1-Inputs!$B$35)*Inputs!$B$16)*Subcatchments!$P$10*Subcatchments!$X$10)) | C34: m3/s | D34: After-flow contribution of SC-07+SC-08 under BASE impervious assumption.
A35: HIGH (imp frac = Inputs!B36) | B35: =Inputs!$B$6*(IF(OR(Subcatchments!$P$9="",Subcatchments!$X$9=""),0,2.78E-7*(Inputs!$B$36*Inputs!$B$14+(1-Inputs!$B$36)*Inputs!$B$16)*Subcatchments!$P$9*Subcatchments!$X$9)+IF(OR(Subcatchments!$P$10="",Subcatchments!$X$10=""),0,2.78E-7*(Inputs!$B$36*Inputs!$B$14+(1-Inputs!$B$36)*Inputs!$B$16)*Subcatchments!$P$10*Subcatchments!$X$10)) | C35: m3/s | D35: After-flow contribution of SC-07+SC-08 under HIGH impervious assumption.
A36: ACTIVE scenario value (from mode) | B36: =(Subcatchments!$Y$9+Subcatchments!$Y$10)*Inputs!$B$6 | C36: m3/s | D36: Current SC-07+SC-08 after-flow using selected mode in Inputs!B33.
A38: Collector trunk explicit total length (m) | B38: =Inputs!$B$49 | C38: m | D38: From explicit east+bottom+west inputs.
A39: Collector trunk implied length from note (m) | B39: =Inputs!$B$45 | C39: m | D39: Computed from 0.983 m / 0.5%.
A40: Length mismatch explicit-implied (m) | B40: =Inputs!$B$50 | C40: m | D40: Target near 0 after field chainage calibration.

Sheet IDF_Station
A1: IDF station table used by model (Saint-Constant project; current values from McTavish table)
A2: Duration_min | B2: 2-Year | C2: 5-Year | D2: 10-Year | E2: 25-Year | F2: 50-Year | G2: 100-Year
A3: 5 | B3: 91.2 | C3: 120 | D3: 138 | E3: 162 | F3: 178.8 | G3: 196.8
A4: 10 | B4: 69.6 | C4: 91.2 | D4: 105.6 | E4: 123.6 | F4: 136.8 | G4: 150
A5: 15 | B5: 55.6 | C5: 74 | D5: 86.4 | E5: 102 | F5: 113.2 | G5: 124.8
A6: 30 | B6: 39.6 | C6: 53.6 | D6: 62.8 | E6: 74.6 | F6: 83.4 | G6: 92
A7: 60 | B7: 24.6 | C7: 36.3 | D7: 44.1 | E7: 53.9 | F7: 61.2 | G7: 68.4
A8: 120 | B8: 13.7 | C8: 20.3 | D8: 24.7 | E8: 30.3 | F8: 34.4 | G8: 38.5
A9: 360 | B9: 6 | C9: 8.1 | D9: 9.6 | E9: 11.4 | F9: 12.8 | G9: 14.2
A10: 720 | B10: 3.6 | C10: 4.8 | D10: 5.5 | E10: 6.5 | F10: 7.2 | G10: 7.9
A11: 1440 | B11: 2.1 | C11: 2.7 | D11: 3.1 | E11: 3.6 | F11: 3.9 | G11: 4.3

Sheet TrenchProfile_3Lines
A1: THREE-LINE TRENCH/DITCH PROFILE INPUT
A3: Path_ID | B3: Station_ID | C3: Distance_from_start_m | D3: Left_edge_elev_m | E3: Center_invert_elev_m | F3: Right_edge_elev_m | G3: Cross_slope_left_to_center_% | H3: Cross_slope_right_to_center_% | I3: Notes
A4: P-FIELD-3LINE | B4: S0 | C4: 0 | G4: =IF(OR(D4="",E4=""),"",IF(C4="","",100*(D4-E4)/MAX(0.001,1))) | H4: =IF(OR(F4="",E4=""),"",IF(C4="","",100*(F4-E4)/MAX(0.001,1))) | I4: Start point
A5: P-FIELD-3LINE | B5: S1 | G5: =IF(OR(D5="",E5=""),"",IF(C5="","",100*(D5-E5)/MAX(0.001,1))) | H5: =IF(OR(F5="",E5=""),"",IF(C5="","",100*(F5-E5)/MAX(0.001,1))) | I5: Intermediate point
A6: P-FIELD-3LINE | B6: S2 | G6: =IF(OR(D6="",E6=""),"",IF(C6="","",100*(D6-E6)/MAX(0.001,1))) | H6: =IF(OR(F6="",E6=""),"",IF(C6="","",100*(F6-E6)/MAX(0.001,1))) | I6: Near outlet point

Sheet Segment_Legend
A1: Segment_ID | B1: Path_ID | C1: From_node | D1: To_node | E1: Plan location intent | F1: Length source
A2: A01-EAST-STRIP | B2: P-EAST-STRIP | C2: Field east strip inflow | D2: J-EAST-IN | E2: SE/right-field edge trench line | F2: Profile/plan geometry (editable in FlowPaths G7)
A3: A02-EAST-OUT | B3: P-EAST-OUT | C3: J-EAST-IN | D3: EAST-OUT | E3: Short east outlet collector | F3: Profile/plan geometry (editable in FlowPaths G8)
A4: A03-FIELD-3LINE | B4: P-FIELD-3LINE | C4: Field interior (3-line drain) | D4: EAST-IN | E4: Center/middle dimensioned segment ending at EAST-IN label. | F4: Inputs!B47 = 34.509 m (user dimension tool).
A5: A01T-EAST-TRUNK | B5: P-EAST-STRIP | C5: EAST-IN | D5: EAST-OUT | E5: East-side collector run for P-EAST-STRIP path. | F5: Inputs!B46 = 66.398 m (user dimension tool).
A6: A03T-EAST-TRUNK | B6: P-FIELD-3LINE | C6: EAST-IN | D6: EAST-OUT | E6: East-side collector run from EAST-IN to EAST-OUT. | F6: Inputs!B46 = 66.398 m (user dimension tool).
A7: A04T-WEST-TRUNK | B7: P-WEST-PAVE | C7: West tie-in | D7: J-TRUNK-WEST | E7: Future collector west side | F7: Inputs!B48 (67.025 m from dimension tool)
A8: A04T-CENTER-SW | B8: P-WEST-PAVE | C8: J-TRUNK-WEST | D8: J-TRUNK-BOTTOM | E8: Center-to-south trunk reach | F8: Inputs!B47 (34.509 m from dimension tool)
A9: A04T-EAST-TRUNK2 | B9: P-WEST-PAVE | C9: J-TRUNK-BOTTOM | D9: EAST-OUT | E9: East approach to outlet | F9: Inputs!B46 (66.398 m from dimension tool)
A10: A02T-EAST-TRUNK | B10: P-EAST-OUT | C10: Along east collector | D10: EAST-OUT | E10: Optional extra east trunk for P-EAST-OUT | F10: Inputs!B46 (66.398 m from dimension tool)
