Workbook

Sheet Guide_adaptation
A1: Adaptation méthode simple Saint-Hubert ← données Reseau_pluvial_dimensionnement_v1
A3: Fichiers sources
A4: Méthode simple: Dimensionnement réseau pluvial- Saint Hubert - bassin 5 à 60 minutes.xlsx
A5: Données projet: Reseau_pluvial_dimensionnement_v1.xlsx
A7: Onglets
A8: Temps de concentration: aires locales (ha), C, L/n/s overland → temps d’entrée
A9: Calcul_reseau: tronçons amont→aval, débit rationnel cumulatif, diamètre, capacité, radiers/couverture
A11: Correspondance topologique (fichier Olivier TECH. MODIF)
A12: L06: P09 → P06 | L=17.458 m
A13: L07: P07 → P06 | L=12.477 m
A14: L08: P06 → P04 | L=9.579 m
A15: L09: P04 → P01 | L=13.317 m
... A23: H/I: à J01, P02→J01 ne cumule pas le réseau amont; J01→RP03 = H(P01→J01)+H(P02→J01)+DA.

Sheet Calcul_reseau
A1: Calculs relatifs à un réseau d'égout pluvial
F2: Projet : | H2: Réseau pluvial – projet (fichier Olivier TECH. MODIF) | M2: IDF projet (Inputs v1) – courbe 1/10 ans A=508.07 B=2.9 C=0.644 | R2: Période de retour: | S2: =1/25 | T2: ans
F3: No dossier : | H3: Adapté méthode simple Saint-Hubert | Q3: I = A/(t+B)C
G4: Date : | H4: 2026-07-31 | M4: Réseau local → exutoire P12 / PUB | Q4: Récurence | R4: A | S4: B | T4: C
Q5: 1/2 ans | R5: 603.83 | S5: 6.2 | T5: 0.794
Q6: 1/5 ans | R6: 509.21 | S6: 3.7 | T6: 0.683
Q7: 1/10 ans | R7: 508.07 | S7: 2.9 | T7: 0.644
Q8: 1/25 ans | R8: 515.88 | S8: 2.1 | T8: 0.607
Q9: 1/50 ans | R9: 548.6 | S9: 1.9 | T9: 0.595
Q10: 1/100 ans | R10: 569.21 | S10: 1.6 | T10: 0.579
R11: Coefficient de Manning: | S11: 0.013
A12: Calcul du débit | M12: Calcul des caractéristiques de la conduite | S12: Niveau du sol | U12: Hauteur de radier | W12: Couverture | Y12: Volume retenu dans les conduites
A13: Tronçon de conduite | D13: Temps de concentration | E13: Accroissement (DA) de l'aire à desservir | F13: Coefficient de ruissellement de DA | G13: Aire imperméables de DA | H13: Aire cumulative | I13: Aire imperméable cumulative | J13: Coefficient de ruissellement de A | K13: Intensité de précipitation | L13: Débit maximal = 2,75 x 10-3 AIR | M13: Pente de la conduite | N13: Diamètre nominal de la conduite | O13: Vitesse d'écoulement dans la conduite coulant à plein débit | P13: Longueur de la conduite | Q13: Temps d'écoulement dans la conduite (L/v) | R13: Capacité hydraulique de la conduite coulant à plein débit | S13: Amont | T13: Aval | U13: Amont | V13: Aval | W13: Amont | X13: Aval | Y13: Conduites | Z13: Diamètre de la bouche d'égouts | AA13: Volume de la bouche d'égouts | AB13: Vérification de la capacité de la conduite Qp > Qmax | AC13: Pipe_ID (réf.)
D14: tc | E14: DA | F14: RT | G14: DART | H14: A | I14: AR | J14: R | K14: I | L14: Qmax | M14: s | N14: dnom | O14: v | P14: L | Q14: tf | R14: Qp | AC14: ID
D15: (min) | E15: (ha) | G15: (ha) | H15: (ha) | I15: (ha) | K15: (mm/h) | L15: (m3/s) | M15: (m/m) | N15: (mm) | O15: (m/s) | P15: (m) | Q15: (min) | R15: (m3/s) | S15: (m) | T15: (m) | U15: (m) | V15: (m) | W15: (m) | X15: (m) | Y15: (m3) | Z15: (m) | AA15: (m3) | AC15: -
A17: Tronçons (amont → aval) — modif Olivier: P01→J01, P02→J01 (1.4 m), J01→RP03
A18: P09 | B18: @ | C18: P06 | D18: ='Temps de concentration'!B7 | E18: 0.0447 | F18: 0.425 | G18: =E18*F18 | H18: =E18 | I18: =G18 | J18: =IF(H18=0,0,I18/H18) | K18: =IF($S$2=0.5,$R$5/((D18+$S$5)^$T$5),IF($S$2=0.2,$R$6/((D18+$S$6)^$T$6),IF($S$2=0.1,$R$7/((D18+$S$7)^$T$7),IF($S$2=0.04,$R$8/((D18+$S$8)^$T$8),IF($S$2=0.02,$R$9/((D18+$S$9)^$T$9),$R$10/((D18+$S$10)^$T$10)))))) | L18: =0.00275*H18*J18*K18 | M18: 0.0306 | N18: 200 | O18: =IF(OR(N18<=0,M18<=0),0,((N18/4000)^(2/3)*SQRT(M18))/$S$11) | P18: 17.458 | Q18: =IF(O18=0,0,P18/(O18*60)) | R18: =O18*(PI()*(N18/1000)^2/4) | U18: =V18+(M18*P18) | V18: =U19 | Y18: =P18*PI()*(N18/1000)^2/4 | AB18: =IF(R18>L18,"OK","AUGMENTER D") | AC18: L06_P09_P06
A19: P07 | B19: @ | C19: P06 | D19: =MAX('Temps de concentration'!C7, D18+Q18) | E19: 0.0442 | F19: 0.765 | G19: =E19*F19 | H19: =H18+E19 | I19: =I18+G19 | J19: =IF(H19=0,0,I19/H19) | K19: =IF($S$2=0.5,$R$5/((D19+$S$5)^$T$5),IF($S$2=0.2,$R$6/((D19+$S$6)^$T$6),IF($S$2=0.1,$R$7/((D19+$S$7)^$T$7),IF($S$2=0.04,$R$8/((D19+$S$8)^$T$8),IF($S$2=0.02,$R$9/((D19+$S$9)^$T$9),$R$10/((D19+$S$10)^$T$10)))))) | L19: =0.00275*H19*J19*K19 | M19: 0.01 | N19: 200 | O19: =IF(OR(N19<=0,M19<=0),0,((N19/4000)^(2/3)*SQRT(M19))/$S$11) | P19: 12.477 | Q19: =IF(O19=0,0,P19/(O19*60)) | R19: =O19*(PI()*(N19/1000)^2/4) | U19: =V19+(M19*P19) | V19: =U20 | Y19: =P19*PI()*(N19/1000)^2/4 | AB19: =IF(R19>L19,"OK","AUGMENTER D") | AC19: L07_P07_P06
A20: P06 | B20: @ | C20: P04 | D20: =MAX('Temps de concentration'!D7, D19+Q19) | E20: 0.0148 | F20: 0.684 | G20: =E20*F20 | H20: =H19+E20 | I20: =I19+G20 | J20: =IF(H20=0,0,I20/H20) | K20: =IF($S$2=0.5,$R$5/((D20+$S$5)^$T$5),IF($S$2=0.2,$R$6/((D20+$S$6)^$T$6),IF($S$2=0.1,$R$7/((D20+$S$7)^$T$7),IF($S$2=0.04,$R$8/((D20+$S$8)^$T$8),IF($S$2=0.02,$R$9/((D20+$S$9)^$T$9),$R$10/((D20+$S$10)^$T$10)))))) | L20: =0.00275*H20*J20*K20 | M20: 0.01 | N20: 200 | O20: =IF(OR(N20<=0,M20<=0),0,((N20/4000)^(2/3)*SQRT(M20))/$S$11) | P20: 9.579 | Q20: =IF(O20=0,0,P20/(O20*60)) | R20: =O20*(PI()*(N20/1000)^2/4) | U20: =V20+(M20*P20) | V20: =U21 | Y20: =P20*PI()*(N20/1000)^2/4 | AB20: =IF(R20>L20,"OK","AUGMENTER D") | AC20: L08_P06_P04
A21: P04 | B21: @ | C21: P01 | D21: =MAX('Temps de concentration'!E7, D20+Q20) | E21: 0.0095 | F21: 0.547 | G21: =E21*F21 | H21: =H20+E21 | I21: =I20+G21 | J21: =IF(H21=0,0,I21/H21) | K21: =IF($S$2=0.5,$R$5/((D21+$S$5)^$T$5),IF($S$2=0.2,$R$6/((D21+$S$6)^$T$6),IF($S$2=0.1,$R$7/((D21+$S$7)^$T$7),IF($S$2=0.04,$R$8/((D21+$S$8)^$T$8),IF($S$2=0.02,$R$9/((D21+$S$9)^$T$9),$R$10/((D21+$S$10)^$T$10)))))) | L21: =0.00275*H21*J21*K21 | M21: 0.01 | N21: 250 | O21: =IF(OR(N21<=0,M21<=0),0,((N21/4000)^(2/3)*SQRT(M21))/$S$11) | P21: 13.317 | Q21: =IF(O21=0,0,P21/(O21*60)) | R21: =O21*(PI()*(N21/1000)^2/4) | U21: =V21+(M21*P21) | V21: =U22 | Y21: =P21*PI()*(N21/1000)^2/4 | AB21: =IF(R21>L21,"OK","AUGMENTER D") | AC21: L09_P04_P01
A22: P01 | B22: @ | C22: J01 | D22: =MAX('Temps de concentration'!F7, D21+Q21) | E22: 0.0257 | F22: 0.633 | G22: =E22*F22 | H22: =H21+E22 | I22: =I21+G22 | J22: =IF(H22=0,0,I22/H22) | K22: =IF($S$2=0.5,$R$5/((D22+$S$5)^$T$5),IF($S$2=0.2,$R$6/((D22+$S$6)^$T$6),IF($S$2=0.1,$R$7/((D22+$S$7)^$T$7),IF($S$2=0.04,$R$8/((D22+$S$8)^$T$8),IF($S$2=0.02,$R$9/((D22+$S$9)^$T$9),$R$10/((D22+$S$10)^$T$10)))))) | L22: =0.00275*H22*J22*K22 | M22: 0.01 | N22: 250 | O22: =IF(OR(N22<=0,M22<=0),0,((N22/4000)^(2/3)*SQRT(M22))/$S$11) | P22: 14.401 | Q22: =IF(O22=0,0,P22/(O22*60)) | R22: =O22*(PI()*(N22/1000)^2/4) | U22: =V22+(M22*P22) | V22: =U23 | Y22: =P22*PI()*(N22/1000)^2/4 | AB22: =IF(R22>L22,"OK","AUGMENTER D") | AC22: L01_P01_J01
A23: P02 | B23: @ | C23: J01 | D23: ='Temps de concentration'!G7 | E23: 0.0468 | F23: 0.642 | G23: =E23*F23 | H23: =E23 | I23: =G23 | J23: =IF(H23=0,0,I23/H23) | K23: =IF($S$2=0.5,$R$5/((D23+$S$5)^$T$5),IF($S$2=0.2,$R$6/((D23+$S$6)^$T$6),IF($S$2=0.1,$R$7/((D23+$S$7)^$T$7),IF($S$2=0.04,$R$8/((D23+$S$8)^$T$8),IF($S$2=0.02,$R$9/((D23+$S$9)^$T$9),$R$10/((D23+$S$10)^$T$10)))))) | L23: =0.00275*H23*J23*K23 | M23: 0.0114 | N23: 250 | O23: =IF(OR(N23<=0,M23<=0),0,((N23/4000)^(2/3)*SQRT(M23))/$S$11) | P23: 1.4 | Q23: =IF(O23=0,0,P23/(O23*60)) | R23: =O23*(PI()*(N23/1000)^2/4) | U23: =V23+(M23*P23) | V23: =U24 | Y23: =P23*PI()*(N23/1000)^2/4 | AB23: =IF(R23>L23,"OK","AUGMENTER D") | AC23: L12_P02_J01
A24: J01 | B24: @ | C24: RP03 | D24: =MAX(D22+Q22, D23+Q23) | E24: 0 | F24: 0.9 | G24: =E24*F24 | H24: =H22+H23+E24 | I24: =I22+I23+G24 | J24: =IF(H24=0,0,I24/H24) | K24: =IF($S$2=0.5,$R$5/((D24+$S$5)^$T$5),IF($S$2=0.2,$R$6/((D24+$S$6)^$T$6),IF($S$2=0.1,$R$7/((D24+$S$7)^$T$7),IF($S$2=0.04,$R$8/((D24+$S$8)^$T$8),IF($S$2=0.02,$R$9/((D24+$S$9)^$T$9),$R$10/((D24+$S$10)^$T$10)))))) | L24: =0.00275*H24*J24*K24 | M24: 0.01 | N24: 250 | O24: =IF(OR(N24<=0,M24<=0),0,((N24/4000)^(2/3)*SQRT(M24))/$S$11) | P24: 11.2 | Q24: =IF(O24=0,0,P24/(O24*60)) | R24: =O24*(PI()*(N24/1000)^2/4) | U24: =V24+(M24*P24) | V24: =U25 | Y24: =P24*PI()*(N24/1000)^2/4 | AB24: =IF(R24>L24,"OK","AUGMENTER D") | AC24: L02_J01_RP03
A25: RP03 | B25: @ | C25: P10 | D25: =D24+Q24 | E25: 0 | F25: 0.9 | G25: =E25*F25 | H25: =H24+E25 | I25: =I24+G25 | J25: =IF(H25=0,0,I25/H25) | K25: =IF($S$2=0.5,$R$5/((D25+$S$5)^$T$5),IF($S$2=0.2,$R$6/((D25+$S$6)^$T$6),IF($S$2=0.1,$R$7/((D25+$S$7)^$T$7),IF($S$2=0.04,$R$8/((D25+$S$8)^$T$8),IF($S$2=0.02,$R$9/((D25+$S$9)^$T$9),$R$10/((D25+$S$10)^$T$10)))))) | L25: =0.00275*H25*J25*K25 | M25: 0.01 | N25: 300 | O25: =IF(OR(N25<=0,M25<=0),0,((N25/4000)^(2/3)*SQRT(M25))/$S$11) | P25: 7.1 | Q25: =IF(O25=0,0,P25/(O25*60)) | R25: =O25*(PI()*(N25/1000)^2/4) | U25: =V25+(M25*P25) | V25: =U26 | Y25: =P25*PI()*(N25/1000)^2/4 | AB25: =IF(R25>L25,"OK","AUGMENTER D") | AC25: L03_RP03_P10
A26: P10 | B26: @ | C26: P11 | D26: =MAX('Temps de concentration'!H7, D25+Q25) | E26: 0.0903 | F26: 0.95 | G26: =E26*F26 | H26: =H25+E26 | I26: =I25+G26 | J26: =IF(H26=0,0,I26/H26) | K26: =IF($S$2=0.5,$R$5/((D26+$S$5)^$T$5),IF($S$2=0.2,$R$6/((D26+$S$6)^$T$6),IF($S$2=0.1,$R$7/((D26+$S$7)^$T$7),IF($S$2=0.04,$R$8/((D26+$S$8)^$T$8),IF($S$2=0.02,$R$9/((D26+$S$9)^$T$9),$R$10/((D26+$S$10)^$T$10)))))) | L26: =0.00275*H26*J26*K26 | M26: 0.0123 | N26: 300 | O26: =IF(OR(N26<=0,M26<=0),0,((N26/4000)^(2/3)*SQRT(M26))/$S$11) | P26: 14.3 | Q26: =IF(O26=0,0,P26/(O26*60)) | R26: =O26*(PI()*(N26/1000)^2/4) | U26: =V26+(M26*P26) | V26: =U27 | Y26: =P26*PI()*(N26/1000)^2/4 | AB26: =IF(R26>L26,"OK","AUGMENTER D") | AC26: L10_P10_P11
A27: P11 | B27: @ | C27: P12 | D27: =MAX('Temps de concentration'!I7, D26+Q26) | E27: 0.0498 | F27: 0.335 | G27: =E27*F27 | H27: =H26+E27 | I27: =I26+G27 | J27: =IF(H27=0,0,I27/H27) | K27: =IF($S$2=0.5,$R$5/((D27+$S$5)^$T$5),IF($S$2=0.2,$R$6/((D27+$S$6)^$T$6),IF($S$2=0.1,$R$7/((D27+$S$7)^$T$7),IF($S$2=0.04,$R$8/((D27+$S$8)^$T$8),IF($S$2=0.02,$R$9/((D27+$S$9)^$T$9),$R$10/((D27+$S$10)^$T$10)))))) | L27: =0.00275*H27*J27*K27 | M27: 0.0123 | N27: 250 | O27: =IF(OR(N27<=0,M27<=0),0,((N27/4000)^(2/3)*SQRT(M27))/$S$11) | P27: 10.9 | Q27: =IF(O27=0,0,P27/(O27*60)) | R27: =O27*(PI()*(N27/1000)^2/4) | U27: =V27+(M27*P27) | V27: =U28 | Y27: =P27*PI()*(N27/1000)^2/4 | AB27: =IF(R27>L27,"OK","AUGMENTER D") | AC27: L11_P11_P12
A28: P12 | B28: @ | C28: PUB | D28: =D27+Q27 | E28: 0 | F28: 0.9 | G28: =E28*F28 | H28: =H27+E28 | I28: =I27+G28 | J28: =IF(H28=0,0,I28/H28) | K28: =IF($S$2=0.5,$R$5/((D28+$S$5)^$T$5),IF($S$2=0.2,$R$6/((D28+$S$6)^$T$6),IF($S$2=0.1,$R$7/((D28+$S$7)^$T$7),IF($S$2=0.04,$R$8/((D28+$S$8)^$T$8),IF($S$2=0.02,$R$9/((D28+$S$9)^$T$9),$R$10/((D28+$S$10)^$T$10)))))) | L28: =0.00275*H28*J28*K28 | M28: 0.01 | N28: 300 | O28: =IF(OR(N28<=0,M28<=0),0,((N28/4000)^(2/3)*SQRT(M28))/$S$11) | P28: 12.4 | Q28: =IF(O28=0,0,P28/(O28*60)) | R28: =O28*(PI()*(N28/1000)^2/4) | U28: =V28+(M28*P28) | V28: 15.305 | Y28: =P28*PI()*(N28/1000)^2/4 | AB28: =IF(R28>L28,"OK","AUGMENTER D") | AC28: L12_P12_PUB
A29: INSTRUCTIONS / HYPOTHÈSES
A30: Jaune = saisie; Vert = calculé automatiquement (Station Saint-Hubert).
A31: Source données: Reseau_pluvial_dimensionnement_v1.xlsx (CB_plan aires, Conduites longueurs/topologie, Noeuds élévations, Inputs IDF/n/pente).
A32: Qmax = 0.00275 × A(ha) × R × I | I = A/(tc+B)^C selon période S2 (défaut 1/10 ans).
A33: v et Qp = Manning pleine section; n = S11 (0.013). Diamètre N est une suggestion — ajuster si AB = AUGMENTER D.
A34: tc: temps d’entrée (Temps de concentration) puis cumul + temps de parcours Q=L/(v*60).
A35: Radiers: calés depuis exutoire invert 15.305 m (Inputs), pente min 1%, chute regard 0.02 m.
A36: Changer la période: modifier S2. H/I à J01 corrigé: branche P02→J01 = DA locale; fusion dans J01→RP03. | Q36: Longueurs à compléter/valider par tech.
A37: Cette feuille garde la logique simple demandée; le classeur v1 reste la référence détaillée.
F81: *
F173: ,0,

Sheet Temps de concentration
K1: Préparé par: | O1: DETAIL TRIBUTAIRES PAR CONDUITE
K2: Vérifié par: | O2: Source CB_plan (v1). Résumé + détail zones. Tes notes L06/L07 plus bas sont conservées.
A4: Paramètres | B4: Sous-bassins locaux (par conduite) | O4: RESUME
B5: L06 | C5: L07 | D5: L08 | E5: L09 | F5: L01 | G5: L02 | H5: L10 | I5: L11 | O5: Pipe | P5: Zones tributaires | Q5: A total (m²) | R5: A_eff (m²) | S5: C pipe | T5: A (ha)
A6: Aire (ha) | B6: 0.044675 | C6: 0.044235 | D6: 0.01479 | E6: 0.00945 | F6: 0.02573 | G6: 0.046789 | H6: 0.0903 | I6: 0.049761 | O6: L06 | P6: J, M | Q6: 446.75 | R6: 189.75 | S6: 0.425 | T6: 0.0447
A7: temps d'entrée (min.) | B7: =((2.187*B10*B11)/(B12)^0.5)^0.467 | C7: =((2.187*C10*C11)/(C12)^0.5)^0.467 | D7: =((2.187*D10*D11)/(D12)^0.5)^0.467 | E7: =((2.187*E10*E11)/(E12)^0.5)^0.467 | F7: =((2.187*F10*F11)/(F12)^0.5)^0.467 | G7: =((2.187*G10*G11)/(G12)^0.5)^0.467 | H7: =((2.187*H10*H11)/(H12)^0.5)^0.467 | I7: =((2.187*I10*I11)/(I12)^0.5)^0.467 | O7: L07 | P7: H, I, K, L | Q7: 442.35 | R7: 338.19 | S7: 0.765 | T7: 0.0442
A8: Coef. Ruissellement | B8: 0.425 | C8: 0.765 | D8: 0.684 | E8: 0.547 | F8: 0.633 | G8: 0.642 | H8: 0.95 | I8: 0.335 | O8: L08 | P8: G | Q8: 147.9 | R8: 101.13 | S8: 0.684 | T8: 0.0148
O9: L09 | P9: D | Q9: 94.5 | R9: 51.7 | S9: 0.547 | T9: 0.0095
A10: L overland (m) | B10: 21.1 | C10: 21 | D10: 12.2 | E10: 10 | F10: 16 | G10: 21.6 | H10: 30 | I10: 22.3 | O10: L01 | P10: A, E | Q10: 257.3 | R10: 162.8 | S10: 0.633 | T10: 0.0257
A11: n overland | B11: 0.02 | C11: 0.02 | D11: 0.02 | E11: 0.02 | F11: 0.02 | G11: 0.02 | H11: 0.02 | I11: 0.02 | O11: L02 | P11: B, C, F | Q11: 467.89 | R11: 300.33 | S11: 0.642 | T11: 0.0468
A12: s overland (m/m) | B12: 0.03057 | C12: 0.0041 | D12: 0.01458 | E12: 0.00319 | F12: 0.00746 | G12: 0.01142 | H12: 0.00628 | I12: 0.01231 | O12: L03 | P12: (aucune – transfert) | Q12: 0 | R12: 0 | T12: 0
O13: L10 | P13: N | Q13: 903 | R13: 857.85 | S13: 0.95 | T13: 0.0903
A14: Notes | O14: L11 | P14: O | Q14: 497.61 | R14: 166.52 | S14: 0.335 | T14: 0.0498
A15: Jaune = saisie (depuis Reseau_pluvial_dimensionnement_v1). Vert = calculé.
A16: L overland estimé ≈ √Aire; s = |Zamont-Zaval|/Lpipe. Ajuster si parcours réel connu. | O16: DETAIL ZONE PAR ZONE
A17: IDF utilisée dans Calcul_reseau: période 1/10 ans (A=508.07, B=2.9, C=0.644) = Inputs du projet. | O17: Pipe | P17: Zone | Q17: Roof m² | R17: Pave m² | S17: Grass m² | T17: Other m² | U17: A m² | V17: A_eff m² | W17: C zone
O18: L06 | P18: J | Q18: 0 | R18: 67.7 | S18: 81.4 | T18: 0 | U18: 149.1 | V18: 81.28 | W18: 0.545
O19: L06 | P19: M | Q19: 0 | R19: 52.4 | S19: 245.25 | T19: 0 | U19: 297.65 | V19: 108.47 | W19: 0.364
O20: L06 | P20: SUM | U20: 446.75 | V20: 189.75 | W20: 0.425
A22: Surface C used (from Inputs): | O22: L07 | P22: H | Q22: 0 | R22: 58.2 | S22: 17.6 | T22: 0 | U22: 75.8 | V22: 56.78 | W22: 0.749
A23: roof = 0.95 | O23: L07 | P23: I | Q23: 0 | R23: 120.01 | S23: 16.2 | T23: 0 | U23: 136.21 | V23: 112.06 | W23: 0.823
A24: pavement = 0.90 | O24: L07 | P24: K | Q24: 0 | R24: 48.8 | S24: 58.4 | T24: 0 | U24: 107.2 | V24: 58.52 | W24: 0.546
A25: grass = 0.25 | O25: L07 | P25: L | Q25: 0 | R25: 123.14 | S25: 0 | T25: 0 | U25: 123.14 | V25: 110.83 | W25: 0.9
A26: other = 0.60 | O26: L07 | P26: SUM | U26: 442.35 | V26: 338.19 | W26: 0.765
A27: For each zone:
A28: A = roof + pave + grass + other | O28: L08 | P28: G | Q28: 0 | R28: 98.7 | S28: 49.2 | T28: 0 | U28: 147.9 | V28: 101.13 | W28: 0.684
A29: A_eff = 0.95·roof + 0.90·pave + 0.25·grass + 0.60·other | O29: L08 | P29: SUM | U29: 147.9 | V29: 101.13 | W29: 0.684
A30: Then for the pipe:
A31: C = ΣA_eff / ΣA | O31: L09 | P31: D | Q31: 0 | R31: 43.2 | S31: 51.3 | T31: 0 | U31: 94.5 | V31: 51.7 | W31: 0.547
O32: L09 | P32: SUM | U32: 94.5 | V32: 51.7 | W32: 0.547
A33: L06_P09_P06 → A = 446.75 m² ≈ 446.8, C ≈ 0.425
A34: Zones J and M only: | O34: L01 | P34: A | Q34: 0 | R34: 61.9 | S34: 89.6 | T34: 0 | U34: 151.5 | V34: 78.11 | W34: 0.516
A35: Zone | B35: Roof | C35: Pave | D35: Grass | E35: Other | F35: A (m²) | G35: A_eff (m²) | H35: C zone | O35: L01 | P35: E | Q35: 0 | R35: 89.6 | S35: 16.2 | T35: 0 | U35: 105.8 | V35: 84.69 | W35: 0.8
A36: J | B36: 0 | C36: 67.7 | D36: 81.4 | E36: 0 | F36: 149.1 | G36: 67.7×0.9 + 81.4×0.25 = 81.28 | H36: 0.545 | O36: L01 | P36: SUM | U36: 257.3 | V36: 162.8 | W36: 0.633
A37: M | B37: 0 | C37: 52.4 | D37: 66.5+178.75=245.25 | E37: 0 | F37: 297.65 | G37: 52.4×0.9 + 245.25×0.25 = 108.4725 | H37: 0.364
A38: Sum | F38: 446.75 | G38: 189.7525 | O38: L02 | P38: B | Q38: 0 | R38: 79.8 | S38: 43 | T38: 0 | U38: 122.8 | V38: 82.57 | W38: 0.672
A39: C = 189.7525 / 446.75 = 0.4247 ≈ 0.425 | O39: L02 | P39: C | Q39: 0 | R39: 87.8 | S39: 123.9 | T39: 0 | U39: 211.7 | V39: 110 | W39: 0.52
O40: L02 | P40: F | Q40: 0 | R40: 114.49 | S40: 18.9 | T40: 0 | U40: 133.39 | V40: 107.77 | W40: 0.808
O41: L02 | P41: SUM | U41: 467.89 | V41: 300.33 | W41: 0.642
A42: L07_P07_P06 → A = 442.35 m², C ≈ 0.765
...
