Workbook

Sheet Guide_adaptation
A1: ADAPTATION méthode simple Olivier ← données Reseau_tresfond (plan 1796-C-03)
A3: Ce fichier = structure Calcul_reseau / Temps / Radiers (Olivier), remplie avec le réseau TRESFOND simplifié.
A4: Source données: Reseau_tresfond_hybride_retention_07_08.xlsx (Zones + Elements).
A6: Réseau
A7: 1) OUEST: gazon+pavé (105.8 m², C≈0.54) → CB P-03 → RP-02 → RS-EX
A8: 2) EST: arbres 164.7 m² C=0.25 → P-07; sud-est 70.6 m² C≈0.75 → P-07 → RP-02
A9: 3) MEC: toit+tréfond+strip 1405.6 m² C≈0.93 → BASSIN-RET
A11: Correspondance Element_ID hybride (AC):
A12: EST_ARBRES_VERS_P07 | EST_P07_RP02 | OUEST_P03_RP02 | RP02_VERS_RUE | MEC_TOIT_TRESFOND_BASSIN
A14: Le classeur hybride reste utile pour le détail zone-par-zone; celui-ci sert au dimensionnement type Saint-Hubert.

Sheet Radiers
A1: RADIERS DYNAMIQUES — changez L ou s dans Calcul_reseau; les inverts se mettent à jour | J1: Note: correction zone N (L10→LT1) sans effet sur radiers.
A2: Formules Excel (pas de recalcul manuel). Aux confluences: radier du noeud = MIN des propositions des branches.
A3: Dynamique: Inv amont = Inv aval + MAX(s,smin)·L + chute. Aux confluences le radier du noeud suit l’AVAL (drainable). Colonne D = MIN des arrivées des branches (couverture) pour choisir/contrôler.
A4: Radiers pour réseau TRESFOND simplifié (P-03, P-07, RP-02, RS-EX, MEC, BASSIN).
A5: PARAMÈTRES (jaune = modifiable)
A6: Invert PUB / exutoire (m) | B6: 21.5 | D6: L et s lus dans Calcul_reseau P/M (lignes 18-22).
A7: Chute de regard (m) | B7: 0.02 | D7: Changez M18=0.01, M28=0.015, M29=0.015 déjà appliqué; vous pouvez les modifier encore.
A8: Pente min radier smin (m/m) | B8: 0.01
A9: Couverture mini pour proposition amont (m) | B9: 1.8
A11: TABLE DES CONDUITES (liée à Calcul_reseau)
A12: Row | B12: Pipe_ID | C12: De | D12: Vers | E12: L (m) | F12: s design | G12: s utilisée | H12: D (m) | I12: Sol amont | J12: Proposition amont (couverture)
A13: 18 | B13: =Calcul_reseau!AC18 | C13: =Calcul_reseau!A18 | D13: =Calcul_reseau!C18 | E13: =Calcul_reseau!P18 | F13: =Calcul_reseau!M18 | G13: =MAX(F13,$B$8) | H13: =IF(Calcul_reseau!N18="",0,Calcul_reseau!N18/1000) | I13: =Calcul_reseau!S18 | J13: =IF(OR(I13="",H13=""),"",I13-$B$9-H13)
A14: 19 | B14: =Calcul_reseau!AC19 | C14: =Calcul_reseau!A19 | D14: =Calcul_reseau!C19 | E14: =Calcul_reseau!P19 | F14: =Calcul_reseau!M19 | G14: =MAX(F14,$B$8) | H14: =IF(Calcul_reseau!N19="",0,Calcul_reseau!N19/1000) | I14: =Calcul_reseau!S19 | J14: =IF(OR(I14="",H14=""),"",I14-$B$9-H14)
A15: 20 | B15: =Calcul_reseau!AC20 | C15: =Calcul_reseau!A20 | D15: =Calcul_reseau!C20 | E15: =Calcul_reseau!P20 | F15: =Calcul_reseau!M20 | G15: =MAX(F15,$B$8) | H15: =IF(Calcul_reseau!N20="",0,Calcul_reseau!N20/1000) | I15: =Calcul_reseau!S20 | J15: =IF(OR(I15="",H15=""),"",I15-$B$9-H15)
A16: 21 | B16: =Calcul_reseau!AC21 | C16: =Calcul_reseau!A21 | D16: =Calcul_reseau!C21 | E16: =Calcul_reseau!P21 | F16: =Calcul_reseau!M21 | G16: =MAX(F16,$B$8) | H16: =IF(Calcul_reseau!N21="",0,Calcul_reseau!N21/1000) | I16: =Calcul_reseau!S21 | J16: =IF(OR(I16="",H16=""),"",I16-$B$9-H16)
A17: 22 | B17: =Calcul_reseau!AC22 | C17: =Calcul_reseau!A22 | D17: =Calcul_reseau!C22 | E17: =Calcul_reseau!P22 | F17: =Calcul_reseau!M22 | G17: =MAX(F17,$B$8) | H17: =IF(Calcul_reseau!N22="",0,Calcul_reseau!N22/1000) | I17: =Calcul_reseau!S22 | J17: =IF(OR(I17="",H17=""),"",I17-$B$9-H17)
J18: =IF(OR(I18="",H18=0),"",I18-$B$9-H18)
J19: =IF(OR(I19="",H19=0),"",I19-$B$9-H19)
J20: =IF(OR(I20="",H20=0),"",I20-$B$9-H20)
J21: =IF(OR(I21="",H21=0),"",I21-$B$9-H21)
J22: =IF(OR(I22="",H22=0),"",I22-$B$9-H22)
J23: =IF(OR(I23="",H23=0),"",I23-$B$9-H23)
J24: =IF(OR(I24="",H24=0),"",I24-$B$9-H24)
A26: INVERTS DES NOEUDS (formules dynamiques)
A27: Noeud.final = proposition AVAL (pour garder l’écoulement vers PUB). Si MIN branches (col D) < aval (col C) → alerte couverture.
A28: Noeud | B28: Invert final (m) | C28: Depuis aval (m) | D28: Arrivée branche(s) | E28: Règle | F28: Sol (m) | G28: Couverture (m) | H28: MIN invert amont des branches
A29: RS-EX | B29: =C29 | C29: =$B$6 | D29: — | E29: Exutoire fixe | F29: 22.7 | G29: =IF(OR(F29="",B29=""),"",F29-B29)
A30: RP-02 | B30: =C30 | C30: =$B$6+G16*E16+$B$7 | D30: =MIN(IFERROR(J14-G14*E14,1E99),IFERROR(J15-G15*E15,1E99)) | E30: CONFLUENCE P-07 & P-03 | F30: 22.82 | G30: =IF(OR(F30="",B30=""),"",F30-B30) | H30: =MIN(B31,B33)
A31: P-07 | B31: =C31 | C31: =B30+G14*E14+$B$7 | D31: =IF(J14="","",J14) | E31: Branche est | F31: 23.5 | G31: =IF(OR(F31="",B31=""),"",F31-B31)
A32: BANDE_ARBRES | B32: =C32 | C32: =B31+G13*E13+$B$7 | D32: =IF(J13="","",J13) | E32: Amont arbres | F32: 23.9 | G32: =IF(OR(F32="",B32=""),"",F32-B32)
A33: P-03 | B33: =C33 | C33: =B30+G15*E15+$B$7 | D33: =IF(J15="","",J15) | E33: Branche ouest | F33: 23.46 | G33: =IF(OR(F33="",B33=""),"",F33-B33)
A34: BASSIN-RET | B34: =C34 | C34: 21.62 | D34: — | E34: Radier bassin (plan) | F34: 23.56 | G34: =IF(OR(F34="",B34=""),"",F34-B34)
A35: MEC-OUT | B35: =C35 | C35: =B34+G17*E17+$B$7 | D35: =IF(J17="","",J17) | E35: Mécanique amont | F35: 23.63 | G35: =IF(OR(F35="",B35=""),"",F35-B35)
A43: Alerte drainage
A44: =IF(AND(ISNUMBER(H30),ISNUMBER(C30),H30<C30),"ALERTE: branche impose radier < aval à RP-02","OK confluence RP-02")
A46: U/V PAR CONDUITE (dynamique) — Calcul_reseau lit ces valeurs
A47: Pipe_ID | B47: De | C47: Vers | D47: V aval = Inv(vers) | E47: U amont = V + s_util·L + chute | F47: s réelle (U−V)/L
A48: =B13 | B48: =C13 | C48: =D13 | D48: =VLOOKUP(D13,$A$29:$B$35,2,FALSE) | E48: =VLOOKUP(C13,$A$29:$B$35,2,FALSE) | F48: =IF(E13=0,"",(E48-D48)/E13)
A49: =B14 | B49: =C14 | C49: =D14 | D49: =VLOOKUP(D14,$A$29:$B$35,2,FALSE) | E49: =VLOOKUP(C14,$A$29:$B$35,2,FALSE) | F49: =IF(E14=0,"",(E49-D49)/E14)
A50: =B15 | B50: =C15 | C50: =D15 | D50: =VLOOKUP(D15,$A$29:$B$35,2,FALSE) | E50: =VLOOKUP(C15,$A$29:$B$35,2,FALSE) | F50: =IF(E15=0,"",(E50-D50)/E15)
...

Sheet Calcul_reseau
A1: Calculs relatifs à un réseau d'égout pluvial
F2: Projet : | H2: Tréfond / Bâtiment 39 logements — méthode simple Olivier + données Reseau_tresfond | M2: IDF projet (Inputs v1) – courbe 1/10 ans A=508.07 B=2.9 C=0.644 | R2: Période de retour: | S2: =1/25 | T2: ans
F3: No dossier : | H3: Adapté méthode simple Saint-Hubert | Q3: I = A/(t+B)C
G4: Date : | H4: 2026-07-31 | M4: P-03→RP-02→RS-EX | P-07→RP-02 | MEC→BASSIN (plan 1796-C-03) | Q4: Récurence | R4: A | S4: B | T4: C
Q5: 1/2 ans | R5: 603.83 | S5: 6.2 | T5: 0.794
Q6: 1/5 ans | R6: 509.21 | S6: 3.7 | T6: 0.683
Q7: 1/10 ans | R7: 508.07 | S7: 2.9 | T7: 0.644
Q8: 1/25 ans | R8: 515.88 | S8: 2.1 | T8: 0.607
Q9: 1/50 ans | R9: 548.6 | S9: 1.9 | T9: 0.595
Q10: 1/100 ans | R10: 569.21 | S10: 1.6 | T10: 0.579
R11: Coefficient de Manning: | S11: 0.013
A12: Calcul du débit | M12: Calcul des caractéristiques de la conduite | S12: Niveau du sol | U12: Hauteur de radier | W12: Couverture | Y12: Volume retenu dans les conduites
A13: Tronçon de conduite | D13: Temps de concentration | E13: Accroissement (DA) de l'aire à desservir | F13: Coefficient de ruissellement de DA | G13: Aire imperméables de DA | H13: Aire cumulative | I13: Aire imperméable cumulative | J13: Coefficient de ruissellement de A | K13: Intensité de précipitation | L13: Débit maximal = 2,75 x 10-3 AIR | M13: Pente de la conduite | N13: Diamètre nominal de la conduite | O13: Vitesse d'écoulement dans la conduite coulant à plein débit | P13: Longueur de la conduite | Q13: Temps d'écoulement dans la conduite (L/v) | R13: Capacité hydraulique de la conduite coulant à plein débit | S13: Amont | T13: Aval | U13: Amont | V13: Aval | W13: Amont | X13: Aval | Y13: Conduites | Z13: Diamètre de la bouche d'égouts | AA13: Volume de la bouche d'égouts | AB13: Vérification de la capacité de la conduite Qp > Qmax | AC13: Pipe_ID (réf.)
D14: tc | E14: DA | F14: RT | G14: DART | H14: A | I14: AR | J14: R | K14: I | L14: Qmax | M14: s | N14: dnom | O14: v | P14: L | Q14: tf | R14: Qp | AC14: ID
D15: (min) | E15: (ha) | G15: (ha) | H15: (ha) | I15: (ha) | K15: (mm/h) | L15: (m3/s) | M15: (m/m) | N15: (mm) | O15: (m/s) | P15: (m) | Q15: (min) | R15: (m3/s) | S15: (m) | T15: (m) | U15: (m) | V15: (m) | W15: (m) | X15: (m) | Y15: (m3) | Z15: (m) | AA15: (m3) | AC15: -
A17: Tronçons TRESFOND (données Reseau_tresfond_hybride). DA/C composés depuis Zones_tributaires. Radiers dynamiques.
A18: BANDE_ARBRES | B18: @ | C18: P-07 | D18: ='Temps de concentration'!C7 | E18: 0.0165 | F18: 0.25 | G18: =E18*F18 | H18: =E18 | I18: =G18 | J18: =IF(H18=0,0,I18/H18) | K18: =IF($S$2=0.5,$R$5/((D18+$S$5)^$T$5),IF($S$2=0.2,$R$6/((D18+$S$6)^$T$6),IF($S$2=0.1,$R$7/((D18+$S$7)^$T$7),IF($S$2=0.04,$R$8/((D18+$S$8)^$T$8),IF($S$2=0.02,$R$9/((D18+$S$9)^$T$9),$R$10/((D18+$S$10)^$T$10)))))) | L18: =0.00275*H18*J18*K18 | M18: 0.01 | N18: 200 | O18: =IF(OR(N18<=0,M18<=0),0,((N18/4000)^(2/3)*SQRT(M18))/$S$11) | P18: 20 | Q18: =IF(O18=0,0,P18/(O18*60)) | R18: =O18*(PI()*(N18/1000)^2/4) | S18: 23.9 | T18: 23.5 | U18: =Radiers!E48 | V18: =Radiers!D48 | W18: =IF(OR(S18="",U18=""),"",S18-U18-N18/1000) | X18: =IF(OR(T18="",V18=""),"",T18-V18-N18/1000) | AC18: EST_ARBRES_VERS_P07
A19: P-07 | B19: @ | C19: RP-02 | D19: =MAX('Temps de concentration'!D7, D18+Q18) | E19: 0.0071 | F19: 0.747 | G19: =E19*F19 | H19: =H18+E19 | I19: =I18+G19 | J19: =IF(H19=0,0,I19/H19) | K19: =IF($S$2=0.5,$R$5/((D19+$S$5)^$T$5),IF($S$2=0.2,$R$6/((D19+$S$6)^$T$6),IF($S$2=0.1,$R$7/((D19+$S$7)^$T$7),IF($S$2=0.04,$R$8/((D19+$S$8)^$T$8),IF($S$2=0.02,$R$9/((D19+$S$9)^$T$9),$R$10/((D19+$S$10)^$T$10)))))) | L19: =0.00275*H19*J19*K19 | M19: 0.0025 | N19: 300 | O19: =IF(OR(N19<=0,M19<=0),0,((N19/4000)^(2/3)*SQRT(M19))/$S$11) | P19: 8.8 | Q19: =IF(O19=0,0,P19/(O19*60)) | R19: =O19*(PI()*(N19/1000)^2/4) | S19: 23.5 | T19: 22.82 | U19: =Radiers!E49 | V19: =Radiers!D49 | W19: =IF(OR(S19="",U19=""),"",S19-U19-N19/1000) | X19: =IF(OR(T19="",V19=""),"",T19-V19-N19/1000) | AC19: EST_P07_RP02
A20: P-03 | B20: @ | C20: RP-02 | D20: ='Temps de concentration'!B7 | E20: 0.0106 | F20: 0.542 | G20: =E20*F20 | H20: =E20 | I20: =G20 | J20: =IF(H20=0,0,I20/H20) | K20: =IF($S$2=0.5,$R$5/((D20+$S$5)^$T$5),IF($S$2=0.2,$R$6/((D20+$S$6)^$T$6),IF($S$2=0.1,$R$7/((D20+$S$7)^$T$7),IF($S$2=0.04,$R$8/((D20+$S$8)^$T$8),IF($S$2=0.02,$R$9/((D20+$S$9)^$T$9),$R$10/((D20+$S$10)^$T$10)))))) | L20: =0.00275*H20*J20*K20 | M20: 0.022 | N20: 300 | O20: =IF(OR(N20<=0,M20<=0),0,((N20/4000)^(2/3)*SQRT(M20))/$S$11) | P20: 2.3 | Q20: =IF(O20=0,0,P20/(O20*60)) | R20: =O20*(PI()*(N20/1000)^2/4) | S20: 23.46 | T20: 22.82 | U20: =Radiers!E50 | V20: =Radiers!D50 | W20: =IF(OR(S20="",U20=""),"",S20-U20-N20/1000) | X20: =IF(OR(T20="",V20=""),"",T20-V20-N20/1000) | AC20: OUEST_P03_RP02
A21: RP-02 | B21: @ | C21: RS-EX | D21: =MAX(D19+Q19, D20+Q20) | E21: 0 | F21: 0.9 | G21: =E21*F21 | H21: =H19+H20+E21 | I21: =I19+I20+G21 | J21: =IF(H21=0,0,I21/H21) | K21: =IF($S$2=0.5,$R$5/((D21+$S$5)^$T$5),IF($S$2=0.2,$R$6/((D21+$S$6)^$T$6),IF($S$2=0.1,$R$7/((D21+$S$7)^$T$7),IF($S$2=0.04,$R$8/((D21+$S$8)^$T$8),IF($S$2=0.02,$R$9/((D21+$S$9)^$T$9),$R$10/((D21+$S$10)^$T$10)))))) | L21: =0.00275*H21*J21*K21 | M21: 0.005 | N21: 300 | O21: =IF(OR(N21<=0,M21<=0),0,((N21/4000)^(2/3)*SQRT(M21))/$S$11) | P21: 16.6 | Q21: =IF(O21=0,0,P21/(O21*60)) | R21: =O21*(PI()*(N21/1000)^2/4) | S21: 22.82 | T21: 22.7 | U21: =Radiers!E51 | V21: =Radiers!D51 | W21: =IF(OR(S21="",U21=""),"",S21-U21-N21/1000) | X21: =IF(OR(T21="",V21=""),"",T21-V21-N21/1000) | AC21: RP02_VERS_RUE
A22: MEC-OUT | B22: @ | C22: BASSIN-RET | D22: ='Temps de concentration'!E7 | E22: 0.1406 | F22: 0.93 | G22: =E22*F22 | H22: =E22 | I22: =G22 | J22: =IF(H22=0,0,I22/H22) | K22: =IF($S$2=0.5,$R$5/((D22+$S$5)^$T$5),IF($S$2=0.2,$R$6/((D22+$S$6)^$T$6),IF($S$2=0.1,$R$7/((D22+$S$7)^$T$7),IF($S$2=0.04,$R$8/((D22+$S$8)^$T$8),IF($S$2=0.02,$R$9/((D22+$S$9)^$T$9),$R$10/((D22+$S$10)^$T$10)))))) | L22: =0.00275*H22*J22*K22 | M22: 0.005 | N22: 300 | O22: =IF(OR(N22<=0,M22<=0),0,((N22/4000)^(2/3)*SQRT(M22))/$S$11) | P22: 12 | Q22: =IF(O22=0,0,P22/(O22*60)) | R22: =O22*(PI()*(N22/1000)^2/4) | S22: 23.63 | T22: 23.56 | U22: =Radiers!E52 | V22: =Radiers!D52 | W22: =IF(OR(S22="",U22=""),"",S22-U22-N22/1000) | X22: =IF(OR(T22="",V22=""),"",T22-V22-N22/1000) | AC22: MEC_TOIT_TRESFOND_BASSIN
A30: INSTRUCTIONS / DONNÉES TRESFOND
A31: Jaune = saisie; Vert = calculé. Structure = méthode simple Olivier (Saint-Hubert).
A32: Données aires/C depuis Reseau_tresfond_hybride_retention_07_08.xlsx (Zones_tributaires). Ouest grass+pavage → P-03; Est arbres → P-07; Toit+tréfond → MEC→BASSIN.
A33: H/I: BANDE→P-07 locale; P-07→RP-02 cumule arbres+sud-est; P-03→RP-02 locale ouest; RP-02→RS-EX fusion est+ouest; MEC→BASSIN branche séparée.
A34: Radiers: exutoire RS-EX invert = Radiers!B6 (défaut 21.50 m — ajuster). Changez L (P) ou s (M) → U/V se recalculent.
A35: Source plan: 1796-C-03-Model.pdf. Fichier hybride détaillé conserve Inputs/Zones si besoin de ventilation fine.
A36: Radiers: calés depuis exutoire invert 15.305 m (Inputs), pente min 1%, chute regard 0.02 m.
A37: Changer la période: modifier S2. H/I à J01 corrigé: branche P02→J01 = DA locale; fusion dans J01→RP03. | Q37: Longueurs à compléter/valider par tech.
A38: Cette feuille garde la logique simple demandée; le classeur v1 reste la référence détaillée.
F82: *
F174: ,0,

Sheet Temps de concentration
K1: Préparé par: | O1: DETAIL TRIBUTAIRES PAR CONDUITE
K2: Vérifié par: | O2: Source CB_plan (v1). Résumé + détail zones. Tes notes L06/L07 plus bas sont conservées.
A4: Paramètres | B4: Sous-bassins locaux (par conduite) | O4: RESUME
B5: OUEST P-03 | C5: EST_ARBRES →P-07 | D5: EST_SUD P-07 | E5: MEC TOIT+TRÉFOND | F5: RP-02 (transfert) | O5: Pipe | P5: Zones tributaires | Q5: A total (m²) | R5: A_eff (m²) | S5: C pipe | T5: A (ha)
A6: Aire (ha) | B6: 0.0106 | C6: 0.0165 | D6: 0.0071 | E6: 0.1406 | F6: 0 | G6: 0.046789 | H6: 0 | I6: 0.049761 | K6: 0.0903 | O6: L06 | P6: J, M | Q6: 446.75 | R6: 189.75 | S6: 0.425 | T6: 0.0447
A7: temps d'entrée (min.) | B7: =((2.187*B10*B11)/(B12)^0.5)^0.467 | C7: =((2.187*C10*C11)/(C12)^0.5)^0.467 | D7: =((2.187*D10*D11)/(D12)^0.5)^0.467 | E7: =((2.187*E10*E11)/(E12)^0.5)^0.467 | F7: 0 | G7: =((2.187*G10*G11)/(G12)^0.5)^0.467 | H7: 0 | I7: =((2.187*I10*I11)/(I12)^0.5)^0.467 | K7: =((2.187*K10*K11)/(K12)^0.5)^0.467 | O7: L07 | P7: H, I, K, L | Q7: 442.35 | R7: 338.19 | S7: 0.765 | T7: 0.0442
A8: Coef. Ruissellement | B8: 0.542 | C8: 0.25 | D8: 0.747 | E8: 0.93 | F8: 0.9 | G8: 0.642 | H8: 0.9 | I8: 0.335 | K8: 0.95 | O8: L08 | P8: G | Q8: 147.9 | R8: 101.13 | S8: 0.684 | T8: 0.0148
O9: L09 | P9: D | Q9: 94.5 | R9: 51.7 | S9: 0.547 | T9: 0.0095
A10: L overland (m) | B10: 10.3 | C10: 12.8 | D10: 10 | E10: 37.5 | F10: 0 | G10: 21.6 | H10: 0 | I10: 22.3 | K10: 30 | O10: L01 | P10: A, E | Q10: 257.3 | R10: 162.8 | S10: 0.633 | T10: 0.0257
A11: n overland | B11: 0.02 | C11: 0.02 | D11: 0.02 | E11: 0.02 | F11: 0.02 | G11: 0.02 | H11: 0.02 | I11: 0.02 | K11: 0.02 | O11: L02 | P11: B, C, F | Q11: 467.89 | R11: 300.33 | S11: 0.642 | T11: 0.0468
A12: s overland (m/m) | B12: 0.015 | C12: 0.01 | D12: 0.01 | E12: 0.02 | F12: 0.01 | G12: 0.01142 | H12: 0.00628 | I12: 0.01231 | K12: 0.01 | O12: L03 | P12: (aucune – transfert) | Q12: 0 | R12: 0 | T12: 0
O13: L10 | P13: (aucune – transfert; N déplacée → LT1) | Q13: 0 | R13: 0 | T13: 0
A14: Notes | O14: L11 | P14: O (PAS de zone N) | Q14: 497.61 | R14: 166.52 | S14: 0.335 | T14: 0.0498
A15: Jaune = saisie (depuis Reseau_pluvial_dimensionnement_v1). Vert = calculé. | O15: LT1 | P15: N (toit → P11) — SEUL propriétaire | Q15: 903 | R15: 857.85 | S15: 0.95 | T15: 0.0903
A16: L overland estimé ≈ √Aire; s = |Zamont-Zaval|/Lpipe. Ajuster si parcours réel connu. | O16: DETAIL ZONE PAR ZONE
A17: IDF utilisée dans Calcul_reseau: période 1/10 ans (A=508.07, B=2.9, C=0.644) = Inputs du projet. | O17: Pipe | P17: Zone | Q17: Roof m² | R17: Pave m² | S17: Grass m² | T17: Other m² | U17: A m² | V17: A_eff m² | W17: C zone
A18: TRESFOND: aires depuis Reseau_tresfond Zones. OUEST=grass+pavage vers P-03; EST_ARBRES=Z03; EST_SUD=Z10-12; MEC=Z01+Z02+Z13. | O18: L06 | P18: J | Q18: 0 | R18: 67.7 | S18: 81.4 | T18: 0 | U18: 149.1 | V18: 81.28 | W18: 0.545
O19: L06 | P19: M | Q19: 0 | R19: 52.4 | S19: 245.25 | T19: 0 | U19: 297.65 | V19: 108.47 | W19: 0.364
O20: L06 | P20: SUM | U20: 446.75 | V20: 189.75 | W20: 0.425
A22: Surface C used (from Inputs): | O22: L07 | P22: H | Q22: 0 | R22: 58.2 | S22: 17.6 | T22: 0 | U22: 75.8 | V22: 56.78 | W22: 0.749
A23: roof = 0.95 | O23: L07 | P23: I | Q23: 0 | R23: 120.01 | S23: 16.2 | T23: 0 | U23: 136.21 | V23: 112.06 | W23: 0.823
A24: pavement = 0.90 | O24: L07 | P24: K | Q24: 0 | R24: 48.8 | S24: 58.4 | T24: 0 | U24: 107.2 | V24: 58.52 | W24: 0.546
A25: grass = 0.25 | O25: L07 | P25: L | Q25: 0 | R25: 123.14 | S25: 0 | T25: 0 | U25: 123.14 | V25: 110.83 | W25: 0.9
A26: other = 0.60 | O26: L07 | P26: SUM | U26: 442.35 | V26: 338.19 | W26: 0.765
A27: For each zone:
A28: A = roof + pave + grass + other | O28: L08 | P28: G | Q28: 0 | R28: 98.7 | S28: 49.2 | T28: 0 | U28: 147.9 | V28: 101.13 | W28: 0.684
A29: A_eff = 0.95·roof + 0.90·pave + 0.25·grass + 0.60·other | O29: L08 | P29: SUM | U29: 147.9 | V29: 101.13 | W29: 0.684
A30: Then for the pipe:
A31: C = ΣA_eff / ΣA | O31: L09 | P31: D | Q31: 0 | R31: 43.2 | S31: 51.3 | T31: 0 | U31: 94.5 | V31: 51.7 | W31: 0.547
O32: L09 | P32: SUM | U32: 94.5 | V32: 51.7 | W32: 0.547
A33: L06_P09_P06 → A = 446.75 m² ≈ 446.8, C ≈ 0.425
A34: Zones J and M only: | O34: L01 | P34: A | Q34: 0 | R34: 61.9 | S34: 89.6 | T34: 0 | U34: 151.5 | V34: 78.11 | W34: 0.516
A35: Zone | B35: Roof | C35: Pave | D35: Grass | E35: Other | F35: A (m²) | G35: A_eff (m²) | H35: C zone | O35: L01 | P35: E | Q35: 0 | R35: 89.6 | S35: 16.2 | T35: 0 | U35: 105.8 | V35: 84.69 | W35: 0.8
A36: J | B36: 0 | C36: 67.7 | D36: 81.4 | E36: 0 | F36: 149.1 | G36: 67.7×0.9 + 81.4×0.25 = 81.28 | H36: 0.545 | O36: L01 | P36: SUM | U36: 257.3 | V36: 162.8 | W36: 0.633
A37: M | B37: 0 | C37: 52.4 | D37: 66.5+178.75=245.25 | E37: 0 | F37: 297.65 | G37: 52.4×0.9 + 245.25×0.25 = 108.4725 | H37: 0.364
A38: Sum | F38: 446.75 | G38: 189.7525 | O38: L02 | P38: B | Q38: 0 | R38: 79.8 | S38: 43 | T38: 0 | U38: 122.8 | V38: 82.57 | W38: 0.672
A39: C = 189.7525 / 446.75 = 0.4247 ≈ 0.425 | O39: L02 | P39: C | Q39: 0 | R39: 87.8 | S39: 123.9 | T39: 0 | U39: 211.7 | V39: 110 | W39: 0.52
O40: L02 | P40: F | Q40: 0 | R40: 114.49 | S40: 18.9 | T40: 0 | U40: 133.39 | V40: 107.77 | W40: 0.808
O41: L02 | P41: SUM | U41: 467.89 | V41: 300.33 | W41: 0.642
A42: L07_P07_P06 → A = 442.35 m², C ≈ 0.765
...
