Workbook

Sheet Guide_adaptation
A1: Adaptation méthode simple Saint-Hubert ← données Reseau_pluvial_dimensionnement_v1
A3: Fichiers sources
A4: Méthode simple: Dimensionnement réseau pluvial- Saint Hubert - bassin 5 à 60 minutes.xlsx
A5: Données projet: Reseau_pluvial_dimensionnement_v1.xlsx
A7: Onglets
A8: Temps de concentration: aires locales (ha), C, L/n/s overland → temps d’entrée
A9: Calcul_reseau: tronçons amont→aval, débit rationnel cumulatif, diamètre, capacité, radiers/couverture
A11: Correspondance topologique utilisée
A12: L06_P09_P06: P09 → P06 → L07_P07_P06 | L=15.7 m | A=446.8 m² | C≈0.425
A13: L07_P07_P06: P07 → P06 → L08_P06_P04 | L=12.2 m | A=442.4 m² | C≈0.765
A14: L08_P06_P04: P06 → P04 → L09_P04_P01 | L=9.6 m | A=147.9 m² | C≈0.684
A15: L09_P04_P01: P04 → P01 → L01_P01_P02 | L=13.5 m | A=94.5 m² | C≈0.547
... A27: 4) Comparer rapidement aux diamètres du classeur v1 si désiré

Sheet Calcul_reseau
A1: Calculs relatifs à un réseau d'égout pluvial
F2: Projet : | H2: Réseau pluvial – projet (données Reseau_pluvial_dimensionnement_v1) | M2: IDF projet (Inputs v1) – courbe 1/10 ans A=508.07 B=2.9 C=0.644 | R2: Période de retour: | S2: =1/25 -> 0.04 | T2: ans
F3: No dossier : | H3: Adapté méthode simple Saint-Hubert | Q3: I = A/(t+B)C
G4: Date : | H4: 2026-07-31 | M4: Réseau local → exutoire P12 / PUB | Q4: Récurence | R4: A | S4: B | T4: C
Q5: 1/2 ans | R5: 603.83 | S5: 6.2 | T5: 0.794
Q6: 1/5 ans | R6: 509.21 | S6: 3.7 | T6: 0.683
Q7: 1/10 ans | R7: 508.07 | S7: 2.9 | T7: 0.644
Q8: 1/25 ans | R8: 515.88 | S8: 2.1 | T8: 0.607
Q9: 1/50 ans | R9: 548.6 | S9: 1.9 | T9: 0.595
Q10: 1/100 ans | R10: 569.21 | S10: 1.6 | T10: 0.579
R11: Coefficient de Manning: | S11: 0.013
A12: Calcul du débit | M12: Calcul des caractéristiques de la conduite | S12: Niveau du sol | U12: Hauteur de radier | W12: Couverture | Y12: Volume retenu dans les conduites
A13: Tronçon de conduite | D13: Temps de concentration | E13: Accroissement (DA) de l'aire à desservir | F13: Coefficient de ruissellement de DA | G13: Aire imperméables de DA | H13: Aire cumulative | I13: Aire imperméable cumulative | J13: Coefficient de ruissellement de A | K13: Intensité de précipitation | L13: Débit maximal = 2,75 x 10-3 AIR | M13: Pente de la conduite | N13: Diamètre nominal de la conduite | O13: Vitesse d'écoulement dans la conduite coulant à plein débit | P13: Longueur de la conduite | Q13: Temps d'écoulement dans la conduite (L/v) | R13: Capacité hydraulique de la conduite coulant à plein débit | S13: Amont | T13: Aval | U13: Amont | V13: Aval | W13: Amont | X13: Aval | Y13: Conduites | Z13: Diamètre de la bouche d'égouts | AA13: Volume de la bouche d'égouts | AB13: Vérification de la capacité de la conduite Qp > Qmax | AC13: Pipe_ID (réf.)
D14: tc | E14: DA | F14: RT | G14: DART | H14: A | I14: AR | J14: R | K14: I | L14: Qmax | M14: s | N14: dnom | O14: v | P14: L | Q14: tf | R14: Qp | AC14: ID
D15: (min) | E15: (ha) | G15: (ha) | H15: (ha) | I15: (ha) | K15: (mm/h) | L15: (m3/s) | M15: (m/m) | N15: (mm) | O15: (m/s) | P15: (m) | Q15: (min) | R15: (m3/s) | S15: (m) | T15: (m) | U15: (m) | V15: (m) | W15: (m) | X15: (m) | Y15: (m3) | Z15: (m) | AA15: (m3) | AC15: -
A17: Tronçons (amont → aval) — données projet
A18: P09 | B18: @ | C18: P06 | D18: ='Temps de concentration'!B7 -> 2.1747724 | E18: 0.0447 | F18: 0.425 | G18: =E18*F18 -> 0.0189975 | H18: =E18 -> 0.0447 | I18: =G18 -> 0.0189975 | J18: =IF(H18=0,0,I18/H18) -> 0.425 | K18: =IF($S$2=0.5,$R$5/((D18+$S$5)^$T$5),IF($S$2=0.2,$R$6/((D18+$S$6)^$T$6),IF($S$2=0.1,$R$7/((D18+$S$7)^$T$7),IF($S$2=0.04,$R$8/((D18+$S$8)^$T$8),IF($S$2=0.02,$R$9/((D18+$S$9)^$T$9),$R$10/((D18+$S$10)^$T$10)))))) -> 213.59176 | L18: =0.00275*H18*J18*K18 -> 0.011158701 | M18: 0.0306 | N18: 200 | O18: =IF(OR(N18<=0,M18<=0),0,((N18/4000)^(2/3)*SQRT(M18))/$S$11) -> 1.826266 | P18: 15.7 | Q18: =IF(O18=0,0,P18/(O18*60)) -> 0.1432796 | R18: =O18*(PI()*(N18/1000)^2/4) -> 0.057373838 | S18: 17.62 | T18: 17.14 | U18: 16.918 | V18: 16.438 | W18: =S18-U18-N18/1000 -> 0.502 | X18: =T18-V18-N18/1000 -> 0.502 | Y18: =P18*PI()*(N18/1000)^2/4 -> 0.49323005 | AB18: =IF(R18>L18,"OK","AUGMENTER D") -> OK | AC18: L06_P09_P06
A19: P07 | B19: @ | C19: P06 | D19: =MAX('Temps de concentration'!C7, D18+Q18) -> 3.46882 | E19: 0.0442 | F19: 0.765 | G19: =E19*F19 -> 0.033813 | H19: =H18+E19 -> 0.0889 | I19: =I18+G19 -> 0.0528105 | J19: =IF(H19=0,0,I19/H19) -> 0.59404387 | K19: =IF($S$2=0.5,$R$5/((D19+$S$5)^$T$5),IF($S$2=0.2,$R$6/((D19+$S$6)^$T$6),IF($S$2=0.1,$R$7/((D19+$S$7)^$T$7),IF($S$2=0.04,$R$8/((D19+$S$8)^$T$8),IF($S$2=0.02,$R$9/((D19+$S$9)^$T$9),$R$10/((D19+$S$10)^$T$10)))))) -> 181.91581 | L19: =0.00275*H19*J19*K19 -> 0.026419428 | M19: 0.01 | N19: 200 | O19: =IF(OR(N19<=0,M19<=0),0,((N19/4000)^(2/3)*SQRT(M19))/$S$11) -> 1.0440068 | P19: 12.2 | Q19: =IF(O19=0,0,P19/(O19*60)) -> 0.19476247 | R19: =O19*(PI()*(N19/1000)^2/4) -> 0.03279844 | S19: 17.09 | T19: 17.14 | U19: 16.418 | V19: 16.296 | W19: =S19-U19-N19/1000 -> 0.472 | X19: =T19-V19-N19/1000 -> 0.644 | Y19: =P19*PI()*(N19/1000)^2/4 -> 0.3832743 | AB19: =IF(R19>L19,"OK","AUGMENTER D") -> OK | AC19: L07_P07_P06
A20: P06 | B20: @ | C20: P04 | D20: =MAX('Temps de concentration'!D7, D19+Q19) -> 3.6635825 | E20: 0.0148 | F20: 0.684 | G20: =E20*F20 -> 0.0101232 | H20: =H19+E20 -> 0.1037 | I20: =I19+G20 -> 0.0629337 | J20: =IF(H20=0,0,I20/H20) -> 0.60688235 | K20: =IF($S$2=0.5,$R$5/((D20+$S$5)^$T$5),IF($S$2=0.2,$R$6/((D20+$S$6)^$T$6),IF($S$2=0.1,$R$7/((D20+$S$7)^$T$7),IF($S$2=0.04,$R$8/((D20+$S$8)^$T$8),IF($S$2=0.02,$R$9/((D20+$S$9)^$T$9),$R$10/((D20+$S$10)^$T$10)))))) -> 178.15923 | L20: =0.00275*H20*J20*K20 -> 0.030833604 | M20: 0.01 | N20: 200 | O20: =IF(OR(N20<=0,M20<=0),0,((N20/4000)^(2/3)*SQRT(M20))/$S$11) -> 1.0440068 | P20: 9.6 | Q20: =IF(O20=0,0,P20/(O20*60)) -> 0.15325571 | R20: =O20*(PI()*(N20/1000)^2/4) -> 0.03279844 | S20: 17.14 | T20: 17.28 | U20: 16.276 | V20: 16.18 | W20: =S20-U20-N20/1000 -> 0.664 | X20: =T20-V20-N20/1000 -> 0.9 | Y20: =P20*PI()*(N20/1000)^2/4 -> 0.30159289 | AB20: =IF(R20>L20,"OK","AUGMENTER D") -> OK | AC20: L08_P06_P04
A21: P04 | B21: @ | C21: P01 | D21: =MAX('Temps de concentration'!E7, D20+Q20) -> 3.8168382 | E21: 0.0095 | F21: 0.547 | G21: =E21*F21 -> 0.0051965 | H21: =H20+E21 -> 0.1132 | I21: =I20+G21 -> 0.0681302 | J21: =IF(H21=0,0,I21/H21) -> 0.60185689 | K21: =IF($S$2=0.5,$R$5/((D21+$S$5)^$T$5),IF($S$2=0.2,$R$6/((D21+$S$6)^$T$6),IF($S$2=0.1,$R$7/((D21+$S$7)^$T$7),IF($S$2=0.04,$R$8/((D21+$S$8)^$T$8),IF($S$2=0.02,$R$9/((D21+$S$9)^$T$9),$R$10/((D21+$S$10)^$T$10)))))) -> 175.34373 | L21: =0.00275*H21*J21*K21 -> 0.03285206 | M21: 0.01 | N21: 250 | O21: =IF(OR(N21<=0,M21<=0),0,((N21/4000)^(2/3)*SQRT(M21))/$S$11) -> 1.2114625 | P21: 13.5 | Q21: =IF(O21=0,0,P21/(O21*60)) -> 0.18572592 | R21: =O21*(PI()*(N21/1000)^2/4) -> 0.059467529 | S21: 17.28 | T21: 17.237 | U21: 16.16 | V21: 16.025 | W21: =S21-U21-N21/1000 -> 0.87 | X21: =T21-V21-N21/1000 -> 0.962 | Y21: =P21*PI()*(N21/1000)^2/4 -> 0.6626797 | AB21: =IF(R21>L21,"OK","AUGMENTER D") -> OK | AC21: L09_P04_P01
A22: P01 | B22: @ | C22: P02 | D22: =MAX('Temps de concentration'!F7, D21+Q21) -> 4.0025641 | E22: 0.0257 | F22: 0.633 | G22: =E22*F22 -> 0.0162681 | H22: =H21+E22 -> 0.1389 | I22: =I21+G22 -> 0.0843983 | J22: =IF(H22=0,0,I22/H22) -> 0.60761915 | K22: =IF($S$2=0.5,$R$5/((D22+$S$5)^$T$5),IF($S$2=0.2,$R$6/((D22+$S$6)^$T$6),IF($S$2=0.1,$R$7/((D22+$S$7)^$T$7),IF($S$2=0.04,$R$8/((D22+$S$8)^$T$8),IF($S$2=0.02,$R$9/((D22+$S$9)^$T$9),$R$10/((D22+$S$10)^$T$10)))))) -> 172.08487 | L22: =0.00275*H22*J22*K22 -> 0.039940094 | M22: 0.01 | N22: 250 | O22: =IF(OR(N22<=0,M22<=0),0,((N22/4000)^(2/3)*SQRT(M22))/$S$11) -> 1.2114625 | P22: 14.2 | Q22: =IF(O22=0,0,P22/(O22*60)) -> 0.19535616 | R22: =O22*(PI()*(N22/1000)^2/4) -> 0.059467529 | S22: 17.237 | T22: 17.131 | U22: 16.005 | V22: 15.863 | W22: =S22-U22-N22/1000 -> 0.982 | X22: =T22-V22-N22/1000 -> 1.018 | Y22: =P22*PI()*(N22/1000)^2/4 -> 0.69704087 | AB22: =IF(R22>L22,"OK","AUGMENTER D") -> OK | AC22: L01_P01_P02
A23: P02 | B23: @ | C23: P03 | D23: =MAX('Temps de concentration'!G7, D22+Q22) -> 4.1979203 | E23: 0.0468 | F23: 0.642 | G23: =E23*F23 -> 0.0300456 | H23: =H22+E23 -> 0.1857 | I23: =I22+G23 -> 0.1144439 | J23: =IF(H23=0,0,I23/H23) -> 0.61628379 | K23: =IF($S$2=0.5,$R$5/((D23+$S$5)^$T$5),IF($S$2=0.2,$R$6/((D23+$S$6)^$T$6),IF($S$2=0.1,$R$7/((D23+$S$7)^$T$7),IF($S$2=0.04,$R$8/((D23+$S$8)^$T$8),IF($S$2=0.02,$R$9/((D23+$S$9)^$T$9),$R$10/((D23+$S$10)^$T$10)))))) -> 168.82471 | L23: =0.00275*H23*J23*K23 -> 0.053132635 | M23: 0.0114 | N23: 250 | O23: =IF(OR(N23<=0,M23<=0),0,((N23/4000)^(2/3)*SQRT(M23))/$S$11) -> 1.293488 | P23: 10.6 | Q23: =IF(O23=0,0,P23/(O23*60)) -> 0.1365816 | R23: =O23*(PI()*(N23/1000)^2/4) -> 0.063493946 | S23: 17.131 | T23: 17.01 | U23: 15.843 | V23: 15.722 | W23: =S23-U23-N23/1000 -> 1.038 | X23: =T23-V23-N23/1000 -> 1.038 | Y23: =P23*PI()*(N23/1000)^2/4 -> 0.52032628 | AB23: =IF(R23>L23,"OK","AUGMENTER D") -> OK | AC23: L02_P02_P03
A24: P03 | B24: @ | C24: P10 | D24: =D23+Q23 -> 4.3345019 | E24: 0 | F24: 0.9 | G24: =E24*F24 -> 0 | H24: =H23+E24 -> 0.1857 | I24: =I23+G24 -> 0.1144439 | J24: =IF(H24=0,0,I24/H24) -> 0.61628379 | K24: =IF($S$2=0.5,$R$5/((D24+$S$5)^$T$5),IF($S$2=0.2,$R$6/((D24+$S$6)^$T$6),IF($S$2=0.1,$R$7/((D24+$S$7)^$T$7),IF($S$2=0.04,$R$8/((D24+$S$8)^$T$8),IF($S$2=0.02,$R$9/((D24+$S$9)^$T$9),$R$10/((D24+$S$10)^$T$10)))))) -> 166.64033 | L24: =0.00275*H24*J24*K24 -> 0.052445167 | M24: 0.01 | N24: 250 | O24: =IF(OR(N24<=0,M24<=0),0,((N24/4000)^(2/3)*SQRT(M24))/$S$11) -> 1.2114625 | P24: 6.8 | Q24: =IF(O24=0,0,P24/(O24*60)) -> 0.093550835 | R24: =O24*(PI()*(N24/1000)^2/4) -> 0.059467529 | S24: 17.01 | T24: 16.965 | U24: 15.702 | V24: 15.634 | W24: =S24-U24-N24/1000 -> 1.058 | X24: =T24-V24-N24/1000 -> 1.081 | Y24: =P24*PI()*(N24/1000)^2/4 -> 0.33379422 | AB24: =IF(R24>L24,"OK","AUGMENTER D") -> OK | AC24: L03_P03_P10
A25: P10 | B25: @ | C25: P11 | D25: =MAX('Temps de concentration'!H7, D24+Q24) -> 4.4280527 | E25: 0.0903 | F25: 0.95 | G25: =E25*F25 -> 0.085785 | H25: =H24+E25 -> 0.276 | I25: =I24+G25 -> 0.2002289 | J25: =IF(H25=0,0,I25/H25) -> 0.72546703 | K25: =IF($S$2=0.5,$R$5/((D25+$S$5)^$T$5),IF($S$2=0.2,$R$6/((D25+$S$6)^$T$6),IF($S$2=0.1,$R$7/((D25+$S$7)^$T$7),IF($S$2=0.04,$R$8/((D25+$S$8)^$T$8),IF($S$2=0.02,$R$9/((D25+$S$9)^$T$9),$R$10/((D25+$S$10)^$T$10)))))) -> 165.18668 | L25: =0.00275*H25*J25*K25 -> 0.090956653 | M25: 0.01 | N25: 300 | O25: =IF(OR(N25<=0,M25<=0),0,((N25/4000)^(2/3)*SQRT(M25))/$S$11) -> 1.3680359 | P25: 14.5 | Q25: =IF(O25=0,0,P25/(O25*60)) -> 0.17665229 | R25: =O25*(PI()*(N25/1000)^2/4) -> 0.096700759 | S25: 16.965 | T25: 16.874 | U25: 15.614 | V25: 15.469 | W25: =S25-U25-N25/1000 -> 1.051 | X25: =T25-V25-N25/1000 -> 1.105 | Y25: =P25*PI()*(N25/1000)^2/4 -> 1.0249446 | AB25: =IF(R25>L25,"OK","AUGMENTER D") -> OK | AC25: L10_P10_P11
A26: P11 | B26: @ | C26: PUB | D26: =MAX('Temps de concentration'!I7, D25+Q25) -> 4.604705 | E26: 0.0498 | F26: 0.335 | G26: =E26*F26 -> 0.016683 | H26: =H25+E26 -> 0.3258 | I26: =I25+G26 -> 0.2169119 | J26: =IF(H26=0,0,I26/H26) -> 0.66578238 | K26: =IF($S$2=0.5,$R$5/((D26+$S$5)^$T$5),IF($S$2=0.2,$R$6/((D26+$S$6)^$T$6),IF($S$2=0.1,$R$7/((D26+$S$7)^$T$7),IF($S$2=0.04,$R$8/((D26+$S$8)^$T$8),IF($S$2=0.02,$R$9/((D26+$S$9)^$T$9),$R$10/((D26+$S$10)^$T$10)))))) -> 162.53101 | L26: =0.00275*H26*J26*K26 -> 0.096951002 | M26: 0.0123 | N26: 300 | O26: =IF(OR(N26<=0,M26<=0),0,((N26/4000)^(2/3)*SQRT(M26))/$S$11) -> 1.5172252 | P26: 11.7 | Q26: =IF(O26=0,0,P26/(O26*60)) -> 0.1285241 | R26: =O26*(PI()*(N26/1000)^2/4) -> 0.10724633 | S26: 16.874 | T26: 16.73 | U26: 15.449 | V26: 15.305 | W26: =S26-U26-N26/1000 -> 1.125 | X26: =T26-V26-N26/1000 -> 1.125 | Y26: =P26*PI()*(N26/1000)^2/4 -> 0.82702427 | AB26: =IF(R26>L26,"OK","AUGMENTER D") -> OK | AC26: L11_P11_P12
A29: INSTRUCTIONS / HYPOTHÈSES
A30: Jaune = saisie; Vert = calculé automatiquement (Station Saint-Hubert).
A31: Source données: Reseau_pluvial_dimensionnement_v1.xlsx (CB_plan aires, Conduites longueurs/topologie, Noeuds élévations, Inputs IDF/n/pente).
A32: Qmax = 0.00275 × A(ha) × R × I | I = A/(tc+B)^C selon période S2 (défaut 1/10 ans).
A33: v et Qp = Manning pleine section; n = S11 (0.013). Diamètre N est une suggestion — ajuster si AB = AUGMENTER D.
A34: tc: temps d’entrée (Temps de concentration) puis cumul + temps de parcours Q=L/(v*60).
A35: Radiers: calés depuis exutoire invert 15.305 m (Inputs), pente min 1%, chute regard 0.02 m.
A36: Changer la période: modifier S2 (ex. 1/25, 1/100). Les coefficients A,B,C sont dans Q5:T10.
A37: Cette feuille garde la logique simple demandée; le classeur v1 reste la référence détaillée.
F81: *
F173: ,0,

Sheet Temps de concentration
K1: Préparé par:
K2: Vérifié par:
A4: Paramètres | B4: Sous-bassins locaux (par conduite)
B5: L06 | C5: L07 | D5: L08 | E5: L09 | F5: L01 | G5: L02 | H5: L10 | I5: L11
A6: Aire (ha) | B6: 0.044675 | C6: 0.044235 | D6: 0.01479 | E6: 0.00945 | F6: 0.02573 | G6: 0.046789 | H6: 0.0903 | I6: 0.049761
A7: temps d'entrée (min.) | B7: =((2.187*B10*B11)/(B12)^0.5)^0.467 -> 2.1747724 | C7: =((2.187*C10*C11)/(C12)^0.5)^0.467 -> 3.46882 | D7: =((2.187*D10*D11)/(D12)^0.5)^0.467 -> 2.0016265 | E7: =((2.187*E10*E11)/(E12)^0.5)^0.467 -> 2.6010893 | F7: =((2.187*F10*F11)/(F12)^0.5)^0.467 -> 2.6566229 | G7: =((2.187*G10*G11)/(G12)^0.5)^0.467 -> 2.7670388 | H7: =((2.187*H10*H11)/(H12)^0.5)^0.467 -> 3.7092187 | I7: =((2.187*I10*I11)/(I12)^0.5)^0.467 -> 2.7597739
A8: Coef. Ruissellement | B8: 0.425 | C8: 0.765 | D8: 0.684 | E8: 0.547 | F8: 0.633 | G8: 0.642 | H8: 0.95 | I8: 0.335
A10: L overland (m) | B10: 21.1 | C10: 21 | D10: 12.2 | E10: 10 | F10: 16 | G10: 21.6 | H10: 30 | I10: 22.3
A11: n overland | B11: 0.02 | C11: 0.02 | D11: 0.02 | E11: 0.02 | F11: 0.02 | G11: 0.02 | H11: 0.02 | I11: 0.02
A12: s overland (m/m) | B12: 0.03057 | C12: 0.0041 | D12: 0.01458 | E12: 0.00319 | F12: 0.00746 | G12: 0.01142 | H12: 0.00628 | I12: 0.01231
A14: Notes
A15: Jaune = saisie (depuis Reseau_pluvial_dimensionnement_v1). Vert = calculé.
A16: L overland estimé ≈ √Aire; s = |Zamont-Zaval|/Lpipe. Ajuster si parcours réel connu.
A17: IDF utilisée dans Calcul_reseau: période 1/10 ans (A=508.07, B=2.9, C=0.644) = Inputs du projet.
A22: Surface C used (from Inputs):
A23: roof = 0.95
A24: pavement = 0.90
A25: grass = 0.25
A26: other = 0.60
A27: For each zone:
A28: A = roof + pave + grass + other
A29: A_eff = 0.95·roof + 0.90·pave + 0.25·grass + 0.60·other
... A34: Zones J and M only:
A35: Zone | B35: Roof | C35: Pave | D35: Grass | E35: Other | F35: A (m²) | G35: A_eff (m²) | H35: C zone
A36: J | B36: 0 | C36: 67.7 | D36: 81.4 | E36: 0 | F36: 149.1 | G36: 67.7×0.9 + 81.4×0.25 = 81.28 | H36: 0.545
A37: M | B37: 0 | C37: 52.4 | D37: 66.5+178.75=245.25 | E37: 0 | F37: 297.65 | G37: 52.4×0.9 + 245.25×0.25 = 108.4725 | H37: 0.364
A38: Sum | F38: 446.75 | G38: 189.7525
A39: C = 189.7525 / 446.75 = 0.4247 ≈ 0.425
A42: L07_P07_P06 → A = 442.35 m², C ≈ 0.765
A43: Zones H, I, K, L:
A44: Zone | B44: Roof | C44: Pave | D44: Grass | E44: Other | F44: A (m²) | G44: A_eff (m²) | H44: C zone
A45: H | B45: 0 | C45: 58.2 | D45: 17.6 | E45: 0 | F45: 75.8 | G45: 58.2×0.9 + 17.6×0.25 = 56.78 | H45: 0.749
A46: I | B46: 0 | C46: 109.5+10.51=120.01 | D46: 16.2 | E46: 0 | F46: 136.21 | G46: 120.01×0.9 + 16.2×0.25 = 112.059 | H46: 0.823
A47: K | B47: 0 | C47: 48.8 | D47: 58.4 | E47: 0 | F47: 107.2 | G47: 48.8×0.9 + 58.4×0.25 = 58.52 | H47: 0.546
A48: L | B48: 0 | C48: 95.5+10.13+17.51=123.14 | D48: 0 | E48: 0 | F48: 123.14 | G48: 123.14×0.9 = 110.826 | H48: 0.9
A49: Sum | F49: 442.35 | G49: 338.185
A50: C = 338.185 / 442.35 = 0.7645 ≈ 0.765
A52: PENTE
A53: P09 → P06 (L06_P09_P06) → 0.0306
A54: Item | B54: Value
...
