Workbook

Sheet Methode
A1: Modèle Excel – Capacité de ponceau (Sainte-Thérèse)
A3: Objectif
A4: Ce classeur calcule le débit de pointe du bassin (méthode rationnelle), estime la capacité du ponceau (Manning, section pleine), puis détermine si le contrôle est à l'entrée (inlet) ou à la sortie (outlet) selon l'approche HDS-5 / HY-8. Il indique enfin si le ponceau est Suffisant ou Insuffisant.
A8: Feuilles du classeur
A9: Feuille | B9: Contenu
A10: Calcul_simplifie | B10: Validation rapide: Q entrant (rationnel) vs capacité Manning pleine section. Vérification 25 ans et 100 ans.
A11: Controle_HY8 | B11: Analyse inlet/outlet control (HDS-5): profondeur d'eau amont, type de contrôle, comparaison au couronnement et à la route.
A12: Coefficients_entree | B12: Coefficients K, M, c, Y pour plusieurs configurations d'entrée (tuyau circulaire béton).
A13: Exemple_HY8 | B13: Valeurs préremplies correspondant à votre cas HY-8 (D=0.9 m, Q=0.59 m³/s) pour vérification.
A15: Formules principales
A16: 1) Méthode rationnelle (A en m²):
A17: Q_entrant = C × i × A / 3 600 000
A18: avec Q en m³/s, i en mm/h, A en m². Équivalent: Q = 0.00278 × C × i × A_ha si A est en hectares.
A20: 2) Capacité Manning (tuyau circulaire plein):
A21: Q_cap = (1/n) × A × R^(2/3) × S^(1/2)
A22: A = π D² / 4 | R = D / 4 | S = pente (m/m)
A24: 3) Contrôle à l'entrée / à la sortie (HDS-5):
A25: • Inlet control: HW/D à partir des équations FHWA (coefficients K, M, c, Y). • Outlet control: pertes H = [1+Ke+29 n² L / R^(4/3)] × V²/(2g), puis HW = H + h_o − L S. • Contrôle déterminant = profondeur HW la plus élevée (inlet vs outlet). • Verdict capacité: Suffisant si Q_Manning ≥ Q_entrant (validation rapide) ET HW < crête de route (contrôle hydraulique).
A30: Code couleur
A31: Jaune = saisie utilisateur
A32: Vert = résultat calculé
... A36: Ce modèle est une première validation. Pour un ponceau existant avec enjeux de stabilité, il faut aussi examiner: hauteur d'eau amont admissible, affouillement, protection de berges, dissipation d'énergie, et idéalement confirmer avec HY-8 / HDS-5.

Sheet Calcul_simplifie
A1: Validation rapide – Méthode rationnelle + capacité Manning
A2: Remplir uniquement les cellules jaunes. Les résultats se mettent à jour automatiquement.
A4: 0. Identification du projet
A5: Paramètre | B5: Valeur | C5: Unité / remarque
A6: Projet / site | B6: Ponceau – Sainte-Thérèse / Ruisseau Charron | C6: texte
A7: Analyse principale | B7: 25 ans | C7: période de retour
A8: Vérification sécurité | B8: 100 ans | C8: période de retour
A9: Notes | B9: Première validation selon workflow rationnel + Manning | C9: texte
A11: 1. Données du bassin et de la pluie
A12: Paramètre | B12: Valeur | C12: Unité | D12: Description
A13: Superficie bassin A | B13: 70800 | C13: m² | D13: Exemple: 7.08 ha pour Q25≈0.59 m³/s avec C=0.5 et i=60 mm/h (à remplacer par votre bassin)
A14: Coefficient de ruissellement C | B14: 0.5 | C14: - | D14: 0.2 (perméable) à 0.9 (très imperméable)
A15: Intensité i (25 ans) | B15: 60 | C15: mm/h | D15: Intensité pour Tc du bassin, période 25 ans
A16: Intensité i (100 ans) | B16: 80 | C16: mm/h | D16: Intensité pour Tc du bassin, période 100 ans
A18: 2. Données du ponceau
A19: Paramètre | B19: Valeur | C19: Unité | D19: Description
A20: Diamètre intérieur D | B20: 0.9 | C20: m | D20: Tuyau circulaire
A21: Coefficient de Manning n | B21: 0.012 | C21: - | D21: Béton typique: 0.012 – 0.015
A22: Pente du ponceau | B22: 1 | C22: % | D22: Saisie en % ; convertie en m/m ci-dessous
A23: Pente S | B23: =B22/100 | C23: m/m | D23: S = pente(%) / 100
A24: Aire hydraulique pleine A_h | B24: =PI()*B20^2/4 | C24: m² | D24: A = π D² / 4
A25: Rayon hydraulique R | B25: =B20/4 | C25: m | D25: R = D / 4 (section pleine)
A27: 3. Débits entrants (méthode rationnelle)
A28: Paramètre | B28: Valeur | C28: Unité | D28: Formule
A29: Q entrant 25 ans | B29: =B14*B15*B13/3600000 | C29: m³/s | D29: Q = C·i·A / 3 600 000
A30: Q entrant 100 ans | B30: =B14*B16*B13/3600000 | C30: m³/s | D30: Q = C·i·A / 3 600 000
A31: Q entrant forcé (optionnel) | B31: 0.59 | C31: m³/s | D31: Si > 0, utilisé pour le verdict 'forcé' (ex.: Q HY-8 = 0.59)
A33: 4. Capacité du ponceau (Manning, plein)
A34: Paramètre | B34: Valeur | C34: Unité | D34: Formule
A35: Capacité Q_ponceau | B35: =IF(OR(B21<=0,B23<=0,B20<=0),0,(1/B21)*B24*(B25^(2/3))*(B23^0.5)) | C35: m³/s | D35: Q = (1/n)·A·R^(2/3)·S^(1/2)
A36: Vitesse à pleine section V | B36: =IF(B24<=0,0,B35/B24) | C36: m/s | D36: V = Q_ponceau / A_h
A38: 5. Comparaison et verdict (première validation)
A39: Critère | B39: Ratio Qent/Qponc | C39: Verdict | D39: Interprétation
A40: Période 25 ans | B40: =IF(B35<=0,"n/d",B29/B35) | C40: =IF(B35<=0,"n/d",IF(B35>=B29,"SUFFISANT","INSUFFISANT")) | D40: Suffisant si Q_ponceau ≥ Q_entrant 25 ans
A41: Période 100 ans | B41: =IF(B35<=0,"n/d",B30/B35) | C41: =IF(B35<=0,"n/d",IF(B35>=B30,"SUFFISANT","INSUFFISANT")) | D41: Vérification de sécurité / débordement
A42: Q forcé (ex. HY-8) | B42: =IF(OR(B35<=0,B31<=0),"n/d",B31/B35) | C42: =IF(B31<=0,"(non utilisé)",IF(B35>=B31,"SUFFISANT","INSUFFISANT")) | D42: Compare un débit imposé (0.59 m³/s) à la capacité Manning
A44: Marge de capacité 25 ans (Qponc − Qent) | B44: =B35-B29 | C44: m³/s | D44: Positif = réserve de capacité
A46: Note: cette feuille ne détermine PAS encore inlet vs outlet control. Utiliser la feuille Controle_HY8 pour cela.

Sheet Coefficients_entree
A1: Coefficients de contrôle à l'entrée – tuyau circulaire (HDS-5 / FHWA)
A3: Choisissez une configuration dans Controle_HY8 (liste déroulante). Les coefficients sont lus automatiquement.
A5: ID | B5: Configuration d'entrée | C5: K | D5: M | E5: c | F5: Y | G5: Ke typique
A6: 1 | B6: Square edge with headwall (béton) | C6: 0.0098 | D6: 2 | E6: 0.0398 | F6: 0.67 | G6: 0.5
A7: 2 | B7: Groove end with headwall | C7: 0.0078 | D7: 2 | E7: 0.0292 | F7: 0.74 | G7: 0.2
A8: 3 | B8: Groove end projecting | C8: 0.0045 | D8: 2 | E8: 0.0317 | F8: 0.69 | G8: 0.2
A9: 4 | B9: Beveled ring / bevel 45° (approx. béton) | C9: 0.0018 | D9: 2.5 | E9: 0.03 | F9: 0.74 | G9: 0.2
A10: 5 | B10: Mitered to slope (approx.) | C10: 0.021 | D10: 1.33 | E10: 0.0463 | F10: 0.75 | G10: 0.7
A12: Équations inlet control (formes FHWA)
A13: Non submergé (Forme 1): HW/D = [ Q / (A · D^0.5) / K ] ^ (1/M)
A14: Submergé (Forme 2): HW/D = c · [ Q / (A · D^0.5) ]² + Y
A15: Transition: Forme 1 si HW/D < 1.2 ; Forme 2 si HW/D > 1.5 ; interpolation linéaire entre 1.2 et 1.5.
A16: Référence: FHWA HDS-5 Hydraulic Design of Highway Culverts.

Sheet Controle_HY8
A1: Contrôle inlet / outlet – approche HDS-5 (type HY-8)
A2: Les cellules jaunes sont modifiables. Cette feuille estime HW inlet, HW outlet et le contrôle déterminant.
A4: 1. Débit à analyser
A5: Source du débit | B5: Q forcé (saisie directe) | C5: Choisir dans la liste
A6: Q forcé | B6: 0.59 | C6: m³/s | D6: Utilisé si source = Q forcé
A7: Q analysé | B7: =IF(B5="Q 25 ans (Calcul_simplifie)",Calcul_simplifie!B29,IF(B5="Q 100 ans (Calcul_simplifie)",Calcul_simplifie!B30,B6)) | C7: m³/s | D7: Débit utilisé dans les calculs inlet/outlet
A9: 2. Géométrie du ponceau et site
A10: Paramètre | B10: Valeur | C10: Unité | D10: Notes
A11: Diamètre D | B11: 0.9 | C11: m | D11: Circulaire
A12: Longueur L | B12: 20 | C12: m | D12: Distance inlet → outlet
A13: Manning n | B13: 0.012 | C13: - | D13: Béton
A14: Pente | B14: 1 | C14: % | D14: Convertie en m/m
A15: Invert amont (inlet) | B15: 30.2 | C15: m | D15: Élévation radier amont
A16: Invert aval (outlet) | B16: 30 | C16: m | D16: Élévation radier aval
A17: Profondeur d'eau aval TW | B17: 1.62 | C17: m | D17: Calé pour rapprocher HY-8 (HW outlet ≈ 1.51 m). Ajuster selon site.
A18: Crête de route | B18: 32.5 | C18: m | D18: Pour vérifier le débordement
A19: Ke (perte d'entrée) | B19: 0.5 | C19: - | D19: Square edge headwall typique = 0.5
A20: Pente S | B20: =IF(ABS(B15-B16)>1E-9,(B15-B16)/B12,B14/100) | C20: m/m | D20: Priorité aux inverts; sinon pente %
A21: Aire pleine A | B21: =PI()*B11^2/4 | C21: m² | D21: πD²/4
A22: Rayon hydraulique R | B22: =B11/4 | C22: m | D22: D/4
A24: 3. Configuration d'entrée (coefficients)
A25: Configuration | B25: Square edge with headwall (béton)
A26: K | B26: =IFERROR(VLOOKUP(B25,Coefficients_entree!$B$6:$G$10,2,FALSE),0.0098) | C26: - | D26: Coefficient forme 1
A27: M | B27: =IFERROR(VLOOKUP(B25,Coefficients_entree!$B$6:$G$10,3,FALSE),2) | C27: - | D27: Exposant forme 1
A28: c | B28: =IFERROR(VLOOKUP(B25,Coefficients_entree!$B$6:$G$10,4,FALSE),0.0398) | C28: - | D28: Coefficient forme 2
A29: Y | B29: =IFERROR(VLOOKUP(B25,Coefficients_entree!$B$6:$G$10,5,FALSE),0.67) | C29: - | D29: Constante forme 2
A30: Ke suggéré | B30: =IFERROR(VLOOKUP(B25,Coefficients_entree!$B$6:$G$10,6,FALSE),0.5) | C30: - | D30: Copier vers B19 si désiré
A32: 4. Contrôle à l'entrée (Inlet Control)
A33: Paramètre | B33: Valeur | C33: Unité | D33: Formule / notes
A34: Paramètre de débit Q/(A√D) | B34: =IF(OR(B21<=0,B11<=0),0,B7/(B21*SQRT(B11))) | C34: m^0.5/s | D34: Argument des équations FHWA
A35: HW/D forme 1 (non submergé) | B35: =IF(OR(B26<=0,B34<=0),0,(B34/B26)^(1/B27)) | C35: - | D35: HW/D = [Q/(A√D)/K]^(1/M)
A36: HW/D forme 2 (submergé) | B36: =B28*B34^2+B29 | C36: - | D36: HW/D = c[Q/(A√D)]² + Y
A37: HW/D inlet (avec transition) | B37: =IF(B7<=0,0,IF(B35<=1.2,B35,B36)) | C37: - | D37: Si forme1≤1.2 → non submergé; sinon forme2 (submergé)
A38: Profondeur HW inlet | B38: =B37*B11 | C38: m | D38: Au-dessus de l'invert amont
A39: Élévation HW inlet | B39: =B15+B38 | C39: m | D39: Invert amont + HW inlet
A41: 5. Contrôle à la sortie (Outlet Control)
A42: Paramètre | B42: Valeur | C42: Unité | D42: Formule / notes
A43: Vitesse pleine V | B43: =IF(B21<=0,0,B7/B21) | C43: m/s | D43: V = Q / A (hypothèse section pleine pour pertes)
A44: Charge de vitesse V²/2g | B44: =IF(B43<=0,0,B43^2/(2*9.81)) | C44: m | D44: g = 9.81 m/s²
A45: Terme de friction 29 n² L / R^(4/3) | B45: =IF(B22<=0,0,29*B13^2*B12/(B22^(4/3))) | C45: - | D45: Forme HDS-5 / HY-8 (SI)
...

Sheet Exemple_HY8
A1: Exemple de calage – cas HY-8 Crossing 1
A3: Valeurs observées dans HY-8 (référence)
A5: Paramètre | B5: Valeur HY-8 | C5: Unité | D5: Valeur dans ce classeur | E5: Écart
A6: Débit design Q | B6: 0.59 | C6: m³/s | D6: =Controle_HY8!B7 | E6: =D6-B6
A7: Diamètre D | B7: 0.9 | C7: m | D7: =Controle_HY8!B11 | E7: =D7-B7
A8: Longueur L | B8: 20 | C8: m | D8: =Controle_HY8!B12 | E8: =D8-B8
A9: Pente | B9: 0.01 | C9: m/m | D9: =Controle_HY8!B20 | E9: =D9-B9
A10: Invert amont | B10: 30.2 | C10: m | D10: =Controle_HY8!B15 | E10: =D10-B10
A11: Invert aval | B11: 30 | C11: m | D11: =Controle_HY8!B16 | E11: =D11-B11
A12: HW inlet depth (HY-8) | B12: 0.66 | C12: m | D12: =Controle_HY8!B38 | E12: =D12-B12
A13: HW outlet depth (HY-8) | B13: 1.51 | C13: m | D13: =Controle_HY8!B50 | E13: =D13-B13
A14: HW déterminante | B14: 1.51 | C14: m | D14: =Controle_HY8!B56 | E14: =D14-B14
A15: Élévation HW | B15: 31.71 | C15: m | D15: =Controle_HY8!B57 | E15: =D15-B15
A16: Contrôle | B16: OUTLET CONTROL | C16: - | D16: =Controle_HY8!B55 | E16: =IF(D16=B16,"OK","Différent")
A18: Comment caler TW pour coller à HY-8
A19: 1. Feuille Controle_HY8 déjà préremplie pour coller à HY-8 (Q=0.59, TW=1.62 m). 2. Vérifiez: Contrôle déterminant = OUTLET CONTROL. 3. Vérifiez: HW inlet ≈ 0.64–0.66 m, HW outlet ≈ 1.51 m, élévation HW ≈ 31.71 m. 4. Remplacez ensuite TW, A, C, i par vos données de terrain / IDF. La feuille Calcul_simplifie fait la validation rapide Manning. La feuille Controle_HY8 fait le diagnostic inlet vs outlet.
A26: Suggestion automatique de TW pour viser HW outlet = 1.51 m
A27: TW de calage estimée | B27: =MAX(Controle_HY8!B48,(1.51-Controle_HY8!B46+Controle_HY8!B12*Controle_HY8!B20)) | C27: m | D27: Copier cette valeur dans Controle_HY8!B17 pour caler HY-8
