Workbook

Sheet Guide
A1: DRAINAGE HYBRIDE - TOIT + TRESFOND VERS BASSIN DE RETENTION
A3: Contrainte cle: pas de conduite/fosse dans le tresfond. Le ruissellement du tresfond est dirige par pente vers les bandes vertes.
A4: Solution recommandee: systeme hybride (noues/swales + tranchees drainantes localisees + conduites perimetriques hors tresfond).
A5: 2) Bande sud (2.0 m): conduite/collecte vers volume de retention dans le corridor contraint.
A6: 3) Ouest: strategie revisee en conduites (pas de noues) vers E04 puis E08 et bassin.
A7: Flux de calcul: Zones_tributaires -> Elements_hybrides -> Noeuds_stockage -> verifications capacite/vitesse/volume tampon.
A8: Les longueurs, pentes, sections et cotes sont pre-remplies comme base; ajuster selon releve topo et contraintes de chantier.
A9: Types d'element supports: PIPE, SWALE, TRENCH.
A10: Vitesse controlee selon Inputs!B15: DESIGN (Q/A), MANNING, ou MAX.
A11: Ce classeur est separe de Reseau_pluvial_reference_method.xlsx (aucun ecrasement).
A14: Recommandation d amenagement (optimal):
A15: 1) Collecte toiture vers noue sud (hors tresfond), 2) pente tresfond vers noue est, 3) collecteur final vers BASIN_RET.
... A56: Affichage decimal harmonise: format [<1]0.0000;0.000 applique aux champs calcules Tc/temps/Q.

Sheet Inputs
A1: INPUTS - PARAMETRES HYDRAULIQUES
A2: Parametre | B2: Valeur | C2: Unite | D2: Note
A3: IDF_a | B3: 7423.67 | C3: - | D3: i = a/(tc+b)^c | E3: MIRABEL
A4: IDF_b | B4: 33.5 | C4: min | D4: Parametre IDF b | E4: MIRABEL
A5: IDF_c | B5: 1.148 | C5: - | D5: Parametre IDF c | E5: MIRABEL
A6: Flow_safety_factor | B6: 1.1 | C6: - | D6: Facteur de securite sur debit element
A7: n_pipe_default | B7: 0.013 | C7: - | D7: Manning conduite
A8: n_swale_default | B8: 0.03 | C8: - | D8: Manning noue vegetee
A9: n_trench_default | B9: 0.028 | C9: - | D9: Manning tranchee drainante ouverte
A10: C_roof | B10: 0.95 | C10: - | D10: Coef ruissellement toiture
A11: C_tresfond | B11: 0.95 | C11: - | D11: Coef ruissellement surface impermeable tresfond
A12: C_grass | B12: 0.25 | C12: - | D12: Coef ruissellement gazon
A13: C_other | B13: 0.6 | C13: - | D13: Coef autre surface
A14: Default_tc_min | B14: 7 | C14: min | D14: Tc si non saisi zone
A15: Velocity_check_method (DESIGN/MANNING/MAX) | B15: MAX | C15: - | D15: Critere vitesse pour CHECK
A16: Min_velocity_mps | B16: 0.75 | C16: m/s | D16: Seuil auto-curage
A17: Max_velocity_mps | B17: 3 | C17: m/s | D17: Seuil erosion
A18: Min_slope_m_per_m | B18: 0.003 | C18: m/m | D18: Pente min de controle
A19: Fill_ratio_limit | B19: 0.8 | C19: - | D19: Q_design/Q_capacity max
A20: Default_side_slope_zH1V | B20: 3 | C20: - | D20: Noue/tranchee trapezoidale
A21: Default_flow_depth_m | B21: 0.3 | C21: m | D21: Profondeur ecoulement initiale
A22: Trench_porosity_default | B22: 0.35 | C22: - | D22: Porosite utile stockage
A23: Node_buffer_time_min | B23: 6 | C23: min | D23: Volume tampon noeud = Qin*temps
A24: East_strip_total_width_m | B24: 2.5 | C24: m | D24: Largeur bande verte est disponible.
A25: East_surface_depression_width_m | B25: 0.6 | C25: m | D25: Largeur depression superficielle.
A26: East_surface_depression_depth_m | B26: 0.1 | C26: m | D26: Profondeur depression de surface.
A27: East_tree_soil_zone_width_m | B27: 1.1 | C27: m | D27: Zone sol vegetal / arbres.
... A37: Basin_ret_top_level_m | B37: 22.94 | C37: m | D37: Niveau de reference du bassin (a ajuster avec topographie).
A38: Basin_ret_invert_m | B38: =B37-B36 -> 21.62 | C38: m | D38: Radier bassin lineaire (derive).
A39: Max_cover_near_utilities_m | B39: 1.2 | C39: m | D39: Profondeur max recommandee dans zone lateraux ouest (approche conservatrice).
A40: West_chain_total_m | B40: 23.58 | C40: m | D40: Somme E05A..E05E (chaine J-OUEST).
A41: West_amont_to_PU2_chain_m | B41: 11.1 | C41: m | D41: Cote plan visible (J-OUEST-AMONT jusqu'a fin zone amont avant troncon pave inferieur).
A42: West_pave1_short_span_m | B42: 2.3 | C42: m | D42: Traverse pave-uni courte (amont).
A43: West_pave2_span_m | B43: 5.1 | C43: m | D43: Traverse pave-uni inferieure (cote plan visible).
A44: West_grass1_area_m2 | B44: 12.5 | C44: m2 | D44: Aire zone gazon 1 (image).
A45: West_grass2_area_m2 | B45: 27.2 | C45: m2 | D45: Aire zone gazon 2 (image).
A46: West_grass3_area_m2 | B46: 21.9 | C46: m2 | D46: Aire zone gazon 3 (image).
A47: West_grass12_total_m | B47: =B41-B42 -> 8.8 | C47: m | D47: Longueur gazon amont+milieu (derivee).
A48: West_grass1_len_m | B48: =IFERROR(B47*B44/(B44+B45),"") -> 2.7707809 | C48: m | D48: Longueur E05A (repartition proportionnelle).
A49: West_grass2_len_m | B49: =IFERROR(B47*B45/(B44+B45),"") -> 6.0292191 | C49: m | D49: Longueur E05C (repartition proportionnelle).
...

Sheet Zones_tributaires
A1: ZONES TRIBUTAIRES - TOIT / TRESFOND / VERT
K2: Routing des zones se fait via Element_ID (colonne J), independamment du renommage des noeuds.
A3: Zone_ID | B3: Description | C3: Surface_type | D3: Area_m2 | E3: C_override | F3: C_used | G3: Tc_min | H3: Intensity_mmh | I3: Q_peak_m3s | J3: Routed_to_Element_ID | K3: Notes | L3: Tc_base_override_min | M3: Travel_time_routed_element_min | N3: Tc_auto_used_min
A4: Z01 | B4: Toiture principale (bloc jaune) | C4: ROOF | D4: 1013.8 | F4: =IF(E4<>"",E4,IF(UPPER(TRIM(C4))="BASIN",IF(UPPER(TRIM(Inputs!$B$52))="YES",Inputs!$B$12,0),IF(UPPER(TRIM(C4))="ROOF",Inputs!$B$10,IF(UPPER(TRIM(C4))="PAVAGE",Inputs!$B$58,IF(UPPER(TRIM(C4))="TRESFOND",Inputs!$B$11,IF(UPPER(TRIM(C4))="GRASS",Inputs!$B$12,Inputs!$B$13)))))) -> 0.95 | G4: =IF(A4="","",N4) -> 5 | H4: =IF(A4="","",Inputs!$B$3/((IF(G4="",Inputs!$B$14,G4)+Inputs!$B$4)^Inputs!$B$5)) -> 112.33362 | I4: =IF(A4="","",0.000000278*F4*D4*H4) -> 0.030076717 | J4: BASSIN-RET | K4: Routage provisoire vers entree EST; scinder est/ouest plus tard si detail aval disponible. | L4: 5 | M4: =IF(A4="","",IF(OR(J4="",Inputs!$B$59=""),0,IFERROR(INDEX(Elements_hybrides!$F$4:$F$204,MATCH(J4,Elements_hybrides!$A$4:$A$204,0))/(Inputs!$B$59*60),0))) -> 0 | N4: =IF(A4="","",IF(L4="",Inputs!$B$14,L4)+M4) -> 5
A5: Z02 | B5: Tresfond est (gris) | C5: TRESFOND | D5: 351 | F5: =IF(E5<>"",E5,IF(UPPER(TRIM(C5))="BASIN",IF(UPPER(TRIM(Inputs!$B$52))="YES",Inputs!$B$12,0),IF(UPPER(TRIM(C5))="ROOF",Inputs!$B$10,IF(UPPER(TRIM(C5))="PAVAGE",Inputs!$B$58,IF(UPPER(TRIM(C5))="TRESFOND",Inputs!$B$11,IF(UPPER(TRIM(C5))="GRASS",Inputs!$B$12,Inputs!$B$13)))))) -> 0.95 | G5: =IF(A5="","",N5) -> 5 | H5: =IF(A5="","",Inputs!$B$3/((IF(G5="",Inputs!$B$14,G5)+Inputs!$B$4)^Inputs!$B$5)) -> 112.33362 | I5: =IF(A5="","",0.000000278*F5*D5*H5) -> 0.010413225 | J5: BASSIN-RET | K5: Puisards zone grise est -> reseau interne mecanique -> sortie sud pres bassin (pas vers bande est). | L5: 5 | M5: =IF(A5="","",IF(OR(J5="",Inputs!$B$59=""),0,IFERROR(INDEX(Elements_hybrides!$F$4:$F$204,MATCH(J5,Elements_hybrides!$A$4:$A$204,0))/(Inputs!$B$59*60),0))) -> 0 | N5: =IF(A5="","",IF(L5="",Inputs!$B$14,L5)+M5) -> 5
A6: Z03 | B6: Bande verte est (arbres) | C6: GRASS | D6: 164.7 | F6: =IF(E6<>"",E6,IF(UPPER(TRIM(C6))="BASIN",IF(UPPER(TRIM(Inputs!$B$52))="YES",Inputs!$B$12,0),IF(UPPER(TRIM(C6))="ROOF",Inputs!$B$10,IF(UPPER(TRIM(C6))="PAVAGE",Inputs!$B$58,IF(UPPER(TRIM(C6))="TRESFOND",Inputs!$B$11,IF(UPPER(TRIM(C6))="GRASS",Inputs!$B$12,Inputs!$B$13)))))) -> 0.25 | G6: =IF(A6="","",N6) -> 5.2683333 | H6: =IF(A6="","",Inputs!$B$3/((IF(G6="",Inputs!$B$14,G6)+Inputs!$B$4)^Inputs!$B$5)) -> 111.44149 | I6: =IF(A6="","",0.000000278*F6*D6*H6) -> 0.0012756317 | J6: E03 | K6: Bande est verte reduite: 205.5 - 40.8 = 164.7 m2 (partie haute deviee vers puisard PEHD central). | L6: 5 | M6: =IF(A6="","",IF(OR(J6="",Inputs!$B$59=""),0,IFERROR(INDEX(Elements_hybrides!$F$4:$F$204,MATCH(J6,Elements_hybrides!$A$4:$A$204,0))/(Inputs!$B$59*60),0))) -> 0.26833333 | N6: =IF(A6="","",IF(L6="",Inputs!$B$14,L6)+M6) -> 5.2683333
A7: Z04 | B7: Ouest gazon amont (12.5 m2) | C7: GRASS | D7: 12.5 | F7: =IF(E7<>"",E7,IF(UPPER(TRIM(C7))="BASIN",IF(UPPER(TRIM(Inputs!$B$52))="YES",Inputs!$B$12,0),IF(UPPER(TRIM(C7))="ROOF",Inputs!$B$10,IF(UPPER(TRIM(C7))="PAVAGE",Inputs!$B$58,IF(UPPER(TRIM(C7))="TRESFOND",Inputs!$B$11,IF(UPPER(TRIM(C7))="GRASS",Inputs!$B$12,Inputs!$B$13)))))) -> 0.25 | G7: =IF(A7="","",N7) -> 5.0461797 | H7: =IF(A7="","",Inputs!$B$3/((IF(G7="",Inputs!$B$14,G7)+Inputs!$B$4)^Inputs!$B$5)) -> 112.17913 | I7: =IF(A7="","",0.000000278*F7*D7*H7) -> 9.7455622e-05 | J7: E05A | K7: Image: zone verte amont gauche. | L7: 5 | M7: =IF(A7="","",IF(OR(J7="",Inputs!$B$59=""),0,IFERROR(INDEX(Elements_hybrides!$F$4:$F$204,MATCH(J7,Elements_hybrides!$A$4:$A$204,0))/(Inputs!$B$59*60),0))) -> 0.046179681 | N7: =IF(A7="","",IF(L7="",Inputs!$B$14,L7)+M7) -> 5.0461797
A8: Z07 | B8: Ouest pave-uni court (6.7 m2) | C8: PAVAGE | D8: 6.7 | F8: =IF(E8<>"",E8,IF(UPPER(TRIM(C8))="BASIN",IF(UPPER(TRIM(Inputs!$B$52))="YES",Inputs!$B$12,0),IF(UPPER(TRIM(C8))="ROOF",Inputs!$B$10,IF(UPPER(TRIM(C8))="PAVAGE",Inputs!$B$58,IF(UPPER(TRIM(C8))="TRESFOND",Inputs!$B$11,IF(UPPER(TRIM(C8))="GRASS",Inputs!$B$12,Inputs!$B$13)))))) -> 0.95 | G8: =IF(A8="","",N8) -> 5.0383333 | H8: =IF(A8="","",Inputs!$B$3/((IF(G8="",Inputs!$B$14,G8)+Inputs!$B$4)^Inputs!$B$5)) -> 112.20535 | I8: =IF(A8="","",0.000000278*F8*D8*H8) -> 0.00019854401 | J8: E05B | K8: Surface pavage (pas tresfond). | L8: 5 | M8: =IF(A8="","",IF(OR(J8="",Inputs!$B$59=""),0,IFERROR(INDEX(Elements_hybrides!$F$4:$F$204,MATCH(J8,Elements_hybrides!$A$4:$A$204,0))/(Inputs!$B$59*60),0))) -> 0.038333333 | N8: =IF(A8="","",IF(L8="",Inputs!$B$14,L8)+M8) -> 5.0383333
A9: Z05 | B9: Ouest gazon milieu (27.2 m2) | C9: GRASS | D9: 27.2 | F9: =IF(E9<>"",E9,IF(UPPER(TRIM(C9))="BASIN",IF(UPPER(TRIM(Inputs!$B$52))="YES",Inputs!$B$12,0),IF(UPPER(TRIM(C9))="ROOF",Inputs!$B$10,IF(UPPER(TRIM(C9))="PAVAGE",Inputs!$B$58,IF(UPPER(TRIM(C9))="TRESFOND",Inputs!$B$11,IF(UPPER(TRIM(C9))="GRASS",Inputs!$B$12,Inputs!$B$13)))))) -> 0.25 | G9: =IF(A9="","",N9) -> 5.100487 | H9: =IF(A9="","",Inputs!$B$3/((IF(G9="",Inputs!$B$14,G9)+Inputs!$B$4)^Inputs!$B$5)) -> 111.99797 | I9: =IF(A9="","",0.000000278*F9*D9*H9) -> 0.00021172096 | J9: E05C | K9: Image: bande verte milieu ouest. | L9: 5 | M9: =IF(A9="","",IF(OR(J9="",Inputs!$B$59=""),0,IFERROR(INDEX(Elements_hybrides!$F$4:$F$204,MATCH(J9,Elements_hybrides!$A$4:$A$204,0))/(Inputs!$B$59*60),0))) -> 0.10048699 | N9: =IF(A9="","",IF(L9="",Inputs!$B$14,L9)+M9) -> 5.100487
A10: Z08 | B10: Ouest pave-uni principal (37.5 m2) | C10: PAVAGE | D10: 37.5 | F10: =IF(E10<>"",E10,IF(UPPER(TRIM(C10))="BASIN",IF(UPPER(TRIM(Inputs!$B$52))="YES",Inputs!$B$12,0),IF(UPPER(TRIM(C10))="ROOF",Inputs!$B$10,IF(UPPER(TRIM(C10))="PAVAGE",Inputs!$B$58,IF(UPPER(TRIM(C10))="TRESFOND",Inputs!$B$11,IF(UPPER(TRIM(C10))="GRASS",Inputs!$B$12,Inputs!$B$13)))))) -> 0.95 | G10: =IF(A10="","",N10) -> 5.085 | H10: =IF(A10="","",Inputs!$B$3/((IF(G10="",Inputs!$B$14,G10)+Inputs!$B$4)^Inputs!$B$5)) -> 112.04958 | I10: =IF(A10="","",0.000000278*F10*D10*H10) -> 0.001109711 | J10: E05D | K10: Surface pavage principal (pave-uni), entre Z05 et Z06. | L10: 5 | M10: =IF(A10="","",IF(OR(J10="",Inputs!$B$59=""),0,IFERROR(INDEX(Elements_hybrides!$F$4:$F$204,MATCH(J10,Elements_hybrides!$A$4:$A$204,0))/(Inputs!$B$59*60),0))) -> 0.085 | N10: =IF(A10="","",IF(L10="",Inputs!$B$14,L10)+M10) -> 5.085
A11: Z06 | B11: Ouest gazon aval coin sud-ouest (21.9 m2) | C11: GRASS | D11: 21.9 | F11: =IF(E11<>"",E11,IF(UPPER(TRIM(C11))="BASIN",IF(UPPER(TRIM(Inputs!$B$52))="YES",Inputs!$B$12,0),IF(UPPER(TRIM(C11))="ROOF",Inputs!$B$10,IF(UPPER(TRIM(C11))="PAVAGE",Inputs!$B$58,IF(UPPER(TRIM(C11))="TRESFOND",Inputs!$B$11,IF(UPPER(TRIM(C11))="GRASS",Inputs!$B$12,Inputs!$B$13)))))) -> 0.25 | G11: =IF(A11="","",N11) -> 5.123 | H11: =IF(A11="","",Inputs!$B$3/((IF(G11="",Inputs!$B$14,G11)+Inputs!$B$4)^Inputs!$B$5)) -> 111.92303 | I11: =IF(A11="","",0.000000278*F11*D11*H11) -> 0.00017035244 | J11: E05E | K11: Image: zone verte pres J-OUEST-AVAL. | L11: 5 | M11: =IF(A11="","",IF(OR(J11="",Inputs!$B$59=""),0,IFERROR(INDEX(Elements_hybrides!$F$4:$F$204,MATCH(J11,Elements_hybrides!$A$4:$A$204,0))/(Inputs!$B$59*60),0))) -> 0.123 | N11: =IF(A11="","",IF(L11="",Inputs!$B$14,L11)+M11) -> 5.123
A12: Z09 | B12: Empreinte bassin retention (zone de stockage) | C12: BASIN | F12: =IF(E12<>"",E12,IF(UPPER(TRIM(C12))="BASIN",IF(UPPER(TRIM(Inputs!$B$52))="YES",Inputs!$B$12,0),IF(UPPER(TRIM(C12))="ROOF",Inputs!$B$10,IF(UPPER(TRIM(C12))="PAVAGE",Inputs!$B$58,IF(UPPER(TRIM(C12))="TRESFOND",Inputs!$B$11,IF(UPPER(TRIM(C12))="GRASS",Inputs!$B$12,Inputs!$B$13)))))) -> 0 | G12: =IF(A12="","",N12) -> 5 | H12: =IF(A12="","",Inputs!$B$3/((IF(G12="",Inputs!$B$14,G12)+Inputs!$B$4)^Inputs!$B$5)) -> 112.33362 | I12: =IF(A12="","",0.000000278*F12*D12*H12) -> 0 | K12: Non contributive par defaut (Inputs!B52=NO). Mettre YES pour sensibilité si requis. | L12: 5 | M12: =IF(A12="","",IF(OR(J12="",Inputs!$B$59=""),0,IFERROR(INDEX(Elements_hybrides!$F$4:$F$204,MATCH(J12,Elements_hybrides!$A$4:$A$204,0))/(Inputs!$B$59*60),0))) -> 0 | N12: =IF(A12="","",IF(L12="",Inputs!$B$14,L12)+M12) -> 5
A13: Z10 | B13: Sud gris local (pavage) | C13: PAVAGE | D13: 44.3 | F13: =IF(E13<>"",E13,IF(UPPER(TRIM(C13))="BASIN",IF(UPPER(TRIM(Inputs!$B$52))="YES",Inputs!$B$12,0),IF(UPPER(TRIM(C13))="ROOF",Inputs!$B$10,IF(UPPER(TRIM(C13))="PAVAGE",Inputs!$B$58,IF(UPPER(TRIM(C13))="TRESFOND",Inputs!$B$11,IF(UPPER(TRIM(C13))="GRASS",Inputs!$B$12,Inputs!$B$13)))))) -> 0.95 | G13: =IF(A13="","",N13) -> 5.2683333 | H13: =IF(A13="","",Inputs!$B$3/((IF(G13="",Inputs!$B$14,G13)+Inputs!$B$4)^Inputs!$B$5)) -> 111.44149 | I13: =IF(A13="","",0.000000278*F13*D13*H13) -> 0.0013038242 | J13: E03 | K13: Surface pavage locale (pas tresfond), routage vers entree EST. | L13: 5 | M13: =IF(A13="","",IF(OR(J13="",Inputs!$B$59=""),0,IFERROR(INDEX(Elements_hybrides!$F$4:$F$204,MATCH(J13,Elements_hybrides!$A$4:$A$204,0))/(Inputs!$B$59*60),0))) -> 0.26833333 | N13: =IF(A13="","",IF(L13="",Inputs!$B$14,L13)+M13) -> 5.2683333
A14: Z11 | B14: Sud est vert | C14: GRASS | D14: 20.5 | F14: =IF(E14<>"",E14,IF(UPPER(TRIM(C14))="BASIN",IF(UPPER(TRIM(Inputs!$B$52))="YES",Inputs!$B$12,0),IF(UPPER(TRIM(C14))="ROOF",Inputs!$B$10,IF(UPPER(TRIM(C14))="PAVAGE",Inputs!$B$58,IF(UPPER(TRIM(C14))="TRESFOND",Inputs!$B$11,IF(UPPER(TRIM(C14))="GRASS",Inputs!$B$12,Inputs!$B$13)))))) -> 0.25 | G14: =IF(A14="","",N14) -> 5.2683333 | H14: =IF(A14="","",Inputs!$B$3/((IF(G14="",Inputs!$B$14,G14)+Inputs!$B$4)^Inputs!$B$5)) -> 111.44149 | I14: =IF(A14="","",0.000000278*F14*D14*H14) -> 0.00015877626 | J14: E03 | K14: Vers noue sud | L14: 5 | M14: =IF(A14="","",IF(OR(J14="",Inputs!$B$59=""),0,IFERROR(INDEX(Elements_hybrides!$F$4:$F$204,MATCH(J14,Elements_hybrides!$A$4:$A$204,0))/(Inputs!$B$59*60),0))) -> 0.26833333 | N14: =IF(A14="","",IF(L14="",Inputs!$B$14,L14)+M14) -> 5.2683333
A15: Z12 | B15: Sud est gris petit (pavage) | C15: PAVAGE | D15: 5.8 | F15: =IF(E15<>"",E15,IF(UPPER(TRIM(C15))="BASIN",IF(UPPER(TRIM(Inputs!$B$52))="YES",Inputs!$B$12,0),IF(UPPER(TRIM(C15))="ROOF",Inputs!$B$10,IF(UPPER(TRIM(C15))="PAVAGE",Inputs!$B$58,IF(UPPER(TRIM(C15))="TRESFOND",Inputs!$B$11,IF(UPPER(TRIM(C15))="GRASS",Inputs!$B$12,Inputs!$B$13)))))) -> 0.95 | G15: =IF(A15="","",N15) -> 8.2683333 | H15: =IF(A15="","",Inputs!$B$3/((IF(G15="",Inputs!$B$14,G15)+Inputs!$B$4)^Inputs!$B$5)) -> 102.30247 | I15: =IF(A15="","",0.000000278*F15*D15*H15) -> 0.00015670488 | J15: E03 | K15: Surface pavage petite zone sud-est (pas tresfond). | L15: 8 | M15: =IF(A15="","",IF(OR(J15="",Inputs!$B$59=""),0,IFERROR(INDEX(Elements_hybrides!$F$4:$F$204,MATCH(J15,Elements_hybrides!$A$4:$A$204,0))/(Inputs!$B$59*60),0))) -> 0.26833333 | N15: =IF(A15="","",IF(L15="",Inputs!$B$14,L15)+M15) -> 8.2683333
A16: Z13 | B16: Petit strip vert nord (vers puisard PEHD central) | C16: GRASS | D16: 40.8 | F16: =IF(E16<>"",E16,IF(UPPER(TRIM(C16))="BASIN",IF(UPPER(TRIM(Inputs!$B$52))="YES",Inputs!$B$12,0),IF(UPPER(TRIM(C16))="ROOF",Inputs!$B$10,IF(UPPER(TRIM(C16))="PAVAGE",Inputs!$B$58,IF(UPPER(TRIM(C16))="TRESFOND",Inputs!$B$11,IF(UPPER(TRIM(C16))="GRASS",Inputs!$B$12,Inputs!$B$13)))))) -> 0.25 | G16: =IF(A16="","",N16) -> 7.2 | H16: =IF(A16="","",Inputs!$B$3/((IF(G16="",Inputs!$B$14,G16)+Inputs!$B$4)^Inputs!$B$5)) -> 105.39118 | I16: =IF(A16="","",0.000000278*F16*D16*H16) -> 0.00029884724 | J16: E09 | K16: Devie vers puisard PEHD central puis reseau interne mecanique vers bassin (pas via bande est). | M16: =IF(A16="","",IF(OR(J16="",Inputs!$B$59=""),0,IFERROR(INDEX(Elements_hybrides!$F$4:$F$204,MATCH(J16,Elements_hybrides!$A$4:$A$204,0))/(Inputs!$B$59*60),0))) -> 0.2 | N16: =IF(A16="","",IF(L16="",Inputs!$B$14,L16)+M16) -> 7.2
D17: =SUM(D4:D16) -> 1746.7 | F17: =IF(E17<>"",E17,IF(UPPER(TRIM(C17))="BASIN",IF(UPPER(TRIM(Inputs!$B$52))="YES",Inputs!$B$12,0),IF(UPPER(TRIM(C17))="ROOF",Inputs!$B$10,IF(UPPER(TRIM(C17))="PAVAGE",Inputs!$B$58,IF(UPPER(TRIM(C17))="TRESFOND",Inputs!$B$11,IF(UPPER(TRIM(C17))="GRASS",Inputs!$B$12,Inputs!$B$13)))))) -> 0.6 | G17: =IF(A17="","",N17) | H17: =IF(A17="","",Inputs!$B$3/((IF(G17="",Inputs!$B$14,G17)+Inputs!$B$4)^Inputs!$B$5)) | I17: =IF(A17="","",0.000000278*F17*D17*H17) | M17: =IF(A17="","",IF(OR(J17="",Inputs!$B$59=""),0,IFERROR(INDEX(Elements_hybrides!$F$4:$F$204,MATCH(J17,Elements_hybrides!$A$4:$A$204,0))/(Inputs!$B$59*60),0))) | N17: =IF(A17="","",IF(L17="",Inputs!$B$14,L17)+M17)
F18: =IF(E18<>"",E18,IF(UPPER(TRIM(C18))="BASIN",IF(UPPER(TRIM(Inputs!$B$52))="YES",Inputs!$B$12,0),IF(UPPER(TRIM(C18))="ROOF",Inputs!$B$10,IF(UPPER(TRIM(C18))="PAVAGE",Inputs!$B$58,IF(UPPER(TRIM(C18))="TRESFOND",Inputs!$B$11,IF(UPPER(TRIM(C18))="GRASS",Inputs!$B$12,Inputs!$B$13)))))) -> 0.6 | G18: =IF(A18="","",N18) | H18: =IF(A18="","",Inputs!$B$3/((IF(G18="",Inputs!$B$14,G18)+Inputs!$B$4)^Inputs!$B$5)) | I18: =IF(A18="","",0.000000278*F18*D18*H18) | M18: =IF(A18="","",IF(OR(J18="",Inputs!$B$59=""),0,IFERROR(INDEX(Elements_hybrides!$F$4:$F$204,MATCH(J18,Elements_hybrides!$A$4:$A$204,0))/(Inputs!$B$59*60),0))) | N18: =IF(A18="","",IF(L18="",Inputs!$B$14,L18)+M18)
C19: grass | D19: =D6+D7+D9+D11+D14 -> 246.8 | F19: =IF(E19<>"",E19,IF(UPPER(TRIM(C19))="BASIN",IF(UPPER(TRIM(Inputs!$B$52))="YES",Inputs!$B$12,0),IF(UPPER(TRIM(C19))="ROOF",Inputs!$B$10,IF(UPPER(TRIM(C19))="PAVAGE",Inputs!$B$58,IF(UPPER(TRIM(C19))="TRESFOND",Inputs!$B$11,IF(UPPER(TRIM(C19))="GRASS",Inputs!$B$12,Inputs!$B$13)))))) -> 0.25 | G19: =IF(A19="","",N19) | H19: =IF(A19="","",Inputs!$B$3/((IF(G19="",Inputs!$B$14,G19)+Inputs!$B$4)^Inputs!$B$5)) | I19: =IF(A19="","",0.000000278*F19*D19*H19) | M19: =IF(A19="","",IF(OR(J19="",Inputs!$B$59=""),0,IFERROR(INDEX(Elements_hybrides!$F$4:$F$204,MATCH(J19,Elements_hybrides!$A$4:$A$204,0))/(Inputs!$B$59*60),0))) | N19: =IF(A19="","",IF(L19="",Inputs!$B$14,L19)+M19)
C20: pavage | D20: =D8+D10+D13+D15 -> 94.3 | F20: =IF(E20<>"",E20,IF(UPPER(TRIM(C20))="BASIN",IF(UPPER(TRIM(Inputs!$B$52))="YES",Inputs!$B$12,0),IF(UPPER(TRIM(C20))="ROOF",Inputs!$B$10,IF(UPPER(TRIM(C20))="PAVAGE",Inputs!$B$58,IF(UPPER(TRIM(C20))="TRESFOND",Inputs!$B$11,IF(UPPER(TRIM(C20))="GRASS",Inputs!$B$12,Inputs!$B$13)))))) -> 0.95 | G20: =IF(A20="","",N20) | H20: =IF(A20="","",Inputs!$B$3/((IF(G20="",Inputs!$B$14,G20)+Inputs!$B$4)^Inputs!$B$5)) | I20: =IF(A20="","",0.000000278*F20*D20*H20) | M20: =IF(A20="","",IF(OR(J20="",Inputs!$B$59=""),0,IFERROR(INDEX(Elements_hybrides!$F$4:$F$204,MATCH(J20,Elements_hybrides!$A$4:$A$204,0))/(Inputs!$B$59*60),0))) | N20: =IF(A20="","",IF(L20="",Inputs!$B$14,L20)+M20)
F21: =IF(E21<>"",E21,IF(UPPER(TRIM(C21))="BASIN",IF(UPPER(TRIM(Inputs!$B$52))="YES",Inputs!$B$12,0),IF(UPPER(TRIM(C21))="ROOF",Inputs!$B$10,IF(UPPER(TRIM(C21))="PAVAGE",Inputs!$B$58,IF(UPPER(TRIM(C21))="TRESFOND",Inputs!$B$11,IF(UPPER(TRIM(C21))="GRASS",Inputs!$B$12,Inputs!$B$13)))))) -> 0.6 | G21: =IF(A21="","",N21) | H21: =IF(A21="","",Inputs!$B$3/((IF(G21="",Inputs!$B$14,G21)+Inputs!$B$4)^Inputs!$B$5)) | I21: =IF(A21="","",0.000000278*F21*D21*H21) | M21: =IF(A21="","",IF(OR(J21="",Inputs!$B$59=""),0,IFERROR(INDEX(Elements_hybrides!$F$4:$F$204,MATCH(J21,Elements_hybrides!$A$4:$A$204,0))/(Inputs!$B$59*60),0))) | N21: =IF(A21="","",IF(L21="",Inputs!$B$14,L21)+M21)
B22: empreinte bassin | D22: 109.7 | F22: =IF(E22<>"",E22,IF(UPPER(TRIM(C22))="BASIN",IF(UPPER(TRIM(Inputs!$B$52))="YES",Inputs!$B$12,0),IF(UPPER(TRIM(C22))="ROOF",Inputs!$B$10,IF(UPPER(TRIM(C22))="PAVAGE",Inputs!$B$58,IF(UPPER(TRIM(C22))="TRESFOND",Inputs!$B$11,IF(UPPER(TRIM(C22))="GRASS",Inputs!$B$12,Inputs!$B$13)))))) -> 0.6 | G22: =IF(A22="","",N22) | H22: =IF(A22="","",Inputs!$B$3/((IF(G22="",Inputs!$B$14,G22)+Inputs!$B$4)^Inputs!$B$5)) | I22: =IF(A22="","",0.000000278*F22*D22*H22) | M22: =IF(A22="","",IF(OR(J22="",Inputs!$B$59=""),0,IFERROR(INDEX(Elements_hybrides!$F$4:$F$204,MATCH(J22,Elements_hybrides!$A$4:$A$204,0))/(Inputs!$B$59*60),0))) | N22: =IF(A22="","",IF(L22="",Inputs!$B$14,L22)+M22)
F23: =IF(E23<>"",E23,IF(UPPER(TRIM(C23))="BASIN",IF(UPPER(TRIM(Inputs!$B$52))="YES",Inputs!$B$12,0),IF(UPPER(TRIM(C23))="ROOF",Inputs!$B$10,IF(UPPER(TRIM(C23))="PAVAGE",Inputs!$B$58,IF(UPPER(TRIM(C23))="TRESFOND",Inputs!$B$11,IF(UPPER(TRIM(C23))="GRASS",Inputs!$B$12,Inputs!$B$13)))))) -> 0.6 | G23: =IF(A23="","",N23) | H23: =IF(A23="","",Inputs!$B$3/((IF(G23="",Inputs!$B$14,G23)+Inputs!$B$4)^Inputs!$B$5)) | I23: =IF(A23="","",0.000000278*F23*D23*H23) | M23: =IF(A23="","",IF(OR(J23="",Inputs!$B$59=""),0,IFERROR(INDEX(Elements_hybrides!$F$4:$F$204,MATCH(J23,Elements_hybrides!$A$4:$A$204,0))/(Inputs!$B$59*60),0))) | N23: =IF(A23="","",IF(L23="",Inputs!$B$14,L23)+M23)
F24: =IF(E24<>"",E24,IF(UPPER(TRIM(C24))="BASIN",IF(UPPER(TRIM(Inputs!$B$52))="YES",Inputs!$B$12,0),IF(UPPER(TRIM(C24))="ROOF",Inputs!$B$10,IF(UPPER(TRIM(C24))="PAVAGE",Inputs!$B$58,IF(UPPER(TRIM(C24))="TRESFOND",Inputs!$B$11,IF(UPPER(TRIM(C24))="GRASS",Inputs!$B$12,Inputs!$B$13)))))) -> 0.6 | G24: =IF(A24="","",N24) | H24: =IF(A24="","",Inputs!$B$3/((IF(G24="",Inputs!$B$14,G24)+Inputs!$B$4)^Inputs!$B$5)) | I24: =IF(A24="","",0.000000278*F24*D24*H24) | M24: =IF(A24="","",IF(OR(J24="",Inputs!$B$59=""),0,IFERROR(INDEX(Elements_hybrides!$F$4:$F$204,MATCH(J24,Elements_hybrides!$A$4:$A$204,0))/(Inputs!$B$59*60),0))) | N24: =IF(A24="","",IF(L24="",Inputs!$B$14,L24)+M24)
F25: =IF(E25<>"",E25,IF(UPPER(TRIM(C25))="BASIN",IF(UPPER(TRIM(Inputs!$B$52))="YES",Inputs!$B$12,0),IF(UPPER(TRIM(C25))="ROOF",Inputs!$B$10,IF(UPPER(TRIM(C25))="PAVAGE",Inputs!$B$58,IF(UPPER(TRIM(C25))="TRESFOND",Inputs!$B$11,IF(UPPER(TRIM(C25))="GRASS",Inputs!$B$12,Inputs!$B$13)))))) -> 0.6 | G25: =IF(A25="","",N25) | H25: =IF(A25="","",Inputs!$B$3/((IF(G25="",Inputs!$B$14,G25)+Inputs!$B$4)^Inputs!$B$5)) | I25: =IF(A25="","",0.000000278*F25*D25*H25) | M25: =IF(A25="","",IF(OR(J25="",Inputs!$B$59=""),0,IFERROR(INDEX(Elements_hybrides!$F$4:$F$204,MATCH(J25,Elements_hybrides!$A$4:$A$204,0))/(Inputs!$B$59*60),0))) | N25: =IF(A25="","",IF(L25="",Inputs!$B$14,L25)+M25)
F26: =IF(E26<>"",E26,IF(UPPER(TRIM(C26))="BASIN",IF(UPPER(TRIM(Inputs!$B$52))="YES",Inputs!$B$12,0),IF(UPPER(TRIM(C26))="ROOF",Inputs!$B$10,IF(UPPER(TRIM(C26))="PAVAGE",Inputs!$B$58,IF(UPPER(TRIM(C26))="TRESFOND",Inputs!$B$11,IF(UPPER(TRIM(C26))="GRASS",Inputs!$B$12,Inputs!$B$13)))))) -> 0.6 | G26: =IF(A26="","",N26) | H26: =IF(A26="","",Inputs!$B$3/((IF(G26="",Inputs!$B$14,G26)+Inputs!$B$4)^Inputs!$B$5)) | I26: =IF(A26="","",0.000000278*F26*D26*H26) | M26: =IF(A26="","",IF(OR(J26="",Inputs!$B$59=""),0,IFERROR(INDEX(Elements_hybrides!$F$4:$F$204,MATCH(J26,Elements_hybrides!$A$4:$A$204,0))/(Inputs!$B$59*60),0))) | N26: =IF(A26="","",IF(L26="",Inputs!$B$14,L26)+M26)
F27: =IF(E27<>"",E27,IF(UPPER(TRIM(C27))="BASIN",IF(UPPER(TRIM(Inputs!$B$52))="YES",Inputs!$B$12,0),IF(UPPER(TRIM(C27))="ROOF",Inputs!$B$10,IF(UPPER(TRIM(C27))="PAVAGE",Inputs!$B$58,IF(UPPER(TRIM(C27))="TRESFOND",Inputs!$B$11,IF(UPPER(TRIM(C27))="GRASS",Inputs!$B$12,Inputs!$B$13)))))) -> 0.6 | G27: =IF(A27="","",N27) | H27: =IF(A27="","",Inputs!$B$3/((IF(G27="",Inputs!$B$14,G27)+Inputs!$B$4)^Inputs!$B$5)) | I27: =IF(A27="","",0.000000278*F27*D27*H27) | M27: =IF(A27="","",IF(OR(J27="",Inputs!$B$59=""),0,IFERROR(INDEX(Elements_hybrides!$F$4:$F$204,MATCH(J27,Elements_hybrides!$A$4:$A$204,0))/(Inputs!$B$59*60),0))) | N27: =IF(A27="","",IF(L27="",Inputs!$B$14,L27)+M27)
F28: =IF(E28<>"",E28,IF(UPPER(TRIM(C28))="BASIN",IF(UPPER(TRIM(Inputs!$B$52))="YES",Inputs!$B$12,0),IF(UPPER(TRIM(C28))="ROOF",Inputs!$B$10,IF(UPPER(TRIM(C28))="PAVAGE",Inputs!$B$58,IF(UPPER(TRIM(C28))="TRESFOND",Inputs!$B$11,IF(UPPER(TRIM(C28))="GRASS",Inputs!$B$12,Inputs!$B$13)))))) -> 0.6 | G28: =IF(A28="","",N28) | H28: =IF(A28="","",Inputs!$B$3/((IF(G28="",Inputs!$B$14,G28)+Inputs!$B$4)^Inputs!$B$5)) | I28: =IF(A28="","",0.000000278*F28*D28*H28) | M28: =IF(A28="","",IF(OR(J28="",Inputs!$B$59=""),0,IFERROR(INDEX(Elements_hybrides!$F$4:$F$204,MATCH(J28,Elements_hybrides!$A$4:$A$204,0))/(Inputs!$B$59*60),0))) | N28: =IF(A28="","",IF(L28="",Inputs!$B$14,L28)+M28)
F29: =IF(E29<>"",E29,IF(UPPER(TRIM(C29))="BASIN",IF(UPPER(TRIM(Inputs!$B$52))="YES",Inputs!$B$12,0),IF(UPPER(TRIM(C29))="ROOF",Inputs!$B$10,IF(UPPER(TRIM(C29))="PAVAGE",Inputs!$B$58,IF(UPPER(TRIM(C29))="TRESFOND",Inputs!$B$11,IF(UPPER(TRIM(C29))="GRASS",Inputs!$B$12,Inputs!$B$13)))))) -> 0.6 | G29: =IF(A29="","",N29) | H29: =IF(A29="","",Inputs!$B$3/((IF(G29="",Inputs!$B$14,G29)+Inputs!$B$4)^Inputs!$B$5)) | I29: =IF(A29="","",0.000000278*F29*D29*H29) | M29: =IF(A29="","",IF(OR(J29="",Inputs!$B$59=""),0,IFERROR(INDEX(Elements_hybrides!$F$4:$F$204,MATCH(J29,Elements_hybrides!$A$4:$A$204,0))/(Inputs!$B$59*60),0))) | N29: =IF(A29="","",IF(L29="",Inputs!$B$14,L29)+M29)
F30: =IF(E30<>"",E30,IF(UPPER(TRIM(C30))="BASIN",IF(UPPER(TRIM(Inputs!$B$52))="YES",Inputs!$B$12,0),IF(UPPER(TRIM(C30))="ROOF",Inputs!$B$10,IF(UPPER(TRIM(C30))="PAVAGE",Inputs!$B$58,IF(UPPER(TRIM(C30))="TRESFOND",Inputs!$B$11,IF(UPPER(TRIM(C30))="GRASS",Inputs!$B$12,Inputs!$B$13)))))) -> 0.6 | G30: =IF(A30="","",N30) | H30: =IF(A30="","",Inputs!$B$3/((IF(G30="",Inputs!$B$14,G30)+Inputs!$B$4)^Inputs!$B$5)) | I30: =IF(A30="","",0.000000278*F30*D30*H30) | M30: =IF(A30="","",IF(OR(J30="",Inputs!$B$59=""),0,IFERROR(INDEX(Elements_hybrides!$F$4:$F$204,MATCH(J30,Elements_hybrides!$A$4:$A$204,0))/(Inputs!$B$59*60),0))) | N30: =IF(A30="","",IF(L30="",Inputs!$B$14,L30)+M30)
F31: =IF(E31<>"",E31,IF(UPPER(TRIM(C31))="BASIN",IF(UPPER(TRIM(Inputs!$B$52))="YES",Inputs!$B$12,0),IF(UPPER(TRIM(C31))="ROOF",Inputs!$B$10,IF(UPPER(TRIM(C31))="PAVAGE",Inputs!$B$58,IF(UPPER(TRIM(C31))="TRESFOND",Inputs!$B$11,IF(UPPER(TRIM(C31))="GRASS",Inputs!$B$12,Inputs!$B$13)))))) -> 0.6 | G31: =IF(A31="","",N31) | H31: =IF(A31="","",Inputs!$B$3/((IF(G31="",Inputs!$B$14,G31)+Inputs!$B$4)^Inputs!$B$5)) | I31: =IF(A31="","",0.000000278*F31*D31*H31) | M31: =IF(A31="","",IF(OR(J31="",Inputs!$B$59=""),0,IFERROR(INDEX(Elements_hybrides!$F$4:$F$204,MATCH(J31,Elements_hybrides!$A$4:$A$204,0))/(Inputs!$B$59*60),0))) | N31: =IF(A31="","",IF(L31="",Inputs!$B$14,L31)+M31)
F32: =IF(E32<>"",E32,IF(UPPER(TRIM(C32))="BASIN",IF(UPPER(TRIM(Inputs!$B$52))="YES",Inputs!$B$12,0),IF(UPPER(TRIM(C32))="ROOF",Inputs!$B$10,IF(UPPER(TRIM(C32))="PAVAGE",Inputs!$B$58,IF(UPPER(TRIM(C32))="TRESFOND",Inputs!$B$11,IF(UPPER(TRIM(C32))="GRASS",Inputs!$B$12,Inputs!$B$13)))))) -> 0.6 | G32: =IF(A32="","",N32) | H32: =IF(A32="","",Inputs!$B$3/((IF(G32="",Inputs!$B$14,G32)+Inputs!$B$4)^Inputs!$B$5)) | I32: =IF(A32="","",0.000000278*F32*D32*H32) | M32: =IF(A32="","",IF(OR(J32="",Inputs!$B$59=""),0,IFERROR(INDEX(Elements_hybrides!$F$4:$F$204,MATCH(J32,Elements_hybrides!$A$4:$A$204,0))/(Inputs!$B$59*60),0))) | N32: =IF(A32="","",IF(L32="",Inputs!$B$14,L32)+M32)
F33: =IF(E33<>"",E33,IF(UPPER(TRIM(C33))="BASIN",IF(UPPER(TRIM(Inputs!$B$52))="YES",Inputs!$B$12,0),IF(UPPER(TRIM(C33))="ROOF",Inputs!$B$10,IF(UPPER(TRIM(C33))="PAVAGE",Inputs!$B$58,IF(UPPER(TRIM(C33))="TRESFOND",Inputs!$B$11,IF(UPPER(TRIM(C33))="GRASS",Inputs!$B$12,Inputs!$B$13)))))) -> 0.6 | G33: =IF(A33="","",N33) | H33: =IF(A33="","",Inputs!$B$3/((IF(G33="",Inputs!$B$14,G33)+Inputs!$B$4)^Inputs!$B$5)) | I33: =IF(A33="","",0.000000278*F33*D33*H33) | M33: =IF(A33="","",IF(OR(J33="",Inputs!$B$59=""),0,IFERROR(INDEX(Elements_hybrides!$F$4:$F$204,MATCH(J33,Elements_hybrides!$A$4:$A$204,0))/(Inputs!$B$59*60),0))) | N33: =IF(A33="","",IF(L33="",Inputs!$B$14,L33)+M33)
F34: =IF(E34<>"",E34,IF(UPPER(TRIM(C34))="BASIN",IF(UPPER(TRIM(Inputs!$B$52))="YES",Inputs!$B$12,0),IF(UPPER(TRIM(C34))="ROOF",Inputs!$B$10,IF(UPPER(TRIM(C34))="PAVAGE",Inputs!$B$58,IF(UPPER(TRIM(C34))="TRESFOND",Inputs!$B$11,IF(UPPER(TRIM(C34))="GRASS",Inputs!$B$12,Inputs!$B$13)))))) -> 0.6 | G34: =IF(A34="","",N34) | H34: =IF(A34="","",Inputs!$B$3/((IF(G34="",Inputs!$B$14,G34)+Inputs!$B$4)^Inputs!$B$5)) | I34: =IF(A34="","",0.000000278*F34*D34*H34) | M34: =IF(A34="","",IF(OR(J34="",Inputs!$B$59=""),0,IFERROR(INDEX(Elements_hybrides!$F$4:$F$204,MATCH(J34,Elements_hybrides!$A$4:$A$204,0))/(Inputs!$B$59*60),0))) | N34: =IF(A34="","",IF(L34="",Inputs!$B$14,L34)+M34)
... F204: =IF(E204<>"",E204,IF(UPPER(TRIM(C204))="BASIN",IF(UPPER(TRIM(Inputs!$B$52))="YES",Inputs!$B$12,0),IF(UPPER(TRIM(C204))="ROOF",Inputs!$B$10,IF(UPPER(TRIM(C204))="PAVAGE",Inputs!$B$58,IF(UPPER(TRIM(C204))="TRESFOND",Inputs!$B$11,IF(UPPER(TRIM(C204))="GRASS",Inputs!$B$12,Inputs!$B$13)))))) -> 0.6 | G204: =IF(A204="","",N204) | H204: =IF(A204="","",Inputs!$B$3/((IF(G204="",Inputs!$B$14,G204)+Inputs!$B$4)^Inputs!$B$5)) | I204: =IF(A204="","",0.000000278*F204*D204*H204) | M204: =IF(A204="","",IF(OR(J204="",Inputs!$B$59=""),0,IFERROR(INDEX(Elements_hybrides!$F$4:$F$204,MATCH(J204,Elements_hybrides!$A$4:$A$204,0))/(Inputs!$B$59*60),0))) | N204: =IF(A204="","",IF(L204="",Inputs!$B$14,L204)+M204)

Sheet Elements_hybrides
A1: DIMENSIONNEMENT ELEMENTS HYBRIDES (PIPE / SWALE / TRENCH)
A2: Legend: PIPE=blue, SWALE=green, TRENCH=orange, CHECK=red; AH connection status and AL drop check use Inputs!B54:B56 thresholds.
A3: Element_ID | B3: Type | C3: From_Node | D3: To_Node | E3: Receives_into_Element_ID | F3: Length_m | G3: Slope_m/m | H3: n_override | I3: n_used | J3: Dia_pipe_mm | K3: Base_width_m | L3: Flow_depth_m | M3: Side_slope_z | N3: Porosity_trench | O3: Q_local_from_zones_m3s | P3: Q_upstream_m3s | Q3: Q_design_m3s | R3: Area_flow_m2 | S3: Hydraulic_radius_m | T3: Capacity_m3s | U3: Q_over_capacity_ratio | V3: Velocity_design_QA_mps | W3: Velocity_manning_mps | X3: Velocity_used_mps | Y3: Storage_per_m_m3 | Z3: Storage_total_m3 | AA3: Check | AB3: Notes | AC3: Invert_down_override_m | AD3: Invert_down_used_m | AE3: Invert_up_m | AF3: Downstream_invert_up_m | AG3: Connection_delta_m | AH3: Connection_status | AI3: Downstream_type | AJ3: Drop_min_req_m | AK3: Drop_max_req_m | AL3: Drop_check_status
A4: E01 | B4: TRENCH | C4: P-01 | D4: P-02 | E4: E02 | F4: 9.6 | G4: =Inputs!$B$33 -> 0.008 | I4: =IF(A4="","",IF(H4<>"",H4,IF(UPPER(TRIM(B4))="PIPE",Inputs!$B$7,IF(UPPER(TRIM(B4))="SWALE",Inputs!$B$8,Inputs!$B$9)))) -> 0.028 | J4: =Inputs!$B$30 -> 200 | K4: =Inputs!$B$28 -> 0.35 | L4: =Inputs!$B$29 -> 0.7 | M4: 0 | N4: =Inputs!$B$22 -> 0.35 | O4: =IF(A4="","",SUMIFS(Zones_tributaires!$I:$I,Zones_tributaires!$J:$J,$A4)) -> 0 | P4: =IF(A4="","",SUMIFS($Q$4:$Q$204,$E$4:$E$204,$A4)) -> 0 | Q4: =IF(A4="","",(O4+P4)*Inputs!$B$6) -> 0 | R4: =IF(A4="","",IF(UPPER(TRIM(B4))="PIPE",PI()*(J4/1000)^2/4,IF(OR(K4="",L4=""),"",L4*(K4+M4*L4)))) -> 0.245 | S4: =IF(A4="","",IF(UPPER(TRIM(B4))="PIPE",(J4/1000)/4,IF(OR(R4="",K4="",L4=""),"",R4/(K4+2*L4*SQRT(1+M4^2))))) -> 0.14 | T4: =IF(A4="","",IF(OR(I4="",R4="",S4="",G4=""),"",(1/I4)*R4*(S4^(2/3))*SQRT(G4))) -> 0.21101099 | U4: =IF(OR(T4="",Q4=""),"",Q4/(T4*Inputs!$B$19)) -> 0 | V4: =IF(OR(R4="",Q4=""),"",Q4/R4) -> 0 | W4: =IF(OR(R4="",T4=""),"",T4/R4) -> 0.86126934 | X4: =IF(A4="","",IF(OR(UPPER(TRIM(Inputs!$B$15))="MANNING",UPPER(TRIM(Inputs!$B$15))="M"),W4,IF(OR(UPPER(TRIM(Inputs!$B$15))="MAX",UPPER(TRIM(Inputs!$B$15))="X"),MAX(V4,W4),V4))) -> 0.86126934 | Y4: =IF(A4="","",IF(UPPER(TRIM(B4))="TRENCH",K4*L4*N4,IF(UPPER(TRIM(B4))="SWALE",K4*L4,0))) -> 0.08575 | Z4: =IF(OR(Y4="",F4=""),"",Y4*F4) -> 0.8232 | AA4: =IF(A4="","",IF(OR(U4>1,AND(X4<>"",X4<Inputs!$B$16),AND(X4<>"",X4>Inputs!$B$17),G4<Inputs!$B$18,AH4="CHECK"),"CHECK","OK")) -> OK | AB4: Longueur corrigee selon plan: P-01 -> P-02 = 9.6 m. | AD4: =IF(A4="","",IF(AC4<>"",AC4,IF(E4="",Inputs!$B$38,IFERROR(INDEX($AE$4:$AE$204,MATCH(E4,$A$4:$A$204,0))+IF(OR(AND(UPPER(TRIM(B4))="SWALE",UPPER(TRIM(AI4))="PIPE"),AND(UPPER(TRIM(B4))="TRENCH",UPPER(TRIM(AI4))="PIPE")),Inputs!$B$57,0),"")))) -> 21.8912 | AE4: =IF(OR(AD4="",F4="",G4=""),"",AD4+F4*G4) -> 21.968 | AF4: =IF(OR(E4="",A4=""),"",IFERROR(INDEX($AE$4:$AE$204,MATCH(E4,$A$4:$A$204,0)),"")) -> 21.8912 | AG4: =IF(OR(AD4="",AF4=""),"",AD4-AF4) -> 0 | AH4: =IF(A4="","",IF(E4="","TERMINAL",IF(OR(AND(UPPER(TRIM(B4))="SWALE",UPPER(TRIM(AI4))="PIPE"),AND(UPPER(TRIM(B4))="TRENCH",UPPER(TRIM(AI4))="PIPE")),IF(OR(AG4="",AJ4="",AK4=""),"INFO",IF(AND(AG4>=AJ4,AG4<=AK4),"OK","CHECK")),IF(AG4="","INFO",IF(ABS(AG4)<=Inputs!$B$54,"OK","CHECK"))))) -> OK | AI4: =IF(A4="","",IF(E4="","",IFERROR(INDEX($B$4:$B$204,MATCH(E4,$A$4:$A$204,0)),""))) -> TRENCH | AJ4: =IF(A4="","",IF(OR(AND(UPPER(TRIM(B4))="SWALE",UPPER(TRIM(AI4))="PIPE"),AND(UPPER(TRIM(B4))="TRENCH",UPPER(TRIM(AI4))="PIPE")),Inputs!$B$55,0)) -> 0 | AK4: =IF(A4="","",IF(OR(AND(UPPER(TRIM(B4))="SWALE",UPPER(TRIM(AI4))="PIPE"),AND(UPPER(TRIM(B4))="TRENCH",UPPER(TRIM(AI4))="PIPE")),Inputs!$B$56,Inputs!$B$54)) -> 0.01 | AL4: =IF(A4="","",IF(E4="","TERMINAL",IF(OR(AND(UPPER(TRIM(B4))="SWALE",UPPER(TRIM(AI4))="PIPE"),AND(UPPER(TRIM(B4))="TRENCH",UPPER(TRIM(AI4))="PIPE")),IF(OR(AG4="",AJ4="",AK4=""),"INFO",IF(AND(AG4>=AJ4,AG4<=AK4),"OK","CHECK")),"N/A"))) -> N/A
A5: E02 | B5: TRENCH | C5: P-02 | D5: P-03 | E5: E03 | F5: 8.7 | G5: =Inputs!$B$33 -> 0.008 | I5: =IF(A5="","",IF(H5<>"",H5,IF(UPPER(TRIM(B5))="PIPE",Inputs!$B$7,IF(UPPER(TRIM(B5))="SWALE",Inputs!$B$8,Inputs!$B$9)))) -> 0.028 | J5: =Inputs!$B$30 -> 200 | K5: =Inputs!$B$28 -> 0.35 | L5: =Inputs!$B$29 -> 0.7 | M5: 0 | N5: =Inputs!$B$22 -> 0.35 | O5: =IF(A5="","",SUMIFS(Zones_tributaires!$I:$I,Zones_tributaires!$J:$J,$A5)) -> 0 | P5: =IF(A5="","",SUMIFS($Q$4:$Q$204,$E$4:$E$204,$A5)) -> 0 | Q5: =IF(A5="","",(O5+P5)*Inputs!$B$6) -> 0 | R5: =IF(A5="","",IF(UPPER(TRIM(B5))="PIPE",PI()*(J5/1000)^2/4,IF(OR(K5="",L5=""),"",L5*(K5+M5*L5)))) -> 0.245 | S5: =IF(A5="","",IF(UPPER(TRIM(B5))="PIPE",(J5/1000)/4,IF(OR(R5="",K5="",L5=""),"",R5/(K5+2*L5*SQRT(1+M5^2))))) -> 0.14 | T5: =IF(A5="","",IF(OR(I5="",R5="",S5="",G5=""),"",(1/I5)*R5*(S5^(2/3))*SQRT(G5))) -> 0.21101099 | U5: =IF(OR(T5="",Q5=""),"",Q5/(T5*Inputs!$B$19)) -> 0 | V5: =IF(OR(R5="",Q5=""),"",Q5/R5) -> 0 | W5: =IF(OR(R5="",T5=""),"",T5/R5) -> 0.86126934 | X5: =IF(A5="","",IF(OR(UPPER(TRIM(Inputs!$B$15))="MANNING",UPPER(TRIM(Inputs!$B$15))="M"),W5,IF(OR(UPPER(TRIM(Inputs!$B$15))="MAX",UPPER(TRIM(Inputs!$B$15))="X"),MAX(V5,W5),V5))) -> 0.86126934 | Y5: =IF(A5="","",IF(UPPER(TRIM(B5))="TRENCH",K5*L5*N5,IF(UPPER(TRIM(B5))="SWALE",K5*L5,0))) -> 0.08575 | Z5: =IF(OR(Y5="",F5=""),"",Y5*F5) -> 0.746025 | AA5: =IF(A5="","",IF(OR(U5>1,AND(X5<>"",X5<Inputs!$B$16),AND(X5<>"",X5>Inputs!$B$17),G5<Inputs!$B$18,AH5="CHECK"),"CHECK","OK")) -> OK | AB5: Longueur corrigee selon plan: P-02 -> P-03 = 8.7 m. | AD5: =IF(A5="","",IF(AC5<>"",AC5,IF(E5="",Inputs!$B$38,IFERROR(INDEX($AE$4:$AE$204,MATCH(E5,$A$4:$A$204,0))+IF(OR(AND(UPPER(TRIM(B5))="SWALE",UPPER(TRIM(AI5))="PIPE"),AND(UPPER(TRIM(B5))="TRENCH",UPPER(TRIM(AI5))="PIPE")),Inputs!$B$57,0),"")))) -> 21.8216 | AE5: =IF(OR(AD5="",F5="",G5=""),"",AD5+F5*G5) -> 21.8912 | AF5: =IF(OR(E5="",A5=""),"",IFERROR(INDEX($AE$4:$AE$204,MATCH(E5,$A$4:$A$204,0)),"")) -> 21.7216 | AG5: =IF(OR(AD5="",AF5=""),"",AD5-AF5) -> 0.1 | AH5: =IF(A5="","",IF(E5="","TERMINAL",IF(OR(AND(UPPER(TRIM(B5))="SWALE",UPPER(TRIM(AI5))="PIPE"),AND(UPPER(TRIM(B5))="TRENCH",UPPER(TRIM(AI5))="PIPE")),IF(OR(AG5="",AJ5="",AK5=""),"INFO",IF(AND(AG5>=AJ5,AG5<=AK5),"OK","CHECK")),IF(AG5="","INFO",IF(ABS(AG5)<=Inputs!$B$54,"OK","CHECK"))))) -> OK | AI5: =IF(A5="","",IF(E5="","",IFERROR(INDEX($B$4:$B$204,MATCH(E5,$A$4:$A$204,0)),""))) -> PIPE | AJ5: =IF(A5="","",IF(OR(AND(UPPER(TRIM(B5))="SWALE",UPPER(TRIM(AI5))="PIPE"),AND(UPPER(TRIM(B5))="TRENCH",UPPER(TRIM(AI5))="PIPE")),Inputs!$B$55,0)) -> 0.05 | AK5: =IF(A5="","",IF(OR(AND(UPPER(TRIM(B5))="SWALE",UPPER(TRIM(AI5))="PIPE"),AND(UPPER(TRIM(B5))="TRENCH",UPPER(TRIM(AI5))="PIPE")),Inputs!$B$56,Inputs!$B$54)) -> 0.3 | AL5: =IF(A5="","",IF(E5="","TERMINAL",IF(OR(AND(UPPER(TRIM(B5))="SWALE",UPPER(TRIM(AI5))="PIPE"),AND(UPPER(TRIM(B5))="TRENCH",UPPER(TRIM(AI5))="PIPE")),IF(OR(AG5="",AJ5="",AK5=""),"INFO",IF(AND(AG5>=AJ5,AG5<=AK5),"OK","CHECK")),"N/A"))) -> OK
A6: E03 | B6: PIPE | C6: P-03 | D6: J-BASSIN-IN | E6: E07 | F6: 16.1 | G6: 0.006 | I6: =IF(A6="","",IF(H6<>"",H6,IF(UPPER(TRIM(B6))="PIPE",Inputs!$B$7,IF(UPPER(TRIM(B6))="SWALE",Inputs!$B$8,Inputs!$B$9)))) -> 0.013 | J6: 200 | N6: 0 | O6: =IF(A6="","",SUMIFS(Zones_tributaires!$I:$I,Zones_tributaires!$J:$J,$A6)) -> 0.0028949371 | P6: =IF(A6="","",SUMIFS($Q$4:$Q$204,$E$4:$E$204,$A6)) -> 0 | Q6: =IF(A6="","",(O6+P6)*Inputs!$B$6) -> 0.0031844308 | R6: =IF(A6="","",IF(UPPER(TRIM(B6))="PIPE",PI()*(J6/1000)^2/4,IF(OR(K6="",L6=""),"",L6*(K6+M6*L6)))) -> 0.031415927 | S6: =IF(A6="","",IF(UPPER(TRIM(B6))="PIPE",(J6/1000)/4,IF(OR(R6="",K6="",L6=""),"",R6/(K6+2*L6*SQRT(1+M6^2))))) -> 0.05 | T6: =IF(A6="","",IF(OR(I6="",R6="",S6="",G6=""),"",(1/I6)*R6*(S6^(2/3))*SQRT(G6))) -> 0.025405563 | U6: =IF(OR(T6="",Q6=""),"",Q6/(T6*Inputs!$B$19)) -> 0.1566798 | V6: =IF(OR(R6="",Q6=""),"",Q6/R6) -> 0.10136358 | W6: =IF(OR(R6="",T6=""),"",T6/R6) -> 0.80868417 | X6: =IF(A6="","",IF(OR(UPPER(TRIM(Inputs!$B$15))="MANNING",UPPER(TRIM(Inputs!$B$15))="M"),W6,IF(OR(UPPER(TRIM(Inputs!$B$15))="MAX",UPPER(TRIM(Inputs!$B$15))="X"),MAX(V6,W6),V6))) -> 0.80868417 | Y6: =IF(A6="","",IF(UPPER(TRIM(B6))="TRENCH",K6*L6*N6,IF(UPPER(TRIM(B6))="SWALE",K6*L6,0))) -> 0 | Z6: =IF(OR(Y6="",F6=""),"",Y6*F6) -> 0 | AA6: =IF(A6="","",IF(OR(U6>1,AND(X6<>"",X6<Inputs!$B$16),AND(X6<>"",X6>Inputs!$B$17),G6<Inputs!$B$18,AH6="CHECK"),"CHECK","OK")) -> OK | AB6: Entree EST: P-03 -> J-BASSIN-IN (16.1 m). | AD6: =IF(A6="","",IF(AC6<>"",AC6,IF(E6="",Inputs!$B$38,IFERROR(INDEX($AE$4:$AE$204,MATCH(E6,$A$4:$A$204,0))+IF(OR(AND(UPPER(TRIM(B6))="SWALE",UPPER(TRIM(AI6))="PIPE"),AND(UPPER(TRIM(B6))="TRENCH",UPPER(TRIM(AI6))="PIPE")),Inputs!$B$57,0),"")))) -> 21.625 | AE6: =IF(OR(AD6="",F6="",G6=""),"",AD6+F6*G6) -> 21.7216 | AF6: =IF(OR(E6="",A6=""),"",IFERROR(INDEX($AE$4:$AE$204,MATCH(E6,$A$4:$A$204,0)),"")) -> 21.625 | AG6: =IF(OR(AD6="",AF6=""),"",AD6-AF6) -> 0 | AH6: =IF(A6="","",IF(E6="","TERMINAL",IF(OR(AND(UPPER(TRIM(B6))="SWALE",UPPER(TRIM(AI6))="PIPE"),AND(UPPER(TRIM(B6))="TRENCH",UPPER(TRIM(AI6))="PIPE")),IF(OR(AG6="",AJ6="",AK6=""),"INFO",IF(AND(AG6>=AJ6,AG6<=AK6),"OK","CHECK")),IF(AG6="","INFO",IF(ABS(AG6)<=Inputs!$B$54,"OK","CHECK"))))) -> OK | AI6: =IF(A6="","",IF(E6="","",IFERROR(INDEX($B$4:$B$204,MATCH(E6,$A$4:$A$204,0)),""))) -> PIPE | AJ6: =IF(A6="","",IF(OR(AND(UPPER(TRIM(B6))="SWALE",UPPER(TRIM(AI6))="PIPE"),AND(UPPER(TRIM(B6))="TRENCH",UPPER(TRIM(AI6))="PIPE")),Inputs!$B$55,0)) -> 0 | AK6: =IF(A6="","",IF(OR(AND(UPPER(TRIM(B6))="SWALE",UPPER(TRIM(AI6))="PIPE"),AND(UPPER(TRIM(B6))="TRENCH",UPPER(TRIM(AI6))="PIPE")),Inputs!$B$56,Inputs!$B$54)) -> 0.01 | AL6: =IF(A6="","",IF(E6="","TERMINAL",IF(OR(AND(UPPER(TRIM(B6))="SWALE",UPPER(TRIM(AI6))="PIPE"),AND(UPPER(TRIM(B6))="TRENCH",UPPER(TRIM(AI6))="PIPE")),IF(OR(AG6="",AJ6="",AK6=""),"INFO",IF(AND(AG6>=AJ6,AG6<=AK6),"OK","CHECK")),"N/A"))) -> N/A
A7: E04 | B7: PIPE | C7: J-OUEST-AVAL | D7: J-BASSIN-OUEST | E7: E08 | F7: =Inputs!$B$53 -> 4.7 | G7: 0.004 | I7: =IF(A7="","",IF(H7<>"",H7,IF(UPPER(TRIM(B7))="PIPE",Inputs!$B$7,IF(UPPER(TRIM(B7))="SWALE",Inputs!$B$8,Inputs!$B$9)))) -> 0.013 | J7: 250 | N7: 0 | O7: =IF(A7="","",SUMIFS(Zones_tributaires!$I:$I,Zones_tributaires!$J:$J,$A7)) -> 0 | P7: =IF(A7="","",SUMIFS($Q$4:$Q$204,$E$4:$E$204,$A7)) -> 0.0022595801 | Q7: =IF(A7="","",(O7+P7)*Inputs!$B$6) -> 0.0024855381 | R7: =IF(A7="","",IF(UPPER(TRIM(B7))="PIPE",PI()*(J7/1000)^2/4,IF(OR(K7="",L7=""),"",L7*(K7+M7*L7)))) -> 0.049087385 | S7: =IF(A7="","",IF(UPPER(TRIM(B7))="PIPE",(J7/1000)/4,IF(OR(R7="",K7="",L7=""),"",R7/(K7+2*L7*SQRT(1+M7^2))))) -> 0.0625 | T7: =IF(A7="","",IF(OR(I7="",R7="",S7="",G7=""),"",(1/I7)*R7*(S7^(2/3))*SQRT(G7))) -> 0.037610568 | U7: =IF(OR(T7="",Q7=""),"",Q7/(T7*Inputs!$B$19)) -> 0.082607704 | V7: =IF(OR(R7="",Q7=""),"",Q7/R7) -> 0.050634967 | W7: =IF(OR(R7="",T7=""),"",T7/R7) -> 0.76619619 | X7: =IF(A7="","",IF(OR(UPPER(TRIM(Inputs!$B$15))="MANNING",UPPER(TRIM(Inputs!$B$15))="M"),W7,IF(OR(UPPER(TRIM(Inputs!$B$15))="MAX",UPPER(TRIM(Inputs!$B$15))="X"),MAX(V7,W7),V7))) -> 0.76619619 | Y7: =IF(A7="","",IF(UPPER(TRIM(B7))="TRENCH",K7*L7*N7,IF(UPPER(TRIM(B7))="SWALE",K7*L7,0))) -> 0 | Z7: =IF(OR(Y7="",F7=""),"",Y7*F7) -> 0 | AA7: =IF(A7="","",IF(OR(U7>1,AND(X7<>"",X7<Inputs!$B$16),AND(X7<>"",X7>Inputs!$B$17),G7<Inputs!$B$18,AH7="CHECK"),"CHECK","OK")) -> OK | AB7: Collecteur ouest final en conduite (4.7 m) vers entree ouest bassin. | AD7: =IF(A7="","",IF(AC7<>"",AC7,IF(E7="",Inputs!$B$38,IFERROR(INDEX($AE$4:$AE$204,MATCH(E7,$A$4:$A$204,0))+IF(OR(AND(UPPER(TRIM(B7))="SWALE",UPPER(TRIM(AI7))="PIPE"),AND(UPPER(TRIM(B7))="TRENCH",UPPER(TRIM(AI7))="PIPE")),Inputs!$B$57,0),"")))) | AE7: =IF(OR(AD7="",F7="",G7=""),"",AD7+F7*G7) | AF7: =IF(OR(E7="",A7=""),"",IFERROR(INDEX($AE$4:$AE$204,MATCH(E7,$A$4:$A$204,0)),"")) | AG7: =IF(OR(AD7="",AF7=""),"",AD7-AF7) | AH7: =IF(A7="","",IF(E7="","TERMINAL",IF(OR(AND(UPPER(TRIM(B7))="SWALE",UPPER(TRIM(AI7))="PIPE"),AND(UPPER(TRIM(B7))="TRENCH",UPPER(TRIM(AI7))="PIPE")),IF(OR(AG7="",AJ7="",AK7=""),"INFO",IF(AND(AG7>=AJ7,AG7<=AK7),"OK","CHECK")),IF(AG7="","INFO",IF(ABS(AG7)<=Inputs!$B$54,"OK","CHECK"))))) -> INFO | AI7: =IF(A7="","",IF(E7="","",IFERROR(INDEX($B$4:$B$204,MATCH(E7,$A$4:$A$204,0)),""))) -> PIPE | AJ7: =IF(A7="","",IF(OR(AND(UPPER(TRIM(B7))="SWALE",UPPER(TRIM(AI7))="PIPE"),AND(UPPER(TRIM(B7))="TRENCH",UPPER(TRIM(AI7))="PIPE")),Inputs!$B$55,0)) -> 0 | AK7: =IF(A7="","",IF(OR(AND(UPPER(TRIM(B7))="SWALE",UPPER(TRIM(AI7))="PIPE"),AND(UPPER(TRIM(B7))="TRENCH",UPPER(TRIM(AI7))="PIPE")),Inputs!$B$56,Inputs!$B$54)) -> 0.01 | AL7: =IF(A7="","",IF(E7="","TERMINAL",IF(OR(AND(UPPER(TRIM(B7))="SWALE",UPPER(TRIM(AI7))="PIPE"),AND(UPPER(TRIM(B7))="TRENCH",UPPER(TRIM(AI7))="PIPE")),IF(OR(AG7="",AJ7="",AK7=""),"INFO",IF(AND(AG7>=AJ7,AG7<=AK7),"OK","CHECK")),"N/A"))) -> N/A
A8: E05A | B8: PIPE | C8: J-OUEST-AMONT | D8: J-OUEST-PU1 | E8: E05B | F8: =Inputs!$B$48 -> 2.7707809 | G8: 0.01 | I8: =IF(A8="","",IF(H8<>"",H8,IF(UPPER(TRIM(B8))="PIPE",Inputs!$B$7,IF(UPPER(TRIM(B8))="SWALE",Inputs!$B$8,Inputs!$B$9)))) -> 0.013 | J8: 200 | N8: 0 | O8: =IF(A8="","",SUMIFS(Zones_tributaires!$I:$I,Zones_tributaires!$J:$J,$A8)) -> 9.7455622e-05 | P8: =IF(A8="","",SUMIFS($Q$4:$Q$204,$E$4:$E$204,$A8)) -> 0 | Q8: =IF(A8="","",(O8+P8)*Inputs!$B$6) -> 0.00010720118 | R8: =IF(A8="","",IF(UPPER(TRIM(B8))="PIPE",PI()*(J8/1000)^2/4,IF(OR(K8="",L8=""),"",L8*(K8+M8*L8)))) -> 0.031415927 | S8: =IF(A8="","",IF(UPPER(TRIM(B8))="PIPE",(J8/1000)/4,IF(OR(R8="",K8="",L8=""),"",R8/(K8+2*L8*SQRT(1+M8^2))))) -> 0.05 | T8: =IF(A8="","",IF(OR(I8="",R8="",S8="",G8=""),"",(1/I8)*R8*(S8^(2/3))*SQRT(G8))) -> 0.03279844 | U8: =IF(OR(T8="",Q8=""),"",Q8/(T8*Inputs!$B$19)) -> 0.0040856053 | V8: =IF(OR(R8="",Q8=""),"",Q8/R8) -> 0.0034123197 | W8: =IF(OR(R8="",T8=""),"",T8/R8) -> 1.0440068 | X8: =IF(A8="","",IF(OR(UPPER(TRIM(Inputs!$B$15))="MANNING",UPPER(TRIM(Inputs!$B$15))="M"),W8,IF(OR(UPPER(TRIM(Inputs!$B$15))="MAX",UPPER(TRIM(Inputs!$B$15))="X"),MAX(V8,W8),V8))) -> 1.0440068 | Y8: =IF(A8="","",IF(UPPER(TRIM(B8))="TRENCH",K8*L8*N8,IF(UPPER(TRIM(B8))="SWALE",K8*L8,0))) -> 0 | Z8: =IF(OR(Y8="",F8=""),"",Y8*F8) -> 0 | AA8: =IF(A8="","",IF(OR(U8>1,AND(X8<>"",X8<Inputs!$B$16),AND(X8<>"",X8>Inputs!$B$17),G8<Inputs!$B$18,AH8="CHECK"),"CHECK","OK")) -> OK | AB8: Ouest segment amont en conduite DN250 vers E05B. | AD8: =IF(A8="","",IF(AC8<>"",AC8,IF(E8="",Inputs!$B$38,IFERROR(INDEX($AE$4:$AE$204,MATCH(E8,$A$4:$A$204,0))+IF(OR(AND(UPPER(TRIM(B8))="SWALE",UPPER(TRIM(AI8))="PIPE"),AND(UPPER(TRIM(B8))="TRENCH",UPPER(TRIM(AI8))="PIPE")),Inputs!$B$57,0),"")))) | AE8: =IF(OR(AD8="",F8="",G8=""),"",AD8+F8*G8) | AF8: =IF(OR(E8="",A8=""),"",IFERROR(INDEX($AE$4:$AE$204,MATCH(E8,$A$4:$A$204,0)),"")) | AG8: =IF(OR(AD8="",AF8=""),"",AD8-AF8) | AH8: =IF(A8="","",IF(E8="","TERMINAL",IF(OR(AND(UPPER(TRIM(B8))="SWALE",UPPER(TRIM(AI8))="PIPE"),AND(UPPER(TRIM(B8))="TRENCH",UPPER(TRIM(AI8))="PIPE")),IF(OR(AG8="",AJ8="",AK8=""),"INFO",IF(AND(AG8>=AJ8,AG8<=AK8),"OK","CHECK")),IF(AG8="","INFO",IF(ABS(AG8)<=Inputs!$B$54,"OK","CHECK"))))) -> INFO | AI8: =IF(A8="","",IF(E8="","",IFERROR(INDEX($B$4:$B$204,MATCH(E8,$A$4:$A$204,0)),""))) -> PIPE | AJ8: =IF(A8="","",IF(OR(AND(UPPER(TRIM(B8))="SWALE",UPPER(TRIM(AI8))="PIPE"),AND(UPPER(TRIM(B8))="TRENCH",UPPER(TRIM(AI8))="PIPE")),Inputs!$B$55,0)) -> 0 | AK8: =IF(A8="","",IF(OR(AND(UPPER(TRIM(B8))="SWALE",UPPER(TRIM(AI8))="PIPE"),AND(UPPER(TRIM(B8))="TRENCH",UPPER(TRIM(AI8))="PIPE")),Inputs!$B$56,Inputs!$B$54)) -> 0.01 | AL8: =IF(A8="","",IF(E8="","TERMINAL",IF(OR(AND(UPPER(TRIM(B8))="SWALE",UPPER(TRIM(AI8))="PIPE"),AND(UPPER(TRIM(B8))="TRENCH",UPPER(TRIM(AI8))="PIPE")),IF(OR(AG8="",AJ8="",AK8=""),"INFO",IF(AND(AG8>=AJ8,AG8<=AK8),"OK","CHECK")),"N/A"))) -> N/A
A9: E05B | B9: PIPE | C9: J-OUEST-PU1 | D9: J-OUEST-PU2 | E9: E05C | F9: =Inputs!$B$42 -> 2.3 | G9: 0.01 | I9: =IF(A9="","",IF(H9<>"",H9,IF(UPPER(TRIM(B9))="PIPE",Inputs!$B$7,IF(UPPER(TRIM(B9))="SWALE",Inputs!$B$8,Inputs!$B$9)))) -> 0.013 | J9: 200 | N9: 0 | O9: =IF(A9="","",SUMIFS(Zones_tributaires!$I:$I,Zones_tributaires!$J:$J,$A9)) -> 0.00019854401 | P9: =IF(A9="","",SUMIFS($Q$4:$Q$204,$E$4:$E$204,$A9)) -> 0.00010720118 | Q9: =IF(A9="","",(O9+P9)*Inputs!$B$6) -> 0.00033631971 | R9: =IF(A9="","",IF(UPPER(TRIM(B9))="PIPE",PI()*(J9/1000)^2/4,IF(OR(K9="",L9=""),"",L9*(K9+M9*L9)))) -> 0.031415927 | S9: =IF(A9="","",IF(UPPER(TRIM(B9))="PIPE",(J9/1000)/4,IF(OR(R9="",K9="",L9=""),"",R9/(K9+2*L9*SQRT(1+M9^2))))) -> 0.05 | T9: =IF(A9="","",IF(OR(I9="",R9="",S9="",G9=""),"",(1/I9)*R9*(S9^(2/3))*SQRT(G9))) -> 0.03279844 | U9: =IF(OR(T9="",Q9=""),"",Q9/(T9*Inputs!$B$19)) -> 0.012817672 | V9: =IF(OR(R9="",Q9=""),"",Q9/R9) -> 0.010705389 | W9: =IF(OR(R9="",T9=""),"",T9/R9) -> 1.0440068 | X9: =IF(A9="","",IF(OR(UPPER(TRIM(Inputs!$B$15))="MANNING",UPPER(TRIM(Inputs!$B$15))="M"),W9,IF(OR(UPPER(TRIM(Inputs!$B$15))="MAX",UPPER(TRIM(Inputs!$B$15))="X"),MAX(V9,W9),V9))) -> 1.0440068 | Y9: =IF(A9="","",IF(UPPER(TRIM(B9))="TRENCH",K9*L9*N9,IF(UPPER(TRIM(B9))="SWALE",K9*L9,0))) -> 0 | Z9: =IF(OR(Y9="",F9=""),"",Y9*F9) -> 0 | AA9: =IF(A9="","",IF(OR(U9>1,AND(X9<>"",X9<Inputs!$B$16),AND(X9<>"",X9>Inputs!$B$17),G9<Inputs!$B$18,AH9="CHECK"),"CHECK","OK")) -> OK | AB9: Traverse pave-uni court en conduite DN250 (strategy ouest tout-pipe). | AD9: =IF(A9="","",IF(AC9<>"",AC9,IF(E9="",Inputs!$B$38,IFERROR(INDEX($AE$4:$AE$204,MATCH(E9,$A$4:$A$204,0))+IF(OR(AND(UPPER(TRIM(B9))="SWALE",UPPER(TRIM(AI9))="PIPE"),AND(UPPER(TRIM(B9))="TRENCH",UPPER(TRIM(AI9))="PIPE")),Inputs!$B$57,0),"")))) | AE9: =IF(OR(AD9="",F9="",G9=""),"",AD9+F9*G9) | AF9: =IF(OR(E9="",A9=""),"",IFERROR(INDEX($AE$4:$AE$204,MATCH(E9,$A$4:$A$204,0)),"")) | AG9: =IF(OR(AD9="",AF9=""),"",AD9-AF9) | AH9: =IF(A9="","",IF(E9="","TERMINAL",IF(OR(AND(UPPER(TRIM(B9))="SWALE",UPPER(TRIM(AI9))="PIPE"),AND(UPPER(TRIM(B9))="TRENCH",UPPER(TRIM(AI9))="PIPE")),IF(OR(AG9="",AJ9="",AK9=""),"INFO",IF(AND(AG9>=AJ9,AG9<=AK9),"OK","CHECK")),IF(AG9="","INFO",IF(ABS(AG9)<=Inputs!$B$54,"OK","CHECK"))))) -> INFO | AI9: =IF(A9="","",IF(E9="","",IFERROR(INDEX($B$4:$B$204,MATCH(E9,$A$4:$A$204,0)),""))) -> PIPE | AJ9: =IF(A9="","",IF(OR(AND(UPPER(TRIM(B9))="SWALE",UPPER(TRIM(AI9))="PIPE"),AND(UPPER(TRIM(B9))="TRENCH",UPPER(TRIM(AI9))="PIPE")),Inputs!$B$55,0)) -> 0 | AK9: =IF(A9="","",IF(OR(AND(UPPER(TRIM(B9))="SWALE",UPPER(TRIM(AI9))="PIPE"),AND(UPPER(TRIM(B9))="TRENCH",UPPER(TRIM(AI9))="PIPE")),Inputs!$B$56,Inputs!$B$54)) -> 0.01 | AL9: =IF(A9="","",IF(E9="","TERMINAL",IF(OR(AND(UPPER(TRIM(B9))="SWALE",UPPER(TRIM(AI9))="PIPE"),AND(UPPER(TRIM(B9))="TRENCH",UPPER(TRIM(AI9))="PIPE")),IF(OR(AG9="",AJ9="",AK9=""),"INFO",IF(AND(AG9>=AJ9,AG9<=AK9),"OK","CHECK")),"N/A"))) -> N/A
A10: E05C | B10: PIPE | C10: J-OUEST-PU2 | D10: J-OUEST-PU3 | E10: E05D | F10: =Inputs!$B$49 -> 6.0292191 | G10: 0.009 | I10: =IF(A10="","",IF(H10<>"",H10,IF(UPPER(TRIM(B10))="PIPE",Inputs!$B$7,IF(UPPER(TRIM(B10))="SWALE",Inputs!$B$8,Inputs!$B$9)))) -> 0.013 | J10: 200 | N10: 0 | O10: =IF(A10="","",SUMIFS(Zones_tributaires!$I:$I,Zones_tributaires!$J:$J,$A10)) -> 0.00021172096 | P10: =IF(A10="","",SUMIFS($Q$4:$Q$204,$E$4:$E$204,$A10)) -> 0.00033631971 | Q10: =IF(A10="","",(O10+P10)*Inputs!$B$6) -> 0.00060284473 | R10: =IF(A10="","",IF(UPPER(TRIM(B10))="PIPE",PI()*(J10/1000)^2/4,IF(OR(K10="",L10=""),"",L10*(K10+M10*L10)))) -> 0.031415927 | S10: =IF(A10="","",IF(UPPER(TRIM(B10))="PIPE",(J10/1000)/4,IF(OR(R10="",K10="",L10=""),"",R10/(K10+2*L10*SQRT(1+M10^2))))) -> 0.05 | T10: =IF(A10="","",IF(OR(I10="",R10="",S10="",G10=""),"",(1/I10)*R10*(S10^(2/3))*SQRT(G10))) -> 0.031115332 | U10: =IF(OR(T10="",Q10=""),"",Q10/(T10*Inputs!$B$19)) -> 0.024218154 | V10: =IF(OR(R10="",Q10=""),"",Q10/R10) -> 0.019189144 | W10: =IF(OR(R10="",T10=""),"",T10/R10) -> 0.99043179 | X10: =IF(A10="","",IF(OR(UPPER(TRIM(Inputs!$B$15))="MANNING",UPPER(TRIM(Inputs!$B$15))="M"),W10,IF(OR(UPPER(TRIM(Inputs!$B$15))="MAX",UPPER(TRIM(Inputs!$B$15))="X"),MAX(V10,W10),V10))) -> 0.99043179 | Y10: =IF(A10="","",IF(UPPER(TRIM(B10))="TRENCH",K10*L10*N10,IF(UPPER(TRIM(B10))="SWALE",K10*L10,0))) -> 0 | Z10: =IF(OR(Y10="",F10=""),"",Y10*F10) -> 0 | AA10: =IF(A10="","",IF(OR(U10>1,AND(X10<>"",X10<Inputs!$B$16),AND(X10<>"",X10>Inputs!$B$17),G10<Inputs!$B$18,AH10="CHECK"),"CHECK","OK")) -> OK | AB10: Ouest segment milieu en conduite DN300 vers E05D. | AD10: =IF(A10="","",IF(AC10<>"",AC10,IF(E10="",Inputs!$B$38,IFERROR(INDEX($AE$4:$AE$204,MATCH(E10,$A$4:$A$204,0))+IF(OR(AND(UPPER(TRIM(B10))="SWALE",UPPER(TRIM(AI10))="PIPE"),AND(UPPER(TRIM(B10))="TRENCH",UPPER(TRIM(AI10))="PIPE")),Inputs!$B$57,0),"")))) | AE10: =IF(OR(AD10="",F10="",G10=""),"",AD10+F10*G10) | AF10: =IF(OR(E10="",A10=""),"",IFERROR(INDEX($AE$4:$AE$204,MATCH(E10,$A$4:$A$204,0)),"")) | AG10: =IF(OR(AD10="",AF10=""),"",AD10-AF10) | AH10: =IF(A10="","",IF(E10="","TERMINAL",IF(OR(AND(UPPER(TRIM(B10))="SWALE",UPPER(TRIM(AI10))="PIPE"),AND(UPPER(TRIM(B10))="TRENCH",UPPER(TRIM(AI10))="PIPE")),IF(OR(AG10="",AJ10="",AK10=""),"INFO",IF(AND(AG10>=AJ10,AG10<=AK10),"OK","CHECK")),IF(AG10="","INFO",IF(ABS(AG10)<=Inputs!$B$54,"OK","CHECK"))))) -> INFO | AI10: =IF(A10="","",IF(E10="","",IFERROR(INDEX($B$4:$B$204,MATCH(E10,$A$4:$A$204,0)),""))) -> PIPE | AJ10: =IF(A10="","",IF(OR(AND(UPPER(TRIM(B10))="SWALE",UPPER(TRIM(AI10))="PIPE"),AND(UPPER(TRIM(B10))="TRENCH",UPPER(TRIM(AI10))="PIPE")),Inputs!$B$55,0)) -> 0 | AK10: =IF(A10="","",IF(OR(AND(UPPER(TRIM(B10))="SWALE",UPPER(TRIM(AI10))="PIPE"),AND(UPPER(TRIM(B10))="TRENCH",UPPER(TRIM(AI10))="PIPE")),Inputs!$B$56,Inputs!$B$54)) -> 0.01 | AL10: =IF(A10="","",IF(E10="","TERMINAL",IF(OR(AND(UPPER(TRIM(B10))="SWALE",UPPER(TRIM(AI10))="PIPE"),AND(UPPER(TRIM(B10))="TRENCH",UPPER(TRIM(AI10))="PIPE")),IF(OR(AG10="",AJ10="",AK10=""),"INFO",IF(AND(AG10>=AJ10,AG10<=AK10),"OK","CHECK")),"N/A"))) -> N/A
A11: E05D | B11: PIPE | C11: J-OUEST-PU3 | D11: J-OUEST-PU4 | E11: E05E | F11: =Inputs!$B$43 -> 5.1 | G11: 0.009 | I11: =IF(A11="","",IF(H11<>"",H11,IF(UPPER(TRIM(B11))="PIPE",Inputs!$B$7,IF(UPPER(TRIM(B11))="SWALE",Inputs!$B$8,Inputs!$B$9)))) -> 0.013 | J11: 200 | N11: 0 | O11: =IF(A11="","",SUMIFS(Zones_tributaires!$I:$I,Zones_tributaires!$J:$J,$A11)) -> 0.001109711 | P11: =IF(A11="","",SUMIFS($Q$4:$Q$204,$E$4:$E$204,$A11)) -> 0.00060284473 | Q11: =IF(A11="","",(O11+P11)*Inputs!$B$6) -> 0.0018838113 | R11: =IF(A11="","",IF(UPPER(TRIM(B11))="PIPE",PI()*(J11/1000)^2/4,IF(OR(K11="",L11=""),"",L11*(K11+M11*L11)))) -> 0.031415927 | S11: =IF(A11="","",IF(UPPER(TRIM(B11))="PIPE",(J11/1000)/4,IF(OR(R11="",K11="",L11=""),"",R11/(K11+2*L11*SQRT(1+M11^2))))) -> 0.05 | T11: =IF(A11="","",IF(OR(I11="",R11="",S11="",G11=""),"",(1/I11)*R11*(S11^(2/3))*SQRT(G11))) -> 0.031115332 | U11: =IF(OR(T11="",Q11=""),"",Q11/(T11*Inputs!$B$19)) -> 0.075678578 | V11: =IF(OR(R11="",Q11=""),"",Q11/R11) -> 0.059963576 | W11: =IF(OR(R11="",T11=""),"",T11/R11) -> 0.99043179 | X11: =IF(A11="","",IF(OR(UPPER(TRIM(Inputs!$B$15))="MANNING",UPPER(TRIM(Inputs!$B$15))="M"),W11,IF(OR(UPPER(TRIM(Inputs!$B$15))="MAX",UPPER(TRIM(Inputs!$B$15))="X"),MAX(V11,W11),V11))) -> 0.99043179 | Y11: =IF(A11="","",IF(UPPER(TRIM(B11))="TRENCH",K11*L11*N11,IF(UPPER(TRIM(B11))="SWALE",K11*L11,0))) -> 0 | Z11: =IF(OR(Y11="",F11=""),"",Y11*F11) -> 0 | AA11: =IF(A11="","",IF(OR(U11>1,AND(X11<>"",X11<Inputs!$B$16),AND(X11<>"",X11>Inputs!$B$17),G11<Inputs!$B$18,AH11="CHECK"),"CHECK","OK")) -> OK | AB11: Traverse pave-uni principal en conduite DN300. | AD11: =IF(A11="","",IF(AC11<>"",AC11,IF(E11="",Inputs!$B$38,IFERROR(INDEX($AE$4:$AE$204,MATCH(E11,$A$4:$A$204,0))+IF(OR(AND(UPPER(TRIM(B11))="SWALE",UPPER(TRIM(AI11))="PIPE"),AND(UPPER(TRIM(B11))="TRENCH",UPPER(TRIM(AI11))="PIPE")),Inputs!$B$57,0),"")))) | AE11: =IF(OR(AD11="",F11="",G11=""),"",AD11+F11*G11) | AF11: =IF(OR(E11="",A11=""),"",IFERROR(INDEX($AE$4:$AE$204,MATCH(E11,$A$4:$A$204,0)),"")) | AG11: =IF(OR(AD11="",AF11=""),"",AD11-AF11) | AH11: =IF(A11="","",IF(E11="","TERMINAL",IF(OR(AND(UPPER(TRIM(B11))="SWALE",UPPER(TRIM(AI11))="PIPE"),AND(UPPER(TRIM(B11))="TRENCH",UPPER(TRIM(AI11))="PIPE")),IF(OR(AG11="",AJ11="",AK11=""),"INFO",IF(AND(AG11>=AJ11,AG11<=AK11),"OK","CHECK")),IF(AG11="","INFO",IF(ABS(AG11)<=Inputs!$B$54,"OK","CHECK"))))) -> INFO | AI11: =IF(A11="","",IF(E11="","",IFERROR(INDEX($B$4:$B$204,MATCH(E11,$A$4:$A$204,0)),""))) -> PIPE | AJ11: =IF(A11="","",IF(OR(AND(UPPER(TRIM(B11))="SWALE",UPPER(TRIM(AI11))="PIPE"),AND(UPPER(TRIM(B11))="TRENCH",UPPER(TRIM(AI11))="PIPE")),Inputs!$B$55,0)) -> 0 | AK11: =IF(A11="","",IF(OR(AND(UPPER(TRIM(B11))="SWALE",UPPER(TRIM(AI11))="PIPE"),AND(UPPER(TRIM(B11))="TRENCH",UPPER(TRIM(AI11))="PIPE")),Inputs!$B$56,Inputs!$B$54)) -> 0.01 | AL11: =IF(A11="","",IF(E11="","TERMINAL",IF(OR(AND(UPPER(TRIM(B11))="SWALE",UPPER(TRIM(AI11))="PIPE"),AND(UPPER(TRIM(B11))="TRENCH",UPPER(TRIM(AI11))="PIPE")),IF(OR(AG11="",AJ11="",AK11=""),"INFO",IF(AND(AG11>=AJ11,AG11<=AK11),"OK","CHECK")),"N/A"))) -> N/A
A12: E05E | B12: PIPE | C12: J-OUEST-PU4 | D12: J-OUEST-AVAL | E12: E04 | F12: =Inputs!$B$50 -> 7.38 | G12: 0.008 | I12: =IF(A12="","",IF(H12<>"",H12,IF(UPPER(TRIM(B12))="PIPE",Inputs!$B$7,IF(UPPER(TRIM(B12))="SWALE",Inputs!$B$8,Inputs!$B$9)))) -> 0.013 | J12: 200 | N12: 0 | O12: =IF(A12="","",SUMIFS(Zones_tributaires!$I:$I,Zones_tributaires!$J:$J,$A12)) -> 0.00017035244 | P12: =IF(A12="","",SUMIFS($Q$4:$Q$204,$E$4:$E$204,$A12)) -> 0.0018838113 | Q12: =IF(A12="","",(O12+P12)*Inputs!$B$6) -> 0.0022595801 | R12: =IF(A12="","",IF(UPPER(TRIM(B12))="PIPE",PI()*(J12/1000)^2/4,IF(OR(K12="",L12=""),"",L12*(K12+M12*L12)))) -> 0.031415927 | S12: =IF(A12="","",IF(UPPER(TRIM(B12))="PIPE",(J12/1000)/4,IF(OR(R12="",K12="",L12=""),"",R12/(K12+2*L12*SQRT(1+M12^2))))) -> 0.05 | T12: =IF(A12="","",IF(OR(I12="",R12="",S12="",G12=""),"",(1/I12)*R12*(S12^(2/3))*SQRT(G12))) -> 0.029335817 | U12: =IF(OR(T12="",Q12=""),"",Q12/(T12*Inputs!$B$19)) -> 0.096280774 | V12: =IF(OR(R12="",Q12=""),"",Q12/R12) -> 0.071924669 | W12: =IF(OR(R12="",T12=""),"",T12/R12) -> 0.93378805 | X12: =IF(A12="","",IF(OR(UPPER(TRIM(Inputs!$B$15))="MANNING",UPPER(TRIM(Inputs!$B$15))="M"),W12,IF(OR(UPPER(TRIM(Inputs!$B$15))="MAX",UPPER(TRIM(Inputs!$B$15))="X"),MAX(V12,W12),V12))) -> 0.93378805 | Y12: =IF(A12="","",IF(UPPER(TRIM(B12))="TRENCH",K12*L12*N12,IF(UPPER(TRIM(B12))="SWALE",K12*L12,0))) -> 0 | Z12: =IF(OR(Y12="",F12=""),"",Y12*F12) -> 0 | AA12: =IF(A12="","",IF(OR(U12>1,AND(X12<>"",X12<Inputs!$B$16),AND(X12<>"",X12>Inputs!$B$17),G12<Inputs!$B$18,AH12="CHECK"),"CHECK","OK")) -> OK | AB12: Ouest segment aval en conduite DN300 vers E04. | AD12: =IF(A12="","",IF(AC12<>"",AC12,IF(E12="",Inputs!$B$38,IFERROR(INDEX($AE$4:$AE$204,MATCH(E12,$A$4:$A$204,0))+IF(OR(AND(UPPER(TRIM(B12))="SWALE",UPPER(TRIM(AI12))="PIPE"),AND(UPPER(TRIM(B12))="TRENCH",UPPER(TRIM(AI12))="PIPE")),Inputs!$B$57,0),"")))) | AE12: =IF(OR(AD12="",F12="",G12=""),"",AD12+F12*G12) | AF12: =IF(OR(E12="",A12=""),"",IFERROR(INDEX($AE$4:$AE$204,MATCH(E12,$A$4:$A$204,0)),"")) | AG12: =IF(OR(AD12="",AF12=""),"",AD12-AF12) | AH12: =IF(A12="","",IF(E12="","TERMINAL",IF(OR(AND(UPPER(TRIM(B12))="SWALE",UPPER(TRIM(AI12))="PIPE"),AND(UPPER(TRIM(B12))="TRENCH",UPPER(TRIM(AI12))="PIPE")),IF(OR(AG12="",AJ12="",AK12=""),"INFO",IF(AND(AG12>=AJ12,AG12<=AK12),"OK","CHECK")),IF(AG12="","INFO",IF(ABS(AG12)<=Inputs!$B$54,"OK","CHECK"))))) -> INFO | AI12: =IF(A12="","",IF(E12="","",IFERROR(INDEX($B$4:$B$204,MATCH(E12,$A$4:$A$204,0)),""))) -> PIPE | AJ12: =IF(A12="","",IF(OR(AND(UPPER(TRIM(B12))="SWALE",UPPER(TRIM(AI12))="PIPE"),AND(UPPER(TRIM(B12))="TRENCH",UPPER(TRIM(AI12))="PIPE")),Inputs!$B$55,0)) -> 0 | AK12: =IF(A12="","",IF(OR(AND(UPPER(TRIM(B12))="SWALE",UPPER(TRIM(AI12))="PIPE"),AND(UPPER(TRIM(B12))="TRENCH",UPPER(TRIM(AI12))="PIPE")),Inputs!$B$56,Inputs!$B$54)) -> 0.01 | AL12: =IF(A12="","",IF(E12="","TERMINAL",IF(OR(AND(UPPER(TRIM(B12))="SWALE",UPPER(TRIM(AI12))="PIPE"),AND(UPPER(TRIM(B12))="TRENCH",UPPER(TRIM(AI12))="PIPE")),IF(OR(AG12="",AJ12="",AK12=""),"INFO",IF(AND(AG12>=AJ12,AG12<=AK12),"OK","CHECK")),"N/A"))) -> N/A
