Workbook

Sheet Guide
A1: RESEAU PLUVIAL - METHODE AVEC ELEVATION DE REFERENCE (EXUTOIRE DROITE)
A3: But: dimensionner diametres, pentes et radiers meme si le radier du reseau public aval est inconnu.
A4: Principe: choisir une elevation de reference a l exutoire (radier connu ou surface connue + profondeur de couverture).
A5: Onglet Inputs: definir les hypotheses hydrauliques, IDF et la liste de diametres disponibles.
A6: Onglet CB_Tributaires: entrer les surfaces de chaque puisard/catch basin et le Pipe_ID qui les recoit.
A7: Onglet Conduites: entrer Pipe_ID, pipe receveur aval, longueur, C, tc, pente manuelle (si connue), terrain amont/aval.
A8: Propagation des radiers: le pipe exutoire prend Inputs!B22; les pipes amont prennent le radier amont du pipe aval + chute de regard.
A9: Dimensionnement: Q_local (rationnelle) + Q amont cumulee -> Q_total_design -> diametre recommande par Manning.
A10: Controle: capacite, vitesse, pentes min/max, recouvrement mini.
A11: Important: les references Receives_into_Pipe_ID doivent pointer vers l aval (vers P_OUT).
A12: Utiliser d abord SURFACE si reseau public inconnu, puis recalibrer quand les radiers municipaux seront disponibles.
A15: Formules cle (texte simple):
... A97: RAPPORT PLANCHER/TERRAIN: 68.56%

Sheet Inputs
A1: INPUTS
A2: Parametre | B2: Valeur | C2: Unite | D2: Commentaire
A3: Reference_Type (INVERT or SURFACE) | B3: invert | C3: - | D3: SURFACE quand radier reseau public inconnu. | F3: Diametres disponibles (mm)
A4: Outfall_reference_elevation_m | B4: 15.305 | C4: m | D4: Si SURFACE: niveau terrain exutoire. Si INVERT: radier exutoire.
A5: Outfall_cover_depth_if_surface_m | B5: 1.8 | C5: m | D5: Profondeur terrain->radier a l exutoire (si SURFACE). | F5: 200
A6: Outfall_pipe_ID | B6: L11_P11_PUB | C6: - | D6: Pipe qui se connecte au reseau public (droite). | F6: 250
A7: Min_slope_m_per_m | B7: 0.01 | C7: m/m | D7: Pente minimale de controle. | F7: 300
A8: Max_slope_m_per_m | B8: 0.05 | C8: m/m | D8: Pente maximale de controle. | F8: 375
A9: Manning_n | B9: 0.013 | C9: - | D9: Rugosite Manning. | F9: 450
A10: Design_fill_ratio_limit | B10: 0.8 | C10: - | D10: Q/(Q pleine) admissible. | F10: 525
A11: Min_velocity_mps | B11: 0.75 | C11: m/s | D11: Vitesse minimale souhaitee. | F11: 600
A12: Max_velocity_mps | B12: 3 | C12: m/s | D12: Vitesse maximale souhaitee. | F12: 675
A13: IDF_a | B13: 508.07 | C13: - | D13: i = a/(tc+b)^c | F13: 750
A14: IDF_b | B14: 2.9 | C14: min | D14: Parametre IDF b. | F14: 900
A15: IDF_c | B15: 0.644 | C15: - | D15: Parametre IDF c.
A16: Flow_safety_factor | B16: 1 | C16: - | D16: Facteur applique a Q total.
A17: Default_runoff_C | B17: 0.9 | C17: - | D17: Utilise si C local non renseigne.
A18: Default_tc_min | B18: 6 | C18: min | D18: Utilise si tc local non renseigne.
A19: Min_cover_depth_m | B19: 1.8 | C19: m | D19: Recouvrement mini de controle.
A20: Default_junction_drop_m | B20: 0.02 | C20: m | D20: Chute de regard par defaut.
A22: Outfall_invert_derived_m | B22: =IF(UPPER(TRIM(B3))="SURFACE",B4-B5,B4) -> 15.305
A23: Tc_travel_velocity_mps | B23: 1 | C23: m/s | D23: Velocity used to compute travel time per pipe for cumulative Tc logic.
A24: Velocity_check_method (DESIGN / MANNING / PARTIAL / MAX) | B24: MAX | C24: - | D24: DESIGN=Q/A; MANNING=V full via Manning; PARTIAL=iterative Manning partial depth; MAX=most conservative.
A25: C_roof_default | B25: 0.95 | C25: - | D25: Typical impervious roof runoff coefficient.
A26: C_pavement_default | B26: 0.9 | C26: - | D26: Typical impervious pavement/asphalt coefficient.
A27: C_grass_default | B27: 0.25 | C27: - | D27: Typical pervious grass/landscaped coefficient.
A28: C_other_default | B28: 0.6 | C28: - | D28: Other surface coefficient (user-adjustable).
B31: 13.64
B32: 49.6
A33: SURFACES DU TERRAIN: | B33: 15.84
A34: SUPERFICIE IMPERMÉABLE: 11 747 pi2 (33.19%) | B34: 7.36
A35: SUPERFICIE D'EMPREINTE: 8 089 pi2 (22.85 %) | B35: =B31+B32+B33+B34 -> 86.44
A36: SURFACE ESPACES VERTES (MIN 40%) 15 557 pi2 (43.96%)
A39: SUPERFICIE DU TERRAIN: 35393.21*0.3048^2 | B39: =35393.21*0.3048^2 -> 3288.1368 | C39: m2
A40: 24267*0.3048^2 | B40: =24267*0.3048^2 -> 2254.4781 | C40: m2
A41: B40/B39 | B41: =B40/B39 -> 0.68563999
A43: STATIONNEMENT: 11747*0.3048^2 | B43: =11747*0.3048^2 -> 1091.332 | C43: m2 | D43: =B43/B46 -> 0.33190179
A44: BÂTIMENT: 8089*0.3048^2 | B44: =8089*0.3048^2 -> 751.49269 | C44: m2 | D44: =B44/B46 -> 0.22854802
A45: SUPERFICE ESPACES VERTS: 15557*0.3048^2 | B45: =15557*0.3048^2 -> 1445.2926 | C45: m2 | D45: =B45/B46 -> 0.43955019
A46: SUPERFICIE TOTALE: | B46: =B43+B44+B45 -> 3288.1173 | C46: m2
...

Sheet Noeuds_plan
A1: NOEUDS PLAN (TOPOLOGIE CORRIGEE)
A3: Node_ID | B3: Downstream_Node_ID | C3: Ground_elev_m (input) | D3: Target_cover_depth_m | E3: Invert_if_manual_m | F3: Notes
A4: P01 | B4: P02 | C4: 17.237 | D4: =Inputs!$B$19 -> 1.8 | E4: =IF(OR(C4="",D4=""),"",C4-D4) -> 15.437 | F4: Top-left
A5: P02 | B5: P03 | C5: 17.131 | D5: =Inputs!$B$19 -> 1.8 | E5: =IF(OR(C5="",D5=""),"",C5-D5) -> 15.331 | F5: Top-center; also branch to P05 (pipe L12)
A6: P03 | B6: P10 | C6: 17.01 | D6: =Inputs!$B$19 -> 1.8 | E6: =IF(OR(C6="",D6=""),"",C6-D6) -> 15.21 | F6: Top-right to P10
A7: P04 | B7: P05 | C7: 17.28 | D7: =Inputs!$B$19 -> 1.8 | E7: =IF(OR(C7="",D7=""),"",C7-D7) -> 15.48 | F7: Mid-left
A8: P05 | B8: P03 | C8: 17.05 | D8: =Inputs!$B$19 -> 1.8 | E8: =IF(OR(C8="",D8=""),"",C8-D8) -> 15.25 | F8: Mid-center
A9: P06 | B9: P04 | C9: 17.14 | D9: =Inputs!$B$19 -> 1.8 | E9: =IF(OR(C9="",D9=""),"",C9-D9) -> 15.34 | F9: Mid-right to P10
A10: P07 | B10: P06 | C10: 17.09 | D10: =Inputs!$B$19 -> 1.8 | E10: =IF(OR(C10="",D10=""),"",C10-D10) -> 15.29 | F10: Lower-left
A11: P08 | B11: P05 | C11: 17.04 | D11: =Inputs!$B$19 -> 1.8 | E11: =IF(OR(C11="",D11=""),"",C11-D11) -> 15.24 | F11: Lower-center
A12: P09 | B12: P06 | C12: 17.62 | D12: =Inputs!$B$19 -> 1.8 | E12: =IF(OR(C12="",D12=""),"",C12-D12) -> 15.82 | F12: Lower-right up to P06
A13: P10 | B13: P11 | C13: 16.965 | D13: =Inputs!$B$19 -> 1.8 | E13: =IF(OR(C13="",D13=""),"",C13-D13) -> 15.165 | F13: Top-right to P11
A14: P11 | B14: P12 | C14: 16.874 | D14: =Inputs!$B$19 -> 1.8 | E14: =IF(OR(C14="",D14=""),"",C14-D14) -> 15.074 | F14: Junction node before public network
A15: P12 | B15: PUB | C15: 16.73 | D15: =Inputs!$B$19 -> 1.8 | E15: =IF(OR(C15="",D15=""),"",C15-D15) -> 14.93 | F15: Public network tie-in
A16: T01 | B16: P08 | C16: 17.01 | D16: =Inputs!$B$19 -> 1.8 | E16: =IF(OR(C16="",D16=""),"",C16-D16) -> 15.21 | F16: Toiture -vers réseau
H17: 17.185
H18: 17.014
H19: =H17-H18 -> 0.171
G20: L= | H20: 22.39
H21: =H19/H20 -> 0.0076373381
G22: L1= | H22: 7.065
H23: =H17-H22*H21 -> 17.131042
G24: L2= | H24: 6.92
H25: =H17+H21*H24 -> 17.23785
H27: 17.2
H28: 17
H29: =H27-H28 -> 0.2
G30: L= | H30: 20
H31: =H29/H30 -> 0.01
G32: L1= | H32: 15.425
H33: =H27-H31*H32 -> 17.04575
G34: L2= | H34: 8.22
H35: =H27+H34*H31 -> 17.2822
H37: 17.104
H38: 17.022
H39: =H37-H38 -> 0.082
G40: L= | H40: 15.83
H41: =H39/H40 -> 0.0051800379
G42: L1= | H42: 2.62
H43: =H37-H42*H41 -> 17.090428
...

Sheet CB_plan
A1: SOUS-BASSINS PAR TYPE DE SURFACE (B/C/D/E) - REPARTITION EXPLICITE REQUISE
A2: Saisir les aires en B/C/D/E: toiture, pavage, gazon, autre. La conduite receptrice est en F.
A3: CB_or_Zone | B3: Area_roof_m2 | C3: Area_pavement_m2 | D3: Area_grass_m2 | E3: Area_other_m2 | F3: Receives_into_Pipe_ID | G3: Area_total_m2 | H3: Area_effective_m2 (sum A*C) | I3: Runoff_C_weighted | J3: Node_hint | K3: Notes | L3: Impervious_area_m2 | M3: Pervious_area_m2 | N3: Impervious_fraction | O3: Dominant_surface | P3: Surface_input_status
A4: A | C4: 61.9 | D4: =58.2+31.4 -> 89.6 | E4: 0 | F4: L01_P01_P02 | G4: =IF(A4="","",SUM(B4:E4)) -> 151.5 | H4: =IF(A4="","",B4*Inputs!$B$25 + C4*Inputs!$B$26 + D4*Inputs!$B$27 + E4*Inputs!$B$28) -> 78.11 | I4: =IF(OR(G4="",G4=0),"",H4/G4) -> 0.51557756 | J4: P01 | K4: From annotated plan.; Prefill 2026-06-28: best-guess surfaces (verify).; Area total set from red m2 labels (2026-06-30 image); split is best-estimate. | L4: =IF(A4="","",B4+C4+E4) -> 61.9 | M4: =IF(A4="","",D4) -> 89.6 | N4: =IF(OR(G4="",G4=0),"",L4/G4) -> 0.40858086 | O4: =IF(A4="","",IF(COUNT(B4:E4)=0,"MISSING",IF(MIN(B4:E4)<0,"INVALID_NEG",IF(SUM(B4:E4)=0,"ZERO_TOTAL",IF(COUNTIF(B4:E4,MAX(B4:E4))>1,"MIXED/TIE",IF(MAX(B4:E4)=B4,"ROOF",IF(MAX(B4:E4)=C4,"PAVEMENT",IF(MAX(B4:E4)=D4,"GRASS","OTHER")))))))) -> GRASS | P4: =IF(A4="","",IF(COUNT(B4:E4)=0,"MISSING_SPLIT",IF(MIN(B4:E4)<0,"INVALID_NEGATIVE",IF(SUM(B4:E4)=0,"ZERO_TOTAL",IF(I4="","NO_WEIGHTED_C","OK"))))) -> OK
A5: B | C5: 79.8 | D5: 43 | E5: 0 | F5: L02_P02_P03 | G5: =IF(A5="","",SUM(B5:E5)) -> 122.8 | H5: =IF(A5="","",B5*Inputs!$B$25 + C5*Inputs!$B$26 + D5*Inputs!$B$27 + E5*Inputs!$B$28) -> 82.57 | I5: =IF(OR(G5="",G5=0),"",H5/G5) -> 0.67239414 | J5: P02 | K5: From annotated plan.; Prefill 2026-06-28: best-guess surfaces (verify).; Area total set from red m2 labels (2026-06-30 image); split is best-estimate. | L5: =IF(A5="","",B5+C5+E5) -> 79.8 | M5: =IF(A5="","",D5) -> 43 | N5: =IF(OR(G5="",G5=0),"",L5/G5) -> 0.64983713 | O5: =IF(A5="","",IF(COUNT(B5:E5)=0,"MISSING",IF(MIN(B5:E5)<0,"INVALID_NEG",IF(SUM(B5:E5)=0,"ZERO_TOTAL",IF(COUNTIF(B5:E5,MAX(B5:E5))>1,"MIXED/TIE",IF(MAX(B5:E5)=B5,"ROOF",IF(MAX(B5:E5)=C5,"PAVEMENT",IF(MAX(B5:E5)=D5,"GRASS","OTHER")))))))) -> PAVEMENT | P5: =IF(A5="","",IF(COUNT(B5:E5)=0,"MISSING_SPLIT",IF(MIN(B5:E5)<0,"INVALID_NEGATIVE",IF(SUM(B5:E5)=0,"ZERO_TOTAL",IF(I5="","NO_WEIGHTED_C","OK"))))) -> OK
A6: C | C6: 87.8 | D6: =47.9+76 -> 123.9 | E6: 0 | F6: L02_P02_P03 | G6: =IF(A6="","",SUM(B6:E6)) -> 211.7 | H6: =IF(A6="","",B6*Inputs!$B$25 + C6*Inputs!$B$26 + D6*Inputs!$B$27 + E6*Inputs!$B$28) -> 109.995 | I6: =IF(OR(G6="",G6=0),"",H6/G6) -> 0.51957959 | J6: P03 | K6: From annotated plan.; Prefill 2026-06-28: best-guess surfaces (verify).; Area total set from red m2 labels (2026-06-30 image); split is best-estimate. | L6: =IF(A6="","",B6+C6+E6) -> 87.8 | M6: =IF(A6="","",D6) -> 123.9 | N6: =IF(OR(G6="",G6=0),"",L6/G6) -> 0.41473784 | O6: =IF(A6="","",IF(COUNT(B6:E6)=0,"MISSING",IF(MIN(B6:E6)<0,"INVALID_NEG",IF(SUM(B6:E6)=0,"ZERO_TOTAL",IF(COUNTIF(B6:E6,MAX(B6:E6))>1,"MIXED/TIE",IF(MAX(B6:E6)=B6,"ROOF",IF(MAX(B6:E6)=C6,"PAVEMENT",IF(MAX(B6:E6)=D6,"GRASS","OTHER")))))))) -> GRASS | P6: =IF(A6="","",IF(COUNT(B6:E6)=0,"MISSING_SPLIT",IF(MIN(B6:E6)<0,"INVALID_NEGATIVE",IF(SUM(B6:E6)=0,"ZERO_TOTAL",IF(I6="","NO_WEIGHTED_C","OK"))))) -> OK
A7: D | C7: 43.2 | D7: 51.3 | E7: 0 | F7: L09_P04_P01 | G7: =IF(A7="","",SUM(B7:E7)) -> 94.5 | H7: =IF(A7="","",B7*Inputs!$B$25 + C7*Inputs!$B$26 + D7*Inputs!$B$27 + E7*Inputs!$B$28) -> 51.705 | I7: =IF(OR(G7="",G7=0),"",H7/G7) -> 0.54714286 | J7: P04 | K7: From annotated plan.; Prefill 2026-06-28: best-guess surfaces (verify).; Area total set from red m2 labels (2026-06-30 image); split is best-estimate. | L7: =IF(A7="","",B7+C7+E7) -> 43.2 | M7: =IF(A7="","",D7) -> 51.3 | N7: =IF(OR(G7="",G7=0),"",L7/G7) -> 0.45714286 | O7: =IF(A7="","",IF(COUNT(B7:E7)=0,"MISSING",IF(MIN(B7:E7)<0,"INVALID_NEG",IF(SUM(B7:E7)=0,"ZERO_TOTAL",IF(COUNTIF(B7:E7,MAX(B7:E7))>1,"MIXED/TIE",IF(MAX(B7:E7)=B7,"ROOF",IF(MAX(B7:E7)=C7,"PAVEMENT",IF(MAX(B7:E7)=D7,"GRASS","OTHER")))))))) -> GRASS | P7: =IF(A7="","",IF(COUNT(B7:E7)=0,"MISSING_SPLIT",IF(MIN(B7:E7)<0,"INVALID_NEGATIVE",IF(SUM(B7:E7)=0,"ZERO_TOTAL",IF(I7="","NO_WEIGHTED_C","OK"))))) -> OK
A8: E | C8: 89.6 | D8: 16.2 | E8: 0 | F8: L01_P01_P02 | G8: =IF(A8="","",SUM(B8:E8)) -> 105.8 | H8: =IF(A8="","",B8*Inputs!$B$25 + C8*Inputs!$B$26 + D8*Inputs!$B$27 + E8*Inputs!$B$28) -> 84.69 | I8: =IF(OR(G8="",G8=0),"",H8/G8) -> 0.80047259 | J8: P04-P05 | K8: From annotated plan.; Prefill 2026-06-28: best-guess surfaces (verify).; Area total set from red m2 labels (2026-06-30 image); split is best-estimate. | L8: =IF(A8="","",B8+C8+E8) -> 89.6 | M8: =IF(A8="","",D8) -> 16.2 | N8: =IF(OR(G8="",G8=0),"",L8/G8) -> 0.84688091 | O8: =IF(A8="","",IF(COUNT(B8:E8)=0,"MISSING",IF(MIN(B8:E8)<0,"INVALID_NEG",IF(SUM(B8:E8)=0,"ZERO_TOTAL",IF(COUNTIF(B8:E8,MAX(B8:E8))>1,"MIXED/TIE",IF(MAX(B8:E8)=B8,"ROOF",IF(MAX(B8:E8)=C8,"PAVEMENT",IF(MAX(B8:E8)=D8,"GRASS","OTHER")))))))) -> PAVEMENT | P8: =IF(A8="","",IF(COUNT(B8:E8)=0,"MISSING_SPLIT",IF(MIN(B8:E8)<0,"INVALID_NEGATIVE",IF(SUM(B8:E8)=0,"ZERO_TOTAL",IF(I8="","NO_WEIGHTED_C","OK"))))) -> OK
A9: F | C9: =88.7+25.79 -> 114.49 | D9: 18.9 | E9: 0 | F9: L02_P02_P03 | G9: =IF(A9="","",SUM(B9:E9)) -> 133.39 | H9: =IF(A9="","",B9*Inputs!$B$25 + C9*Inputs!$B$26 + D9*Inputs!$B$27 + E9*Inputs!$B$28) -> 107.766 | I9: =IF(OR(G9="",G9=0),"",H9/G9) -> 0.80790164 | J9: P05-P06 | K9: From annotated plan.; Prefill 2026-06-28: best-guess surfaces (verify).; Area total set from red m2 labels (2026-06-30 image); split is best-estimate. | L9: =IF(A9="","",B9+C9+E9) -> 114.49 | M9: =IF(A9="","",D9) -> 18.9 | N9: =IF(OR(G9="",G9=0),"",L9/G9) -> 0.85831022 | O9: =IF(A9="","",IF(COUNT(B9:E9)=0,"MISSING",IF(MIN(B9:E9)<0,"INVALID_NEG",IF(SUM(B9:E9)=0,"ZERO_TOTAL",IF(COUNTIF(B9:E9,MAX(B9:E9))>1,"MIXED/TIE",IF(MAX(B9:E9)=B9,"ROOF",IF(MAX(B9:E9)=C9,"PAVEMENT",IF(MAX(B9:E9)=D9,"GRASS","OTHER")))))))) -> PAVEMENT | P9: =IF(A9="","",IF(COUNT(B9:E9)=0,"MISSING_SPLIT",IF(MIN(B9:E9)<0,"INVALID_NEGATIVE",IF(SUM(B9:E9)=0,"ZERO_TOTAL",IF(I9="","NO_WEIGHTED_C","OK"))))) -> OK
A10: G | C10: 98.7 | D10: 49.2 | E10: 0 | F10: L08_P06_P04 | G10: =IF(A10="","",SUM(B10:E10)) -> 147.9 | H10: =IF(A10="","",B10*Inputs!$B$25 + C10*Inputs!$B$26 + D10*Inputs!$B$27 + E10*Inputs!$B$28) -> 101.13 | I10: =IF(OR(G10="",G10=0),"",H10/G10) -> 0.68377282 | J10: P06 | K10: From annotated plan; verify blanks (G/J/K) if needed.; Area total set from red m2 labels (2026-06-30 image); split is best-estimate. | L10: =IF(A10="","",B10+C10+E10) -> 98.7 | M10: =IF(A10="","",D10) -> 49.2 | N10: =IF(OR(G10="",G10=0),"",L10/G10) -> 0.6673428 | O10: =IF(A10="","",IF(COUNT(B10:E10)=0,"MISSING",IF(MIN(B10:E10)<0,"INVALID_NEG",IF(SUM(B10:E10)=0,"ZERO_TOTAL",IF(COUNTIF(B10:E10,MAX(B10:E10))>1,"MIXED/TIE",IF(MAX(B10:E10)=B10,"ROOF",IF(MAX(B10:E10)=C10,"PAVEMENT",IF(MAX(B10:E10)=D10,"GRASS","OTHER")))))))) -> PAVEMENT | P10: =IF(A10="","",IF(COUNT(B10:E10)=0,"MISSING_SPLIT",IF(MIN(B10:E10)<0,"INVALID_NEGATIVE",IF(SUM(B10:E10)=0,"ZERO_TOTAL",IF(I10="","NO_WEIGHTED_C","OK"))))) -> OK
A11: H | C11: 58.2 | D11: 17.6 | E11: 0 | F11: L07_P07_P06 | G11: =IF(A11="","",SUM(B11:E11)) -> 75.8 | H11: =IF(A11="","",B11*Inputs!$B$25 + C11*Inputs!$B$26 + D11*Inputs!$B$27 + E11*Inputs!$B$28) -> 56.78 | I11: =IF(OR(G11="",G11=0),"",H11/G11) -> 0.74907652 | J11: P07 | K11: From annotated plan.; Prefill 2026-06-28: best-guess surfaces (verify).; Area total set from red m2 labels (2026-06-30 image); split is best-estimate. | L11: =IF(A11="","",B11+C11+E11) -> 58.2 | M11: =IF(A11="","",D11) -> 17.6 | N11: =IF(OR(G11="",G11=0),"",L11/G11) -> 0.76781003 | O11: =IF(A11="","",IF(COUNT(B11:E11)=0,"MISSING",IF(MIN(B11:E11)<0,"INVALID_NEG",IF(SUM(B11:E11)=0,"ZERO_TOTAL",IF(COUNTIF(B11:E11,MAX(B11:E11))>1,"MIXED/TIE",IF(MAX(B11:E11)=B11,"ROOF",IF(MAX(B11:E11)=C11,"PAVEMENT",IF(MAX(B11:E11)=D11,"GRASS","OTHER")))))))) -> PAVEMENT | P11: =IF(A11="","",IF(COUNT(B11:E11)=0,"MISSING_SPLIT",IF(MIN(B11:E11)<0,"INVALID_NEGATIVE",IF(SUM(B11:E11)=0,"ZERO_TOTAL",IF(I11="","NO_WEIGHTED_C","OK"))))) -> OK
A12: I | C12: =109.5+10.51 -> 120.01 | D12: 16.2 | E12: 0 | F12: L07_P07_P06 | G12: =IF(A12="","",SUM(B12:E12)) -> 136.21 | H12: =IF(A12="","",B12*Inputs!$B$25 + C12*Inputs!$B$26 + D12*Inputs!$B$27 + E12*Inputs!$B$28) -> 112.059 | I12: =IF(OR(G12="",G12=0),"",H12/G12) -> 0.8226929 | J12: P08 | K12: From annotated plan.; Prefill 2026-06-28: best-guess surfaces (verify).; Area total set from red m2 labels (2026-06-30 image); split is best-estimate. | L12: =IF(A12="","",B12+C12+E12) -> 120.01 | M12: =IF(A12="","",D12) -> 16.2 | N12: =IF(OR(G12="",G12=0),"",L12/G12) -> 0.881066 | O12: =IF(A12="","",IF(COUNT(B12:E12)=0,"MISSING",IF(MIN(B12:E12)<0,"INVALID_NEG",IF(SUM(B12:E12)=0,"ZERO_TOTAL",IF(COUNTIF(B12:E12,MAX(B12:E12))>1,"MIXED/TIE",IF(MAX(B12:E12)=B12,"ROOF",IF(MAX(B12:E12)=C12,"PAVEMENT",IF(MAX(B12:E12)=D12,"GRASS","OTHER")))))))) -> PAVEMENT | P12: =IF(A12="","",IF(COUNT(B12:E12)=0,"MISSING_SPLIT",IF(MIN(B12:E12)<0,"INVALID_NEGATIVE",IF(SUM(B12:E12)=0,"ZERO_TOTAL",IF(I12="","NO_WEIGHTED_C","OK"))))) -> OK
A13: J | C13: 67.7 | D13: 81.4 | E13: 0 | F13: L06_P09_P06 | G13: =IF(A13="","",SUM(B13:E13)) -> 149.1 | H13: =IF(A13="","",B13*Inputs!$B$25 + C13*Inputs!$B$26 + D13*Inputs!$B$27 + E13*Inputs!$B$28) -> 81.28 | I13: =IF(OR(G13="",G13=0),"",H13/G13) -> 0.54513749 | J13: P09 | K13: From annotated plan; verify blanks (G/J/K) if needed.; Area total set from red m2 labels (2026-06-30 image); split is best-estimate. | L13: =IF(A13="","",B13+C13+E13) -> 67.7 | M13: =IF(A13="","",D13) -> 81.4 | N13: =IF(OR(G13="",G13=0),"",L13/G13) -> 0.45405768 | O13: =IF(A13="","",IF(COUNT(B13:E13)=0,"MISSING",IF(MIN(B13:E13)<0,"INVALID_NEG",IF(SUM(B13:E13)=0,"ZERO_TOTAL",IF(COUNTIF(B13:E13,MAX(B13:E13))>1,"MIXED/TIE",IF(MAX(B13:E13)=B13,"ROOF",IF(MAX(B13:E13)=C13,"PAVEMENT",IF(MAX(B13:E13)=D13,"GRASS","OTHER")))))))) -> GRASS | P13: =IF(A13="","",IF(COUNT(B13:E13)=0,"MISSING_SPLIT",IF(MIN(B13:E13)<0,"INVALID_NEGATIVE",IF(SUM(B13:E13)=0,"ZERO_TOTAL",IF(I13="","NO_WEIGHTED_C","OK"))))) -> OK
A14: K | C14: 48.8 | D14: 58.4 | E14: 0 | F14: L07_P07_P06 | G14: =IF(A14="","",SUM(B14:E14)) -> 107.2 | H14: =IF(A14="","",B14*Inputs!$B$25 + C14*Inputs!$B$26 + D14*Inputs!$B$27 + E14*Inputs!$B$28) -> 58.52 | I14: =IF(OR(G14="",G14=0),"",H14/G14) -> 0.54589552 | J14: P06/P09 flank | K14: From annotated plan; verify blanks (G/J/K) if needed.; Area total set from red m2 labels (2026-06-30 image); split is best-estimate. | L14: =IF(A14="","",B14+C14+E14) -> 48.8 | M14: =IF(A14="","",D14) -> 58.4 | N14: =IF(OR(G14="",G14=0),"",L14/G14) -> 0.45522388 | O14: =IF(A14="","",IF(COUNT(B14:E14)=0,"MISSING",IF(MIN(B14:E14)<0,"INVALID_NEG",IF(SUM(B14:E14)=0,"ZERO_TOTAL",IF(COUNTIF(B14:E14,MAX(B14:E14))>1,"MIXED/TIE",IF(MAX(B14:E14)=B14,"ROOF",IF(MAX(B14:E14)=C14,"PAVEMENT",IF(MAX(B14:E14)=D14,"GRASS","OTHER")))))))) -> GRASS | P14: =IF(A14="","",IF(COUNT(B14:E14)=0,"MISSING_SPLIT",IF(MIN(B14:E14)<0,"INVALID_NEGATIVE",IF(SUM(B14:E14)=0,"ZERO_TOTAL",IF(I14="","NO_WEIGHTED_C","OK"))))) -> OK
A15: L | C15: =95.5+10.13+17.51 -> 123.14 | D15: 0 | E15: 0 | F15: L07_P07_P06 | G15: =IF(A15="","",SUM(B15:E15)) -> 123.14 | H15: =IF(A15="","",B15*Inputs!$B$25 + C15*Inputs!$B$26 + D15*Inputs!$B$27 + E15*Inputs!$B$28) -> 110.826 | I15: =IF(OR(G15="",G15=0),"",H15/G15) -> 0.9 | J15: P08 | K15: From annotated plan.; Prefill 2026-06-28: best-guess surfaces (verify).; Area total set from red m2 labels (2026-06-30 image); split is best-estimate. | L15: =IF(A15="","",B15+C15+E15) -> 123.14 | M15: =IF(A15="","",D15) -> 0 | N15: =IF(OR(G15="",G15=0),"",L15/G15) -> 1 | O15: =IF(A15="","",IF(COUNT(B15:E15)=0,"MISSING",IF(MIN(B15:E15)<0,"INVALID_NEG",IF(SUM(B15:E15)=0,"ZERO_TOTAL",IF(COUNTIF(B15:E15,MAX(B15:E15))>1,"MIXED/TIE",IF(MAX(B15:E15)=B15,"ROOF",IF(MAX(B15:E15)=C15,"PAVEMENT",IF(MAX(B15:E15)=D15,"GRASS","OTHER")))))))) -> PAVEMENT | P15: =IF(A15="","",IF(COUNT(B15:E15)=0,"MISSING_SPLIT",IF(MIN(B15:E15)<0,"INVALID_NEGATIVE",IF(SUM(B15:E15)=0,"ZERO_TOTAL",IF(I15="","NO_WEIGHTED_C","OK"))))) -> OK
A16: M | C16: 52.4 | D16: =66.5+178.75 -> 245.25 | E16: 0 | F16: L06_P09_P06 | G16: =IF(A16="","",SUM(B16:E16)) -> 297.65 | H16: =IF(A16="","",B16*Inputs!$B$25 + C16*Inputs!$B$26 + D16*Inputs!$B$27 + E16*Inputs!$B$28) -> 108.4725 | I16: =IF(OR(G16="",G16=0),"",H16/G16) -> 0.3644297 | J16: P09 | K16: From annotated plan.; Prefill 2026-06-28: best-guess surfaces (verify).; Area total set from red m2 labels (2026-06-30 image); split is best-estimate. | L16: =IF(A16="","",B16+C16+E16) -> 52.4 | M16: =IF(A16="","",D16) -> 245.25 | N16: =IF(OR(G16="",G16=0),"",L16/G16) -> 0.17604569 | O16: =IF(A16="","",IF(COUNT(B16:E16)=0,"MISSING",IF(MIN(B16:E16)<0,"INVALID_NEG",IF(SUM(B16:E16)=0,"ZERO_TOTAL",IF(COUNTIF(B16:E16,MAX(B16:E16))>1,"MIXED/TIE",IF(MAX(B16:E16)=B16,"ROOF",IF(MAX(B16:E16)=C16,"PAVEMENT",IF(MAX(B16:E16)=D16,"GRASS","OTHER")))))))) -> GRASS | P16: =IF(A16="","",IF(COUNT(B16:E16)=0,"MISSING_SPLIT",IF(MIN(B16:E16)<0,"INVALID_NEGATIVE",IF(SUM(B16:E16)=0,"ZERO_TOTAL",IF(I16="","NO_WEIGHTED_C","OK"))))) -> OK
A17: N | B17: 903 | C17: 0 | D17: 0 | E17: 0 | F17: L10_P10_P11 | G17: =IF(A17="","",SUM(B17:E17)) -> 903 | H17: =IF(A17="","",B17*Inputs!$B$25 + C17*Inputs!$B$26 + D17*Inputs!$B$27 + E17*Inputs!$B$28) -> 857.85 | I17: =IF(OR(G17="",G17=0),"",H17/G17) -> 0.95 | J17: T01 | K17: From annotated plan.; Prefill 2026-06-28: best-guess surfaces (verify).; Area total set from red m2 labels (2026-06-30 image); split is best-estimate. | L17: =IF(A17="","",B17+C17+E17) -> 903 | M17: =IF(A17="","",D17) -> 0 | N17: =IF(OR(G17="",G17=0),"",L17/G17) -> 1 | O17: =IF(A17="","",IF(COUNT(B17:E17)=0,"MISSING",IF(MIN(B17:E17)<0,"INVALID_NEG",IF(SUM(B17:E17)=0,"ZERO_TOTAL",IF(COUNTIF(B17:E17,MAX(B17:E17))>1,"MIXED/TIE",IF(MAX(B17:E17)=B17,"ROOF",IF(MAX(B17:E17)=C17,"PAVEMENT",IF(MAX(B17:E17)=D17,"GRASS","OTHER")))))))) -> ROOF | P17: =IF(A17="","",IF(COUNT(B17:E17)=0,"MISSING_SPLIT",IF(MIN(B17:E17)<0,"INVALID_NEGATIVE",IF(SUM(B17:E17)=0,"ZERO_TOTAL",IF(I17="","NO_WEIGHTED_C","OK"))))) -> OK
A18: O | C18: =33.2+17.46+14.14 -> 64.8 | D18: =191.8+35.46+178.75+26.8 -> 432.81 | E18: 0 | F18: L11_P11_P12 | G18: =IF(A18="","",SUM(B18:E18)) -> 497.61 | H18: =IF(A18="","",B18*Inputs!$B$25 + C18*Inputs!$B$26 + D18*Inputs!$B$27 + E18*Inputs!$B$28) -> 166.5225 | I18: =IF(OR(G18="",G18=0),"",H18/G18) -> 0.3346446 | J18: P010 corridor | K18: From annotated plan.; Prefill 2026-06-28: best-guess surfaces (verify).; Area total set from red m2 labels (2026-06-30 image); split is best-estimate. | L18: =IF(A18="","",B18+C18+E18) -> 64.8 | M18: =IF(A18="","",D18) -> 432.81 | N18: =IF(OR(G18="",G18=0),"",L18/G18) -> 0.13022246 | O18: =IF(A18="","",IF(COUNT(B18:E18)=0,"MISSING",IF(MIN(B18:E18)<0,"INVALID_NEG",IF(SUM(B18:E18)=0,"ZERO_TOTAL",IF(COUNTIF(B18:E18,MAX(B18:E18))>1,"MIXED/TIE",IF(MAX(B18:E18)=B18,"ROOF",IF(MAX(B18:E18)=C18,"PAVEMENT",IF(MAX(B18:E18)=D18,"GRASS","OTHER")))))))) -> GRASS | P18: =IF(A18="","",IF(COUNT(B18:E18)=0,"MISSING_SPLIT",IF(MIN(B18:E18)<0,"INVALID_NEGATIVE",IF(SUM(B18:E18)=0,"ZERO_TOTAL",IF(I18="","NO_WEIGHTED_C","OK"))))) -> OK
G19: =IF(A19="","",SUM(B19:E19)) | H19: =IF(A19="","",B20*Inputs!$B$25 + C20*Inputs!$B$26 + D20*Inputs!$B$27 + E19*Inputs!$B$28) | I19: =IF(OR(G19="",G19=0),"",H19/G19) | L19: =IF(A19="","",B20+C20+E19) | M19: =IF(A19="","",D20) | N19: =IF(OR(G19="",G19=0),"",L19/G19) | O19: =IF(A19="","",IF(COUNT(B19:E19)=0,"MISSING",IF(MIN(B19:E19)<0,"INVALID_NEG",IF(SUM(B19:E19)=0,"ZERO_TOTAL",IF(COUNTIF(B19:E19,MAX(B19:E19))>1,"MIXED/TIE",IF(MAX(B19:E19)=B20,"ROOF",IF(MAX(B19:E19)=C20,"PAVEMENT",IF(MAX(B19:E19)=D20,"GRASS","OTHER")))))))) | P19: =IF(A19="","",IF(COUNT(B19:E19)=0,"MISSING_SPLIT",IF(MIN(B19:E19)<0,"INVALID_NEGATIVE",IF(SUM(B19:E19)=0,"ZERO_TOTAL",IF(I19="","NO_WEIGHTED_C","OK")))))
B20: =SUM(B4:B18) -> 903 | C20: =SUM(C4:C18) -> 1110.54 | D20: =SUM(D4:D18) -> 1243.76 | G20: =IF(A20="","",SUM(B20:E20)) | H20: =IF(A20="","",B20*Inputs!$B$25 + C20*Inputs!$B$26 + D20*Inputs!$B$27 + E20*Inputs!$B$28) | I20: =IF(OR(G20="",G20=0),"",H20/G20) | L20: =IF(A20="","",B20+C20+E20) | M20: =IF(A20="","",D20) | N20: =IF(OR(G20="",G20=0),"",L20/G20) | O20: =IF(A20="","",IF(COUNT(B20:E20)=0,"MISSING",IF(MIN(B20:E20)<0,"INVALID_NEG",IF(SUM(B20:E20)=0,"ZERO_TOTAL",IF(COUNTIF(B20:E20,MAX(B20:E20))>1,"MIXED/TIE",IF(MAX(B20:E20)=B20,"ROOF",IF(MAX(B20:E20)=C20,"PAVEMENT",IF(MAX(B20:E20)=D20,"GRASS","OTHER")))))))) | P20: =IF(A20="","",IF(COUNT(B20:E20)=0,"MISSING_SPLIT",IF(MIN(B20:E20)<0,"INVALID_NEGATIVE",IF(SUM(B20:E20)=0,"ZERO_TOTAL",IF(I20="","NO_WEIGHTED_C","OK")))))
C21: =35393.21*0.3048^2 -> 3288.1368 | G21: =IF(A21="","",SUM(B21:E21)) | H21: =IF(A21="","",B21*Inputs!$B$25 + C21*Inputs!$B$26 + D21*Inputs!$B$27 + E21*Inputs!$B$28) | I21: =IF(OR(G21="",G21=0),"",H21/G21) | L21: =IF(A21="","",B21+C21+E21) | M21: =IF(A21="","",D21) | N21: =IF(OR(G21="",G21=0),"",L21/G21) | O21: =IF(A21="","",IF(COUNT(B21:E21)=0,"MISSING",IF(MIN(B21:E21)<0,"INVALID_NEG",IF(SUM(B21:E21)=0,"ZERO_TOTAL",IF(COUNTIF(B21:E21,MAX(B21:E21))>1,"MIXED/TIE",IF(MAX(B21:E21)=B21,"ROOF",IF(MAX(B21:E21)=C21,"PAVEMENT",IF(MAX(B21:E21)=D21,"GRASS","OTHER")))))))) | P21: =IF(A21="","",IF(COUNT(B21:E21)=0,"MISSING_SPLIT",IF(MIN(B21:E21)<0,"INVALID_NEGATIVE",IF(SUM(B21:E21)=0,"ZERO_TOTAL",IF(I21="","NO_WEIGHTED_C","OK")))))
C22: =8089*0.3048^2 -> 751.49269 | G22: =IF(A22="","",SUM(B22:E22)) | H22: =IF(A22="","",B22*Inputs!$B$25 + C22*Inputs!$B$26 + D22*Inputs!$B$27 + E22*Inputs!$B$28) | I22: =IF(OR(G22="",G22=0),"",H22/G22) | L22: =IF(A22="","",B22+C22+E22) | M22: =IF(A22="","",D22) | N22: =IF(OR(G22="",G22=0),"",L22/G22) | O22: =IF(A22="","",IF(COUNT(B22:E22)=0,"MISSING",IF(MIN(B22:E22)<0,"INVALID_NEG",IF(SUM(B22:E22)=0,"ZERO_TOTAL",IF(COUNTIF(B22:E22,MAX(B22:E22))>1,"MIXED/TIE",IF(MAX(B22:E22)=B22,"ROOF",IF(MAX(B22:E22)=C22,"PAVEMENT",IF(MAX(B22:E22)=D22,"GRASS","OTHER")))))))) | P22: =IF(A22="","",IF(COUNT(B22:E22)=0,"MISSING_SPLIT",IF(MIN(B22:E22)<0,"INVALID_NEGATIVE",IF(SUM(B22:E22)=0,"ZERO_TOTAL",IF(I22="","NO_WEIGHTED_C","OK")))))
C23: =C20+D20+B20 -> 3257.3 | G23: =IF(A23="","",SUM(B23:E23)) | H23: =IF(A23="","",B23*Inputs!$B$25 + C23*Inputs!$B$26 + D23*Inputs!$B$27 + E23*Inputs!$B$28) | I23: =IF(OR(G23="",G23=0),"",H23/G23) | L23: =IF(A23="","",B23+C23+E23) | M23: =IF(A23="","",D23) | N23: =IF(OR(G23="",G23=0),"",L23/G23) | O23: =IF(A23="","",IF(COUNT(B23:E23)=0,"MISSING",IF(MIN(B23:E23)<0,"INVALID_NEG",IF(SUM(B23:E23)=0,"ZERO_TOTAL",IF(COUNTIF(B23:E23,MAX(B23:E23))>1,"MIXED/TIE",IF(MAX(B23:E23)=B23,"ROOF",IF(MAX(B23:E23)=C23,"PAVEMENT",IF(MAX(B23:E23)=D23,"GRASS","OTHER")))))))) | P23: =IF(A23="","",IF(COUNT(B23:E23)=0,"MISSING_SPLIT",IF(MIN(B23:E23)<0,"INVALID_NEGATIVE",IF(SUM(B23:E23)=0,"ZERO_TOTAL",IF(I23="","NO_WEIGHTED_C","OK")))))
C24: =C21-C23 -> 30.836804 | G24: =IF(A24="","",SUM(B24:E24)) | H24: =IF(A24="","",B24*Inputs!$B$25 + C24*Inputs!$B$26 + D24*Inputs!$B$27 + E24*Inputs!$B$28) | I24: =IF(OR(G24="",G24=0),"",H24/G24) | L24: =IF(A24="","",B24+C24+E24) | M24: =IF(A24="","",D24) | N24: =IF(OR(G24="",G24=0),"",L24/G24) | O24: =IF(A24="","",IF(COUNT(B24:E24)=0,"MISSING",IF(MIN(B24:E24)<0,"INVALID_NEG",IF(SUM(B24:E24)=0,"ZERO_TOTAL",IF(COUNTIF(B24:E24,MAX(B24:E24))>1,"MIXED/TIE",IF(MAX(B24:E24)=B24,"ROOF",IF(MAX(B24:E24)=C24,"PAVEMENT",IF(MAX(B24:E24)=D24,"GRASS","OTHER")))))))) | P24: =IF(A24="","",IF(COUNT(B24:E24)=0,"MISSING_SPLIT",IF(MIN(B24:E24)<0,"INVALID_NEGATIVE",IF(SUM(B24:E24)=0,"ZERO_TOTAL",IF(I24="","NO_WEIGHTED_C","OK")))))
G25: =IF(A25="","",SUM(B25:E25)) | H25: =IF(A25="","",B25*Inputs!$B$25 + C25*Inputs!$B$26 + D25*Inputs!$B$27 + E25*Inputs!$B$28) | I25: =IF(OR(G25="",G25=0),"",H25/G25) | L25: =IF(A25="","",B25+C25+E25) | M25: =IF(A25="","",D25) | N25: =IF(OR(G25="",G25=0),"",L25/G25) | O25: =IF(A25="","",IF(COUNT(B25:E25)=0,"MISSING",IF(MIN(B25:E25)<0,"INVALID_NEG",IF(SUM(B25:E25)=0,"ZERO_TOTAL",IF(COUNTIF(B25:E25,MAX(B25:E25))>1,"MIXED/TIE",IF(MAX(B25:E25)=B25,"ROOF",IF(MAX(B25:E25)=C25,"PAVEMENT",IF(MAX(B25:E25)=D25,"GRASS","OTHER")))))))) | P25: =IF(A25="","",IF(COUNT(B25:E25)=0,"MISSING_SPLIT",IF(MIN(B25:E25)<0,"INVALID_NEGATIVE",IF(SUM(B25:E25)=0,"ZERO_TOTAL",IF(I25="","NO_WEIGHTED_C","OK")))))
G26: =IF(A26="","",SUM(B26:E26)) | H26: =IF(A26="","",B26*Inputs!$B$25 + C26*Inputs!$B$26 + D26*Inputs!$B$27 + E26*Inputs!$B$28) | I26: =IF(OR(G26="",G26=0),"",H26/G26) | L26: =IF(A26="","",B26+C26+E26) | M26: =IF(A26="","",D26) | N26: =IF(OR(G26="",G26=0),"",L26/G26) | O26: =IF(A26="","",IF(COUNT(B26:E26)=0,"MISSING",IF(MIN(B26:E26)<0,"INVALID_NEG",IF(SUM(B26:E26)=0,"ZERO_TOTAL",IF(COUNTIF(B26:E26,MAX(B26:E26))>1,"MIXED/TIE",IF(MAX(B26:E26)=B26,"ROOF",IF(MAX(B26:E26)=C26,"PAVEMENT",IF(MAX(B26:E26)=D26,"GRASS","OTHER")))))))) | P26: =IF(A26="","",IF(COUNT(B26:E26)=0,"MISSING_SPLIT",IF(MIN(B26:E26)<0,"INVALID_NEGATIVE",IF(SUM(B26:E26)=0,"ZERO_TOTAL",IF(I26="","NO_WEIGHTED_C","OK")))))
G27: =IF(A27="","",SUM(B27:E27)) | H27: =IF(A27="","",B27*Inputs!$B$25 + C27*Inputs!$B$26 + D27*Inputs!$B$27 + E27*Inputs!$B$28) | I27: =IF(OR(G27="",G27=0),"",H27/G27) | L27: =IF(A27="","",B27+C27+E27) | M27: =IF(A27="","",D27) | N27: =IF(OR(G27="",G27=0),"",L27/G27) | O27: =IF(A27="","",IF(COUNT(B27:E27)=0,"MISSING",IF(MIN(B27:E27)<0,"INVALID_NEG",IF(SUM(B27:E27)=0,"ZERO_TOTAL",IF(COUNTIF(B27:E27,MAX(B27:E27))>1,"MIXED/TIE",IF(MAX(B27:E27)=B27,"ROOF",IF(MAX(B27:E27)=C27,"PAVEMENT",IF(MAX(B27:E27)=D27,"GRASS","OTHER")))))))) | P27: =IF(A27="","",IF(COUNT(B27:E27)=0,"MISSING_SPLIT",IF(MIN(B27:E27)<0,"INVALID_NEGATIVE",IF(SUM(B27:E27)=0,"ZERO_TOTAL",IF(I27="","NO_WEIGHTED_C","OK")))))
G28: =IF(A28="","",SUM(B28:E28)) | H28: =IF(A28="","",B28*Inputs!$B$25 + C28*Inputs!$B$26 + D28*Inputs!$B$27 + E28*Inputs!$B$28) | I28: =IF(OR(G28="",G28=0),"",H28/G28) | L28: =IF(A28="","",B28+C28+E28) | M28: =IF(A28="","",D28) | N28: =IF(OR(G28="",G28=0),"",L28/G28) | O28: =IF(A28="","",IF(COUNT(B28:E28)=0,"MISSING",IF(MIN(B28:E28)<0,"INVALID_NEG",IF(SUM(B28:E28)=0,"ZERO_TOTAL",IF(COUNTIF(B28:E28,MAX(B28:E28))>1,"MIXED/TIE",IF(MAX(B28:E28)=B28,"ROOF",IF(MAX(B28:E28)=C28,"PAVEMENT",IF(MAX(B28:E28)=D28,"GRASS","OTHER")))))))) | P28: =IF(A28="","",IF(COUNT(B28:E28)=0,"MISSING_SPLIT",IF(MIN(B28:E28)<0,"INVALID_NEGATIVE",IF(SUM(B28:E28)=0,"ZERO_TOTAL",IF(I28="","NO_WEIGHTED_C","OK")))))
G29: =IF(A29="","",SUM(B29:E29)) | H29: =IF(A29="","",B29*Inputs!$B$25 + C29*Inputs!$B$26 + D29*Inputs!$B$27 + E29*Inputs!$B$28) | I29: =IF(OR(G29="",G29=0),"",H29/G29) | L29: =IF(A29="","",B29+C29+E29) | M29: =IF(A29="","",D29) | N29: =IF(OR(G29="",G29=0),"",L29/G29) | O29: =IF(A29="","",IF(COUNT(B29:E29)=0,"MISSING",IF(MIN(B29:E29)<0,"INVALID_NEG",IF(SUM(B29:E29)=0,"ZERO_TOTAL",IF(COUNTIF(B29:E29,MAX(B29:E29))>1,"MIXED/TIE",IF(MAX(B29:E29)=B29,"ROOF",IF(MAX(B29:E29)=C29,"PAVEMENT",IF(MAX(B29:E29)=D29,"GRASS","OTHER")))))))) | P29: =IF(A29="","",IF(COUNT(B29:E29)=0,"MISSING_SPLIT",IF(MIN(B29:E29)<0,"INVALID_NEGATIVE",IF(SUM(B29:E29)=0,"ZERO_TOTAL",IF(I29="","NO_WEIGHTED_C","OK")))))
G30: =IF(A30="","",SUM(B30:E30)) | H30: =IF(A30="","",B30*Inputs!$B$25 + C30*Inputs!$B$26 + D30*Inputs!$B$27 + E30*Inputs!$B$28) | I30: =IF(OR(G30="",G30=0),"",H30/G30) | L30: =IF(A30="","",B30+C30+E30) | M30: =IF(A30="","",D30) | N30: =IF(OR(G30="",G30=0),"",L30/G30) | O30: =IF(A30="","",IF(COUNT(B30:E30)=0,"MISSING",IF(MIN(B30:E30)<0,"INVALID_NEG",IF(SUM(B30:E30)=0,"ZERO_TOTAL",IF(COUNTIF(B30:E30,MAX(B30:E30))>1,"MIXED/TIE",IF(MAX(B30:E30)=B30,"ROOF",IF(MAX(B30:E30)=C30,"PAVEMENT",IF(MAX(B30:E30)=D30,"GRASS","OTHER")))))))) | P30: =IF(A30="","",IF(COUNT(B30:E30)=0,"MISSING_SPLIT",IF(MIN(B30:E30)<0,"INVALID_NEGATIVE",IF(SUM(B30:E30)=0,"ZERO_TOTAL",IF(I30="","NO_WEIGHTED_C","OK")))))
G31: =IF(A31="","",SUM(B31:E31)) | H31: =IF(A31="","",B31*Inputs!$B$25 + C31*Inputs!$B$26 + D31*Inputs!$B$27 + E31*Inputs!$B$28) | I31: =IF(OR(G31="",G31=0),"",H31/G31) | L31: =IF(A31="","",B31+C31+E31) | M31: =IF(A31="","",D31) | N31: =IF(OR(G31="",G31=0),"",L31/G31) | O31: =IF(A31="","",IF(COUNT(B31:E31)=0,"MISSING",IF(MIN(B31:E31)<0,"INVALID_NEG",IF(SUM(B31:E31)=0,"ZERO_TOTAL",IF(COUNTIF(B31:E31,MAX(B31:E31))>1,"MIXED/TIE",IF(MAX(B31:E31)=B31,"ROOF",IF(MAX(B31:E31)=C31,"PAVEMENT",IF(MAX(B31:E31)=D31,"GRASS","OTHER")))))))) | P31: =IF(A31="","",IF(COUNT(B31:E31)=0,"MISSING_SPLIT",IF(MIN(B31:E31)<0,"INVALID_NEGATIVE",IF(SUM(B31:E31)=0,"ZERO_TOTAL",IF(I31="","NO_WEIGHTED_C","OK")))))
G32: =IF(A32="","",SUM(B32:E32)) | H32: =IF(A32="","",B32*Inputs!$B$25 + C32*Inputs!$B$26 + D32*Inputs!$B$27 + E32*Inputs!$B$28) | I32: =IF(OR(G32="",G32=0),"",H32/G32) | L32: =IF(A32="","",B32+C32+E32) | M32: =IF(A32="","",D32) | N32: =IF(OR(G32="",G32=0),"",L32/G32) | O32: =IF(A32="","",IF(COUNT(B32:E32)=0,"MISSING",IF(MIN(B32:E32)<0,"INVALID_NEG",IF(SUM(B32:E32)=0,"ZERO_TOTAL",IF(COUNTIF(B32:E32,MAX(B32:E32))>1,"MIXED/TIE",IF(MAX(B32:E32)=B32,"ROOF",IF(MAX(B32:E32)=C32,"PAVEMENT",IF(MAX(B32:E32)=D32,"GRASS","OTHER")))))))) | P32: =IF(A32="","",IF(COUNT(B32:E32)=0,"MISSING_SPLIT",IF(MIN(B32:E32)<0,"INVALID_NEGATIVE",IF(SUM(B32:E32)=0,"ZERO_TOTAL",IF(I32="","NO_WEIGHTED_C","OK")))))
G33: =IF(A33="","",SUM(B33:E33)) | H33: =IF(A33="","",B33*Inputs!$B$25 + C33*Inputs!$B$26 + D33*Inputs!$B$27 + E33*Inputs!$B$28) | I33: =IF(OR(G33="",G33=0),"",H33/G33) | L33: =IF(A33="","",B33+C33+E33) | M33: =IF(A33="","",D33) | N33: =IF(OR(G33="",G33=0),"",L33/G33) | O33: =IF(A33="","",IF(COUNT(B33:E33)=0,"MISSING",IF(MIN(B33:E33)<0,"INVALID_NEG",IF(SUM(B33:E33)=0,"ZERO_TOTAL",IF(COUNTIF(B33:E33,MAX(B33:E33))>1,"MIXED/TIE",IF(MAX(B33:E33)=B33,"ROOF",IF(MAX(B33:E33)=C33,"PAVEMENT",IF(MAX(B33:E33)=D33,"GRASS","OTHER")))))))) | P33: =IF(A33="","",IF(COUNT(B33:E33)=0,"MISSING_SPLIT",IF(MIN(B33:E33)<0,"INVALID_NEGATIVE",IF(SUM(B33:E33)=0,"ZERO_TOTAL",IF(I33="","NO_WEIGHTED_C","OK")))))
G34: =IF(A34="","",SUM(B34:E34)) | H34: =IF(A34="","",B34*Inputs!$B$25 + C34*Inputs!$B$26 + D34*Inputs!$B$27 + E34*Inputs!$B$28) | I34: =IF(OR(G34="",G34=0),"",H34/G34) | L34: =IF(A34="","",B34+C34+E34) | M34: =IF(A34="","",D34) | N34: =IF(OR(G34="",G34=0),"",L34/G34) | O34: =IF(A34="","",IF(COUNT(B34:E34)=0,"MISSING",IF(MIN(B34:E34)<0,"INVALID_NEG",IF(SUM(B34:E34)=0,"ZERO_TOTAL",IF(COUNTIF(B34:E34,MAX(B34:E34))>1,"MIXED/TIE",IF(MAX(B34:E34)=B34,"ROOF",IF(MAX(B34:E34)=C34,"PAVEMENT",IF(MAX(B34:E34)=D34,"GRASS","OTHER")))))))) | P34: =IF(A34="","",IF(COUNT(B34:E34)=0,"MISSING_SPLIT",IF(MIN(B34:E34)<0,"INVALID_NEGATIVE",IF(SUM(B34:E34)=0,"ZERO_TOTAL",IF(I34="","NO_WEIGHTED_C","OK")))))
G35: =IF(A35="","",SUM(B35:E35)) | H35: =IF(A35="","",B35*Inputs!$B$25 + C35*Inputs!$B$26 + D35*Inputs!$B$27 + E35*Inputs!$B$28) | I35: =IF(OR(G35="",G35=0),"",H35/G35) | L35: =IF(A35="","",B35+C35+E35) | M35: =IF(A35="","",D35) | N35: =IF(OR(G35="",G35=0),"",L35/G35) | O35: =IF(A35="","",IF(COUNT(B35:E35)=0,"MISSING",IF(MIN(B35:E35)<0,"INVALID_NEG",IF(SUM(B35:E35)=0,"ZERO_TOTAL",IF(COUNTIF(B35:E35,MAX(B35:E35))>1,"MIXED/TIE",IF(MAX(B35:E35)=B35,"ROOF",IF(MAX(B35:E35)=C35,"PAVEMENT",IF(MAX(B35:E35)=D35,"GRASS","OTHER")))))))) | P35: =IF(A35="","",IF(COUNT(B35:E35)=0,"MISSING_SPLIT",IF(MIN(B35:E35)<0,"INVALID_NEGATIVE",IF(SUM(B35:E35)=0,"ZERO_TOTAL",IF(I35="","NO_WEIGHTED_C","OK")))))
G36: =IF(A36="","",SUM(B36:E36)) | H36: =IF(A36="","",B36*Inputs!$B$25 + C36*Inputs!$B$26 + D36*Inputs!$B$27 + E36*Inputs!$B$28) | I36: =IF(OR(G36="",G36=0),"",H36/G36) | L36: =IF(A36="","",B36+C36+E36) | M36: =IF(A36="","",D36) | N36: =IF(OR(G36="",G36=0),"",L36/G36) | O36: =IF(A36="","",IF(COUNT(B36:E36)=0,"MISSING",IF(MIN(B36:E36)<0,"INVALID_NEG",IF(SUM(B36:E36)=0,"ZERO_TOTAL",IF(COUNTIF(B36:E36,MAX(B36:E36))>1,"MIXED/TIE",IF(MAX(B36:E36)=B36,"ROOF",IF(MAX(B36:E36)=C36,"PAVEMENT",IF(MAX(B36:E36)=D36,"GRASS","OTHER")))))))) | P36: =IF(A36="","",IF(COUNT(B36:E36)=0,"MISSING_SPLIT",IF(MIN(B36:E36)<0,"INVALID_NEGATIVE",IF(SUM(B36:E36)=0,"ZERO_TOTAL",IF(I36="","NO_WEIGHTED_C","OK")))))
... G204: =IF(A204="","",SUM(B204:E204)) | H204: =IF(A204="","",B204*Inputs!$B$25 + C204*Inputs!$B$26 + D204*Inputs!$B$27 + E204*Inputs!$B$28) | I204: =IF(OR(G204="",G204=0),"",H204/G204) | L204: =IF(A204="","",B204+C204+E204) | M204: =IF(A204="","",D204) | N204: =IF(OR(G204="",G204=0),"",L204/G204) | O204: =IF(A204="","",IF(COUNT(B204:E204)=0,"MISSING",IF(MIN(B204:E204)<0,"INVALID_NEG",IF(SUM(B204:E204)=0,"ZERO_TOTAL",IF(COUNTIF(B204:E204,MAX(B204:E204))>1,"MIXED/TIE",IF(MAX(B204:E204)=B204,"ROOF",IF(MAX(B204:E204)=C204,"PAVEMENT",IF(MAX(B204:E204)=D204,"GRASS","OTHER")))))))) | P204: =IF(A204="","",IF(COUNT(B204:E204)=0,"MISSING_SPLIT",IF(MIN(B204:E204)<0,"INVALID_NEGATIVE",IF(SUM(B204:E204)=0,"ZERO_TOTAL",IF(I204="","NO_WEIGHTED_C","OK")))))

Sheet Conduites_plan_noeuds
A1: CONDUITES PLAN NOEUD-PAR-NOEUD (TOPOLOGIE CORRIGEE + Tc CUMULE)
A2: Network_status | B2: =IF(COUNTIF(AE4:AE201,"CHECK")>0,"CHECK","OK") -> OK | D2: Pipes_with_checks | E2: =COUNTIF(AE4:AE201,"CHECK") -> 0
A3: Pipe_ID | B3: From_Node | C3: To_Node | D3: Receives_into_Pipe_ID | E3: Length_m | F3: Area_override_m2 | G3: Area_from_CB_m2 | H3: Area_used_m2 | I3: C_local | J3: Tc_local_min | K3: Intensity_mmh | L3: Q_local_m3s | M3: Q_from_upstream_m3s | N3: Q_total_design_m3s | O3: Slope_manual_m/m | P3: Slope_used_m/m | Q3: Dia_recommended_mm | R3: Dia_override_mm | S3: Dia_used_mm | T3: Dia_used_m | U3: Capacity_full_m3s | V3: Q_over_capacity_ratio | W3: Velocity_design_QA_mps | X3: Junction_drop_m | Y3: Invert_down_m | Z3: Invert_up_m | AA3: Ground_down_m | AB3: Ground_up_m | AC3: Cover_down_m | AD3: Cover_up_m | AE3: Checks | AF3: Notes | AG3: Cap_5 | AH3: Cap_6 | AI3: Cap_7 | AJ3: Cap_8 | AK3: Cap_9 | AL3: Cap_10 | AM3: Cap_11 | AN3: Cap_12 | AO3: Cap_13 | AP3: Cap_14 | AQ3: Upstream_pipe_count | AR3: Pipe_role | AS3: Tc_start_base_min | AT3: Tc_prev_upstream_max_min | AU3: t_travel_pipe_min | AV3: Tc_used_min | AW3: Velocity_design_QA_mps_copy | AX3: Velocity_manning_full_mps | AY3: Velocity_used_for_check_mps | AZ3: Depth_partial_iter_m | BA3: Velocity_partial_iter_mps | BB3: Q_target_partial_m3s | BC3: Q_cap_open_0p94D_m3s | BD3: low0 | BE3: high0 | BF3: mid1 | BG3: q1 | BH3: low1 | BI3: high1 | BJ3: mid2 | BK3: q2 | BL3: low2 | BM3: high2 | BN3: mid3 | BO3: q3 | BP3: low3 | BQ3: high3 | BR3: mid4 | BS3: q4 | BT3: low4 | BU3: high4 | BV3: mid5 | BW3: q5 | BX3: low5 | BY3: high5 | BZ3: mid6 | CA3: q6 | CB3: low6 | CC3: high6 | CD3: mid7 | CE3: q7 | CF3: low7 | CG3: high7 | CH3: mid8
A4: L01_P01_P02 | B4: P01 | C4: P02 | D4: L02_P02_P03 | E4: 14.2 | G4: =SUMIFS(CB_plan!$G:$G,CB_plan!$F:$F,$A4) -> 257.3 | H4: =IF(F4="",G4,F4) -> 257.3 | K4: =IF(A4="","",Inputs!$B$13/((IF(AV4="",Inputs!$B$18,AV4)+Inputs!$B$14)^Inputs!$B$15)) -> 122.22955 | L4: =IF(A4="","",IF(H4="","",0.000000278*IF(I4<>"",I4,IFERROR(SUMIFS(CB_plan!$H:$H,CB_plan!$F:$F,$A4)/SUMIFS(CB_plan!$G:$G,CB_plan!$F:$F,$A4),Inputs!$B$17))*H4*K4)) -> 0.005531914 | M4: =IF(A4="","",SUMIFS($N$4:$N$201,$D$4:$D$201,$A4)) -> 0.023168413 | N4: =IF(A4="","",(L4+M4)*Inputs!$B$16) -> 0.028700327 | P4: =IF(A4="","",IF(O4="",Inputs!$B$7,O4)) -> 0.01 | Q4: =IF(A4="","",IF(N4/Inputs!$B$10<=AG4,Inputs!$F$5,IF(N4/Inputs!$B$10>AP4,"OVERSIZE",INDEX(Inputs!$F$5:$F$14,MATCH(N4/Inputs!$B$10,AG4:AP4,1)+1)))) -> 250 | S4: =IF(A4="","",IF(R4="",Q4,R4)) -> 250 | T4: =IF(OR(S4="",S4="OVERSIZE"),"",S4/1000) -> 0.25 | U4: =IF(T4="","",(1/Inputs!$B$9)*(PI()*T4^2/4)*((T4/4)^(2/3))*SQRT(P4)) -> 0.059467529 | V4: =IF(OR(U4="",N4=""),"",N4/(U4*Inputs!$B$10)) -> 0.60327728 | W4: =IF(OR(T4="",N4=""),"",4*N4/(PI()*T4^2)) -> 0.58467827 | Y4: =IF(A4="","",IF(A4=Inputs!$B$6,Inputs!$B$22,IF(D4="","",IFERROR(INDEX($Z$4:$Z$201,MATCH(D4,$A$4:$A$201,0))+IF(X4="",Inputs!$B$20,X4),"")))) | Z4: =IF(OR(Y4="",P4="",E4=""),"",Y4+P4*E4) | AA4: =IF(C4="","",IFERROR(INDEX(Noeuds_plan!$C$4:$C$200,MATCH(C4,Noeuds_plan!$A$4:$A$200,0)),"")) -> 17.131 | AB4: =IF(B4="","",IFERROR(INDEX(Noeuds_plan!$C$4:$C$200,MATCH(B4,Noeuds_plan!$A$4:$A$200,0)),"")) -> 17.237 | AC4: =IF(OR(AA4="",Y4=""),"",AA4-Y4) | AD4: =IF(OR(AB4="",Z4=""),"",AB4-Z4) | AE4: =IF(A4="","",IF(OR(V4>1,AND(AY4<>"",AY4<Inputs!$B$11),AND(AY4<>"",AY4>Inputs!$B$12),AC4<Inputs!$B$19,AD4<Inputs!$B$19,P4<Inputs!$B$7,P4>Inputs!$B$8),"CHECK","OK")) -> OK | AF4: Top horizontal; Length updated from red dimension labels (2026-06-30 image). | AG4: =IF(A4="","",(1/Inputs!$B$9)*(PI()*(Inputs!$F$5/1000)^2/4)*((Inputs!$F$5/1000/4)^(2/3))*SQRT(P4)) -> 0.03279844 | AH4: =IF(A4="","",(1/Inputs!$B$9)*(PI()*(Inputs!$F$6/1000)^2/4)*((Inputs!$F$6/1000/4)^(2/3))*SQRT(P4)) -> 0.059467529 | AI4: =IF(A4="","",(1/Inputs!$B$9)*(PI()*(Inputs!$F$7/1000)^2/4)*((Inputs!$F$7/1000/4)^(2/3))*SQRT(P4)) -> 0.096700759 | AJ4: =IF(A4="","",(1/Inputs!$B$9)*(PI()*(Inputs!$F$8/1000)^2/4)*((Inputs!$F$8/1000/4)^(2/3))*SQRT(P4)) -> 0.17533014 | AK4: =IF(A4="","",(1/Inputs!$B$9)*(PI()*(Inputs!$F$9/1000)^2/4)*((Inputs!$F$9/1000/4)^(2/3))*SQRT(P4)) -> 0.28510614 | AL4: =IF(A4="","",(1/Inputs!$B$9)*(PI()*(Inputs!$F$10/1000)^2/4)*((Inputs!$F$10/1000/4)^(2/3))*SQRT(P4)) -> 0.43006227 | AM4: =IF(A4="","",(1/Inputs!$B$9)*(PI()*(Inputs!$F$11/1000)^2/4)*((Inputs!$F$11/1000/4)^(2/3))*SQRT(P4)) -> 0.61401154 | AN4: =IF(A4="","",(1/Inputs!$B$9)*(PI()*(Inputs!$F$12/1000)^2/4)*((Inputs!$F$12/1000/4)^(2/3))*SQRT(P4)) -> 0.84058815 | AO4: =IF(A4="","",(1/Inputs!$B$9)*(PI()*(Inputs!$F$13/1000)^2/4)*((Inputs!$F$13/1000/4)^(2/3))*SQRT(P4)) -> 1.113277 | AP4: =IF(A4="","",(1/Inputs!$B$9)*(PI()*(Inputs!$F$14/1000)^2/4)*((Inputs!$F$14/1000/4)^(2/3))*SQRT(P4)) -> 1.8103112 | AQ4: =IF(A4="","",COUNTIF($D$4:$D$201,$A4)) -> 1 | AR4: =IF(A4="","",IF(AQ4=0,"START","CONTINUOUS")) -> CONTINUOUS | AS4: =IF(A4="","",IF(J4="",Inputs!$B$18,J4)) -> 6 | AT4: =IF(A4="","",IFERROR(_xludf.maxifs($AV$4:$AV$201,$D$4:$D$201,$A4),"")) | AU4: =IF(A4="","",IF(OR(E4="",Inputs!$B$23=""),"",E4/(Inputs!$B$23*60))) -> 0.23666667 | AV4: =IF(A4="","",IF(AQ4=0,AS4+AU4,IF(AT4="",AS4+AU4,AT4+AU4))) -> 6.2366667 | AW4: =IF(A4="","",W4) -> 0.58467827 | AX4: =IF(OR(T4="",P4=""),"",(1/Inputs!$B$9)*((T4/4)^(2/3))*SQRT(P4)) -> 1.2114625 | AY4: =IF(A4="","",IF(AND(AW4="",AX4="",BA4=""),"",IF(OR(UPPER(TRIM(Inputs!$B$24))="MANNING",UPPER(TRIM(Inputs!$B$24))="M"),AX4,IF(OR(UPPER(TRIM(Inputs!$B$24))="PARTIAL",UPPER(TRIM(Inputs!$B$24))="P"),BA4,IF(OR(UPPER(TRIM(Inputs!$B$24))="MAX",UPPER(TRIM(Inputs!$B$24))="X"),MAX(IF(AW4="",0,AW4),IF(AX4="",0,AX4),IF(BA4="",0,BA4)),AW4))))) -> 1.2114625 | AZ4: =IF(BB4="","",CH4) -> 0.12220996 | BA4: =IF(OR(BB4="",AZ4="",T4="",T4<=0,AZ4<=0),"",BB4/((T4^2/8)*(2*ACOS(1-2*AZ4/T4)-SIN(2*ACOS(1-2*AZ4/T4))))) -> 1.2035577 | BB4: =IF(OR(N4="",BC4=""),"",MIN(N4,BC4)) -> 0.028700327 | BC4: =IF(OR(N4="",T4="",P4=""),"",IF(OR(T4="",P4="",(0.94*T4)="",T4<=0,(0.94*T4)<=0),"",(1/Inputs!$B$9)*((T4^2/8)*((2*ACOS(1-2*(0.94*T4)/T4))-SIN((2*ACOS(1-2*(0.94*T4)/T4)))))*((((T4^2/8)*((2*ACOS(1-2*(0.94*T4)/T4))-SIN((2*ACOS(1-2*(0.94*T4)/T4)))))/((T4/2)*((2*ACOS(1-2*(0.94*T4)/T4)))))^(2/3))*SQRT(P4))) -> 0.063967998 | BD4: =IF(BB4="","",0.001*T4) -> 0.00025 | BE4: =IF(BB4="","",0.94*T4) -> 0.235 | BF4: =IF(BB4="","",(BD4+BE4)/2) -> 0.117625 | BG4: =IF(OR(T4="",P4="",BF4="",T4<=0,BF4<=0),"",(1/Inputs!$B$9)*((T4^2/8)*((2*ACOS(1-2*BF4/T4))-SIN((2*ACOS(1-2*BF4/T4)))))*((((T4^2/8)*((2*ACOS(1-2*BF4/T4))-SIN((2*ACOS(1-2*BF4/T4)))))/((T4/2)*((2*ACOS(1-2*BF4/T4)))))^(2/3))*SQRT(P4)) -> 0.026782415 | BH4: =IF(BB4="","",IF(BG4<BB4,BF4,BD4)) -> 0.117625 | BI4: =IF(BB4="","",IF(BG4<BB4,BE4,BF4)) -> 0.235 | BJ4: =IF(BB4="","",(BH4+BI4)/2) -> 0.1763125 | BK4: =IF(OR(T4="",P4="",BJ4="",T4<=0,BJ4<=0),"",(1/Inputs!$B$9)*((T4^2/8)*((2*ACOS(1-2*BJ4/T4))-SIN((2*ACOS(1-2*BJ4/T4)))))*((((T4^2/8)*((2*ACOS(1-2*BJ4/T4))-SIN((2*ACOS(1-2*BJ4/T4)))))/((T4/2)*((2*ACOS(1-2*BJ4/T4)))))^(2/3))*SQRT(P4)) -> 0.050274513 | BL4: =IF(BB4="","",IF(BK4<BB4,BJ4,BH4)) -> 0.117625 | BM4: =IF(BB4="","",IF(BK4<BB4,BI4,BJ4)) -> 0.1763125 | BN4: =IF(BB4="","",(BL4+BM4)/2) -> 0.14696875 | BO4: =IF(OR(T4="",P4="",BN4="",T4<=0,BN4<=0),"",(1/Inputs!$B$9)*((T4^2/8)*((2*ACOS(1-2*BN4/T4))-SIN((2*ACOS(1-2*BN4/T4)))))*((((T4^2/8)*((2*ACOS(1-2*BN4/T4))-SIN((2*ACOS(1-2*BN4/T4)))))/((T4/2)*((2*ACOS(1-2*BN4/T4)))))^(2/3))*SQRT(P4)) -> 0.038714491 | BP4: =IF(BB4="","",IF(BO4<BB4,BN4,BL4)) -> 0.117625 | BQ4: =IF(BB4="","",IF(BO4<BB4,BM4,BN4)) -> 0.14696875 | BR4: =IF(BB4="","",(BP4+BQ4)/2) -> 0.13229687 | BS4: =IF(OR(T4="",P4="",BR4="",T4<=0,BR4<=0),"",(1/Inputs!$B$9)*((T4^2/8)*((2*ACOS(1-2*BR4/T4))-SIN((2*ACOS(1-2*BR4/T4)))))*((((T4^2/8)*((2*ACOS(1-2*BR4/T4))-SIN((2*ACOS(1-2*BR4/T4)))))/((T4/2)*((2*ACOS(1-2*BR4/T4)))))^(2/3))*SQRT(P4)) -> 0.032699717 | BT4: =IF(BB4="","",IF(BS4<BB4,BR4,BP4)) -> 0.117625 | BU4: =IF(BB4="","",IF(BS4<BB4,BQ4,BR4)) -> 0.13229687 | BV4: =IF(BB4="","",(BT4+BU4)/2) -> 0.12496094 | BW4: =IF(OR(T4="",P4="",BV4="",T4<=0,BV4<=0),"",(1/Inputs!$B$9)*((T4^2/8)*((2*ACOS(1-2*BV4/T4))-SIN((2*ACOS(1-2*BV4/T4)))))*((((T4^2/8)*((2*ACOS(1-2*BV4/T4))-SIN((2*ACOS(1-2*BV4/T4)))))/((T4/2)*((2*ACOS(1-2*BV4/T4)))))^(2/3))*SQRT(P4)) -> 0.029717991 | BX4: =IF(BB4="","",IF(BW4<BB4,BV4,BT4)) -> 0.117625 | BY4: =IF(BB4="","",IF(BW4<BB4,BU4,BV4)) -> 0.12496094 | BZ4: =IF(BB4="","",(BX4+BY4)/2) -> 0.12129297 | CA4: =IF(OR(T4="",P4="",BZ4="",T4<=0,BZ4<=0),"",(1/Inputs!$B$9)*((T4^2/8)*((2*ACOS(1-2*BZ4/T4))-SIN((2*ACOS(1-2*BZ4/T4)))))*((((T4^2/8)*((2*ACOS(1-2*BZ4/T4))-SIN((2*ACOS(1-2*BZ4/T4)))))/((T4/2)*((2*ACOS(1-2*BZ4/T4)))))^(2/3))*SQRT(P4)) -> 0.028243126 | CB4: =IF(BB4="","",IF(CA4<BB4,BZ4,BX4)) -> 0.12129297 | CC4: =IF(BB4="","",IF(CA4<BB4,BY4,BZ4)) -> 0.12496094 | CD4: =IF(BB4="","",(CB4+CC4)/2) -> 0.12312695 | CE4: =IF(OR(T4="",P4="",CD4="",T4<=0,CD4<=0),"",(1/Inputs!$B$9)*((T4^2/8)*((2*ACOS(1-2*CD4/T4))-SIN((2*ACOS(1-2*CD4/T4)))))*((((T4^2/8)*((2*ACOS(1-2*CD4/T4))-SIN((2*ACOS(1-2*CD4/T4)))))/((T4/2)*((2*ACOS(1-2*CD4/T4)))))^(2/3))*SQRT(P4)) -> 0.02897895 | CF4: =IF(BB4="","",IF(CE4<BB4,CD4,CB4)) -> 0.12129297 | CG4: =IF(BB4="","",IF(CE4<BB4,CC4,CD4)) -> 0.12312695 | CH4: =IF(BB4="","",(CF4+CG4)/2) -> 0.12220996
A5: L02_P02_P03 | B5: P02 | C5: P03 | D5: L03_P03_P10 | E5: 10.6 | G5: =SUMIFS(CB_plan!$G:$G,CB_plan!$F:$F,$A5) -> 467.89 | H5: =IF(F5="",G5,F5) -> 467.89 | K5: =IF(A5="","",Inputs!$B$13/((IF(AV5="",Inputs!$B$18,AV5)+Inputs!$B$14)^Inputs!$B$15)) -> 122.74928 | L5: =IF(A5="","",IF(H5="","",0.000000278*IF(I5<>"",I5,IFERROR(SUMIFS(CB_plan!$H:$H,CB_plan!$F:$F,$A5)/SUMIFS(CB_plan!$G:$G,CB_plan!$F:$F,$A5),Inputs!$B$17))*H5*K5)) -> 0.010248585 | M5: =IF(A5="","",SUMIFS($N$4:$N$201,$D$4:$D$201,$A5)) -> 0.028700327 | N5: =IF(A5="","",(L5+M5)*Inputs!$B$16) -> 0.038948912 | P5: =IF(A5="","",IF(O5="",Inputs!$B$7,O5)) -> 0.01 | Q5: =IF(A5="","",IF(N5/Inputs!$B$10<=AG5,Inputs!$F$5,IF(N5/Inputs!$B$10>AP5,"OVERSIZE",INDEX(Inputs!$F$5:$F$14,MATCH(N5/Inputs!$B$10,AG5:AP5,1)+1)))) -> 250 | R5: 300 | S5: =IF(A5="","",IF(R5="",Q5,R5)) -> 300 | T5: =IF(OR(S5="",S5="OVERSIZE"),"",S5/1000) -> 0.3 | U5: =IF(T5="","",(1/Inputs!$B$9)*(PI()*T5^2/4)*((T5/4)^(2/3))*SQRT(P5)) -> 0.096700759 | V5: =IF(OR(U5="",N5=""),"",N5/(U5*Inputs!$B$10)) -> 0.50347217 | W5: =IF(OR(T5="",N5=""),"",4*N5/(PI()*T5^2)) -> 0.5510144 | Y5: =IF(A5="","",IF(A5=Inputs!$B$6,Inputs!$B$22,IF(D5="","",IFERROR(INDEX($Z$4:$Z$201,MATCH(D5,$A$4:$A$201,0))+IF(X5="",Inputs!$B$20,X5),"")))) | Z5: =IF(OR(Y5="",P5="",E5=""),"",Y5+P5*E5) | AA5: =IF(C5="","",IFERROR(INDEX(Noeuds_plan!$C$4:$C$200,MATCH(C5,Noeuds_plan!$A$4:$A$200,0)),"")) -> 17.01 | AB5: =IF(B5="","",IFERROR(INDEX(Noeuds_plan!$C$4:$C$200,MATCH(B5,Noeuds_plan!$A$4:$A$200,0)),"")) -> 17.131 | AC5: =IF(OR(AA5="",Y5=""),"",AA5-Y5) | AD5: =IF(OR(AB5="",Z5=""),"",AB5-Z5) | AE5: =IF(A5="","",IF(OR(V5>1,AND(AY5<>"",AY5<Inputs!$B$11),AND(AY5<>"",AY5>Inputs!$B$12),AC5<Inputs!$B$19,AD5<Inputs!$B$19,P5<Inputs!$B$7,P5>Inputs!$B$8),"CHECK","OK")) -> OK | AF5: Top horizontal (from image); Length updated from red dimension labels (2026-06-30 image). | AG5: =IF(A5="","",(1/Inputs!$B$9)*(PI()*(Inputs!$F$5/1000)^2/4)*((Inputs!$F$5/1000/4)^(2/3))*SQRT(P5)) -> 0.03279844 | AH5: =IF(A5="","",(1/Inputs!$B$9)*(PI()*(Inputs!$F$6/1000)^2/4)*((Inputs!$F$6/1000/4)^(2/3))*SQRT(P5)) -> 0.059467529 | AI5: =IF(A5="","",(1/Inputs!$B$9)*(PI()*(Inputs!$F$7/1000)^2/4)*((Inputs!$F$7/1000/4)^(2/3))*SQRT(P5)) -> 0.096700759 | AJ5: =IF(A5="","",(1/Inputs!$B$9)*(PI()*(Inputs!$F$8/1000)^2/4)*((Inputs!$F$8/1000/4)^(2/3))*SQRT(P5)) -> 0.17533014 | AK5: =IF(A5="","",(1/Inputs!$B$9)*(PI()*(Inputs!$F$9/1000)^2/4)*((Inputs!$F$9/1000/4)^(2/3))*SQRT(P5)) -> 0.28510614 | AL5: =IF(A5="","",(1/Inputs!$B$9)*(PI()*(Inputs!$F$10/1000)^2/4)*((Inputs!$F$10/1000/4)^(2/3))*SQRT(P5)) -> 0.43006227 | AM5: =IF(A5="","",(1/Inputs!$B$9)*(PI()*(Inputs!$F$11/1000)^2/4)*((Inputs!$F$11/1000/4)^(2/3))*SQRT(P5)) -> 0.61401154 | AN5: =IF(A5="","",(1/Inputs!$B$9)*(PI()*(Inputs!$F$12/1000)^2/4)*((Inputs!$F$12/1000/4)^(2/3))*SQRT(P5)) -> 0.84058815 | AO5: =IF(A5="","",(1/Inputs!$B$9)*(PI()*(Inputs!$F$13/1000)^2/4)*((Inputs!$F$13/1000/4)^(2/3))*SQRT(P5)) -> 1.113277 | AP5: =IF(A5="","",(1/Inputs!$B$9)*(PI()*(Inputs!$F$14/1000)^2/4)*((Inputs!$F$14/1000/4)^(2/3))*SQRT(P5)) -> 1.8103112 | AQ5: =IF(A5="","",COUNTIF($D$4:$D$201,$A5)) -> 1 | AR5: =IF(A5="","",IF(AQ5=0,"START","CONTINUOUS")) -> CONTINUOUS | AS5: =IF(A5="","",IF(J5="",Inputs!$B$18,J5)) -> 6 | AT5: =IF(A5="","",IFERROR(_xludf.maxifs($AV$4:$AV$201,$D$4:$D$201,$A5),"")) | AU5: =IF(A5="","",IF(OR(E5="",Inputs!$B$23=""),"",E5/(Inputs!$B$23*60))) -> 0.17666667 | AV5: =IF(A5="","",IF(AQ5=0,AS5+AU5,IF(AT5="",AS5+AU5,AT5+AU5))) -> 6.1766667 | AW5: =IF(A5="","",W5) -> 0.5510144 | AX5: =IF(OR(T5="",P5=""),"",(1/Inputs!$B$9)*((T5/4)^(2/3))*SQRT(P5)) -> 1.3680359 | AY5: =IF(A5="","",IF(AND(AW5="",AX5="",BA5=""),"",IF(OR(UPPER(TRIM(Inputs!$B$24))="MANNING",UPPER(TRIM(Inputs!$B$24))="M"),AX5,IF(OR(UPPER(TRIM(Inputs!$B$24))="PARTIAL",UPPER(TRIM(Inputs!$B$24))="P"),BA5,IF(OR(UPPER(TRIM(Inputs!$B$24))="MAX",UPPER(TRIM(Inputs!$B$24))="X"),MAX(IF(AW5="",0,AW5),IF(AX5="",0,AX5),IF(BA5="",0,BA5)),AW5))))) -> 1.3680359 | AZ5: =IF(BB5="","",CH5) -> 0.13344727 | BA5: =IF(OR(BB5="",AZ5="",T5="",T5<=0,AZ5<=0),"",BB5/((T5^2/8)*(2*ACOS(1-2*AZ5/T5)-SIN(2*ACOS(1-2*AZ5/T5))))) -> 1.2817542 | BB5: =IF(OR(N5="",BC5=""),"",MIN(N5,BC5)) -> 0.038948912 | BC5: =IF(OR(N5="",T5="",P5=""),"",IF(OR(T5="",P5="",(0.94*T5)="",T5<=0,(0.94*T5)<=0),"",(1/Inputs!$B$9)*((T5^2/8)*((2*ACOS(1-2*(0.94*T5)/T5))-SIN((2*ACOS(1-2*(0.94*T5)/T5)))))*((((T5^2/8)*((2*ACOS(1-2*(0.94*T5)/T5))-SIN((2*ACOS(1-2*(0.94*T5)/T5)))))/((T5/2)*((2*ACOS(1-2*(0.94*T5)/T5)))))^(2/3))*SQRT(P5))) -> 0.10401902 | BD5: =IF(BB5="","",0.001*T5) -> 0.0003 | BE5: =IF(BB5="","",0.94*T5) -> 0.282 | BF5: =IF(BB5="","",(BD5+BE5)/2) -> 0.14115 | BG5: =IF(OR(T5="",P5="",BF5="",T5<=0,BF5<=0),"",(1/Inputs!$B$9)*((T5^2/8)*((2*ACOS(1-2*BF5/T5))-SIN((2*ACOS(1-2*BF5/T5)))))*((((T5^2/8)*((2*ACOS(1-2*BF5/T5))-SIN((2*ACOS(1-2*BF5/T5)))))/((T5/2)*((2*ACOS(1-2*BF5/T5)))))^(2/3))*SQRT(P5)) -> 0.04355116 | BH5: =IF(BB5="","",IF(BG5<BB5,BF5,BD5)) -> 0.0003 | BI5: =IF(BB5="","",IF(BG5<BB5,BE5,BF5)) -> 0.14115 | BJ5: =IF(BB5="","",(BH5+BI5)/2) -> 0.070725 | BK5: =IF(OR(T5="",P5="",BJ5="",T5<=0,BJ5<=0),"",(1/Inputs!$B$9)*((T5^2/8)*((2*ACOS(1-2*BJ5/T5))-SIN((2*ACOS(1-2*BJ5/T5)))))*((((T5^2/8)*((2*ACOS(1-2*BJ5/T5))-SIN((2*ACOS(1-2*BJ5/T5)))))/((T5/2)*((2*ACOS(1-2*BJ5/T5)))))^(2/3))*SQRT(P5)) -> 0.011786906 | BL5: =IF(BB5="","",IF(BK5<BB5,BJ5,BH5)) -> 0.070725 | BM5: =IF(BB5="","",IF(BK5<BB5,BI5,BJ5)) -> 0.14115 | BN5: =IF(BB5="","",(BL5+BM5)/2) -> 0.1059375 | BO5: =IF(OR(T5="",P5="",BN5="",T5<=0,BN5<=0),"",(1/Inputs!$B$9)*((T5^2/8)*((2*ACOS(1-2*BN5/T5))-SIN((2*ACOS(1-2*BN5/T5)))))*((((T5^2/8)*((2*ACOS(1-2*BN5/T5))-SIN((2*ACOS(1-2*BN5/T5)))))/((T5/2)*((2*ACOS(1-2*BN5/T5)))))^(2/3))*SQRT(P5)) -> 0.025855745 | BP5: =IF(BB5="","",IF(BO5<BB5,BN5,BL5)) -> 0.1059375 | BQ5: =IF(BB5="","",IF(BO5<BB5,BM5,BN5)) -> 0.14115 | BR5: =IF(BB5="","",(BP5+BQ5)/2) -> 0.12354375 | BS5: =IF(OR(T5="",P5="",BR5="",T5<=0,BR5<=0),"",(1/Inputs!$B$9)*((T5^2/8)*((2*ACOS(1-2*BR5/T5))-SIN((2*ACOS(1-2*BR5/T5)))))*((((T5^2/8)*((2*ACOS(1-2*BR5/T5))-SIN((2*ACOS(1-2*BR5/T5)))))/((T5/2)*((2*ACOS(1-2*BR5/T5)))))^(2/3))*SQRT(P5)) -> 0.034361658 | BT5: =IF(BB5="","",IF(BS5<BB5,BR5,BP5)) -> 0.12354375 | BU5: =IF(BB5="","",IF(BS5<BB5,BQ5,BR5)) -> 0.14115 | BV5: =IF(BB5="","",(BT5+BU5)/2) -> 0.13234688 | BW5: =IF(OR(T5="",P5="",BV5="",T5<=0,BV5<=0),"",(1/Inputs!$B$9)*((T5^2/8)*((2*ACOS(1-2*BV5/T5))-SIN((2*ACOS(1-2*BV5/T5)))))*((((T5^2/8)*((2*ACOS(1-2*BV5/T5))-SIN((2*ACOS(1-2*BV5/T5)))))/((T5/2)*((2*ACOS(1-2*BV5/T5)))))^(2/3))*SQRT(P5)) -> 0.038886121 | BX5: =IF(BB5="","",IF(BW5<BB5,BV5,BT5)) -> 0.13234688 | BY5: =IF(BB5="","",IF(BW5<BB5,BU5,BV5)) -> 0.14115 | BZ5: =IF(BB5="","",(BX5+BY5)/2) -> 0.13674844 | CA5: =IF(OR(T5="",P5="",BZ5="",T5<=0,BZ5<=0),"",(1/Inputs!$B$9)*((T5^2/8)*((2*ACOS(1-2*BZ5/T5))-SIN((2*ACOS(1-2*BZ5/T5)))))*((((T5^2/8)*((2*ACOS(1-2*BZ5/T5))-SIN((2*ACOS(1-2*BZ5/T5)))))/((T5/2)*((2*ACOS(1-2*BZ5/T5)))))^(2/3))*SQRT(P5)) -> 0.041203039 | CB5: =IF(BB5="","",IF(CA5<BB5,BZ5,BX5)) -> 0.13234688 | CC5: =IF(BB5="","",IF(CA5<BB5,BY5,BZ5)) -> 0.13674844 | CD5: =IF(BB5="","",(CB5+CC5)/2) -> 0.13454766 | CE5: =IF(OR(T5="",P5="",CD5="",T5<=0,CD5<=0),"",(1/Inputs!$B$9)*((T5^2/8)*((2*ACOS(1-2*CD5/T5))-SIN((2*ACOS(1-2*CD5/T5)))))*((((T5^2/8)*((2*ACOS(1-2*CD5/T5))-SIN((2*ACOS(1-2*CD5/T5)))))/((T5/2)*((2*ACOS(1-2*CD5/T5)))))^(2/3))*SQRT(P5)) -> 0.04004043 | CF5: =IF(BB5="","",IF(CE5<BB5,CD5,CB5)) -> 0.13234688 | CG5: =IF(BB5="","",IF(CE5<BB5,CC5,CD5)) -> 0.13454766 | CH5: =IF(BB5="","",(CF5+CG5)/2) -> 0.13344727
