Workbook

Sheet Guide
A1: RESEAU PLUVIAL - METHODE AVEC ELEVATION DE REFERENCE (EXUTOIRE DROITE)
A3: But: dimensionner diametres, pentes et radiers meme si le radier du reseau public aval est inconnu.
A4: Principe: choisir une elevation de reference a l exutoire (radier connu ou surface connue + profondeur de couverture).
A5: Onglet Inputs: definir les hypotheses hydrauliques, IDF et la liste de diametres disponibles.
A6: Onglet CB_Tributaires: entrer les surfaces de chaque puisard/catch basin et le Pipe_ID qui les recoit.
A7: Onglet Conduites: entrer Pipe_ID, pipe receveur aval, longueur, C, tc, pente manuelle (si connue), terrain amont/aval.
A8: Propagation des radiers: le pipe exutoire prend Inputs!B22; les pipes amont prennent le radier amont du pipe aval + chute de regard.
A9: Dimensionnement: Q_local (rationnelle) + Q amont cumulee -> Q_total_design -> diametre recommande par Manning.
A10: Controle: capacite, vitesse, pentes min/max, recouvrement mini.
A11: Important: les references Receives_into_Pipe_ID doivent pointer vers l aval (vers P_OUT).
A12: Utiliser d abord SURFACE si reseau public inconnu, puis recalibrer quand les radiers municipaux seront disponibles.
A15: Formules cle (texte simple):
... A22: Workflow: (1) paste elevations in Noeuds_plan!C, (2) paste areas in CB_plan!C, (3) review lengths blanks in Conduites_plan_noeuds!E.

Sheet Inputs
A1: INPUTS
A2: Parametre | B2: Valeur | C2: Unite | D2: Commentaire
A3: Reference_Type (INVERT or SURFACE) | B3: SURFACE | C3: - | D3: SURFACE quand radier reseau public inconnu. | F3: Diametres disponibles (mm)
A4: Outfall_reference_elevation_m | B4: 103.2 | C4: m | D4: Si SURFACE: niveau terrain exutoire. Si INVERT: radier exutoire.
A5: Outfall_cover_depth_if_surface_m | B5: 1.8 | C5: m | D5: Profondeur terrain->radier a l exutoire (si SURFACE). | F5: 200
A6: Outfall_pipe_ID | B6: L12_JOUT_PUB | C6: - | D6: Pipe qui se connecte au reseau public (droite). | F6: 250
A7: Min_slope_m_per_m | B7: 0.003 | C7: m/m | D7: Pente minimale de controle. | F7: 300
A8: Max_slope_m_per_m | B8: 0.05 | C8: m/m | D8: Pente maximale de controle. | F8: 375
A9: Manning_n | B9: 0.013 | C9: - | D9: Rugosite Manning. | F9: 450
A10: Design_fill_ratio_limit | B10: 0.8 | C10: - | D10: Q/(Q pleine) admissible. | F10: 525
A11: Min_velocity_mps | B11: 0.75 | C11: m/s | D11: Vitesse minimale souhaitee. | F11: 600
A12: Max_velocity_mps | B12: 3 | C12: m/s | D12: Vitesse maximale souhaitee. | F12: 675
A13: IDF_a | B13: 4156.21 | C13: - | D13: i = a/(tc+b)^c | F13: 750
A14: IDF_b | B14: 15.1 | C14: min | D14: Parametre IDF b. | F14: 900
A15: IDF_c | B15: 1.026 | C15: - | D15: Parametre IDF c.
A16: Flow_safety_factor | B16: 1.1 | C16: - | D16: Facteur applique a Q total.
A17: Default_runoff_C | B17: 0.9 | C17: - | D17: Utilise si C local non renseigne.
A18: Default_tc_min | B18: 10 | C18: min | D18: Utilise si tc local non renseigne.
A19: Min_cover_depth_m | B19: 1.2 | C19: m | D19: Recouvrement mini de controle.
A20: Default_junction_drop_m | B20: 0.02 | C20: m | D20: Chute de regard par defaut.
A22: Outfall_invert_derived_m | B22: =IF(UPPER(TRIM(B3))="SURFACE",B4-B5,B4)

Sheet CB_Tributaires
A1: AREAS TRIBUTAIRES PAR CATCH BASIN
A3: CB_ID | B3: Receives_into_Pipe_ID | C3: Area_m2 | D3: Runoff_C | E3: Area_x_C | F3: Notes
E4: =IF(OR(C4="",D4=""),"",C4*D4)
E5: =IF(OR(C5="",D5=""),"",C5*D5)
E6: =IF(OR(C6="",D6=""),"",C6*D6)
E7: =IF(OR(C7="",D7=""),"",C7*D7)
E8: =IF(OR(C8="",D8=""),"",C8*D8)
E9: =IF(OR(C9="",D9=""),"",C9*D9)
E10: =IF(OR(C10="",D10=""),"",C10*D10)
E11: =IF(OR(C11="",D11=""),"",C11*D11)
E12: =IF(OR(C12="",D12=""),"",C12*D12)
E13: =IF(OR(C13="",D13=""),"",C13*D13)
E14: =IF(OR(C14="",D14=""),"",C14*D14)
E15: =IF(OR(C15="",D15=""),"",C15*D15)
... E204: =IF(OR(C204="",D204=""),"",C204*D204)

Sheet Conduites
A1: DIMENSIONNEMENT ET PROFIL - CONDUITES VERS EXUTOIRE DROITE
A2: Network_status | B2: =IF(COUNTIF(AC4:AC203,"CHECK")>0,"CHECK","OK") | D2: Pipes_with_checks | E2: =COUNTIF(AC4:AC203,"CHECK")
A3: Pipe_ID | B3: Receives_into_Pipe_ID | C3: Length_m | D3: Area_local_override_m2 | E3: Area_from_CB_m2 | F3: Area_used_m2 | G3: C_local | H3: Tc_local_min | I3: Intensity_mmh | J3: Q_local_m3s | K3: Q_from_upstream_m3s | L3: Q_total_design_m3s | M3: Slope_manual_m/m | N3: Slope_used_m/m | O3: Dia_recommended_mm | P3: Dia_override_mm | Q3: Dia_used_mm | R3: Dia_used_m | S3: Capacity_full_m3s | T3: Q_over_capacity_ratio | U3: Velocity_mps | V3: Junction_drop_m | W3: Invert_down_m | X3: Invert_up_m | Y3: Ground_down_m | Z3: Ground_up_m | AA3: Cover_down_m | AB3: Cover_up_m | AC3: Checks | AD3: Cap_5 | AE3: Cap_6 | AF3: Cap_7 | AG3: Cap_8 | AH3: Cap_9 | AI3: Cap_10 | AJ3: Cap_11 | AK3: Cap_12 | AL3: Cap_13 | AM3: Cap_14
A4: P01 | B4: P02 | C4: 7 | E4: =SUMIFS(CB_Tributaires!$C:$C,CB_Tributaires!$B:$B,$A4) | F4: =IF(D4="",E4,D4) | I4: =IF(A4="","",Inputs!$B$13/((IF(H4="",Inputs!$B$18,H4)+Inputs!$B$14)^Inputs!$B$15)) | J4: =IF(A4="","",0.00278*IF(G4="",Inputs!$B$17,G4)*F4*I4) | K4: =IF(A4="","",SUMIFS($L$4:$L$203,$B$4:$B$203,$A4)) | L4: =IF(A4="","",(J4+K4)*Inputs!$B$16) | N4: =IF(A4="","",IF(M4="",Inputs!$B$7,M4)) | O4: =IF(A4="","",IF(L4/Inputs!$B$10<=AD4,Inputs!$F$5,IF(L4/Inputs!$B$10>AM4,"OVERSIZE",INDEX(Inputs!$F$5:$F$14,MATCH(L4/Inputs!$B$10,AD4:AM4,1)+1)))) | Q4: =IF(A4="","",IF(P4="",O4,P4)) | R4: =IF(OR(Q4="",Q4="OVERSIZE"),"",Q4/1000) | S4: =IF(R4="","",(1/Inputs!$B$9)*(PI()*R4^2/4)*((R4/4)^(2/3))*SQRT(N4)) | T4: =IF(OR(S4="",L4=""),"",L4/(S4*Inputs!$B$10)) | U4: =IF(OR(R4="",L4=""),"",4*L4/(PI()*R4^2)) | W4: =IF(A4="","",IF(A4=Inputs!$B$6,Inputs!$B$22,IF(B4="","",IFERROR(INDEX($X$4:$X$203,MATCH(B4,$A$4:$A$203,0))+IF(V4="",Inputs!$B$20,V4),"")))) | X4: =IF(OR(W4="",N4="",C4=""),"",W4+N4*C4) | AA4: =IF(OR(Y4="",W4=""),"",Y4-W4) | AB4: =IF(OR(Z4="",X4=""),"",Z4-X4) | AC4: =IF(A4="","",IF(OR(T4>1,U4<Inputs!$B$11,U4>Inputs!$B$12,AA4<Inputs!$B$19,AB4<Inputs!$B$19,N4<Inputs!$B$7,N4>Inputs!$B$8),"CHECK","OK")) | AD4: =IF(A4="","",(1/Inputs!$B$9)*(PI()*(Inputs!$F$5/1000)^2/4)*((Inputs!$F$5/1000/4)^(2/3))*SQRT(N4)) | AE4: =IF(A4="","",(1/Inputs!$B$9)*(PI()*(Inputs!$F$6/1000)^2/4)*((Inputs!$F$6/1000/4)^(2/3))*SQRT(N4)) | AF4: =IF(A4="","",(1/Inputs!$B$9)*(PI()*(Inputs!$F$7/1000)^2/4)*((Inputs!$F$7/1000/4)^(2/3))*SQRT(N4)) | AG4: =IF(A4="","",(1/Inputs!$B$9)*(PI()*(Inputs!$F$8/1000)^2/4)*((Inputs!$F$8/1000/4)^(2/3))*SQRT(N4)) | AH4: =IF(A4="","",(1/Inputs!$B$9)*(PI()*(Inputs!$F$9/1000)^2/4)*((Inputs!$F$9/1000/4)^(2/3))*SQRT(N4)) | AI4: =IF(A4="","",(1/Inputs!$B$9)*(PI()*(Inputs!$F$10/1000)^2/4)*((Inputs!$F$10/1000/4)^(2/3))*SQRT(N4)) | AJ4: =IF(A4="","",(1/Inputs!$B$9)*(PI()*(Inputs!$F$11/1000)^2/4)*((Inputs!$F$11/1000/4)^(2/3))*SQRT(N4)) | AK4: =IF(A4="","",(1/Inputs!$B$9)*(PI()*(Inputs!$F$12/1000)^2/4)*((Inputs!$F$12/1000/4)^(2/3))*SQRT(N4)) | AL4: =IF(A4="","",(1/Inputs!$B$9)*(PI()*(Inputs!$F$13/1000)^2/4)*((Inputs!$F$13/1000/4)^(2/3))*SQRT(N4)) | AM4: =IF(A4="","",(1/Inputs!$B$9)*(PI()*(Inputs!$F$14/1000)^2/4)*((Inputs!$F$14/1000/4)^(2/3))*SQRT(N4))
A5: P02 | B5: P06 | C5: 9.6 | E5: =SUMIFS(CB_Tributaires!$C:$C,CB_Tributaires!$B:$B,$A5) | F5: =IF(D5="",E5,D5) | I5: =IF(A5="","",Inputs!$B$13/((IF(H5="",Inputs!$B$18,H5)+Inputs!$B$14)^Inputs!$B$15)) | J5: =IF(A5="","",0.00278*IF(G5="",Inputs!$B$17,G5)*F5*I5) | K5: =IF(A5="","",SUMIFS($L$4:$L$203,$B$4:$B$203,$A5)) | L5: =IF(A5="","",(J5+K5)*Inputs!$B$16) | N5: =IF(A5="","",IF(M5="",Inputs!$B$7,M5)) | O5: =IF(A5="","",IF(L5/Inputs!$B$10<=AD5,Inputs!$F$5,IF(L5/Inputs!$B$10>AM5,"OVERSIZE",INDEX(Inputs!$F$5:$F$14,MATCH(L5/Inputs!$B$10,AD5:AM5,1)+1)))) | Q5: =IF(A5="","",IF(P5="",O5,P5)) | R5: =IF(OR(Q5="",Q5="OVERSIZE"),"",Q5/1000) | S5: =IF(R5="","",(1/Inputs!$B$9)*(PI()*R5^2/4)*((R5/4)^(2/3))*SQRT(N5)) | T5: =IF(OR(S5="",L5=""),"",L5/(S5*Inputs!$B$10)) | U5: =IF(OR(R5="",L5=""),"",4*L5/(PI()*R5^2)) | W5: =IF(A5="","",IF(A5=Inputs!$B$6,Inputs!$B$22,IF(B5="","",IFERROR(INDEX($X$4:$X$203,MATCH(B5,$A$4:$A$203,0))+IF(V5="",Inputs!$B$20,V5),"")))) | X5: =IF(OR(W5="",N5="",C5=""),"",W5+N5*C5) | AA5: =IF(OR(Y5="",W5=""),"",Y5-W5) | AB5: =IF(OR(Z5="",X5=""),"",Z5-X5) | AC5: =IF(A5="","",IF(OR(T5>1,U5<Inputs!$B$11,U5>Inputs!$B$12,AA5<Inputs!$B$19,AB5<Inputs!$B$19,N5<Inputs!$B$7,N5>Inputs!$B$8),"CHECK","OK")) | AD5: =IF(A5="","",(1/Inputs!$B$9)*(PI()*(Inputs!$F$5/1000)^2/4)*((Inputs!$F$5/1000/4)^(2/3))*SQRT(N5)) | AE5: =IF(A5="","",(1/Inputs!$B$9)*(PI()*(Inputs!$F$6/1000)^2/4)*((Inputs!$F$6/1000/4)^(2/3))*SQRT(N5)) | AF5: =IF(A5="","",(1/Inputs!$B$9)*(PI()*(Inputs!$F$7/1000)^2/4)*((Inputs!$F$7/1000/4)^(2/3))*SQRT(N5)) | AG5: =IF(A5="","",(1/Inputs!$B$9)*(PI()*(Inputs!$F$8/1000)^2/4)*((Inputs!$F$8/1000/4)^(2/3))*SQRT(N5)) | AH5: =IF(A5="","",(1/Inputs!$B$9)*(PI()*(Inputs!$F$9/1000)^2/4)*((Inputs!$F$9/1000/4)^(2/3))*SQRT(N5)) | AI5: =IF(A5="","",(1/Inputs!$B$9)*(PI()*(Inputs!$F$10/1000)^2/4)*((Inputs!$F$10/1000/4)^(2/3))*SQRT(N5)) | AJ5: =IF(A5="","",(1/Inputs!$B$9)*(PI()*(Inputs!$F$11/1000)^2/4)*((Inputs!$F$11/1000/4)^(2/3))*SQRT(N5)) | AK5: =IF(A5="","",(1/Inputs!$B$9)*(PI()*(Inputs!$F$12/1000)^2/4)*((Inputs!$F$12/1000/4)^(2/3))*SQRT(N5)) | AL5: =IF(A5="","",(1/Inputs!$B$9)*(PI()*(Inputs!$F$13/1000)^2/4)*((Inputs!$F$13/1000/4)^(2/3))*SQRT(N5)) | AM5: =IF(A5="","",(1/Inputs!$B$9)*(PI()*(Inputs!$F$14/1000)^2/4)*((Inputs!$F$14/1000/4)^(2/3))*SQRT(N5))
A6: P03 | B6: P06 | C6: 6.95 | E6: =SUMIFS(CB_Tributaires!$C:$C,CB_Tributaires!$B:$B,$A6) | F6: =IF(D6="",E6,D6) | I6: =IF(A6="","",Inputs!$B$13/((IF(H6="",Inputs!$B$18,H6)+Inputs!$B$14)^Inputs!$B$15)) | J6: =IF(A6="","",0.00278*IF(G6="",Inputs!$B$17,G6)*F6*I6) | K6: =IF(A6="","",SUMIFS($L$4:$L$203,$B$4:$B$203,$A6)) | L6: =IF(A6="","",(J6+K6)*Inputs!$B$16) | N6: =IF(A6="","",IF(M6="",Inputs!$B$7,M6)) | O6: =IF(A6="","",IF(L6/Inputs!$B$10<=AD6,Inputs!$F$5,IF(L6/Inputs!$B$10>AM6,"OVERSIZE",INDEX(Inputs!$F$5:$F$14,MATCH(L6/Inputs!$B$10,AD6:AM6,1)+1)))) | Q6: =IF(A6="","",IF(P6="",O6,P6)) | R6: =IF(OR(Q6="",Q6="OVERSIZE"),"",Q6/1000) | S6: =IF(R6="","",(1/Inputs!$B$9)*(PI()*R6^2/4)*((R6/4)^(2/3))*SQRT(N6)) | T6: =IF(OR(S6="",L6=""),"",L6/(S6*Inputs!$B$10)) | U6: =IF(OR(R6="",L6=""),"",4*L6/(PI()*R6^2)) | W6: =IF(A6="","",IF(A6=Inputs!$B$6,Inputs!$B$22,IF(B6="","",IFERROR(INDEX($X$4:$X$203,MATCH(B6,$A$4:$A$203,0))+IF(V6="",Inputs!$B$20,V6),"")))) | X6: =IF(OR(W6="",N6="",C6=""),"",W6+N6*C6) | AA6: =IF(OR(Y6="",W6=""),"",Y6-W6) | AB6: =IF(OR(Z6="",X6=""),"",Z6-X6) | AC6: =IF(A6="","",IF(OR(T6>1,U6<Inputs!$B$11,U6>Inputs!$B$12,AA6<Inputs!$B$19,AB6<Inputs!$B$19,N6<Inputs!$B$7,N6>Inputs!$B$8),"CHECK","OK")) | AD6: =IF(A6="","",(1/Inputs!$B$9)*(PI()*(Inputs!$F$5/1000)^2/4)*((Inputs!$F$5/1000/4)^(2/3))*SQRT(N6)) | AE6: =IF(A6="","",(1/Inputs!$B$9)*(PI()*(Inputs!$F$6/1000)^2/4)*((Inputs!$F$6/1000/4)^(2/3))*SQRT(N6)) | AF6: =IF(A6="","",(1/Inputs!$B$9)*(PI()*(Inputs!$F$7/1000)^2/4)*((Inputs!$F$7/1000/4)^(2/3))*SQRT(N6)) | AG6: =IF(A6="","",(1/Inputs!$B$9)*(PI()*(Inputs!$F$8/1000)^2/4)*((Inputs!$F$8/1000/4)^(2/3))*SQRT(N6)) | AH6: =IF(A6="","",(1/Inputs!$B$9)*(PI()*(Inputs!$F$9/1000)^2/4)*((Inputs!$F$9/1000/4)^(2/3))*SQRT(N6)) | AI6: =IF(A6="","",(1/Inputs!$B$9)*(PI()*(Inputs!$F$10/1000)^2/4)*((Inputs!$F$10/1000/4)^(2/3))*SQRT(N6)) | AJ6: =IF(A6="","",(1/Inputs!$B$9)*(PI()*(Inputs!$F$11/1000)^2/4)*((Inputs!$F$11/1000/4)^(2/3))*SQRT(N6)) | AK6: =IF(A6="","",(1/Inputs!$B$9)*(PI()*(Inputs!$F$12/1000)^2/4)*((Inputs!$F$12/1000/4)^(2/3))*SQRT(N6)) | AL6: =IF(A6="","",(1/Inputs!$B$9)*(PI()*(Inputs!$F$13/1000)^2/4)*((Inputs!$F$13/1000/4)^(2/3))*SQRT(N6)) | AM6: =IF(A6="","",(1/Inputs!$B$9)*(PI()*(Inputs!$F$14/1000)^2/4)*((Inputs!$F$14/1000/4)^(2/3))*SQRT(N6))
A7: P04 | B7: P05 | C7: 11.54 | E7: =SUMIFS(CB_Tributaires!$C:$C,CB_Tributaires!$B:$B,$A7) | F7: =IF(D7="",E7,D7) | I7: =IF(A7="","",Inputs!$B$13/((IF(H7="",Inputs!$B$18,H7)+Inputs!$B$14)^Inputs!$B$15)) | J7: =IF(A7="","",0.00278*IF(G7="",Inputs!$B$17,G7)*F7*I7) | K7: =IF(A7="","",SUMIFS($L$4:$L$203,$B$4:$B$203,$A7)) | L7: =IF(A7="","",(J7+K7)*Inputs!$B$16) | N7: =IF(A7="","",IF(M7="",Inputs!$B$7,M7)) | O7: =IF(A7="","",IF(L7/Inputs!$B$10<=AD7,Inputs!$F$5,IF(L7/Inputs!$B$10>AM7,"OVERSIZE",INDEX(Inputs!$F$5:$F$14,MATCH(L7/Inputs!$B$10,AD7:AM7,1)+1)))) | Q7: =IF(A7="","",IF(P7="",O7,P7)) | R7: =IF(OR(Q7="",Q7="OVERSIZE"),"",Q7/1000) | S7: =IF(R7="","",(1/Inputs!$B$9)*(PI()*R7^2/4)*((R7/4)^(2/3))*SQRT(N7)) | T7: =IF(OR(S7="",L7=""),"",L7/(S7*Inputs!$B$10)) | U7: =IF(OR(R7="",L7=""),"",4*L7/(PI()*R7^2)) | W7: =IF(A7="","",IF(A7=Inputs!$B$6,Inputs!$B$22,IF(B7="","",IFERROR(INDEX($X$4:$X$203,MATCH(B7,$A$4:$A$203,0))+IF(V7="",Inputs!$B$20,V7),"")))) | X7: =IF(OR(W7="",N7="",C7=""),"",W7+N7*C7) | AA7: =IF(OR(Y7="",W7=""),"",Y7-W7) | AB7: =IF(OR(Z7="",X7=""),"",Z7-X7) | AC7: =IF(A7="","",IF(OR(T7>1,U7<Inputs!$B$11,U7>Inputs!$B$12,AA7<Inputs!$B$19,AB7<Inputs!$B$19,N7<Inputs!$B$7,N7>Inputs!$B$8),"CHECK","OK")) | AD7: =IF(A7="","",(1/Inputs!$B$9)*(PI()*(Inputs!$F$5/1000)^2/4)*((Inputs!$F$5/1000/4)^(2/3))*SQRT(N7)) | AE7: =IF(A7="","",(1/Inputs!$B$9)*(PI()*(Inputs!$F$6/1000)^2/4)*((Inputs!$F$6/1000/4)^(2/3))*SQRT(N7)) | AF7: =IF(A7="","",(1/Inputs!$B$9)*(PI()*(Inputs!$F$7/1000)^2/4)*((Inputs!$F$7/1000/4)^(2/3))*SQRT(N7)) | AG7: =IF(A7="","",(1/Inputs!$B$9)*(PI()*(Inputs!$F$8/1000)^2/4)*((Inputs!$F$8/1000/4)^(2/3))*SQRT(N7)) | AH7: =IF(A7="","",(1/Inputs!$B$9)*(PI()*(Inputs!$F$9/1000)^2/4)*((Inputs!$F$9/1000/4)^(2/3))*SQRT(N7)) | AI7: =IF(A7="","",(1/Inputs!$B$9)*(PI()*(Inputs!$F$10/1000)^2/4)*((Inputs!$F$10/1000/4)^(2/3))*SQRT(N7)) | AJ7: =IF(A7="","",(1/Inputs!$B$9)*(PI()*(Inputs!$F$11/1000)^2/4)*((Inputs!$F$11/1000/4)^(2/3))*SQRT(N7)) | AK7: =IF(A7="","",(1/Inputs!$B$9)*(PI()*(Inputs!$F$12/1000)^2/4)*((Inputs!$F$12/1000/4)^(2/3))*SQRT(N7)) | AL7: =IF(A7="","",(1/Inputs!$B$9)*(PI()*(Inputs!$F$13/1000)^2/4)*((Inputs!$F$13/1000/4)^(2/3))*SQRT(N7)) | AM7: =IF(A7="","",(1/Inputs!$B$9)*(PI()*(Inputs!$F$14/1000)^2/4)*((Inputs!$F$14/1000/4)^(2/3))*SQRT(N7))
A8: P05 | B8: P06 | C8: 14.25 | E8: =SUMIFS(CB_Tributaires!$C:$C,CB_Tributaires!$B:$B,$A8) | F8: =IF(D8="",E8,D8) | I8: =IF(A8="","",Inputs!$B$13/((IF(H8="",Inputs!$B$18,H8)+Inputs!$B$14)^Inputs!$B$15)) | J8: =IF(A8="","",0.00278*IF(G8="",Inputs!$B$17,G8)*F8*I8) | K8: =IF(A8="","",SUMIFS($L$4:$L$203,$B$4:$B$203,$A8)) | L8: =IF(A8="","",(J8+K8)*Inputs!$B$16) | N8: =IF(A8="","",IF(M8="",Inputs!$B$7,M8)) | O8: =IF(A8="","",IF(L8/Inputs!$B$10<=AD8,Inputs!$F$5,IF(L8/Inputs!$B$10>AM8,"OVERSIZE",INDEX(Inputs!$F$5:$F$14,MATCH(L8/Inputs!$B$10,AD8:AM8,1)+1)))) | Q8: =IF(A8="","",IF(P8="",O8,P8)) | R8: =IF(OR(Q8="",Q8="OVERSIZE"),"",Q8/1000) | S8: =IF(R8="","",(1/Inputs!$B$9)*(PI()*R8^2/4)*((R8/4)^(2/3))*SQRT(N8)) | T8: =IF(OR(S8="",L8=""),"",L8/(S8*Inputs!$B$10)) | U8: =IF(OR(R8="",L8=""),"",4*L8/(PI()*R8^2)) | W8: =IF(A8="","",IF(A8=Inputs!$B$6,Inputs!$B$22,IF(B8="","",IFERROR(INDEX($X$4:$X$203,MATCH(B8,$A$4:$A$203,0))+IF(V8="",Inputs!$B$20,V8),"")))) | X8: =IF(OR(W8="",N8="",C8=""),"",W8+N8*C8) | AA8: =IF(OR(Y8="",W8=""),"",Y8-W8) | AB8: =IF(OR(Z8="",X8=""),"",Z8-X8) | AC8: =IF(A8="","",IF(OR(T8>1,U8<Inputs!$B$11,U8>Inputs!$B$12,AA8<Inputs!$B$19,AB8<Inputs!$B$19,N8<Inputs!$B$7,N8>Inputs!$B$8),"CHECK","OK")) | AD8: =IF(A8="","",(1/Inputs!$B$9)*(PI()*(Inputs!$F$5/1000)^2/4)*((Inputs!$F$5/1000/4)^(2/3))*SQRT(N8)) | AE8: =IF(A8="","",(1/Inputs!$B$9)*(PI()*(Inputs!$F$6/1000)^2/4)*((Inputs!$F$6/1000/4)^(2/3))*SQRT(N8)) | AF8: =IF(A8="","",(1/Inputs!$B$9)*(PI()*(Inputs!$F$7/1000)^2/4)*((Inputs!$F$7/1000/4)^(2/3))*SQRT(N8)) | AG8: =IF(A8="","",(1/Inputs!$B$9)*(PI()*(Inputs!$F$8/1000)^2/4)*((Inputs!$F$8/1000/4)^(2/3))*SQRT(N8)) | AH8: =IF(A8="","",(1/Inputs!$B$9)*(PI()*(Inputs!$F$9/1000)^2/4)*((Inputs!$F$9/1000/4)^(2/3))*SQRT(N8)) | AI8: =IF(A8="","",(1/Inputs!$B$9)*(PI()*(Inputs!$F$10/1000)^2/4)*((Inputs!$F$10/1000/4)^(2/3))*SQRT(N8)) | AJ8: =IF(A8="","",(1/Inputs!$B$9)*(PI()*(Inputs!$F$11/1000)^2/4)*((Inputs!$F$11/1000/4)^(2/3))*SQRT(N8)) | AK8: =IF(A8="","",(1/Inputs!$B$9)*(PI()*(Inputs!$F$12/1000)^2/4)*((Inputs!$F$12/1000/4)^(2/3))*SQRT(N8)) | AL8: =IF(A8="","",(1/Inputs!$B$9)*(PI()*(Inputs!$F$13/1000)^2/4)*((Inputs!$F$13/1000/4)^(2/3))*SQRT(N8)) | AM8: =IF(A8="","",(1/Inputs!$B$9)*(PI()*(Inputs!$F$14/1000)^2/4)*((Inputs!$F$14/1000/4)^(2/3))*SQRT(N8))
A9: P07 | B9: P08 | C9: 14.29 | E9: =SUMIFS(CB_Tributaires!$C:$C,CB_Tributaires!$B:$B,$A9) | F9: =IF(D9="",E9,D9) | I9: =IF(A9="","",Inputs!$B$13/((IF(H9="",Inputs!$B$18,H9)+Inputs!$B$14)^Inputs!$B$15)) | J9: =IF(A9="","",0.00278*IF(G9="",Inputs!$B$17,G9)*F9*I9) | K9: =IF(A9="","",SUMIFS($L$4:$L$203,$B$4:$B$203,$A9)) | L9: =IF(A9="","",(J9+K9)*Inputs!$B$16) | N9: =IF(A9="","",IF(M9="",Inputs!$B$7,M9)) | O9: =IF(A9="","",IF(L9/Inputs!$B$10<=AD9,Inputs!$F$5,IF(L9/Inputs!$B$10>AM9,"OVERSIZE",INDEX(Inputs!$F$5:$F$14,MATCH(L9/Inputs!$B$10,AD9:AM9,1)+1)))) | Q9: =IF(A9="","",IF(P9="",O9,P9)) | R9: =IF(OR(Q9="",Q9="OVERSIZE"),"",Q9/1000) | S9: =IF(R9="","",(1/Inputs!$B$9)*(PI()*R9^2/4)*((R9/4)^(2/3))*SQRT(N9)) | T9: =IF(OR(S9="",L9=""),"",L9/(S9*Inputs!$B$10)) | U9: =IF(OR(R9="",L9=""),"",4*L9/(PI()*R9^2)) | W9: =IF(A9="","",IF(A9=Inputs!$B$6,Inputs!$B$22,IF(B9="","",IFERROR(INDEX($X$4:$X$203,MATCH(B9,$A$4:$A$203,0))+IF(V9="",Inputs!$B$20,V9),"")))) | X9: =IF(OR(W9="",N9="",C9=""),"",W9+N9*C9) | AA9: =IF(OR(Y9="",W9=""),"",Y9-W9) | AB9: =IF(OR(Z9="",X9=""),"",Z9-X9) | AC9: =IF(A9="","",IF(OR(T9>1,U9<Inputs!$B$11,U9>Inputs!$B$12,AA9<Inputs!$B$19,AB9<Inputs!$B$19,N9<Inputs!$B$7,N9>Inputs!$B$8),"CHECK","OK")) | AD9: =IF(A9="","",(1/Inputs!$B$9)*(PI()*(Inputs!$F$5/1000)^2/4)*((Inputs!$F$5/1000/4)^(2/3))*SQRT(N9)) | AE9: =IF(A9="","",(1/Inputs!$B$9)*(PI()*(Inputs!$F$6/1000)^2/4)*((Inputs!$F$6/1000/4)^(2/3))*SQRT(N9)) | AF9: =IF(A9="","",(1/Inputs!$B$9)*(PI()*(Inputs!$F$7/1000)^2/4)*((Inputs!$F$7/1000/4)^(2/3))*SQRT(N9)) | AG9: =IF(A9="","",(1/Inputs!$B$9)*(PI()*(Inputs!$F$8/1000)^2/4)*((Inputs!$F$8/1000/4)^(2/3))*SQRT(N9)) | AH9: =IF(A9="","",(1/Inputs!$B$9)*(PI()*(Inputs!$F$9/1000)^2/4)*((Inputs!$F$9/1000/4)^(2/3))*SQRT(N9)) | AI9: =IF(A9="","",(1/Inputs!$B$9)*(PI()*(Inputs!$F$10/1000)^2/4)*((Inputs!$F$10/1000/4)^(2/3))*SQRT(N9)) | AJ9: =IF(A9="","",(1/Inputs!$B$9)*(PI()*(Inputs!$F$11/1000)^2/4)*((Inputs!$F$11/1000/4)^(2/3))*SQRT(N9)) | AK9: =IF(A9="","",(1/Inputs!$B$9)*(PI()*(Inputs!$F$12/1000)^2/4)*((Inputs!$F$12/1000/4)^(2/3))*SQRT(N9)) | AL9: =IF(A9="","",(1/Inputs!$B$9)*(PI()*(Inputs!$F$13/1000)^2/4)*((Inputs!$F$13/1000/4)^(2/3))*SQRT(N9)) | AM9: =IF(A9="","",(1/Inputs!$B$9)*(PI()*(Inputs!$F$14/1000)^2/4)*((Inputs!$F$14/1000/4)^(2/3))*SQRT(N9))
A10: P08 | B10: P09 | C10: 12.4 | E10: =SUMIFS(CB_Tributaires!$C:$C,CB_Tributaires!$B:$B,$A10) | F10: =IF(D10="",E10,D10) | I10: =IF(A10="","",Inputs!$B$13/((IF(H10="",Inputs!$B$18,H10)+Inputs!$B$14)^Inputs!$B$15)) | J10: =IF(A10="","",0.00278*IF(G10="",Inputs!$B$17,G10)*F10*I10) | K10: =IF(A10="","",SUMIFS($L$4:$L$203,$B$4:$B$203,$A10)) | L10: =IF(A10="","",(J10+K10)*Inputs!$B$16) | N10: =IF(A10="","",IF(M10="",Inputs!$B$7,M10)) | O10: =IF(A10="","",IF(L10/Inputs!$B$10<=AD10,Inputs!$F$5,IF(L10/Inputs!$B$10>AM10,"OVERSIZE",INDEX(Inputs!$F$5:$F$14,MATCH(L10/Inputs!$B$10,AD10:AM10,1)+1)))) | Q10: =IF(A10="","",IF(P10="",O10,P10)) | R10: =IF(OR(Q10="",Q10="OVERSIZE"),"",Q10/1000) | S10: =IF(R10="","",(1/Inputs!$B$9)*(PI()*R10^2/4)*((R10/4)^(2/3))*SQRT(N10)) | T10: =IF(OR(S10="",L10=""),"",L10/(S10*Inputs!$B$10)) | U10: =IF(OR(R10="",L10=""),"",4*L10/(PI()*R10^2)) | W10: =IF(A10="","",IF(A10=Inputs!$B$6,Inputs!$B$22,IF(B10="","",IFERROR(INDEX($X$4:$X$203,MATCH(B10,$A$4:$A$203,0))+IF(V10="",Inputs!$B$20,V10),"")))) | X10: =IF(OR(W10="",N10="",C10=""),"",W10+N10*C10) | AA10: =IF(OR(Y10="",W10=""),"",Y10-W10) | AB10: =IF(OR(Z10="",X10=""),"",Z10-X10) | AC10: =IF(A10="","",IF(OR(T10>1,U10<Inputs!$B$11,U10>Inputs!$B$12,AA10<Inputs!$B$19,AB10<Inputs!$B$19,N10<Inputs!$B$7,N10>Inputs!$B$8),"CHECK","OK")) | AD10: =IF(A10="","",(1/Inputs!$B$9)*(PI()*(Inputs!$F$5/1000)^2/4)*((Inputs!$F$5/1000/4)^(2/3))*SQRT(N10)) | AE10: =IF(A10="","",(1/Inputs!$B$9)*(PI()*(Inputs!$F$6/1000)^2/4)*((Inputs!$F$6/1000/4)^(2/3))*SQRT(N10)) | AF10: =IF(A10="","",(1/Inputs!$B$9)*(PI()*(Inputs!$F$7/1000)^2/4)*((Inputs!$F$7/1000/4)^(2/3))*SQRT(N10)) | AG10: =IF(A10="","",(1/Inputs!$B$9)*(PI()*(Inputs!$F$8/1000)^2/4)*((Inputs!$F$8/1000/4)^(2/3))*SQRT(N10)) | AH10: =IF(A10="","",(1/Inputs!$B$9)*(PI()*(Inputs!$F$9/1000)^2/4)*((Inputs!$F$9/1000/4)^(2/3))*SQRT(N10)) | AI10: =IF(A10="","",(1/Inputs!$B$9)*(PI()*(Inputs!$F$10/1000)^2/4)*((Inputs!$F$10/1000/4)^(2/3))*SQRT(N10)) | AJ10: =IF(A10="","",(1/Inputs!$B$9)*(PI()*(Inputs!$F$11/1000)^2/4)*((Inputs!$F$11/1000/4)^(2/3))*SQRT(N10)) | AK10: =IF(A10="","",(1/Inputs!$B$9)*(PI()*(Inputs!$F$12/1000)^2/4)*((Inputs!$F$12/1000/4)^(2/3))*SQRT(N10)) | AL10: =IF(A10="","",(1/Inputs!$B$9)*(PI()*(Inputs!$F$13/1000)^2/4)*((Inputs!$F$13/1000/4)^(2/3))*SQRT(N10)) | AM10: =IF(A10="","",(1/Inputs!$B$9)*(PI()*(Inputs!$F$14/1000)^2/4)*((Inputs!$F$14/1000/4)^(2/3))*SQRT(N10))
A11: P10 | B11: P09 | C11: 8.6 | E11: =SUMIFS(CB_Tributaires!$C:$C,CB_Tributaires!$B:$B,$A11) | F11: =IF(D11="",E11,D11) | I11: =IF(A11="","",Inputs!$B$13/((IF(H11="",Inputs!$B$18,H11)+Inputs!$B$14)^Inputs!$B$15)) | J11: =IF(A11="","",0.00278*IF(G11="",Inputs!$B$17,G11)*F11*I11) | K11: =IF(A11="","",SUMIFS($L$4:$L$203,$B$4:$B$203,$A11)) | L11: =IF(A11="","",(J11+K11)*Inputs!$B$16) | N11: =IF(A11="","",IF(M11="",Inputs!$B$7,M11)) | O11: =IF(A11="","",IF(L11/Inputs!$B$10<=AD11,Inputs!$F$5,IF(L11/Inputs!$B$10>AM11,"OVERSIZE",INDEX(Inputs!$F$5:$F$14,MATCH(L11/Inputs!$B$10,AD11:AM11,1)+1)))) | Q11: =IF(A11="","",IF(P11="",O11,P11)) | R11: =IF(OR(Q11="",Q11="OVERSIZE"),"",Q11/1000) | S11: =IF(R11="","",(1/Inputs!$B$9)*(PI()*R11^2/4)*((R11/4)^(2/3))*SQRT(N11)) | T11: =IF(OR(S11="",L11=""),"",L11/(S11*Inputs!$B$10)) | U11: =IF(OR(R11="",L11=""),"",4*L11/(PI()*R11^2)) | W11: =IF(A11="","",IF(A11=Inputs!$B$6,Inputs!$B$22,IF(B11="","",IFERROR(INDEX($X$4:$X$203,MATCH(B11,$A$4:$A$203,0))+IF(V11="",Inputs!$B$20,V11),"")))) | X11: =IF(OR(W11="",N11="",C11=""),"",W11+N11*C11) | AA11: =IF(OR(Y11="",W11=""),"",Y11-W11) | AB11: =IF(OR(Z11="",X11=""),"",Z11-X11) | AC11: =IF(A11="","",IF(OR(T11>1,U11<Inputs!$B$11,U11>Inputs!$B$12,AA11<Inputs!$B$19,AB11<Inputs!$B$19,N11<Inputs!$B$7,N11>Inputs!$B$8),"CHECK","OK")) | AD11: =IF(A11="","",(1/Inputs!$B$9)*(PI()*(Inputs!$F$5/1000)^2/4)*((Inputs!$F$5/1000/4)^(2/3))*SQRT(N11)) | AE11: =IF(A11="","",(1/Inputs!$B$9)*(PI()*(Inputs!$F$6/1000)^2/4)*((Inputs!$F$6/1000/4)^(2/3))*SQRT(N11)) | AF11: =IF(A11="","",(1/Inputs!$B$9)*(PI()*(Inputs!$F$7/1000)^2/4)*((Inputs!$F$7/1000/4)^(2/3))*SQRT(N11)) | AG11: =IF(A11="","",(1/Inputs!$B$9)*(PI()*(Inputs!$F$8/1000)^2/4)*((Inputs!$F$8/1000/4)^(2/3))*SQRT(N11)) | AH11: =IF(A11="","",(1/Inputs!$B$9)*(PI()*(Inputs!$F$9/1000)^2/4)*((Inputs!$F$9/1000/4)^(2/3))*SQRT(N11)) | AI11: =IF(A11="","",(1/Inputs!$B$9)*(PI()*(Inputs!$F$10/1000)^2/4)*((Inputs!$F$10/1000/4)^(2/3))*SQRT(N11)) | AJ11: =IF(A11="","",(1/Inputs!$B$9)*(PI()*(Inputs!$F$11/1000)^2/4)*((Inputs!$F$11/1000/4)^(2/3))*SQRT(N11)) | AK11: =IF(A11="","",(1/Inputs!$B$9)*(PI()*(Inputs!$F$12/1000)^2/4)*((Inputs!$F$12/1000/4)^(2/3))*SQRT(N11)) | AL11: =IF(A11="","",(1/Inputs!$B$9)*(PI()*(Inputs!$F$13/1000)^2/4)*((Inputs!$F$13/1000/4)^(2/3))*SQRT(N11)) | AM11: =IF(A11="","",(1/Inputs!$B$9)*(PI()*(Inputs!$F$14/1000)^2/4)*((Inputs!$F$14/1000/4)^(2/3))*SQRT(N11))
A12: P09 | B12: P_OUT | C12: 6.22 | E12: =SUMIFS(CB_Tributaires!$C:$C,CB_Tributaires!$B:$B,$A12) | F12: =IF(D12="",E12,D12) | I12: =IF(A12="","",Inputs!$B$13/((IF(H12="",Inputs!$B$18,H12)+Inputs!$B$14)^Inputs!$B$15)) | J12: =IF(A12="","",0.00278*IF(G12="",Inputs!$B$17,G12)*F12*I12) | K12: =IF(A12="","",SUMIFS($L$4:$L$203,$B$4:$B$203,$A12)) | L12: =IF(A12="","",(J12+K12)*Inputs!$B$16) | N12: =IF(A12="","",IF(M12="",Inputs!$B$7,M12)) | O12: =IF(A12="","",IF(L12/Inputs!$B$10<=AD12,Inputs!$F$5,IF(L12/Inputs!$B$10>AM12,"OVERSIZE",INDEX(Inputs!$F$5:$F$14,MATCH(L12/Inputs!$B$10,AD12:AM12,1)+1)))) | Q12: =IF(A12="","",IF(P12="",O12,P12)) | R12: =IF(OR(Q12="",Q12="OVERSIZE"),"",Q12/1000) | S12: =IF(R12="","",(1/Inputs!$B$9)*(PI()*R12^2/4)*((R12/4)^(2/3))*SQRT(N12)) | T12: =IF(OR(S12="",L12=""),"",L12/(S12*Inputs!$B$10)) | U12: =IF(OR(R12="",L12=""),"",4*L12/(PI()*R12^2)) | W12: =IF(A12="","",IF(A12=Inputs!$B$6,Inputs!$B$22,IF(B12="","",IFERROR(INDEX($X$4:$X$203,MATCH(B12,$A$4:$A$203,0))+IF(V12="",Inputs!$B$20,V12),"")))) | X12: =IF(OR(W12="",N12="",C12=""),"",W12+N12*C12) | AA12: =IF(OR(Y12="",W12=""),"",Y12-W12) | AB12: =IF(OR(Z12="",X12=""),"",Z12-X12) | AC12: =IF(A12="","",IF(OR(T12>1,U12<Inputs!$B$11,U12>Inputs!$B$12,AA12<Inputs!$B$19,AB12<Inputs!$B$19,N12<Inputs!$B$7,N12>Inputs!$B$8),"CHECK","OK")) | AD12: =IF(A12="","",(1/Inputs!$B$9)*(PI()*(Inputs!$F$5/1000)^2/4)*((Inputs!$F$5/1000/4)^(2/3))*SQRT(N12)) | AE12: =IF(A12="","",(1/Inputs!$B$9)*(PI()*(Inputs!$F$6/1000)^2/4)*((Inputs!$F$6/1000/4)^(2/3))*SQRT(N12)) | AF12: =IF(A12="","",(1/Inputs!$B$9)*(PI()*(Inputs!$F$7/1000)^2/4)*((Inputs!$F$7/1000/4)^(2/3))*SQRT(N12)) | AG12: =IF(A12="","",(1/Inputs!$B$9)*(PI()*(Inputs!$F$8/1000)^2/4)*((Inputs!$F$8/1000/4)^(2/3))*SQRT(N12)) | AH12: =IF(A12="","",(1/Inputs!$B$9)*(PI()*(Inputs!$F$9/1000)^2/4)*((Inputs!$F$9/1000/4)^(2/3))*SQRT(N12)) | AI12: =IF(A12="","",(1/Inputs!$B$9)*(PI()*(Inputs!$F$10/1000)^2/4)*((Inputs!$F$10/1000/4)^(2/3))*SQRT(N12)) | AJ12: =IF(A12="","",(1/Inputs!$B$9)*(PI()*(Inputs!$F$11/1000)^2/4)*((Inputs!$F$11/1000/4)^(2/3))*SQRT(N12)) | AK12: =IF(A12="","",(1/Inputs!$B$9)*(PI()*(Inputs!$F$12/1000)^2/4)*((Inputs!$F$12/1000/4)^(2/3))*SQRT(N12)) | AL12: =IF(A12="","",(1/Inputs!$B$9)*(PI()*(Inputs!$F$13/1000)^2/4)*((Inputs!$F$13/1000/4)^(2/3))*SQRT(N12)) | AM12: =IF(A12="","",(1/Inputs!$B$9)*(PI()*(Inputs!$F$14/1000)^2/4)*((Inputs!$F$14/1000/4)^(2/3))*SQRT(N12))
A13: P06 | B13: P_OUT | C13: 9.05 | E13: =SUMIFS(CB_Tributaires!$C:$C,CB_Tributaires!$B:$B,$A13) | F13: =IF(D13="",E13,D13) | I13: =IF(A13="","",Inputs!$B$13/((IF(H13="",Inputs!$B$18,H13)+Inputs!$B$14)^Inputs!$B$15)) | J13: =IF(A13="","",0.00278*IF(G13="",Inputs!$B$17,G13)*F13*I13) | K13: =IF(A13="","",SUMIFS($L$4:$L$203,$B$4:$B$203,$A13)) | L13: =IF(A13="","",(J13+K13)*Inputs!$B$16) | N13: =IF(A13="","",IF(M13="",Inputs!$B$7,M13)) | O13: =IF(A13="","",IF(L13/Inputs!$B$10<=AD13,Inputs!$F$5,IF(L13/Inputs!$B$10>AM13,"OVERSIZE",INDEX(Inputs!$F$5:$F$14,MATCH(L13/Inputs!$B$10,AD13:AM13,1)+1)))) | Q13: =IF(A13="","",IF(P13="",O13,P13)) | R13: =IF(OR(Q13="",Q13="OVERSIZE"),"",Q13/1000) | S13: =IF(R13="","",(1/Inputs!$B$9)*(PI()*R13^2/4)*((R13/4)^(2/3))*SQRT(N13)) | T13: =IF(OR(S13="",L13=""),"",L13/(S13*Inputs!$B$10)) | U13: =IF(OR(R13="",L13=""),"",4*L13/(PI()*R13^2)) | W13: =IF(A13="","",IF(A13=Inputs!$B$6,Inputs!$B$22,IF(B13="","",IFERROR(INDEX($X$4:$X$203,MATCH(B13,$A$4:$A$203,0))+IF(V13="",Inputs!$B$20,V13),"")))) | X13: =IF(OR(W13="",N13="",C13=""),"",W13+N13*C13) | AA13: =IF(OR(Y13="",W13=""),"",Y13-W13) | AB13: =IF(OR(Z13="",X13=""),"",Z13-X13) | AC13: =IF(A13="","",IF(OR(T13>1,U13<Inputs!$B$11,U13>Inputs!$B$12,AA13<Inputs!$B$19,AB13<Inputs!$B$19,N13<Inputs!$B$7,N13>Inputs!$B$8),"CHECK","OK")) | AD13: =IF(A13="","",(1/Inputs!$B$9)*(PI()*(Inputs!$F$5/1000)^2/4)*((Inputs!$F$5/1000/4)^(2/3))*SQRT(N13)) | AE13: =IF(A13="","",(1/Inputs!$B$9)*(PI()*(Inputs!$F$6/1000)^2/4)*((Inputs!$F$6/1000/4)^(2/3))*SQRT(N13)) | AF13: =IF(A13="","",(1/Inputs!$B$9)*(PI()*(Inputs!$F$7/1000)^2/4)*((Inputs!$F$7/1000/4)^(2/3))*SQRT(N13)) | AG13: =IF(A13="","",(1/Inputs!$B$9)*(PI()*(Inputs!$F$8/1000)^2/4)*((Inputs!$F$8/1000/4)^(2/3))*SQRT(N13)) | AH13: =IF(A13="","",(1/Inputs!$B$9)*(PI()*(Inputs!$F$9/1000)^2/4)*((Inputs!$F$9/1000/4)^(2/3))*SQRT(N13)) | AI13: =IF(A13="","",(1/Inputs!$B$9)*(PI()*(Inputs!$F$10/1000)^2/4)*((Inputs!$F$10/1000/4)^(2/3))*SQRT(N13)) | AJ13: =IF(A13="","",(1/Inputs!$B$9)*(PI()*(Inputs!$F$11/1000)^2/4)*((Inputs!$F$11/1000/4)^(2/3))*SQRT(N13)) | AK13: =IF(A13="","",(1/Inputs!$B$9)*(PI()*(Inputs!$F$12/1000)^2/4)*((Inputs!$F$12/1000/4)^(2/3))*SQRT(N13)) | AL13: =IF(A13="","",(1/Inputs!$B$9)*(PI()*(Inputs!$F$13/1000)^2/4)*((Inputs!$F$13/1000/4)^(2/3))*SQRT(N13)) | AM13: =IF(A13="","",(1/Inputs!$B$9)*(PI()*(Inputs!$F$14/1000)^2/4)*((Inputs!$F$14/1000/4)^(2/3))*SQRT(N13))
A14: P_OUT | C14: 4.5 | E14: =SUMIFS(CB_Tributaires!$C:$C,CB_Tributaires!$B:$B,$A14) | F14: =IF(D14="",E14,D14) | I14: =IF(A14="","",Inputs!$B$13/((IF(H14="",Inputs!$B$18,H14)+Inputs!$B$14)^Inputs!$B$15)) | J14: =IF(A14="","",0.00278*IF(G14="",Inputs!$B$17,G14)*F14*I14) | K14: =IF(A14="","",SUMIFS($L$4:$L$203,$B$4:$B$203,$A14)) | L14: =IF(A14="","",(J14+K14)*Inputs!$B$16) | N14: =IF(A14="","",IF(M14="",Inputs!$B$7,M14)) | O14: =IF(A14="","",IF(L14/Inputs!$B$10<=AD14,Inputs!$F$5,IF(L14/Inputs!$B$10>AM14,"OVERSIZE",INDEX(Inputs!$F$5:$F$14,MATCH(L14/Inputs!$B$10,AD14:AM14,1)+1)))) | Q14: =IF(A14="","",IF(P14="",O14,P14)) | R14: =IF(OR(Q14="",Q14="OVERSIZE"),"",Q14/1000) | S14: =IF(R14="","",(1/Inputs!$B$9)*(PI()*R14^2/4)*((R14/4)^(2/3))*SQRT(N14)) | T14: =IF(OR(S14="",L14=""),"",L14/(S14*Inputs!$B$10)) | U14: =IF(OR(R14="",L14=""),"",4*L14/(PI()*R14^2)) | W14: =IF(A14="","",IF(A14=Inputs!$B$6,Inputs!$B$22,IF(B14="","",IFERROR(INDEX($X$4:$X$203,MATCH(B14,$A$4:$A$203,0))+IF(V14="",Inputs!$B$20,V14),"")))) | X14: =IF(OR(W14="",N14="",C14=""),"",W14+N14*C14) | AA14: =IF(OR(Y14="",W14=""),"",Y14-W14) | AB14: =IF(OR(Z14="",X14=""),"",Z14-X14) | AC14: =IF(A14="","",IF(OR(T14>1,U14<Inputs!$B$11,U14>Inputs!$B$12,AA14<Inputs!$B$19,AB14<Inputs!$B$19,N14<Inputs!$B$7,N14>Inputs!$B$8),"CHECK","OK")) | AD14: =IF(A14="","",(1/Inputs!$B$9)*(PI()*(Inputs!$F$5/1000)^2/4)*((Inputs!$F$5/1000/4)^(2/3))*SQRT(N14)) | AE14: =IF(A14="","",(1/Inputs!$B$9)*(PI()*(Inputs!$F$6/1000)^2/4)*((Inputs!$F$6/1000/4)^(2/3))*SQRT(N14)) | AF14: =IF(A14="","",(1/Inputs!$B$9)*(PI()*(Inputs!$F$7/1000)^2/4)*((Inputs!$F$7/1000/4)^(2/3))*SQRT(N14)) | AG14: =IF(A14="","",(1/Inputs!$B$9)*(PI()*(Inputs!$F$8/1000)^2/4)*((Inputs!$F$8/1000/4)^(2/3))*SQRT(N14)) | AH14: =IF(A14="","",(1/Inputs!$B$9)*(PI()*(Inputs!$F$9/1000)^2/4)*((Inputs!$F$9/1000/4)^(2/3))*SQRT(N14)) | AI14: =IF(A14="","",(1/Inputs!$B$9)*(PI()*(Inputs!$F$10/1000)^2/4)*((Inputs!$F$10/1000/4)^(2/3))*SQRT(N14)) | AJ14: =IF(A14="","",(1/Inputs!$B$9)*(PI()*(Inputs!$F$11/1000)^2/4)*((Inputs!$F$11/1000/4)^(2/3))*SQRT(N14)) | AK14: =IF(A14="","",(1/Inputs!$B$9)*(PI()*(Inputs!$F$12/1000)^2/4)*((Inputs!$F$12/1000/4)^(2/3))*SQRT(N14)) | AL14: =IF(A14="","",(1/Inputs!$B$9)*(PI()*(Inputs!$F$13/1000)^2/4)*((Inputs!$F$13/1000/4)^(2/3))*SQRT(N14)) | AM14: =IF(A14="","",(1/Inputs!$B$9)*(PI()*(Inputs!$F$14/1000)^2/4)*((Inputs!$F$14/1000/4)^(2/3))*SQRT(N14))
E15: =SUMIFS(CB_Tributaires!$C:$C,CB_Tributaires!$B:$B,$A15) | F15: =IF(D15="",E15,D15) | I15: =IF(A15="","",Inputs!$B$13/((IF(H15="",Inputs!$B$18,H15)+Inputs!$B$14)^Inputs!$B$15)) | J15: =IF(A15="","",0.00278*IF(G15="",Inputs!$B$17,G15)*F15*I15) | K15: =IF(A15="","",SUMIFS($L$4:$L$203,$B$4:$B$203,$A15)) | L15: =IF(A15="","",(J15+K15)*Inputs!$B$16) | N15: =IF(A15="","",IF(M15="",Inputs!$B$7,M15)) | O15: =IF(A15="","",IF(L15/Inputs!$B$10<=AD15,Inputs!$F$5,IF(L15/Inputs!$B$10>AM15,"OVERSIZE",INDEX(Inputs!$F$5:$F$14,MATCH(L15/Inputs!$B$10,AD15:AM15,1)+1)))) | Q15: =IF(A15="","",IF(P15="",O15,P15)) | R15: =IF(OR(Q15="",Q15="OVERSIZE"),"",Q15/1000) | S15: =IF(R15="","",(1/Inputs!$B$9)*(PI()*R15^2/4)*((R15/4)^(2/3))*SQRT(N15)) | T15: =IF(OR(S15="",L15=""),"",L15/(S15*Inputs!$B$10)) | U15: =IF(OR(R15="",L15=""),"",4*L15/(PI()*R15^2)) | W15: =IF(A15="","",IF(A15=Inputs!$B$6,Inputs!$B$22,IF(B15="","",IFERROR(INDEX($X$4:$X$203,MATCH(B15,$A$4:$A$203,0))+IF(V15="",Inputs!$B$20,V15),"")))) | X15: =IF(OR(W15="",N15="",C15=""),"",W15+N15*C15) | AA15: =IF(OR(Y15="",W15=""),"",Y15-W15) | AB15: =IF(OR(Z15="",X15=""),"",Z15-X15) | AC15: =IF(A15="","",IF(OR(T15>1,U15<Inputs!$B$11,U15>Inputs!$B$12,AA15<Inputs!$B$19,AB15<Inputs!$B$19,N15<Inputs!$B$7,N15>Inputs!$B$8),"CHECK","OK")) | AD15: =IF(A15="","",(1/Inputs!$B$9)*(PI()*(Inputs!$F$5/1000)^2/4)*((Inputs!$F$5/1000/4)^(2/3))*SQRT(N15)) | AE15: =IF(A15="","",(1/Inputs!$B$9)*(PI()*(Inputs!$F$6/1000)^2/4)*((Inputs!$F$6/1000/4)^(2/3))*SQRT(N15)) | AF15: =IF(A15="","",(1/Inputs!$B$9)*(PI()*(Inputs!$F$7/1000)^2/4)*((Inputs!$F$7/1000/4)^(2/3))*SQRT(N15)) | AG15: =IF(A15="","",(1/Inputs!$B$9)*(PI()*(Inputs!$F$8/1000)^2/4)*((Inputs!$F$8/1000/4)^(2/3))*SQRT(N15)) | AH15: =IF(A15="","",(1/Inputs!$B$9)*(PI()*(Inputs!$F$9/1000)^2/4)*((Inputs!$F$9/1000/4)^(2/3))*SQRT(N15)) | AI15: =IF(A15="","",(1/Inputs!$B$9)*(PI()*(Inputs!$F$10/1000)^2/4)*((Inputs!$F$10/1000/4)^(2/3))*SQRT(N15)) | AJ15: =IF(A15="","",(1/Inputs!$B$9)*(PI()*(Inputs!$F$11/1000)^2/4)*((Inputs!$F$11/1000/4)^(2/3))*SQRT(N15)) | AK15: =IF(A15="","",(1/Inputs!$B$9)*(PI()*(Inputs!$F$12/1000)^2/4)*((Inputs!$F$12/1000/4)^(2/3))*SQRT(N15)) | AL15: =IF(A15="","",(1/Inputs!$B$9)*(PI()*(Inputs!$F$13/1000)^2/4)*((Inputs!$F$13/1000/4)^(2/3))*SQRT(N15)) | AM15: =IF(A15="","",(1/Inputs!$B$9)*(PI()*(Inputs!$F$14/1000)^2/4)*((Inputs!$F$14/1000/4)^(2/3))*SQRT(N15))
E16: =SUMIFS(CB_Tributaires!$C:$C,CB_Tributaires!$B:$B,$A16) | F16: =IF(D16="",E16,D16) | I16: =IF(A16="","",Inputs!$B$13/((IF(H16="",Inputs!$B$18,H16)+Inputs!$B$14)^Inputs!$B$15)) | J16: =IF(A16="","",0.00278*IF(G16="",Inputs!$B$17,G16)*F16*I16) | K16: =IF(A16="","",SUMIFS($L$4:$L$203,$B$4:$B$203,$A16)) | L16: =IF(A16="","",(J16+K16)*Inputs!$B$16) | N16: =IF(A16="","",IF(M16="",Inputs!$B$7,M16)) | O16: =IF(A16="","",IF(L16/Inputs!$B$10<=AD16,Inputs!$F$5,IF(L16/Inputs!$B$10>AM16,"OVERSIZE",INDEX(Inputs!$F$5:$F$14,MATCH(L16/Inputs!$B$10,AD16:AM16,1)+1)))) | Q16: =IF(A16="","",IF(P16="",O16,P16)) | R16: =IF(OR(Q16="",Q16="OVERSIZE"),"",Q16/1000) | S16: =IF(R16="","",(1/Inputs!$B$9)*(PI()*R16^2/4)*((R16/4)^(2/3))*SQRT(N16)) | T16: =IF(OR(S16="",L16=""),"",L16/(S16*Inputs!$B$10)) | U16: =IF(OR(R16="",L16=""),"",4*L16/(PI()*R16^2)) | W16: =IF(A16="","",IF(A16=Inputs!$B$6,Inputs!$B$22,IF(B16="","",IFERROR(INDEX($X$4:$X$203,MATCH(B16,$A$4:$A$203,0))+IF(V16="",Inputs!$B$20,V16),"")))) | X16: =IF(OR(W16="",N16="",C16=""),"",W16+N16*C16) | AA16: =IF(OR(Y16="",W16=""),"",Y16-W16) | AB16: =IF(OR(Z16="",X16=""),"",Z16-X16) | AC16: =IF(A16="","",IF(OR(T16>1,U16<Inputs!$B$11,U16>Inputs!$B$12,AA16<Inputs!$B$19,AB16<Inputs!$B$19,N16<Inputs!$B$7,N16>Inputs!$B$8),"CHECK","OK")) | AD16: =IF(A16="","",(1/Inputs!$B$9)*(PI()*(Inputs!$F$5/1000)^2/4)*((Inputs!$F$5/1000/4)^(2/3))*SQRT(N16)) | AE16: =IF(A16="","",(1/Inputs!$B$9)*(PI()*(Inputs!$F$6/1000)^2/4)*((Inputs!$F$6/1000/4)^(2/3))*SQRT(N16)) | AF16: =IF(A16="","",(1/Inputs!$B$9)*(PI()*(Inputs!$F$7/1000)^2/4)*((Inputs!$F$7/1000/4)^(2/3))*SQRT(N16)) | AG16: =IF(A16="","",(1/Inputs!$B$9)*(PI()*(Inputs!$F$8/1000)^2/4)*((Inputs!$F$8/1000/4)^(2/3))*SQRT(N16)) | AH16: =IF(A16="","",(1/Inputs!$B$9)*(PI()*(Inputs!$F$9/1000)^2/4)*((Inputs!$F$9/1000/4)^(2/3))*SQRT(N16)) | AI16: =IF(A16="","",(1/Inputs!$B$9)*(PI()*(Inputs!$F$10/1000)^2/4)*((Inputs!$F$10/1000/4)^(2/3))*SQRT(N16)) | AJ16: =IF(A16="","",(1/Inputs!$B$9)*(PI()*(Inputs!$F$11/1000)^2/4)*((Inputs!$F$11/1000/4)^(2/3))*SQRT(N16)) | AK16: =IF(A16="","",(1/Inputs!$B$9)*(PI()*(Inputs!$F$12/1000)^2/4)*((Inputs!$F$12/1000/4)^(2/3))*SQRT(N16)) | AL16: =IF(A16="","",(1/Inputs!$B$9)*(PI()*(Inputs!$F$13/1000)^2/4)*((Inputs!$F$13/1000/4)^(2/3))*SQRT(N16)) | AM16: =IF(A16="","",(1/Inputs!$B$9)*(PI()*(Inputs!$F$14/1000)^2/4)*((Inputs!$F$14/1000/4)^(2/3))*SQRT(N16))
E17: =SUMIFS(CB_Tributaires!$C:$C,CB_Tributaires!$B:$B,$A17) | F17: =IF(D17="",E17,D17) | I17: =IF(A17="","",Inputs!$B$13/((IF(H17="",Inputs!$B$18,H17)+Inputs!$B$14)^Inputs!$B$15)) | J17: =IF(A17="","",0.00278*IF(G17="",Inputs!$B$17,G17)*F17*I17) | K17: =IF(A17="","",SUMIFS($L$4:$L$203,$B$4:$B$203,$A17)) | L17: =IF(A17="","",(J17+K17)*Inputs!$B$16) | N17: =IF(A17="","",IF(M17="",Inputs!$B$7,M17)) | O17: =IF(A17="","",IF(L17/Inputs!$B$10<=AD17,Inputs!$F$5,IF(L17/Inputs!$B$10>AM17,"OVERSIZE",INDEX(Inputs!$F$5:$F$14,MATCH(L17/Inputs!$B$10,AD17:AM17,1)+1)))) | Q17: =IF(A17="","",IF(P17="",O17,P17)) | R17: =IF(OR(Q17="",Q17="OVERSIZE"),"",Q17/1000) | S17: =IF(R17="","",(1/Inputs!$B$9)*(PI()*R17^2/4)*((R17/4)^(2/3))*SQRT(N17)) | T17: =IF(OR(S17="",L17=""),"",L17/(S17*Inputs!$B$10)) | U17: =IF(OR(R17="",L17=""),"",4*L17/(PI()*R17^2)) | W17: =IF(A17="","",IF(A17=Inputs!$B$6,Inputs!$B$22,IF(B17="","",IFERROR(INDEX($X$4:$X$203,MATCH(B17,$A$4:$A$203,0))+IF(V17="",Inputs!$B$20,V17),"")))) | X17: =IF(OR(W17="",N17="",C17=""),"",W17+N17*C17) | AA17: =IF(OR(Y17="",W17=""),"",Y17-W17) | AB17: =IF(OR(Z17="",X17=""),"",Z17-X17) | AC17: =IF(A17="","",IF(OR(T17>1,U17<Inputs!$B$11,U17>Inputs!$B$12,AA17<Inputs!$B$19,AB17<Inputs!$B$19,N17<Inputs!$B$7,N17>Inputs!$B$8),"CHECK","OK")) | AD17: =IF(A17="","",(1/Inputs!$B$9)*(PI()*(Inputs!$F$5/1000)^2/4)*((Inputs!$F$5/1000/4)^(2/3))*SQRT(N17)) | AE17: =IF(A17="","",(1/Inputs!$B$9)*(PI()*(Inputs!$F$6/1000)^2/4)*((Inputs!$F$6/1000/4)^(2/3))*SQRT(N17)) | AF17: =IF(A17="","",(1/Inputs!$B$9)*(PI()*(Inputs!$F$7/1000)^2/4)*((Inputs!$F$7/1000/4)^(2/3))*SQRT(N17)) | AG17: =IF(A17="","",(1/Inputs!$B$9)*(PI()*(Inputs!$F$8/1000)^2/4)*((Inputs!$F$8/1000/4)^(2/3))*SQRT(N17)) | AH17: =IF(A17="","",(1/Inputs!$B$9)*(PI()*(Inputs!$F$9/1000)^2/4)*((Inputs!$F$9/1000/4)^(2/3))*SQRT(N17)) | AI17: =IF(A17="","",(1/Inputs!$B$9)*(PI()*(Inputs!$F$10/1000)^2/4)*((Inputs!$F$10/1000/4)^(2/3))*SQRT(N17)) | AJ17: =IF(A17="","",(1/Inputs!$B$9)*(PI()*(Inputs!$F$11/1000)^2/4)*((Inputs!$F$11/1000/4)^(2/3))*SQRT(N17)) | AK17: =IF(A17="","",(1/Inputs!$B$9)*(PI()*(Inputs!$F$12/1000)^2/4)*((Inputs!$F$12/1000/4)^(2/3))*SQRT(N17)) | AL17: =IF(A17="","",(1/Inputs!$B$9)*(PI()*(Inputs!$F$13/1000)^2/4)*((Inputs!$F$13/1000/4)^(2/3))*SQRT(N17)) | AM17: =IF(A17="","",(1/Inputs!$B$9)*(PI()*(Inputs!$F$14/1000)^2/4)*((Inputs!$F$14/1000/4)^(2/3))*SQRT(N17))
E18: =SUMIFS(CB_Tributaires!$C:$C,CB_Tributaires!$B:$B,$A18) | F18: =IF(D18="",E18,D18) | I18: =IF(A18="","",Inputs!$B$13/((IF(H18="",Inputs!$B$18,H18)+Inputs!$B$14)^Inputs!$B$15)) | J18: =IF(A18="","",0.00278*IF(G18="",Inputs!$B$17,G18)*F18*I18) | K18: =IF(A18="","",SUMIFS($L$4:$L$203,$B$4:$B$203,$A18)) | L18: =IF(A18="","",(J18+K18)*Inputs!$B$16) | N18: =IF(A18="","",IF(M18="",Inputs!$B$7,M18)) | O18: =IF(A18="","",IF(L18/Inputs!$B$10<=AD18,Inputs!$F$5,IF(L18/Inputs!$B$10>AM18,"OVERSIZE",INDEX(Inputs!$F$5:$F$14,MATCH(L18/Inputs!$B$10,AD18:AM18,1)+1)))) | Q18: =IF(A18="","",IF(P18="",O18,P18)) | R18: =IF(OR(Q18="",Q18="OVERSIZE"),"",Q18/1000) | S18: =IF(R18="","",(1/Inputs!$B$9)*(PI()*R18^2/4)*((R18/4)^(2/3))*SQRT(N18)) | T18: =IF(OR(S18="",L18=""),"",L18/(S18*Inputs!$B$10)) | U18: =IF(OR(R18="",L18=""),"",4*L18/(PI()*R18^2)) | W18: =IF(A18="","",IF(A18=Inputs!$B$6,Inputs!$B$22,IF(B18="","",IFERROR(INDEX($X$4:$X$203,MATCH(B18,$A$4:$A$203,0))+IF(V18="",Inputs!$B$20,V18),"")))) | X18: =IF(OR(W18="",N18="",C18=""),"",W18+N18*C18) | AA18: =IF(OR(Y18="",W18=""),"",Y18-W18) | AB18: =IF(OR(Z18="",X18=""),"",Z18-X18) | AC18: =IF(A18="","",IF(OR(T18>1,U18<Inputs!$B$11,U18>Inputs!$B$12,AA18<Inputs!$B$19,AB18<Inputs!$B$19,N18<Inputs!$B$7,N18>Inputs!$B$8),"CHECK","OK")) | AD18: =IF(A18="","",(1/Inputs!$B$9)*(PI()*(Inputs!$F$5/1000)^2/4)*((Inputs!$F$5/1000/4)^(2/3))*SQRT(N18)) | AE18: =IF(A18="","",(1/Inputs!$B$9)*(PI()*(Inputs!$F$6/1000)^2/4)*((Inputs!$F$6/1000/4)^(2/3))*SQRT(N18)) | AF18: =IF(A18="","",(1/Inputs!$B$9)*(PI()*(Inputs!$F$7/1000)^2/4)*((Inputs!$F$7/1000/4)^(2/3))*SQRT(N18)) | AG18: =IF(A18="","",(1/Inputs!$B$9)*(PI()*(Inputs!$F$8/1000)^2/4)*((Inputs!$F$8/1000/4)^(2/3))*SQRT(N18)) | AH18: =IF(A18="","",(1/Inputs!$B$9)*(PI()*(Inputs!$F$9/1000)^2/4)*((Inputs!$F$9/1000/4)^(2/3))*SQRT(N18)) | AI18: =IF(A18="","",(1/Inputs!$B$9)*(PI()*(Inputs!$F$10/1000)^2/4)*((Inputs!$F$10/1000/4)^(2/3))*SQRT(N18)) | AJ18: =IF(A18="","",(1/Inputs!$B$9)*(PI()*(Inputs!$F$11/1000)^2/4)*((Inputs!$F$11/1000/4)^(2/3))*SQRT(N18)) | AK18: =IF(A18="","",(1/Inputs!$B$9)*(PI()*(Inputs!$F$12/1000)^2/4)*((Inputs!$F$12/1000/4)^(2/3))*SQRT(N18)) | AL18: =IF(A18="","",(1/Inputs!$B$9)*(PI()*(Inputs!$F$13/1000)^2/4)*((Inputs!$F$13/1000/4)^(2/3))*SQRT(N18)) | AM18: =IF(A18="","",(1/Inputs!$B$9)*(PI()*(Inputs!$F$14/1000)^2/4)*((Inputs!$F$14/1000/4)^(2/3))*SQRT(N18))
E19: =SUMIFS(CB_Tributaires!$C:$C,CB_Tributaires!$B:$B,$A19) | F19: =IF(D19="",E19,D19) | I19: =IF(A19="","",Inputs!$B$13/((IF(H19="",Inputs!$B$18,H19)+Inputs!$B$14)^Inputs!$B$15)) | J19: =IF(A19="","",0.00278*IF(G19="",Inputs!$B$17,G19)*F19*I19) | K19: =IF(A19="","",SUMIFS($L$4:$L$203,$B$4:$B$203,$A19)) | L19: =IF(A19="","",(J19+K19)*Inputs!$B$16) | N19: =IF(A19="","",IF(M19="",Inputs!$B$7,M19)) | O19: =IF(A19="","",IF(L19/Inputs!$B$10<=AD19,Inputs!$F$5,IF(L19/Inputs!$B$10>AM19,"OVERSIZE",INDEX(Inputs!$F$5:$F$14,MATCH(L19/Inputs!$B$10,AD19:AM19,1)+1)))) | Q19: =IF(A19="","",IF(P19="",O19,P19)) | R19: =IF(OR(Q19="",Q19="OVERSIZE"),"",Q19/1000) | S19: =IF(R19="","",(1/Inputs!$B$9)*(PI()*R19^2/4)*((R19/4)^(2/3))*SQRT(N19)) | T19: =IF(OR(S19="",L19=""),"",L19/(S19*Inputs!$B$10)) | U19: =IF(OR(R19="",L19=""),"",4*L19/(PI()*R19^2)) | W19: =IF(A19="","",IF(A19=Inputs!$B$6,Inputs!$B$22,IF(B19="","",IFERROR(INDEX($X$4:$X$203,MATCH(B19,$A$4:$A$203,0))+IF(V19="",Inputs!$B$20,V19),"")))) | X19: =IF(OR(W19="",N19="",C19=""),"",W19+N19*C19) | AA19: =IF(OR(Y19="",W19=""),"",Y19-W19) | AB19: =IF(OR(Z19="",X19=""),"",Z19-X19) | AC19: =IF(A19="","",IF(OR(T19>1,U19<Inputs!$B$11,U19>Inputs!$B$12,AA19<Inputs!$B$19,AB19<Inputs!$B$19,N19<Inputs!$B$7,N19>Inputs!$B$8),"CHECK","OK")) | AD19: =IF(A19="","",(1/Inputs!$B$9)*(PI()*(Inputs!$F$5/1000)^2/4)*((Inputs!$F$5/1000/4)^(2/3))*SQRT(N19)) | AE19: =IF(A19="","",(1/Inputs!$B$9)*(PI()*(Inputs!$F$6/1000)^2/4)*((Inputs!$F$6/1000/4)^(2/3))*SQRT(N19)) | AF19: =IF(A19="","",(1/Inputs!$B$9)*(PI()*(Inputs!$F$7/1000)^2/4)*((Inputs!$F$7/1000/4)^(2/3))*SQRT(N19)) | AG19: =IF(A19="","",(1/Inputs!$B$9)*(PI()*(Inputs!$F$8/1000)^2/4)*((Inputs!$F$8/1000/4)^(2/3))*SQRT(N19)) | AH19: =IF(A19="","",(1/Inputs!$B$9)*(PI()*(Inputs!$F$9/1000)^2/4)*((Inputs!$F$9/1000/4)^(2/3))*SQRT(N19)) | AI19: =IF(A19="","",(1/Inputs!$B$9)*(PI()*(Inputs!$F$10/1000)^2/4)*((Inputs!$F$10/1000/4)^(2/3))*SQRT(N19)) | AJ19: =IF(A19="","",(1/Inputs!$B$9)*(PI()*(Inputs!$F$11/1000)^2/4)*((Inputs!$F$11/1000/4)^(2/3))*SQRT(N19)) | AK19: =IF(A19="","",(1/Inputs!$B$9)*(PI()*(Inputs!$F$12/1000)^2/4)*((Inputs!$F$12/1000/4)^(2/3))*SQRT(N19)) | AL19: =IF(A19="","",(1/Inputs!$B$9)*(PI()*(Inputs!$F$13/1000)^2/4)*((Inputs!$F$13/1000/4)^(2/3))*SQRT(N19)) | AM19: =IF(A19="","",(1/Inputs!$B$9)*(PI()*(Inputs!$F$14/1000)^2/4)*((Inputs!$F$14/1000/4)^(2/3))*SQRT(N19))
E20: =SUMIFS(CB_Tributaires!$C:$C,CB_Tributaires!$B:$B,$A20) | F20: =IF(D20="",E20,D20) | I20: =IF(A20="","",Inputs!$B$13/((IF(H20="",Inputs!$B$18,H20)+Inputs!$B$14)^Inputs!$B$15)) | J20: =IF(A20="","",0.00278*IF(G20="",Inputs!$B$17,G20)*F20*I20) | K20: =IF(A20="","",SUMIFS($L$4:$L$203,$B$4:$B$203,$A20)) | L20: =IF(A20="","",(J20+K20)*Inputs!$B$16) | N20: =IF(A20="","",IF(M20="",Inputs!$B$7,M20)) | O20: =IF(A20="","",IF(L20/Inputs!$B$10<=AD20,Inputs!$F$5,IF(L20/Inputs!$B$10>AM20,"OVERSIZE",INDEX(Inputs!$F$5:$F$14,MATCH(L20/Inputs!$B$10,AD20:AM20,1)+1)))) | Q20: =IF(A20="","",IF(P20="",O20,P20)) | R20: =IF(OR(Q20="",Q20="OVERSIZE"),"",Q20/1000) | S20: =IF(R20="","",(1/Inputs!$B$9)*(PI()*R20^2/4)*((R20/4)^(2/3))*SQRT(N20)) | T20: =IF(OR(S20="",L20=""),"",L20/(S20*Inputs!$B$10)) | U20: =IF(OR(R20="",L20=""),"",4*L20/(PI()*R20^2)) | W20: =IF(A20="","",IF(A20=Inputs!$B$6,Inputs!$B$22,IF(B20="","",IFERROR(INDEX($X$4:$X$203,MATCH(B20,$A$4:$A$203,0))+IF(V20="",Inputs!$B$20,V20),"")))) | X20: =IF(OR(W20="",N20="",C20=""),"",W20+N20*C20) | AA20: =IF(OR(Y20="",W20=""),"",Y20-W20) | AB20: =IF(OR(Z20="",X20=""),"",Z20-X20) | AC20: =IF(A20="","",IF(OR(T20>1,U20<Inputs!$B$11,U20>Inputs!$B$12,AA20<Inputs!$B$19,AB20<Inputs!$B$19,N20<Inputs!$B$7,N20>Inputs!$B$8),"CHECK","OK")) | AD20: =IF(A20="","",(1/Inputs!$B$9)*(PI()*(Inputs!$F$5/1000)^2/4)*((Inputs!$F$5/1000/4)^(2/3))*SQRT(N20)) | AE20: =IF(A20="","",(1/Inputs!$B$9)*(PI()*(Inputs!$F$6/1000)^2/4)*((Inputs!$F$6/1000/4)^(2/3))*SQRT(N20)) | AF20: =IF(A20="","",(1/Inputs!$B$9)*(PI()*(Inputs!$F$7/1000)^2/4)*((Inputs!$F$7/1000/4)^(2/3))*SQRT(N20)) | AG20: =IF(A20="","",(1/Inputs!$B$9)*(PI()*(Inputs!$F$8/1000)^2/4)*((Inputs!$F$8/1000/4)^(2/3))*SQRT(N20)) | AH20: =IF(A20="","",(1/Inputs!$B$9)*(PI()*(Inputs!$F$9/1000)^2/4)*((Inputs!$F$9/1000/4)^(2/3))*SQRT(N20)) | AI20: =IF(A20="","",(1/Inputs!$B$9)*(PI()*(Inputs!$F$10/1000)^2/4)*((Inputs!$F$10/1000/4)^(2/3))*SQRT(N20)) | AJ20: =IF(A20="","",(1/Inputs!$B$9)*(PI()*(Inputs!$F$11/1000)^2/4)*((Inputs!$F$11/1000/4)^(2/3))*SQRT(N20)) | AK20: =IF(A20="","",(1/Inputs!$B$9)*(PI()*(Inputs!$F$12/1000)^2/4)*((Inputs!$F$12/1000/4)^(2/3))*SQRT(N20)) | AL20: =IF(A20="","",(1/Inputs!$B$9)*(PI()*(Inputs!$F$13/1000)^2/4)*((Inputs!$F$13/1000/4)^(2/3))*SQRT(N20)) | AM20: =IF(A20="","",(1/Inputs!$B$9)*(PI()*(Inputs!$F$14/1000)^2/4)*((Inputs!$F$14/1000/4)^(2/3))*SQRT(N20))
E21: =SUMIFS(CB_Tributaires!$C:$C,CB_Tributaires!$B:$B,$A21) | F21: =IF(D21="",E21,D21) | I21: =IF(A21="","",Inputs!$B$13/((IF(H21="",Inputs!$B$18,H21)+Inputs!$B$14)^Inputs!$B$15)) | J21: =IF(A21="","",0.00278*IF(G21="",Inputs!$B$17,G21)*F21*I21) | K21: =IF(A21="","",SUMIFS($L$4:$L$203,$B$4:$B$203,$A21)) | L21: =IF(A21="","",(J21+K21)*Inputs!$B$16) | N21: =IF(A21="","",IF(M21="",Inputs!$B$7,M21)) | O21: =IF(A21="","",IF(L21/Inputs!$B$10<=AD21,Inputs!$F$5,IF(L21/Inputs!$B$10>AM21,"OVERSIZE",INDEX(Inputs!$F$5:$F$14,MATCH(L21/Inputs!$B$10,AD21:AM21,1)+1)))) | Q21: =IF(A21="","",IF(P21="",O21,P21)) | R21: =IF(OR(Q21="",Q21="OVERSIZE"),"",Q21/1000) | S21: =IF(R21="","",(1/Inputs!$B$9)*(PI()*R21^2/4)*((R21/4)^(2/3))*SQRT(N21)) | T21: =IF(OR(S21="",L21=""),"",L21/(S21*Inputs!$B$10)) | U21: =IF(OR(R21="",L21=""),"",4*L21/(PI()*R21^2)) | W21: =IF(A21="","",IF(A21=Inputs!$B$6,Inputs!$B$22,IF(B21="","",IFERROR(INDEX($X$4:$X$203,MATCH(B21,$A$4:$A$203,0))+IF(V21="",Inputs!$B$20,V21),"")))) | X21: =IF(OR(W21="",N21="",C21=""),"",W21+N21*C21) | AA21: =IF(OR(Y21="",W21=""),"",Y21-W21) | AB21: =IF(OR(Z21="",X21=""),"",Z21-X21) | AC21: =IF(A21="","",IF(OR(T21>1,U21<Inputs!$B$11,U21>Inputs!$B$12,AA21<Inputs!$B$19,AB21<Inputs!$B$19,N21<Inputs!$B$7,N21>Inputs!$B$8),"CHECK","OK")) | AD21: =IF(A21="","",(1/Inputs!$B$9)*(PI()*(Inputs!$F$5/1000)^2/4)*((Inputs!$F$5/1000/4)^(2/3))*SQRT(N21)) | AE21: =IF(A21="","",(1/Inputs!$B$9)*(PI()*(Inputs!$F$6/1000)^2/4)*((Inputs!$F$6/1000/4)^(2/3))*SQRT(N21)) | AF21: =IF(A21="","",(1/Inputs!$B$9)*(PI()*(Inputs!$F$7/1000)^2/4)*((Inputs!$F$7/1000/4)^(2/3))*SQRT(N21)) | AG21: =IF(A21="","",(1/Inputs!$B$9)*(PI()*(Inputs!$F$8/1000)^2/4)*((Inputs!$F$8/1000/4)^(2/3))*SQRT(N21)) | AH21: =IF(A21="","",(1/Inputs!$B$9)*(PI()*(Inputs!$F$9/1000)^2/4)*((Inputs!$F$9/1000/4)^(2/3))*SQRT(N21)) | AI21: =IF(A21="","",(1/Inputs!$B$9)*(PI()*(Inputs!$F$10/1000)^2/4)*((Inputs!$F$10/1000/4)^(2/3))*SQRT(N21)) | AJ21: =IF(A21="","",(1/Inputs!$B$9)*(PI()*(Inputs!$F$11/1000)^2/4)*((Inputs!$F$11/1000/4)^(2/3))*SQRT(N21)) | AK21: =IF(A21="","",(1/Inputs!$B$9)*(PI()*(Inputs!$F$12/1000)^2/4)*((Inputs!$F$12/1000/4)^(2/3))*SQRT(N21)) | AL21: =IF(A21="","",(1/Inputs!$B$9)*(PI()*(Inputs!$F$13/1000)^2/4)*((Inputs!$F$13/1000/4)^(2/3))*SQRT(N21)) | AM21: =IF(A21="","",(1/Inputs!$B$9)*(PI()*(Inputs!$F$14/1000)^2/4)*((Inputs!$F$14/1000/4)^(2/3))*SQRT(N21))
E22: =SUMIFS(CB_Tributaires!$C:$C,CB_Tributaires!$B:$B,$A22) | F22: =IF(D22="",E22,D22) | I22: =IF(A22="","",Inputs!$B$13/((IF(H22="",Inputs!$B$18,H22)+Inputs!$B$14)^Inputs!$B$15)) | J22: =IF(A22="","",0.00278*IF(G22="",Inputs!$B$17,G22)*F22*I22) | K22: =IF(A22="","",SUMIFS($L$4:$L$203,$B$4:$B$203,$A22)) | L22: =IF(A22="","",(J22+K22)*Inputs!$B$16) | N22: =IF(A22="","",IF(M22="",Inputs!$B$7,M22)) | O22: =IF(A22="","",IF(L22/Inputs!$B$10<=AD22,Inputs!$F$5,IF(L22/Inputs!$B$10>AM22,"OVERSIZE",INDEX(Inputs!$F$5:$F$14,MATCH(L22/Inputs!$B$10,AD22:AM22,1)+1)))) | Q22: =IF(A22="","",IF(P22="",O22,P22)) | R22: =IF(OR(Q22="",Q22="OVERSIZE"),"",Q22/1000) | S22: =IF(R22="","",(1/Inputs!$B$9)*(PI()*R22^2/4)*((R22/4)^(2/3))*SQRT(N22)) | T22: =IF(OR(S22="",L22=""),"",L22/(S22*Inputs!$B$10)) | U22: =IF(OR(R22="",L22=""),"",4*L22/(PI()*R22^2)) | W22: =IF(A22="","",IF(A22=Inputs!$B$6,Inputs!$B$22,IF(B22="","",IFERROR(INDEX($X$4:$X$203,MATCH(B22,$A$4:$A$203,0))+IF(V22="",Inputs!$B$20,V22),"")))) | X22: =IF(OR(W22="",N22="",C22=""),"",W22+N22*C22) | AA22: =IF(OR(Y22="",W22=""),"",Y22-W22) | AB22: =IF(OR(Z22="",X22=""),"",Z22-X22) | AC22: =IF(A22="","",IF(OR(T22>1,U22<Inputs!$B$11,U22>Inputs!$B$12,AA22<Inputs!$B$19,AB22<Inputs!$B$19,N22<Inputs!$B$7,N22>Inputs!$B$8),"CHECK","OK")) | AD22: =IF(A22="","",(1/Inputs!$B$9)*(PI()*(Inputs!$F$5/1000)^2/4)*((Inputs!$F$5/1000/4)^(2/3))*SQRT(N22)) | AE22: =IF(A22="","",(1/Inputs!$B$9)*(PI()*(Inputs!$F$6/1000)^2/4)*((Inputs!$F$6/1000/4)^(2/3))*SQRT(N22)) | AF22: =IF(A22="","",(1/Inputs!$B$9)*(PI()*(Inputs!$F$7/1000)^2/4)*((Inputs!$F$7/1000/4)^(2/3))*SQRT(N22)) | AG22: =IF(A22="","",(1/Inputs!$B$9)*(PI()*(Inputs!$F$8/1000)^2/4)*((Inputs!$F$8/1000/4)^(2/3))*SQRT(N22)) | AH22: =IF(A22="","",(1/Inputs!$B$9)*(PI()*(Inputs!$F$9/1000)^2/4)*((Inputs!$F$9/1000/4)^(2/3))*SQRT(N22)) | AI22: =IF(A22="","",(1/Inputs!$B$9)*(PI()*(Inputs!$F$10/1000)^2/4)*((Inputs!$F$10/1000/4)^(2/3))*SQRT(N22)) | AJ22: =IF(A22="","",(1/Inputs!$B$9)*(PI()*(Inputs!$F$11/1000)^2/4)*((Inputs!$F$11/1000/4)^(2/3))*SQRT(N22)) | AK22: =IF(A22="","",(1/Inputs!$B$9)*(PI()*(Inputs!$F$12/1000)^2/4)*((Inputs!$F$12/1000/4)^(2/3))*SQRT(N22)) | AL22: =IF(A22="","",(1/Inputs!$B$9)*(PI()*(Inputs!$F$13/1000)^2/4)*((Inputs!$F$13/1000/4)^(2/3))*SQRT(N22)) | AM22: =IF(A22="","",(1/Inputs!$B$9)*(PI()*(Inputs!$F$14/1000)^2/4)*((Inputs!$F$14/1000/4)^(2/3))*SQRT(N22))
E23: =SUMIFS(CB_Tributaires!$C:$C,CB_Tributaires!$B:$B,$A23) | F23: =IF(D23="",E23,D23) | I23: =IF(A23="","",Inputs!$B$13/((IF(H23="",Inputs!$B$18,H23)+Inputs!$B$14)^Inputs!$B$15)) | J23: =IF(A23="","",0.00278*IF(G23="",Inputs!$B$17,G23)*F23*I23) | K23: =IF(A23="","",SUMIFS($L$4:$L$203,$B$4:$B$203,$A23)) | L23: =IF(A23="","",(J23+K23)*Inputs!$B$16) | N23: =IF(A23="","",IF(M23="",Inputs!$B$7,M23)) | O23: =IF(A23="","",IF(L23/Inputs!$B$10<=AD23,Inputs!$F$5,IF(L23/Inputs!$B$10>AM23,"OVERSIZE",INDEX(Inputs!$F$5:$F$14,MATCH(L23/Inputs!$B$10,AD23:AM23,1)+1)))) | Q23: =IF(A23="","",IF(P23="",O23,P23)) | R23: =IF(OR(Q23="",Q23="OVERSIZE"),"",Q23/1000) | S23: =IF(R23="","",(1/Inputs!$B$9)*(PI()*R23^2/4)*((R23/4)^(2/3))*SQRT(N23)) | T23: =IF(OR(S23="",L23=""),"",L23/(S23*Inputs!$B$10)) | U23: =IF(OR(R23="",L23=""),"",4*L23/(PI()*R23^2)) | W23: =IF(A23="","",IF(A23=Inputs!$B$6,Inputs!$B$22,IF(B23="","",IFERROR(INDEX($X$4:$X$203,MATCH(B23,$A$4:$A$203,0))+IF(V23="",Inputs!$B$20,V23),"")))) | X23: =IF(OR(W23="",N23="",C23=""),"",W23+N23*C23) | AA23: =IF(OR(Y23="",W23=""),"",Y23-W23) | AB23: =IF(OR(Z23="",X23=""),"",Z23-X23) | AC23: =IF(A23="","",IF(OR(T23>1,U23<Inputs!$B$11,U23>Inputs!$B$12,AA23<Inputs!$B$19,AB23<Inputs!$B$19,N23<Inputs!$B$7,N23>Inputs!$B$8),"CHECK","OK")) | AD23: =IF(A23="","",(1/Inputs!$B$9)*(PI()*(Inputs!$F$5/1000)^2/4)*((Inputs!$F$5/1000/4)^(2/3))*SQRT(N23)) | AE23: =IF(A23="","",(1/Inputs!$B$9)*(PI()*(Inputs!$F$6/1000)^2/4)*((Inputs!$F$6/1000/4)^(2/3))*SQRT(N23)) | AF23: =IF(A23="","",(1/Inputs!$B$9)*(PI()*(Inputs!$F$7/1000)^2/4)*((Inputs!$F$7/1000/4)^(2/3))*SQRT(N23)) | AG23: =IF(A23="","",(1/Inputs!$B$9)*(PI()*(Inputs!$F$8/1000)^2/4)*((Inputs!$F$8/1000/4)^(2/3))*SQRT(N23)) | AH23: =IF(A23="","",(1/Inputs!$B$9)*(PI()*(Inputs!$F$9/1000)^2/4)*((Inputs!$F$9/1000/4)^(2/3))*SQRT(N23)) | AI23: =IF(A23="","",(1/Inputs!$B$9)*(PI()*(Inputs!$F$10/1000)^2/4)*((Inputs!$F$10/1000/4)^(2/3))*SQRT(N23)) | AJ23: =IF(A23="","",(1/Inputs!$B$9)*(PI()*(Inputs!$F$11/1000)^2/4)*((Inputs!$F$11/1000/4)^(2/3))*SQRT(N23)) | AK23: =IF(A23="","",(1/Inputs!$B$9)*(PI()*(Inputs!$F$12/1000)^2/4)*((Inputs!$F$12/1000/4)^(2/3))*SQRT(N23)) | AL23: =IF(A23="","",(1/Inputs!$B$9)*(PI()*(Inputs!$F$13/1000)^2/4)*((Inputs!$F$13/1000/4)^(2/3))*SQRT(N23)) | AM23: =IF(A23="","",(1/Inputs!$B$9)*(PI()*(Inputs!$F$14/1000)^2/4)*((Inputs!$F$14/1000/4)^(2/3))*SQRT(N23))
E24: =SUMIFS(CB_Tributaires!$C:$C,CB_Tributaires!$B:$B,$A24) | F24: =IF(D24="",E24,D24) | I24: =IF(A24="","",Inputs!$B$13/((IF(H24="",Inputs!$B$18,H24)+Inputs!$B$14)^Inputs!$B$15)) | J24: =IF(A24="","",0.00278*IF(G24="",Inputs!$B$17,G24)*F24*I24) | K24: =IF(A24="","",SUMIFS($L$4:$L$203,$B$4:$B$203,$A24)) | L24: =IF(A24="","",(J24+K24)*Inputs!$B$16) | N24: =IF(A24="","",IF(M24="",Inputs!$B$7,M24)) | O24: =IF(A24="","",IF(L24/Inputs!$B$10<=AD24,Inputs!$F$5,IF(L24/Inputs!$B$10>AM24,"OVERSIZE",INDEX(Inputs!$F$5:$F$14,MATCH(L24/Inputs!$B$10,AD24:AM24,1)+1)))) | Q24: =IF(A24="","",IF(P24="",O24,P24)) | R24: =IF(OR(Q24="",Q24="OVERSIZE"),"",Q24/1000) | S24: =IF(R24="","",(1/Inputs!$B$9)*(PI()*R24^2/4)*((R24/4)^(2/3))*SQRT(N24)) | T24: =IF(OR(S24="",L24=""),"",L24/(S24*Inputs!$B$10)) | U24: =IF(OR(R24="",L24=""),"",4*L24/(PI()*R24^2)) | W24: =IF(A24="","",IF(A24=Inputs!$B$6,Inputs!$B$22,IF(B24="","",IFERROR(INDEX($X$4:$X$203,MATCH(B24,$A$4:$A$203,0))+IF(V24="",Inputs!$B$20,V24),"")))) | X24: =IF(OR(W24="",N24="",C24=""),"",W24+N24*C24) | AA24: =IF(OR(Y24="",W24=""),"",Y24-W24) | AB24: =IF(OR(Z24="",X24=""),"",Z24-X24) | AC24: =IF(A24="","",IF(OR(T24>1,U24<Inputs!$B$11,U24>Inputs!$B$12,AA24<Inputs!$B$19,AB24<Inputs!$B$19,N24<Inputs!$B$7,N24>Inputs!$B$8),"CHECK","OK")) | AD24: =IF(A24="","",(1/Inputs!$B$9)*(PI()*(Inputs!$F$5/1000)^2/4)*((Inputs!$F$5/1000/4)^(2/3))*SQRT(N24)) | AE24: =IF(A24="","",(1/Inputs!$B$9)*(PI()*(Inputs!$F$6/1000)^2/4)*((Inputs!$F$6/1000/4)^(2/3))*SQRT(N24)) | AF24: =IF(A24="","",(1/Inputs!$B$9)*(PI()*(Inputs!$F$7/1000)^2/4)*((Inputs!$F$7/1000/4)^(2/3))*SQRT(N24)) | AG24: =IF(A24="","",(1/Inputs!$B$9)*(PI()*(Inputs!$F$8/1000)^2/4)*((Inputs!$F$8/1000/4)^(2/3))*SQRT(N24)) | AH24: =IF(A24="","",(1/Inputs!$B$9)*(PI()*(Inputs!$F$9/1000)^2/4)*((Inputs!$F$9/1000/4)^(2/3))*SQRT(N24)) | AI24: =IF(A24="","",(1/Inputs!$B$9)*(PI()*(Inputs!$F$10/1000)^2/4)*((Inputs!$F$10/1000/4)^(2/3))*SQRT(N24)) | AJ24: =IF(A24="","",(1/Inputs!$B$9)*(PI()*(Inputs!$F$11/1000)^2/4)*((Inputs!$F$11/1000/4)^(2/3))*SQRT(N24)) | AK24: =IF(A24="","",(1/Inputs!$B$9)*(PI()*(Inputs!$F$12/1000)^2/4)*((Inputs!$F$12/1000/4)^(2/3))*SQRT(N24)) | AL24: =IF(A24="","",(1/Inputs!$B$9)*(PI()*(Inputs!$F$13/1000)^2/4)*((Inputs!$F$13/1000/4)^(2/3))*SQRT(N24)) | AM24: =IF(A24="","",(1/Inputs!$B$9)*(PI()*(Inputs!$F$14/1000)^2/4)*((Inputs!$F$14/1000/4)^(2/3))*SQRT(N24))
E25: =SUMIFS(CB_Tributaires!$C:$C,CB_Tributaires!$B:$B,$A25) | F25: =IF(D25="",E25,D25) | I25: =IF(A25="","",Inputs!$B$13/((IF(H25="",Inputs!$B$18,H25)+Inputs!$B$14)^Inputs!$B$15)) | J25: =IF(A25="","",0.00278*IF(G25="",Inputs!$B$17,G25)*F25*I25) | K25: =IF(A25="","",SUMIFS($L$4:$L$203,$B$4:$B$203,$A25)) | L25: =IF(A25="","",(J25+K25)*Inputs!$B$16) | N25: =IF(A25="","",IF(M25="",Inputs!$B$7,M25)) | O25: =IF(A25="","",IF(L25/Inputs!$B$10<=AD25,Inputs!$F$5,IF(L25/Inputs!$B$10>AM25,"OVERSIZE",INDEX(Inputs!$F$5:$F$14,MATCH(L25/Inputs!$B$10,AD25:AM25,1)+1)))) | Q25: =IF(A25="","",IF(P25="",O25,P25)) | R25: =IF(OR(Q25="",Q25="OVERSIZE"),"",Q25/1000) | S25: =IF(R25="","",(1/Inputs!$B$9)*(PI()*R25^2/4)*((R25/4)^(2/3))*SQRT(N25)) | T25: =IF(OR(S25="",L25=""),"",L25/(S25*Inputs!$B$10)) | U25: =IF(OR(R25="",L25=""),"",4*L25/(PI()*R25^2)) | W25: =IF(A25="","",IF(A25=Inputs!$B$6,Inputs!$B$22,IF(B25="","",IFERROR(INDEX($X$4:$X$203,MATCH(B25,$A$4:$A$203,0))+IF(V25="",Inputs!$B$20,V25),"")))) | X25: =IF(OR(W25="",N25="",C25=""),"",W25+N25*C25) | AA25: =IF(OR(Y25="",W25=""),"",Y25-W25) | AB25: =IF(OR(Z25="",X25=""),"",Z25-X25) | AC25: =IF(A25="","",IF(OR(T25>1,U25<Inputs!$B$11,U25>Inputs!$B$12,AA25<Inputs!$B$19,AB25<Inputs!$B$19,N25<Inputs!$B$7,N25>Inputs!$B$8),"CHECK","OK")) | AD25: =IF(A25="","",(1/Inputs!$B$9)*(PI()*(Inputs!$F$5/1000)^2/4)*((Inputs!$F$5/1000/4)^(2/3))*SQRT(N25)) | AE25: =IF(A25="","",(1/Inputs!$B$9)*(PI()*(Inputs!$F$6/1000)^2/4)*((Inputs!$F$6/1000/4)^(2/3))*SQRT(N25)) | AF25: =IF(A25="","",(1/Inputs!$B$9)*(PI()*(Inputs!$F$7/1000)^2/4)*((Inputs!$F$7/1000/4)^(2/3))*SQRT(N25)) | AG25: =IF(A25="","",(1/Inputs!$B$9)*(PI()*(Inputs!$F$8/1000)^2/4)*((Inputs!$F$8/1000/4)^(2/3))*SQRT(N25)) | AH25: =IF(A25="","",(1/Inputs!$B$9)*(PI()*(Inputs!$F$9/1000)^2/4)*((Inputs!$F$9/1000/4)^(2/3))*SQRT(N25)) | AI25: =IF(A25="","",(1/Inputs!$B$9)*(PI()*(Inputs!$F$10/1000)^2/4)*((Inputs!$F$10/1000/4)^(2/3))*SQRT(N25)) | AJ25: =IF(A25="","",(1/Inputs!$B$9)*(PI()*(Inputs!$F$11/1000)^2/4)*((Inputs!$F$11/1000/4)^(2/3))*SQRT(N25)) | AK25: =IF(A25="","",(1/Inputs!$B$9)*(PI()*(Inputs!$F$12/1000)^2/4)*((Inputs!$F$12/1000/4)^(2/3))*SQRT(N25)) | AL25: =IF(A25="","",(1/Inputs!$B$9)*(PI()*(Inputs!$F$13/1000)^2/4)*((Inputs!$F$13/1000/4)^(2/3))*SQRT(N25)) | AM25: =IF(A25="","",(1/Inputs!$B$9)*(PI()*(Inputs!$F$14/1000)^2/4)*((Inputs!$F$14/1000/4)^(2/3))*SQRT(N25))
E26: =SUMIFS(CB_Tributaires!$C:$C,CB_Tributaires!$B:$B,$A26) | F26: =IF(D26="",E26,D26) | I26: =IF(A26="","",Inputs!$B$13/((IF(H26="",Inputs!$B$18,H26)+Inputs!$B$14)^Inputs!$B$15)) | J26: =IF(A26="","",0.00278*IF(G26="",Inputs!$B$17,G26)*F26*I26) | K26: =IF(A26="","",SUMIFS($L$4:$L$203,$B$4:$B$203,$A26)) | L26: =IF(A26="","",(J26+K26)*Inputs!$B$16) | N26: =IF(A26="","",IF(M26="",Inputs!$B$7,M26)) | O26: =IF(A26="","",IF(L26/Inputs!$B$10<=AD26,Inputs!$F$5,IF(L26/Inputs!$B$10>AM26,"OVERSIZE",INDEX(Inputs!$F$5:$F$14,MATCH(L26/Inputs!$B$10,AD26:AM26,1)+1)))) | Q26: =IF(A26="","",IF(P26="",O26,P26)) | R26: =IF(OR(Q26="",Q26="OVERSIZE"),"",Q26/1000) | S26: =IF(R26="","",(1/Inputs!$B$9)*(PI()*R26^2/4)*((R26/4)^(2/3))*SQRT(N26)) | T26: =IF(OR(S26="",L26=""),"",L26/(S26*Inputs!$B$10)) | U26: =IF(OR(R26="",L26=""),"",4*L26/(PI()*R26^2)) | W26: =IF(A26="","",IF(A26=Inputs!$B$6,Inputs!$B$22,IF(B26="","",IFERROR(INDEX($X$4:$X$203,MATCH(B26,$A$4:$A$203,0))+IF(V26="",Inputs!$B$20,V26),"")))) | X26: =IF(OR(W26="",N26="",C26=""),"",W26+N26*C26) | AA26: =IF(OR(Y26="",W26=""),"",Y26-W26) | AB26: =IF(OR(Z26="",X26=""),"",Z26-X26) | AC26: =IF(A26="","",IF(OR(T26>1,U26<Inputs!$B$11,U26>Inputs!$B$12,AA26<Inputs!$B$19,AB26<Inputs!$B$19,N26<Inputs!$B$7,N26>Inputs!$B$8),"CHECK","OK")) | AD26: =IF(A26="","",(1/Inputs!$B$9)*(PI()*(Inputs!$F$5/1000)^2/4)*((Inputs!$F$5/1000/4)^(2/3))*SQRT(N26)) | AE26: =IF(A26="","",(1/Inputs!$B$9)*(PI()*(Inputs!$F$6/1000)^2/4)*((Inputs!$F$6/1000/4)^(2/3))*SQRT(N26)) | AF26: =IF(A26="","",(1/Inputs!$B$9)*(PI()*(Inputs!$F$7/1000)^2/4)*((Inputs!$F$7/1000/4)^(2/3))*SQRT(N26)) | AG26: =IF(A26="","",(1/Inputs!$B$9)*(PI()*(Inputs!$F$8/1000)^2/4)*((Inputs!$F$8/1000/4)^(2/3))*SQRT(N26)) | AH26: =IF(A26="","",(1/Inputs!$B$9)*(PI()*(Inputs!$F$9/1000)^2/4)*((Inputs!$F$9/1000/4)^(2/3))*SQRT(N26)) | AI26: =IF(A26="","",(1/Inputs!$B$9)*(PI()*(Inputs!$F$10/1000)^2/4)*((Inputs!$F$10/1000/4)^(2/3))*SQRT(N26)) | AJ26: =IF(A26="","",(1/Inputs!$B$9)*(PI()*(Inputs!$F$11/1000)^2/4)*((Inputs!$F$11/1000/4)^(2/3))*SQRT(N26)) | AK26: =IF(A26="","",(1/Inputs!$B$9)*(PI()*(Inputs!$F$12/1000)^2/4)*((Inputs!$F$12/1000/4)^(2/3))*SQRT(N26)) | AL26: =IF(A26="","",(1/Inputs!$B$9)*(PI()*(Inputs!$F$13/1000)^2/4)*((Inputs!$F$13/1000/4)^(2/3))*SQRT(N26)) | AM26: =IF(A26="","",(1/Inputs!$B$9)*(PI()*(Inputs!$F$14/1000)^2/4)*((Inputs!$F$14/1000/4)^(2/3))*SQRT(N26))
